[2025-06-26T18:32:33.012+0700] {local_task_job_runner.py:120} INFO - ::group::Pre task execution logs
[2025-06-26T18:32:33.032+0700] {taskinstance.py:2073} INFO - Dependencies all met for dep_context=non-requeueable deps ti=<TaskInstance: send_data_to_powerbi.compact_csv_to_one_file scheduled__2025-06-26T11:20:00+00:00 [queued]>
[2025-06-26T18:32:33.037+0700] {taskinstance.py:2073} INFO - Dependencies all met for dep_context=requeueable deps ti=<TaskInstance: send_data_to_powerbi.compact_csv_to_one_file scheduled__2025-06-26T11:20:00+00:00 [queued]>
[2025-06-26T18:32:33.037+0700] {taskinstance.py:2303} INFO - Starting attempt 1 of 3
[2025-06-26T18:32:33.065+0700] {taskinstance.py:2327} INFO - Executing <Task(BashOperator): compact_csv_to_one_file> on 2025-06-26 11:20:00+00:00
[2025-06-26T18:32:33.072+0700] {standard_task_runner.py:63} INFO - Started process 14685 to run task
[2025-06-26T18:32:33.077+0700] {standard_task_runner.py:90} INFO - Running: ['airflow', 'tasks', 'run', 'send_data_to_powerbi', 'compact_csv_to_one_file', 'scheduled__2025-06-26T11:20:00+00:00', '--job-id', '55', '--raw', '--subdir', 'DAGS_FOLDER/load_power_bi.py', '--cfg-path', '/tmp/tmpefy61_25']
[2025-06-26T18:32:33.078+0700] {standard_task_runner.py:91} INFO - Job 55: Subtask compact_csv_to_one_file
[2025-06-26T18:32:33.169+0700] {task_command.py:426} INFO - Running <TaskInstance: send_data_to_powerbi.compact_csv_to_one_file scheduled__2025-06-26T11:20:00+00:00 [running]> on host Panda
[2025-06-26T18:32:33.352+0700] {taskinstance.py:2644} INFO - Exporting env vars: AIRFLOW_CTX_DAG_OWNER='group_03' AIRFLOW_CTX_DAG_ID='send_data_to_powerbi' AIRFLOW_CTX_TASK_ID='compact_csv_to_one_file' AIRFLOW_CTX_EXECUTION_DATE='2025-06-26T11:20:00+00:00' AIRFLOW_CTX_TRY_NUMBER='1' AIRFLOW_CTX_DAG_RUN_ID='scheduled__2025-06-26T11:20:00+00:00'
[2025-06-26T18:32:33.353+0700] {taskinstance.py:430} INFO - ::endgroup::
[2025-06-26T18:32:33.354+0700] {subprocess.py:63} INFO - Tmp dir root location: /tmp
[2025-06-26T18:32:33.354+0700] {subprocess.py:75} INFO - Running command: ['/usr/bin/bash', '-c', 'spark-submit /home/panda/Documents/ODAP/Project/hadoop/compact_csv.py && sleep 10']
[2025-06-26T18:32:33.369+0700] {subprocess.py:86} INFO - Output:
[2025-06-26T18:32:35.933+0700] {subprocess.py:93} INFO - 25/06/26 18:32:35 INFO SparkContext: Running Spark version 3.5.5
[2025-06-26T18:32:35.937+0700] {subprocess.py:93} INFO - 25/06/26 18:32:35 INFO SparkContext: OS info Linux, 6.11.0-26-generic, amd64
[2025-06-26T18:32:35.938+0700] {subprocess.py:93} INFO - 25/06/26 18:32:35 INFO SparkContext: Java version 11.0.27
[2025-06-26T18:32:36.107+0700] {subprocess.py:93} INFO - 25/06/26 18:32:36 INFO ResourceUtils: ==============================================================
[2025-06-26T18:32:36.108+0700] {subprocess.py:93} INFO - 25/06/26 18:32:36 INFO ResourceUtils: No custom resources configured for spark.driver.
[2025-06-26T18:32:36.108+0700] {subprocess.py:93} INFO - 25/06/26 18:32:36 INFO ResourceUtils: ==============================================================
[2025-06-26T18:32:36.108+0700] {subprocess.py:93} INFO - 25/06/26 18:32:36 INFO SparkContext: Submitted application: CompactSmallFiles
[2025-06-26T18:32:36.132+0700] {subprocess.py:93} INFO - 25/06/26 18:32:36 INFO ResourceProfile: Default ResourceProfile created, executor resources: Map(cores -> name: cores, amount: 1, script: , vendor: , memory -> name: memory, amount: 1024, script: , vendor: , offHeap -> name: offHeap, amount: 0, script: , vendor: ), task resources: Map(cpus -> name: cpus, amount: 1.0)
[2025-06-26T18:32:36.144+0700] {subprocess.py:93} INFO - 25/06/26 18:32:36 INFO ResourceProfile: Limiting resource is cpu
[2025-06-26T18:32:36.144+0700] {subprocess.py:93} INFO - 25/06/26 18:32:36 INFO ResourceProfileManager: Added ResourceProfile id: 0
[2025-06-26T18:32:36.209+0700] {subprocess.py:93} INFO - 25/06/26 18:32:36 INFO SecurityManager: Changing view acls to: panda
[2025-06-26T18:32:36.210+0700] {subprocess.py:93} INFO - 25/06/26 18:32:36 INFO SecurityManager: Changing modify acls to: panda
[2025-06-26T18:32:36.210+0700] {subprocess.py:93} INFO - 25/06/26 18:32:36 INFO SecurityManager: Changing view acls groups to:
[2025-06-26T18:32:36.210+0700] {subprocess.py:93} INFO - 25/06/26 18:32:36 INFO SecurityManager: Changing modify acls groups to:
[2025-06-26T18:32:36.211+0700] {subprocess.py:93} INFO - 25/06/26 18:32:36 INFO SecurityManager: SecurityManager: authentication disabled; ui acls disabled; users with view permissions: panda; groups with view permissions: EMPTY; users with modify permissions: panda; groups with modify permissions: EMPTY
[2025-06-26T18:32:36.509+0700] {subprocess.py:93} INFO - 25/06/26 18:32:36 INFO Utils: Successfully started service 'sparkDriver' on port 33151.
[2025-06-26T18:32:36.539+0700] {subprocess.py:93} INFO - 25/06/26 18:32:36 INFO SparkEnv: Registering MapOutputTracker
[2025-06-26T18:32:36.577+0700] {subprocess.py:93} INFO - 25/06/26 18:32:36 INFO SparkEnv: Registering BlockManagerMaster
[2025-06-26T18:32:36.623+0700] {subprocess.py:93} INFO - 25/06/26 18:32:36 INFO BlockManagerMasterEndpoint: Using org.apache.spark.storage.DefaultTopologyMapper for getting topology information
[2025-06-26T18:32:36.624+0700] {subprocess.py:93} INFO - 25/06/26 18:32:36 INFO BlockManagerMasterEndpoint: BlockManagerMasterEndpoint up
[2025-06-26T18:32:36.629+0700] {subprocess.py:93} INFO - 25/06/26 18:32:36 INFO SparkEnv: Registering BlockManagerMasterHeartbeat
[2025-06-26T18:32:36.656+0700] {subprocess.py:93} INFO - 25/06/26 18:32:36 INFO DiskBlockManager: Created local directory at /tmp/blockmgr-f13b2a0b-f266-4a27-bbc3-2f63c7c711ea
[2025-06-26T18:32:36.671+0700] {subprocess.py:93} INFO - 25/06/26 18:32:36 INFO MemoryStore: MemoryStore started with capacity 434.4 MiB
[2025-06-26T18:32:36.687+0700] {subprocess.py:93} INFO - 25/06/26 18:32:36 INFO SparkEnv: Registering OutputCommitCoordinator
[2025-06-26T18:32:36.857+0700] {subprocess.py:93} INFO - 25/06/26 18:32:36 INFO JettyUtils: Start Jetty 127.0.0.1:4040 for SparkUI
[2025-06-26T18:32:36.947+0700] {subprocess.py:93} INFO - 25/06/26 18:32:36 INFO Utils: Successfully started service 'SparkUI' on port 4040.
[2025-06-26T18:32:37.073+0700] {subprocess.py:93} INFO - 25/06/26 18:32:37 INFO Executor: Starting executor ID driver on host localhost
[2025-06-26T18:32:37.074+0700] {subprocess.py:93} INFO - 25/06/26 18:32:37 INFO Executor: OS info Linux, 6.11.0-26-generic, amd64
[2025-06-26T18:32:37.074+0700] {subprocess.py:93} INFO - 25/06/26 18:32:37 INFO Executor: Java version 11.0.27
[2025-06-26T18:32:37.086+0700] {subprocess.py:93} INFO - 25/06/26 18:32:37 INFO Executor: Starting executor with user classpath (userClassPathFirst = false): ''
[2025-06-26T18:32:37.087+0700] {subprocess.py:93} INFO - 25/06/26 18:32:37 INFO Executor: Created or updated repl class loader org.apache.spark.util.MutableURLClassLoader@55000ea9 for default.
[2025-06-26T18:32:37.125+0700] {subprocess.py:93} INFO - 25/06/26 18:32:37 INFO Utils: Successfully started service 'org.apache.spark.network.netty.NettyBlockTransferService' on port 37563.
[2025-06-26T18:32:37.125+0700] {subprocess.py:93} INFO - 25/06/26 18:32:37 INFO NettyBlockTransferService: Server created on localhost:37563
[2025-06-26T18:32:37.128+0700] {subprocess.py:93} INFO - 25/06/26 18:32:37 INFO BlockManager: Using org.apache.spark.storage.RandomBlockReplicationPolicy for block replication policy
[2025-06-26T18:32:37.140+0700] {subprocess.py:93} INFO - 25/06/26 18:32:37 INFO BlockManagerMaster: Registering BlockManager BlockManagerId(driver, localhost, 37563, None)
[2025-06-26T18:32:37.146+0700] {subprocess.py:93} INFO - 25/06/26 18:32:37 INFO BlockManagerMasterEndpoint: Registering block manager localhost:37563 with 434.4 MiB RAM, BlockManagerId(driver, localhost, 37563, None)
[2025-06-26T18:32:37.151+0700] {subprocess.py:93} INFO - 25/06/26 18:32:37 INFO BlockManagerMaster: Registered BlockManager BlockManagerId(driver, localhost, 37563, None)
[2025-06-26T18:32:37.152+0700] {subprocess.py:93} INFO - 25/06/26 18:32:37 INFO BlockManager: Initialized BlockManager: BlockManagerId(driver, localhost, 37563, None)
[2025-06-26T18:32:37.620+0700] {subprocess.py:93} INFO - 25/06/26 18:32:37 INFO SharedState: Setting hive.metastore.warehouse.dir ('null') to the value of spark.sql.warehouse.dir.
[2025-06-26T18:32:37.628+0700] {subprocess.py:93} INFO - 25/06/26 18:32:37 INFO SharedState: Warehouse path is 'file:/tmp/airflowtmplnm45paz/spark-warehouse'.
[2025-06-26T18:32:38.838+0700] {subprocess.py:93} INFO - 25/06/26 18:32:38 INFO MetadataLogFileIndex: Reading streaming file log from hdfs://localhost:9000/transactions_by_hour/_spark_metadata
[2025-06-26T18:32:38.907+0700] {subprocess.py:93} INFO - 25/06/26 18:32:38 INFO FileStreamSinkLog: BatchIds found from listing: 0, 1, 2, 3, 4, 5, 6, 7, 8, 9, 10, 11, 12, 13, 14, 15, 16, 17, 18, 19, 20, 21, 22, 23, 24, 25, 26, 27, 28, 29, 30, 31, 32, 33, 34, 35, 36, 37, 38, 39, 40, 41, 42, 43, 44, 45, 46, 47, 48, 49, 50, 51, 52, 53, 54, 55, 56, 57, 58, 59, 60, 61, 62, 63, 64, 65, 66, 67, 68, 69, 70, 71, 72, 73, 74, 75, 76, 77, 78, 79, 80, 81, 82, 83, 84, 85, 86, 87, 88, 89, 90, 91, 92, 93, 94, 95, 96, 97, 98, 99, 100, 101, 102, 103, 104, 105, 106, 107, 108, 109, 110, 111, 112, 113, 114, 115, 116, 117, 118, 119, 120, 121, 122, 123, 124, 125, 126, 127, 128, 129, 130, 131, 132, 133, 134, 135, 136, 137, 138, 139, 140, 141, 142, 143, 144, 145, 146, 147, 148
[2025-06-26T18:32:38.944+0700] {subprocess.py:93} INFO - 25/06/26 18:32:38 INFO FileStreamSinkLog: Set the compact interval to 10 [defaultCompactInterval: 10]
[2025-06-26T18:32:39.425+0700] {subprocess.py:93} INFO - 25/06/26 18:32:39 INFO HadoopFSUtils: Listing leaf files and directories in parallel under 149 paths. The first several paths are: hdfs://localhost:9000/transactions_by_hour/part-00000-bb8e9023-9b02-4175-a80b-0bcd66f220bf-c000.csv, hdfs://localhost:9000/transactions_by_hour/part-00000-71db78a4-5a68-4e86-ab52-811799d8429d-c000.csv, hdfs://localhost:9000/transactions_by_hour/part-00000-3978d575-97e5-4096-9883-dac5aa201568-c000.csv, hdfs://localhost:9000/transactions_by_hour/part-00000-0350f0e5-ad33-4abe-aa50-2a362584824e-c000.csv, hdfs://localhost:9000/transactions_by_hour/part-00000-e8b907bd-9eab-43a3-9173-93788c2d1762-c000.csv, hdfs://localhost:9000/transactions_by_hour/part-00000-ddea7f8b-1391-43bb-b913-1f30408f9697-c000.csv, hdfs://localhost:9000/transactions_by_hour/part-00000-8655a41e-ddba-480c-8a8a-c56164c7bfbf-c000.csv, hdfs://localhost:9000/transactions_by_hour/part-00000-2505f243-eaec-445e-a812-23ac922a22c4-c000.csv, hdfs://localhost:9000/transactions_by_hour/part-00000-aa7b7aa4-3f53-4ee7-85f7-e28d4c130ba5-c000.csv, hdfs://localhost:9000/transactions_by_hour/part-00000-48ec54eb-9275-4c64-8008-84d2f624a0fa-c000.csv.
[2025-06-26T18:32:39.872+0700] {subprocess.py:93} INFO - 25/06/26 18:32:39 INFO SparkContext: Starting job: csv at NativeMethodAccessorImpl.java:0
[2025-06-26T18:32:39.900+0700] {subprocess.py:93} INFO - 25/06/26 18:32:39 INFO DAGScheduler: Got job 0 (csv at NativeMethodAccessorImpl.java:0) with 149 output partitions
[2025-06-26T18:32:39.900+0700] {subprocess.py:93} INFO - 25/06/26 18:32:39 INFO DAGScheduler: Final stage: ResultStage 0 (csv at NativeMethodAccessorImpl.java:0)
[2025-06-26T18:32:39.901+0700] {subprocess.py:93} INFO - 25/06/26 18:32:39 INFO DAGScheduler: Parents of final stage: List()
[2025-06-26T18:32:39.903+0700] {subprocess.py:93} INFO - 25/06/26 18:32:39 INFO DAGScheduler: Missing parents: List()
[2025-06-26T18:32:39.908+0700] {subprocess.py:93} INFO - 25/06/26 18:32:39 INFO DAGScheduler: Submitting ResultStage 0 (MapPartitionsRDD[1] at csv at NativeMethodAccessorImpl.java:0), which has no missing parents
[2025-06-26T18:32:40.025+0700] {subprocess.py:93} INFO - 25/06/26 18:32:40 INFO MemoryStore: Block broadcast_0 stored as values in memory (estimated size 103.2 KiB, free 434.3 MiB)
[2025-06-26T18:32:40.064+0700] {subprocess.py:93} INFO - 25/06/26 18:32:40 INFO MemoryStore: Block broadcast_0_piece0 stored as bytes in memory (estimated size 37.3 KiB, free 434.3 MiB)
[2025-06-26T18:32:40.067+0700] {subprocess.py:93} INFO - 25/06/26 18:32:40 INFO BlockManagerInfo: Added broadcast_0_piece0 in memory on localhost:37563 (size: 37.3 KiB, free: 434.4 MiB)
[2025-06-26T18:32:40.072+0700] {subprocess.py:93} INFO - 25/06/26 18:32:40 INFO SparkContext: Created broadcast 0 from broadcast at DAGScheduler.scala:1585
[2025-06-26T18:32:40.093+0700] {subprocess.py:93} INFO - 25/06/26 18:32:40 INFO DAGScheduler: Submitting 149 missing tasks from ResultStage 0 (MapPartitionsRDD[1] at csv at NativeMethodAccessorImpl.java:0) (first 15 tasks are for partitions Vector(0, 1, 2, 3, 4, 5, 6, 7, 8, 9, 10, 11, 12, 13, 14))
[2025-06-26T18:32:40.094+0700] {subprocess.py:93} INFO - 25/06/26 18:32:40 INFO TaskSchedulerImpl: Adding task set 0.0 with 149 tasks resource profile 0
[2025-06-26T18:32:40.161+0700] {subprocess.py:93} INFO - 25/06/26 18:32:40 INFO TaskSetManager: Starting task 0.0 in stage 0.0 (TID 0) (localhost, executor driver, partition 0, PROCESS_LOCAL, 9215 bytes)
[2025-06-26T18:32:40.165+0700] {subprocess.py:93} INFO - 25/06/26 18:32:40 INFO TaskSetManager: Starting task 1.0 in stage 0.0 (TID 1) (localhost, executor driver, partition 1, PROCESS_LOCAL, 9215 bytes)
[2025-06-26T18:32:40.166+0700] {subprocess.py:93} INFO - 25/06/26 18:32:40 INFO TaskSetManager: Starting task 2.0 in stage 0.0 (TID 2) (localhost, executor driver, partition 2, PROCESS_LOCAL, 9215 bytes)
[2025-06-26T18:32:40.166+0700] {subprocess.py:93} INFO - 25/06/26 18:32:40 INFO TaskSetManager: Starting task 3.0 in stage 0.0 (TID 3) (localhost, executor driver, partition 3, PROCESS_LOCAL, 9215 bytes)
[2025-06-26T18:32:40.169+0700] {subprocess.py:93} INFO - 25/06/26 18:32:40 INFO TaskSetManager: Starting task 4.0 in stage 0.0 (TID 4) (localhost, executor driver, partition 4, PROCESS_LOCAL, 9215 bytes)
[2025-06-26T18:32:40.169+0700] {subprocess.py:93} INFO - 25/06/26 18:32:40 INFO TaskSetManager: Starting task 5.0 in stage 0.0 (TID 5) (localhost, executor driver, partition 5, PROCESS_LOCAL, 9215 bytes)
[2025-06-26T18:32:40.170+0700] {subprocess.py:93} INFO - 25/06/26 18:32:40 INFO TaskSetManager: Starting task 6.0 in stage 0.0 (TID 6) (localhost, executor driver, partition 6, PROCESS_LOCAL, 9215 bytes)
[2025-06-26T18:32:40.170+0700] {subprocess.py:93} INFO - 25/06/26 18:32:40 INFO TaskSetManager: Starting task 7.0 in stage 0.0 (TID 7) (localhost, executor driver, partition 7, PROCESS_LOCAL, 9215 bytes)
[2025-06-26T18:32:40.171+0700] {subprocess.py:93} INFO - 25/06/26 18:32:40 INFO TaskSetManager: Starting task 8.0 in stage 0.0 (TID 8) (localhost, executor driver, partition 8, PROCESS_LOCAL, 9215 bytes)
[2025-06-26T18:32:40.171+0700] {subprocess.py:93} INFO - 25/06/26 18:32:40 INFO TaskSetManager: Starting task 9.0 in stage 0.0 (TID 9) (localhost, executor driver, partition 9, PROCESS_LOCAL, 9215 bytes)
[2025-06-26T18:32:40.172+0700] {subprocess.py:93} INFO - 25/06/26 18:32:40 INFO TaskSetManager: Starting task 10.0 in stage 0.0 (TID 10) (localhost, executor driver, partition 10, PROCESS_LOCAL, 9215 bytes)
[2025-06-26T18:32:40.172+0700] {subprocess.py:93} INFO - 25/06/26 18:32:40 INFO TaskSetManager: Starting task 11.0 in stage 0.0 (TID 11) (localhost, executor driver, partition 11, PROCESS_LOCAL, 9215 bytes)
[2025-06-26T18:32:40.172+0700] {subprocess.py:93} INFO - 25/06/26 18:32:40 INFO TaskSetManager: Starting task 12.0 in stage 0.0 (TID 12) (localhost, executor driver, partition 12, PROCESS_LOCAL, 9215 bytes)
[2025-06-26T18:32:40.173+0700] {subprocess.py:93} INFO - 25/06/26 18:32:40 INFO TaskSetManager: Starting task 13.0 in stage 0.0 (TID 13) (localhost, executor driver, partition 13, PROCESS_LOCAL, 9215 bytes)
[2025-06-26T18:32:40.173+0700] {subprocess.py:93} INFO - 25/06/26 18:32:40 INFO TaskSetManager: Starting task 14.0 in stage 0.0 (TID 14) (localhost, executor driver, partition 14, PROCESS_LOCAL, 9215 bytes)
[2025-06-26T18:32:40.175+0700] {subprocess.py:93} INFO - 25/06/26 18:32:40 INFO TaskSetManager: Starting task 15.0 in stage 0.0 (TID 15) (localhost, executor driver, partition 15, PROCESS_LOCAL, 9215 bytes)
[2025-06-26T18:32:40.175+0700] {subprocess.py:93} INFO - 25/06/26 18:32:40 INFO TaskSetManager: Starting task 16.0 in stage 0.0 (TID 16) (localhost, executor driver, partition 16, PROCESS_LOCAL, 9215 bytes)
[2025-06-26T18:32:40.175+0700] {subprocess.py:93} INFO - 25/06/26 18:32:40 INFO TaskSetManager: Starting task 17.0 in stage 0.0 (TID 17) (localhost, executor driver, partition 17, PROCESS_LOCAL, 9215 bytes)
[2025-06-26T18:32:40.177+0700] {subprocess.py:93} INFO - 25/06/26 18:32:40 INFO TaskSetManager: Starting task 18.0 in stage 0.0 (TID 18) (localhost, executor driver, partition 18, PROCESS_LOCAL, 9215 bytes)
[2025-06-26T18:32:40.177+0700] {subprocess.py:93} INFO - 25/06/26 18:32:40 INFO TaskSetManager: Starting task 19.0 in stage 0.0 (TID 19) (localhost, executor driver, partition 19, PROCESS_LOCAL, 9215 bytes)
[2025-06-26T18:32:40.178+0700] {subprocess.py:93} INFO - 25/06/26 18:32:40 INFO TaskSetManager: Starting task 20.0 in stage 0.0 (TID 20) (localhost, executor driver, partition 20, PROCESS_LOCAL, 9215 bytes)
[2025-06-26T18:32:40.178+0700] {subprocess.py:93} INFO - 25/06/26 18:32:40 INFO TaskSetManager: Starting task 21.0 in stage 0.0 (TID 21) (localhost, executor driver, partition 21, PROCESS_LOCAL, 9215 bytes)
[2025-06-26T18:32:40.197+0700] {subprocess.py:93} INFO - 25/06/26 18:32:40 INFO Executor: Running task 19.0 in stage 0.0 (TID 19)
[2025-06-26T18:32:40.197+0700] {subprocess.py:93} INFO - 25/06/26 18:32:40 INFO Executor: Running task 9.0 in stage 0.0 (TID 9)
[2025-06-26T18:32:40.198+0700] {subprocess.py:93} INFO - 25/06/26 18:32:40 INFO Executor: Running task 20.0 in stage 0.0 (TID 20)
[2025-06-26T18:32:40.198+0700] {subprocess.py:93} INFO - 25/06/26 18:32:40 INFO Executor: Running task 0.0 in stage 0.0 (TID 0)
[2025-06-26T18:32:40.198+0700] {subprocess.py:93} INFO - 25/06/26 18:32:40 INFO Executor: Running task 2.0 in stage 0.0 (TID 2)
[2025-06-26T18:32:40.198+0700] {subprocess.py:93} INFO - 25/06/26 18:32:40 INFO Executor: Running task 10.0 in stage 0.0 (TID 10)
[2025-06-26T18:32:40.198+0700] {subprocess.py:93} INFO - 25/06/26 18:32:40 INFO Executor: Running task 13.0 in stage 0.0 (TID 13)
[2025-06-26T18:32:40.198+0700] {subprocess.py:93} INFO - 25/06/26 18:32:40 INFO Executor: Running task 4.0 in stage 0.0 (TID 4)
[2025-06-26T18:32:40.198+0700] {subprocess.py:93} INFO - 25/06/26 18:32:40 INFO Executor: Running task 16.0 in stage 0.0 (TID 16)
[2025-06-26T18:32:40.198+0700] {subprocess.py:93} INFO - 25/06/26 18:32:40 INFO Executor: Running task 12.0 in stage 0.0 (TID 12)
[2025-06-26T18:32:40.199+0700] {subprocess.py:93} INFO - 25/06/26 18:32:40 INFO Executor: Running task 3.0 in stage 0.0 (TID 3)
[2025-06-26T18:32:40.199+0700] {subprocess.py:93} INFO - 25/06/26 18:32:40 INFO Executor: Running task 17.0 in stage 0.0 (TID 17)
[2025-06-26T18:32:40.199+0700] {subprocess.py:93} INFO - 25/06/26 18:32:40 INFO Executor: Running task 8.0 in stage 0.0 (TID 8)
[2025-06-26T18:32:40.199+0700] {subprocess.py:93} INFO - 25/06/26 18:32:40 INFO Executor: Running task 15.0 in stage 0.0 (TID 15)
[2025-06-26T18:32:40.199+0700] {subprocess.py:93} INFO - 25/06/26 18:32:40 INFO Executor: Running task 5.0 in stage 0.0 (TID 5)
[2025-06-26T18:32:40.199+0700] {subprocess.py:93} INFO - 25/06/26 18:32:40 INFO Executor: Running task 18.0 in stage 0.0 (TID 18)
[2025-06-26T18:32:40.199+0700] {subprocess.py:93} INFO - 25/06/26 18:32:40 INFO Executor: Running task 21.0 in stage 0.0 (TID 21)
[2025-06-26T18:32:40.199+0700] {subprocess.py:93} INFO - 25/06/26 18:32:40 INFO Executor: Running task 14.0 in stage 0.0 (TID 14)
[2025-06-26T18:32:40.199+0700] {subprocess.py:93} INFO - 25/06/26 18:32:40 INFO Executor: Running task 1.0 in stage 0.0 (TID 1)
[2025-06-26T18:32:40.199+0700] {subprocess.py:93} INFO - 25/06/26 18:32:40 INFO Executor: Running task 11.0 in stage 0.0 (TID 11)
[2025-06-26T18:32:40.199+0700] {subprocess.py:93} INFO - 25/06/26 18:32:40 INFO Executor: Running task 6.0 in stage 0.0 (TID 6)
[2025-06-26T18:32:40.199+0700] {subprocess.py:93} INFO - 25/06/26 18:32:40 INFO Executor: Running task 7.0 in stage 0.0 (TID 7)
[2025-06-26T18:32:40.540+0700] {subprocess.py:93} INFO - 25/06/26 18:32:40 INFO Executor: Finished task 21.0 in stage 0.0 (TID 21). 3218 bytes result sent to driver
[2025-06-26T18:32:40.541+0700] {subprocess.py:93} INFO - 25/06/26 18:32:40 INFO Executor: Finished task 10.0 in stage 0.0 (TID 10). 3218 bytes result sent to driver
[2025-06-26T18:32:40.542+0700] {subprocess.py:93} INFO - 25/06/26 18:32:40 INFO Executor: Finished task 11.0 in stage 0.0 (TID 11). 3218 bytes result sent to driver
[2025-06-26T18:32:40.543+0700] {subprocess.py:93} INFO - 25/06/26 18:32:40 INFO Executor: Finished task 7.0 in stage 0.0 (TID 7). 3218 bytes result sent to driver
[2025-06-26T18:32:40.543+0700] {subprocess.py:93} INFO - 25/06/26 18:32:40 INFO Executor: Finished task 8.0 in stage 0.0 (TID 8). 3218 bytes result sent to driver
[2025-06-26T18:32:40.544+0700] {subprocess.py:93} INFO - 25/06/26 18:32:40 INFO Executor: Finished task 3.0 in stage 0.0 (TID 3). 3218 bytes result sent to driver
[2025-06-26T18:32:40.545+0700] {subprocess.py:93} INFO - 25/06/26 18:32:40 INFO Executor: Finished task 14.0 in stage 0.0 (TID 14). 3218 bytes result sent to driver
[2025-06-26T18:32:40.546+0700] {subprocess.py:93} INFO - 25/06/26 18:32:40 INFO Executor: Finished task 12.0 in stage 0.0 (TID 12). 3218 bytes result sent to driver
[2025-06-26T18:32:40.546+0700] {subprocess.py:93} INFO - 25/06/26 18:32:40 INFO Executor: Finished task 13.0 in stage 0.0 (TID 13). 3218 bytes result sent to driver
[2025-06-26T18:32:40.547+0700] {subprocess.py:93} INFO - 25/06/26 18:32:40 INFO Executor: Finished task 18.0 in stage 0.0 (TID 18). 3218 bytes result sent to driver
[2025-06-26T18:32:40.547+0700] {subprocess.py:93} INFO - 25/06/26 18:32:40 INFO Executor: Finished task 17.0 in stage 0.0 (TID 17). 3218 bytes result sent to driver
[2025-06-26T18:32:40.547+0700] {subprocess.py:93} INFO - 25/06/26 18:32:40 INFO Executor: Finished task 19.0 in stage 0.0 (TID 19). 3218 bytes result sent to driver
[2025-06-26T18:32:40.547+0700] {subprocess.py:93} INFO - 25/06/26 18:32:40 INFO Executor: Finished task 16.0 in stage 0.0 (TID 16). 3218 bytes result sent to driver
[2025-06-26T18:32:40.547+0700] {subprocess.py:93} INFO - 25/06/26 18:32:40 INFO Executor: Finished task 5.0 in stage 0.0 (TID 5). 3218 bytes result sent to driver
[2025-06-26T18:32:40.547+0700] {subprocess.py:93} INFO - 25/06/26 18:32:40 INFO Executor: Finished task 6.0 in stage 0.0 (TID 6). 3218 bytes result sent to driver
[2025-06-26T18:32:40.547+0700] {subprocess.py:93} INFO - 25/06/26 18:32:40 INFO Executor: Finished task 15.0 in stage 0.0 (TID 15). 3218 bytes result sent to driver
[2025-06-26T18:32:40.548+0700] {subprocess.py:93} INFO - 25/06/26 18:32:40 INFO Executor: Finished task 20.0 in stage 0.0 (TID 20). 3218 bytes result sent to driver
[2025-06-26T18:32:40.548+0700] {subprocess.py:93} INFO - 25/06/26 18:32:40 INFO Executor: Finished task 0.0 in stage 0.0 (TID 0). 3218 bytes result sent to driver
[2025-06-26T18:32:40.548+0700] {subprocess.py:93} INFO - 25/06/26 18:32:40 INFO Executor: Finished task 9.0 in stage 0.0 (TID 9). 3218 bytes result sent to driver
[2025-06-26T18:32:40.548+0700] {subprocess.py:93} INFO - 25/06/26 18:32:40 INFO Executor: Finished task 2.0 in stage 0.0 (TID 2). 3218 bytes result sent to driver
[2025-06-26T18:32:40.548+0700] {subprocess.py:93} INFO - 25/06/26 18:32:40 INFO Executor: Finished task 4.0 in stage 0.0 (TID 4). 3218 bytes result sent to driver
[2025-06-26T18:32:40.548+0700] {subprocess.py:93} INFO - 25/06/26 18:32:40 INFO Executor: Finished task 1.0 in stage 0.0 (TID 1). 3218 bytes result sent to driver
[2025-06-26T18:32:40.551+0700] {subprocess.py:93} INFO - 25/06/26 18:32:40 INFO TaskSetManager: Starting task 22.0 in stage 0.0 (TID 22) (localhost, executor driver, partition 22, PROCESS_LOCAL, 9215 bytes)
[2025-06-26T18:32:40.553+0700] {subprocess.py:93} INFO - 25/06/26 18:32:40 INFO Executor: Running task 22.0 in stage 0.0 (TID 22)
[2025-06-26T18:32:40.554+0700] {subprocess.py:93} INFO - 25/06/26 18:32:40 INFO TaskSetManager: Starting task 23.0 in stage 0.0 (TID 23) (localhost, executor driver, partition 23, PROCESS_LOCAL, 9215 bytes)
[2025-06-26T18:32:40.555+0700] {subprocess.py:93} INFO - 25/06/26 18:32:40 INFO Executor: Running task 23.0 in stage 0.0 (TID 23)
[2025-06-26T18:32:40.570+0700] {subprocess.py:93} INFO - 25/06/26 18:32:40 INFO TaskSetManager: Starting task 24.0 in stage 0.0 (TID 24) (localhost, executor driver, partition 24, PROCESS_LOCAL, 9215 bytes)
[2025-06-26T18:32:40.573+0700] {subprocess.py:93} INFO - 25/06/26 18:32:40 INFO Executor: Running task 24.0 in stage 0.0 (TID 24)
[2025-06-26T18:32:40.574+0700] {subprocess.py:93} INFO - 25/06/26 18:32:40 INFO TaskSetManager: Starting task 25.0 in stage 0.0 (TID 25) (localhost, executor driver, partition 25, PROCESS_LOCAL, 9215 bytes)
[2025-06-26T18:32:40.575+0700] {subprocess.py:93} INFO - 25/06/26 18:32:40 INFO Executor: Running task 25.0 in stage 0.0 (TID 25)
[2025-06-26T18:32:40.575+0700] {subprocess.py:93} INFO - 25/06/26 18:32:40 INFO TaskSetManager: Starting task 26.0 in stage 0.0 (TID 26) (localhost, executor driver, partition 26, PROCESS_LOCAL, 9215 bytes)
[2025-06-26T18:32:40.575+0700] {subprocess.py:93} INFO - 25/06/26 18:32:40 INFO Executor: Running task 26.0 in stage 0.0 (TID 26)
[2025-06-26T18:32:40.576+0700] {subprocess.py:93} INFO - 25/06/26 18:32:40 INFO TaskSetManager: Starting task 27.0 in stage 0.0 (TID 27) (localhost, executor driver, partition 27, PROCESS_LOCAL, 9215 bytes)
[2025-06-26T18:32:40.577+0700] {subprocess.py:93} INFO - 25/06/26 18:32:40 INFO Executor: Running task 27.0 in stage 0.0 (TID 27)
[2025-06-26T18:32:40.578+0700] {subprocess.py:93} INFO - 25/06/26 18:32:40 INFO TaskSetManager: Starting task 28.0 in stage 0.0 (TID 28) (localhost, executor driver, partition 28, PROCESS_LOCAL, 9215 bytes)
[2025-06-26T18:32:40.579+0700] {subprocess.py:93} INFO - 25/06/26 18:32:40 INFO Executor: Running task 28.0 in stage 0.0 (TID 28)
[2025-06-26T18:32:40.586+0700] {subprocess.py:93} INFO - 25/06/26 18:32:40 INFO TaskSetManager: Finished task 3.0 in stage 0.0 (TID 3) in 413 ms on localhost (executor driver) (1/149)
[2025-06-26T18:32:40.588+0700] {subprocess.py:93} INFO - 25/06/26 18:32:40 INFO TaskSetManager: Finished task 17.0 in stage 0.0 (TID 17) in 413 ms on localhost (executor driver) (2/149)
[2025-06-26T18:32:40.593+0700] {subprocess.py:93} INFO - 25/06/26 18:32:40 INFO TaskSetManager: Finished task 19.0 in stage 0.0 (TID 19) in 413 ms on localhost (executor driver) (3/149)
[2025-06-26T18:32:40.593+0700] {subprocess.py:93} INFO - 25/06/26 18:32:40 INFO TaskSetManager: Finished task 6.0 in stage 0.0 (TID 6) in 421 ms on localhost (executor driver) (4/149)
[2025-06-26T18:32:40.593+0700] {subprocess.py:93} INFO - 25/06/26 18:32:40 INFO TaskSetManager: Finished task 11.0 in stage 0.0 (TID 11) in 419 ms on localhost (executor driver) (5/149)
[2025-06-26T18:32:40.593+0700] {subprocess.py:93} INFO - 25/06/26 18:32:40 INFO TaskSetManager: Finished task 21.0 in stage 0.0 (TID 21) in 414 ms on localhost (executor driver) (6/149)
[2025-06-26T18:32:40.594+0700] {subprocess.py:93} INFO - 25/06/26 18:32:40 INFO TaskSetManager: Finished task 5.0 in stage 0.0 (TID 5) in 425 ms on localhost (executor driver) (7/149)
[2025-06-26T18:32:40.597+0700] {subprocess.py:93} INFO - 25/06/26 18:32:40 INFO TaskSetManager: Starting task 29.0 in stage 0.0 (TID 29) (localhost, executor driver, partition 29, PROCESS_LOCAL, 9215 bytes)
[2025-06-26T18:32:40.600+0700] {subprocess.py:93} INFO - 25/06/26 18:32:40 INFO TaskSetManager: Finished task 15.0 in stage 0.0 (TID 15) in 426 ms on localhost (executor driver) (8/149)
[2025-06-26T18:32:40.601+0700] {subprocess.py:93} INFO - 25/06/26 18:32:40 INFO Executor: Running task 29.0 in stage 0.0 (TID 29)
[2025-06-26T18:32:40.606+0700] {subprocess.py:93} INFO - 25/06/26 18:32:40 INFO TaskSetManager: Starting task 30.0 in stage 0.0 (TID 30) (localhost, executor driver, partition 30, PROCESS_LOCAL, 9215 bytes)
[2025-06-26T18:32:40.607+0700] {subprocess.py:93} INFO - 25/06/26 18:32:40 INFO Executor: Running task 30.0 in stage 0.0 (TID 30)
[2025-06-26T18:32:40.607+0700] {subprocess.py:93} INFO - 25/06/26 18:32:40 INFO TaskSetManager: Starting task 31.0 in stage 0.0 (TID 31) (localhost, executor driver, partition 31, PROCESS_LOCAL, 9215 bytes)
[2025-06-26T18:32:40.607+0700] {subprocess.py:93} INFO - 25/06/26 18:32:40 INFO Executor: Running task 31.0 in stage 0.0 (TID 31)
[2025-06-26T18:32:40.609+0700] {subprocess.py:93} INFO - 25/06/26 18:32:40 INFO Executor: Finished task 22.0 in stage 0.0 (TID 22). 3261 bytes result sent to driver
[2025-06-26T18:32:40.613+0700] {subprocess.py:93} INFO - 25/06/26 18:32:40 INFO TaskSetManager: Starting task 32.0 in stage 0.0 (TID 32) (localhost, executor driver, partition 32, PROCESS_LOCAL, 9215 bytes)
[2025-06-26T18:32:40.614+0700] {subprocess.py:93} INFO - 25/06/26 18:32:40 INFO Executor: Finished task 23.0 in stage 0.0 (TID 23). 3218 bytes result sent to driver
[2025-06-26T18:32:40.614+0700] {subprocess.py:93} INFO - 25/06/26 18:32:40 INFO TaskSetManager: Finished task 16.0 in stage 0.0 (TID 16) in 439 ms on localhost (executor driver) (9/149)
[2025-06-26T18:32:40.615+0700] {subprocess.py:93} INFO - 25/06/26 18:32:40 INFO Executor: Running task 32.0 in stage 0.0 (TID 32)
[2025-06-26T18:32:40.623+0700] {subprocess.py:93} INFO - 25/06/26 18:32:40 INFO TaskSetManager: Starting task 33.0 in stage 0.0 (TID 33) (localhost, executor driver, partition 33, PROCESS_LOCAL, 9215 bytes)
[2025-06-26T18:32:40.625+0700] {subprocess.py:93} INFO - 25/06/26 18:32:40 INFO Executor: Running task 33.0 in stage 0.0 (TID 33)
[2025-06-26T18:32:40.625+0700] {subprocess.py:93} INFO - 25/06/26 18:32:40 INFO TaskSetManager: Starting task 34.0 in stage 0.0 (TID 34) (localhost, executor driver, partition 34, PROCESS_LOCAL, 9215 bytes)
[2025-06-26T18:32:40.627+0700] {subprocess.py:93} INFO - 25/06/26 18:32:40 INFO TaskSetManager: Starting task 35.0 in stage 0.0 (TID 35) (localhost, executor driver, partition 35, PROCESS_LOCAL, 9215 bytes)
[2025-06-26T18:32:40.627+0700] {subprocess.py:93} INFO - 25/06/26 18:32:40 INFO TaskSetManager: Finished task 7.0 in stage 0.0 (TID 7) in 457 ms on localhost (executor driver) (10/149)
[2025-06-26T18:32:40.627+0700] {subprocess.py:93} INFO - 25/06/26 18:32:40 INFO Executor: Running task 35.0 in stage 0.0 (TID 35)
[2025-06-26T18:32:40.628+0700] {subprocess.py:93} INFO - 25/06/26 18:32:40 INFO TaskSetManager: Finished task 20.0 in stage 0.0 (TID 20) in 451 ms on localhost (executor driver) (11/149)
[2025-06-26T18:32:40.629+0700] {subprocess.py:93} INFO - 25/06/26 18:32:40 INFO TaskSetManager: Finished task 18.0 in stage 0.0 (TID 18) in 452 ms on localhost (executor driver) (12/149)
[2025-06-26T18:32:40.629+0700] {subprocess.py:93} INFO - 25/06/26 18:32:40 INFO TaskSetManager: Finished task 8.0 in stage 0.0 (TID 8) in 459 ms on localhost (executor driver) (13/149)
[2025-06-26T18:32:40.631+0700] {subprocess.py:93} INFO - 25/06/26 18:32:40 INFO TaskSetManager: Starting task 36.0 in stage 0.0 (TID 36) (localhost, executor driver, partition 36, PROCESS_LOCAL, 9215 bytes)
[2025-06-26T18:32:40.633+0700] {subprocess.py:93} INFO - 25/06/26 18:32:40 INFO TaskSetManager: Finished task 13.0 in stage 0.0 (TID 13) in 459 ms on localhost (executor driver) (14/149)
[2025-06-26T18:32:40.634+0700] {subprocess.py:93} INFO - 25/06/26 18:32:40 INFO Executor: Running task 34.0 in stage 0.0 (TID 34)
[2025-06-26T18:32:40.634+0700] {subprocess.py:93} INFO - 25/06/26 18:32:40 INFO Executor: Running task 36.0 in stage 0.0 (TID 36)
[2025-06-26T18:32:40.636+0700] {subprocess.py:93} INFO - 25/06/26 18:32:40 INFO TaskSetManager: Starting task 37.0 in stage 0.0 (TID 37) (localhost, executor driver, partition 37, PROCESS_LOCAL, 9215 bytes)
[2025-06-26T18:32:40.637+0700] {subprocess.py:93} INFO - 25/06/26 18:32:40 INFO TaskSetManager: Starting task 38.0 in stage 0.0 (TID 38) (localhost, executor driver, partition 38, PROCESS_LOCAL, 9215 bytes)
[2025-06-26T18:32:40.637+0700] {subprocess.py:93} INFO - 25/06/26 18:32:40 INFO Executor: Running task 37.0 in stage 0.0 (TID 37)
[2025-06-26T18:32:40.638+0700] {subprocess.py:93} INFO - 25/06/26 18:32:40 INFO Executor: Running task 38.0 in stage 0.0 (TID 38)
[2025-06-26T18:32:40.648+0700] {subprocess.py:93} INFO - 25/06/26 18:32:40 INFO Executor: Finished task 25.0 in stage 0.0 (TID 25). 3218 bytes result sent to driver
[2025-06-26T18:32:40.656+0700] {subprocess.py:93} INFO - 25/06/26 18:32:40 INFO TaskSetManager: Starting task 39.0 in stage 0.0 (TID 39) (localhost, executor driver, partition 39, PROCESS_LOCAL, 9215 bytes)
[2025-06-26T18:32:40.657+0700] {subprocess.py:93} INFO - 25/06/26 18:32:40 INFO Executor: Finished task 27.0 in stage 0.0 (TID 27). 3218 bytes result sent to driver
[2025-06-26T18:32:40.657+0700] {subprocess.py:93} INFO - 25/06/26 18:32:40 INFO TaskSetManager: Starting task 40.0 in stage 0.0 (TID 40) (localhost, executor driver, partition 40, PROCESS_LOCAL, 9215 bytes)
[2025-06-26T18:32:40.657+0700] {subprocess.py:93} INFO - 25/06/26 18:32:40 INFO Executor: Running task 39.0 in stage 0.0 (TID 39)
[2025-06-26T18:32:40.659+0700] {subprocess.py:93} INFO - 25/06/26 18:32:40 INFO TaskSetManager: Starting task 41.0 in stage 0.0 (TID 41) (localhost, executor driver, partition 41, PROCESS_LOCAL, 9215 bytes)
[2025-06-26T18:32:40.659+0700] {subprocess.py:93} INFO - 25/06/26 18:32:40 INFO Executor: Running task 40.0 in stage 0.0 (TID 40)
[2025-06-26T18:32:40.661+0700] {subprocess.py:93} INFO - 25/06/26 18:32:40 INFO Executor: Running task 41.0 in stage 0.0 (TID 41)
[2025-06-26T18:32:40.662+0700] {subprocess.py:93} INFO - 25/06/26 18:32:40 INFO Executor: Finished task 24.0 in stage 0.0 (TID 24). 3218 bytes result sent to driver
[2025-06-26T18:32:40.662+0700] {subprocess.py:93} INFO - 25/06/26 18:32:40 INFO Executor: Finished task 29.0 in stage 0.0 (TID 29). 3218 bytes result sent to driver
[2025-06-26T18:32:40.665+0700] {subprocess.py:93} INFO - 25/06/26 18:32:40 INFO TaskSetManager: Starting task 42.0 in stage 0.0 (TID 42) (localhost, executor driver, partition 42, PROCESS_LOCAL, 9215 bytes)
[2025-06-26T18:32:40.666+0700] {subprocess.py:93} INFO - 25/06/26 18:32:40 INFO Executor: Finished task 28.0 in stage 0.0 (TID 28). 3218 bytes result sent to driver
[2025-06-26T18:32:40.666+0700] {subprocess.py:93} INFO - 25/06/26 18:32:40 INFO TaskSetManager: Finished task 14.0 in stage 0.0 (TID 14) in 492 ms on localhost (executor driver) (15/149)
[2025-06-26T18:32:40.666+0700] {subprocess.py:93} INFO - 25/06/26 18:32:40 INFO Executor: Finished task 30.0 in stage 0.0 (TID 30). 3218 bytes result sent to driver
[2025-06-26T18:32:40.669+0700] {subprocess.py:93} INFO - 25/06/26 18:32:40 INFO TaskSetManager: Finished task 0.0 in stage 0.0 (TID 0) in 533 ms on localhost (executor driver) (16/149)
[2025-06-26T18:32:40.670+0700] {subprocess.py:93} INFO - 25/06/26 18:32:40 INFO TaskSetManager: Finished task 4.0 in stage 0.0 (TID 4) in 502 ms on localhost (executor driver) (17/149)
[2025-06-26T18:32:40.670+0700] {subprocess.py:93} INFO - 25/06/26 18:32:40 INFO TaskSetManager: Finished task 1.0 in stage 0.0 (TID 1) in 505 ms on localhost (executor driver) (18/149)
[2025-06-26T18:32:40.670+0700] {subprocess.py:93} INFO - 25/06/26 18:32:40 INFO Executor: Running task 42.0 in stage 0.0 (TID 42)
[2025-06-26T18:32:40.670+0700] {subprocess.py:93} INFO - 25/06/26 18:32:40 INFO Executor: Finished task 31.0 in stage 0.0 (TID 31). 3218 bytes result sent to driver
[2025-06-26T18:32:40.670+0700] {subprocess.py:93} INFO - 25/06/26 18:32:40 INFO TaskSetManager: Finished task 12.0 in stage 0.0 (TID 12) in 498 ms on localhost (executor driver) (19/149)
[2025-06-26T18:32:40.671+0700] {subprocess.py:93} INFO - 25/06/26 18:32:40 INFO Executor: Finished task 26.0 in stage 0.0 (TID 26). 3218 bytes result sent to driver
[2025-06-26T18:32:40.672+0700] {subprocess.py:93} INFO - 25/06/26 18:32:40 INFO TaskSetManager: Starting task 43.0 in stage 0.0 (TID 43) (localhost, executor driver, partition 43, PROCESS_LOCAL, 9215 bytes)
[2025-06-26T18:32:40.672+0700] {subprocess.py:93} INFO - 25/06/26 18:32:40 INFO TaskSetManager: Finished task 9.0 in stage 0.0 (TID 9) in 500 ms on localhost (executor driver) (20/149)
[2025-06-26T18:32:40.674+0700] {subprocess.py:93} INFO - 25/06/26 18:32:40 INFO Executor: Running task 43.0 in stage 0.0 (TID 43)
[2025-06-26T18:32:40.678+0700] {subprocess.py:93} INFO - 25/06/26 18:32:40 INFO TaskSetManager: Finished task 10.0 in stage 0.0 (TID 10) in 506 ms on localhost (executor driver) (21/149)
[2025-06-26T18:32:40.681+0700] {subprocess.py:93} INFO - 25/06/26 18:32:40 INFO TaskSetManager: Starting task 44.0 in stage 0.0 (TID 44) (localhost, executor driver, partition 44, PROCESS_LOCAL, 9215 bytes)
[2025-06-26T18:32:40.681+0700] {subprocess.py:93} INFO - 25/06/26 18:32:40 INFO Executor: Finished task 35.0 in stage 0.0 (TID 35). 3218 bytes result sent to driver
[2025-06-26T18:32:40.682+0700] {subprocess.py:93} INFO - 25/06/26 18:32:40 INFO TaskSetManager: Starting task 45.0 in stage 0.0 (TID 45) (localhost, executor driver, partition 45, PROCESS_LOCAL, 9215 bytes)
[2025-06-26T18:32:40.683+0700] {subprocess.py:93} INFO - 25/06/26 18:32:40 INFO Executor: Finished task 32.0 in stage 0.0 (TID 32). 3218 bytes result sent to driver
[2025-06-26T18:32:40.683+0700] {subprocess.py:93} INFO - 25/06/26 18:32:40 INFO Executor: Running task 44.0 in stage 0.0 (TID 44)
[2025-06-26T18:32:40.684+0700] {subprocess.py:93} INFO - 25/06/26 18:32:40 INFO TaskSetManager: Starting task 46.0 in stage 0.0 (TID 46) (localhost, executor driver, partition 46, PROCESS_LOCAL, 9215 bytes)
[2025-06-26T18:32:40.684+0700] {subprocess.py:93} INFO - 25/06/26 18:32:40 INFO TaskSetManager: Finished task 2.0 in stage 0.0 (TID 2) in 518 ms on localhost (executor driver) (22/149)
[2025-06-26T18:32:40.684+0700] {subprocess.py:93} INFO - 25/06/26 18:32:40 INFO TaskSetManager: Finished task 25.0 in stage 0.0 (TID 25) in 111 ms on localhost (executor driver) (23/149)
[2025-06-26T18:32:40.686+0700] {subprocess.py:93} INFO - 25/06/26 18:32:40 INFO TaskSetManager: Finished task 22.0 in stage 0.0 (TID 22) in 136 ms on localhost (executor driver) (24/149)
[2025-06-26T18:32:40.686+0700] {subprocess.py:93} INFO - 25/06/26 18:32:40 INFO Executor: Running task 45.0 in stage 0.0 (TID 45)
[2025-06-26T18:32:40.686+0700] {subprocess.py:93} INFO - 25/06/26 18:32:40 INFO TaskSetManager: Finished task 23.0 in stage 0.0 (TID 23) in 131 ms on localhost (executor driver) (25/149)
[2025-06-26T18:32:40.686+0700] {subprocess.py:93} INFO - 25/06/26 18:32:40 INFO TaskSetManager: Finished task 27.0 in stage 0.0 (TID 27) in 111 ms on localhost (executor driver) (26/149)
[2025-06-26T18:32:40.687+0700] {subprocess.py:93} INFO - 25/06/26 18:32:40 INFO Executor: Running task 46.0 in stage 0.0 (TID 46)
[2025-06-26T18:32:40.689+0700] {subprocess.py:93} INFO - 25/06/26 18:32:40 INFO TaskSetManager: Starting task 47.0 in stage 0.0 (TID 47) (localhost, executor driver, partition 47, PROCESS_LOCAL, 9215 bytes)
[2025-06-26T18:32:40.694+0700] {subprocess.py:93} INFO - 25/06/26 18:32:40 INFO Executor: Running task 47.0 in stage 0.0 (TID 47)
[2025-06-26T18:32:40.695+0700] {subprocess.py:93} INFO - 25/06/26 18:32:40 INFO Executor: Finished task 36.0 in stage 0.0 (TID 36). 3218 bytes result sent to driver
[2025-06-26T18:32:40.695+0700] {subprocess.py:93} INFO - 25/06/26 18:32:40 INFO TaskSetManager: Starting task 48.0 in stage 0.0 (TID 48) (localhost, executor driver, partition 48, PROCESS_LOCAL, 9215 bytes)
[2025-06-26T18:32:40.695+0700] {subprocess.py:93} INFO - 25/06/26 18:32:40 INFO Executor: Running task 48.0 in stage 0.0 (TID 48)
[2025-06-26T18:32:40.706+0700] {subprocess.py:93} INFO - 25/06/26 18:32:40 INFO Executor: Finished task 37.0 in stage 0.0 (TID 37). 3218 bytes result sent to driver
[2025-06-26T18:32:40.706+0700] {subprocess.py:93} INFO - 25/06/26 18:32:40 INFO TaskSetManager: Finished task 24.0 in stage 0.0 (TID 24) in 135 ms on localhost (executor driver) (27/149)
[2025-06-26T18:32:40.706+0700] {subprocess.py:93} INFO - 25/06/26 18:32:40 INFO TaskSetManager: Finished task 29.0 in stage 0.0 (TID 29) in 109 ms on localhost (executor driver) (28/149)
[2025-06-26T18:32:40.706+0700] {subprocess.py:93} INFO - 25/06/26 18:32:40 INFO TaskSetManager: Starting task 49.0 in stage 0.0 (TID 49) (localhost, executor driver, partition 49, PROCESS_LOCAL, 9215 bytes)
[2025-06-26T18:32:40.707+0700] {subprocess.py:93} INFO - 25/06/26 18:32:40 INFO Executor: Finished task 33.0 in stage 0.0 (TID 33). 3175 bytes result sent to driver
[2025-06-26T18:32:40.708+0700] {subprocess.py:93} INFO - 25/06/26 18:32:40 INFO Executor: Running task 49.0 in stage 0.0 (TID 49)
[2025-06-26T18:32:40.710+0700] {subprocess.py:93} INFO - 25/06/26 18:32:40 INFO Executor: Finished task 39.0 in stage 0.0 (TID 39). 3218 bytes result sent to driver
[2025-06-26T18:32:40.713+0700] {subprocess.py:93} INFO - 25/06/26 18:32:40 INFO TaskSetManager: Starting task 50.0 in stage 0.0 (TID 50) (localhost, executor driver, partition 50, PROCESS_LOCAL, 9215 bytes)
[2025-06-26T18:32:40.715+0700] {subprocess.py:93} INFO - 25/06/26 18:32:40 INFO Executor: Running task 50.0 in stage 0.0 (TID 50)
[2025-06-26T18:32:40.715+0700] {subprocess.py:93} INFO - 25/06/26 18:32:40 INFO Executor: Finished task 41.0 in stage 0.0 (TID 41). 3218 bytes result sent to driver
[2025-06-26T18:32:40.717+0700] {subprocess.py:93} INFO - 25/06/26 18:32:40 INFO TaskSetManager: Starting task 51.0 in stage 0.0 (TID 51) (localhost, executor driver, partition 51, PROCESS_LOCAL, 9215 bytes)
[2025-06-26T18:32:40.717+0700] {subprocess.py:93} INFO - 25/06/26 18:32:40 INFO Executor: Finished task 43.0 in stage 0.0 (TID 43). 3218 bytes result sent to driver
[2025-06-26T18:32:40.717+0700] {subprocess.py:93} INFO - 25/06/26 18:32:40 INFO Executor: Finished task 38.0 in stage 0.0 (TID 38). 3175 bytes result sent to driver
[2025-06-26T18:32:40.719+0700] {subprocess.py:93} INFO - 25/06/26 18:32:40 INFO TaskSetManager: Finished task 28.0 in stage 0.0 (TID 28) in 142 ms on localhost (executor driver) (29/149)
[2025-06-26T18:32:40.720+0700] {subprocess.py:93} INFO - 25/06/26 18:32:40 INFO TaskSetManager: Finished task 31.0 in stage 0.0 (TID 31) in 117 ms on localhost (executor driver) (30/149)
[2025-06-26T18:32:40.720+0700] {subprocess.py:93} INFO - 25/06/26 18:32:40 INFO Executor: Running task 51.0 in stage 0.0 (TID 51)
[2025-06-26T18:32:40.723+0700] {subprocess.py:93} INFO - 25/06/26 18:32:40 INFO TaskSetManager: Starting task 52.0 in stage 0.0 (TID 52) (localhost, executor driver, partition 52, PROCESS_LOCAL, 9215 bytes)
[2025-06-26T18:32:40.727+0700] {subprocess.py:93} INFO - 25/06/26 18:32:40 INFO Executor: Finished task 42.0 in stage 0.0 (TID 42). 3218 bytes result sent to driver
[2025-06-26T18:32:40.727+0700] {subprocess.py:93} INFO - 25/06/26 18:32:40 INFO TaskSetManager: Finished task 30.0 in stage 0.0 (TID 30) in 123 ms on localhost (executor driver) (31/149)
[2025-06-26T18:32:40.727+0700] {subprocess.py:93} INFO - 25/06/26 18:32:40 INFO Executor: Running task 52.0 in stage 0.0 (TID 52)
[2025-06-26T18:32:40.727+0700] {subprocess.py:93} INFO - 25/06/26 18:32:40 INFO Executor: Finished task 47.0 in stage 0.0 (TID 47). 3218 bytes result sent to driver
[2025-06-26T18:32:40.727+0700] {subprocess.py:93} INFO - 25/06/26 18:32:40 INFO Executor: Finished task 40.0 in stage 0.0 (TID 40). 3218 bytes result sent to driver
[2025-06-26T18:32:40.728+0700] {subprocess.py:93} INFO - 25/06/26 18:32:40 INFO Executor: Finished task 45.0 in stage 0.0 (TID 45). 3218 bytes result sent to driver
[2025-06-26T18:32:40.728+0700] {subprocess.py:93} INFO - 25/06/26 18:32:40 INFO TaskSetManager: Starting task 53.0 in stage 0.0 (TID 53) (localhost, executor driver, partition 53, PROCESS_LOCAL, 9215 bytes)
[2025-06-26T18:32:40.728+0700] {subprocess.py:93} INFO - 25/06/26 18:32:40 INFO Executor: Finished task 48.0 in stage 0.0 (TID 48). 3218 bytes result sent to driver
[2025-06-26T18:32:40.729+0700] {subprocess.py:93} INFO - 25/06/26 18:32:40 INFO Executor: Finished task 49.0 in stage 0.0 (TID 49). 3175 bytes result sent to driver
[2025-06-26T18:32:40.729+0700] {subprocess.py:93} INFO - 25/06/26 18:32:40 INFO TaskSetManager: Starting task 54.0 in stage 0.0 (TID 54) (localhost, executor driver, partition 54, PROCESS_LOCAL, 9215 bytes)
[2025-06-26T18:32:40.729+0700] {subprocess.py:93} INFO - 25/06/26 18:32:40 INFO Executor: Finished task 46.0 in stage 0.0 (TID 46). 3218 bytes result sent to driver
[2025-06-26T18:32:40.730+0700] {subprocess.py:93} INFO - 25/06/26 18:32:40 INFO Executor: Running task 54.0 in stage 0.0 (TID 54)
[2025-06-26T18:32:40.731+0700] {subprocess.py:93} INFO - 25/06/26 18:32:40 INFO Executor: Finished task 34.0 in stage 0.0 (TID 34). 3218 bytes result sent to driver
[2025-06-26T18:32:40.731+0700] {subprocess.py:93} INFO - 25/06/26 18:32:40 INFO Executor: Finished task 44.0 in stage 0.0 (TID 44). 3175 bytes result sent to driver
[2025-06-26T18:32:40.732+0700] {subprocess.py:93} INFO - 25/06/26 18:32:40 INFO Executor: Running task 53.0 in stage 0.0 (TID 53)
[2025-06-26T18:32:40.733+0700] {subprocess.py:93} INFO - 25/06/26 18:32:40 INFO TaskSetManager: Starting task 55.0 in stage 0.0 (TID 55) (localhost, executor driver, partition 55, PROCESS_LOCAL, 9215 bytes)
[2025-06-26T18:32:40.734+0700] {subprocess.py:93} INFO - 25/06/26 18:32:40 INFO Executor: Finished task 51.0 in stage 0.0 (TID 51). 3175 bytes result sent to driver
[2025-06-26T18:32:40.735+0700] {subprocess.py:93} INFO - 25/06/26 18:32:40 INFO Executor: Running task 55.0 in stage 0.0 (TID 55)
[2025-06-26T18:32:40.736+0700] {subprocess.py:93} INFO - 25/06/26 18:32:40 INFO TaskSetManager: Starting task 56.0 in stage 0.0 (TID 56) (localhost, executor driver, partition 56, PROCESS_LOCAL, 9215 bytes)
[2025-06-26T18:32:40.736+0700] {subprocess.py:93} INFO - 25/06/26 18:32:40 INFO Executor: Finished task 50.0 in stage 0.0 (TID 50). 3175 bytes result sent to driver
[2025-06-26T18:32:40.737+0700] {subprocess.py:93} INFO - 25/06/26 18:32:40 INFO Executor: Running task 56.0 in stage 0.0 (TID 56)
[2025-06-26T18:32:40.738+0700] {subprocess.py:93} INFO - 25/06/26 18:32:40 INFO TaskSetManager: Starting task 57.0 in stage 0.0 (TID 57) (localhost, executor driver, partition 57, PROCESS_LOCAL, 9215 bytes)
[2025-06-26T18:32:40.739+0700] {subprocess.py:93} INFO - 25/06/26 18:32:40 INFO TaskSetManager: Finished task 35.0 in stage 0.0 (TID 35) in 113 ms on localhost (executor driver) (32/149)
[2025-06-26T18:32:40.739+0700] {subprocess.py:93} INFO - 25/06/26 18:32:40 INFO Executor: Running task 57.0 in stage 0.0 (TID 57)
[2025-06-26T18:32:40.740+0700] {subprocess.py:93} INFO - 25/06/26 18:32:40 INFO TaskSetManager: Finished task 32.0 in stage 0.0 (TID 32) in 128 ms on localhost (executor driver) (33/149)
[2025-06-26T18:32:40.741+0700] {subprocess.py:93} INFO - 25/06/26 18:32:40 INFO TaskSetManager: Finished task 36.0 in stage 0.0 (TID 36) in 109 ms on localhost (executor driver) (34/149)
[2025-06-26T18:32:40.744+0700] {subprocess.py:93} INFO - 25/06/26 18:32:40 INFO TaskSetManager: Starting task 58.0 in stage 0.0 (TID 58) (localhost, executor driver, partition 58, PROCESS_LOCAL, 9215 bytes)
[2025-06-26T18:32:40.746+0700] {subprocess.py:93} INFO - 25/06/26 18:32:40 INFO Executor: Running task 58.0 in stage 0.0 (TID 58)
[2025-06-26T18:32:40.746+0700] {subprocess.py:93} INFO - 25/06/26 18:32:40 INFO Executor: Finished task 52.0 in stage 0.0 (TID 52). 3175 bytes result sent to driver
[2025-06-26T18:32:40.747+0700] {subprocess.py:93} INFO - 25/06/26 18:32:40 INFO TaskSetManager: Starting task 59.0 in stage 0.0 (TID 59) (localhost, executor driver, partition 59, PROCESS_LOCAL, 9215 bytes)
[2025-06-26T18:32:40.748+0700] {subprocess.py:93} INFO - 25/06/26 18:32:40 INFO Executor: Finished task 54.0 in stage 0.0 (TID 54). 3218 bytes result sent to driver
[2025-06-26T18:32:40.748+0700] {subprocess.py:93} INFO - 25/06/26 18:32:40 INFO Executor: Running task 59.0 in stage 0.0 (TID 59)
[2025-06-26T18:32:40.752+0700] {subprocess.py:93} INFO - 25/06/26 18:32:40 INFO TaskSetManager: Starting task 60.0 in stage 0.0 (TID 60) (localhost, executor driver, partition 60, PROCESS_LOCAL, 9215 bytes)
[2025-06-26T18:32:40.753+0700] {subprocess.py:93} INFO - 25/06/26 18:32:40 INFO Executor: Finished task 53.0 in stage 0.0 (TID 53). 3218 bytes result sent to driver
[2025-06-26T18:32:40.754+0700] {subprocess.py:93} INFO - 25/06/26 18:32:40 INFO Executor: Finished task 55.0 in stage 0.0 (TID 55). 3175 bytes result sent to driver
[2025-06-26T18:32:40.754+0700] {subprocess.py:93} INFO - 25/06/26 18:32:40 INFO TaskSetManager: Starting task 61.0 in stage 0.0 (TID 61) (localhost, executor driver, partition 61, PROCESS_LOCAL, 9215 bytes)
[2025-06-26T18:32:40.755+0700] {subprocess.py:93} INFO - 25/06/26 18:32:40 INFO Executor: Running task 60.0 in stage 0.0 (TID 60)
[2025-06-26T18:32:40.755+0700] {subprocess.py:93} INFO - 25/06/26 18:32:40 INFO TaskSetManager: Finished task 26.0 in stage 0.0 (TID 26) in 180 ms on localhost (executor driver) (35/149)
[2025-06-26T18:32:40.755+0700] {subprocess.py:93} INFO - 25/06/26 18:32:40 INFO Executor: Running task 61.0 in stage 0.0 (TID 61)
[2025-06-26T18:32:40.755+0700] {subprocess.py:93} INFO - 25/06/26 18:32:40 INFO TaskSetManager: Finished task 39.0 in stage 0.0 (TID 39) in 102 ms on localhost (executor driver) (36/149)
[2025-06-26T18:32:40.756+0700] {subprocess.py:93} INFO - 25/06/26 18:32:40 INFO Executor: Finished task 56.0 in stage 0.0 (TID 56). 3175 bytes result sent to driver
[2025-06-26T18:32:40.756+0700] {subprocess.py:93} INFO - 25/06/26 18:32:40 INFO TaskSetManager: Finished task 33.0 in stage 0.0 (TID 33) in 134 ms on localhost (executor driver) (37/149)
[2025-06-26T18:32:40.756+0700] {subprocess.py:93} INFO - 25/06/26 18:32:40 INFO TaskSetManager: Finished task 37.0 in stage 0.0 (TID 37) in 121 ms on localhost (executor driver) (38/149)
[2025-06-26T18:32:40.757+0700] {subprocess.py:93} INFO - 25/06/26 18:32:40 INFO TaskSetManager: Finished task 43.0 in stage 0.0 (TID 43) in 85 ms on localhost (executor driver) (39/149)
[2025-06-26T18:32:40.758+0700] {subprocess.py:93} INFO - 25/06/26 18:32:40 INFO TaskSetManager: Finished task 41.0 in stage 0.0 (TID 41) in 99 ms on localhost (executor driver) (40/149)
[2025-06-26T18:32:40.760+0700] {subprocess.py:93} INFO - 25/06/26 18:32:40 INFO TaskSetManager: Starting task 62.0 in stage 0.0 (TID 62) (localhost, executor driver, partition 62, PROCESS_LOCAL, 9215 bytes)
[2025-06-26T18:32:40.762+0700] {subprocess.py:93} INFO - 25/06/26 18:32:40 INFO TaskSetManager: Starting task 63.0 in stage 0.0 (TID 63) (localhost, executor driver, partition 63, PROCESS_LOCAL, 9215 bytes)
[2025-06-26T18:32:40.762+0700] {subprocess.py:93} INFO - 25/06/26 18:32:40 INFO Executor: Running task 62.0 in stage 0.0 (TID 62)
[2025-06-26T18:32:40.766+0700] {subprocess.py:93} INFO - 25/06/26 18:32:40 INFO Executor: Running task 63.0 in stage 0.0 (TID 63)
[2025-06-26T18:32:40.766+0700] {subprocess.py:93} INFO - 25/06/26 18:32:40 INFO TaskSetManager: Starting task 64.0 in stage 0.0 (TID 64) (localhost, executor driver, partition 64, PROCESS_LOCAL, 9215 bytes)
[2025-06-26T18:32:40.767+0700] {subprocess.py:93} INFO - 25/06/26 18:32:40 INFO Executor: Finished task 57.0 in stage 0.0 (TID 57). 3175 bytes result sent to driver
[2025-06-26T18:32:40.767+0700] {subprocess.py:93} INFO - 25/06/26 18:32:40 INFO TaskSetManager: Finished task 38.0 in stage 0.0 (TID 38) in 128 ms on localhost (executor driver) (41/149)
[2025-06-26T18:32:40.767+0700] {subprocess.py:93} INFO - 25/06/26 18:32:40 INFO Executor: Running task 64.0 in stage 0.0 (TID 64)
[2025-06-26T18:32:40.768+0700] {subprocess.py:93} INFO - 25/06/26 18:32:40 INFO TaskSetManager: Starting task 65.0 in stage 0.0 (TID 65) (localhost, executor driver, partition 65, PROCESS_LOCAL, 9215 bytes)
[2025-06-26T18:32:40.768+0700] {subprocess.py:93} INFO - 25/06/26 18:32:40 INFO TaskSetManager: Finished task 42.0 in stage 0.0 (TID 42) in 106 ms on localhost (executor driver) (42/149)
[2025-06-26T18:32:40.768+0700] {subprocess.py:93} INFO - 25/06/26 18:32:40 INFO Executor: Running task 65.0 in stage 0.0 (TID 65)
[2025-06-26T18:32:40.768+0700] {subprocess.py:93} INFO - 25/06/26 18:32:40 INFO TaskSetManager: Starting task 66.0 in stage 0.0 (TID 66) (localhost, executor driver, partition 66, PROCESS_LOCAL, 9215 bytes)
[2025-06-26T18:32:40.768+0700] {subprocess.py:93} INFO - 25/06/26 18:32:40 INFO TaskSetManager: Finished task 47.0 in stage 0.0 (TID 47) in 80 ms on localhost (executor driver) (43/149)
[2025-06-26T18:32:40.768+0700] {subprocess.py:93} INFO - 25/06/26 18:32:40 INFO Executor: Running task 66.0 in stage 0.0 (TID 66)
[2025-06-26T18:32:40.768+0700] {subprocess.py:93} INFO - 25/06/26 18:32:40 INFO TaskSetManager: Finished task 40.0 in stage 0.0 (TID 40) in 112 ms on localhost (executor driver) (44/149)
[2025-06-26T18:32:40.779+0700] {subprocess.py:93} INFO - 25/06/26 18:32:40 INFO TaskSetManager: Starting task 67.0 in stage 0.0 (TID 67) (localhost, executor driver, partition 67, PROCESS_LOCAL, 9215 bytes)
[2025-06-26T18:32:40.780+0700] {subprocess.py:93} INFO - 25/06/26 18:32:40 INFO Executor: Finished task 58.0 in stage 0.0 (TID 58). 3218 bytes result sent to driver
[2025-06-26T18:32:40.780+0700] {subprocess.py:93} INFO - 25/06/26 18:32:40 INFO TaskSetManager: Finished task 45.0 in stage 0.0 (TID 45) in 100 ms on localhost (executor driver) (45/149)
[2025-06-26T18:32:40.782+0700] {subprocess.py:93} INFO - 25/06/26 18:32:40 INFO Executor: Running task 67.0 in stage 0.0 (TID 67)
[2025-06-26T18:32:40.785+0700] {subprocess.py:93} INFO - 25/06/26 18:32:40 INFO TaskSetManager: Starting task 68.0 in stage 0.0 (TID 68) (localhost, executor driver, partition 68, PROCESS_LOCAL, 9215 bytes)
[2025-06-26T18:32:40.787+0700] {subprocess.py:93} INFO - 25/06/26 18:32:40 INFO Executor: Finished task 60.0 in stage 0.0 (TID 60). 3218 bytes result sent to driver
[2025-06-26T18:32:40.787+0700] {subprocess.py:93} INFO - 25/06/26 18:32:40 INFO Executor: Finished task 59.0 in stage 0.0 (TID 59). 3218 bytes result sent to driver
[2025-06-26T18:32:40.790+0700] {subprocess.py:93} INFO - 25/06/26 18:32:40 INFO Executor: Finished task 61.0 in stage 0.0 (TID 61). 3218 bytes result sent to driver
[2025-06-26T18:32:40.791+0700] {subprocess.py:93} INFO - 25/06/26 18:32:40 INFO Executor: Finished task 64.0 in stage 0.0 (TID 64). 3218 bytes result sent to driver
[2025-06-26T18:32:40.791+0700] {subprocess.py:93} INFO - 25/06/26 18:32:40 INFO TaskSetManager: Starting task 69.0 in stage 0.0 (TID 69) (localhost, executor driver, partition 69, PROCESS_LOCAL, 9215 bytes)
[2025-06-26T18:32:40.793+0700] {subprocess.py:93} INFO - 25/06/26 18:32:40 INFO Executor: Running task 69.0 in stage 0.0 (TID 69)
[2025-06-26T18:32:40.793+0700] {subprocess.py:93} INFO - 25/06/26 18:32:40 INFO Executor: Running task 68.0 in stage 0.0 (TID 68)
[2025-06-26T18:32:40.796+0700] {subprocess.py:93} INFO - 25/06/26 18:32:40 INFO TaskSetManager: Starting task 70.0 in stage 0.0 (TID 70) (localhost, executor driver, partition 70, PROCESS_LOCAL, 9215 bytes)
[2025-06-26T18:32:40.796+0700] {subprocess.py:93} INFO - 25/06/26 18:32:40 INFO TaskSetManager: Finished task 49.0 in stage 0.0 (TID 49) in 89 ms on localhost (executor driver) (46/149)
[2025-06-26T18:32:40.796+0700] {subprocess.py:93} INFO - 25/06/26 18:32:40 INFO Executor: Running task 70.0 in stage 0.0 (TID 70)
[2025-06-26T18:32:40.797+0700] {subprocess.py:93} INFO - 25/06/26 18:32:40 INFO Executor: Finished task 66.0 in stage 0.0 (TID 66). 3218 bytes result sent to driver
[2025-06-26T18:32:40.797+0700] {subprocess.py:93} INFO - 25/06/26 18:32:40 INFO TaskSetManager: Starting task 71.0 in stage 0.0 (TID 71) (localhost, executor driver, partition 71, PROCESS_LOCAL, 9215 bytes)
[2025-06-26T18:32:40.797+0700] {subprocess.py:93} INFO - 25/06/26 18:32:40 INFO Executor: Finished task 65.0 in stage 0.0 (TID 65). 3218 bytes result sent to driver
[2025-06-26T18:32:40.797+0700] {subprocess.py:93} INFO - 25/06/26 18:32:40 INFO Executor: Finished task 62.0 in stage 0.0 (TID 62). 3218 bytes result sent to driver
[2025-06-26T18:32:40.798+0700] {subprocess.py:93} INFO - 25/06/26 18:32:40 INFO Executor: Running task 71.0 in stage 0.0 (TID 71)
[2025-06-26T18:32:40.798+0700] {subprocess.py:93} INFO - 25/06/26 18:32:40 INFO TaskSetManager: Starting task 72.0 in stage 0.0 (TID 72) (localhost, executor driver, partition 72, PROCESS_LOCAL, 9215 bytes)
[2025-06-26T18:32:40.799+0700] {subprocess.py:93} INFO - 25/06/26 18:32:40 INFO TaskSetManager: Finished task 34.0 in stage 0.0 (TID 34) in 175 ms on localhost (executor driver) (47/149)
[2025-06-26T18:32:40.800+0700] {subprocess.py:93} INFO - 25/06/26 18:32:40 INFO TaskSetManager: Finished task 44.0 in stage 0.0 (TID 44) in 120 ms on localhost (executor driver) (48/149)
[2025-06-26T18:32:40.800+0700] {subprocess.py:93} INFO - 25/06/26 18:32:40 INFO Executor: Finished task 63.0 in stage 0.0 (TID 63). 3218 bytes result sent to driver
[2025-06-26T18:32:40.800+0700] {subprocess.py:93} INFO - 25/06/26 18:32:40 INFO Executor: Running task 72.0 in stage 0.0 (TID 72)
[2025-06-26T18:32:40.800+0700] {subprocess.py:93} INFO - 25/06/26 18:32:40 INFO TaskSetManager: Finished task 48.0 in stage 0.0 (TID 48) in 107 ms on localhost (executor driver) (49/149)
[2025-06-26T18:32:40.801+0700] {subprocess.py:93} INFO - 25/06/26 18:32:40 INFO TaskSetManager: Finished task 46.0 in stage 0.0 (TID 46) in 117 ms on localhost (executor driver) (50/149)
[2025-06-26T18:32:40.801+0700] {subprocess.py:93} INFO - 25/06/26 18:32:40 INFO TaskSetManager: Finished task 51.0 in stage 0.0 (TID 51) in 86 ms on localhost (executor driver) (51/149)
[2025-06-26T18:32:40.803+0700] {subprocess.py:93} INFO - 25/06/26 18:32:40 INFO TaskSetManager: Starting task 73.0 in stage 0.0 (TID 73) (localhost, executor driver, partition 73, PROCESS_LOCAL, 9215 bytes)
[2025-06-26T18:32:40.804+0700] {subprocess.py:93} INFO - 25/06/26 18:32:40 INFO Executor: Finished task 67.0 in stage 0.0 (TID 67). 3175 bytes result sent to driver
[2025-06-26T18:32:40.805+0700] {subprocess.py:93} INFO - 25/06/26 18:32:40 INFO Executor: Running task 73.0 in stage 0.0 (TID 73)
[2025-06-26T18:32:40.805+0700] {subprocess.py:93} INFO - 25/06/26 18:32:40 INFO TaskSetManager: Starting task 74.0 in stage 0.0 (TID 74) (localhost, executor driver, partition 74, PROCESS_LOCAL, 9215 bytes)
[2025-06-26T18:32:40.806+0700] {subprocess.py:93} INFO - 25/06/26 18:32:40 INFO Executor: Running task 74.0 in stage 0.0 (TID 74)
[2025-06-26T18:32:40.806+0700] {subprocess.py:93} INFO - 25/06/26 18:32:40 INFO TaskSetManager: Starting task 75.0 in stage 0.0 (TID 75) (localhost, executor driver, partition 75, PROCESS_LOCAL, 9215 bytes)
[2025-06-26T18:32:40.807+0700] {subprocess.py:93} INFO - 25/06/26 18:32:40 INFO Executor: Running task 75.0 in stage 0.0 (TID 75)
[2025-06-26T18:32:40.808+0700] {subprocess.py:93} INFO - 25/06/26 18:32:40 INFO TaskSetManager: Starting task 76.0 in stage 0.0 (TID 76) (localhost, executor driver, partition 76, PROCESS_LOCAL, 9215 bytes)
[2025-06-26T18:32:40.808+0700] {subprocess.py:93} INFO - 25/06/26 18:32:40 INFO Executor: Running task 76.0 in stage 0.0 (TID 76)
[2025-06-26T18:32:40.809+0700] {subprocess.py:93} INFO - 25/06/26 18:32:40 INFO TaskSetManager: Starting task 77.0 in stage 0.0 (TID 77) (localhost, executor driver, partition 77, PROCESS_LOCAL, 9215 bytes)
[2025-06-26T18:32:40.809+0700] {subprocess.py:93} INFO - 25/06/26 18:32:40 INFO TaskSetManager: Finished task 50.0 in stage 0.0 (TID 50) in 97 ms on localhost (executor driver) (52/149)
[2025-06-26T18:32:40.809+0700] {subprocess.py:93} INFO - 25/06/26 18:32:40 INFO Executor: Finished task 68.0 in stage 0.0 (TID 68). 3175 bytes result sent to driver
[2025-06-26T18:32:40.810+0700] {subprocess.py:93} INFO - 25/06/26 18:32:40 INFO Executor: Running task 77.0 in stage 0.0 (TID 77)
[2025-06-26T18:32:40.810+0700] {subprocess.py:93} INFO - 25/06/26 18:32:40 INFO TaskSetManager: Finished task 56.0 in stage 0.0 (TID 56) in 75 ms on localhost (executor driver) (53/149)
[2025-06-26T18:32:40.815+0700] {subprocess.py:93} INFO - 25/06/26 18:32:40 INFO TaskSetManager: Starting task 78.0 in stage 0.0 (TID 78) (localhost, executor driver, partition 78, PROCESS_LOCAL, 9215 bytes)
[2025-06-26T18:32:40.818+0700] {subprocess.py:93} INFO - 25/06/26 18:32:40 INFO Executor: Running task 78.0 in stage 0.0 (TID 78)
[2025-06-26T18:32:40.819+0700] {subprocess.py:93} INFO - 25/06/26 18:32:40 INFO TaskSetManager: Finished task 54.0 in stage 0.0 (TID 54) in 88 ms on localhost (executor driver) (54/149)
[2025-06-26T18:32:40.819+0700] {subprocess.py:93} INFO - 25/06/26 18:32:40 INFO Executor: Finished task 70.0 in stage 0.0 (TID 70). 3175 bytes result sent to driver
[2025-06-26T18:32:40.819+0700] {subprocess.py:93} INFO - 25/06/26 18:32:40 INFO Executor: Finished task 73.0 in stage 0.0 (TID 73). 3175 bytes result sent to driver
[2025-06-26T18:32:40.819+0700] {subprocess.py:93} INFO - 25/06/26 18:32:40 INFO Executor: Finished task 71.0 in stage 0.0 (TID 71). 3175 bytes result sent to driver
[2025-06-26T18:32:40.819+0700] {subprocess.py:93} INFO - 25/06/26 18:32:40 INFO TaskSetManager: Finished task 57.0 in stage 0.0 (TID 57) in 80 ms on localhost (executor driver) (55/149)
[2025-06-26T18:32:40.819+0700] {subprocess.py:93} INFO - 25/06/26 18:32:40 INFO Executor: Finished task 74.0 in stage 0.0 (TID 74). 3175 bytes result sent to driver
[2025-06-26T18:32:40.820+0700] {subprocess.py:93} INFO - 25/06/26 18:32:40 INFO Executor: Finished task 72.0 in stage 0.0 (TID 72). 3175 bytes result sent to driver
[2025-06-26T18:32:40.820+0700] {subprocess.py:93} INFO - 25/06/26 18:32:40 INFO Executor: Finished task 69.0 in stage 0.0 (TID 69). 3175 bytes result sent to driver
[2025-06-26T18:32:40.820+0700] {subprocess.py:93} INFO - 25/06/26 18:32:40 INFO TaskSetManager: Starting task 79.0 in stage 0.0 (TID 79) (localhost, executor driver, partition 79, PROCESS_LOCAL, 9215 bytes)
[2025-06-26T18:32:40.820+0700] {subprocess.py:93} INFO - 25/06/26 18:32:40 INFO Executor: Finished task 76.0 in stage 0.0 (TID 76). 3175 bytes result sent to driver
[2025-06-26T18:32:40.820+0700] {subprocess.py:93} INFO - 25/06/26 18:32:40 INFO Executor: Finished task 75.0 in stage 0.0 (TID 75). 3175 bytes result sent to driver
[2025-06-26T18:32:40.820+0700] {subprocess.py:93} INFO - 25/06/26 18:32:40 INFO TaskSetManager: Finished task 52.0 in stage 0.0 (TID 52) in 97 ms on localhost (executor driver) (56/149)
[2025-06-26T18:32:40.820+0700] {subprocess.py:93} INFO - 25/06/26 18:32:40 INFO Executor: Running task 79.0 in stage 0.0 (TID 79)
[2025-06-26T18:32:40.820+0700] {subprocess.py:93} INFO - 25/06/26 18:32:40 INFO TaskSetManager: Starting task 80.0 in stage 0.0 (TID 80) (localhost, executor driver, partition 80, PROCESS_LOCAL, 9215 bytes)
[2025-06-26T18:32:40.821+0700] {subprocess.py:93} INFO - 25/06/26 18:32:40 INFO Executor: Running task 80.0 in stage 0.0 (TID 80)
[2025-06-26T18:32:40.822+0700] {subprocess.py:93} INFO - 25/06/26 18:32:40 INFO TaskSetManager: Starting task 81.0 in stage 0.0 (TID 81) (localhost, executor driver, partition 81, PROCESS_LOCAL, 9215 bytes)
[2025-06-26T18:32:40.822+0700] {subprocess.py:93} INFO - 25/06/26 18:32:40 INFO TaskSetManager: Finished task 53.0 in stage 0.0 (TID 53) in 96 ms on localhost (executor driver) (57/149)
[2025-06-26T18:32:40.823+0700] {subprocess.py:93} INFO - 25/06/26 18:32:40 INFO TaskSetManager: Finished task 60.0 in stage 0.0 (TID 60) in 74 ms on localhost (executor driver) (58/149)
[2025-06-26T18:32:40.823+0700] {subprocess.py:93} INFO - 25/06/26 18:32:40 INFO TaskSetManager: Finished task 55.0 in stage 0.0 (TID 55) in 91 ms on localhost (executor driver) (59/149)
[2025-06-26T18:32:40.824+0700] {subprocess.py:93} INFO - 25/06/26 18:32:40 INFO Executor: Running task 81.0 in stage 0.0 (TID 81)
[2025-06-26T18:32:40.827+0700] {subprocess.py:93} INFO - 25/06/26 18:32:40 INFO TaskSetManager: Starting task 82.0 in stage 0.0 (TID 82) (localhost, executor driver, partition 82, PROCESS_LOCAL, 9215 bytes)
[2025-06-26T18:32:40.828+0700] {subprocess.py:93} INFO - 25/06/26 18:32:40 INFO Executor: Finished task 77.0 in stage 0.0 (TID 77). 3175 bytes result sent to driver
[2025-06-26T18:32:40.828+0700] {subprocess.py:93} INFO - 25/06/26 18:32:40 INFO Executor: Finished task 78.0 in stage 0.0 (TID 78). 3175 bytes result sent to driver
[2025-06-26T18:32:40.828+0700] {subprocess.py:93} INFO - 25/06/26 18:32:40 INFO Executor: Running task 82.0 in stage 0.0 (TID 82)
[2025-06-26T18:32:40.833+0700] {subprocess.py:93} INFO - 25/06/26 18:32:40 INFO TaskSetManager: Starting task 83.0 in stage 0.0 (TID 83) (localhost, executor driver, partition 83, PROCESS_LOCAL, 9215 bytes)
[2025-06-26T18:32:40.833+0700] {subprocess.py:93} INFO - 25/06/26 18:32:40 INFO TaskSetManager: Finished task 58.0 in stage 0.0 (TID 58) in 89 ms on localhost (executor driver) (60/149)
[2025-06-26T18:32:40.834+0700] {subprocess.py:93} INFO - 25/06/26 18:32:40 INFO Executor: Running task 83.0 in stage 0.0 (TID 83)
[2025-06-26T18:32:40.834+0700] {subprocess.py:93} INFO - 25/06/26 18:32:40 INFO TaskSetManager: Finished task 59.0 in stage 0.0 (TID 59) in 87 ms on localhost (executor driver) (61/149)
[2025-06-26T18:32:40.836+0700] {subprocess.py:93} INFO - 25/06/26 18:32:40 INFO TaskSetManager: Starting task 84.0 in stage 0.0 (TID 84) (localhost, executor driver, partition 84, PROCESS_LOCAL, 9215 bytes)
[2025-06-26T18:32:40.839+0700] {subprocess.py:93} INFO - 25/06/26 18:32:40 INFO Executor: Finished task 79.0 in stage 0.0 (TID 79). 3175 bytes result sent to driver
[2025-06-26T18:32:40.839+0700] {subprocess.py:93} INFO - 25/06/26 18:32:40 INFO TaskSetManager: Finished task 64.0 in stage 0.0 (TID 64) in 76 ms on localhost (executor driver) (62/149)
[2025-06-26T18:32:40.840+0700] {subprocess.py:93} INFO - 25/06/26 18:32:40 INFO Executor: Finished task 80.0 in stage 0.0 (TID 80). 3175 bytes result sent to driver
[2025-06-26T18:32:40.840+0700] {subprocess.py:93} INFO - 25/06/26 18:32:40 INFO Executor: Running task 84.0 in stage 0.0 (TID 84)
[2025-06-26T18:32:40.841+0700] {subprocess.py:93} INFO - 25/06/26 18:32:40 INFO TaskSetManager: Finished task 61.0 in stage 0.0 (TID 61) in 88 ms on localhost (executor driver) (63/149)
[2025-06-26T18:32:40.842+0700] {subprocess.py:93} INFO - 25/06/26 18:32:40 INFO TaskSetManager: Starting task 85.0 in stage 0.0 (TID 85) (localhost, executor driver, partition 85, PROCESS_LOCAL, 9215 bytes)
[2025-06-26T18:32:40.843+0700] {subprocess.py:93} INFO - 25/06/26 18:32:40 INFO Executor: Finished task 82.0 in stage 0.0 (TID 82). 3175 bytes result sent to driver
[2025-06-26T18:32:40.843+0700] {subprocess.py:93} INFO - 25/06/26 18:32:40 INFO Executor: Finished task 81.0 in stage 0.0 (TID 81). 3175 bytes result sent to driver
[2025-06-26T18:32:40.843+0700] {subprocess.py:93} INFO - 25/06/26 18:32:40 INFO Executor: Running task 85.0 in stage 0.0 (TID 85)
[2025-06-26T18:32:40.843+0700] {subprocess.py:93} INFO - 25/06/26 18:32:40 INFO TaskSetManager: Starting task 86.0 in stage 0.0 (TID 86) (localhost, executor driver, partition 86, PROCESS_LOCAL, 9215 bytes)
[2025-06-26T18:32:40.844+0700] {subprocess.py:93} INFO - 25/06/26 18:32:40 INFO TaskSetManager: Finished task 66.0 in stage 0.0 (TID 66) in 77 ms on localhost (executor driver) (64/149)
[2025-06-26T18:32:40.844+0700] {subprocess.py:93} INFO - 25/06/26 18:32:40 INFO Executor: Running task 86.0 in stage 0.0 (TID 86)
[2025-06-26T18:32:40.845+0700] {subprocess.py:93} INFO - 25/06/26 18:32:40 INFO Executor: Finished task 83.0 in stage 0.0 (TID 83). 3175 bytes result sent to driver
[2025-06-26T18:32:40.845+0700] {subprocess.py:93} INFO - 25/06/26 18:32:40 INFO TaskSetManager: Finished task 65.0 in stage 0.0 (TID 65) in 80 ms on localhost (executor driver) (65/149)
[2025-06-26T18:32:40.847+0700] {subprocess.py:93} INFO - 25/06/26 18:32:40 INFO TaskSetManager: Starting task 87.0 in stage 0.0 (TID 87) (localhost, executor driver, partition 87, PROCESS_LOCAL, 9215 bytes)
[2025-06-26T18:32:40.848+0700] {subprocess.py:93} INFO - 25/06/26 18:32:40 INFO Executor: Running task 87.0 in stage 0.0 (TID 87)
[2025-06-26T18:32:40.848+0700] {subprocess.py:93} INFO - 25/06/26 18:32:40 INFO TaskSetManager: Starting task 88.0 in stage 0.0 (TID 88) (localhost, executor driver, partition 88, PROCESS_LOCAL, 9215 bytes)
[2025-06-26T18:32:40.849+0700] {subprocess.py:93} INFO - 25/06/26 18:32:40 INFO TaskSetManager: Finished task 62.0 in stage 0.0 (TID 62) in 88 ms on localhost (executor driver) (66/149)
[2025-06-26T18:32:40.849+0700] {subprocess.py:93} INFO - 25/06/26 18:32:40 INFO Executor: Running task 88.0 in stage 0.0 (TID 88)
[2025-06-26T18:32:40.850+0700] {subprocess.py:93} INFO - 25/06/26 18:32:40 INFO TaskSetManager: Finished task 63.0 in stage 0.0 (TID 63) in 88 ms on localhost (executor driver) (67/149)
[2025-06-26T18:32:40.853+0700] {subprocess.py:93} INFO - 25/06/26 18:32:40 INFO TaskSetManager: Starting task 89.0 in stage 0.0 (TID 89) (localhost, executor driver, partition 89, PROCESS_LOCAL, 9215 bytes)
[2025-06-26T18:32:40.856+0700] {subprocess.py:93} INFO - 25/06/26 18:32:40 INFO TaskSetManager: Starting task 90.0 in stage 0.0 (TID 90) (localhost, executor driver, partition 90, PROCESS_LOCAL, 9215 bytes)
[2025-06-26T18:32:40.857+0700] {subprocess.py:93} INFO - 25/06/26 18:32:40 INFO Executor: Running task 89.0 in stage 0.0 (TID 89)
[2025-06-26T18:32:40.858+0700] {subprocess.py:93} INFO - 25/06/26 18:32:40 INFO TaskSetManager: Starting task 91.0 in stage 0.0 (TID 91) (localhost, executor driver, partition 91, PROCESS_LOCAL, 9215 bytes)
[2025-06-26T18:32:40.858+0700] {subprocess.py:93} INFO - 25/06/26 18:32:40 INFO Executor: Finished task 86.0 in stage 0.0 (TID 86). 3175 bytes result sent to driver
[2025-06-26T18:32:40.859+0700] {subprocess.py:93} INFO - 25/06/26 18:32:40 INFO Executor: Finished task 84.0 in stage 0.0 (TID 84). 3218 bytes result sent to driver
[2025-06-26T18:32:40.859+0700] {subprocess.py:93} INFO - 25/06/26 18:32:40 INFO Executor: Running task 90.0 in stage 0.0 (TID 90)
[2025-06-26T18:32:40.859+0700] {subprocess.py:93} INFO - 25/06/26 18:32:40 INFO Executor: Running task 91.0 in stage 0.0 (TID 91)
[2025-06-26T18:32:40.859+0700] {subprocess.py:93} INFO - 25/06/26 18:32:40 INFO TaskSetManager: Starting task 92.0 in stage 0.0 (TID 92) (localhost, executor driver, partition 92, PROCESS_LOCAL, 9215 bytes)
[2025-06-26T18:32:40.860+0700] {subprocess.py:93} INFO - 25/06/26 18:32:40 INFO TaskSetManager: Starting task 93.0 in stage 0.0 (TID 93) (localhost, executor driver, partition 93, PROCESS_LOCAL, 9215 bytes)
[2025-06-26T18:32:40.860+0700] {subprocess.py:93} INFO - 25/06/26 18:32:40 INFO TaskSetManager: Starting task 94.0 in stage 0.0 (TID 94) (localhost, executor driver, partition 94, PROCESS_LOCAL, 9215 bytes)
[2025-06-26T18:32:40.860+0700] {subprocess.py:93} INFO - 25/06/26 18:32:40 INFO Executor: Running task 93.0 in stage 0.0 (TID 93)
[2025-06-26T18:32:40.860+0700] {subprocess.py:93} INFO - 25/06/26 18:32:40 INFO Executor: Running task 92.0 in stage 0.0 (TID 92)
[2025-06-26T18:32:40.860+0700] {subprocess.py:93} INFO - 25/06/26 18:32:40 INFO Executor: Running task 94.0 in stage 0.0 (TID 94)
[2025-06-26T18:32:40.861+0700] {subprocess.py:93} INFO - 25/06/26 18:32:40 INFO TaskSetManager: Starting task 95.0 in stage 0.0 (TID 95) (localhost, executor driver, partition 95, PROCESS_LOCAL, 9215 bytes)
[2025-06-26T18:32:40.861+0700] {subprocess.py:93} INFO - 25/06/26 18:32:40 INFO Executor: Running task 95.0 in stage 0.0 (TID 95)
[2025-06-26T18:32:40.862+0700] {subprocess.py:93} INFO - 25/06/26 18:32:40 INFO Executor: Finished task 85.0 in stage 0.0 (TID 85). 3175 bytes result sent to driver
[2025-06-26T18:32:40.862+0700] {subprocess.py:93} INFO - 25/06/26 18:32:40 INFO TaskSetManager: Finished task 67.0 in stage 0.0 (TID 67) in 83 ms on localhost (executor driver) (68/149)
[2025-06-26T18:32:40.865+0700] {subprocess.py:93} INFO - 25/06/26 18:32:40 INFO TaskSetManager: Starting task 96.0 in stage 0.0 (TID 96) (localhost, executor driver, partition 96, PROCESS_LOCAL, 9215 bytes)
[2025-06-26T18:32:40.866+0700] {subprocess.py:93} INFO - 25/06/26 18:32:40 INFO Executor: Running task 96.0 in stage 0.0 (TID 96)
[2025-06-26T18:32:40.866+0700] {subprocess.py:93} INFO - 25/06/26 18:32:40 INFO TaskSetManager: Starting task 97.0 in stage 0.0 (TID 97) (localhost, executor driver, partition 97, PROCESS_LOCAL, 9215 bytes)
[2025-06-26T18:32:40.866+0700] {subprocess.py:93} INFO - 25/06/26 18:32:40 INFO TaskSetManager: Starting task 98.0 in stage 0.0 (TID 98) (localhost, executor driver, partition 98, PROCESS_LOCAL, 9215 bytes)
[2025-06-26T18:32:40.867+0700] {subprocess.py:93} INFO - 25/06/26 18:32:40 INFO Executor: Running task 97.0 in stage 0.0 (TID 97)
[2025-06-26T18:32:40.868+0700] {subprocess.py:93} INFO - 25/06/26 18:32:40 INFO TaskSetManager: Starting task 99.0 in stage 0.0 (TID 99) (localhost, executor driver, partition 99, PROCESS_LOCAL, 9215 bytes)
[2025-06-26T18:32:40.868+0700] {subprocess.py:93} INFO - 25/06/26 18:32:40 INFO Executor: Running task 98.0 in stage 0.0 (TID 98)
[2025-06-26T18:32:40.868+0700] {subprocess.py:93} INFO - 25/06/26 18:32:40 INFO Executor: Finished task 88.0 in stage 0.0 (TID 88). 3175 bytes result sent to driver
[2025-06-26T18:32:40.869+0700] {subprocess.py:93} INFO - 25/06/26 18:32:40 INFO Executor: Finished task 87.0 in stage 0.0 (TID 87). 3175 bytes result sent to driver
[2025-06-26T18:32:40.872+0700] {subprocess.py:93} INFO - 25/06/26 18:32:40 INFO Executor: Running task 99.0 in stage 0.0 (TID 99)
[2025-06-26T18:32:40.873+0700] {subprocess.py:93} INFO - 25/06/26 18:32:40 INFO Executor: Finished task 89.0 in stage 0.0 (TID 89). 3175 bytes result sent to driver
[2025-06-26T18:32:40.873+0700] {subprocess.py:93} INFO - 25/06/26 18:32:40 INFO Executor: Finished task 91.0 in stage 0.0 (TID 91). 3175 bytes result sent to driver
[2025-06-26T18:32:40.874+0700] {subprocess.py:93} INFO - 25/06/26 18:32:40 INFO TaskSetManager: Starting task 100.0 in stage 0.0 (TID 100) (localhost, executor driver, partition 100, PROCESS_LOCAL, 9215 bytes)
[2025-06-26T18:32:40.874+0700] {subprocess.py:93} INFO - 25/06/26 18:32:40 INFO Executor: Finished task 90.0 in stage 0.0 (TID 90). 3175 bytes result sent to driver
[2025-06-26T18:32:40.876+0700] {subprocess.py:93} INFO - 25/06/26 18:32:40 INFO Executor: Finished task 95.0 in stage 0.0 (TID 95). 3175 bytes result sent to driver
[2025-06-26T18:32:40.876+0700] {subprocess.py:93} INFO - 25/06/26 18:32:40 INFO Executor: Running task 100.0 in stage 0.0 (TID 100)
[2025-06-26T18:32:40.877+0700] {subprocess.py:93} INFO - 25/06/26 18:32:40 INFO Executor: Finished task 92.0 in stage 0.0 (TID 92). 3175 bytes result sent to driver
[2025-06-26T18:32:40.878+0700] {subprocess.py:93} INFO - 25/06/26 18:32:40 INFO Executor: Finished task 94.0 in stage 0.0 (TID 94). 3175 bytes result sent to driver
[2025-06-26T18:32:40.878+0700] {subprocess.py:93} INFO - 25/06/26 18:32:40 INFO TaskSetManager: Starting task 101.0 in stage 0.0 (TID 101) (localhost, executor driver, partition 101, PROCESS_LOCAL, 9215 bytes)
[2025-06-26T18:32:40.880+0700] {subprocess.py:93} INFO - 25/06/26 18:32:40 INFO TaskSetManager: Finished task 73.0 in stage 0.0 (TID 73) in 72 ms on localhost (executor driver) (69/149)
[2025-06-26T18:32:40.881+0700] {subprocess.py:93} INFO - 25/06/26 18:32:40 INFO Executor: Finished task 93.0 in stage 0.0 (TID 93). 3175 bytes result sent to driver
[2025-06-26T18:32:40.881+0700] {subprocess.py:93} INFO - 25/06/26 18:32:40 INFO Executor: Running task 101.0 in stage 0.0 (TID 101)
[2025-06-26T18:32:40.881+0700] {subprocess.py:93} INFO - 25/06/26 18:32:40 INFO TaskSetManager: Finished task 74.0 in stage 0.0 (TID 74) in 73 ms on localhost (executor driver) (70/149)
[2025-06-26T18:32:40.881+0700] {subprocess.py:93} INFO - 25/06/26 18:32:40 INFO TaskSetManager: Finished task 68.0 in stage 0.0 (TID 68) in 95 ms on localhost (executor driver) (71/149)
[2025-06-26T18:32:40.881+0700] {subprocess.py:93} INFO - 25/06/26 18:32:40 INFO TaskSetManager: Finished task 71.0 in stage 0.0 (TID 71) in 82 ms on localhost (executor driver) (72/149)
[2025-06-26T18:32:40.881+0700] {subprocess.py:93} INFO - 25/06/26 18:32:40 INFO TaskSetManager: Finished task 72.0 in stage 0.0 (TID 72) in 82 ms on localhost (executor driver) (73/149)
[2025-06-26T18:32:40.881+0700] {subprocess.py:93} INFO - 25/06/26 18:32:40 INFO TaskSetManager: Finished task 70.0 in stage 0.0 (TID 70) in 86 ms on localhost (executor driver) (74/149)
[2025-06-26T18:32:40.882+0700] {subprocess.py:93} INFO - 25/06/26 18:32:40 INFO Executor: Finished task 97.0 in stage 0.0 (TID 97). 3175 bytes result sent to driver
[2025-06-26T18:32:40.882+0700] {subprocess.py:93} INFO - 25/06/26 18:32:40 INFO TaskSetManager: Finished task 75.0 in stage 0.0 (TID 75) in 76 ms on localhost (executor driver) (75/149)
[2025-06-26T18:32:40.882+0700] {subprocess.py:93} INFO - 25/06/26 18:32:40 INFO TaskSetManager: Finished task 76.0 in stage 0.0 (TID 76) in 75 ms on localhost (executor driver) (76/149)
[2025-06-26T18:32:40.882+0700] {subprocess.py:93} INFO - 25/06/26 18:32:40 INFO Executor: Finished task 96.0 in stage 0.0 (TID 96). 3175 bytes result sent to driver
[2025-06-26T18:32:40.894+0700] {subprocess.py:93} INFO - 25/06/26 18:32:40 INFO Executor: Finished task 99.0 in stage 0.0 (TID 99). 3261 bytes result sent to driver
[2025-06-26T18:32:40.895+0700] {subprocess.py:93} INFO - 25/06/26 18:32:40 INFO Executor: Finished task 98.0 in stage 0.0 (TID 98). 3218 bytes result sent to driver
[2025-06-26T18:32:40.896+0700] {subprocess.py:93} INFO - 25/06/26 18:32:40 INFO TaskSetManager: Starting task 102.0 in stage 0.0 (TID 102) (localhost, executor driver, partition 102, PROCESS_LOCAL, 9215 bytes)
[2025-06-26T18:32:40.897+0700] {subprocess.py:93} INFO - 25/06/26 18:32:40 INFO TaskSetManager: Finished task 78.0 in stage 0.0 (TID 78) in 85 ms on localhost (executor driver) (77/149)
[2025-06-26T18:32:40.897+0700] {subprocess.py:93} INFO - 25/06/26 18:32:40 INFO Executor: Running task 102.0 in stage 0.0 (TID 102)
[2025-06-26T18:32:40.899+0700] {subprocess.py:93} INFO - 25/06/26 18:32:40 INFO TaskSetManager: Finished task 69.0 in stage 0.0 (TID 69) in 109 ms on localhost (executor driver) (78/149)
[2025-06-26T18:32:40.899+0700] {subprocess.py:93} INFO - 25/06/26 18:32:40 INFO TaskSetManager: Finished task 77.0 in stage 0.0 (TID 77) in 90 ms on localhost (executor driver) (79/149)
[2025-06-26T18:32:40.900+0700] {subprocess.py:93} INFO - 25/06/26 18:32:40 INFO Executor: Finished task 100.0 in stage 0.0 (TID 100). 3218 bytes result sent to driver
[2025-06-26T18:32:40.900+0700] {subprocess.py:93} INFO - 25/06/26 18:32:40 INFO TaskSetManager: Finished task 79.0 in stage 0.0 (TID 79) in 81 ms on localhost (executor driver) (80/149)
[2025-06-26T18:32:40.900+0700] {subprocess.py:93} INFO - 25/06/26 18:32:40 INFO TaskSetManager: Finished task 82.0 in stage 0.0 (TID 82) in 74 ms on localhost (executor driver) (81/149)
[2025-06-26T18:32:40.900+0700] {subprocess.py:93} INFO - 25/06/26 18:32:40 INFO TaskSetManager: Finished task 80.0 in stage 0.0 (TID 80) in 80 ms on localhost (executor driver) (82/149)
[2025-06-26T18:32:40.901+0700] {subprocess.py:93} INFO - 25/06/26 18:32:40 INFO TaskSetManager: Starting task 103.0 in stage 0.0 (TID 103) (localhost, executor driver, partition 103, PROCESS_LOCAL, 9215 bytes)
[2025-06-26T18:32:40.902+0700] {subprocess.py:93} INFO - 25/06/26 18:32:40 INFO Executor: Running task 103.0 in stage 0.0 (TID 103)
[2025-06-26T18:32:40.903+0700] {subprocess.py:93} INFO - 25/06/26 18:32:40 INFO TaskSetManager: Starting task 104.0 in stage 0.0 (TID 104) (localhost, executor driver, partition 104, PROCESS_LOCAL, 9215 bytes)
[2025-06-26T18:32:40.903+0700] {subprocess.py:93} INFO - 25/06/26 18:32:40 INFO Executor: Running task 104.0 in stage 0.0 (TID 104)
[2025-06-26T18:32:40.904+0700] {subprocess.py:93} INFO - 25/06/26 18:32:40 INFO TaskSetManager: Starting task 105.0 in stage 0.0 (TID 105) (localhost, executor driver, partition 105, PROCESS_LOCAL, 9215 bytes)
[2025-06-26T18:32:40.904+0700] {subprocess.py:93} INFO - 25/06/26 18:32:40 INFO TaskSetManager: Finished task 81.0 in stage 0.0 (TID 81) in 83 ms on localhost (executor driver) (83/149)
[2025-06-26T18:32:40.905+0700] {subprocess.py:93} INFO - 25/06/26 18:32:40 INFO Executor: Finished task 101.0 in stage 0.0 (TID 101). 3218 bytes result sent to driver
[2025-06-26T18:32:40.905+0700] {subprocess.py:93} INFO - 25/06/26 18:32:40 INFO Executor: Running task 105.0 in stage 0.0 (TID 105)
[2025-06-26T18:32:40.905+0700] {subprocess.py:93} INFO - 25/06/26 18:32:40 INFO TaskSetManager: Starting task 106.0 in stage 0.0 (TID 106) (localhost, executor driver, partition 106, PROCESS_LOCAL, 9215 bytes)
[2025-06-26T18:32:40.906+0700] {subprocess.py:93} INFO - 25/06/26 18:32:40 INFO Executor: Running task 106.0 in stage 0.0 (TID 106)
[2025-06-26T18:32:40.906+0700] {subprocess.py:93} INFO - 25/06/26 18:32:40 INFO TaskSetManager: Starting task 107.0 in stage 0.0 (TID 107) (localhost, executor driver, partition 107, PROCESS_LOCAL, 9215 bytes)
[2025-06-26T18:32:40.908+0700] {subprocess.py:93} INFO - 25/06/26 18:32:40 INFO Executor: Running task 107.0 in stage 0.0 (TID 107)
[2025-06-26T18:32:40.909+0700] {subprocess.py:93} INFO - 25/06/26 18:32:40 INFO TaskSetManager: Starting task 108.0 in stage 0.0 (TID 108) (localhost, executor driver, partition 108, PROCESS_LOCAL, 9215 bytes)
[2025-06-26T18:32:40.929+0700] {subprocess.py:93} INFO - 25/06/26 18:32:40 INFO Executor: Running task 108.0 in stage 0.0 (TID 108)
[2025-06-26T18:32:40.930+0700] {subprocess.py:93} INFO - 25/06/26 18:32:40 INFO TaskSetManager: Starting task 109.0 in stage 0.0 (TID 109) (localhost, executor driver, partition 109, PROCESS_LOCAL, 9215 bytes)
[2025-06-26T18:32:40.933+0700] {subprocess.py:93} INFO - 25/06/26 18:32:40 INFO Executor: Running task 109.0 in stage 0.0 (TID 109)
[2025-06-26T18:32:40.934+0700] {subprocess.py:93} INFO - 25/06/26 18:32:40 INFO TaskSetManager: Starting task 110.0 in stage 0.0 (TID 110) (localhost, executor driver, partition 110, PROCESS_LOCAL, 9215 bytes)
[2025-06-26T18:32:40.934+0700] {subprocess.py:93} INFO - 25/06/26 18:32:40 INFO TaskSetManager: Finished task 83.0 in stage 0.0 (TID 83) in 105 ms on localhost (executor driver) (84/149)
[2025-06-26T18:32:40.934+0700] {subprocess.py:93} INFO - 25/06/26 18:32:40 INFO Executor: Running task 110.0 in stage 0.0 (TID 110)
[2025-06-26T18:32:40.936+0700] {subprocess.py:93} INFO - 25/06/26 18:32:40 INFO Executor: Finished task 102.0 in stage 0.0 (TID 102). 3175 bytes result sent to driver
[2025-06-26T18:32:40.936+0700] {subprocess.py:93} INFO - 25/06/26 18:32:40 INFO Executor: Finished task 103.0 in stage 0.0 (TID 103). 3175 bytes result sent to driver
[2025-06-26T18:32:40.938+0700] {subprocess.py:93} INFO - 25/06/26 18:32:40 INFO TaskSetManager: Starting task 111.0 in stage 0.0 (TID 111) (localhost, executor driver, partition 111, PROCESS_LOCAL, 9215 bytes)
[2025-06-26T18:32:40.938+0700] {subprocess.py:93} INFO - 25/06/26 18:32:40 INFO Executor: Finished task 106.0 in stage 0.0 (TID 106). 3175 bytes result sent to driver
[2025-06-26T18:32:40.940+0700] {subprocess.py:93} INFO - 25/06/26 18:32:40 INFO Executor: Running task 111.0 in stage 0.0 (TID 111)
[2025-06-26T18:32:40.943+0700] {subprocess.py:93} INFO - 25/06/26 18:32:40 INFO TaskSetManager: Starting task 112.0 in stage 0.0 (TID 112) (localhost, executor driver, partition 112, PROCESS_LOCAL, 9215 bytes)
[2025-06-26T18:32:40.944+0700] {subprocess.py:93} INFO - 25/06/26 18:32:40 INFO Executor: Running task 112.0 in stage 0.0 (TID 112)
[2025-06-26T18:32:40.945+0700] {subprocess.py:93} INFO - 25/06/26 18:32:40 INFO Executor: Finished task 104.0 in stage 0.0 (TID 104). 3175 bytes result sent to driver
[2025-06-26T18:32:40.946+0700] {subprocess.py:93} INFO - 25/06/26 18:32:40 INFO TaskSetManager: Starting task 113.0 in stage 0.0 (TID 113) (localhost, executor driver, partition 113, PROCESS_LOCAL, 9215 bytes)
[2025-06-26T18:32:40.946+0700] {subprocess.py:93} INFO - 25/06/26 18:32:40 INFO Executor: Running task 113.0 in stage 0.0 (TID 113)
[2025-06-26T18:32:40.946+0700] {subprocess.py:93} INFO - 25/06/26 18:32:40 INFO TaskSetManager: Starting task 114.0 in stage 0.0 (TID 114) (localhost, executor driver, partition 114, PROCESS_LOCAL, 9215 bytes)
[2025-06-26T18:32:40.947+0700] {subprocess.py:93} INFO - 25/06/26 18:32:40 INFO TaskSetManager: Finished task 85.0 in stage 0.0 (TID 85) in 103 ms on localhost (executor driver) (85/149)
[2025-06-26T18:32:40.947+0700] {subprocess.py:93} INFO - 25/06/26 18:32:40 INFO Executor: Running task 114.0 in stage 0.0 (TID 114)
[2025-06-26T18:32:40.947+0700] {subprocess.py:93} INFO - 25/06/26 18:32:40 INFO Executor: Finished task 105.0 in stage 0.0 (TID 105). 3175 bytes result sent to driver
[2025-06-26T18:32:40.947+0700] {subprocess.py:93} INFO - 25/06/26 18:32:40 INFO TaskSetManager: Finished task 86.0 in stage 0.0 (TID 86) in 102 ms on localhost (executor driver) (86/149)
[2025-06-26T18:32:40.947+0700] {subprocess.py:93} INFO - 25/06/26 18:32:40 INFO TaskSetManager: Finished task 88.0 in stage 0.0 (TID 88) in 99 ms on localhost (executor driver) (87/149)
[2025-06-26T18:32:40.948+0700] {subprocess.py:93} INFO - 25/06/26 18:32:40 INFO TaskSetManager: Finished task 89.0 in stage 0.0 (TID 89) in 97 ms on localhost (executor driver) (88/149)
[2025-06-26T18:32:40.950+0700] {subprocess.py:93} INFO - 25/06/26 18:32:40 INFO Executor: Finished task 107.0 in stage 0.0 (TID 107). 3175 bytes result sent to driver
[2025-06-26T18:32:40.951+0700] {subprocess.py:93} INFO - 25/06/26 18:32:40 INFO TaskSetManager: Finished task 87.0 in stage 0.0 (TID 87) in 104 ms on localhost (executor driver) (89/149)
[2025-06-26T18:32:40.951+0700] {subprocess.py:93} INFO - 25/06/26 18:32:40 INFO Executor: Finished task 109.0 in stage 0.0 (TID 109). 3175 bytes result sent to driver
[2025-06-26T18:32:40.951+0700] {subprocess.py:93} INFO - 25/06/26 18:32:40 INFO TaskSetManager: Finished task 84.0 in stage 0.0 (TID 84) in 117 ms on localhost (executor driver) (90/149)
[2025-06-26T18:32:40.953+0700] {subprocess.py:93} INFO - 25/06/26 18:32:40 INFO TaskSetManager: Starting task 115.0 in stage 0.0 (TID 115) (localhost, executor driver, partition 115, PROCESS_LOCAL, 9215 bytes)
[2025-06-26T18:32:40.954+0700] {subprocess.py:93} INFO - 25/06/26 18:32:40 INFO TaskSetManager: Finished task 91.0 in stage 0.0 (TID 91) in 97 ms on localhost (executor driver) (91/149)
[2025-06-26T18:32:40.955+0700] {subprocess.py:93} INFO - 25/06/26 18:32:40 INFO Executor: Finished task 108.0 in stage 0.0 (TID 108). 3175 bytes result sent to driver
[2025-06-26T18:32:40.956+0700] {subprocess.py:93} INFO - 25/06/26 18:32:40 INFO Executor: Running task 115.0 in stage 0.0 (TID 115)
[2025-06-26T18:32:40.956+0700] {subprocess.py:93} INFO - 25/06/26 18:32:40 INFO TaskSetManager: Finished task 90.0 in stage 0.0 (TID 90) in 100 ms on localhost (executor driver) (92/149)
[2025-06-26T18:32:40.957+0700] {subprocess.py:93} INFO - 25/06/26 18:32:40 INFO Executor: Finished task 111.0 in stage 0.0 (TID 111). 3175 bytes result sent to driver
[2025-06-26T18:32:40.957+0700] {subprocess.py:93} INFO - 25/06/26 18:32:40 INFO Executor: Finished task 112.0 in stage 0.0 (TID 112). 3175 bytes result sent to driver
[2025-06-26T18:32:40.957+0700] {subprocess.py:93} INFO - 25/06/26 18:32:40 INFO Executor: Finished task 110.0 in stage 0.0 (TID 110). 3218 bytes result sent to driver
[2025-06-26T18:32:40.957+0700] {subprocess.py:93} INFO - 25/06/26 18:32:40 INFO TaskSetManager: Starting task 116.0 in stage 0.0 (TID 116) (localhost, executor driver, partition 116, PROCESS_LOCAL, 9215 bytes)
[2025-06-26T18:32:40.958+0700] {subprocess.py:93} INFO - 25/06/26 18:32:40 INFO Executor: Finished task 113.0 in stage 0.0 (TID 113). 3175 bytes result sent to driver
[2025-06-26T18:32:40.958+0700] {subprocess.py:93} INFO - 25/06/26 18:32:40 INFO TaskSetManager: Finished task 95.0 in stage 0.0 (TID 95) in 95 ms on localhost (executor driver) (93/149)
[2025-06-26T18:32:40.958+0700] {subprocess.py:93} INFO - 25/06/26 18:32:40 INFO Executor: Running task 116.0 in stage 0.0 (TID 116)
[2025-06-26T18:32:40.958+0700] {subprocess.py:93} INFO - 25/06/26 18:32:40 INFO TaskSetManager: Finished task 94.0 in stage 0.0 (TID 94) in 96 ms on localhost (executor driver) (94/149)
[2025-06-26T18:32:40.958+0700] {subprocess.py:93} INFO - 25/06/26 18:32:40 INFO TaskSetManager: Starting task 117.0 in stage 0.0 (TID 117) (localhost, executor driver, partition 117, PROCESS_LOCAL, 9215 bytes)
[2025-06-26T18:32:40.958+0700] {subprocess.py:93} INFO - 25/06/26 18:32:40 INFO TaskSetManager: Finished task 92.0 in stage 0.0 (TID 92) in 98 ms on localhost (executor driver) (95/149)
[2025-06-26T18:32:40.958+0700] {subprocess.py:93} INFO - 25/06/26 18:32:40 INFO Executor: Running task 117.0 in stage 0.0 (TID 117)
[2025-06-26T18:32:40.959+0700] {subprocess.py:93} INFO - 25/06/26 18:32:40 INFO TaskSetManager: Finished task 93.0 in stage 0.0 (TID 93) in 98 ms on localhost (executor driver) (96/149)
[2025-06-26T18:32:40.959+0700] {subprocess.py:93} INFO - 25/06/26 18:32:40 INFO TaskSetManager: Starting task 118.0 in stage 0.0 (TID 118) (localhost, executor driver, partition 118, PROCESS_LOCAL, 9215 bytes)
[2025-06-26T18:32:40.959+0700] {subprocess.py:93} INFO - 25/06/26 18:32:40 INFO Executor: Running task 118.0 in stage 0.0 (TID 118)
[2025-06-26T18:32:40.959+0700] {subprocess.py:93} INFO - 25/06/26 18:32:40 INFO TaskSetManager: Starting task 119.0 in stage 0.0 (TID 119) (localhost, executor driver, partition 119, PROCESS_LOCAL, 9215 bytes)
[2025-06-26T18:32:40.959+0700] {subprocess.py:93} INFO - 25/06/26 18:32:40 INFO TaskSetManager: Finished task 97.0 in stage 0.0 (TID 97) in 95 ms on localhost (executor driver) (97/149)
[2025-06-26T18:32:40.959+0700] {subprocess.py:93} INFO - 25/06/26 18:32:40 INFO Executor: Running task 119.0 in stage 0.0 (TID 119)
[2025-06-26T18:32:40.960+0700] {subprocess.py:93} INFO - 25/06/26 18:32:40 INFO TaskSetManager: Finished task 96.0 in stage 0.0 (TID 96) in 97 ms on localhost (executor driver) (98/149)
[2025-06-26T18:32:40.961+0700] {subprocess.py:93} INFO - 25/06/26 18:32:40 INFO Executor: Finished task 114.0 in stage 0.0 (TID 114). 3175 bytes result sent to driver
[2025-06-26T18:32:40.961+0700] {subprocess.py:93} INFO - 25/06/26 18:32:40 INFO TaskSetManager: Starting task 120.0 in stage 0.0 (TID 120) (localhost, executor driver, partition 120, PROCESS_LOCAL, 9215 bytes)
[2025-06-26T18:32:40.962+0700] {subprocess.py:93} INFO - 25/06/26 18:32:40 INFO Executor: Running task 120.0 in stage 0.0 (TID 120)
[2025-06-26T18:32:40.963+0700] {subprocess.py:93} INFO - 25/06/26 18:32:40 INFO TaskSetManager: Starting task 121.0 in stage 0.0 (TID 121) (localhost, executor driver, partition 121, PROCESS_LOCAL, 9215 bytes)
[2025-06-26T18:32:40.964+0700] {subprocess.py:93} INFO - 25/06/26 18:32:40 INFO Executor: Running task 121.0 in stage 0.0 (TID 121)
[2025-06-26T18:32:40.965+0700] {subprocess.py:93} INFO - 25/06/26 18:32:40 INFO Executor: Finished task 115.0 in stage 0.0 (TID 115). 3175 bytes result sent to driver
[2025-06-26T18:32:40.966+0700] {subprocess.py:93} INFO - 25/06/26 18:32:40 INFO TaskSetManager: Starting task 122.0 in stage 0.0 (TID 122) (localhost, executor driver, partition 122, PROCESS_LOCAL, 9215 bytes)
[2025-06-26T18:32:40.968+0700] {subprocess.py:93} INFO - 25/06/26 18:32:40 INFO TaskSetManager: Starting task 123.0 in stage 0.0 (TID 123) (localhost, executor driver, partition 123, PROCESS_LOCAL, 9215 bytes)
[2025-06-26T18:32:40.968+0700] {subprocess.py:93} INFO - 25/06/26 18:32:40 INFO Executor: Running task 122.0 in stage 0.0 (TID 122)
[2025-06-26T18:32:40.969+0700] {subprocess.py:93} INFO - 25/06/26 18:32:40 INFO Executor: Finished task 116.0 in stage 0.0 (TID 116). 3175 bytes result sent to driver
[2025-06-26T18:32:40.969+0700] {subprocess.py:93} INFO - 25/06/26 18:32:40 INFO TaskSetManager: Finished task 98.0 in stage 0.0 (TID 98) in 102 ms on localhost (executor driver) (99/149)
[2025-06-26T18:32:40.969+0700] {subprocess.py:93} INFO - 25/06/26 18:32:40 INFO TaskSetManager: Finished task 99.0 in stage 0.0 (TID 99) in 102 ms on localhost (executor driver) (100/149)
[2025-06-26T18:32:40.969+0700] {subprocess.py:93} INFO - 25/06/26 18:32:40 INFO TaskSetManager: Finished task 101.0 in stage 0.0 (TID 101) in 94 ms on localhost (executor driver) (101/149)
[2025-06-26T18:32:40.970+0700] {subprocess.py:93} INFO - 25/06/26 18:32:40 INFO Executor: Finished task 117.0 in stage 0.0 (TID 117). 3218 bytes result sent to driver
[2025-06-26T18:32:40.970+0700] {subprocess.py:93} INFO - 25/06/26 18:32:40 INFO TaskSetManager: Finished task 100.0 in stage 0.0 (TID 100) in 97 ms on localhost (executor driver) (102/149)
[2025-06-26T18:32:40.971+0700] {subprocess.py:93} INFO - 25/06/26 18:32:40 INFO Executor: Running task 123.0 in stage 0.0 (TID 123)
[2025-06-26T18:32:40.972+0700] {subprocess.py:93} INFO - 25/06/26 18:32:40 INFO Executor: Finished task 118.0 in stage 0.0 (TID 118). 3175 bytes result sent to driver
[2025-06-26T18:32:40.972+0700] {subprocess.py:93} INFO - 25/06/26 18:32:40 INFO TaskSetManager: Starting task 124.0 in stage 0.0 (TID 124) (localhost, executor driver, partition 124, PROCESS_LOCAL, 9215 bytes)
[2025-06-26T18:32:40.972+0700] {subprocess.py:93} INFO - 25/06/26 18:32:40 INFO Executor: Finished task 119.0 in stage 0.0 (TID 119). 3175 bytes result sent to driver
[2025-06-26T18:32:40.972+0700] {subprocess.py:93} INFO - 25/06/26 18:32:40 INFO Executor: Running task 124.0 in stage 0.0 (TID 124)
[2025-06-26T18:32:40.973+0700] {subprocess.py:93} INFO - 25/06/26 18:32:40 INFO TaskSetManager: Starting task 125.0 in stage 0.0 (TID 125) (localhost, executor driver, partition 125, PROCESS_LOCAL, 9215 bytes)
[2025-06-26T18:32:40.973+0700] {subprocess.py:93} INFO - 25/06/26 18:32:40 INFO Executor: Running task 125.0 in stage 0.0 (TID 125)
[2025-06-26T18:32:40.973+0700] {subprocess.py:93} INFO - 25/06/26 18:32:40 INFO TaskSetManager: Starting task 126.0 in stage 0.0 (TID 126) (localhost, executor driver, partition 126, PROCESS_LOCAL, 9215 bytes)
[2025-06-26T18:32:40.974+0700] {subprocess.py:93} INFO - 25/06/26 18:32:40 INFO Executor: Finished task 121.0 in stage 0.0 (TID 121). 3175 bytes result sent to driver
[2025-06-26T18:32:40.974+0700] {subprocess.py:93} INFO - 25/06/26 18:32:40 INFO TaskSetManager: Starting task 127.0 in stage 0.0 (TID 127) (localhost, executor driver, partition 127, PROCESS_LOCAL, 9215 bytes)
[2025-06-26T18:32:40.974+0700] {subprocess.py:93} INFO - 25/06/26 18:32:40 INFO TaskSetManager: Finished task 102.0 in stage 0.0 (TID 102) in 92 ms on localhost (executor driver) (103/149)
[2025-06-26T18:32:40.974+0700] {subprocess.py:93} INFO - 25/06/26 18:32:40 INFO Executor: Running task 126.0 in stage 0.0 (TID 126)
[2025-06-26T18:32:40.977+0700] {subprocess.py:93} INFO - 25/06/26 18:32:40 INFO TaskSetManager: Starting task 128.0 in stage 0.0 (TID 128) (localhost, executor driver, partition 128, PROCESS_LOCAL, 9215 bytes)
[2025-06-26T18:32:40.977+0700] {subprocess.py:93} INFO - 25/06/26 18:32:40 INFO Executor: Running task 128.0 in stage 0.0 (TID 128)
[2025-06-26T18:32:40.977+0700] {subprocess.py:93} INFO - 25/06/26 18:32:40 INFO TaskSetManager: Starting task 129.0 in stage 0.0 (TID 129) (localhost, executor driver, partition 129, PROCESS_LOCAL, 9215 bytes)
[2025-06-26T18:32:40.978+0700] {subprocess.py:93} INFO - 25/06/26 18:32:40 INFO Executor: Running task 127.0 in stage 0.0 (TID 127)
[2025-06-26T18:32:40.978+0700] {subprocess.py:93} INFO - 25/06/26 18:32:40 INFO Executor: Running task 129.0 in stage 0.0 (TID 129)
[2025-06-26T18:32:40.978+0700] {subprocess.py:93} INFO - 25/06/26 18:32:40 INFO TaskSetManager: Starting task 130.0 in stage 0.0 (TID 130) (localhost, executor driver, partition 130, PROCESS_LOCAL, 9215 bytes)
[2025-06-26T18:32:40.978+0700] {subprocess.py:93} INFO - 25/06/26 18:32:40 INFO Executor: Running task 130.0 in stage 0.0 (TID 130)
[2025-06-26T18:32:40.978+0700] {subprocess.py:93} INFO - 25/06/26 18:32:40 INFO TaskSetManager: Starting task 131.0 in stage 0.0 (TID 131) (localhost, executor driver, partition 131, PROCESS_LOCAL, 9215 bytes)
[2025-06-26T18:32:40.978+0700] {subprocess.py:93} INFO - 25/06/26 18:32:40 INFO Executor: Running task 131.0 in stage 0.0 (TID 131)
[2025-06-26T18:32:40.978+0700] {subprocess.py:93} INFO - 25/06/26 18:32:40 INFO TaskSetManager: Finished task 103.0 in stage 0.0 (TID 103) in 77 ms on localhost (executor driver) (104/149)
[2025-06-26T18:32:40.979+0700] {subprocess.py:93} INFO - 25/06/26 18:32:40 INFO TaskSetManager: Finished task 106.0 in stage 0.0 (TID 106) in 73 ms on localhost (executor driver) (105/149)
[2025-06-26T18:32:40.979+0700] {subprocess.py:93} INFO - 25/06/26 18:32:40 INFO TaskSetManager: Finished task 109.0 in stage 0.0 (TID 109) in 50 ms on localhost (executor driver) (106/149)
[2025-06-26T18:32:40.979+0700] {subprocess.py:93} INFO - 25/06/26 18:32:40 INFO TaskSetManager: Finished task 104.0 in stage 0.0 (TID 104) in 77 ms on localhost (executor driver) (107/149)
[2025-06-26T18:32:40.979+0700] {subprocess.py:93} INFO - 25/06/26 18:32:40 INFO TaskSetManager: Finished task 108.0 in stage 0.0 (TID 108) in 72 ms on localhost (executor driver) (108/149)
[2025-06-26T18:32:40.980+0700] {subprocess.py:93} INFO - 25/06/26 18:32:40 INFO TaskSetManager: Finished task 105.0 in stage 0.0 (TID 105) in 76 ms on localhost (executor driver) (109/149)
[2025-06-26T18:32:40.980+0700] {subprocess.py:93} INFO - 25/06/26 18:32:40 INFO TaskSetManager: Finished task 107.0 in stage 0.0 (TID 107) in 74 ms on localhost (executor driver) (110/149)
[2025-06-26T18:32:40.981+0700] {subprocess.py:93} INFO - 25/06/26 18:32:40 INFO TaskSetManager: Finished task 111.0 in stage 0.0 (TID 111) in 43 ms on localhost (executor driver) (111/149)
[2025-06-26T18:32:40.982+0700] {subprocess.py:93} INFO - 25/06/26 18:32:40 INFO TaskSetManager: Starting task 132.0 in stage 0.0 (TID 132) (localhost, executor driver, partition 132, PROCESS_LOCAL, 9215 bytes)
[2025-06-26T18:32:40.984+0700] {subprocess.py:93} INFO - 25/06/26 18:32:40 INFO Executor: Running task 132.0 in stage 0.0 (TID 132)
[2025-06-26T18:32:40.986+0700] {subprocess.py:93} INFO - 25/06/26 18:32:40 INFO TaskSetManager: Starting task 133.0 in stage 0.0 (TID 133) (localhost, executor driver, partition 133, PROCESS_LOCAL, 9215 bytes)
[2025-06-26T18:32:40.989+0700] {subprocess.py:93} INFO - 25/06/26 18:32:40 INFO Executor: Finished task 120.0 in stage 0.0 (TID 120). 3175 bytes result sent to driver
[2025-06-26T18:32:40.989+0700] {subprocess.py:93} INFO - 25/06/26 18:32:40 INFO Executor: Running task 133.0 in stage 0.0 (TID 133)
[2025-06-26T18:32:40.992+0700] {subprocess.py:93} INFO - 25/06/26 18:32:40 INFO TaskSetManager: Starting task 134.0 in stage 0.0 (TID 134) (localhost, executor driver, partition 134, PROCESS_LOCAL, 9215 bytes)
[2025-06-26T18:32:40.992+0700] {subprocess.py:93} INFO - 25/06/26 18:32:40 INFO Executor: Running task 134.0 in stage 0.0 (TID 134)
[2025-06-26T18:32:40.993+0700] {subprocess.py:93} INFO - 25/06/26 18:32:40 INFO Executor: Finished task 122.0 in stage 0.0 (TID 122). 3218 bytes result sent to driver
[2025-06-26T18:32:40.993+0700] {subprocess.py:93} INFO - 25/06/26 18:32:40 INFO Executor: Finished task 125.0 in stage 0.0 (TID 125). 3175 bytes result sent to driver
[2025-06-26T18:32:40.993+0700] {subprocess.py:93} INFO - 25/06/26 18:32:40 INFO Executor: Finished task 123.0 in stage 0.0 (TID 123). 3175 bytes result sent to driver
