[2025-06-26T20:20:03.692+0700] {local_task_job_runner.py:120} INFO - ::group::Pre task execution logs
[2025-06-26T20:20:03.712+0700] {taskinstance.py:2073} INFO - Dependencies all met for dep_context=non-requeueable deps ti=<TaskInstance: send_data_to_powerbi.compact_csv_to_one_file scheduled__2025-06-26T13:10:00+00:00 [queued]>
[2025-06-26T20:20:03.720+0700] {taskinstance.py:2073} INFO - Dependencies all met for dep_context=requeueable deps ti=<TaskInstance: send_data_to_powerbi.compact_csv_to_one_file scheduled__2025-06-26T13:10:00+00:00 [queued]>
[2025-06-26T20:20:03.720+0700] {taskinstance.py:2303} INFO - Starting attempt 1 of 3
[2025-06-26T20:20:03.741+0700] {taskinstance.py:2327} INFO - Executing <Task(BashOperator): compact_csv_to_one_file> on 2025-06-26 13:10:00+00:00
[2025-06-26T20:20:03.747+0700] {standard_task_runner.py:63} INFO - Started process 134598 to run task
[2025-06-26T20:20:03.750+0700] {standard_task_runner.py:90} INFO - Running: ['airflow', 'tasks', 'run', 'send_data_to_powerbi', 'compact_csv_to_one_file', 'scheduled__2025-06-26T13:10:00+00:00', '--job-id', '68', '--raw', '--subdir', 'DAGS_FOLDER/load_power_bi.py', '--cfg-path', '/tmp/tmpph7il6x9']
[2025-06-26T20:20:03.751+0700] {standard_task_runner.py:91} INFO - Job 68: Subtask compact_csv_to_one_file
[2025-06-26T20:20:03.798+0700] {task_command.py:426} INFO - Running <TaskInstance: send_data_to_powerbi.compact_csv_to_one_file scheduled__2025-06-26T13:10:00+00:00 [running]> on host Panda
[2025-06-26T20:20:03.887+0700] {taskinstance.py:2644} INFO - Exporting env vars: AIRFLOW_CTX_DAG_OWNER='group_03' AIRFLOW_CTX_DAG_ID='send_data_to_powerbi' AIRFLOW_CTX_TASK_ID='compact_csv_to_one_file' AIRFLOW_CTX_EXECUTION_DATE='2025-06-26T13:10:00+00:00' AIRFLOW_CTX_TRY_NUMBER='1' AIRFLOW_CTX_DAG_RUN_ID='scheduled__2025-06-26T13:10:00+00:00'
[2025-06-26T20:20:03.889+0700] {taskinstance.py:430} INFO - ::endgroup::
[2025-06-26T20:20:03.889+0700] {subprocess.py:63} INFO - Tmp dir root location: /tmp
[2025-06-26T20:20:03.890+0700] {subprocess.py:75} INFO - Running command: ['/usr/bin/bash', '-c', 'spark-submit /home/panda/Documents/ODAP/Project/hadoop/compact_csv.py && sleep 10']
[2025-06-26T20:20:03.907+0700] {subprocess.py:86} INFO - Output:
[2025-06-26T20:20:06.344+0700] {subprocess.py:93} INFO - 25/06/26 20:20:06 INFO SparkContext: Running Spark version 3.5.5
[2025-06-26T20:20:06.347+0700] {subprocess.py:93} INFO - 25/06/26 20:20:06 INFO SparkContext: OS info Linux, 6.11.0-26-generic, amd64
[2025-06-26T20:20:06.348+0700] {subprocess.py:93} INFO - 25/06/26 20:20:06 INFO SparkContext: Java version 11.0.27
[2025-06-26T20:20:06.521+0700] {subprocess.py:93} INFO - 25/06/26 20:20:06 INFO ResourceUtils: ==============================================================
[2025-06-26T20:20:06.521+0700] {subprocess.py:93} INFO - 25/06/26 20:20:06 INFO ResourceUtils: No custom resources configured for spark.driver.
[2025-06-26T20:20:06.521+0700] {subprocess.py:93} INFO - 25/06/26 20:20:06 INFO ResourceUtils: ==============================================================
[2025-06-26T20:20:06.522+0700] {subprocess.py:93} INFO - 25/06/26 20:20:06 INFO SparkContext: Submitted application: CompactSmallFiles
[2025-06-26T20:20:06.554+0700] {subprocess.py:93} INFO - 25/06/26 20:20:06 INFO ResourceProfile: Default ResourceProfile created, executor resources: Map(cores -> name: cores, amount: 1, script: , vendor: , memory -> name: memory, amount: 1024, script: , vendor: , offHeap -> name: offHeap, amount: 0, script: , vendor: ), task resources: Map(cpus -> name: cpus, amount: 1.0)
[2025-06-26T20:20:06.566+0700] {subprocess.py:93} INFO - 25/06/26 20:20:06 INFO ResourceProfile: Limiting resource is cpu
[2025-06-26T20:20:06.567+0700] {subprocess.py:93} INFO - 25/06/26 20:20:06 INFO ResourceProfileManager: Added ResourceProfile id: 0
[2025-06-26T20:20:06.637+0700] {subprocess.py:93} INFO - 25/06/26 20:20:06 INFO SecurityManager: Changing view acls to: panda
[2025-06-26T20:20:06.638+0700] {subprocess.py:93} INFO - 25/06/26 20:20:06 INFO SecurityManager: Changing modify acls to: panda
[2025-06-26T20:20:06.638+0700] {subprocess.py:93} INFO - 25/06/26 20:20:06 INFO SecurityManager: Changing view acls groups to:
[2025-06-26T20:20:06.638+0700] {subprocess.py:93} INFO - 25/06/26 20:20:06 INFO SecurityManager: Changing modify acls groups to:
[2025-06-26T20:20:06.638+0700] {subprocess.py:93} INFO - 25/06/26 20:20:06 INFO SecurityManager: SecurityManager: authentication disabled; ui acls disabled; users with view permissions: panda; groups with view permissions: EMPTY; users with modify permissions: panda; groups with modify permissions: EMPTY
[2025-06-26T20:20:06.905+0700] {subprocess.py:93} INFO - 25/06/26 20:20:06 INFO Utils: Successfully started service 'sparkDriver' on port 33429.
[2025-06-26T20:20:06.937+0700] {subprocess.py:93} INFO - 25/06/26 20:20:06 INFO SparkEnv: Registering MapOutputTracker
[2025-06-26T20:20:06.980+0700] {subprocess.py:93} INFO - 25/06/26 20:20:06 INFO SparkEnv: Registering BlockManagerMaster
[2025-06-26T20:20:07.003+0700] {subprocess.py:93} INFO - 25/06/26 20:20:07 INFO BlockManagerMasterEndpoint: Using org.apache.spark.storage.DefaultTopologyMapper for getting topology information
[2025-06-26T20:20:07.004+0700] {subprocess.py:93} INFO - 25/06/26 20:20:07 INFO BlockManagerMasterEndpoint: BlockManagerMasterEndpoint up
[2025-06-26T20:20:07.008+0700] {subprocess.py:93} INFO - 25/06/26 20:20:07 INFO SparkEnv: Registering BlockManagerMasterHeartbeat
[2025-06-26T20:20:07.034+0700] {subprocess.py:93} INFO - 25/06/26 20:20:07 INFO DiskBlockManager: Created local directory at /tmp/blockmgr-49e75e5a-7911-4498-9dd3-a76c89cd8fee
[2025-06-26T20:20:07.051+0700] {subprocess.py:93} INFO - 25/06/26 20:20:07 INFO MemoryStore: MemoryStore started with capacity 434.4 MiB
[2025-06-26T20:20:07.067+0700] {subprocess.py:93} INFO - 25/06/26 20:20:07 INFO SparkEnv: Registering OutputCommitCoordinator
[2025-06-26T20:20:07.246+0700] {subprocess.py:93} INFO - 25/06/26 20:20:07 INFO JettyUtils: Start Jetty 127.0.0.1:4040 for SparkUI
[2025-06-26T20:20:07.307+0700] {subprocess.py:93} INFO - 25/06/26 20:20:07 WARN Utils: Service 'SparkUI' could not bind on port 4040. Attempting port 4041.
[2025-06-26T20:20:07.324+0700] {subprocess.py:93} INFO - 25/06/26 20:20:07 INFO Utils: Successfully started service 'SparkUI' on port 4041.
[2025-06-26T20:20:07.429+0700] {subprocess.py:93} INFO - 25/06/26 20:20:07 INFO Executor: Starting executor ID driver on host localhost
[2025-06-26T20:20:07.430+0700] {subprocess.py:93} INFO - 25/06/26 20:20:07 INFO Executor: OS info Linux, 6.11.0-26-generic, amd64
[2025-06-26T20:20:07.430+0700] {subprocess.py:93} INFO - 25/06/26 20:20:07 INFO Executor: Java version 11.0.27
[2025-06-26T20:20:07.439+0700] {subprocess.py:93} INFO - 25/06/26 20:20:07 INFO Executor: Starting executor with user classpath (userClassPathFirst = false): ''
[2025-06-26T20:20:07.439+0700] {subprocess.py:93} INFO - 25/06/26 20:20:07 INFO Executor: Created or updated repl class loader org.apache.spark.util.MutableURLClassLoader@7a92d242 for default.
[2025-06-26T20:20:07.468+0700] {subprocess.py:93} INFO - 25/06/26 20:20:07 INFO Utils: Successfully started service 'org.apache.spark.network.netty.NettyBlockTransferService' on port 33995.
[2025-06-26T20:20:07.469+0700] {subprocess.py:93} INFO - 25/06/26 20:20:07 INFO NettyBlockTransferService: Server created on localhost:33995
[2025-06-26T20:20:07.470+0700] {subprocess.py:93} INFO - 25/06/26 20:20:07 INFO BlockManager: Using org.apache.spark.storage.RandomBlockReplicationPolicy for block replication policy
[2025-06-26T20:20:07.478+0700] {subprocess.py:93} INFO - 25/06/26 20:20:07 INFO BlockManagerMaster: Registering BlockManager BlockManagerId(driver, localhost, 33995, None)
[2025-06-26T20:20:07.484+0700] {subprocess.py:93} INFO - 25/06/26 20:20:07 INFO BlockManagerMasterEndpoint: Registering block manager localhost:33995 with 434.4 MiB RAM, BlockManagerId(driver, localhost, 33995, None)
[2025-06-26T20:20:07.488+0700] {subprocess.py:93} INFO - 25/06/26 20:20:07 INFO BlockManagerMaster: Registered BlockManager BlockManagerId(driver, localhost, 33995, None)
[2025-06-26T20:20:07.489+0700] {subprocess.py:93} INFO - 25/06/26 20:20:07 INFO BlockManager: Initialized BlockManager: BlockManagerId(driver, localhost, 33995, None)
[2025-06-26T20:20:07.943+0700] {subprocess.py:93} INFO - 25/06/26 20:20:07 INFO SharedState: Setting hive.metastore.warehouse.dir ('null') to the value of spark.sql.warehouse.dir.
[2025-06-26T20:20:07.951+0700] {subprocess.py:93} INFO - 25/06/26 20:20:07 INFO SharedState: Warehouse path is 'file:/tmp/airflowtmpi_n7b0dh/spark-warehouse'.
[2025-06-26T20:20:09.179+0700] {subprocess.py:93} INFO - 25/06/26 20:20:09 INFO MetadataLogFileIndex: Reading streaming file log from hdfs://localhost:9000/transactions_by_hour/_spark_metadata
[2025-06-26T20:20:09.253+0700] {subprocess.py:93} INFO - 25/06/26 20:20:09 INFO FileStreamSinkLog: BatchIds found from listing: 2333, 2334, 2335, 2336, 2337, 2338, 2339, 2340, 2341, 2342, 2343, 2344, 2345, 2346, 2347, 2348, 2349, 2350, 2351, 2352, 2353, 2354, 2355, 2356, 2357, 2358, 2359, 2360, 2361, 2362, 2363, 2364, 2365, 2366, 2367, 2368, 2369, 2370, 2371, 2372, 2373, 2374, 2375, 2376, 2377, 2378, 2379, 2380, 2381, 2382, 2383, 2384, 2385, 2386, 2387, 2388, 2389, 2390, 2391, 2392, 2393, 2394, 2395, 2396, 2397, 2398, 2399, 2400, 2401, 2402, 2403, 2404, 2405, 2406, 2407, 2408, 2409, 2410, 2411, 2412, 2413, 2414, 2415, 2416, 2417, 2418, 2419, 2420, 2421, 2422, 2423, 2424, 2425, 2426, 2427, 2428, 2429, 2430, 2431, 2432, 2433, 2434, 2435, 2436, 2437, 2438, 2439, 2440, 2441, 2442, 2443, 2444, 2445, 2446, 2447, 2448, 2449, 2450, 2451, 2452, 2453, 2454, 2455, 2456, 2457, 2458, 2459, 2460, 2461, 2462, 2463, 2464, 2465, 2466, 2467, 2468, 2469, 2470, 2471, 2472, 2473, 2474, 2475, 2476, 2477, 2478, 2479, 2480, 2481, 2482, 2483, 2484, 2485, 2486, 2487, 2488, 2489, 2490, 2491, 2492, 2493, 2494, 2495, 2496, 2497, 2498, 2499, 2500, 2501, 2502, 2503, 2504, 2505, 2506, 2507, 2508, 2509, 2510, 2511, 2512, 2513, 2514, 2515, 2516, 2517, 2518, 2519, 2520, 2521, 2522, 2523, 2524, 2525, 2526, 2527, 2528, 2529, 2530, 2531, 2532, 2533, 2534, 2535, 2536, 2537, 2538, 2539, 2540, 2541, 2542, 2543, 2544, 2545, 2546, 2547, 2548, 2549, 2550, 2551, 2552, 2553, 2554, 2555, 2556, 2557, 2558, 2559, 2560, 2561, 2562, 2563, 2564, 2565, 2566, 2567, 2568, 2569, 2570, 2571, 2572, 2573, 2574, 2575, 2576, 2577, 2578, 2579, 2580, 2581, 2582, 2583, 2584, 2585, 2586, 2587, 2588, 2589, 2590, 2591, 2592, 2593, 2594, 2595, 2596, 2597, 2598, 2599, 2600, 2601, 2602, 2603, 2604, 2605, 2606, 2607, 2608, 2609, 2610, 2611, 2612, 2613, 2614, 2615, 2616, 2617, 2618, 2619, 2620, 2621, 2622, 2623, 2624, 2625, 2626, 2627, 2628, 2629, 2630, 2631, 2632, 2633, 2634
[2025-06-26T20:20:09.287+0700] {subprocess.py:93} INFO - 25/06/26 20:20:09 INFO FileStreamSinkLog: Set the compact interval to 10 [defaultCompactInterval: 10]
[2025-06-26T20:20:09.918+0700] {subprocess.py:93} INFO - 25/06/26 20:20:09 INFO HadoopFSUtils: Listing leaf files and directories in parallel under 2635 paths. The first several paths are: hdfs://localhost:9000/transactions_by_hour/part-00000-35848e14-b857-426e-8939-db9c96261483-c000.csv, hdfs://localhost:9000/transactions_by_hour/part-00000-d7ab39d9-b4ef-4e2e-b472-4c1883c38273-c000.csv, hdfs://localhost:9000/transactions_by_hour/part-00000-cce2d287-6512-49d1-aa31-f452c0dcdaf9-c000.csv, hdfs://localhost:9000/transactions_by_hour/part-00000-ac8933a1-5bf2-4814-a228-6604c7045e4c-c000.csv, hdfs://localhost:9000/transactions_by_hour/part-00000-9c60d322-8794-4968-a7a5-364181d16d94-c000.csv, hdfs://localhost:9000/transactions_by_hour/part-00000-76895572-6aa7-4225-8325-6962e0c98ee2-c000.csv, hdfs://localhost:9000/transactions_by_hour/part-00000-a92a3ce5-6132-4e9e-8e69-11e47f72f0a2-c000.csv, hdfs://localhost:9000/transactions_by_hour/part-00000-b48a08d4-d847-4307-b612-e35a8f471916-c000.csv, hdfs://localhost:9000/transactions_by_hour/part-00000-e8f1544c-6d23-403f-a02b-06e9bef1638a-c000.csv, hdfs://localhost:9000/transactions_by_hour/part-00000-08040c60-6fee-4dcc-b2e9-af62320fb049-c000.csv.
[2025-06-26T20:20:10.326+0700] {subprocess.py:93} INFO - 25/06/26 20:20:10 INFO SparkContext: Starting job: csv at NativeMethodAccessorImpl.java:0
[2025-06-26T20:20:10.353+0700] {subprocess.py:93} INFO - 25/06/26 20:20:10 INFO DAGScheduler: Got job 0 (csv at NativeMethodAccessorImpl.java:0) with 2635 output partitions
[2025-06-26T20:20:10.353+0700] {subprocess.py:93} INFO - 25/06/26 20:20:10 INFO DAGScheduler: Final stage: ResultStage 0 (csv at NativeMethodAccessorImpl.java:0)
[2025-06-26T20:20:10.354+0700] {subprocess.py:93} INFO - 25/06/26 20:20:10 INFO DAGScheduler: Parents of final stage: List()
[2025-06-26T20:20:10.356+0700] {subprocess.py:93} INFO - 25/06/26 20:20:10 INFO DAGScheduler: Missing parents: List()
[2025-06-26T20:20:10.360+0700] {subprocess.py:93} INFO - 25/06/26 20:20:10 INFO DAGScheduler: Submitting ResultStage 0 (MapPartitionsRDD[1] at csv at NativeMethodAccessorImpl.java:0), which has no missing parents
[2025-06-26T20:20:10.498+0700] {subprocess.py:93} INFO - 25/06/26 20:20:10 INFO MemoryStore: Block broadcast_0 stored as values in memory (estimated size 103.2 KiB, free 434.3 MiB)
[2025-06-26T20:20:10.541+0700] {subprocess.py:93} INFO - 25/06/26 20:20:10 INFO MemoryStore: Block broadcast_0_piece0 stored as bytes in memory (estimated size 37.3 KiB, free 434.3 MiB)
[2025-06-26T20:20:10.544+0700] {subprocess.py:93} INFO - 25/06/26 20:20:10 INFO BlockManagerInfo: Added broadcast_0_piece0 in memory on localhost:33995 (size: 37.3 KiB, free: 434.4 MiB)
[2025-06-26T20:20:10.550+0700] {subprocess.py:93} INFO - 25/06/26 20:20:10 INFO SparkContext: Created broadcast 0 from broadcast at DAGScheduler.scala:1585
[2025-06-26T20:20:10.576+0700] {subprocess.py:93} INFO - 25/06/26 20:20:10 INFO DAGScheduler: Submitting 2635 missing tasks from ResultStage 0 (MapPartitionsRDD[1] at csv at NativeMethodAccessorImpl.java:0) (first 15 tasks are for partitions Vector(0, 1, 2, 3, 4, 5, 6, 7, 8, 9, 10, 11, 12, 13, 14))
[2025-06-26T20:20:10.578+0700] {subprocess.py:93} INFO - 25/06/26 20:20:10 INFO TaskSchedulerImpl: Adding task set 0.0 with 2635 tasks resource profile 0
[2025-06-26T20:20:10.654+0700] {subprocess.py:93} INFO - 25/06/26 20:20:10 INFO TaskSetManager: Starting task 0.0 in stage 0.0 (TID 0) (localhost, executor driver, partition 0, PROCESS_LOCAL, 9215 bytes)
[2025-06-26T20:20:10.658+0700] {subprocess.py:93} INFO - 25/06/26 20:20:10 INFO TaskSetManager: Starting task 1.0 in stage 0.0 (TID 1) (localhost, executor driver, partition 1, PROCESS_LOCAL, 9215 bytes)
[2025-06-26T20:20:10.658+0700] {subprocess.py:93} INFO - 25/06/26 20:20:10 INFO TaskSetManager: Starting task 2.0 in stage 0.0 (TID 2) (localhost, executor driver, partition 2, PROCESS_LOCAL, 9215 bytes)
[2025-06-26T20:20:10.659+0700] {subprocess.py:93} INFO - 25/06/26 20:20:10 INFO TaskSetManager: Starting task 3.0 in stage 0.0 (TID 3) (localhost, executor driver, partition 3, PROCESS_LOCAL, 9215 bytes)
[2025-06-26T20:20:10.659+0700] {subprocess.py:93} INFO - 25/06/26 20:20:10 INFO TaskSetManager: Starting task 4.0 in stage 0.0 (TID 4) (localhost, executor driver, partition 4, PROCESS_LOCAL, 9215 bytes)
[2025-06-26T20:20:10.659+0700] {subprocess.py:93} INFO - 25/06/26 20:20:10 INFO TaskSetManager: Starting task 5.0 in stage 0.0 (TID 5) (localhost, executor driver, partition 5, PROCESS_LOCAL, 9215 bytes)
[2025-06-26T20:20:10.660+0700] {subprocess.py:93} INFO - 25/06/26 20:20:10 INFO TaskSetManager: Starting task 6.0 in stage 0.0 (TID 6) (localhost, executor driver, partition 6, PROCESS_LOCAL, 9215 bytes)
[2025-06-26T20:20:10.661+0700] {subprocess.py:93} INFO - 25/06/26 20:20:10 INFO TaskSetManager: Starting task 7.0 in stage 0.0 (TID 7) (localhost, executor driver, partition 7, PROCESS_LOCAL, 9215 bytes)
[2025-06-26T20:20:10.661+0700] {subprocess.py:93} INFO - 25/06/26 20:20:10 INFO TaskSetManager: Starting task 8.0 in stage 0.0 (TID 8) (localhost, executor driver, partition 8, PROCESS_LOCAL, 9215 bytes)
[2025-06-26T20:20:10.662+0700] {subprocess.py:93} INFO - 25/06/26 20:20:10 INFO TaskSetManager: Starting task 9.0 in stage 0.0 (TID 9) (localhost, executor driver, partition 9, PROCESS_LOCAL, 9215 bytes)
[2025-06-26T20:20:10.662+0700] {subprocess.py:93} INFO - 25/06/26 20:20:10 INFO TaskSetManager: Starting task 10.0 in stage 0.0 (TID 10) (localhost, executor driver, partition 10, PROCESS_LOCAL, 9215 bytes)
[2025-06-26T20:20:10.663+0700] {subprocess.py:93} INFO - 25/06/26 20:20:10 INFO TaskSetManager: Starting task 11.0 in stage 0.0 (TID 11) (localhost, executor driver, partition 11, PROCESS_LOCAL, 9215 bytes)
[2025-06-26T20:20:10.663+0700] {subprocess.py:93} INFO - 25/06/26 20:20:10 INFO TaskSetManager: Starting task 12.0 in stage 0.0 (TID 12) (localhost, executor driver, partition 12, PROCESS_LOCAL, 9215 bytes)
[2025-06-26T20:20:10.663+0700] {subprocess.py:93} INFO - 25/06/26 20:20:10 INFO TaskSetManager: Starting task 13.0 in stage 0.0 (TID 13) (localhost, executor driver, partition 13, PROCESS_LOCAL, 9215 bytes)
[2025-06-26T20:20:10.664+0700] {subprocess.py:93} INFO - 25/06/26 20:20:10 INFO TaskSetManager: Starting task 14.0 in stage 0.0 (TID 14) (localhost, executor driver, partition 14, PROCESS_LOCAL, 9215 bytes)
[2025-06-26T20:20:10.665+0700] {subprocess.py:93} INFO - 25/06/26 20:20:10 INFO TaskSetManager: Starting task 15.0 in stage 0.0 (TID 15) (localhost, executor driver, partition 15, PROCESS_LOCAL, 9215 bytes)
[2025-06-26T20:20:10.666+0700] {subprocess.py:93} INFO - 25/06/26 20:20:10 INFO TaskSetManager: Starting task 16.0 in stage 0.0 (TID 16) (localhost, executor driver, partition 16, PROCESS_LOCAL, 9215 bytes)
[2025-06-26T20:20:10.666+0700] {subprocess.py:93} INFO - 25/06/26 20:20:10 INFO TaskSetManager: Starting task 17.0 in stage 0.0 (TID 17) (localhost, executor driver, partition 17, PROCESS_LOCAL, 9215 bytes)
[2025-06-26T20:20:10.666+0700] {subprocess.py:93} INFO - 25/06/26 20:20:10 INFO TaskSetManager: Starting task 18.0 in stage 0.0 (TID 18) (localhost, executor driver, partition 18, PROCESS_LOCAL, 9215 bytes)
[2025-06-26T20:20:10.667+0700] {subprocess.py:93} INFO - 25/06/26 20:20:10 INFO TaskSetManager: Starting task 19.0 in stage 0.0 (TID 19) (localhost, executor driver, partition 19, PROCESS_LOCAL, 9215 bytes)
[2025-06-26T20:20:10.667+0700] {subprocess.py:93} INFO - 25/06/26 20:20:10 INFO TaskSetManager: Starting task 20.0 in stage 0.0 (TID 20) (localhost, executor driver, partition 20, PROCESS_LOCAL, 9215 bytes)
[2025-06-26T20:20:10.668+0700] {subprocess.py:93} INFO - 25/06/26 20:20:10 INFO TaskSetManager: Starting task 21.0 in stage 0.0 (TID 21) (localhost, executor driver, partition 21, PROCESS_LOCAL, 9215 bytes)
[2025-06-26T20:20:10.687+0700] {subprocess.py:93} INFO - 25/06/26 20:20:10 INFO Executor: Running task 15.0 in stage 0.0 (TID 15)
[2025-06-26T20:20:10.688+0700] {subprocess.py:93} INFO - 25/06/26 20:20:10 INFO Executor: Running task 18.0 in stage 0.0 (TID 18)
[2025-06-26T20:20:10.688+0700] {subprocess.py:93} INFO - 25/06/26 20:20:10 INFO Executor: Running task 3.0 in stage 0.0 (TID 3)
[2025-06-26T20:20:10.688+0700] {subprocess.py:93} INFO - 25/06/26 20:20:10 INFO Executor: Running task 13.0 in stage 0.0 (TID 13)
[2025-06-26T20:20:10.688+0700] {subprocess.py:93} INFO - 25/06/26 20:20:10 INFO Executor: Running task 11.0 in stage 0.0 (TID 11)
[2025-06-26T20:20:10.688+0700] {subprocess.py:93} INFO - 25/06/26 20:20:10 INFO Executor: Running task 12.0 in stage 0.0 (TID 12)
[2025-06-26T20:20:10.688+0700] {subprocess.py:93} INFO - 25/06/26 20:20:10 INFO Executor: Running task 1.0 in stage 0.0 (TID 1)
[2025-06-26T20:20:10.688+0700] {subprocess.py:93} INFO - 25/06/26 20:20:10 INFO Executor: Running task 7.0 in stage 0.0 (TID 7)
[2025-06-26T20:20:10.688+0700] {subprocess.py:93} INFO - 25/06/26 20:20:10 INFO Executor: Running task 5.0 in stage 0.0 (TID 5)
[2025-06-26T20:20:10.688+0700] {subprocess.py:93} INFO - 25/06/26 20:20:10 INFO Executor: Running task 14.0 in stage 0.0 (TID 14)
[2025-06-26T20:20:10.688+0700] {subprocess.py:93} INFO - 25/06/26 20:20:10 INFO Executor: Running task 10.0 in stage 0.0 (TID 10)
[2025-06-26T20:20:10.688+0700] {subprocess.py:93} INFO - 25/06/26 20:20:10 INFO Executor: Running task 2.0 in stage 0.0 (TID 2)
[2025-06-26T20:20:10.688+0700] {subprocess.py:93} INFO - 25/06/26 20:20:10 INFO Executor: Running task 0.0 in stage 0.0 (TID 0)
[2025-06-26T20:20:10.689+0700] {subprocess.py:93} INFO - 25/06/26 20:20:10 INFO Executor: Running task 4.0 in stage 0.0 (TID 4)
[2025-06-26T20:20:10.689+0700] {subprocess.py:93} INFO - 25/06/26 20:20:10 INFO Executor: Running task 6.0 in stage 0.0 (TID 6)
[2025-06-26T20:20:10.689+0700] {subprocess.py:93} INFO - 25/06/26 20:20:10 INFO Executor: Running task 9.0 in stage 0.0 (TID 9)
[2025-06-26T20:20:10.689+0700] {subprocess.py:93} INFO - 25/06/26 20:20:10 INFO Executor: Running task 16.0 in stage 0.0 (TID 16)
[2025-06-26T20:20:10.689+0700] {subprocess.py:93} INFO - 25/06/26 20:20:10 INFO Executor: Running task 20.0 in stage 0.0 (TID 20)
[2025-06-26T20:20:10.689+0700] {subprocess.py:93} INFO - 25/06/26 20:20:10 INFO Executor: Running task 19.0 in stage 0.0 (TID 19)
[2025-06-26T20:20:10.689+0700] {subprocess.py:93} INFO - 25/06/26 20:20:10 INFO Executor: Running task 21.0 in stage 0.0 (TID 21)
[2025-06-26T20:20:10.689+0700] {subprocess.py:93} INFO - 25/06/26 20:20:10 INFO Executor: Running task 8.0 in stage 0.0 (TID 8)
[2025-06-26T20:20:10.689+0700] {subprocess.py:93} INFO - 25/06/26 20:20:10 INFO Executor: Running task 17.0 in stage 0.0 (TID 17)
[2025-06-26T20:20:11.074+0700] {subprocess.py:93} INFO - 25/06/26 20:20:11 INFO Executor: Finished task 12.0 in stage 0.0 (TID 12). 3261 bytes result sent to driver
[2025-06-26T20:20:11.075+0700] {subprocess.py:93} INFO - 25/06/26 20:20:11 INFO Executor: Finished task 3.0 in stage 0.0 (TID 3). 3261 bytes result sent to driver
[2025-06-26T20:20:11.075+0700] {subprocess.py:93} INFO - 25/06/26 20:20:11 INFO Executor: Finished task 0.0 in stage 0.0 (TID 0). 3261 bytes result sent to driver
[2025-06-26T20:20:11.075+0700] {subprocess.py:93} INFO - 25/06/26 20:20:11 INFO Executor: Finished task 18.0 in stage 0.0 (TID 18). 3261 bytes result sent to driver
[2025-06-26T20:20:11.075+0700] {subprocess.py:93} INFO - 25/06/26 20:20:11 INFO Executor: Finished task 10.0 in stage 0.0 (TID 10). 3261 bytes result sent to driver
[2025-06-26T20:20:11.075+0700] {subprocess.py:93} INFO - 25/06/26 20:20:11 INFO Executor: Finished task 6.0 in stage 0.0 (TID 6). 3261 bytes result sent to driver
[2025-06-26T20:20:11.075+0700] {subprocess.py:93} INFO - 25/06/26 20:20:11 INFO Executor: Finished task 16.0 in stage 0.0 (TID 16). 3261 bytes result sent to driver
[2025-06-26T20:20:11.075+0700] {subprocess.py:93} INFO - 25/06/26 20:20:11 INFO Executor: Finished task 14.0 in stage 0.0 (TID 14). 3261 bytes result sent to driver
[2025-06-26T20:20:11.075+0700] {subprocess.py:93} INFO - 25/06/26 20:20:11 INFO Executor: Finished task 21.0 in stage 0.0 (TID 21). 3261 bytes result sent to driver
[2025-06-26T20:20:11.076+0700] {subprocess.py:93} INFO - 25/06/26 20:20:11 INFO Executor: Finished task 4.0 in stage 0.0 (TID 4). 3261 bytes result sent to driver
[2025-06-26T20:20:11.076+0700] {subprocess.py:93} INFO - 25/06/26 20:20:11 INFO Executor: Finished task 11.0 in stage 0.0 (TID 11). 3261 bytes result sent to driver
[2025-06-26T20:20:11.076+0700] {subprocess.py:93} INFO - 25/06/26 20:20:11 INFO Executor: Finished task 5.0 in stage 0.0 (TID 5). 3261 bytes result sent to driver
[2025-06-26T20:20:11.076+0700] {subprocess.py:93} INFO - 25/06/26 20:20:11 INFO Executor: Finished task 19.0 in stage 0.0 (TID 19). 3261 bytes result sent to driver
[2025-06-26T20:20:11.076+0700] {subprocess.py:93} INFO - 25/06/26 20:20:11 INFO Executor: Finished task 15.0 in stage 0.0 (TID 15). 3261 bytes result sent to driver
[2025-06-26T20:20:11.076+0700] {subprocess.py:93} INFO - 25/06/26 20:20:11 INFO Executor: Finished task 9.0 in stage 0.0 (TID 9). 3261 bytes result sent to driver
[2025-06-26T20:20:11.076+0700] {subprocess.py:93} INFO - 25/06/26 20:20:11 INFO Executor: Finished task 8.0 in stage 0.0 (TID 8). 3261 bytes result sent to driver
[2025-06-26T20:20:11.076+0700] {subprocess.py:93} INFO - 25/06/26 20:20:11 INFO Executor: Finished task 7.0 in stage 0.0 (TID 7). 3261 bytes result sent to driver
[2025-06-26T20:20:11.076+0700] {subprocess.py:93} INFO - 25/06/26 20:20:11 INFO Executor: Finished task 2.0 in stage 0.0 (TID 2). 3261 bytes result sent to driver
[2025-06-26T20:20:11.076+0700] {subprocess.py:93} INFO - 25/06/26 20:20:11 INFO Executor: Finished task 17.0 in stage 0.0 (TID 17). 3261 bytes result sent to driver
[2025-06-26T20:20:11.076+0700] {subprocess.py:93} INFO - 25/06/26 20:20:11 INFO Executor: Finished task 1.0 in stage 0.0 (TID 1). 3261 bytes result sent to driver
[2025-06-26T20:20:11.077+0700] {subprocess.py:93} INFO - 25/06/26 20:20:11 INFO Executor: Finished task 13.0 in stage 0.0 (TID 13). 3261 bytes result sent to driver
[2025-06-26T20:20:11.077+0700] {subprocess.py:93} INFO - 25/06/26 20:20:11 INFO Executor: Finished task 20.0 in stage 0.0 (TID 20). 3261 bytes result sent to driver
[2025-06-26T20:20:11.084+0700] {subprocess.py:93} INFO - 25/06/26 20:20:11 INFO TaskSetManager: Starting task 22.0 in stage 0.0 (TID 22) (localhost, executor driver, partition 22, PROCESS_LOCAL, 9215 bytes)
[2025-06-26T20:20:11.085+0700] {subprocess.py:93} INFO - 25/06/26 20:20:11 INFO Executor: Running task 22.0 in stage 0.0 (TID 22)
[2025-06-26T20:20:11.087+0700] {subprocess.py:93} INFO - 25/06/26 20:20:11 INFO TaskSetManager: Starting task 23.0 in stage 0.0 (TID 23) (localhost, executor driver, partition 23, PROCESS_LOCAL, 9215 bytes)
[2025-06-26T20:20:11.087+0700] {subprocess.py:93} INFO - 25/06/26 20:20:11 INFO Executor: Running task 23.0 in stage 0.0 (TID 23)
[2025-06-26T20:20:11.089+0700] {subprocess.py:93} INFO - 25/06/26 20:20:11 INFO TaskSetManager: Starting task 24.0 in stage 0.0 (TID 24) (localhost, executor driver, partition 24, PROCESS_LOCAL, 9215 bytes)
[2025-06-26T20:20:11.090+0700] {subprocess.py:93} INFO - 25/06/26 20:20:11 INFO Executor: Running task 24.0 in stage 0.0 (TID 24)
[2025-06-26T20:20:11.091+0700] {subprocess.py:93} INFO - 25/06/26 20:20:11 INFO TaskSetManager: Starting task 25.0 in stage 0.0 (TID 25) (localhost, executor driver, partition 25, PROCESS_LOCAL, 9215 bytes)
[2025-06-26T20:20:11.092+0700] {subprocess.py:93} INFO - 25/06/26 20:20:11 INFO Executor: Running task 25.0 in stage 0.0 (TID 25)
[2025-06-26T20:20:11.093+0700] {subprocess.py:93} INFO - 25/06/26 20:20:11 INFO TaskSetManager: Starting task 26.0 in stage 0.0 (TID 26) (localhost, executor driver, partition 26, PROCESS_LOCAL, 9215 bytes)
[2025-06-26T20:20:11.093+0700] {subprocess.py:93} INFO - 25/06/26 20:20:11 INFO Executor: Running task 26.0 in stage 0.0 (TID 26)
[2025-06-26T20:20:11.094+0700] {subprocess.py:93} INFO - 25/06/26 20:20:11 INFO TaskSetManager: Finished task 20.0 in stage 0.0 (TID 20) in 426 ms on localhost (executor driver) (1/2635)
[2025-06-26T20:20:11.097+0700] {subprocess.py:93} INFO - 25/06/26 20:20:11 INFO TaskSetManager: Starting task 27.0 in stage 0.0 (TID 27) (localhost, executor driver, partition 27, PROCESS_LOCAL, 9215 bytes)
[2025-06-26T20:20:11.098+0700] {subprocess.py:93} INFO - 25/06/26 20:20:11 INFO TaskSetManager: Finished task 8.0 in stage 0.0 (TID 8) in 437 ms on localhost (executor driver) (2/2635)
[2025-06-26T20:20:11.098+0700] {subprocess.py:93} INFO - 25/06/26 20:20:11 INFO Executor: Running task 27.0 in stage 0.0 (TID 27)
[2025-06-26T20:20:11.098+0700] {subprocess.py:93} INFO - 25/06/26 20:20:11 INFO TaskSetManager: Finished task 4.0 in stage 0.0 (TID 4) in 439 ms on localhost (executor driver) (3/2635)
[2025-06-26T20:20:11.099+0700] {subprocess.py:93} INFO - 25/06/26 20:20:11 INFO TaskSetManager: Finished task 15.0 in stage 0.0 (TID 15) in 434 ms on localhost (executor driver) (4/2635)
[2025-06-26T20:20:11.099+0700] {subprocess.py:93} INFO - 25/06/26 20:20:11 INFO TaskSetManager: Starting task 28.0 in stage 0.0 (TID 28) (localhost, executor driver, partition 28, PROCESS_LOCAL, 9215 bytes)
[2025-06-26T20:20:11.100+0700] {subprocess.py:93} INFO - 25/06/26 20:20:11 INFO TaskSetManager: Finished task 13.0 in stage 0.0 (TID 13) in 436 ms on localhost (executor driver) (5/2635)
[2025-06-26T20:20:11.100+0700] {subprocess.py:93} INFO - 25/06/26 20:20:11 INFO TaskSetManager: Finished task 19.0 in stage 0.0 (TID 19) in 434 ms on localhost (executor driver) (6/2635)
[2025-06-26T20:20:11.100+0700] {subprocess.py:93} INFO - 25/06/26 20:20:11 INFO Executor: Running task 28.0 in stage 0.0 (TID 28)
[2025-06-26T20:20:11.101+0700] {subprocess.py:93} INFO - 25/06/26 20:20:11 INFO TaskSetManager: Starting task 29.0 in stage 0.0 (TID 29) (localhost, executor driver, partition 29, PROCESS_LOCAL, 9215 bytes)
[2025-06-26T20:20:11.102+0700] {subprocess.py:93} INFO - 25/06/26 20:20:11 INFO TaskSetManager: Finished task 14.0 in stage 0.0 (TID 14) in 439 ms on localhost (executor driver) (7/2635)
[2025-06-26T20:20:11.102+0700] {subprocess.py:93} INFO - 25/06/26 20:20:11 INFO Executor: Running task 29.0 in stage 0.0 (TID 29)
[2025-06-26T20:20:11.103+0700] {subprocess.py:93} INFO - 25/06/26 20:20:11 INFO TaskSetManager: Starting task 30.0 in stage 0.0 (TID 30) (localhost, executor driver, partition 30, PROCESS_LOCAL, 9215 bytes)
[2025-06-26T20:20:11.103+0700] {subprocess.py:93} INFO - 25/06/26 20:20:11 INFO TaskSetManager: Finished task 7.0 in stage 0.0 (TID 7) in 442 ms on localhost (executor driver) (8/2635)
[2025-06-26T20:20:11.104+0700] {subprocess.py:93} INFO - 25/06/26 20:20:11 INFO Executor: Running task 30.0 in stage 0.0 (TID 30)
[2025-06-26T20:20:11.104+0700] {subprocess.py:93} INFO - 25/06/26 20:20:11 INFO TaskSetManager: Finished task 6.0 in stage 0.0 (TID 6) in 444 ms on localhost (executor driver) (9/2635)
[2025-06-26T20:20:11.105+0700] {subprocess.py:93} INFO - 25/06/26 20:20:11 INFO TaskSetManager: Starting task 31.0 in stage 0.0 (TID 31) (localhost, executor driver, partition 31, PROCESS_LOCAL, 9215 bytes)
[2025-06-26T20:20:11.106+0700] {subprocess.py:93} INFO - 25/06/26 20:20:11 INFO TaskSetManager: Starting task 32.0 in stage 0.0 (TID 32) (localhost, executor driver, partition 32, PROCESS_LOCAL, 9215 bytes)
[2025-06-26T20:20:11.106+0700] {subprocess.py:93} INFO - 25/06/26 20:20:11 INFO Executor: Running task 31.0 in stage 0.0 (TID 31)
[2025-06-26T20:20:11.107+0700] {subprocess.py:93} INFO - 25/06/26 20:20:11 INFO Executor: Running task 32.0 in stage 0.0 (TID 32)
[2025-06-26T20:20:11.107+0700] {subprocess.py:93} INFO - 25/06/26 20:20:11 INFO Executor: Finished task 22.0 in stage 0.0 (TID 22). 3218 bytes result sent to driver
[2025-06-26T20:20:11.110+0700] {subprocess.py:93} INFO - 25/06/26 20:20:11 INFO TaskSetManager: Starting task 33.0 in stage 0.0 (TID 33) (localhost, executor driver, partition 33, PROCESS_LOCAL, 9215 bytes)
[2025-06-26T20:20:11.110+0700] {subprocess.py:93} INFO - 25/06/26 20:20:11 INFO TaskSetManager: Finished task 12.0 in stage 0.0 (TID 12) in 447 ms on localhost (executor driver) (10/2635)
[2025-06-26T20:20:11.111+0700] {subprocess.py:93} INFO - 25/06/26 20:20:11 INFO Executor: Running task 33.0 in stage 0.0 (TID 33)
[2025-06-26T20:20:11.111+0700] {subprocess.py:93} INFO - 25/06/26 20:20:11 INFO TaskSetManager: Starting task 34.0 in stage 0.0 (TID 34) (localhost, executor driver, partition 34, PROCESS_LOCAL, 9215 bytes)
[2025-06-26T20:20:11.113+0700] {subprocess.py:93} INFO - 25/06/26 20:20:11 INFO Executor: Running task 34.0 in stage 0.0 (TID 34)
[2025-06-26T20:20:11.113+0700] {subprocess.py:93} INFO - 25/06/26 20:20:11 INFO TaskSetManager: Starting task 35.0 in stage 0.0 (TID 35) (localhost, executor driver, partition 35, PROCESS_LOCAL, 9215 bytes)
[2025-06-26T20:20:11.114+0700] {subprocess.py:93} INFO - 25/06/26 20:20:11 INFO Executor: Running task 35.0 in stage 0.0 (TID 35)
[2025-06-26T20:20:11.114+0700] {subprocess.py:93} INFO - 25/06/26 20:20:11 INFO TaskSetManager: Starting task 36.0 in stage 0.0 (TID 36) (localhost, executor driver, partition 36, PROCESS_LOCAL, 9215 bytes)
[2025-06-26T20:20:11.114+0700] {subprocess.py:93} INFO - 25/06/26 20:20:11 INFO Executor: Finished task 23.0 in stage 0.0 (TID 23). 3218 bytes result sent to driver
[2025-06-26T20:20:11.114+0700] {subprocess.py:93} INFO - 25/06/26 20:20:11 INFO Executor: Running task 36.0 in stage 0.0 (TID 36)
[2025-06-26T20:20:11.119+0700] {subprocess.py:93} INFO - 25/06/26 20:20:11 INFO TaskSetManager: Starting task 37.0 in stage 0.0 (TID 37) (localhost, executor driver, partition 37, PROCESS_LOCAL, 9215 bytes)
[2025-06-26T20:20:11.121+0700] {subprocess.py:93} INFO - 25/06/26 20:20:11 INFO TaskSetManager: Finished task 5.0 in stage 0.0 (TID 5) in 461 ms on localhost (executor driver) (11/2635)
[2025-06-26T20:20:11.122+0700] {subprocess.py:93} INFO - 25/06/26 20:20:11 INFO TaskSetManager: Finished task 21.0 in stage 0.0 (TID 21) in 454 ms on localhost (executor driver) (12/2635)
[2025-06-26T20:20:11.125+0700] {subprocess.py:93} INFO - 25/06/26 20:20:11 INFO Executor: Running task 37.0 in stage 0.0 (TID 37)
[2025-06-26T20:20:11.126+0700] {subprocess.py:93} INFO - 25/06/26 20:20:11 INFO TaskSetManager: Starting task 38.0 in stage 0.0 (TID 38) (localhost, executor driver, partition 38, PROCESS_LOCAL, 9215 bytes)
[2025-06-26T20:20:11.137+0700] {subprocess.py:93} INFO - 25/06/26 20:20:11 INFO Executor: Running task 38.0 in stage 0.0 (TID 38)
[2025-06-26T20:20:11.137+0700] {subprocess.py:93} INFO - 25/06/26 20:20:11 INFO TaskSetManager: Finished task 2.0 in stage 0.0 (TID 2) in 479 ms on localhost (executor driver) (13/2635)
[2025-06-26T20:20:11.140+0700] {subprocess.py:93} INFO - 25/06/26 20:20:11 INFO TaskSetManager: Starting task 39.0 in stage 0.0 (TID 39) (localhost, executor driver, partition 39, PROCESS_LOCAL, 9215 bytes)
[2025-06-26T20:20:11.140+0700] {subprocess.py:93} INFO - 25/06/26 20:20:11 INFO TaskSetManager: Finished task 10.0 in stage 0.0 (TID 10) in 478 ms on localhost (executor driver) (14/2635)
[2025-06-26T20:20:11.141+0700] {subprocess.py:93} INFO - 25/06/26 20:20:11 INFO TaskSetManager: Finished task 0.0 in stage 0.0 (TID 0) in 512 ms on localhost (executor driver) (15/2635)
[2025-06-26T20:20:11.141+0700] {subprocess.py:93} INFO - 25/06/26 20:20:11 INFO TaskSetManager: Finished task 11.0 in stage 0.0 (TID 11) in 479 ms on localhost (executor driver) (16/2635)
[2025-06-26T20:20:11.142+0700] {subprocess.py:93} INFO - 25/06/26 20:20:11 INFO Executor: Running task 39.0 in stage 0.0 (TID 39)
[2025-06-26T20:20:11.142+0700] {subprocess.py:93} INFO - 25/06/26 20:20:11 INFO TaskSetManager: Finished task 1.0 in stage 0.0 (TID 1) in 485 ms on localhost (executor driver) (17/2635)
[2025-06-26T20:20:11.145+0700] {subprocess.py:93} INFO - 25/06/26 20:20:11 INFO TaskSetManager: Finished task 16.0 in stage 0.0 (TID 16) in 477 ms on localhost (executor driver) (18/2635)
[2025-06-26T20:20:11.148+0700] {subprocess.py:93} INFO - 25/06/26 20:20:11 INFO TaskSetManager: Starting task 40.0 in stage 0.0 (TID 40) (localhost, executor driver, partition 40, PROCESS_LOCAL, 9215 bytes)
[2025-06-26T20:20:11.150+0700] {subprocess.py:93} INFO - 25/06/26 20:20:11 INFO Executor: Running task 40.0 in stage 0.0 (TID 40)
[2025-06-26T20:20:11.152+0700] {subprocess.py:93} INFO - 25/06/26 20:20:11 INFO Executor: Finished task 24.0 in stage 0.0 (TID 24). 3218 bytes result sent to driver
[2025-06-26T20:20:11.154+0700] {subprocess.py:93} INFO - 25/06/26 20:20:11 INFO TaskSetManager: Starting task 41.0 in stage 0.0 (TID 41) (localhost, executor driver, partition 41, PROCESS_LOCAL, 9215 bytes)
[2025-06-26T20:20:11.155+0700] {subprocess.py:93} INFO - 25/06/26 20:20:11 INFO Executor: Running task 41.0 in stage 0.0 (TID 41)
[2025-06-26T20:20:11.155+0700] {subprocess.py:93} INFO - 25/06/26 20:20:11 INFO TaskSetManager: Starting task 42.0 in stage 0.0 (TID 42) (localhost, executor driver, partition 42, PROCESS_LOCAL, 9215 bytes)
[2025-06-26T20:20:11.156+0700] {subprocess.py:93} INFO - 25/06/26 20:20:11 INFO TaskSetManager: Starting task 43.0 in stage 0.0 (TID 43) (localhost, executor driver, partition 43, PROCESS_LOCAL, 9215 bytes)
[2025-06-26T20:20:11.160+0700] {subprocess.py:93} INFO - 25/06/26 20:20:11 INFO Executor: Running task 43.0 in stage 0.0 (TID 43)
[2025-06-26T20:20:11.160+0700] {subprocess.py:93} INFO - 25/06/26 20:20:11 INFO Executor: Running task 42.0 in stage 0.0 (TID 42)
[2025-06-26T20:20:11.160+0700] {subprocess.py:93} INFO - 25/06/26 20:20:11 INFO TaskSetManager: Finished task 17.0 in stage 0.0 (TID 17) in 491 ms on localhost (executor driver) (19/2635)
[2025-06-26T20:20:11.160+0700] {subprocess.py:93} INFO - 25/06/26 20:20:11 INFO TaskSetManager: Finished task 3.0 in stage 0.0 (TID 3) in 499 ms on localhost (executor driver) (20/2635)
[2025-06-26T20:20:11.160+0700] {subprocess.py:93} INFO - 25/06/26 20:20:11 INFO TaskSetManager: Starting task 44.0 in stage 0.0 (TID 44) (localhost, executor driver, partition 44, PROCESS_LOCAL, 9215 bytes)
[2025-06-26T20:20:11.160+0700] {subprocess.py:93} INFO - 25/06/26 20:20:11 INFO TaskSetManager: Finished task 18.0 in stage 0.0 (TID 18) in 493 ms on localhost (executor driver) (21/2635)
[2025-06-26T20:20:11.161+0700] {subprocess.py:93} INFO - 25/06/26 20:20:11 INFO Executor: Running task 44.0 in stage 0.0 (TID 44)
[2025-06-26T20:20:11.161+0700] {subprocess.py:93} INFO - 25/06/26 20:20:11 INFO TaskSetManager: Finished task 22.0 in stage 0.0 (TID 22) in 78 ms on localhost (executor driver) (22/2635)
[2025-06-26T20:20:11.165+0700] {subprocess.py:93} INFO - 25/06/26 20:20:11 INFO TaskSetManager: Starting task 45.0 in stage 0.0 (TID 45) (localhost, executor driver, partition 45, PROCESS_LOCAL, 9215 bytes)
[2025-06-26T20:20:11.169+0700] {subprocess.py:93} INFO - 25/06/26 20:20:11 INFO Executor: Running task 45.0 in stage 0.0 (TID 45)
[2025-06-26T20:20:11.172+0700] {subprocess.py:93} INFO - 25/06/26 20:20:11 INFO TaskSetManager: Starting task 46.0 in stage 0.0 (TID 46) (localhost, executor driver, partition 46, PROCESS_LOCAL, 9215 bytes)
[2025-06-26T20:20:11.173+0700] {subprocess.py:93} INFO - 25/06/26 20:20:11 INFO Executor: Running task 46.0 in stage 0.0 (TID 46)
[2025-06-26T20:20:11.173+0700] {subprocess.py:93} INFO - 25/06/26 20:20:11 INFO TaskSetManager: Finished task 23.0 in stage 0.0 (TID 23) in 85 ms on localhost (executor driver) (23/2635)
[2025-06-26T20:20:11.174+0700] {subprocess.py:93} INFO - 25/06/26 20:20:11 INFO TaskSetManager: Finished task 24.0 in stage 0.0 (TID 24) in 84 ms on localhost (executor driver) (24/2635)
[2025-06-26T20:20:11.174+0700] {subprocess.py:93} INFO - 25/06/26 20:20:11 INFO Executor: Finished task 26.0 in stage 0.0 (TID 26). 3261 bytes result sent to driver
[2025-06-26T20:20:11.185+0700] {subprocess.py:93} INFO - 25/06/26 20:20:11 INFO TaskSetManager: Starting task 47.0 in stage 0.0 (TID 47) (localhost, executor driver, partition 47, PROCESS_LOCAL, 9215 bytes)
[2025-06-26T20:20:11.186+0700] {subprocess.py:93} INFO - 25/06/26 20:20:11 INFO TaskSetManager: Finished task 9.0 in stage 0.0 (TID 9) in 524 ms on localhost (executor driver) (25/2635)
[2025-06-26T20:20:11.186+0700] {subprocess.py:93} INFO - 25/06/26 20:20:11 INFO Executor: Running task 47.0 in stage 0.0 (TID 47)
[2025-06-26T20:20:11.186+0700] {subprocess.py:93} INFO - 25/06/26 20:20:11 INFO Executor: Finished task 25.0 in stage 0.0 (TID 25). 3218 bytes result sent to driver
[2025-06-26T20:20:11.187+0700] {subprocess.py:93} INFO - 25/06/26 20:20:11 INFO TaskSetManager: Finished task 26.0 in stage 0.0 (TID 26) in 94 ms on localhost (executor driver) (26/2635)
[2025-06-26T20:20:11.190+0700] {subprocess.py:93} INFO - 25/06/26 20:20:11 INFO TaskSetManager: Starting task 48.0 in stage 0.0 (TID 48) (localhost, executor driver, partition 48, PROCESS_LOCAL, 9215 bytes)
[2025-06-26T20:20:11.191+0700] {subprocess.py:93} INFO - 25/06/26 20:20:11 INFO Executor: Running task 48.0 in stage 0.0 (TID 48)
[2025-06-26T20:20:11.191+0700] {subprocess.py:93} INFO - 25/06/26 20:20:11 INFO TaskSetManager: Finished task 25.0 in stage 0.0 (TID 25) in 100 ms on localhost (executor driver) (27/2635)
[2025-06-26T20:20:11.199+0700] {subprocess.py:93} INFO - 25/06/26 20:20:11 INFO Executor: Finished task 27.0 in stage 0.0 (TID 27). 3218 bytes result sent to driver
[2025-06-26T20:20:11.199+0700] {subprocess.py:93} INFO - 25/06/26 20:20:11 INFO TaskSetManager: Starting task 49.0 in stage 0.0 (TID 49) (localhost, executor driver, partition 49, PROCESS_LOCAL, 9215 bytes)
[2025-06-26T20:20:11.199+0700] {subprocess.py:93} INFO - 25/06/26 20:20:11 INFO TaskSetManager: Finished task 27.0 in stage 0.0 (TID 27) in 101 ms on localhost (executor driver) (28/2635)
[2025-06-26T20:20:11.203+0700] {subprocess.py:93} INFO - 25/06/26 20:20:11 INFO Executor: Finished task 28.0 in stage 0.0 (TID 28). 3218 bytes result sent to driver
[2025-06-26T20:20:11.204+0700] {subprocess.py:93} INFO - 25/06/26 20:20:11 INFO Executor: Running task 49.0 in stage 0.0 (TID 49)
[2025-06-26T20:20:11.209+0700] {subprocess.py:93} INFO - 25/06/26 20:20:11 INFO TaskSetManager: Starting task 50.0 in stage 0.0 (TID 50) (localhost, executor driver, partition 50, PROCESS_LOCAL, 9215 bytes)
[2025-06-26T20:20:11.210+0700] {subprocess.py:93} INFO - 25/06/26 20:20:11 INFO TaskSetManager: Finished task 28.0 in stage 0.0 (TID 28) in 109 ms on localhost (executor driver) (29/2635)
[2025-06-26T20:20:11.210+0700] {subprocess.py:93} INFO - 25/06/26 20:20:11 INFO Executor: Finished task 34.0 in stage 0.0 (TID 34). 3261 bytes result sent to driver
[2025-06-26T20:20:11.214+0700] {subprocess.py:93} INFO - 25/06/26 20:20:11 INFO Executor: Running task 50.0 in stage 0.0 (TID 50)
[2025-06-26T20:20:11.214+0700] {subprocess.py:93} INFO - 25/06/26 20:20:11 INFO TaskSetManager: Starting task 51.0 in stage 0.0 (TID 51) (localhost, executor driver, partition 51, PROCESS_LOCAL, 9215 bytes)
[2025-06-26T20:20:11.214+0700] {subprocess.py:93} INFO - 25/06/26 20:20:11 INFO TaskSetManager: Finished task 34.0 in stage 0.0 (TID 34) in 102 ms on localhost (executor driver) (30/2635)
[2025-06-26T20:20:11.214+0700] {subprocess.py:93} INFO - 25/06/26 20:20:11 INFO Executor: Running task 51.0 in stage 0.0 (TID 51)
[2025-06-26T20:20:11.215+0700] {subprocess.py:93} INFO - 25/06/26 20:20:11 INFO Executor: Finished task 32.0 in stage 0.0 (TID 32). 3218 bytes result sent to driver
[2025-06-26T20:20:11.220+0700] {subprocess.py:93} INFO - 25/06/26 20:20:11 INFO TaskSetManager: Starting task 52.0 in stage 0.0 (TID 52) (localhost, executor driver, partition 52, PROCESS_LOCAL, 9215 bytes)
[2025-06-26T20:20:11.227+0700] {subprocess.py:93} INFO - 25/06/26 20:20:11 INFO TaskSetManager: Finished task 32.0 in stage 0.0 (TID 32) in 117 ms on localhost (executor driver) (31/2635)
[2025-06-26T20:20:11.228+0700] {subprocess.py:93} INFO - 25/06/26 20:20:11 INFO Executor: Finished task 31.0 in stage 0.0 (TID 31). 3218 bytes result sent to driver
[2025-06-26T20:20:11.228+0700] {subprocess.py:93} INFO - 25/06/26 20:20:11 INFO Executor: Running task 52.0 in stage 0.0 (TID 52)
[2025-06-26T20:20:11.229+0700] {subprocess.py:93} INFO - 25/06/26 20:20:11 INFO Executor: Finished task 35.0 in stage 0.0 (TID 35). 3218 bytes result sent to driver
[2025-06-26T20:20:11.231+0700] {subprocess.py:93} INFO - 25/06/26 20:20:11 INFO TaskSetManager: Starting task 53.0 in stage 0.0 (TID 53) (localhost, executor driver, partition 53, PROCESS_LOCAL, 9215 bytes)
[2025-06-26T20:20:11.231+0700] {subprocess.py:93} INFO - 25/06/26 20:20:11 INFO Executor: Finished task 36.0 in stage 0.0 (TID 36). 3218 bytes result sent to driver
[2025-06-26T20:20:11.231+0700] {subprocess.py:93} INFO - 25/06/26 20:20:11 INFO Executor: Finished task 41.0 in stage 0.0 (TID 41). 3175 bytes result sent to driver
[2025-06-26T20:20:11.232+0700] {subprocess.py:93} INFO - 25/06/26 20:20:11 INFO Executor: Finished task 29.0 in stage 0.0 (TID 29). 3261 bytes result sent to driver
[2025-06-26T20:20:11.232+0700] {subprocess.py:93} INFO - 25/06/26 20:20:11 INFO Executor: Running task 53.0 in stage 0.0 (TID 53)
[2025-06-26T20:20:11.232+0700] {subprocess.py:93} INFO - 25/06/26 20:20:11 INFO Executor: Finished task 33.0 in stage 0.0 (TID 33). 3218 bytes result sent to driver
[2025-06-26T20:20:11.232+0700] {subprocess.py:93} INFO - 25/06/26 20:20:11 INFO Executor: Finished task 43.0 in stage 0.0 (TID 43). 3175 bytes result sent to driver
[2025-06-26T20:20:11.232+0700] {subprocess.py:93} INFO - 25/06/26 20:20:11 INFO Executor: Finished task 46.0 in stage 0.0 (TID 46). 3175 bytes result sent to driver
[2025-06-26T20:20:11.232+0700] {subprocess.py:93} INFO - 25/06/26 20:20:11 INFO Executor: Finished task 37.0 in stage 0.0 (TID 37). 3218 bytes result sent to driver
[2025-06-26T20:20:11.232+0700] {subprocess.py:93} INFO - 25/06/26 20:20:11 INFO Executor: Finished task 40.0 in stage 0.0 (TID 40). 3175 bytes result sent to driver
[2025-06-26T20:20:11.233+0700] {subprocess.py:93} INFO - 25/06/26 20:20:11 INFO TaskSetManager: Starting task 54.0 in stage 0.0 (TID 54) (localhost, executor driver, partition 54, PROCESS_LOCAL, 9215 bytes)
[2025-06-26T20:20:11.234+0700] {subprocess.py:93} INFO - 25/06/26 20:20:11 INFO Executor: Finished task 30.0 in stage 0.0 (TID 30). 3218 bytes result sent to driver
[2025-06-26T20:20:11.240+0700] {subprocess.py:93} INFO - 25/06/26 20:20:11 INFO Executor: Running task 54.0 in stage 0.0 (TID 54)
[2025-06-26T20:20:11.240+0700] {subprocess.py:93} INFO - 25/06/26 20:20:11 INFO TaskSetManager: Starting task 55.0 in stage 0.0 (TID 55) (localhost, executor driver, partition 55, PROCESS_LOCAL, 9215 bytes)
[2025-06-26T20:20:11.241+0700] {subprocess.py:93} INFO - 25/06/26 20:20:11 INFO TaskSetManager: Finished task 36.0 in stage 0.0 (TID 36) in 128 ms on localhost (executor driver) (32/2635)
[2025-06-26T20:20:11.242+0700] {subprocess.py:93} INFO - 25/06/26 20:20:11 INFO Executor: Running task 55.0 in stage 0.0 (TID 55)
[2025-06-26T20:20:11.243+0700] {subprocess.py:93} INFO - 25/06/26 20:20:11 INFO TaskSetManager: Starting task 56.0 in stage 0.0 (TID 56) (localhost, executor driver, partition 56, PROCESS_LOCAL, 9215 bytes)
[2025-06-26T20:20:11.244+0700] {subprocess.py:93} INFO - 25/06/26 20:20:11 INFO TaskSetManager: Finished task 31.0 in stage 0.0 (TID 31) in 140 ms on localhost (executor driver) (33/2635)
[2025-06-26T20:20:11.244+0700] {subprocess.py:93} INFO - 25/06/26 20:20:11 INFO Executor: Running task 56.0 in stage 0.0 (TID 56)
[2025-06-26T20:20:11.244+0700] {subprocess.py:93} INFO - 25/06/26 20:20:11 INFO Executor: Finished task 38.0 in stage 0.0 (TID 38). 3175 bytes result sent to driver
[2025-06-26T20:20:11.244+0700] {subprocess.py:93} INFO - 25/06/26 20:20:11 INFO Executor: Finished task 44.0 in stage 0.0 (TID 44). 3175 bytes result sent to driver
[2025-06-26T20:20:11.245+0700] {subprocess.py:93} INFO - 25/06/26 20:20:11 INFO Executor: Finished task 39.0 in stage 0.0 (TID 39). 3175 bytes result sent to driver
[2025-06-26T20:20:11.245+0700] {subprocess.py:93} INFO - 25/06/26 20:20:11 INFO TaskSetManager: Finished task 29.0 in stage 0.0 (TID 29) in 144 ms on localhost (executor driver) (34/2635)
[2025-06-26T20:20:11.246+0700] {subprocess.py:93} INFO - 25/06/26 20:20:11 INFO TaskSetManager: Finished task 35.0 in stage 0.0 (TID 35) in 134 ms on localhost (executor driver) (35/2635)
[2025-06-26T20:20:11.250+0700] {subprocess.py:93} INFO - 25/06/26 20:20:11 INFO TaskSetManager: Starting task 57.0 in stage 0.0 (TID 57) (localhost, executor driver, partition 57, PROCESS_LOCAL, 9215 bytes)
[2025-06-26T20:20:11.250+0700] {subprocess.py:93} INFO - 25/06/26 20:20:11 INFO Executor: Running task 57.0 in stage 0.0 (TID 57)
[2025-06-26T20:20:11.251+0700] {subprocess.py:93} INFO - 25/06/26 20:20:11 INFO Executor: Finished task 47.0 in stage 0.0 (TID 47). 3175 bytes result sent to driver
[2025-06-26T20:20:11.252+0700] {subprocess.py:93} INFO - 25/06/26 20:20:11 INFO TaskSetManager: Starting task 58.0 in stage 0.0 (TID 58) (localhost, executor driver, partition 58, PROCESS_LOCAL, 9215 bytes)
[2025-06-26T20:20:11.252+0700] {subprocess.py:93} INFO - 25/06/26 20:20:11 INFO TaskSetManager: Finished task 33.0 in stage 0.0 (TID 33) in 143 ms on localhost (executor driver) (36/2635)
[2025-06-26T20:20:11.253+0700] {subprocess.py:93} INFO - 25/06/26 20:20:11 INFO TaskSetManager: Finished task 41.0 in stage 0.0 (TID 41) in 99 ms on localhost (executor driver) (37/2635)
[2025-06-26T20:20:11.256+0700] {subprocess.py:93} INFO - 25/06/26 20:20:11 INFO Executor: Finished task 42.0 in stage 0.0 (TID 42). 3218 bytes result sent to driver
[2025-06-26T20:20:11.257+0700] {subprocess.py:93} INFO - 25/06/26 20:20:11 INFO Executor: Running task 58.0 in stage 0.0 (TID 58)
[2025-06-26T20:20:11.257+0700] {subprocess.py:93} INFO - 25/06/26 20:20:11 INFO Executor: Finished task 45.0 in stage 0.0 (TID 45). 3175 bytes result sent to driver
[2025-06-26T20:20:11.257+0700] {subprocess.py:93} INFO - 25/06/26 20:20:11 INFO TaskSetManager: Starting task 59.0 in stage 0.0 (TID 59) (localhost, executor driver, partition 59, PROCESS_LOCAL, 9215 bytes)
[2025-06-26T20:20:11.257+0700] {subprocess.py:93} INFO - 25/06/26 20:20:11 INFO Executor: Running task 59.0 in stage 0.0 (TID 59)
[2025-06-26T20:20:11.257+0700] {subprocess.py:93} INFO - 25/06/26 20:20:11 INFO Executor: Finished task 49.0 in stage 0.0 (TID 49). 3218 bytes result sent to driver
[2025-06-26T20:20:11.257+0700] {subprocess.py:93} INFO - 25/06/26 20:20:11 INFO Executor: Finished task 48.0 in stage 0.0 (TID 48). 3218 bytes result sent to driver
[2025-06-26T20:20:11.258+0700] {subprocess.py:93} INFO - 25/06/26 20:20:11 INFO TaskSetManager: Starting task 60.0 in stage 0.0 (TID 60) (localhost, executor driver, partition 60, PROCESS_LOCAL, 9215 bytes)
[2025-06-26T20:20:11.258+0700] {subprocess.py:93} INFO - 25/06/26 20:20:11 INFO Executor: Running task 60.0 in stage 0.0 (TID 60)
[2025-06-26T20:20:11.258+0700] {subprocess.py:93} INFO - 25/06/26 20:20:11 INFO TaskSetManager: Starting task 61.0 in stage 0.0 (TID 61) (localhost, executor driver, partition 61, PROCESS_LOCAL, 9215 bytes)
[2025-06-26T20:20:11.258+0700] {subprocess.py:93} INFO - 25/06/26 20:20:11 INFO TaskSetManager: Finished task 46.0 in stage 0.0 (TID 46) in 89 ms on localhost (executor driver) (38/2635)
[2025-06-26T20:20:11.258+0700] {subprocess.py:93} INFO - 25/06/26 20:20:11 INFO TaskSetManager: Finished task 43.0 in stage 0.0 (TID 43) in 103 ms on localhost (executor driver) (39/2635)
[2025-06-26T20:20:11.259+0700] {subprocess.py:93} INFO - 25/06/26 20:20:11 INFO TaskSetManager: Finished task 40.0 in stage 0.0 (TID 40) in 112 ms on localhost (executor driver) (40/2635)
[2025-06-26T20:20:11.260+0700] {subprocess.py:93} INFO - 25/06/26 20:20:11 INFO Executor: Running task 61.0 in stage 0.0 (TID 61)
[2025-06-26T20:20:11.260+0700] {subprocess.py:93} INFO - 25/06/26 20:20:11 INFO TaskSetManager: Starting task 62.0 in stage 0.0 (TID 62) (localhost, executor driver, partition 62, PROCESS_LOCAL, 9215 bytes)
[2025-06-26T20:20:11.261+0700] {subprocess.py:93} INFO - 25/06/26 20:20:11 INFO Executor: Finished task 50.0 in stage 0.0 (TID 50). 3175 bytes result sent to driver
[2025-06-26T20:20:11.262+0700] {subprocess.py:93} INFO - 25/06/26 20:20:11 INFO TaskSetManager: Starting task 63.0 in stage 0.0 (TID 63) (localhost, executor driver, partition 63, PROCESS_LOCAL, 9215 bytes)
[2025-06-26T20:20:11.262+0700] {subprocess.py:93} INFO - 25/06/26 20:20:11 INFO TaskSetManager: Finished task 37.0 in stage 0.0 (TID 37) in 144 ms on localhost (executor driver) (41/2635)
[2025-06-26T20:20:11.262+0700] {subprocess.py:93} INFO - 25/06/26 20:20:11 INFO Executor: Running task 63.0 in stage 0.0 (TID 63)
[2025-06-26T20:20:11.263+0700] {subprocess.py:93} INFO - 25/06/26 20:20:11 INFO TaskSetManager: Finished task 30.0 in stage 0.0 (TID 30) in 160 ms on localhost (executor driver) (42/2635)
[2025-06-26T20:20:11.263+0700] {subprocess.py:93} INFO - 25/06/26 20:20:11 INFO Executor: Running task 62.0 in stage 0.0 (TID 62)
[2025-06-26T20:20:11.264+0700] {subprocess.py:93} INFO - 25/06/26 20:20:11 INFO TaskSetManager: Starting task 64.0 in stage 0.0 (TID 64) (localhost, executor driver, partition 64, PROCESS_LOCAL, 9215 bytes)
[2025-06-26T20:20:11.264+0700] {subprocess.py:93} INFO - 25/06/26 20:20:11 INFO Executor: Finished task 52.0 in stage 0.0 (TID 52). 3175 bytes result sent to driver
[2025-06-26T20:20:11.265+0700] {subprocess.py:93} INFO - 25/06/26 20:20:11 INFO Executor: Running task 64.0 in stage 0.0 (TID 64)
[2025-06-26T20:20:11.266+0700] {subprocess.py:93} INFO - 25/06/26 20:20:11 INFO TaskSetManager: Starting task 65.0 in stage 0.0 (TID 65) (localhost, executor driver, partition 65, PROCESS_LOCAL, 9215 bytes)
[2025-06-26T20:20:11.266+0700] {subprocess.py:93} INFO - 25/06/26 20:20:11 INFO TaskSetManager: Finished task 44.0 in stage 0.0 (TID 44) in 108 ms on localhost (executor driver) (43/2635)
[2025-06-26T20:20:11.266+0700] {subprocess.py:93} INFO - 25/06/26 20:20:11 INFO Executor: Running task 65.0 in stage 0.0 (TID 65)
[2025-06-26T20:20:11.267+0700] {subprocess.py:93} INFO - 25/06/26 20:20:11 INFO TaskSetManager: Starting task 66.0 in stage 0.0 (TID 66) (localhost, executor driver, partition 66, PROCESS_LOCAL, 9215 bytes)
[2025-06-26T20:20:11.267+0700] {subprocess.py:93} INFO - 25/06/26 20:20:11 INFO Executor: Finished task 53.0 in stage 0.0 (TID 53). 3175 bytes result sent to driver
[2025-06-26T20:20:11.268+0700] {subprocess.py:93} INFO - 25/06/26 20:20:11 INFO Executor: Running task 66.0 in stage 0.0 (TID 66)
[2025-06-26T20:20:11.268+0700] {subprocess.py:93} INFO - 25/06/26 20:20:11 INFO TaskSetManager: Starting task 67.0 in stage 0.0 (TID 67) (localhost, executor driver, partition 67, PROCESS_LOCAL, 9215 bytes)
[2025-06-26T20:20:11.272+0700] {subprocess.py:93} INFO - 25/06/26 20:20:11 INFO Executor: Running task 67.0 in stage 0.0 (TID 67)
[2025-06-26T20:20:11.273+0700] {subprocess.py:93} INFO - 25/06/26 20:20:11 INFO TaskSetManager: Starting task 68.0 in stage 0.0 (TID 68) (localhost, executor driver, partition 68, PROCESS_LOCAL, 9215 bytes)
[2025-06-26T20:20:11.273+0700] {subprocess.py:93} INFO - 25/06/26 20:20:11 INFO Executor: Running task 68.0 in stage 0.0 (TID 68)
[2025-06-26T20:20:11.274+0700] {subprocess.py:93} INFO - 25/06/26 20:20:11 INFO TaskSetManager: Starting task 69.0 in stage 0.0 (TID 69) (localhost, executor driver, partition 69, PROCESS_LOCAL, 9215 bytes)
[2025-06-26T20:20:11.274+0700] {subprocess.py:93} INFO - 25/06/26 20:20:11 INFO TaskSetManager: Starting task 70.0 in stage 0.0 (TID 70) (localhost, executor driver, partition 70, PROCESS_LOCAL, 9215 bytes)
[2025-06-26T20:20:11.274+0700] {subprocess.py:93} INFO - 25/06/26 20:20:11 INFO Executor: Running task 70.0 in stage 0.0 (TID 70)
[2025-06-26T20:20:11.274+0700] {subprocess.py:93} INFO - 25/06/26 20:20:11 INFO TaskSetManager: Starting task 71.0 in stage 0.0 (TID 71) (localhost, executor driver, partition 71, PROCESS_LOCAL, 9215 bytes)
[2025-06-26T20:20:11.275+0700] {subprocess.py:93} INFO - 25/06/26 20:20:11 INFO Executor: Running task 69.0 in stage 0.0 (TID 69)
[2025-06-26T20:20:11.276+0700] {subprocess.py:93} INFO - 25/06/26 20:20:11 INFO Executor: Finished task 51.0 in stage 0.0 (TID 51). 3175 bytes result sent to driver
[2025-06-26T20:20:11.287+0700] {subprocess.py:93} INFO - 25/06/26 20:20:11 INFO Executor: Running task 71.0 in stage 0.0 (TID 71)
[2025-06-26T20:20:11.288+0700] {subprocess.py:93} INFO - 25/06/26 20:20:11 INFO TaskSetManager: Starting task 72.0 in stage 0.0 (TID 72) (localhost, executor driver, partition 72, PROCESS_LOCAL, 9215 bytes)
[2025-06-26T20:20:11.288+0700] {subprocess.py:93} INFO - 25/06/26 20:20:11 INFO Executor: Finished task 54.0 in stage 0.0 (TID 54). 3261 bytes result sent to driver
[2025-06-26T20:20:11.289+0700] {subprocess.py:93} INFO - 25/06/26 20:20:11 INFO Executor: Running task 72.0 in stage 0.0 (TID 72)
[2025-06-26T20:20:11.290+0700] {subprocess.py:93} INFO - 25/06/26 20:20:11 INFO TaskSetManager: Starting task 73.0 in stage 0.0 (TID 73) (localhost, executor driver, partition 73, PROCESS_LOCAL, 9215 bytes)
[2025-06-26T20:20:11.291+0700] {subprocess.py:93} INFO - 25/06/26 20:20:11 INFO Executor: Running task 73.0 in stage 0.0 (TID 73)
[2025-06-26T20:20:11.292+0700] {subprocess.py:93} INFO - 25/06/26 20:20:11 INFO TaskSetManager: Starting task 74.0 in stage 0.0 (TID 74) (localhost, executor driver, partition 74, PROCESS_LOCAL, 9215 bytes)
[2025-06-26T20:20:11.293+0700] {subprocess.py:93} INFO - 25/06/26 20:20:11 INFO Executor: Running task 74.0 in stage 0.0 (TID 74)
[2025-06-26T20:20:11.294+0700] {subprocess.py:93} INFO - 25/06/26 20:20:11 INFO TaskSetManager: Starting task 75.0 in stage 0.0 (TID 75) (localhost, executor driver, partition 75, PROCESS_LOCAL, 9215 bytes)
[2025-06-26T20:20:11.297+0700] {subprocess.py:93} INFO - 25/06/26 20:20:11 INFO TaskSetManager: Finished task 38.0 in stage 0.0 (TID 38) in 171 ms on localhost (executor driver) (44/2635)
[2025-06-26T20:20:11.297+0700] {subprocess.py:93} INFO - 25/06/26 20:20:11 INFO Executor: Running task 75.0 in stage 0.0 (TID 75)
[2025-06-26T20:20:11.298+0700] {subprocess.py:93} INFO - 25/06/26 20:20:11 INFO TaskSetManager: Finished task 42.0 in stage 0.0 (TID 42) in 140 ms on localhost (executor driver) (45/2635)
[2025-06-26T20:20:11.298+0700] {subprocess.py:93} INFO - 25/06/26 20:20:11 INFO TaskSetManager: Finished task 45.0 in stage 0.0 (TID 45) in 132 ms on localhost (executor driver) (46/2635)
[2025-06-26T20:20:11.298+0700] {subprocess.py:93} INFO - 25/06/26 20:20:11 INFO TaskSetManager: Finished task 39.0 in stage 0.0 (TID 39) in 158 ms on localhost (executor driver) (47/2635)
[2025-06-26T20:20:11.298+0700] {subprocess.py:93} INFO - 25/06/26 20:20:11 INFO TaskSetManager: Finished task 47.0 in stage 0.0 (TID 47) in 115 ms on localhost (executor driver) (48/2635)
[2025-06-26T20:20:11.298+0700] {subprocess.py:93} INFO - 25/06/26 20:20:11 INFO TaskSetManager: Finished task 52.0 in stage 0.0 (TID 52) in 79 ms on localhost (executor driver) (49/2635)
[2025-06-26T20:20:11.298+0700] {subprocess.py:93} INFO - 25/06/26 20:20:11 INFO TaskSetManager: Finished task 49.0 in stage 0.0 (TID 49) in 101 ms on localhost (executor driver) (50/2635)
[2025-06-26T20:20:11.298+0700] {subprocess.py:93} INFO - 25/06/26 20:20:11 INFO TaskSetManager: Finished task 54.0 in stage 0.0 (TID 54) in 66 ms on localhost (executor driver) (51/2635)
[2025-06-26T20:20:11.301+0700] {subprocess.py:93} INFO - 25/06/26 20:20:11 INFO TaskSetManager: Starting task 76.0 in stage 0.0 (TID 76) (localhost, executor driver, partition 76, PROCESS_LOCAL, 9215 bytes)
[2025-06-26T20:20:11.302+0700] {subprocess.py:93} INFO - 25/06/26 20:20:11 INFO Executor: Finished task 57.0 in stage 0.0 (TID 57). 3218 bytes result sent to driver
[2025-06-26T20:20:11.303+0700] {subprocess.py:93} INFO - 25/06/26 20:20:11 INFO TaskSetManager: Finished task 53.0 in stage 0.0 (TID 53) in 74 ms on localhost (executor driver) (52/2635)
[2025-06-26T20:20:11.303+0700] {subprocess.py:93} INFO - 25/06/26 20:20:11 INFO TaskSetManager: Finished task 48.0 in stage 0.0 (TID 48) in 115 ms on localhost (executor driver) (53/2635)
[2025-06-26T20:20:11.303+0700] {subprocess.py:93} INFO - 25/06/26 20:20:11 INFO TaskSetManager: Finished task 50.0 in stage 0.0 (TID 50) in 98 ms on localhost (executor driver) (54/2635)
[2025-06-26T20:20:11.303+0700] {subprocess.py:93} INFO - 25/06/26 20:20:11 INFO Executor: Running task 76.0 in stage 0.0 (TID 76)
[2025-06-26T20:20:11.305+0700] {subprocess.py:93} INFO - 25/06/26 20:20:11 INFO TaskSetManager: Starting task 77.0 in stage 0.0 (TID 77) (localhost, executor driver, partition 77, PROCESS_LOCAL, 9215 bytes)
[2025-06-26T20:20:11.306+0700] {subprocess.py:93} INFO - 25/06/26 20:20:11 INFO Executor: Running task 77.0 in stage 0.0 (TID 77)
[2025-06-26T20:20:11.307+0700] {subprocess.py:93} INFO - 25/06/26 20:20:11 INFO Executor: Finished task 58.0 in stage 0.0 (TID 58). 3218 bytes result sent to driver
[2025-06-26T20:20:11.308+0700] {subprocess.py:93} INFO - 25/06/26 20:20:11 INFO TaskSetManager: Finished task 57.0 in stage 0.0 (TID 57) in 60 ms on localhost (executor driver) (55/2635)
[2025-06-26T20:20:11.311+0700] {subprocess.py:93} INFO - 25/06/26 20:20:11 INFO TaskSetManager: Starting task 78.0 in stage 0.0 (TID 78) (localhost, executor driver, partition 78, PROCESS_LOCAL, 9215 bytes)
[2025-06-26T20:20:11.312+0700] {subprocess.py:93} INFO - 25/06/26 20:20:11 INFO TaskSetManager: Finished task 51.0 in stage 0.0 (TID 51) in 101 ms on localhost (executor driver) (56/2635)
[2025-06-26T20:20:11.312+0700] {subprocess.py:93} INFO - 25/06/26 20:20:11 INFO Executor: Running task 78.0 in stage 0.0 (TID 78)
[2025-06-26T20:20:11.337+0700] {subprocess.py:93} INFO - 25/06/26 20:20:11 INFO Executor: Finished task 59.0 in stage 0.0 (TID 59). 3218 bytes result sent to driver
[2025-06-26T20:20:11.338+0700] {subprocess.py:93} INFO - 25/06/26 20:20:11 INFO TaskSetManager: Finished task 58.0 in stage 0.0 (TID 58) in 88 ms on localhost (executor driver) (57/2635)
[2025-06-26T20:20:11.339+0700] {subprocess.py:93} INFO - 25/06/26 20:20:11 INFO Executor: Finished task 55.0 in stage 0.0 (TID 55). 3218 bytes result sent to driver
[2025-06-26T20:20:11.339+0700] {subprocess.py:93} INFO - 25/06/26 20:20:11 INFO TaskSetManager: Starting task 79.0 in stage 0.0 (TID 79) (localhost, executor driver, partition 79, PROCESS_LOCAL, 9215 bytes)
[2025-06-26T20:20:11.339+0700] {subprocess.py:93} INFO - 25/06/26 20:20:11 INFO Executor: Finished task 56.0 in stage 0.0 (TID 56). 3218 bytes result sent to driver
[2025-06-26T20:20:11.340+0700] {subprocess.py:93} INFO - 25/06/26 20:20:11 INFO Executor: Running task 79.0 in stage 0.0 (TID 79)
[2025-06-26T20:20:11.343+0700] {subprocess.py:93} INFO - 25/06/26 20:20:11 INFO TaskSetManager: Starting task 80.0 in stage 0.0 (TID 80) (localhost, executor driver, partition 80, PROCESS_LOCAL, 9215 bytes)
[2025-06-26T20:20:11.347+0700] {subprocess.py:93} INFO - 25/06/26 20:20:11 INFO TaskSetManager: Starting task 81.0 in stage 0.0 (TID 81) (localhost, executor driver, partition 81, PROCESS_LOCAL, 9215 bytes)
[2025-06-26T20:20:11.348+0700] {subprocess.py:93} INFO - 25/06/26 20:20:11 INFO TaskSetManager: Finished task 59.0 in stage 0.0 (TID 59) in 93 ms on localhost (executor driver) (58/2635)
[2025-06-26T20:20:11.348+0700] {subprocess.py:93} INFO - 25/06/26 20:20:11 INFO Executor: Running task 80.0 in stage 0.0 (TID 80)
[2025-06-26T20:20:11.349+0700] {subprocess.py:93} INFO - 25/06/26 20:20:11 INFO TaskSetManager: Finished task 55.0 in stage 0.0 (TID 55) in 114 ms on localhost (executor driver) (59/2635)
[2025-06-26T20:20:11.349+0700] {subprocess.py:93} INFO - 25/06/26 20:20:11 INFO Executor: Running task 81.0 in stage 0.0 (TID 81)
[2025-06-26T20:20:11.350+0700] {subprocess.py:93} INFO - 25/06/26 20:20:11 INFO TaskSetManager: Finished task 56.0 in stage 0.0 (TID 56) in 108 ms on localhost (executor driver) (60/2635)
[2025-06-26T20:20:11.362+0700] {subprocess.py:93} INFO - 25/06/26 20:20:11 INFO Executor: Finished task 60.0 in stage 0.0 (TID 60). 3218 bytes result sent to driver
[2025-06-26T20:20:11.362+0700] {subprocess.py:93} INFO - 25/06/26 20:20:11 INFO Executor: Finished task 61.0 in stage 0.0 (TID 61). 3218 bytes result sent to driver
[2025-06-26T20:20:11.365+0700] {subprocess.py:93} INFO - 25/06/26 20:20:11 INFO TaskSetManager: Starting task 82.0 in stage 0.0 (TID 82) (localhost, executor driver, partition 82, PROCESS_LOCAL, 9215 bytes)
[2025-06-26T20:20:11.366+0700] {subprocess.py:93} INFO - 25/06/26 20:20:11 INFO Executor: Running task 82.0 in stage 0.0 (TID 82)
[2025-06-26T20:20:11.367+0700] {subprocess.py:93} INFO - 25/06/26 20:20:11 INFO TaskSetManager: Starting task 83.0 in stage 0.0 (TID 83) (localhost, executor driver, partition 83, PROCESS_LOCAL, 9215 bytes)
[2025-06-26T20:20:11.368+0700] {subprocess.py:93} INFO - 25/06/26 20:20:11 INFO TaskSetManager: Finished task 60.0 in stage 0.0 (TID 60) in 112 ms on localhost (executor driver) (61/2635)
[2025-06-26T20:20:11.369+0700] {subprocess.py:93} INFO - 25/06/26 20:20:11 INFO TaskSetManager: Finished task 61.0 in stage 0.0 (TID 61) in 111 ms on localhost (executor driver) (62/2635)
[2025-06-26T20:20:11.370+0700] {subprocess.py:93} INFO - 25/06/26 20:20:11 INFO Executor: Running task 83.0 in stage 0.0 (TID 83)
[2025-06-26T20:20:11.371+0700] {subprocess.py:93} INFO - 25/06/26 20:20:11 INFO Executor: Finished task 69.0 in stage 0.0 (TID 69). 3218 bytes result sent to driver
[2025-06-26T20:20:11.372+0700] {subprocess.py:93} INFO - 25/06/26 20:20:11 INFO Executor: Finished task 65.0 in stage 0.0 (TID 65). 3218 bytes result sent to driver
[2025-06-26T20:20:11.372+0700] {subprocess.py:93} INFO - 25/06/26 20:20:11 INFO TaskSetManager: Starting task 84.0 in stage 0.0 (TID 84) (localhost, executor driver, partition 84, PROCESS_LOCAL, 9215 bytes)
[2025-06-26T20:20:11.373+0700] {subprocess.py:93} INFO - 25/06/26 20:20:11 INFO Executor: Running task 84.0 in stage 0.0 (TID 84)
[2025-06-26T20:20:11.373+0700] {subprocess.py:93} INFO - 25/06/26 20:20:11 INFO Executor: Finished task 63.0 in stage 0.0 (TID 63). 3218 bytes result sent to driver
[2025-06-26T20:20:11.374+0700] {subprocess.py:93} INFO - 25/06/26 20:20:11 INFO Executor: Finished task 67.0 in stage 0.0 (TID 67). 3218 bytes result sent to driver
[2025-06-26T20:20:11.374+0700] {subprocess.py:93} INFO - 25/06/26 20:20:11 INFO TaskSetManager: Finished task 69.0 in stage 0.0 (TID 69) in 102 ms on localhost (executor driver) (63/2635)
[2025-06-26T20:20:11.376+0700] {subprocess.py:93} INFO - 25/06/26 20:20:11 INFO TaskSetManager: Starting task 85.0 in stage 0.0 (TID 85) (localhost, executor driver, partition 85, PROCESS_LOCAL, 9215 bytes)
[2025-06-26T20:20:11.377+0700] {subprocess.py:93} INFO - 25/06/26 20:20:11 INFO Executor: Finished task 71.0 in stage 0.0 (TID 71). 3175 bytes result sent to driver
[2025-06-26T20:20:11.378+0700] {subprocess.py:93} INFO - 25/06/26 20:20:11 INFO TaskSetManager: Starting task 86.0 in stage 0.0 (TID 86) (localhost, executor driver, partition 86, PROCESS_LOCAL, 9215 bytes)
[2025-06-26T20:20:11.380+0700] {subprocess.py:93} INFO - 25/06/26 20:20:11 INFO Executor: Running task 85.0 in stage 0.0 (TID 85)
[2025-06-26T20:20:11.381+0700] {subprocess.py:93} INFO - 25/06/26 20:20:11 INFO Executor: Running task 86.0 in stage 0.0 (TID 86)
[2025-06-26T20:20:11.382+0700] {subprocess.py:93} INFO - 25/06/26 20:20:11 INFO TaskSetManager: Starting task 87.0 in stage 0.0 (TID 87) (localhost, executor driver, partition 87, PROCESS_LOCAL, 9215 bytes)
[2025-06-26T20:20:11.383+0700] {subprocess.py:93} INFO - 25/06/26 20:20:11 INFO Executor: Finished task 75.0 in stage 0.0 (TID 75). 3175 bytes result sent to driver
[2025-06-26T20:20:11.384+0700] {subprocess.py:93} INFO - 25/06/26 20:20:11 INFO TaskSetManager: Starting task 88.0 in stage 0.0 (TID 88) (localhost, executor driver, partition 88, PROCESS_LOCAL, 9215 bytes)
[2025-06-26T20:20:11.384+0700] {subprocess.py:93} INFO - 25/06/26 20:20:11 INFO Executor: Running task 87.0 in stage 0.0 (TID 87)
[2025-06-26T20:20:11.384+0700] {subprocess.py:93} INFO - 25/06/26 20:20:11 INFO Executor: Running task 88.0 in stage 0.0 (TID 88)
[2025-06-26T20:20:11.384+0700] {subprocess.py:93} INFO - 25/06/26 20:20:11 INFO TaskSetManager: Starting task 89.0 in stage 0.0 (TID 89) (localhost, executor driver, partition 89, PROCESS_LOCAL, 9215 bytes)
[2025-06-26T20:20:11.384+0700] {subprocess.py:93} INFO - 25/06/26 20:20:11 INFO Executor: Running task 89.0 in stage 0.0 (TID 89)
[2025-06-26T20:20:11.385+0700] {subprocess.py:93} INFO - 25/06/26 20:20:11 INFO TaskSetManager: Finished task 65.0 in stage 0.0 (TID 65) in 119 ms on localhost (executor driver) (64/2635)
[2025-06-26T20:20:11.386+0700] {subprocess.py:93} INFO - 25/06/26 20:20:11 INFO TaskSetManager: Finished task 75.0 in stage 0.0 (TID 75) in 92 ms on localhost (executor driver) (65/2635)
[2025-06-26T20:20:11.386+0700] {subprocess.py:93} INFO - 25/06/26 20:20:11 INFO TaskSetManager: Finished task 67.0 in stage 0.0 (TID 67) in 119 ms on localhost (executor driver) (66/2635)
[2025-06-26T20:20:11.386+0700] {subprocess.py:93} INFO - 25/06/26 20:20:11 INFO Executor: Finished task 73.0 in stage 0.0 (TID 73). 3175 bytes result sent to driver
[2025-06-26T20:20:11.386+0700] {subprocess.py:93} INFO - 25/06/26 20:20:11 INFO Executor: Finished task 70.0 in stage 0.0 (TID 70). 3218 bytes result sent to driver
[2025-06-26T20:20:11.387+0700] {subprocess.py:93} INFO - 25/06/26 20:20:11 INFO TaskSetManager: Finished task 63.0 in stage 0.0 (TID 63) in 125 ms on localhost (executor driver) (67/2635)
[2025-06-26T20:20:11.388+0700] {subprocess.py:93} INFO - 25/06/26 20:20:11 INFO TaskSetManager: Starting task 90.0 in stage 0.0 (TID 90) (localhost, executor driver, partition 90, PROCESS_LOCAL, 9215 bytes)
[2025-06-26T20:20:11.389+0700] {subprocess.py:93} INFO - 25/06/26 20:20:11 INFO Executor: Finished task 66.0 in stage 0.0 (TID 66). 3218 bytes result sent to driver
[2025-06-26T20:20:11.391+0700] {subprocess.py:93} INFO - 25/06/26 20:20:11 INFO TaskSetManager: Starting task 91.0 in stage 0.0 (TID 91) (localhost, executor driver, partition 91, PROCESS_LOCAL, 9215 bytes)
[2025-06-26T20:20:11.392+0700] {subprocess.py:93} INFO - 25/06/26 20:20:11 INFO Executor: Running task 90.0 in stage 0.0 (TID 90)
[2025-06-26T20:20:11.392+0700] {subprocess.py:93} INFO - 25/06/26 20:20:11 INFO Executor: Running task 91.0 in stage 0.0 (TID 91)
[2025-06-26T20:20:11.392+0700] {subprocess.py:93} INFO - 25/06/26 20:20:11 INFO Executor: Finished task 64.0 in stage 0.0 (TID 64). 3218 bytes result sent to driver
[2025-06-26T20:20:11.392+0700] {subprocess.py:93} INFO - 25/06/26 20:20:11 INFO Executor: Finished task 68.0 in stage 0.0 (TID 68). 3218 bytes result sent to driver
[2025-06-26T20:20:11.392+0700] {subprocess.py:93} INFO - 25/06/26 20:20:11 INFO TaskSetManager: Starting task 92.0 in stage 0.0 (TID 92) (localhost, executor driver, partition 92, PROCESS_LOCAL, 9215 bytes)
[2025-06-26T20:20:11.392+0700] {subprocess.py:93} INFO - 25/06/26 20:20:11 INFO Executor: Finished task 77.0 in stage 0.0 (TID 77). 3175 bytes result sent to driver
[2025-06-26T20:20:11.393+0700] {subprocess.py:93} INFO - 25/06/26 20:20:11 INFO Executor: Running task 92.0 in stage 0.0 (TID 92)
[2025-06-26T20:20:11.393+0700] {subprocess.py:93} INFO - 25/06/26 20:20:11 INFO TaskSetManager: Starting task 93.0 in stage 0.0 (TID 93) (localhost, executor driver, partition 93, PROCESS_LOCAL, 9215 bytes)
[2025-06-26T20:20:11.394+0700] {subprocess.py:93} INFO - 25/06/26 20:20:11 INFO TaskSetManager: Finished task 71.0 in stage 0.0 (TID 71) in 119 ms on localhost (executor driver) (68/2635)
[2025-06-26T20:20:11.396+0700] {subprocess.py:93} INFO - 25/06/26 20:20:11 INFO Executor: Running task 93.0 in stage 0.0 (TID 93)
[2025-06-26T20:20:11.396+0700] {subprocess.py:93} INFO - 25/06/26 20:20:11 INFO TaskSetManager: Finished task 73.0 in stage 0.0 (TID 73) in 105 ms on localhost (executor driver) (69/2635)
[2025-06-26T20:20:11.396+0700] {subprocess.py:93} INFO - 25/06/26 20:20:11 INFO TaskSetManager: Starting task 94.0 in stage 0.0 (TID 94) (localhost, executor driver, partition 94, PROCESS_LOCAL, 9215 bytes)
[2025-06-26T20:20:11.397+0700] {subprocess.py:93} INFO - 25/06/26 20:20:11 INFO TaskSetManager: Finished task 64.0 in stage 0.0 (TID 64) in 133 ms on localhost (executor driver) (70/2635)
[2025-06-26T20:20:11.397+0700] {subprocess.py:93} INFO - 25/06/26 20:20:11 INFO Executor: Running task 94.0 in stage 0.0 (TID 94)
[2025-06-26T20:20:11.397+0700] {subprocess.py:93} INFO - 25/06/26 20:20:11 INFO TaskSetManager: Starting task 95.0 in stage 0.0 (TID 95) (localhost, executor driver, partition 95, PROCESS_LOCAL, 9215 bytes)
[2025-06-26T20:20:11.398+0700] {subprocess.py:93} INFO - 25/06/26 20:20:11 INFO Executor: Running task 95.0 in stage 0.0 (TID 95)
[2025-06-26T20:20:11.399+0700] {subprocess.py:93} INFO - 25/06/26 20:20:11 INFO TaskSetManager: Finished task 66.0 in stage 0.0 (TID 66) in 131 ms on localhost (executor driver) (71/2635)
[2025-06-26T20:20:11.399+0700] {subprocess.py:93} INFO - 25/06/26 20:20:11 INFO TaskSetManager: Finished task 70.0 in stage 0.0 (TID 70) in 126 ms on localhost (executor driver) (72/2635)
[2025-06-26T20:20:11.399+0700] {subprocess.py:93} INFO - 25/06/26 20:20:11 INFO TaskSetManager: Finished task 68.0 in stage 0.0 (TID 68) in 131 ms on localhost (executor driver) (73/2635)
[2025-06-26T20:20:11.400+0700] {subprocess.py:93} INFO - 25/06/26 20:20:11 INFO TaskSetManager: Finished task 77.0 in stage 0.0 (TID 77) in 95 ms on localhost (executor driver) (74/2635)
[2025-06-26T20:20:11.411+0700] {subprocess.py:93} INFO - 25/06/26 20:20:11 INFO Executor: Finished task 76.0 in stage 0.0 (TID 76). 3175 bytes result sent to driver
[2025-06-26T20:20:11.412+0700] {subprocess.py:93} INFO - 25/06/26 20:20:11 INFO Executor: Finished task 80.0 in stage 0.0 (TID 80). 3175 bytes result sent to driver
[2025-06-26T20:20:11.412+0700] {subprocess.py:93} INFO - 25/06/26 20:20:11 INFO Executor: Finished task 74.0 in stage 0.0 (TID 74). 3175 bytes result sent to driver
[2025-06-26T20:20:11.412+0700] {subprocess.py:93} INFO - 25/06/26 20:20:11 INFO Executor: Finished task 62.0 in stage 0.0 (TID 62). 3218 bytes result sent to driver
[2025-06-26T20:20:11.412+0700] {subprocess.py:93} INFO - 25/06/26 20:20:11 INFO TaskSetManager: Starting task 96.0 in stage 0.0 (TID 96) (localhost, executor driver, partition 96, PROCESS_LOCAL, 9215 bytes)
[2025-06-26T20:20:11.416+0700] {subprocess.py:93} INFO - 25/06/26 20:20:11 INFO Executor: Running task 96.0 in stage 0.0 (TID 96)
[2025-06-26T20:20:11.416+0700] {subprocess.py:93} INFO - 25/06/26 20:20:11 INFO TaskSetManager: Starting task 97.0 in stage 0.0 (TID 97) (localhost, executor driver, partition 97, PROCESS_LOCAL, 9215 bytes)
[2025-06-26T20:20:11.417+0700] {subprocess.py:93} INFO - 25/06/26 20:20:11 INFO TaskSetManager: Starting task 98.0 in stage 0.0 (TID 98) (localhost, executor driver, partition 98, PROCESS_LOCAL, 9215 bytes)
[2025-06-26T20:20:11.417+0700] {subprocess.py:93} INFO - 25/06/26 20:20:11 INFO Executor: Finished task 79.0 in stage 0.0 (TID 79). 3175 bytes result sent to driver
[2025-06-26T20:20:11.418+0700] {subprocess.py:93} INFO - 25/06/26 20:20:11 INFO Executor: Finished task 78.0 in stage 0.0 (TID 78). 3175 bytes result sent to driver
[2025-06-26T20:20:11.418+0700] {subprocess.py:93} INFO - 25/06/26 20:20:11 INFO Executor: Running task 98.0 in stage 0.0 (TID 98)
[2025-06-26T20:20:11.418+0700] {subprocess.py:93} INFO - 25/06/26 20:20:11 INFO TaskSetManager: Starting task 99.0 in stage 0.0 (TID 99) (localhost, executor driver, partition 99, PROCESS_LOCAL, 9215 bytes)
[2025-06-26T20:20:11.419+0700] {subprocess.py:93} INFO - 25/06/26 20:20:11 INFO Executor: Running task 99.0 in stage 0.0 (TID 99)
[2025-06-26T20:20:11.422+0700] {subprocess.py:93} INFO - 25/06/26 20:20:11 INFO Executor: Running task 97.0 in stage 0.0 (TID 97)
[2025-06-26T20:20:11.423+0700] {subprocess.py:93} INFO - 25/06/26 20:20:11 INFO TaskSetManager: Starting task 100.0 in stage 0.0 (TID 100) (localhost, executor driver, partition 100, PROCESS_LOCAL, 9215 bytes)
[2025-06-26T20:20:11.423+0700] {subprocess.py:93} INFO - 25/06/26 20:20:11 INFO TaskSetManager: Starting task 101.0 in stage 0.0 (TID 101) (localhost, executor driver, partition 101, PROCESS_LOCAL, 9215 bytes)
[2025-06-26T20:20:11.424+0700] {subprocess.py:93} INFO - 25/06/26 20:20:11 INFO Executor: Running task 100.0 in stage 0.0 (TID 100)
[2025-06-26T20:20:11.424+0700] {subprocess.py:93} INFO - 25/06/26 20:20:11 INFO TaskSetManager: Finished task 80.0 in stage 0.0 (TID 80) in 80 ms on localhost (executor driver) (75/2635)
[2025-06-26T20:20:11.424+0700] {subprocess.py:93} INFO - 25/06/26 20:20:11 INFO TaskSetManager: Finished task 76.0 in stage 0.0 (TID 76) in 120 ms on localhost (executor driver) (76/2635)
[2025-06-26T20:20:11.424+0700] {subprocess.py:93} INFO - 25/06/26 20:20:11 INFO Executor: Running task 101.0 in stage 0.0 (TID 101)
[2025-06-26T20:20:11.424+0700] {subprocess.py:93} INFO - 25/06/26 20:20:11 INFO TaskSetManager: Finished task 74.0 in stage 0.0 (TID 74) in 130 ms on localhost (executor driver) (77/2635)
[2025-06-26T20:20:11.424+0700] {subprocess.py:93} INFO - 25/06/26 20:20:11 INFO TaskSetManager: Finished task 79.0 in stage 0.0 (TID 79) in 84 ms on localhost (executor driver) (78/2635)
[2025-06-26T20:20:11.424+0700] {subprocess.py:93} INFO - 25/06/26 20:20:11 INFO TaskSetManager: Finished task 78.0 in stage 0.0 (TID 78) in 113 ms on localhost (executor driver) (79/2635)
[2025-06-26T20:20:11.424+0700] {subprocess.py:93} INFO - 25/06/26 20:20:11 INFO TaskSetManager: Finished task 62.0 in stage 0.0 (TID 62) in 162 ms on localhost (executor driver) (80/2635)
[2025-06-26T20:20:11.424+0700] {subprocess.py:93} INFO - 25/06/26 20:20:11 INFO Executor: Finished task 81.0 in stage 0.0 (TID 81). 3175 bytes result sent to driver
[2025-06-26T20:20:11.424+0700] {subprocess.py:93} INFO - 25/06/26 20:20:11 INFO TaskSetManager: Starting task 102.0 in stage 0.0 (TID 102) (localhost, executor driver, partition 102, PROCESS_LOCAL, 9215 bytes)
[2025-06-26T20:20:11.425+0700] {subprocess.py:93} INFO - 25/06/26 20:20:11 INFO Executor: Running task 102.0 in stage 0.0 (TID 102)
[2025-06-26T20:20:11.426+0700] {subprocess.py:93} INFO - 25/06/26 20:20:11 INFO TaskSetManager: Finished task 81.0 in stage 0.0 (TID 81) in 82 ms on localhost (executor driver) (81/2635)
[2025-06-26T20:20:11.442+0700] {subprocess.py:93} INFO - 25/06/26 20:20:11 INFO Executor: Finished task 84.0 in stage 0.0 (TID 84). 3218 bytes result sent to driver
[2025-06-26T20:20:11.444+0700] {subprocess.py:93} INFO - 25/06/26 20:20:11 INFO Executor: Finished task 72.0 in stage 0.0 (TID 72). 3261 bytes result sent to driver
[2025-06-26T20:20:11.445+0700] {subprocess.py:93} INFO - 25/06/26 20:20:11 INFO Executor: Finished task 89.0 in stage 0.0 (TID 89). 3218 bytes result sent to driver
[2025-06-26T20:20:11.446+0700] {subprocess.py:93} INFO - 25/06/26 20:20:11 INFO Executor: Finished task 83.0 in stage 0.0 (TID 83). 3261 bytes result sent to driver
[2025-06-26T20:20:11.446+0700] {subprocess.py:93} INFO - 25/06/26 20:20:11 INFO Executor: Finished task 91.0 in stage 0.0 (TID 91). 3218 bytes result sent to driver
[2025-06-26T20:20:11.447+0700] {subprocess.py:93} INFO - 25/06/26 20:20:11 INFO Executor: Finished task 85.0 in stage 0.0 (TID 85). 3218 bytes result sent to driver
[2025-06-26T20:20:11.447+0700] {subprocess.py:93} INFO - 25/06/26 20:20:11 INFO Executor: Finished task 82.0 in stage 0.0 (TID 82). 3218 bytes result sent to driver
[2025-06-26T20:20:11.447+0700] {subprocess.py:93} INFO - 25/06/26 20:20:11 INFO Executor: Finished task 87.0 in stage 0.0 (TID 87). 3218 bytes result sent to driver
[2025-06-26T20:20:11.447+0700] {subprocess.py:93} INFO - 25/06/26 20:20:11 INFO Executor: Finished task 94.0 in stage 0.0 (TID 94). 3218 bytes result sent to driver
[2025-06-26T20:20:11.448+0700] {subprocess.py:93} INFO - 25/06/26 20:20:11 INFO TaskSetManager: Starting task 103.0 in stage 0.0 (TID 103) (localhost, executor driver, partition 103, PROCESS_LOCAL, 9215 bytes)
[2025-06-26T20:20:11.450+0700] {subprocess.py:93} INFO - 25/06/26 20:20:11 INFO TaskSetManager: Starting task 104.0 in stage 0.0 (TID 104) (localhost, executor driver, partition 104, PROCESS_LOCAL, 9215 bytes)
[2025-06-26T20:20:11.450+0700] {subprocess.py:93} INFO - 25/06/26 20:20:11 INFO TaskSetManager: Finished task 84.0 in stage 0.0 (TID 84) in 77 ms on localhost (executor driver) (82/2635)
[2025-06-26T20:20:11.454+0700] {subprocess.py:93} INFO - 25/06/26 20:20:11 INFO Executor: Running task 103.0 in stage 0.0 (TID 103)
[2025-06-26T20:20:11.454+0700] {subprocess.py:93} INFO - 25/06/26 20:20:11 INFO Executor: Running task 104.0 in stage 0.0 (TID 104)
[2025-06-26T20:20:11.454+0700] {subprocess.py:93} INFO - 25/06/26 20:20:11 INFO Executor: Finished task 86.0 in stage 0.0 (TID 86). 3218 bytes result sent to driver
[2025-06-26T20:20:11.455+0700] {subprocess.py:93} INFO - 25/06/26 20:20:11 INFO TaskSetManager: Starting task 105.0 in stage 0.0 (TID 105) (localhost, executor driver, partition 105, PROCESS_LOCAL, 9215 bytes)
[2025-06-26T20:20:11.455+0700] {subprocess.py:93} INFO - 25/06/26 20:20:11 INFO Executor: Finished task 92.0 in stage 0.0 (TID 92). 3218 bytes result sent to driver
[2025-06-26T20:20:11.455+0700] {subprocess.py:93} INFO - 25/06/26 20:20:11 INFO Executor: Finished task 93.0 in stage 0.0 (TID 93). 3218 bytes result sent to driver
[2025-06-26T20:20:11.455+0700] {subprocess.py:93} INFO - 25/06/26 20:20:11 INFO TaskSetManager: Finished task 72.0 in stage 0.0 (TID 72) in 179 ms on localhost (executor driver) (83/2635)
[2025-06-26T20:20:11.455+0700] {subprocess.py:93} INFO - 25/06/26 20:20:11 INFO Executor: Finished task 90.0 in stage 0.0 (TID 90). 3218 bytes result sent to driver
[2025-06-26T20:20:11.455+0700] {subprocess.py:93} INFO - 25/06/26 20:20:11 INFO Executor: Running task 105.0 in stage 0.0 (TID 105)
[2025-06-26T20:20:11.457+0700] {subprocess.py:93} INFO - 25/06/26 20:20:11 INFO TaskSetManager: Starting task 106.0 in stage 0.0 (TID 106) (localhost, executor driver, partition 106, PROCESS_LOCAL, 9215 bytes)
[2025-06-26T20:20:11.459+0700] {subprocess.py:93} INFO - 25/06/26 20:20:11 INFO Executor: Running task 106.0 in stage 0.0 (TID 106)
[2025-06-26T20:20:11.459+0700] {subprocess.py:93} INFO - 25/06/26 20:20:11 INFO Executor: Finished task 95.0 in stage 0.0 (TID 95). 3218 bytes result sent to driver
[2025-06-26T20:20:11.463+0700] {subprocess.py:93} INFO - 25/06/26 20:20:11 INFO TaskSetManager: Starting task 107.0 in stage 0.0 (TID 107) (localhost, executor driver, partition 107, PROCESS_LOCAL, 9215 bytes)
[2025-06-26T20:20:11.463+0700] {subprocess.py:93} INFO - 25/06/26 20:20:11 INFO Executor: Finished task 88.0 in stage 0.0 (TID 88). 3218 bytes result sent to driver
[2025-06-26T20:20:11.464+0700] {subprocess.py:93} INFO - 25/06/26 20:20:11 INFO Executor: Running task 107.0 in stage 0.0 (TID 107)
[2025-06-26T20:20:11.465+0700] {subprocess.py:93} INFO - 25/06/26 20:20:11 INFO TaskSetManager: Starting task 108.0 in stage 0.0 (TID 108) (localhost, executor driver, partition 108, PROCESS_LOCAL, 9215 bytes)
[2025-06-26T20:20:11.465+0700] {subprocess.py:93} INFO - 25/06/26 20:20:11 INFO TaskSetManager: Finished task 89.0 in stage 0.0 (TID 89) in 83 ms on localhost (executor driver) (84/2635)
[2025-06-26T20:20:11.465+0700] {subprocess.py:93} INFO - 25/06/26 20:20:11 INFO Executor: Running task 108.0 in stage 0.0 (TID 108)
[2025-06-26T20:20:11.465+0700] {subprocess.py:93} INFO - 25/06/26 20:20:11 INFO TaskSetManager: Finished task 91.0 in stage 0.0 (TID 91) in 76 ms on localhost (executor driver) (85/2635)
[2025-06-26T20:20:11.475+0700] {subprocess.py:93} INFO - 25/06/26 20:20:11 INFO TaskSetManager: Starting task 109.0 in stage 0.0 (TID 109) (localhost, executor driver, partition 109, PROCESS_LOCAL, 9215 bytes)
[2025-06-26T20:20:11.476+0700] {subprocess.py:93} INFO - 25/06/26 20:20:11 INFO Executor: Running task 109.0 in stage 0.0 (TID 109)
[2025-06-26T20:20:11.476+0700] {subprocess.py:93} INFO - 25/06/26 20:20:11 INFO TaskSetManager: Finished task 82.0 in stage 0.0 (TID 82) in 113 ms on localhost (executor driver) (86/2635)
[2025-06-26T20:20:11.476+0700] {subprocess.py:93} INFO - 25/06/26 20:20:11 INFO TaskSetManager: Finished task 87.0 in stage 0.0 (TID 87) in 97 ms on localhost (executor driver) (87/2635)
[2025-06-26T20:20:11.480+0700] {subprocess.py:93} INFO - 25/06/26 20:20:11 INFO TaskSetManager: Starting task 110.0 in stage 0.0 (TID 110) (localhost, executor driver, partition 110, PROCESS_LOCAL, 9215 bytes)
[2025-06-26T20:20:11.482+0700] {subprocess.py:93} INFO - 25/06/26 20:20:11 INFO TaskSetManager: Starting task 111.0 in stage 0.0 (TID 111) (localhost, executor driver, partition 111, PROCESS_LOCAL, 9215 bytes)
[2025-06-26T20:20:11.483+0700] {subprocess.py:93} INFO - 25/06/26 20:20:11 INFO Executor: Running task 110.0 in stage 0.0 (TID 110)
[2025-06-26T20:20:11.484+0700] {subprocess.py:93} INFO - 25/06/26 20:20:11 INFO TaskSetManager: Starting task 112.0 in stage 0.0 (TID 112) (localhost, executor driver, partition 112, PROCESS_LOCAL, 9215 bytes)
[2025-06-26T20:20:11.485+0700] {subprocess.py:93} INFO - 25/06/26 20:20:11 INFO Executor: Finished task 96.0 in stage 0.0 (TID 96). 3218 bytes result sent to driver
[2025-06-26T20:20:11.485+0700] {subprocess.py:93} INFO - 25/06/26 20:20:11 INFO Executor: Running task 112.0 in stage 0.0 (TID 112)
[2025-06-26T20:20:11.485+0700] {subprocess.py:93} INFO - 25/06/26 20:20:11 INFO Executor: Finished task 98.0 in stage 0.0 (TID 98). 3218 bytes result sent to driver
[2025-06-26T20:20:11.486+0700] {subprocess.py:93} INFO - 25/06/26 20:20:11 INFO TaskSetManager: Starting task 113.0 in stage 0.0 (TID 113) (localhost, executor driver, partition 113, PROCESS_LOCAL, 9215 bytes)
[2025-06-26T20:20:11.486+0700] {subprocess.py:93} INFO - 25/06/26 20:20:11 INFO Executor: Running task 111.0 in stage 0.0 (TID 111)
[2025-06-26T20:20:11.486+0700] {subprocess.py:93} INFO - 25/06/26 20:20:11 INFO TaskSetManager: Starting task 114.0 in stage 0.0 (TID 114) (localhost, executor driver, partition 114, PROCESS_LOCAL, 9215 bytes)
[2025-06-26T20:20:11.486+0700] {subprocess.py:93} INFO - 25/06/26 20:20:11 INFO Executor: Running task 113.0 in stage 0.0 (TID 113)
[2025-06-26T20:20:11.486+0700] {subprocess.py:93} INFO - 25/06/26 20:20:11 INFO Executor: Finished task 100.0 in stage 0.0 (TID 100). 3218 bytes result sent to driver
[2025-06-26T20:20:11.487+0700] {subprocess.py:93} INFO - 25/06/26 20:20:11 INFO Executor: Running task 114.0 in stage 0.0 (TID 114)
[2025-06-26T20:20:11.487+0700] {subprocess.py:93} INFO - 25/06/26 20:20:11 INFO Executor: Finished task 102.0 in stage 0.0 (TID 102). 3218 bytes result sent to driver
[2025-06-26T20:20:11.487+0700] {subprocess.py:93} INFO - 25/06/26 20:20:11 INFO TaskSetManager: Starting task 115.0 in stage 0.0 (TID 115) (localhost, executor driver, partition 115, PROCESS_LOCAL, 9215 bytes)
[2025-06-26T20:20:11.487+0700] {subprocess.py:93} INFO - 25/06/26 20:20:11 INFO Executor: Running task 115.0 in stage 0.0 (TID 115)
[2025-06-26T20:20:11.488+0700] {subprocess.py:93} INFO - 25/06/26 20:20:11 INFO TaskSetManager: Starting task 116.0 in stage 0.0 (TID 116) (localhost, executor driver, partition 116, PROCESS_LOCAL, 9215 bytes)
[2025-06-26T20:20:11.489+0700] {subprocess.py:93} INFO - 25/06/26 20:20:11 INFO TaskSetManager: Starting task 117.0 in stage 0.0 (TID 117) (localhost, executor driver, partition 117, PROCESS_LOCAL, 9215 bytes)
[2025-06-26T20:20:11.490+0700] {subprocess.py:93} INFO - 25/06/26 20:20:11 INFO Executor: Running task 116.0 in stage 0.0 (TID 116)
[2025-06-26T20:20:11.491+0700] {subprocess.py:93} INFO - 25/06/26 20:20:11 INFO TaskSetManager: Starting task 118.0 in stage 0.0 (TID 118) (localhost, executor driver, partition 118, PROCESS_LOCAL, 9215 bytes)
[2025-06-26T20:20:11.491+0700] {subprocess.py:93} INFO - 25/06/26 20:20:11 INFO Executor: Finished task 101.0 in stage 0.0 (TID 101). 3218 bytes result sent to driver
[2025-06-26T20:20:11.491+0700] {subprocess.py:93} INFO - 25/06/26 20:20:11 INFO Executor: Finished task 97.0 in stage 0.0 (TID 97). 3261 bytes result sent to driver
[2025-06-26T20:20:11.491+0700] {subprocess.py:93} INFO - 25/06/26 20:20:11 INFO TaskSetManager: Finished task 83.0 in stage 0.0 (TID 83) in 124 ms on localhost (executor driver) (88/2635)
[2025-06-26T20:20:11.491+0700] {subprocess.py:93} INFO - 25/06/26 20:20:11 INFO TaskSetManager: Finished task 85.0 in stage 0.0 (TID 85) in 115 ms on localhost (executor driver) (89/2635)
[2025-06-26T20:20:11.492+0700] {subprocess.py:93} INFO - 25/06/26 20:20:11 INFO Executor: Running task 118.0 in stage 0.0 (TID 118)
[2025-06-26T20:20:11.497+0700] {subprocess.py:93} INFO - 25/06/26 20:20:11 INFO TaskSetManager: Finished task 92.0 in stage 0.0 (TID 92) in 100 ms on localhost (executor driver) (90/2635)
[2025-06-26T20:20:11.498+0700] {subprocess.py:93} INFO - 25/06/26 20:20:11 INFO Executor: Running task 117.0 in stage 0.0 (TID 117)
[2025-06-26T20:20:11.500+0700] {subprocess.py:93} INFO - 25/06/26 20:20:11 INFO TaskSetManager: Finished task 90.0 in stage 0.0 (TID 90) in 111 ms on localhost (executor driver) (91/2635)
[2025-06-26T20:20:11.502+0700] {subprocess.py:93} INFO - 25/06/26 20:20:11 INFO TaskSetManager: Starting task 119.0 in stage 0.0 (TID 119) (localhost, executor driver, partition 119, PROCESS_LOCAL, 9215 bytes)
[2025-06-26T20:20:11.503+0700] {subprocess.py:93} INFO - 25/06/26 20:20:11 INFO Executor: Finished task 99.0 in stage 0.0 (TID 99). 3218 bytes result sent to driver
[2025-06-26T20:20:11.504+0700] {subprocess.py:93} INFO - 25/06/26 20:20:11 INFO TaskSetManager: Finished task 93.0 in stage 0.0 (TID 93) in 110 ms on localhost (executor driver) (92/2635)
[2025-06-26T20:20:11.504+0700] {subprocess.py:93} INFO - 25/06/26 20:20:11 INFO Executor: Running task 119.0 in stage 0.0 (TID 119)
[2025-06-26T20:20:11.505+0700] {subprocess.py:93} INFO - 25/06/26 20:20:11 INFO TaskSetManager: Starting task 120.0 in stage 0.0 (TID 120) (localhost, executor driver, partition 120, PROCESS_LOCAL, 9215 bytes)
[2025-06-26T20:20:11.505+0700] {subprocess.py:93} INFO - 25/06/26 20:20:11 INFO Executor: Finished task 104.0 in stage 0.0 (TID 104). 3175 bytes result sent to driver
[2025-06-26T20:20:11.505+0700] {subprocess.py:93} INFO - 25/06/26 20:20:11 INFO Executor: Running task 120.0 in stage 0.0 (TID 120)
[2025-06-26T20:20:11.507+0700] {subprocess.py:93} INFO - 25/06/26 20:20:11 INFO TaskSetManager: Starting task 121.0 in stage 0.0 (TID 121) (localhost, executor driver, partition 121, PROCESS_LOCAL, 9215 bytes)
[2025-06-26T20:20:11.507+0700] {subprocess.py:93} INFO - 25/06/26 20:20:11 INFO Executor: Running task 121.0 in stage 0.0 (TID 121)
[2025-06-26T20:20:11.509+0700] {subprocess.py:93} INFO - 25/06/26 20:20:11 INFO Executor: Finished task 105.0 in stage 0.0 (TID 105). 3175 bytes result sent to driver
[2025-06-26T20:20:11.510+0700] {subprocess.py:93} INFO - 25/06/26 20:20:11 INFO TaskSetManager: Starting task 122.0 in stage 0.0 (TID 122) (localhost, executor driver, partition 122, PROCESS_LOCAL, 9215 bytes)
[2025-06-26T20:20:11.510+0700] {subprocess.py:93} INFO - 25/06/26 20:20:11 INFO TaskSetManager: Starting task 123.0 in stage 0.0 (TID 123) (localhost, executor driver, partition 123, PROCESS_LOCAL, 9215 bytes)
[2025-06-26T20:20:11.510+0700] {subprocess.py:93} INFO - 25/06/26 20:20:11 INFO Executor: Running task 123.0 in stage 0.0 (TID 123)
[2025-06-26T20:20:11.511+0700] {subprocess.py:93} INFO - 25/06/26 20:20:11 INFO TaskSetManager: Starting task 124.0 in stage 0.0 (TID 124) (localhost, executor driver, partition 124, PROCESS_LOCAL, 9215 bytes)
[2025-06-26T20:20:11.512+0700] {subprocess.py:93} INFO - 25/06/26 20:20:11 INFO Executor: Running task 122.0 in stage 0.0 (TID 122)
[2025-06-26T20:20:11.512+0700] {subprocess.py:93} INFO - 25/06/26 20:20:11 INFO Executor: Running task 124.0 in stage 0.0 (TID 124)
[2025-06-26T20:20:11.512+0700] {subprocess.py:93} INFO - 25/06/26 20:20:11 INFO TaskSetManager: Starting task 125.0 in stage 0.0 (TID 125) (localhost, executor driver, partition 125, PROCESS_LOCAL, 9215 bytes)
[2025-06-26T20:20:11.512+0700] {subprocess.py:93} INFO - 25/06/26 20:20:11 INFO TaskSetManager: Finished task 94.0 in stage 0.0 (TID 94) in 117 ms on localhost (executor driver) (93/2635)
[2025-06-26T20:20:11.512+0700] {subprocess.py:93} INFO - 25/06/26 20:20:11 INFO Executor: Running task 125.0 in stage 0.0 (TID 125)
[2025-06-26T20:20:11.512+0700] {subprocess.py:93} INFO - 25/06/26 20:20:11 INFO Executor: Finished task 106.0 in stage 0.0 (TID 106). 3175 bytes result sent to driver
[2025-06-26T20:20:11.513+0700] {subprocess.py:93} INFO - 25/06/26 20:20:11 INFO TaskSetManager: Finished task 96.0 in stage 0.0 (TID 96) in 102 ms on localhost (executor driver) (94/2635)
[2025-06-26T20:20:11.514+0700] {subprocess.py:93} INFO - 25/06/26 20:20:11 INFO Executor: Finished task 107.0 in stage 0.0 (TID 107). 3175 bytes result sent to driver
[2025-06-26T20:20:11.514+0700] {subprocess.py:93} INFO - 25/06/26 20:20:11 INFO TaskSetManager: Finished task 98.0 in stage 0.0 (TID 98) in 100 ms on localhost (executor driver) (95/2635)
[2025-06-26T20:20:11.514+0700] {subprocess.py:93} INFO - 25/06/26 20:20:11 INFO Executor: Finished task 103.0 in stage 0.0 (TID 103). 3175 bytes result sent to driver
[2025-06-26T20:20:11.514+0700] {subprocess.py:93} INFO - 25/06/26 20:20:11 INFO Executor: Finished task 108.0 in stage 0.0 (TID 108). 3175 bytes result sent to driver
[2025-06-26T20:20:11.515+0700] {subprocess.py:93} INFO - 25/06/26 20:20:11 INFO TaskSetManager: Finished task 100.0 in stage 0.0 (TID 100) in 98 ms on localhost (executor driver) (96/2635)
[2025-06-26T20:20:11.516+0700] {subprocess.py:93} INFO - 25/06/26 20:20:11 INFO TaskSetManager: Finished task 102.0 in stage 0.0 (TID 102) in 92 ms on localhost (executor driver) (97/2635)
[2025-06-26T20:20:11.516+0700] {subprocess.py:93} INFO - 25/06/26 20:20:11 INFO TaskSetManager: Finished task 101.0 in stage 0.0 (TID 101) in 99 ms on localhost (executor driver) (98/2635)
[2025-06-26T20:20:11.519+0700] {subprocess.py:93} INFO - 25/06/26 20:20:11 INFO TaskSetManager: Finished task 86.0 in stage 0.0 (TID 86) in 140 ms on localhost (executor driver) (99/2635)
[2025-06-26T20:20:11.520+0700] {subprocess.py:93} INFO - 25/06/26 20:20:11 INFO TaskSetManager: Finished task 99.0 in stage 0.0 (TID 99) in 104 ms on localhost (executor driver) (100/2635)
[2025-06-26T20:20:11.520+0700] {subprocess.py:93} INFO - 25/06/26 20:20:11 INFO TaskSetManager: Finished task 104.0 in stage 0.0 (TID 104) in 71 ms on localhost (executor driver) (101/2635)
[2025-06-26T20:20:11.520+0700] {subprocess.py:93} INFO - 25/06/26 20:20:11 INFO TaskSetManager: Finished task 97.0 in stage 0.0 (TID 97) in 106 ms on localhost (executor driver) (102/2635)
[2025-06-26T20:20:11.521+0700] {subprocess.py:93} INFO - 25/06/26 20:20:11 INFO TaskSetManager: Starting task 126.0 in stage 0.0 (TID 126) (localhost, executor driver, partition 126, PROCESS_LOCAL, 9215 bytes)
[2025-06-26T20:20:11.522+0700] {subprocess.py:93} INFO - 25/06/26 20:20:11 INFO Executor: Running task 126.0 in stage 0.0 (TID 126)
[2025-06-26T20:20:11.524+0700] {subprocess.py:93} INFO - 25/06/26 20:20:11 INFO TaskSetManager: Starting task 127.0 in stage 0.0 (TID 127) (localhost, executor driver, partition 127, PROCESS_LOCAL, 9215 bytes)
[2025-06-26T20:20:11.525+0700] {subprocess.py:93} INFO - 25/06/26 20:20:11 INFO TaskSetManager: Finished task 95.0 in stage 0.0 (TID 95) in 127 ms on localhost (executor driver) (103/2635)
[2025-06-26T20:20:11.526+0700] {subprocess.py:93} INFO - 25/06/26 20:20:11 INFO TaskSetManager: Finished task 105.0 in stage 0.0 (TID 105) in 75 ms on localhost (executor driver) (104/2635)
[2025-06-26T20:20:11.528+0700] {subprocess.py:93} INFO - 25/06/26 20:20:11 INFO TaskSetManager: Finished task 88.0 in stage 0.0 (TID 88) in 147 ms on localhost (executor driver) (105/2635)
[2025-06-26T20:20:11.546+0700] {subprocess.py:93} INFO - 25/06/26 20:20:11 INFO TaskSetManager: Finished task 106.0 in stage 0.0 (TID 106) in 78 ms on localhost (executor driver) (106/2635)
[2025-06-26T20:20:11.547+0700] {subprocess.py:93} INFO - 25/06/26 20:20:11 INFO Executor: Running task 127.0 in stage 0.0 (TID 127)
[2025-06-26T20:20:11.552+0700] {subprocess.py:93} INFO - 25/06/26 20:20:11 INFO Executor: Finished task 112.0 in stage 0.0 (TID 112). 3261 bytes result sent to driver
[2025-06-26T20:20:11.552+0700] {subprocess.py:93} INFO - 25/06/26 20:20:11 INFO Executor: Finished task 109.0 in stage 0.0 (TID 109). 3261 bytes result sent to driver
[2025-06-26T20:20:11.553+0700] {subprocess.py:93} INFO - 25/06/26 20:20:11 INFO Executor: Finished task 111.0 in stage 0.0 (TID 111). 3261 bytes result sent to driver
[2025-06-26T20:20:11.553+0700] {subprocess.py:93} INFO - 25/06/26 20:20:11 INFO Executor: Finished task 114.0 in stage 0.0 (TID 114). 3218 bytes result sent to driver
[2025-06-26T20:20:11.553+0700] {subprocess.py:93} INFO - 25/06/26 20:20:11 INFO Executor: Finished task 115.0 in stage 0.0 (TID 115). 3218 bytes result sent to driver
[2025-06-26T20:20:11.553+0700] {subprocess.py:93} INFO - 25/06/26 20:20:11 INFO Executor: Finished task 110.0 in stage 0.0 (TID 110). 3261 bytes result sent to driver
[2025-06-26T20:20:11.553+0700] {subprocess.py:93} INFO - 25/06/26 20:20:11 INFO Executor: Finished task 113.0 in stage 0.0 (TID 113). 3261 bytes result sent to driver
[2025-06-26T20:20:11.554+0700] {subprocess.py:93} INFO - 25/06/26 20:20:11 INFO TaskSetManager: Starting task 128.0 in stage 0.0 (TID 128) (localhost, executor driver, partition 128, PROCESS_LOCAL, 9215 bytes)
[2025-06-26T20:20:11.556+0700] {subprocess.py:93} INFO - 25/06/26 20:20:11 INFO Executor: Finished task 116.0 in stage 0.0 (TID 116). 3261 bytes result sent to driver
[2025-06-26T20:20:11.556+0700] {subprocess.py:93} INFO - 25/06/26 20:20:11 INFO Executor: Finished task 121.0 in stage 0.0 (TID 121). 3218 bytes result sent to driver
[2025-06-26T20:20:11.557+0700] {subprocess.py:93} INFO - 25/06/26 20:20:11 INFO Executor: Running task 128.0 in stage 0.0 (TID 128)
[2025-06-26T20:20:11.557+0700] {subprocess.py:93} INFO - 25/06/26 20:20:11 INFO TaskSetManager: Starting task 129.0 in stage 0.0 (TID 129) (localhost, executor driver, partition 129, PROCESS_LOCAL, 9215 bytes)
[2025-06-26T20:20:11.557+0700] {subprocess.py:93} INFO - 25/06/26 20:20:11 INFO TaskSetManager: Finished task 107.0 in stage 0.0 (TID 107) in 95 ms on localhost (executor driver) (107/2635)
[2025-06-26T20:20:11.559+0700] {subprocess.py:93} INFO - 25/06/26 20:20:11 INFO Executor: Running task 129.0 in stage 0.0 (TID 129)
[2025-06-26T20:20:11.559+0700] {subprocess.py:93} INFO - 25/06/26 20:20:11 INFO Executor: Finished task 118.0 in stage 0.0 (TID 118). 3218 bytes result sent to driver
[2025-06-26T20:20:11.561+0700] {subprocess.py:93} INFO - 25/06/26 20:20:11 INFO TaskSetManager: Starting task 130.0 in stage 0.0 (TID 130) (localhost, executor driver, partition 130, PROCESS_LOCAL, 9215 bytes)
[2025-06-26T20:20:11.561+0700] {subprocess.py:93} INFO - 25/06/26 20:20:11 INFO TaskSetManager: Finished task 103.0 in stage 0.0 (TID 103) in 114 ms on localhost (executor driver) (108/2635)
[2025-06-26T20:20:11.562+0700] {subprocess.py:93} INFO - 25/06/26 20:20:11 INFO Executor: Running task 130.0 in stage 0.0 (TID 130)
[2025-06-26T20:20:11.564+0700] {subprocess.py:93} INFO - 25/06/26 20:20:11 INFO Executor: Finished task 119.0 in stage 0.0 (TID 119). 3218 bytes result sent to driver
[2025-06-26T20:20:11.565+0700] {subprocess.py:93} INFO - 25/06/26 20:20:11 INFO Executor: Finished task 123.0 in stage 0.0 (TID 123). 3218 bytes result sent to driver
[2025-06-26T20:20:11.565+0700] {subprocess.py:93} INFO - 25/06/26 20:20:11 INFO TaskSetManager: Starting task 131.0 in stage 0.0 (TID 131) (localhost, executor driver, partition 131, PROCESS_LOCAL, 9215 bytes)
[2025-06-26T20:20:11.565+0700] {subprocess.py:93} INFO - 25/06/26 20:20:11 INFO Executor: Finished task 124.0 in stage 0.0 (TID 124). 3218 bytes result sent to driver
[2025-06-26T20:20:11.565+0700] {subprocess.py:93} INFO - 25/06/26 20:20:11 INFO Executor: Finished task 122.0 in stage 0.0 (TID 122). 3218 bytes result sent to driver
[2025-06-26T20:20:11.566+0700] {subprocess.py:93} INFO - 25/06/26 20:20:11 INFO Executor: Finished task 125.0 in stage 0.0 (TID 125). 3218 bytes result sent to driver
[2025-06-26T20:20:11.566+0700] {subprocess.py:93} INFO - 25/06/26 20:20:11 INFO Executor: Running task 131.0 in stage 0.0 (TID 131)
[2025-06-26T20:20:11.566+0700] {subprocess.py:93} INFO - 25/06/26 20:20:11 INFO TaskSetManager: Starting task 132.0 in stage 0.0 (TID 132) (localhost, executor driver, partition 132, PROCESS_LOCAL, 9215 bytes)
[2025-06-26T20:20:11.567+0700] {subprocess.py:93} INFO - 25/06/26 20:20:11 INFO Executor: Finished task 120.0 in stage 0.0 (TID 120). 3261 bytes result sent to driver
