[2025-06-26T19:40:03.088+0700] {local_task_job_runner.py:120} INFO - ::group::Pre task execution logs
[2025-06-26T19:40:03.107+0700] {taskinstance.py:2073} INFO - Dependencies all met for dep_context=non-requeueable deps ti=<TaskInstance: send_data_to_powerbi.compact_csv_to_one_file scheduled__2025-06-26T12:30:00+00:00 [queued]>
[2025-06-26T19:40:03.114+0700] {taskinstance.py:2073} INFO - Dependencies all met for dep_context=requeueable deps ti=<TaskInstance: send_data_to_powerbi.compact_csv_to_one_file scheduled__2025-06-26T12:30:00+00:00 [queued]>
[2025-06-26T19:40:03.114+0700] {taskinstance.py:2303} INFO - Starting attempt 1 of 3
[2025-06-26T19:40:03.129+0700] {taskinstance.py:2327} INFO - Executing <Task(BashOperator): compact_csv_to_one_file> on 2025-06-26 12:30:00+00:00
[2025-06-26T19:40:03.135+0700] {standard_task_runner.py:63} INFO - Started process 84035 to run task
[2025-06-26T19:40:03.140+0700] {standard_task_runner.py:90} INFO - Running: ['airflow', 'tasks', 'run', 'send_data_to_powerbi', 'compact_csv_to_one_file', 'scheduled__2025-06-26T12:30:00+00:00', '--job-id', '60', '--raw', '--subdir', 'DAGS_FOLDER/load_power_bi.py', '--cfg-path', '/tmp/tmpcbwyos2h']
[2025-06-26T19:40:03.141+0700] {standard_task_runner.py:91} INFO - Job 60: Subtask compact_csv_to_one_file
[2025-06-26T19:40:03.189+0700] {task_command.py:426} INFO - Running <TaskInstance: send_data_to_powerbi.compact_csv_to_one_file scheduled__2025-06-26T12:30:00+00:00 [running]> on host Panda
[2025-06-26T19:40:03.265+0700] {taskinstance.py:2644} INFO - Exporting env vars: AIRFLOW_CTX_DAG_OWNER='group_03' AIRFLOW_CTX_DAG_ID='send_data_to_powerbi' AIRFLOW_CTX_TASK_ID='compact_csv_to_one_file' AIRFLOW_CTX_EXECUTION_DATE='2025-06-26T12:30:00+00:00' AIRFLOW_CTX_TRY_NUMBER='1' AIRFLOW_CTX_DAG_RUN_ID='scheduled__2025-06-26T12:30:00+00:00'
[2025-06-26T19:40:03.267+0700] {taskinstance.py:430} INFO - ::endgroup::
[2025-06-26T19:40:03.267+0700] {subprocess.py:63} INFO - Tmp dir root location: /tmp
[2025-06-26T19:40:03.268+0700] {subprocess.py:75} INFO - Running command: ['/usr/bin/bash', '-c', 'spark-submit /home/panda/Documents/ODAP/Project/hadoop/compact_csv.py && sleep 10']
[2025-06-26T19:40:03.283+0700] {subprocess.py:86} INFO - Output:
[2025-06-26T19:40:05.668+0700] {subprocess.py:93} INFO - 25/06/26 19:40:05 INFO SparkContext: Running Spark version 3.5.5
[2025-06-26T19:40:05.671+0700] {subprocess.py:93} INFO - 25/06/26 19:40:05 INFO SparkContext: OS info Linux, 6.11.0-26-generic, amd64
[2025-06-26T19:40:05.671+0700] {subprocess.py:93} INFO - 25/06/26 19:40:05 INFO SparkContext: Java version 11.0.27
[2025-06-26T19:40:05.830+0700] {subprocess.py:93} INFO - 25/06/26 19:40:05 INFO ResourceUtils: ==============================================================
[2025-06-26T19:40:05.831+0700] {subprocess.py:93} INFO - 25/06/26 19:40:05 INFO ResourceUtils: No custom resources configured for spark.driver.
[2025-06-26T19:40:05.831+0700] {subprocess.py:93} INFO - 25/06/26 19:40:05 INFO ResourceUtils: ==============================================================
[2025-06-26T19:40:05.831+0700] {subprocess.py:93} INFO - 25/06/26 19:40:05 INFO SparkContext: Submitted application: CompactSmallFiles
[2025-06-26T19:40:05.853+0700] {subprocess.py:93} INFO - 25/06/26 19:40:05 INFO ResourceProfile: Default ResourceProfile created, executor resources: Map(cores -> name: cores, amount: 1, script: , vendor: , memory -> name: memory, amount: 1024, script: , vendor: , offHeap -> name: offHeap, amount: 0, script: , vendor: ), task resources: Map(cpus -> name: cpus, amount: 1.0)
[2025-06-26T19:40:05.865+0700] {subprocess.py:93} INFO - 25/06/26 19:40:05 INFO ResourceProfile: Limiting resource is cpu
[2025-06-26T19:40:05.865+0700] {subprocess.py:93} INFO - 25/06/26 19:40:05 INFO ResourceProfileManager: Added ResourceProfile id: 0
[2025-06-26T19:40:05.925+0700] {subprocess.py:93} INFO - 25/06/26 19:40:05 INFO SecurityManager: Changing view acls to: panda
[2025-06-26T19:40:05.926+0700] {subprocess.py:93} INFO - 25/06/26 19:40:05 INFO SecurityManager: Changing modify acls to: panda
[2025-06-26T19:40:05.926+0700] {subprocess.py:93} INFO - 25/06/26 19:40:05 INFO SecurityManager: Changing view acls groups to:
[2025-06-26T19:40:05.926+0700] {subprocess.py:93} INFO - 25/06/26 19:40:05 INFO SecurityManager: Changing modify acls groups to:
[2025-06-26T19:40:05.927+0700] {subprocess.py:93} INFO - 25/06/26 19:40:05 INFO SecurityManager: SecurityManager: authentication disabled; ui acls disabled; users with view permissions: panda; groups with view permissions: EMPTY; users with modify permissions: panda; groups with modify permissions: EMPTY
[2025-06-26T19:40:06.165+0700] {subprocess.py:93} INFO - 25/06/26 19:40:06 INFO Utils: Successfully started service 'sparkDriver' on port 45299.
[2025-06-26T19:40:06.195+0700] {subprocess.py:93} INFO - 25/06/26 19:40:06 INFO SparkEnv: Registering MapOutputTracker
[2025-06-26T19:40:06.253+0700] {subprocess.py:93} INFO - 25/06/26 19:40:06 INFO SparkEnv: Registering BlockManagerMaster
[2025-06-26T19:40:06.280+0700] {subprocess.py:93} INFO - 25/06/26 19:40:06 INFO BlockManagerMasterEndpoint: Using org.apache.spark.storage.DefaultTopologyMapper for getting topology information
[2025-06-26T19:40:06.280+0700] {subprocess.py:93} INFO - 25/06/26 19:40:06 INFO BlockManagerMasterEndpoint: BlockManagerMasterEndpoint up
[2025-06-26T19:40:06.285+0700] {subprocess.py:93} INFO - 25/06/26 19:40:06 INFO SparkEnv: Registering BlockManagerMasterHeartbeat
[2025-06-26T19:40:06.312+0700] {subprocess.py:93} INFO - 25/06/26 19:40:06 INFO DiskBlockManager: Created local directory at /tmp/blockmgr-d1ecb5b7-f209-44b9-8429-3c0d34c0051e
[2025-06-26T19:40:06.329+0700] {subprocess.py:93} INFO - 25/06/26 19:40:06 INFO MemoryStore: MemoryStore started with capacity 434.4 MiB
[2025-06-26T19:40:06.346+0700] {subprocess.py:93} INFO - 25/06/26 19:40:06 INFO SparkEnv: Registering OutputCommitCoordinator
[2025-06-26T19:40:06.505+0700] {subprocess.py:93} INFO - 25/06/26 19:40:06 INFO JettyUtils: Start Jetty 127.0.0.1:4040 for SparkUI
[2025-06-26T19:40:06.574+0700] {subprocess.py:93} INFO - 25/06/26 19:40:06 WARN Utils: Service 'SparkUI' could not bind on port 4040. Attempting port 4041.
[2025-06-26T19:40:06.590+0700] {subprocess.py:93} INFO - 25/06/26 19:40:06 INFO Utils: Successfully started service 'SparkUI' on port 4041.
[2025-06-26T19:40:06.728+0700] {subprocess.py:93} INFO - 25/06/26 19:40:06 INFO Executor: Starting executor ID driver on host localhost
[2025-06-26T19:40:06.729+0700] {subprocess.py:93} INFO - 25/06/26 19:40:06 INFO Executor: OS info Linux, 6.11.0-26-generic, amd64
[2025-06-26T19:40:06.729+0700] {subprocess.py:93} INFO - 25/06/26 19:40:06 INFO Executor: Java version 11.0.27
[2025-06-26T19:40:06.742+0700] {subprocess.py:93} INFO - 25/06/26 19:40:06 INFO Executor: Starting executor with user classpath (userClassPathFirst = false): ''
[2025-06-26T19:40:06.744+0700] {subprocess.py:93} INFO - 25/06/26 19:40:06 INFO Executor: Created or updated repl class loader org.apache.spark.util.MutableURLClassLoader@e06c4fd for default.
[2025-06-26T19:40:06.779+0700] {subprocess.py:93} INFO - 25/06/26 19:40:06 INFO Utils: Successfully started service 'org.apache.spark.network.netty.NettyBlockTransferService' on port 35635.
[2025-06-26T19:40:06.780+0700] {subprocess.py:93} INFO - 25/06/26 19:40:06 INFO NettyBlockTransferService: Server created on localhost:35635
[2025-06-26T19:40:06.782+0700] {subprocess.py:93} INFO - 25/06/26 19:40:06 INFO BlockManager: Using org.apache.spark.storage.RandomBlockReplicationPolicy for block replication policy
[2025-06-26T19:40:06.793+0700] {subprocess.py:93} INFO - 25/06/26 19:40:06 INFO BlockManagerMaster: Registering BlockManager BlockManagerId(driver, localhost, 35635, None)
[2025-06-26T19:40:06.799+0700] {subprocess.py:93} INFO - 25/06/26 19:40:06 INFO BlockManagerMasterEndpoint: Registering block manager localhost:35635 with 434.4 MiB RAM, BlockManagerId(driver, localhost, 35635, None)
[2025-06-26T19:40:06.803+0700] {subprocess.py:93} INFO - 25/06/26 19:40:06 INFO BlockManagerMaster: Registered BlockManager BlockManagerId(driver, localhost, 35635, None)
[2025-06-26T19:40:06.804+0700] {subprocess.py:93} INFO - 25/06/26 19:40:06 INFO BlockManager: Initialized BlockManager: BlockManagerId(driver, localhost, 35635, None)
[2025-06-26T19:40:07.307+0700] {subprocess.py:93} INFO - 25/06/26 19:40:07 INFO SharedState: Setting hive.metastore.warehouse.dir ('null') to the value of spark.sql.warehouse.dir.
[2025-06-26T19:40:07.316+0700] {subprocess.py:93} INFO - 25/06/26 19:40:07 INFO SharedState: Warehouse path is 'file:/tmp/airflowtmpa092cdcv/spark-warehouse'.
[2025-06-26T19:40:08.544+0700] {subprocess.py:93} INFO - 25/06/26 19:40:08 INFO MetadataLogFileIndex: Reading streaming file log from hdfs://localhost:9000/transactions_by_hour/_spark_metadata
[2025-06-26T19:40:08.618+0700] {subprocess.py:93} INFO - 25/06/26 19:40:08 INFO FileStreamSinkLog: BatchIds found from listing: 1150, 1151, 1152, 1153, 1154, 1155, 1156, 1157, 1158, 1159, 1160, 1161, 1162, 1163, 1164, 1165, 1166, 1167, 1168, 1169, 1170, 1171, 1172, 1173, 1174, 1175, 1176, 1177, 1178, 1179, 1180, 1181, 1182, 1183, 1184, 1185, 1186, 1187, 1188, 1189, 1190, 1191, 1192, 1193, 1194, 1195, 1196, 1197, 1198, 1199, 1200, 1201, 1202, 1203, 1204, 1205, 1206, 1207, 1208, 1209, 1210, 1211, 1212, 1213, 1214, 1215, 1216, 1217, 1218, 1219, 1220, 1221, 1222, 1223, 1224, 1225, 1226, 1227, 1228, 1229, 1230, 1231, 1232, 1233, 1234, 1235, 1236, 1237, 1238, 1239, 1240, 1241, 1242, 1243, 1244, 1245, 1246, 1247, 1248, 1249, 1250, 1251, 1252, 1253, 1254, 1255, 1256, 1257, 1258, 1259, 1260, 1261, 1262, 1263, 1264, 1265, 1266, 1267, 1268, 1269, 1270, 1271, 1272, 1273, 1274, 1275, 1276, 1277, 1278, 1279, 1280, 1281, 1282, 1283, 1284, 1285, 1286, 1287, 1288, 1289, 1290, 1291, 1292, 1293, 1294, 1295, 1296, 1297, 1298, 1299, 1300, 1301, 1302, 1303, 1304, 1305, 1306, 1307, 1308, 1309, 1310, 1311, 1312, 1313, 1314, 1315, 1316, 1317, 1318, 1319, 1320, 1321, 1322, 1323, 1324, 1325, 1326, 1327, 1328, 1329, 1330, 1331, 1332, 1333, 1334, 1335, 1336, 1337, 1338, 1339, 1340, 1341, 1342, 1343, 1344, 1345, 1346, 1347, 1348, 1349, 1350, 1351, 1352, 1353, 1354, 1355, 1356, 1357, 1358, 1359, 1360, 1361, 1362, 1363, 1364, 1365, 1366, 1367, 1368, 1369, 1370, 1371, 1372, 1373, 1374, 1375, 1376, 1377, 1378, 1379, 1380, 1381, 1382, 1383, 1384, 1385, 1386, 1387, 1388, 1389, 1390, 1391, 1392, 1393, 1394, 1395, 1396, 1397, 1398, 1399, 1400, 1401, 1402, 1403, 1404, 1405, 1406, 1407, 1408, 1409, 1410, 1411, 1412, 1413, 1414, 1415, 1416, 1417, 1418, 1419, 1420, 1421, 1422, 1423, 1424, 1425, 1426, 1427, 1428, 1429, 1430, 1431, 1432, 1433, 1434, 1435, 1436, 1437, 1438, 1439, 1440, 1441, 1442, 1443, 1444, 1445, 1446, 1447, 1448, 1449, 1450, 1451, 1452, 1453
[2025-06-26T19:40:08.651+0700] {subprocess.py:93} INFO - 25/06/26 19:40:08 INFO FileStreamSinkLog: Set the compact interval to 10 [defaultCompactInterval: 10]
[2025-06-26T19:40:09.261+0700] {subprocess.py:93} INFO - 25/06/26 19:40:09 INFO HadoopFSUtils: Listing leaf files and directories in parallel under 1454 paths. The first several paths are: hdfs://localhost:9000/transactions_by_hour/part-00000-35848e14-b857-426e-8939-db9c96261483-c000.csv, hdfs://localhost:9000/transactions_by_hour/part-00000-d7ab39d9-b4ef-4e2e-b472-4c1883c38273-c000.csv, hdfs://localhost:9000/transactions_by_hour/part-00000-cce2d287-6512-49d1-aa31-f452c0dcdaf9-c000.csv, hdfs://localhost:9000/transactions_by_hour/part-00000-ac8933a1-5bf2-4814-a228-6604c7045e4c-c000.csv, hdfs://localhost:9000/transactions_by_hour/part-00000-9c60d322-8794-4968-a7a5-364181d16d94-c000.csv, hdfs://localhost:9000/transactions_by_hour/part-00000-76895572-6aa7-4225-8325-6962e0c98ee2-c000.csv, hdfs://localhost:9000/transactions_by_hour/part-00000-a92a3ce5-6132-4e9e-8e69-11e47f72f0a2-c000.csv, hdfs://localhost:9000/transactions_by_hour/part-00000-b48a08d4-d847-4307-b612-e35a8f471916-c000.csv, hdfs://localhost:9000/transactions_by_hour/part-00000-e8f1544c-6d23-403f-a02b-06e9bef1638a-c000.csv, hdfs://localhost:9000/transactions_by_hour/part-00000-08040c60-6fee-4dcc-b2e9-af62320fb049-c000.csv.
[2025-06-26T19:40:09.656+0700] {subprocess.py:93} INFO - 25/06/26 19:40:09 INFO SparkContext: Starting job: csv at NativeMethodAccessorImpl.java:0
[2025-06-26T19:40:09.678+0700] {subprocess.py:93} INFO - 25/06/26 19:40:09 INFO DAGScheduler: Got job 0 (csv at NativeMethodAccessorImpl.java:0) with 1454 output partitions
[2025-06-26T19:40:09.679+0700] {subprocess.py:93} INFO - 25/06/26 19:40:09 INFO DAGScheduler: Final stage: ResultStage 0 (csv at NativeMethodAccessorImpl.java:0)
[2025-06-26T19:40:09.679+0700] {subprocess.py:93} INFO - 25/06/26 19:40:09 INFO DAGScheduler: Parents of final stage: List()
[2025-06-26T19:40:09.680+0700] {subprocess.py:93} INFO - 25/06/26 19:40:09 INFO DAGScheduler: Missing parents: List()
[2025-06-26T19:40:09.684+0700] {subprocess.py:93} INFO - 25/06/26 19:40:09 INFO DAGScheduler: Submitting ResultStage 0 (MapPartitionsRDD[1] at csv at NativeMethodAccessorImpl.java:0), which has no missing parents
[2025-06-26T19:40:09.802+0700] {subprocess.py:93} INFO - 25/06/26 19:40:09 INFO MemoryStore: Block broadcast_0 stored as values in memory (estimated size 103.2 KiB, free 434.3 MiB)
[2025-06-26T19:40:09.837+0700] {subprocess.py:93} INFO - 25/06/26 19:40:09 INFO MemoryStore: Block broadcast_0_piece0 stored as bytes in memory (estimated size 37.3 KiB, free 434.3 MiB)
[2025-06-26T19:40:09.840+0700] {subprocess.py:93} INFO - 25/06/26 19:40:09 INFO BlockManagerInfo: Added broadcast_0_piece0 in memory on localhost:35635 (size: 37.3 KiB, free: 434.4 MiB)
[2025-06-26T19:40:09.845+0700] {subprocess.py:93} INFO - 25/06/26 19:40:09 INFO SparkContext: Created broadcast 0 from broadcast at DAGScheduler.scala:1585
[2025-06-26T19:40:09.879+0700] {subprocess.py:93} INFO - 25/06/26 19:40:09 INFO DAGScheduler: Submitting 1454 missing tasks from ResultStage 0 (MapPartitionsRDD[1] at csv at NativeMethodAccessorImpl.java:0) (first 15 tasks are for partitions Vector(0, 1, 2, 3, 4, 5, 6, 7, 8, 9, 10, 11, 12, 13, 14))
[2025-06-26T19:40:09.881+0700] {subprocess.py:93} INFO - 25/06/26 19:40:09 INFO TaskSchedulerImpl: Adding task set 0.0 with 1454 tasks resource profile 0
[2025-06-26T19:40:09.970+0700] {subprocess.py:93} INFO - 25/06/26 19:40:09 INFO TaskSetManager: Starting task 0.0 in stage 0.0 (TID 0) (localhost, executor driver, partition 0, PROCESS_LOCAL, 9215 bytes)
[2025-06-26T19:40:09.977+0700] {subprocess.py:93} INFO - 25/06/26 19:40:09 INFO TaskSetManager: Starting task 1.0 in stage 0.0 (TID 1) (localhost, executor driver, partition 1, PROCESS_LOCAL, 9215 bytes)
[2025-06-26T19:40:09.978+0700] {subprocess.py:93} INFO - 25/06/26 19:40:09 INFO TaskSetManager: Starting task 2.0 in stage 0.0 (TID 2) (localhost, executor driver, partition 2, PROCESS_LOCAL, 9215 bytes)
[2025-06-26T19:40:09.978+0700] {subprocess.py:93} INFO - 25/06/26 19:40:09 INFO TaskSetManager: Starting task 3.0 in stage 0.0 (TID 3) (localhost, executor driver, partition 3, PROCESS_LOCAL, 9215 bytes)
[2025-06-26T19:40:09.979+0700] {subprocess.py:93} INFO - 25/06/26 19:40:09 INFO TaskSetManager: Starting task 4.0 in stage 0.0 (TID 4) (localhost, executor driver, partition 4, PROCESS_LOCAL, 9215 bytes)
[2025-06-26T19:40:09.979+0700] {subprocess.py:93} INFO - 25/06/26 19:40:09 INFO TaskSetManager: Starting task 5.0 in stage 0.0 (TID 5) (localhost, executor driver, partition 5, PROCESS_LOCAL, 9215 bytes)
[2025-06-26T19:40:09.981+0700] {subprocess.py:93} INFO - 25/06/26 19:40:09 INFO TaskSetManager: Starting task 6.0 in stage 0.0 (TID 6) (localhost, executor driver, partition 6, PROCESS_LOCAL, 9215 bytes)
[2025-06-26T19:40:09.981+0700] {subprocess.py:93} INFO - 25/06/26 19:40:09 INFO TaskSetManager: Starting task 7.0 in stage 0.0 (TID 7) (localhost, executor driver, partition 7, PROCESS_LOCAL, 9215 bytes)
[2025-06-26T19:40:09.982+0700] {subprocess.py:93} INFO - 25/06/26 19:40:09 INFO TaskSetManager: Starting task 8.0 in stage 0.0 (TID 8) (localhost, executor driver, partition 8, PROCESS_LOCAL, 9215 bytes)
[2025-06-26T19:40:09.982+0700] {subprocess.py:93} INFO - 25/06/26 19:40:09 INFO TaskSetManager: Starting task 9.0 in stage 0.0 (TID 9) (localhost, executor driver, partition 9, PROCESS_LOCAL, 9215 bytes)
[2025-06-26T19:40:09.983+0700] {subprocess.py:93} INFO - 25/06/26 19:40:09 INFO TaskSetManager: Starting task 10.0 in stage 0.0 (TID 10) (localhost, executor driver, partition 10, PROCESS_LOCAL, 9215 bytes)
[2025-06-26T19:40:09.983+0700] {subprocess.py:93} INFO - 25/06/26 19:40:09 INFO TaskSetManager: Starting task 11.0 in stage 0.0 (TID 11) (localhost, executor driver, partition 11, PROCESS_LOCAL, 9215 bytes)
[2025-06-26T19:40:09.984+0700] {subprocess.py:93} INFO - 25/06/26 19:40:09 INFO TaskSetManager: Starting task 12.0 in stage 0.0 (TID 12) (localhost, executor driver, partition 12, PROCESS_LOCAL, 9215 bytes)
[2025-06-26T19:40:09.984+0700] {subprocess.py:93} INFO - 25/06/26 19:40:09 INFO TaskSetManager: Starting task 13.0 in stage 0.0 (TID 13) (localhost, executor driver, partition 13, PROCESS_LOCAL, 9215 bytes)
[2025-06-26T19:40:09.985+0700] {subprocess.py:93} INFO - 25/06/26 19:40:09 INFO TaskSetManager: Starting task 14.0 in stage 0.0 (TID 14) (localhost, executor driver, partition 14, PROCESS_LOCAL, 9215 bytes)
[2025-06-26T19:40:09.986+0700] {subprocess.py:93} INFO - 25/06/26 19:40:09 INFO TaskSetManager: Starting task 15.0 in stage 0.0 (TID 15) (localhost, executor driver, partition 15, PROCESS_LOCAL, 9215 bytes)
[2025-06-26T19:40:09.987+0700] {subprocess.py:93} INFO - 25/06/26 19:40:09 INFO TaskSetManager: Starting task 16.0 in stage 0.0 (TID 16) (localhost, executor driver, partition 16, PROCESS_LOCAL, 9215 bytes)
[2025-06-26T19:40:09.987+0700] {subprocess.py:93} INFO - 25/06/26 19:40:09 INFO TaskSetManager: Starting task 17.0 in stage 0.0 (TID 17) (localhost, executor driver, partition 17, PROCESS_LOCAL, 9215 bytes)
[2025-06-26T19:40:09.988+0700] {subprocess.py:93} INFO - 25/06/26 19:40:09 INFO TaskSetManager: Starting task 18.0 in stage 0.0 (TID 18) (localhost, executor driver, partition 18, PROCESS_LOCAL, 9215 bytes)
[2025-06-26T19:40:09.989+0700] {subprocess.py:93} INFO - 25/06/26 19:40:09 INFO TaskSetManager: Starting task 19.0 in stage 0.0 (TID 19) (localhost, executor driver, partition 19, PROCESS_LOCAL, 9215 bytes)
[2025-06-26T19:40:09.989+0700] {subprocess.py:93} INFO - 25/06/26 19:40:09 INFO TaskSetManager: Starting task 20.0 in stage 0.0 (TID 20) (localhost, executor driver, partition 20, PROCESS_LOCAL, 9215 bytes)
[2025-06-26T19:40:09.989+0700] {subprocess.py:93} INFO - 25/06/26 19:40:09 INFO TaskSetManager: Starting task 21.0 in stage 0.0 (TID 21) (localhost, executor driver, partition 21, PROCESS_LOCAL, 9215 bytes)
[2025-06-26T19:40:10.008+0700] {subprocess.py:93} INFO - 25/06/26 19:40:10 INFO Executor: Running task 6.0 in stage 0.0 (TID 6)
[2025-06-26T19:40:10.009+0700] {subprocess.py:93} INFO - 25/06/26 19:40:10 INFO Executor: Running task 15.0 in stage 0.0 (TID 15)
[2025-06-26T19:40:10.009+0700] {subprocess.py:93} INFO - 25/06/26 19:40:10 INFO Executor: Running task 7.0 in stage 0.0 (TID 7)
[2025-06-26T19:40:10.009+0700] {subprocess.py:93} INFO - 25/06/26 19:40:10 INFO Executor: Running task 2.0 in stage 0.0 (TID 2)
[2025-06-26T19:40:10.009+0700] {subprocess.py:93} INFO - 25/06/26 19:40:10 INFO Executor: Running task 5.0 in stage 0.0 (TID 5)
[2025-06-26T19:40:10.009+0700] {subprocess.py:93} INFO - 25/06/26 19:40:10 INFO Executor: Running task 14.0 in stage 0.0 (TID 14)
[2025-06-26T19:40:10.009+0700] {subprocess.py:93} INFO - 25/06/26 19:40:10 INFO Executor: Running task 3.0 in stage 0.0 (TID 3)
[2025-06-26T19:40:10.009+0700] {subprocess.py:93} INFO - 25/06/26 19:40:10 INFO Executor: Running task 1.0 in stage 0.0 (TID 1)
[2025-06-26T19:40:10.009+0700] {subprocess.py:93} INFO - 25/06/26 19:40:10 INFO Executor: Running task 9.0 in stage 0.0 (TID 9)
[2025-06-26T19:40:10.009+0700] {subprocess.py:93} INFO - 25/06/26 19:40:10 INFO Executor: Running task 21.0 in stage 0.0 (TID 21)
[2025-06-26T19:40:10.010+0700] {subprocess.py:93} INFO - 25/06/26 19:40:10 INFO Executor: Running task 11.0 in stage 0.0 (TID 11)
[2025-06-26T19:40:10.010+0700] {subprocess.py:93} INFO - 25/06/26 19:40:10 INFO Executor: Running task 17.0 in stage 0.0 (TID 17)
[2025-06-26T19:40:10.010+0700] {subprocess.py:93} INFO - 25/06/26 19:40:10 INFO Executor: Running task 10.0 in stage 0.0 (TID 10)
[2025-06-26T19:40:10.010+0700] {subprocess.py:93} INFO - 25/06/26 19:40:10 INFO Executor: Running task 16.0 in stage 0.0 (TID 16)
[2025-06-26T19:40:10.010+0700] {subprocess.py:93} INFO - 25/06/26 19:40:10 INFO Executor: Running task 19.0 in stage 0.0 (TID 19)
[2025-06-26T19:40:10.010+0700] {subprocess.py:93} INFO - 25/06/26 19:40:10 INFO Executor: Running task 18.0 in stage 0.0 (TID 18)
[2025-06-26T19:40:10.010+0700] {subprocess.py:93} INFO - 25/06/26 19:40:10 INFO Executor: Running task 8.0 in stage 0.0 (TID 8)
[2025-06-26T19:40:10.010+0700] {subprocess.py:93} INFO - 25/06/26 19:40:10 INFO Executor: Running task 4.0 in stage 0.0 (TID 4)
[2025-06-26T19:40:10.010+0700] {subprocess.py:93} INFO - 25/06/26 19:40:10 INFO Executor: Running task 0.0 in stage 0.0 (TID 0)
[2025-06-26T19:40:10.010+0700] {subprocess.py:93} INFO - 25/06/26 19:40:10 INFO Executor: Running task 12.0 in stage 0.0 (TID 12)
[2025-06-26T19:40:10.011+0700] {subprocess.py:93} INFO - 25/06/26 19:40:10 INFO Executor: Running task 13.0 in stage 0.0 (TID 13)
[2025-06-26T19:40:10.011+0700] {subprocess.py:93} INFO - 25/06/26 19:40:10 INFO Executor: Running task 20.0 in stage 0.0 (TID 20)
[2025-06-26T19:40:10.327+0700] {subprocess.py:93} INFO - 25/06/26 19:40:10 INFO Executor: Finished task 21.0 in stage 0.0 (TID 21). 3261 bytes result sent to driver
[2025-06-26T19:40:10.328+0700] {subprocess.py:93} INFO - 25/06/26 19:40:10 INFO Executor: Finished task 12.0 in stage 0.0 (TID 12). 3261 bytes result sent to driver
[2025-06-26T19:40:10.328+0700] {subprocess.py:93} INFO - 25/06/26 19:40:10 INFO Executor: Finished task 18.0 in stage 0.0 (TID 18). 3261 bytes result sent to driver
[2025-06-26T19:40:10.329+0700] {subprocess.py:93} INFO - 25/06/26 19:40:10 INFO Executor: Finished task 10.0 in stage 0.0 (TID 10). 3261 bytes result sent to driver
[2025-06-26T19:40:10.329+0700] {subprocess.py:93} INFO - 25/06/26 19:40:10 INFO Executor: Finished task 2.0 in stage 0.0 (TID 2). 3261 bytes result sent to driver
[2025-06-26T19:40:10.329+0700] {subprocess.py:93} INFO - 25/06/26 19:40:10 INFO Executor: Finished task 11.0 in stage 0.0 (TID 11). 3261 bytes result sent to driver
[2025-06-26T19:40:10.329+0700] {subprocess.py:93} INFO - 25/06/26 19:40:10 INFO Executor: Finished task 7.0 in stage 0.0 (TID 7). 3261 bytes result sent to driver
[2025-06-26T19:40:10.329+0700] {subprocess.py:93} INFO - 25/06/26 19:40:10 INFO Executor: Finished task 1.0 in stage 0.0 (TID 1). 3261 bytes result sent to driver
[2025-06-26T19:40:10.329+0700] {subprocess.py:93} INFO - 25/06/26 19:40:10 INFO Executor: Finished task 8.0 in stage 0.0 (TID 8). 3261 bytes result sent to driver
[2025-06-26T19:40:10.329+0700] {subprocess.py:93} INFO - 25/06/26 19:40:10 INFO Executor: Finished task 0.0 in stage 0.0 (TID 0). 3261 bytes result sent to driver
[2025-06-26T19:40:10.330+0700] {subprocess.py:93} INFO - 25/06/26 19:40:10 INFO Executor: Finished task 14.0 in stage 0.0 (TID 14). 3261 bytes result sent to driver
[2025-06-26T19:40:10.330+0700] {subprocess.py:93} INFO - 25/06/26 19:40:10 INFO Executor: Finished task 17.0 in stage 0.0 (TID 17). 3261 bytes result sent to driver
[2025-06-26T19:40:10.330+0700] {subprocess.py:93} INFO - 25/06/26 19:40:10 INFO Executor: Finished task 19.0 in stage 0.0 (TID 19). 3261 bytes result sent to driver
[2025-06-26T19:40:10.330+0700] {subprocess.py:93} INFO - 25/06/26 19:40:10 INFO Executor: Finished task 9.0 in stage 0.0 (TID 9). 3261 bytes result sent to driver
[2025-06-26T19:40:10.330+0700] {subprocess.py:93} INFO - 25/06/26 19:40:10 INFO Executor: Finished task 5.0 in stage 0.0 (TID 5). 3261 bytes result sent to driver
[2025-06-26T19:40:10.330+0700] {subprocess.py:93} INFO - 25/06/26 19:40:10 INFO Executor: Finished task 15.0 in stage 0.0 (TID 15). 3261 bytes result sent to driver
[2025-06-26T19:40:10.330+0700] {subprocess.py:93} INFO - 25/06/26 19:40:10 INFO Executor: Finished task 3.0 in stage 0.0 (TID 3). 3261 bytes result sent to driver
[2025-06-26T19:40:10.330+0700] {subprocess.py:93} INFO - 25/06/26 19:40:10 INFO Executor: Finished task 4.0 in stage 0.0 (TID 4). 3261 bytes result sent to driver
[2025-06-26T19:40:10.330+0700] {subprocess.py:93} INFO - 25/06/26 19:40:10 INFO Executor: Finished task 6.0 in stage 0.0 (TID 6). 3261 bytes result sent to driver
[2025-06-26T19:40:10.331+0700] {subprocess.py:93} INFO - 25/06/26 19:40:10 INFO Executor: Finished task 16.0 in stage 0.0 (TID 16). 3261 bytes result sent to driver
[2025-06-26T19:40:10.331+0700] {subprocess.py:93} INFO - 25/06/26 19:40:10 INFO Executor: Finished task 13.0 in stage 0.0 (TID 13). 3261 bytes result sent to driver
[2025-06-26T19:40:10.331+0700] {subprocess.py:93} INFO - 25/06/26 19:40:10 INFO Executor: Finished task 20.0 in stage 0.0 (TID 20). 3261 bytes result sent to driver
[2025-06-26T19:40:10.336+0700] {subprocess.py:93} INFO - 25/06/26 19:40:10 INFO TaskSetManager: Starting task 22.0 in stage 0.0 (TID 22) (localhost, executor driver, partition 22, PROCESS_LOCAL, 9215 bytes)
[2025-06-26T19:40:10.338+0700] {subprocess.py:93} INFO - 25/06/26 19:40:10 INFO Executor: Running task 22.0 in stage 0.0 (TID 22)
[2025-06-26T19:40:10.339+0700] {subprocess.py:93} INFO - 25/06/26 19:40:10 INFO TaskSetManager: Starting task 23.0 in stage 0.0 (TID 23) (localhost, executor driver, partition 23, PROCESS_LOCAL, 9215 bytes)
[2025-06-26T19:40:10.340+0700] {subprocess.py:93} INFO - 25/06/26 19:40:10 INFO Executor: Running task 23.0 in stage 0.0 (TID 23)
[2025-06-26T19:40:10.341+0700] {subprocess.py:93} INFO - 25/06/26 19:40:10 INFO TaskSetManager: Starting task 24.0 in stage 0.0 (TID 24) (localhost, executor driver, partition 24, PROCESS_LOCAL, 9215 bytes)
[2025-06-26T19:40:10.342+0700] {subprocess.py:93} INFO - 25/06/26 19:40:10 INFO Executor: Running task 24.0 in stage 0.0 (TID 24)
[2025-06-26T19:40:10.343+0700] {subprocess.py:93} INFO - 25/06/26 19:40:10 INFO TaskSetManager: Finished task 17.0 in stage 0.0 (TID 17) in 354 ms on localhost (executor driver) (1/1454)
[2025-06-26T19:40:10.345+0700] {subprocess.py:93} INFO - 25/06/26 19:40:10 INFO TaskSetManager: Finished task 6.0 in stage 0.0 (TID 6) in 366 ms on localhost (executor driver) (2/1454)
[2025-06-26T19:40:10.347+0700] {subprocess.py:93} INFO - 25/06/26 19:40:10 INFO TaskSetManager: Starting task 25.0 in stage 0.0 (TID 25) (localhost, executor driver, partition 25, PROCESS_LOCAL, 9215 bytes)
[2025-06-26T19:40:10.348+0700] {subprocess.py:93} INFO - 25/06/26 19:40:10 INFO TaskSetManager: Finished task 5.0 in stage 0.0 (TID 5) in 369 ms on localhost (executor driver) (3/1454)
[2025-06-26T19:40:10.348+0700] {subprocess.py:93} INFO - 25/06/26 19:40:10 INFO Executor: Running task 25.0 in stage 0.0 (TID 25)
[2025-06-26T19:40:10.349+0700] {subprocess.py:93} INFO - 25/06/26 19:40:10 INFO TaskSetManager: Starting task 26.0 in stage 0.0 (TID 26) (localhost, executor driver, partition 26, PROCESS_LOCAL, 9215 bytes)
[2025-06-26T19:40:10.350+0700] {subprocess.py:93} INFO - 25/06/26 19:40:10 INFO TaskSetManager: Finished task 3.0 in stage 0.0 (TID 3) in 372 ms on localhost (executor driver) (4/1454)
[2025-06-26T19:40:10.350+0700] {subprocess.py:93} INFO - 25/06/26 19:40:10 INFO Executor: Running task 26.0 in stage 0.0 (TID 26)
[2025-06-26T19:40:10.351+0700] {subprocess.py:93} INFO - 25/06/26 19:40:10 INFO TaskSetManager: Starting task 27.0 in stage 0.0 (TID 27) (localhost, executor driver, partition 27, PROCESS_LOCAL, 9215 bytes)
[2025-06-26T19:40:10.351+0700] {subprocess.py:93} INFO - 25/06/26 19:40:10 INFO TaskSetManager: Finished task 8.0 in stage 0.0 (TID 8) in 370 ms on localhost (executor driver) (5/1454)
[2025-06-26T19:40:10.352+0700] {subprocess.py:93} INFO - 25/06/26 19:40:10 INFO Executor: Running task 27.0 in stage 0.0 (TID 27)
[2025-06-26T19:40:10.357+0700] {subprocess.py:93} INFO - 25/06/26 19:40:10 INFO TaskSetManager: Starting task 28.0 in stage 0.0 (TID 28) (localhost, executor driver, partition 28, PROCESS_LOCAL, 9215 bytes)
[2025-06-26T19:40:10.357+0700] {subprocess.py:93} INFO - 25/06/26 19:40:10 INFO TaskSetManager: Finished task 9.0 in stage 0.0 (TID 9) in 375 ms on localhost (executor driver) (6/1454)
[2025-06-26T19:40:10.358+0700] {subprocess.py:93} INFO - 25/06/26 19:40:10 INFO Executor: Running task 28.0 in stage 0.0 (TID 28)
[2025-06-26T19:40:10.360+0700] {subprocess.py:93} INFO - 25/06/26 19:40:10 INFO TaskSetManager: Starting task 29.0 in stage 0.0 (TID 29) (localhost, executor driver, partition 29, PROCESS_LOCAL, 9215 bytes)
[2025-06-26T19:40:10.361+0700] {subprocess.py:93} INFO - 25/06/26 19:40:10 INFO TaskSetManager: Finished task 11.0 in stage 0.0 (TID 11) in 377 ms on localhost (executor driver) (7/1454)
[2025-06-26T19:40:10.361+0700] {subprocess.py:93} INFO - 25/06/26 19:40:10 INFO Executor: Running task 29.0 in stage 0.0 (TID 29)
[2025-06-26T19:40:10.361+0700] {subprocess.py:93} INFO - 25/06/26 19:40:10 INFO Executor: Finished task 24.0 in stage 0.0 (TID 24). 3218 bytes result sent to driver
[2025-06-26T19:40:10.362+0700] {subprocess.py:93} INFO - 25/06/26 19:40:10 INFO Executor: Finished task 22.0 in stage 0.0 (TID 22). 3218 bytes result sent to driver
[2025-06-26T19:40:10.362+0700] {subprocess.py:93} INFO - 25/06/26 19:40:10 INFO TaskSetManager: Starting task 30.0 in stage 0.0 (TID 30) (localhost, executor driver, partition 30, PROCESS_LOCAL, 9215 bytes)
[2025-06-26T19:40:10.364+0700] {subprocess.py:93} INFO - 25/06/26 19:40:10 INFO TaskSetManager: Finished task 18.0 in stage 0.0 (TID 18) in 376 ms on localhost (executor driver) (8/1454)
[2025-06-26T19:40:10.365+0700] {subprocess.py:93} INFO - 25/06/26 19:40:10 INFO Executor: Running task 30.0 in stage 0.0 (TID 30)
[2025-06-26T19:40:10.368+0700] {subprocess.py:93} INFO - 25/06/26 19:40:10 INFO TaskSetManager: Starting task 31.0 in stage 0.0 (TID 31) (localhost, executor driver, partition 31, PROCESS_LOCAL, 9215 bytes)
[2025-06-26T19:40:10.369+0700] {subprocess.py:93} INFO - 25/06/26 19:40:10 INFO Executor: Running task 31.0 in stage 0.0 (TID 31)
[2025-06-26T19:40:10.369+0700] {subprocess.py:93} INFO - 25/06/26 19:40:10 INFO TaskSetManager: Starting task 32.0 in stage 0.0 (TID 32) (localhost, executor driver, partition 32, PROCESS_LOCAL, 9215 bytes)
[2025-06-26T19:40:10.369+0700] {subprocess.py:93} INFO - 25/06/26 19:40:10 INFO TaskSetManager: Finished task 10.0 in stage 0.0 (TID 10) in 387 ms on localhost (executor driver) (9/1454)
[2025-06-26T19:40:10.370+0700] {subprocess.py:93} INFO - 25/06/26 19:40:10 INFO TaskSetManager: Finished task 19.0 in stage 0.0 (TID 19) in 381 ms on localhost (executor driver) (10/1454)
[2025-06-26T19:40:10.370+0700] {subprocess.py:93} INFO - 25/06/26 19:40:10 INFO Executor: Finished task 23.0 in stage 0.0 (TID 23). 3218 bytes result sent to driver
[2025-06-26T19:40:10.370+0700] {subprocess.py:93} INFO - 25/06/26 19:40:10 INFO Executor: Running task 32.0 in stage 0.0 (TID 32)
[2025-06-26T19:40:10.371+0700] {subprocess.py:93} INFO - 25/06/26 19:40:10 INFO TaskSetManager: Starting task 33.0 in stage 0.0 (TID 33) (localhost, executor driver, partition 33, PROCESS_LOCAL, 9215 bytes)
[2025-06-26T19:40:10.371+0700] {subprocess.py:93} INFO - 25/06/26 19:40:10 INFO TaskSetManager: Finished task 4.0 in stage 0.0 (TID 4) in 393 ms on localhost (executor driver) (11/1454)
[2025-06-26T19:40:10.372+0700] {subprocess.py:93} INFO - 25/06/26 19:40:10 INFO Executor: Running task 33.0 in stage 0.0 (TID 33)
[2025-06-26T19:40:10.372+0700] {subprocess.py:93} INFO - 25/06/26 19:40:10 INFO TaskSetManager: Starting task 34.0 in stage 0.0 (TID 34) (localhost, executor driver, partition 34, PROCESS_LOCAL, 9215 bytes)
[2025-06-26T19:40:10.373+0700] {subprocess.py:93} INFO - 25/06/26 19:40:10 INFO TaskSetManager: Finished task 7.0 in stage 0.0 (TID 7) in 391 ms on localhost (executor driver) (12/1454)
[2025-06-26T19:40:10.373+0700] {subprocess.py:93} INFO - 25/06/26 19:40:10 INFO Executor: Running task 34.0 in stage 0.0 (TID 34)
[2025-06-26T19:40:10.374+0700] {subprocess.py:93} INFO - 25/06/26 19:40:10 INFO TaskSetManager: Starting task 35.0 in stage 0.0 (TID 35) (localhost, executor driver, partition 35, PROCESS_LOCAL, 9215 bytes)
[2025-06-26T19:40:10.375+0700] {subprocess.py:93} INFO - 25/06/26 19:40:10 INFO TaskSetManager: Finished task 2.0 in stage 0.0 (TID 2) in 397 ms on localhost (executor driver) (13/1454)
[2025-06-26T19:40:10.375+0700] {subprocess.py:93} INFO - 25/06/26 19:40:10 INFO Executor: Running task 35.0 in stage 0.0 (TID 35)
[2025-06-26T19:40:10.377+0700] {subprocess.py:93} INFO - 25/06/26 19:40:10 INFO TaskSetManager: Finished task 15.0 in stage 0.0 (TID 15) in 391 ms on localhost (executor driver) (14/1454)
[2025-06-26T19:40:10.378+0700] {subprocess.py:93} INFO - 25/06/26 19:40:10 INFO TaskSetManager: Starting task 36.0 in stage 0.0 (TID 36) (localhost, executor driver, partition 36, PROCESS_LOCAL, 9215 bytes)
[2025-06-26T19:40:10.381+0700] {subprocess.py:93} INFO - 25/06/26 19:40:10 INFO TaskSetManager: Finished task 20.0 in stage 0.0 (TID 20) in 392 ms on localhost (executor driver) (15/1454)
[2025-06-26T19:40:10.381+0700] {subprocess.py:93} INFO - 25/06/26 19:40:10 INFO Executor: Running task 36.0 in stage 0.0 (TID 36)
[2025-06-26T19:40:10.382+0700] {subprocess.py:93} INFO - 25/06/26 19:40:10 INFO TaskSetManager: Starting task 37.0 in stage 0.0 (TID 37) (localhost, executor driver, partition 37, PROCESS_LOCAL, 9215 bytes)
[2025-06-26T19:40:10.382+0700] {subprocess.py:93} INFO - 25/06/26 19:40:10 INFO Executor: Finished task 25.0 in stage 0.0 (TID 25). 3218 bytes result sent to driver
[2025-06-26T19:40:10.384+0700] {subprocess.py:93} INFO - 25/06/26 19:40:10 INFO Executor: Running task 37.0 in stage 0.0 (TID 37)
[2025-06-26T19:40:10.385+0700] {subprocess.py:93} INFO - 25/06/26 19:40:10 INFO TaskSetManager: Starting task 38.0 in stage 0.0 (TID 38) (localhost, executor driver, partition 38, PROCESS_LOCAL, 9215 bytes)
[2025-06-26T19:40:10.385+0700] {subprocess.py:93} INFO - 25/06/26 19:40:10 INFO Executor: Running task 38.0 in stage 0.0 (TID 38)
[2025-06-26T19:40:10.385+0700] {subprocess.py:93} INFO - 25/06/26 19:40:10 INFO TaskSetManager: Starting task 39.0 in stage 0.0 (TID 39) (localhost, executor driver, partition 39, PROCESS_LOCAL, 9215 bytes)
[2025-06-26T19:40:10.389+0700] {subprocess.py:93} INFO - 25/06/26 19:40:10 INFO Executor: Running task 39.0 in stage 0.0 (TID 39)
[2025-06-26T19:40:10.391+0700] {subprocess.py:93} INFO - 25/06/26 19:40:10 INFO TaskSetManager: Starting task 40.0 in stage 0.0 (TID 40) (localhost, executor driver, partition 40, PROCESS_LOCAL, 9215 bytes)
[2025-06-26T19:40:10.392+0700] {subprocess.py:93} INFO - 25/06/26 19:40:10 INFO TaskSetManager: Finished task 12.0 in stage 0.0 (TID 12) in 409 ms on localhost (executor driver) (16/1454)
[2025-06-26T19:40:10.392+0700] {subprocess.py:93} INFO - 25/06/26 19:40:10 INFO Executor: Running task 40.0 in stage 0.0 (TID 40)
[2025-06-26T19:40:10.393+0700] {subprocess.py:93} INFO - 25/06/26 19:40:10 INFO TaskSetManager: Finished task 16.0 in stage 0.0 (TID 16) in 406 ms on localhost (executor driver) (17/1454)
[2025-06-26T19:40:10.393+0700] {subprocess.py:93} INFO - 25/06/26 19:40:10 INFO TaskSetManager: Finished task 13.0 in stage 0.0 (TID 13) in 409 ms on localhost (executor driver) (18/1454)
[2025-06-26T19:40:10.398+0700] {subprocess.py:93} INFO - 25/06/26 19:40:10 INFO TaskSetManager: Finished task 21.0 in stage 0.0 (TID 21) in 408 ms on localhost (executor driver) (19/1454)
[2025-06-26T19:40:10.399+0700] {subprocess.py:93} INFO - 25/06/26 19:40:10 INFO Executor: Finished task 26.0 in stage 0.0 (TID 26). 3218 bytes result sent to driver
[2025-06-26T19:40:10.400+0700] {subprocess.py:93} INFO - 25/06/26 19:40:10 INFO Executor: Finished task 27.0 in stage 0.0 (TID 27). 3175 bytes result sent to driver
[2025-06-26T19:40:10.407+0700] {subprocess.py:93} INFO - 25/06/26 19:40:10 INFO Executor: Finished task 28.0 in stage 0.0 (TID 28). 3175 bytes result sent to driver
[2025-06-26T19:40:10.407+0700] {subprocess.py:93} INFO - 25/06/26 19:40:10 INFO TaskSetManager: Starting task 41.0 in stage 0.0 (TID 41) (localhost, executor driver, partition 41, PROCESS_LOCAL, 9215 bytes)
[2025-06-26T19:40:10.408+0700] {subprocess.py:93} INFO - 25/06/26 19:40:10 INFO Executor: Running task 41.0 in stage 0.0 (TID 41)
[2025-06-26T19:40:10.408+0700] {subprocess.py:93} INFO - 25/06/26 19:40:10 INFO Executor: Finished task 29.0 in stage 0.0 (TID 29). 3218 bytes result sent to driver
[2025-06-26T19:40:10.412+0700] {subprocess.py:93} INFO - 25/06/26 19:40:10 INFO TaskSetManager: Starting task 42.0 in stage 0.0 (TID 42) (localhost, executor driver, partition 42, PROCESS_LOCAL, 9215 bytes)
[2025-06-26T19:40:10.413+0700] {subprocess.py:93} INFO - 25/06/26 19:40:10 INFO TaskSetManager: Finished task 0.0 in stage 0.0 (TID 0) in 479 ms on localhost (executor driver) (20/1454)
[2025-06-26T19:40:10.413+0700] {subprocess.py:93} INFO - 25/06/26 19:40:10 INFO Executor: Running task 42.0 in stage 0.0 (TID 42)
[2025-06-26T19:40:10.420+0700] {subprocess.py:93} INFO - 25/06/26 19:40:10 INFO TaskSetManager: Starting task 43.0 in stage 0.0 (TID 43) (localhost, executor driver, partition 43, PROCESS_LOCAL, 9215 bytes)
[2025-06-26T19:40:10.421+0700] {subprocess.py:93} INFO - 25/06/26 19:40:10 INFO TaskSetManager: Finished task 1.0 in stage 0.0 (TID 1) in 445 ms on localhost (executor driver) (21/1454)
[2025-06-26T19:40:10.421+0700] {subprocess.py:93} INFO - 25/06/26 19:40:10 INFO Executor: Running task 43.0 in stage 0.0 (TID 43)
[2025-06-26T19:40:10.422+0700] {subprocess.py:93} INFO - 25/06/26 19:40:10 INFO TaskSetManager: Starting task 44.0 in stage 0.0 (TID 44) (localhost, executor driver, partition 44, PROCESS_LOCAL, 9215 bytes)
[2025-06-26T19:40:10.422+0700] {subprocess.py:93} INFO - 25/06/26 19:40:10 INFO TaskSetManager: Finished task 14.0 in stage 0.0 (TID 14) in 438 ms on localhost (executor driver) (22/1454)
[2025-06-26T19:40:10.423+0700] {subprocess.py:93} INFO - 25/06/26 19:40:10 INFO Executor: Finished task 31.0 in stage 0.0 (TID 31). 3175 bytes result sent to driver
[2025-06-26T19:40:10.423+0700] {subprocess.py:93} INFO - 25/06/26 19:40:10 INFO Executor: Running task 44.0 in stage 0.0 (TID 44)
[2025-06-26T19:40:10.423+0700] {subprocess.py:93} INFO - 25/06/26 19:40:10 INFO Executor: Finished task 34.0 in stage 0.0 (TID 34). 3175 bytes result sent to driver
[2025-06-26T19:40:10.423+0700] {subprocess.py:93} INFO - 25/06/26 19:40:10 INFO TaskSetManager: Finished task 24.0 in stage 0.0 (TID 24) in 83 ms on localhost (executor driver) (23/1454)
[2025-06-26T19:40:10.423+0700] {subprocess.py:93} INFO - 25/06/26 19:40:10 INFO Executor: Finished task 32.0 in stage 0.0 (TID 32). 3175 bytes result sent to driver
[2025-06-26T19:40:10.423+0700] {subprocess.py:93} INFO - 25/06/26 19:40:10 INFO Executor: Finished task 33.0 in stage 0.0 (TID 33). 3218 bytes result sent to driver
[2025-06-26T19:40:10.424+0700] {subprocess.py:93} INFO - 25/06/26 19:40:10 INFO TaskSetManager: Starting task 45.0 in stage 0.0 (TID 45) (localhost, executor driver, partition 45, PROCESS_LOCAL, 9215 bytes)
[2025-06-26T19:40:10.425+0700] {subprocess.py:93} INFO - 25/06/26 19:40:10 INFO Executor: Running task 45.0 in stage 0.0 (TID 45)
[2025-06-26T19:40:10.426+0700] {subprocess.py:93} INFO - 25/06/26 19:40:10 INFO TaskSetManager: Starting task 46.0 in stage 0.0 (TID 46) (localhost, executor driver, partition 46, PROCESS_LOCAL, 9215 bytes)
[2025-06-26T19:40:10.431+0700] {subprocess.py:93} INFO - 25/06/26 19:40:10 INFO Executor: Running task 46.0 in stage 0.0 (TID 46)
[2025-06-26T19:40:10.453+0700] {subprocess.py:93} INFO - 25/06/26 19:40:10 INFO TaskSetManager: Starting task 47.0 in stage 0.0 (TID 47) (localhost, executor driver, partition 47, PROCESS_LOCAL, 9215 bytes)
[2025-06-26T19:40:10.455+0700] {subprocess.py:93} INFO - 25/06/26 19:40:10 INFO Executor: Running task 47.0 in stage 0.0 (TID 47)
[2025-06-26T19:40:10.456+0700] {subprocess.py:93} INFO - 25/06/26 19:40:10 INFO Executor: Finished task 30.0 in stage 0.0 (TID 30). 3261 bytes result sent to driver
[2025-06-26T19:40:10.457+0700] {subprocess.py:93} INFO - 25/06/26 19:40:10 INFO Executor: Finished task 36.0 in stage 0.0 (TID 36). 3218 bytes result sent to driver
[2025-06-26T19:40:10.458+0700] {subprocess.py:93} INFO - 25/06/26 19:40:10 INFO Executor: Finished task 35.0 in stage 0.0 (TID 35). 3218 bytes result sent to driver
[2025-06-26T19:40:10.458+0700] {subprocess.py:93} INFO - 25/06/26 19:40:10 INFO TaskSetManager: Starting task 48.0 in stage 0.0 (TID 48) (localhost, executor driver, partition 48, PROCESS_LOCAL, 9215 bytes)
[2025-06-26T19:40:10.458+0700] {subprocess.py:93} INFO - 25/06/26 19:40:10 INFO TaskSetManager: Finished task 22.0 in stage 0.0 (TID 22) in 122 ms on localhost (executor driver) (24/1454)
[2025-06-26T19:40:10.458+0700] {subprocess.py:93} INFO - 25/06/26 19:40:10 INFO Executor: Finished task 39.0 in stage 0.0 (TID 39). 3218 bytes result sent to driver
[2025-06-26T19:40:10.459+0700] {subprocess.py:93} INFO - 25/06/26 19:40:10 INFO Executor: Running task 48.0 in stage 0.0 (TID 48)
[2025-06-26T19:40:10.459+0700] {subprocess.py:93} INFO - 25/06/26 19:40:10 INFO TaskSetManager: Starting task 49.0 in stage 0.0 (TID 49) (localhost, executor driver, partition 49, PROCESS_LOCAL, 9215 bytes)
[2025-06-26T19:40:10.459+0700] {subprocess.py:93} INFO - 25/06/26 19:40:10 INFO TaskSetManager: Finished task 23.0 in stage 0.0 (TID 23) in 121 ms on localhost (executor driver) (25/1454)
[2025-06-26T19:40:10.459+0700] {subprocess.py:93} INFO - 25/06/26 19:40:10 INFO Executor: Running task 49.0 in stage 0.0 (TID 49)
[2025-06-26T19:40:10.459+0700] {subprocess.py:93} INFO - 25/06/26 19:40:10 INFO TaskSetManager: Finished task 26.0 in stage 0.0 (TID 26) in 110 ms on localhost (executor driver) (26/1454)
[2025-06-26T19:40:10.460+0700] {subprocess.py:93} INFO - 25/06/26 19:40:10 INFO Executor: Finished task 40.0 in stage 0.0 (TID 40). 3218 bytes result sent to driver
[2025-06-26T19:40:10.460+0700] {subprocess.py:93} INFO - 25/06/26 19:40:10 INFO TaskSetManager: Finished task 25.0 in stage 0.0 (TID 25) in 113 ms on localhost (executor driver) (27/1454)
[2025-06-26T19:40:10.461+0700] {subprocess.py:93} INFO - 25/06/26 19:40:10 INFO Executor: Finished task 37.0 in stage 0.0 (TID 37). 3218 bytes result sent to driver
[2025-06-26T19:40:10.461+0700] {subprocess.py:93} INFO - 25/06/26 19:40:10 INFO TaskSetManager: Finished task 27.0 in stage 0.0 (TID 27) in 110 ms on localhost (executor driver) (28/1454)
[2025-06-26T19:40:10.464+0700] {subprocess.py:93} INFO - 25/06/26 19:40:10 INFO Executor: Finished task 41.0 in stage 0.0 (TID 41). 3218 bytes result sent to driver
[2025-06-26T19:40:10.466+0700] {subprocess.py:93} INFO - 25/06/26 19:40:10 INFO Executor: Finished task 38.0 in stage 0.0 (TID 38). 3218 bytes result sent to driver
[2025-06-26T19:40:10.466+0700] {subprocess.py:93} INFO - 25/06/26 19:40:10 INFO TaskSetManager: Starting task 50.0 in stage 0.0 (TID 50) (localhost, executor driver, partition 50, PROCESS_LOCAL, 9215 bytes)
[2025-06-26T19:40:10.467+0700] {subprocess.py:93} INFO - 25/06/26 19:40:10 INFO Executor: Running task 50.0 in stage 0.0 (TID 50)
[2025-06-26T19:40:10.468+0700] {subprocess.py:93} INFO - 25/06/26 19:40:10 INFO TaskSetManager: Starting task 51.0 in stage 0.0 (TID 51) (localhost, executor driver, partition 51, PROCESS_LOCAL, 9215 bytes)
[2025-06-26T19:40:10.468+0700] {subprocess.py:93} INFO - 25/06/26 19:40:10 INFO TaskSetManager: Finished task 28.0 in stage 0.0 (TID 28) in 115 ms on localhost (executor driver) (29/1454)
[2025-06-26T19:40:10.468+0700] {subprocess.py:93} INFO - 25/06/26 19:40:10 INFO Executor: Running task 51.0 in stage 0.0 (TID 51)
[2025-06-26T19:40:10.469+0700] {subprocess.py:93} INFO - 25/06/26 19:40:10 INFO TaskSetManager: Starting task 52.0 in stage 0.0 (TID 52) (localhost, executor driver, partition 52, PROCESS_LOCAL, 9215 bytes)
[2025-06-26T19:40:10.470+0700] {subprocess.py:93} INFO - 25/06/26 19:40:10 INFO Executor: Finished task 44.0 in stage 0.0 (TID 44). 3218 bytes result sent to driver
[2025-06-26T19:40:10.470+0700] {subprocess.py:93} INFO - 25/06/26 19:40:10 INFO TaskSetManager: Finished task 29.0 in stage 0.0 (TID 29) in 111 ms on localhost (executor driver) (30/1454)
[2025-06-26T19:40:10.470+0700] {subprocess.py:93} INFO - 25/06/26 19:40:10 INFO Executor: Running task 52.0 in stage 0.0 (TID 52)
[2025-06-26T19:40:10.470+0700] {subprocess.py:93} INFO - 25/06/26 19:40:10 INFO Executor: Finished task 42.0 in stage 0.0 (TID 42). 3218 bytes result sent to driver
[2025-06-26T19:40:10.470+0700] {subprocess.py:93} INFO - 25/06/26 19:40:10 INFO TaskSetManager: Finished task 31.0 in stage 0.0 (TID 31) in 103 ms on localhost (executor driver) (31/1454)
[2025-06-26T19:40:10.472+0700] {subprocess.py:93} INFO - 25/06/26 19:40:10 INFO TaskSetManager: Starting task 53.0 in stage 0.0 (TID 53) (localhost, executor driver, partition 53, PROCESS_LOCAL, 9215 bytes)
[2025-06-26T19:40:10.472+0700] {subprocess.py:93} INFO - 25/06/26 19:40:10 INFO Executor: Running task 53.0 in stage 0.0 (TID 53)
[2025-06-26T19:40:10.473+0700] {subprocess.py:93} INFO - 25/06/26 19:40:10 INFO TaskSetManager: Starting task 54.0 in stage 0.0 (TID 54) (localhost, executor driver, partition 54, PROCESS_LOCAL, 9215 bytes)
[2025-06-26T19:40:10.473+0700] {subprocess.py:93} INFO - 25/06/26 19:40:10 INFO Executor: Finished task 45.0 in stage 0.0 (TID 45). 3218 bytes result sent to driver
[2025-06-26T19:40:10.474+0700] {subprocess.py:93} INFO - 25/06/26 19:40:10 INFO Executor: Finished task 43.0 in stage 0.0 (TID 43). 3218 bytes result sent to driver
[2025-06-26T19:40:10.475+0700] {subprocess.py:93} INFO - 25/06/26 19:40:10 INFO TaskSetManager: Starting task 55.0 in stage 0.0 (TID 55) (localhost, executor driver, partition 55, PROCESS_LOCAL, 9215 bytes)
[2025-06-26T19:40:10.475+0700] {subprocess.py:93} INFO - 25/06/26 19:40:10 INFO Executor: Running task 54.0 in stage 0.0 (TID 54)
[2025-06-26T19:40:10.476+0700] {subprocess.py:93} INFO - 25/06/26 19:40:10 INFO Executor: Running task 55.0 in stage 0.0 (TID 55)
[2025-06-26T19:40:10.477+0700] {subprocess.py:93} INFO - 25/06/26 19:40:10 INFO TaskSetManager: Starting task 56.0 in stage 0.0 (TID 56) (localhost, executor driver, partition 56, PROCESS_LOCAL, 9215 bytes)
[2025-06-26T19:40:10.477+0700] {subprocess.py:93} INFO - 25/06/26 19:40:10 INFO Executor: Finished task 47.0 in stage 0.0 (TID 47). 3175 bytes result sent to driver
[2025-06-26T19:40:10.477+0700] {subprocess.py:93} INFO - 25/06/26 19:40:10 INFO Executor: Running task 56.0 in stage 0.0 (TID 56)
[2025-06-26T19:40:10.477+0700] {subprocess.py:93} INFO - 25/06/26 19:40:10 INFO Executor: Finished task 46.0 in stage 0.0 (TID 46). 3218 bytes result sent to driver
[2025-06-26T19:40:10.478+0700] {subprocess.py:93} INFO - 25/06/26 19:40:10 INFO TaskSetManager: Starting task 57.0 in stage 0.0 (TID 57) (localhost, executor driver, partition 57, PROCESS_LOCAL, 9215 bytes)
[2025-06-26T19:40:10.479+0700] {subprocess.py:93} INFO - 25/06/26 19:40:10 INFO Executor: Running task 57.0 in stage 0.0 (TID 57)
[2025-06-26T19:40:10.479+0700] {subprocess.py:93} INFO - 25/06/26 19:40:10 INFO TaskSetManager: Starting task 58.0 in stage 0.0 (TID 58) (localhost, executor driver, partition 58, PROCESS_LOCAL, 9215 bytes)
[2025-06-26T19:40:10.479+0700] {subprocess.py:93} INFO - 25/06/26 19:40:10 INFO Executor: Running task 58.0 in stage 0.0 (TID 58)
[2025-06-26T19:40:10.479+0700] {subprocess.py:93} INFO - 25/06/26 19:40:10 INFO TaskSetManager: Finished task 36.0 in stage 0.0 (TID 36) in 101 ms on localhost (executor driver) (32/1454)
[2025-06-26T19:40:10.480+0700] {subprocess.py:93} INFO - 25/06/26 19:40:10 INFO TaskSetManager: Finished task 34.0 in stage 0.0 (TID 34) in 109 ms on localhost (executor driver) (33/1454)
[2025-06-26T19:40:10.481+0700] {subprocess.py:93} INFO - 25/06/26 19:40:10 INFO TaskSetManager: Starting task 59.0 in stage 0.0 (TID 59) (localhost, executor driver, partition 59, PROCESS_LOCAL, 9215 bytes)
[2025-06-26T19:40:10.482+0700] {subprocess.py:93} INFO - 25/06/26 19:40:10 INFO TaskSetManager: Finished task 33.0 in stage 0.0 (TID 33) in 112 ms on localhost (executor driver) (34/1454)
[2025-06-26T19:40:10.482+0700] {subprocess.py:93} INFO - 25/06/26 19:40:10 INFO Executor: Running task 59.0 in stage 0.0 (TID 59)
[2025-06-26T19:40:10.483+0700] {subprocess.py:93} INFO - 25/06/26 19:40:10 INFO TaskSetManager: Finished task 32.0 in stage 0.0 (TID 32) in 113 ms on localhost (executor driver) (35/1454)
[2025-06-26T19:40:10.484+0700] {subprocess.py:93} INFO - 25/06/26 19:40:10 INFO TaskSetManager: Starting task 60.0 in stage 0.0 (TID 60) (localhost, executor driver, partition 60, PROCESS_LOCAL, 9215 bytes)
[2025-06-26T19:40:10.484+0700] {subprocess.py:93} INFO - 25/06/26 19:40:10 INFO Executor: Finished task 48.0 in stage 0.0 (TID 48). 3175 bytes result sent to driver
[2025-06-26T19:40:10.485+0700] {subprocess.py:93} INFO - 25/06/26 19:40:10 INFO Executor: Running task 60.0 in stage 0.0 (TID 60)
[2025-06-26T19:40:10.485+0700] {subprocess.py:93} INFO - 25/06/26 19:40:10 INFO TaskSetManager: Starting task 61.0 in stage 0.0 (TID 61) (localhost, executor driver, partition 61, PROCESS_LOCAL, 9215 bytes)
[2025-06-26T19:40:10.485+0700] {subprocess.py:93} INFO - 25/06/26 19:40:10 INFO Executor: Finished task 49.0 in stage 0.0 (TID 49). 3175 bytes result sent to driver
[2025-06-26T19:40:10.486+0700] {subprocess.py:93} INFO - 25/06/26 19:40:10 INFO Executor: Running task 61.0 in stage 0.0 (TID 61)
[2025-06-26T19:40:10.486+0700] {subprocess.py:93} INFO - 25/06/26 19:40:10 INFO TaskSetManager: Starting task 62.0 in stage 0.0 (TID 62) (localhost, executor driver, partition 62, PROCESS_LOCAL, 9215 bytes)
[2025-06-26T19:40:10.487+0700] {subprocess.py:93} INFO - 25/06/26 19:40:10 INFO TaskSetManager: Finished task 35.0 in stage 0.0 (TID 35) in 112 ms on localhost (executor driver) (36/1454)
[2025-06-26T19:40:10.488+0700] {subprocess.py:93} INFO - 25/06/26 19:40:10 INFO Executor: Running task 62.0 in stage 0.0 (TID 62)
[2025-06-26T19:40:10.488+0700] {subprocess.py:93} INFO - 25/06/26 19:40:10 INFO TaskSetManager: Finished task 30.0 in stage 0.0 (TID 30) in 126 ms on localhost (executor driver) (37/1454)
[2025-06-26T19:40:10.488+0700] {subprocess.py:93} INFO - 25/06/26 19:40:10 INFO TaskSetManager: Finished task 39.0 in stage 0.0 (TID 39) in 102 ms on localhost (executor driver) (38/1454)
[2025-06-26T19:40:10.489+0700] {subprocess.py:93} INFO - 25/06/26 19:40:10 INFO TaskSetManager: Finished task 41.0 in stage 0.0 (TID 41) in 86 ms on localhost (executor driver) (39/1454)
[2025-06-26T19:40:10.490+0700] {subprocess.py:93} INFO - 25/06/26 19:40:10 INFO Executor: Finished task 51.0 in stage 0.0 (TID 51). 3175 bytes result sent to driver
[2025-06-26T19:40:10.490+0700] {subprocess.py:93} INFO - 25/06/26 19:40:10 INFO TaskSetManager: Starting task 63.0 in stage 0.0 (TID 63) (localhost, executor driver, partition 63, PROCESS_LOCAL, 9215 bytes)
[2025-06-26T19:40:10.490+0700] {subprocess.py:93} INFO - 25/06/26 19:40:10 INFO TaskSetManager: Finished task 37.0 in stage 0.0 (TID 37) in 108 ms on localhost (executor driver) (40/1454)
[2025-06-26T19:40:10.490+0700] {subprocess.py:93} INFO - 25/06/26 19:40:10 INFO TaskSetManager: Finished task 40.0 in stage 0.0 (TID 40) in 101 ms on localhost (executor driver) (41/1454)
[2025-06-26T19:40:10.491+0700] {subprocess.py:93} INFO - 25/06/26 19:40:10 INFO Executor: Running task 63.0 in stage 0.0 (TID 63)
[2025-06-26T19:40:10.491+0700] {subprocess.py:93} INFO - 25/06/26 19:40:10 INFO TaskSetManager: Starting task 64.0 in stage 0.0 (TID 64) (localhost, executor driver, partition 64, PROCESS_LOCAL, 9215 bytes)
[2025-06-26T19:40:10.491+0700] {subprocess.py:93} INFO - 25/06/26 19:40:10 INFO Executor: Running task 64.0 in stage 0.0 (TID 64)
[2025-06-26T19:40:10.492+0700] {subprocess.py:93} INFO - 25/06/26 19:40:10 INFO TaskSetManager: Finished task 38.0 in stage 0.0 (TID 38) in 107 ms on localhost (executor driver) (42/1454)
[2025-06-26T19:40:10.492+0700] {subprocess.py:93} INFO - 25/06/26 19:40:10 INFO Executor: Finished task 50.0 in stage 0.0 (TID 50). 3175 bytes result sent to driver
[2025-06-26T19:40:10.495+0700] {subprocess.py:93} INFO - 25/06/26 19:40:10 INFO TaskSetManager: Starting task 65.0 in stage 0.0 (TID 65) (localhost, executor driver, partition 65, PROCESS_LOCAL, 9215 bytes)
[2025-06-26T19:40:10.496+0700] {subprocess.py:93} INFO - 25/06/26 19:40:10 INFO Executor: Running task 65.0 in stage 0.0 (TID 65)
[2025-06-26T19:40:10.496+0700] {subprocess.py:93} INFO - 25/06/26 19:40:10 INFO TaskSetManager: Finished task 42.0 in stage 0.0 (TID 42) in 85 ms on localhost (executor driver) (43/1454)
[2025-06-26T19:40:10.497+0700] {subprocess.py:93} INFO - 25/06/26 19:40:10 INFO TaskSetManager: Finished task 44.0 in stage 0.0 (TID 44) in 73 ms on localhost (executor driver) (44/1454)
[2025-06-26T19:40:10.497+0700] {subprocess.py:93} INFO - 25/06/26 19:40:10 INFO Executor: Finished task 52.0 in stage 0.0 (TID 52). 3175 bytes result sent to driver
[2025-06-26T19:40:10.499+0700] {subprocess.py:93} INFO - 25/06/26 19:40:10 INFO Executor: Finished task 53.0 in stage 0.0 (TID 53). 3175 bytes result sent to driver
[2025-06-26T19:40:10.500+0700] {subprocess.py:93} INFO - 25/06/26 19:40:10 INFO TaskSetManager: Starting task 66.0 in stage 0.0 (TID 66) (localhost, executor driver, partition 66, PROCESS_LOCAL, 9215 bytes)
[2025-06-26T19:40:10.500+0700] {subprocess.py:93} INFO - 25/06/26 19:40:10 INFO Executor: Running task 66.0 in stage 0.0 (TID 66)
[2025-06-26T19:40:10.501+0700] {subprocess.py:93} INFO - 25/06/26 19:40:10 INFO TaskSetManager: Starting task 67.0 in stage 0.0 (TID 67) (localhost, executor driver, partition 67, PROCESS_LOCAL, 9215 bytes)
[2025-06-26T19:40:10.501+0700] {subprocess.py:93} INFO - 25/06/26 19:40:10 INFO TaskSetManager: Finished task 45.0 in stage 0.0 (TID 45) in 77 ms on localhost (executor driver) (45/1454)
[2025-06-26T19:40:10.502+0700] {subprocess.py:93} INFO - 25/06/26 19:40:10 INFO Executor: Running task 67.0 in stage 0.0 (TID 67)
[2025-06-26T19:40:10.502+0700] {subprocess.py:93} INFO - 25/06/26 19:40:10 INFO Executor: Finished task 54.0 in stage 0.0 (TID 54). 3175 bytes result sent to driver
[2025-06-26T19:40:10.503+0700] {subprocess.py:93} INFO - 25/06/26 19:40:10 INFO TaskSetManager: Starting task 68.0 in stage 0.0 (TID 68) (localhost, executor driver, partition 68, PROCESS_LOCAL, 9215 bytes)
[2025-06-26T19:40:10.503+0700] {subprocess.py:93} INFO - 25/06/26 19:40:10 INFO TaskSetManager: Finished task 43.0 in stage 0.0 (TID 43) in 88 ms on localhost (executor driver) (46/1454)
[2025-06-26T19:40:10.504+0700] {subprocess.py:93} INFO - 25/06/26 19:40:10 INFO TaskSetManager: Starting task 69.0 in stage 0.0 (TID 69) (localhost, executor driver, partition 69, PROCESS_LOCAL, 9215 bytes)
[2025-06-26T19:40:10.504+0700] {subprocess.py:93} INFO - 25/06/26 19:40:10 INFO TaskSetManager: Finished task 47.0 in stage 0.0 (TID 47) in 72 ms on localhost (executor driver) (47/1454)
[2025-06-26T19:40:10.505+0700] {subprocess.py:93} INFO - 25/06/26 19:40:10 INFO Executor: Running task 69.0 in stage 0.0 (TID 69)
[2025-06-26T19:40:10.506+0700] {subprocess.py:93} INFO - 25/06/26 19:40:10 INFO TaskSetManager: Starting task 70.0 in stage 0.0 (TID 70) (localhost, executor driver, partition 70, PROCESS_LOCAL, 9215 bytes)
[2025-06-26T19:40:10.507+0700] {subprocess.py:93} INFO - 25/06/26 19:40:10 INFO Executor: Finished task 55.0 in stage 0.0 (TID 55). 3175 bytes result sent to driver
[2025-06-26T19:40:10.507+0700] {subprocess.py:93} INFO - 25/06/26 19:40:10 INFO Executor: Finished task 56.0 in stage 0.0 (TID 56). 3175 bytes result sent to driver
[2025-06-26T19:40:10.507+0700] {subprocess.py:93} INFO - 25/06/26 19:40:10 INFO Executor: Running task 68.0 in stage 0.0 (TID 68)
[2025-06-26T19:40:10.507+0700] {subprocess.py:93} INFO - 25/06/26 19:40:10 INFO TaskSetManager: Finished task 46.0 in stage 0.0 (TID 46) in 80 ms on localhost (executor driver) (48/1454)
[2025-06-26T19:40:10.507+0700] {subprocess.py:93} INFO - 25/06/26 19:40:10 INFO Executor: Running task 70.0 in stage 0.0 (TID 70)
[2025-06-26T19:40:10.508+0700] {subprocess.py:93} INFO - 25/06/26 19:40:10 INFO TaskSetManager: Starting task 71.0 in stage 0.0 (TID 71) (localhost, executor driver, partition 71, PROCESS_LOCAL, 9215 bytes)
[2025-06-26T19:40:10.508+0700] {subprocess.py:93} INFO - 25/06/26 19:40:10 INFO Executor: Running task 71.0 in stage 0.0 (TID 71)
[2025-06-26T19:40:10.509+0700] {subprocess.py:93} INFO - 25/06/26 19:40:10 INFO TaskSetManager: Starting task 72.0 in stage 0.0 (TID 72) (localhost, executor driver, partition 72, PROCESS_LOCAL, 9215 bytes)
[2025-06-26T19:40:10.509+0700] {subprocess.py:93} INFO - 25/06/26 19:40:10 INFO Executor: Finished task 57.0 in stage 0.0 (TID 57). 3175 bytes result sent to driver
[2025-06-26T19:40:10.509+0700] {subprocess.py:93} INFO - 25/06/26 19:40:10 INFO Executor: Finished task 58.0 in stage 0.0 (TID 58). 3175 bytes result sent to driver
[2025-06-26T19:40:10.509+0700] {subprocess.py:93} INFO - 25/06/26 19:40:10 INFO Executor: Running task 72.0 in stage 0.0 (TID 72)
[2025-06-26T19:40:10.509+0700] {subprocess.py:93} INFO - 25/06/26 19:40:10 INFO TaskSetManager: Starting task 73.0 in stage 0.0 (TID 73) (localhost, executor driver, partition 73, PROCESS_LOCAL, 9215 bytes)
[2025-06-26T19:40:10.509+0700] {subprocess.py:93} INFO - 25/06/26 19:40:10 INFO TaskSetManager: Finished task 49.0 in stage 0.0 (TID 49) in 50 ms on localhost (executor driver) (49/1454)
[2025-06-26T19:40:10.509+0700] {subprocess.py:93} INFO - 25/06/26 19:40:10 INFO Executor: Finished task 59.0 in stage 0.0 (TID 59). 3175 bytes result sent to driver
[2025-06-26T19:40:10.509+0700] {subprocess.py:93} INFO - 25/06/26 19:40:10 INFO TaskSetManager: Finished task 48.0 in stage 0.0 (TID 48) in 53 ms on localhost (executor driver) (50/1454)
[2025-06-26T19:40:10.510+0700] {subprocess.py:93} INFO - 25/06/26 19:40:10 INFO Executor: Running task 73.0 in stage 0.0 (TID 73)
[2025-06-26T19:40:10.510+0700] {subprocess.py:93} INFO - 25/06/26 19:40:10 INFO Executor: Finished task 60.0 in stage 0.0 (TID 60). 3175 bytes result sent to driver
[2025-06-26T19:40:10.510+0700] {subprocess.py:93} INFO - 25/06/26 19:40:10 INFO TaskSetManager: Finished task 51.0 in stage 0.0 (TID 51) in 43 ms on localhost (executor driver) (51/1454)
[2025-06-26T19:40:10.510+0700] {subprocess.py:93} INFO - 25/06/26 19:40:10 INFO TaskSetManager: Finished task 50.0 in stage 0.0 (TID 50) in 45 ms on localhost (executor driver) (52/1454)
[2025-06-26T19:40:10.512+0700] {subprocess.py:93} INFO - 25/06/26 19:40:10 INFO TaskSetManager: Starting task 74.0 in stage 0.0 (TID 74) (localhost, executor driver, partition 74, PROCESS_LOCAL, 9215 bytes)
[2025-06-26T19:40:10.513+0700] {subprocess.py:93} INFO - 25/06/26 19:40:10 INFO Executor: Finished task 62.0 in stage 0.0 (TID 62). 3175 bytes result sent to driver
[2025-06-26T19:40:10.513+0700] {subprocess.py:93} INFO - 25/06/26 19:40:10 INFO Executor: Running task 74.0 in stage 0.0 (TID 74)
[2025-06-26T19:40:10.514+0700] {subprocess.py:93} INFO - 25/06/26 19:40:10 INFO Executor: Finished task 61.0 in stage 0.0 (TID 61). 3175 bytes result sent to driver
[2025-06-26T19:40:10.515+0700] {subprocess.py:93} INFO - 25/06/26 19:40:10 INFO TaskSetManager: Starting task 75.0 in stage 0.0 (TID 75) (localhost, executor driver, partition 75, PROCESS_LOCAL, 9215 bytes)
[2025-06-26T19:40:10.516+0700] {subprocess.py:93} INFO - 25/06/26 19:40:10 INFO TaskSetManager: Finished task 52.0 in stage 0.0 (TID 52) in 47 ms on localhost (executor driver) (53/1454)
[2025-06-26T19:40:10.516+0700] {subprocess.py:93} INFO - 25/06/26 19:40:10 INFO Executor: Running task 75.0 in stage 0.0 (TID 75)
[2025-06-26T19:40:10.518+0700] {subprocess.py:93} INFO - 25/06/26 19:40:10 INFO TaskSetManager: Finished task 53.0 in stage 0.0 (TID 53) in 46 ms on localhost (executor driver) (54/1454)
[2025-06-26T19:40:10.520+0700] {subprocess.py:93} INFO - 25/06/26 19:40:10 INFO Executor: Finished task 63.0 in stage 0.0 (TID 63). 3175 bytes result sent to driver
[2025-06-26T19:40:10.520+0700] {subprocess.py:93} INFO - 25/06/26 19:40:10 INFO Executor: Finished task 64.0 in stage 0.0 (TID 64). 3175 bytes result sent to driver
[2025-06-26T19:40:10.520+0700] {subprocess.py:93} INFO - 25/06/26 19:40:10 INFO TaskSetManager: Starting task 76.0 in stage 0.0 (TID 76) (localhost, executor driver, partition 76, PROCESS_LOCAL, 9215 bytes)
[2025-06-26T19:40:10.522+0700] {subprocess.py:93} INFO - 25/06/26 19:40:10 INFO Executor: Running task 76.0 in stage 0.0 (TID 76)
[2025-06-26T19:40:10.522+0700] {subprocess.py:93} INFO - 25/06/26 19:40:10 INFO TaskSetManager: Finished task 54.0 in stage 0.0 (TID 54) in 48 ms on localhost (executor driver) (55/1454)
[2025-06-26T19:40:10.522+0700] {subprocess.py:93} INFO - 25/06/26 19:40:10 INFO Executor: Finished task 65.0 in stage 0.0 (TID 65). 3175 bytes result sent to driver
[2025-06-26T19:40:10.523+0700] {subprocess.py:93} INFO - 25/06/26 19:40:10 INFO TaskSetManager: Starting task 77.0 in stage 0.0 (TID 77) (localhost, executor driver, partition 77, PROCESS_LOCAL, 9215 bytes)
[2025-06-26T19:40:10.523+0700] {subprocess.py:93} INFO - 25/06/26 19:40:10 INFO Executor: Running task 77.0 in stage 0.0 (TID 77)
[2025-06-26T19:40:10.524+0700] {subprocess.py:93} INFO - 25/06/26 19:40:10 INFO TaskSetManager: Starting task 78.0 in stage 0.0 (TID 78) (localhost, executor driver, partition 78, PROCESS_LOCAL, 9215 bytes)
[2025-06-26T19:40:10.524+0700] {subprocess.py:93} INFO - 25/06/26 19:40:10 INFO Executor: Running task 78.0 in stage 0.0 (TID 78)
[2025-06-26T19:40:10.524+0700] {subprocess.py:93} INFO - 25/06/26 19:40:10 INFO TaskSetManager: Finished task 55.0 in stage 0.0 (TID 55) in 50 ms on localhost (executor driver) (56/1454)
[2025-06-26T19:40:10.525+0700] {subprocess.py:93} INFO - 25/06/26 19:40:10 INFO TaskSetManager: Finished task 56.0 in stage 0.0 (TID 56) in 49 ms on localhost (executor driver) (57/1454)
[2025-06-26T19:40:10.526+0700] {subprocess.py:93} INFO - 25/06/26 19:40:10 INFO TaskSetManager: Starting task 79.0 in stage 0.0 (TID 79) (localhost, executor driver, partition 79, PROCESS_LOCAL, 9215 bytes)
[2025-06-26T19:40:10.528+0700] {subprocess.py:93} INFO - 25/06/26 19:40:10 INFO Executor: Finished task 69.0 in stage 0.0 (TID 69). 3175 bytes result sent to driver
[2025-06-26T19:40:10.528+0700] {subprocess.py:93} INFO - 25/06/26 19:40:10 INFO TaskSetManager: Finished task 57.0 in stage 0.0 (TID 57) in 50 ms on localhost (executor driver) (58/1454)
[2025-06-26T19:40:10.528+0700] {subprocess.py:93} INFO - 25/06/26 19:40:10 INFO Executor: Running task 79.0 in stage 0.0 (TID 79)
[2025-06-26T19:40:10.528+0700] {subprocess.py:93} INFO - 25/06/26 19:40:10 INFO Executor: Finished task 66.0 in stage 0.0 (TID 66). 3175 bytes result sent to driver
[2025-06-26T19:40:10.529+0700] {subprocess.py:93} INFO - 25/06/26 19:40:10 INFO TaskSetManager: Starting task 80.0 in stage 0.0 (TID 80) (localhost, executor driver, partition 80, PROCESS_LOCAL, 9215 bytes)
[2025-06-26T19:40:10.530+0700] {subprocess.py:93} INFO - 25/06/26 19:40:10 INFO TaskSetManager: Starting task 81.0 in stage 0.0 (TID 81) (localhost, executor driver, partition 81, PROCESS_LOCAL, 9215 bytes)
[2025-06-26T19:40:10.530+0700] {subprocess.py:93} INFO - 25/06/26 19:40:10 INFO Executor: Running task 80.0 in stage 0.0 (TID 80)
[2025-06-26T19:40:10.530+0700] {subprocess.py:93} INFO - 25/06/26 19:40:10 INFO TaskSetManager: Finished task 58.0 in stage 0.0 (TID 58) in 52 ms on localhost (executor driver) (59/1454)
[2025-06-26T19:40:10.530+0700] {subprocess.py:93} INFO - 25/06/26 19:40:10 INFO Executor: Running task 81.0 in stage 0.0 (TID 81)
[2025-06-26T19:40:10.532+0700] {subprocess.py:93} INFO - 25/06/26 19:40:10 INFO TaskSetManager: Starting task 82.0 in stage 0.0 (TID 82) (localhost, executor driver, partition 82, PROCESS_LOCAL, 9215 bytes)
[2025-06-26T19:40:10.533+0700] {subprocess.py:93} INFO - 25/06/26 19:40:10 INFO Executor: Running task 82.0 in stage 0.0 (TID 82)
[2025-06-26T19:40:10.533+0700] {subprocess.py:93} INFO - 25/06/26 19:40:10 INFO Executor: Finished task 67.0 in stage 0.0 (TID 67). 3218 bytes result sent to driver
[2025-06-26T19:40:10.534+0700] {subprocess.py:93} INFO - 25/06/26 19:40:10 INFO TaskSetManager: Starting task 83.0 in stage 0.0 (TID 83) (localhost, executor driver, partition 83, PROCESS_LOCAL, 9215 bytes)
[2025-06-26T19:40:10.534+0700] {subprocess.py:93} INFO - 25/06/26 19:40:10 INFO Executor: Running task 83.0 in stage 0.0 (TID 83)
[2025-06-26T19:40:10.535+0700] {subprocess.py:93} INFO - 25/06/26 19:40:10 INFO TaskSetManager: Finished task 59.0 in stage 0.0 (TID 59) in 52 ms on localhost (executor driver) (60/1454)
[2025-06-26T19:40:10.535+0700] {subprocess.py:93} INFO - 25/06/26 19:40:10 INFO TaskSetManager: Starting task 84.0 in stage 0.0 (TID 84) (localhost, executor driver, partition 84, PROCESS_LOCAL, 9215 bytes)
[2025-06-26T19:40:10.535+0700] {subprocess.py:93} INFO - 25/06/26 19:40:10 INFO Executor: Running task 84.0 in stage 0.0 (TID 84)
[2025-06-26T19:40:10.536+0700] {subprocess.py:93} INFO - 25/06/26 19:40:10 INFO TaskSetManager: Starting task 85.0 in stage 0.0 (TID 85) (localhost, executor driver, partition 85, PROCESS_LOCAL, 9215 bytes)
[2025-06-26T19:40:10.549+0700] {subprocess.py:93} INFO - 25/06/26 19:40:10 INFO Executor: Running task 85.0 in stage 0.0 (TID 85)
[2025-06-26T19:40:10.549+0700] {subprocess.py:93} INFO - 25/06/26 19:40:10 INFO TaskSetManager: Starting task 86.0 in stage 0.0 (TID 86) (localhost, executor driver, partition 86, PROCESS_LOCAL, 9215 bytes)
[2025-06-26T19:40:10.550+0700] {subprocess.py:93} INFO - 25/06/26 19:40:10 INFO Executor: Finished task 68.0 in stage 0.0 (TID 68). 3261 bytes result sent to driver
[2025-06-26T19:40:10.550+0700] {subprocess.py:93} INFO - 25/06/26 19:40:10 INFO Executor: Finished task 74.0 in stage 0.0 (TID 74). 3218 bytes result sent to driver
[2025-06-26T19:40:10.550+0700] {subprocess.py:93} INFO - 25/06/26 19:40:10 INFO TaskSetManager: Starting task 87.0 in stage 0.0 (TID 87) (localhost, executor driver, partition 87, PROCESS_LOCAL, 9215 bytes)
[2025-06-26T19:40:10.550+0700] {subprocess.py:93} INFO - 25/06/26 19:40:10 INFO Executor: Running task 86.0 in stage 0.0 (TID 86)
[2025-06-26T19:40:10.551+0700] {subprocess.py:93} INFO - 25/06/26 19:40:10 INFO Executor: Finished task 71.0 in stage 0.0 (TID 71). 3261 bytes result sent to driver
[2025-06-26T19:40:10.551+0700] {subprocess.py:93} INFO - 25/06/26 19:40:10 INFO Executor: Finished task 72.0 in stage 0.0 (TID 72). 3218 bytes result sent to driver
[2025-06-26T19:40:10.551+0700] {subprocess.py:93} INFO - 25/06/26 19:40:10 INFO Executor: Running task 87.0 in stage 0.0 (TID 87)
[2025-06-26T19:40:10.551+0700] {subprocess.py:93} INFO - 25/06/26 19:40:10 INFO TaskSetManager: Starting task 88.0 in stage 0.0 (TID 88) (localhost, executor driver, partition 88, PROCESS_LOCAL, 9215 bytes)
[2025-06-26T19:40:10.551+0700] {subprocess.py:93} INFO - 25/06/26 19:40:10 INFO Executor: Running task 88.0 in stage 0.0 (TID 88)
[2025-06-26T19:40:10.552+0700] {subprocess.py:93} INFO - 25/06/26 19:40:10 INFO TaskSetManager: Starting task 89.0 in stage 0.0 (TID 89) (localhost, executor driver, partition 89, PROCESS_LOCAL, 9215 bytes)
[2025-06-26T19:40:10.553+0700] {subprocess.py:93} INFO - 25/06/26 19:40:10 INFO Executor: Running task 89.0 in stage 0.0 (TID 89)
[2025-06-26T19:40:10.554+0700] {subprocess.py:93} INFO - 25/06/26 19:40:10 INFO TaskSetManager: Starting task 90.0 in stage 0.0 (TID 90) (localhost, executor driver, partition 90, PROCESS_LOCAL, 9215 bytes)
[2025-06-26T19:40:10.554+0700] {subprocess.py:93} INFO - 25/06/26 19:40:10 INFO Executor: Finished task 70.0 in stage 0.0 (TID 70). 3261 bytes result sent to driver
[2025-06-26T19:40:10.554+0700] {subprocess.py:93} INFO - 25/06/26 19:40:10 INFO TaskSetManager: Finished task 64.0 in stage 0.0 (TID 64) in 63 ms on localhost (executor driver) (61/1454)
[2025-06-26T19:40:10.554+0700] {subprocess.py:93} INFO - 25/06/26 19:40:10 INFO Executor: Running task 90.0 in stage 0.0 (TID 90)
[2025-06-26T19:40:10.554+0700] {subprocess.py:93} INFO - 25/06/26 19:40:10 INFO Executor: Finished task 73.0 in stage 0.0 (TID 73). 3218 bytes result sent to driver
[2025-06-26T19:40:10.556+0700] {subprocess.py:93} INFO - 25/06/26 19:40:10 INFO TaskSetManager: Finished task 63.0 in stage 0.0 (TID 63) in 67 ms on localhost (executor driver) (62/1454)
[2025-06-26T19:40:10.557+0700] {subprocess.py:93} INFO - 25/06/26 19:40:10 INFO TaskSetManager: Finished task 60.0 in stage 0.0 (TID 60) in 74 ms on localhost (executor driver) (63/1454)
[2025-06-26T19:40:10.558+0700] {subprocess.py:93} INFO - 25/06/26 19:40:10 INFO Executor: Finished task 75.0 in stage 0.0 (TID 75). 3218 bytes result sent to driver
[2025-06-26T19:40:10.558+0700] {subprocess.py:93} INFO - 25/06/26 19:40:10 INFO TaskSetManager: Finished task 61.0 in stage 0.0 (TID 61) in 73 ms on localhost (executor driver) (64/1454)
[2025-06-26T19:40:10.558+0700] {subprocess.py:93} INFO - 25/06/26 19:40:10 INFO TaskSetManager: Finished task 65.0 in stage 0.0 (TID 65) in 66 ms on localhost (executor driver) (65/1454)
[2025-06-26T19:40:10.560+0700] {subprocess.py:93} INFO - 25/06/26 19:40:10 INFO TaskSetManager: Starting task 91.0 in stage 0.0 (TID 91) (localhost, executor driver, partition 91, PROCESS_LOCAL, 9215 bytes)
[2025-06-26T19:40:10.560+0700] {subprocess.py:93} INFO - 25/06/26 19:40:10 INFO TaskSetManager: Finished task 62.0 in stage 0.0 (TID 62) in 75 ms on localhost (executor driver) (66/1454)
[2025-06-26T19:40:10.561+0700] {subprocess.py:93} INFO - 25/06/26 19:40:10 INFO Executor: Running task 91.0 in stage 0.0 (TID 91)
[2025-06-26T19:40:10.561+0700] {subprocess.py:93} INFO - 25/06/26 19:40:10 INFO TaskSetManager: Starting task 92.0 in stage 0.0 (TID 92) (localhost, executor driver, partition 92, PROCESS_LOCAL, 9215 bytes)
[2025-06-26T19:40:10.563+0700] {subprocess.py:93} INFO - 25/06/26 19:40:10 INFO Executor: Running task 92.0 in stage 0.0 (TID 92)
[2025-06-26T19:40:10.563+0700] {subprocess.py:93} INFO - 25/06/26 19:40:10 INFO TaskSetManager: Finished task 69.0 in stage 0.0 (TID 69) in 59 ms on localhost (executor driver) (67/1454)
[2025-06-26T19:40:10.564+0700] {subprocess.py:93} INFO - 25/06/26 19:40:10 INFO TaskSetManager: Finished task 67.0 in stage 0.0 (TID 67) in 64 ms on localhost (executor driver) (68/1454)
[2025-06-26T19:40:10.564+0700] {subprocess.py:93} INFO - 25/06/26 19:40:10 INFO TaskSetManager: Finished task 66.0 in stage 0.0 (TID 66) in 67 ms on localhost (executor driver) (69/1454)
[2025-06-26T19:40:10.564+0700] {subprocess.py:93} INFO - 25/06/26 19:40:10 INFO TaskSetManager: Starting task 93.0 in stage 0.0 (TID 93) (localhost, executor driver, partition 93, PROCESS_LOCAL, 9215 bytes)
[2025-06-26T19:40:10.567+0700] {subprocess.py:93} INFO - 25/06/26 19:40:10 INFO Executor: Running task 93.0 in stage 0.0 (TID 93)
[2025-06-26T19:40:10.567+0700] {subprocess.py:93} INFO - 25/06/26 19:40:10 INFO TaskSetManager: Starting task 94.0 in stage 0.0 (TID 94) (localhost, executor driver, partition 94, PROCESS_LOCAL, 9215 bytes)
[2025-06-26T19:40:10.568+0700] {subprocess.py:93} INFO - 25/06/26 19:40:10 INFO Executor: Running task 94.0 in stage 0.0 (TID 94)
[2025-06-26T19:40:10.569+0700] {subprocess.py:93} INFO - 25/06/26 19:40:10 INFO Executor: Finished task 78.0 in stage 0.0 (TID 78). 3218 bytes result sent to driver
[2025-06-26T19:40:10.569+0700] {subprocess.py:93} INFO - 25/06/26 19:40:10 INFO TaskSetManager: Starting task 95.0 in stage 0.0 (TID 95) (localhost, executor driver, partition 95, PROCESS_LOCAL, 9215 bytes)
[2025-06-26T19:40:10.569+0700] {subprocess.py:93} INFO - 25/06/26 19:40:10 INFO TaskSetManager: Finished task 68.0 in stage 0.0 (TID 68) in 66 ms on localhost (executor driver) (70/1454)
[2025-06-26T19:40:10.569+0700] {subprocess.py:93} INFO - 25/06/26 19:40:10 INFO Executor: Finished task 77.0 in stage 0.0 (TID 77). 3218 bytes result sent to driver
[2025-06-26T19:40:10.569+0700] {subprocess.py:93} INFO - 25/06/26 19:40:10 INFO Executor: Running task 95.0 in stage 0.0 (TID 95)
[2025-06-26T19:40:10.571+0700] {subprocess.py:93} INFO - 25/06/26 19:40:10 INFO TaskSetManager: Starting task 96.0 in stage 0.0 (TID 96) (localhost, executor driver, partition 96, PROCESS_LOCAL, 9215 bytes)
[2025-06-26T19:40:10.573+0700] {subprocess.py:93} INFO - 25/06/26 19:40:10 INFO TaskSetManager: Starting task 97.0 in stage 0.0 (TID 97) (localhost, executor driver, partition 97, PROCESS_LOCAL, 9215 bytes)
[2025-06-26T19:40:10.573+0700] {subprocess.py:93} INFO - 25/06/26 19:40:10 INFO Executor: Running task 97.0 in stage 0.0 (TID 97)
[2025-06-26T19:40:10.573+0700] {subprocess.py:93} INFO - 25/06/26 19:40:10 INFO Executor: Running task 96.0 in stage 0.0 (TID 96)
[2025-06-26T19:40:10.573+0700] {subprocess.py:93} INFO - 25/06/26 19:40:10 INFO Executor: Finished task 76.0 in stage 0.0 (TID 76). 3218 bytes result sent to driver
[2025-06-26T19:40:10.573+0700] {subprocess.py:93} INFO - 25/06/26 19:40:10 INFO TaskSetManager: Starting task 98.0 in stage 0.0 (TID 98) (localhost, executor driver, partition 98, PROCESS_LOCAL, 9215 bytes)
[2025-06-26T19:40:10.596+0700] {subprocess.py:93} INFO - 25/06/26 19:40:10 INFO TaskSetManager: Finished task 74.0 in stage 0.0 (TID 74) in 83 ms on localhost (executor driver) (71/1454)
[2025-06-26T19:40:10.597+0700] {subprocess.py:93} INFO - 25/06/26 19:40:10 INFO Executor: Running task 98.0 in stage 0.0 (TID 98)
[2025-06-26T19:40:10.598+0700] {subprocess.py:93} INFO - 25/06/26 19:40:10 INFO TaskSetManager: Finished task 72.0 in stage 0.0 (TID 72) in 89 ms on localhost (executor driver) (72/1454)
[2025-06-26T19:40:10.598+0700] {subprocess.py:93} INFO - 25/06/26 19:40:10 INFO TaskSetManager: Finished task 73.0 in stage 0.0 (TID 73) in 88 ms on localhost (executor driver) (73/1454)
[2025-06-26T19:40:10.599+0700] {subprocess.py:93} INFO - 25/06/26 19:40:10 INFO TaskSetManager: Finished task 75.0 in stage 0.0 (TID 75) in 82 ms on localhost (executor driver) (74/1454)
[2025-06-26T19:40:10.599+0700] {subprocess.py:93} INFO - 25/06/26 19:40:10 INFO TaskSetManager: Finished task 78.0 in stage 0.0 (TID 78) in 74 ms on localhost (executor driver) (75/1454)
[2025-06-26T19:40:10.599+0700] {subprocess.py:93} INFO - 25/06/26 19:40:10 INFO TaskSetManager: Starting task 99.0 in stage 0.0 (TID 99) (localhost, executor driver, partition 99, PROCESS_LOCAL, 9215 bytes)
[2025-06-26T19:40:10.601+0700] {subprocess.py:93} INFO - 25/06/26 19:40:10 INFO TaskSetManager: Starting task 100.0 in stage 0.0 (TID 100) (localhost, executor driver, partition 100, PROCESS_LOCAL, 9215 bytes)
[2025-06-26T19:40:10.602+0700] {subprocess.py:93} INFO - 25/06/26 19:40:10 INFO Executor: Running task 100.0 in stage 0.0 (TID 100)
[2025-06-26T19:40:10.602+0700] {subprocess.py:93} INFO - 25/06/26 19:40:10 INFO TaskSetManager: Finished task 71.0 in stage 0.0 (TID 71) in 94 ms on localhost (executor driver) (76/1454)
[2025-06-26T19:40:10.602+0700] {subprocess.py:93} INFO - 25/06/26 19:40:10 INFO Executor: Finished task 82.0 in stage 0.0 (TID 82). 3218 bytes result sent to driver
[2025-06-26T19:40:10.602+0700] {subprocess.py:93} INFO - 25/06/26 19:40:10 INFO TaskSetManager: Finished task 70.0 in stage 0.0 (TID 70) in 96 ms on localhost (executor driver) (77/1454)
[2025-06-26T19:40:10.602+0700] {subprocess.py:93} INFO - 25/06/26 19:40:10 INFO Executor: Running task 99.0 in stage 0.0 (TID 99)
[2025-06-26T19:40:10.604+0700] {subprocess.py:93} INFO - 25/06/26 19:40:10 INFO TaskSetManager: Finished task 76.0 in stage 0.0 (TID 76) in 84 ms on localhost (executor driver) (78/1454)
[2025-06-26T19:40:10.604+0700] {subprocess.py:93} INFO - 25/06/26 19:40:10 INFO TaskSetManager: Finished task 77.0 in stage 0.0 (TID 77) in 82 ms on localhost (executor driver) (79/1454)
[2025-06-26T19:40:10.604+0700] {subprocess.py:93} INFO - 25/06/26 19:40:10 INFO Executor: Finished task 83.0 in stage 0.0 (TID 83). 3218 bytes result sent to driver
[2025-06-26T19:40:10.604+0700] {subprocess.py:93} INFO - 25/06/26 19:40:10 INFO Executor: Finished task 90.0 in stage 0.0 (TID 90). 3175 bytes result sent to driver
[2025-06-26T19:40:10.606+0700] {subprocess.py:93} INFO - 25/06/26 19:40:10 INFO TaskSetManager: Starting task 101.0 in stage 0.0 (TID 101) (localhost, executor driver, partition 101, PROCESS_LOCAL, 9215 bytes)
[2025-06-26T19:40:10.610+0700] {subprocess.py:93} INFO - 25/06/26 19:40:10 INFO Executor: Running task 101.0 in stage 0.0 (TID 101)
[2025-06-26T19:40:10.611+0700] {subprocess.py:93} INFO - 25/06/26 19:40:10 INFO TaskSetManager: Starting task 102.0 in stage 0.0 (TID 102) (localhost, executor driver, partition 102, PROCESS_LOCAL, 9215 bytes)
[2025-06-26T19:40:10.611+0700] {subprocess.py:93} INFO - 25/06/26 19:40:10 INFO Executor: Finished task 79.0 in stage 0.0 (TID 79). 3218 bytes result sent to driver
[2025-06-26T19:40:10.611+0700] {subprocess.py:93} INFO - 25/06/26 19:40:10 INFO Executor: Finished task 80.0 in stage 0.0 (TID 80). 3218 bytes result sent to driver
[2025-06-26T19:40:10.611+0700] {subprocess.py:93} INFO - 25/06/26 19:40:10 INFO TaskSetManager: Finished task 82.0 in stage 0.0 (TID 82) in 80 ms on localhost (executor driver) (80/1454)
[2025-06-26T19:40:10.611+0700] {subprocess.py:93} INFO - 25/06/26 19:40:10 INFO Executor: Running task 102.0 in stage 0.0 (TID 102)
[2025-06-26T19:40:10.612+0700] {subprocess.py:93} INFO - 25/06/26 19:40:10 INFO Executor: Finished task 85.0 in stage 0.0 (TID 85). 3175 bytes result sent to driver
[2025-06-26T19:40:10.613+0700] {subprocess.py:93} INFO - 25/06/26 19:40:10 INFO TaskSetManager: Starting task 103.0 in stage 0.0 (TID 103) (localhost, executor driver, partition 103, PROCESS_LOCAL, 9215 bytes)
[2025-06-26T19:40:10.614+0700] {subprocess.py:93} INFO - 25/06/26 19:40:10 INFO Executor: Running task 103.0 in stage 0.0 (TID 103)
[2025-06-26T19:40:10.615+0700] {subprocess.py:93} INFO - 25/06/26 19:40:10 INFO TaskSetManager: Starting task 104.0 in stage 0.0 (TID 104) (localhost, executor driver, partition 104, PROCESS_LOCAL, 9215 bytes)
[2025-06-26T19:40:10.615+0700] {subprocess.py:93} INFO - 25/06/26 19:40:10 INFO Executor: Running task 104.0 in stage 0.0 (TID 104)
[2025-06-26T19:40:10.615+0700] {subprocess.py:93} INFO - 25/06/26 19:40:10 INFO TaskSetManager: Finished task 83.0 in stage 0.0 (TID 83) in 83 ms on localhost (executor driver) (81/1454)
[2025-06-26T19:40:10.617+0700] {subprocess.py:93} INFO - 25/06/26 19:40:10 INFO TaskSetManager: Starting task 105.0 in stage 0.0 (TID 105) (localhost, executor driver, partition 105, PROCESS_LOCAL, 9215 bytes)
[2025-06-26T19:40:10.618+0700] {subprocess.py:93} INFO - 25/06/26 19:40:10 INFO TaskSetManager: Finished task 90.0 in stage 0.0 (TID 90) in 65 ms on localhost (executor driver) (82/1454)
[2025-06-26T19:40:10.618+0700] {subprocess.py:93} INFO - 25/06/26 19:40:10 INFO Executor: Running task 105.0 in stage 0.0 (TID 105)
[2025-06-26T19:40:10.619+0700] {subprocess.py:93} INFO - 25/06/26 19:40:10 INFO TaskSetManager: Finished task 79.0 in stage 0.0 (TID 79) in 91 ms on localhost (executor driver) (83/1454)
[2025-06-26T19:40:10.619+0700] {subprocess.py:93} INFO - 25/06/26 19:40:10 INFO TaskSetManager: Starting task 106.0 in stage 0.0 (TID 106) (localhost, executor driver, partition 106, PROCESS_LOCAL, 9215 bytes)
[2025-06-26T19:40:10.619+0700] {subprocess.py:93} INFO - 25/06/26 19:40:10 INFO TaskSetManager: Finished task 80.0 in stage 0.0 (TID 80) in 91 ms on localhost (executor driver) (84/1454)
[2025-06-26T19:40:10.619+0700] {subprocess.py:93} INFO - 25/06/26 19:40:10 INFO Executor: Running task 106.0 in stage 0.0 (TID 106)
[2025-06-26T19:40:10.619+0700] {subprocess.py:93} INFO - 25/06/26 19:40:10 INFO Executor: Finished task 81.0 in stage 0.0 (TID 81). 3218 bytes result sent to driver
[2025-06-26T19:40:10.621+0700] {subprocess.py:93} INFO - 25/06/26 19:40:10 INFO TaskSetManager: Starting task 107.0 in stage 0.0 (TID 107) (localhost, executor driver, partition 107, PROCESS_LOCAL, 9215 bytes)
[2025-06-26T19:40:10.622+0700] {subprocess.py:93} INFO - 25/06/26 19:40:10 INFO Executor: Running task 107.0 in stage 0.0 (TID 107)
[2025-06-26T19:40:10.622+0700] {subprocess.py:93} INFO - 25/06/26 19:40:10 INFO TaskSetManager: Finished task 85.0 in stage 0.0 (TID 85) in 86 ms on localhost (executor driver) (85/1454)
[2025-06-26T19:40:10.623+0700] {subprocess.py:93} INFO - 25/06/26 19:40:10 INFO Executor: Finished task 87.0 in stage 0.0 (TID 87). 3175 bytes result sent to driver
[2025-06-26T19:40:10.623+0700] {subprocess.py:93} INFO - 25/06/26 19:40:10 INFO TaskSetManager: Finished task 81.0 in stage 0.0 (TID 81) in 94 ms on localhost (executor driver) (86/1454)
[2025-06-26T19:40:10.625+0700] {subprocess.py:93} INFO - 25/06/26 19:40:10 INFO TaskSetManager: Starting task 108.0 in stage 0.0 (TID 108) (localhost, executor driver, partition 108, PROCESS_LOCAL, 9215 bytes)
[2025-06-26T19:40:10.625+0700] {subprocess.py:93} INFO - 25/06/26 19:40:10 INFO TaskSetManager: Finished task 87.0 in stage 0.0 (TID 87) in 76 ms on localhost (executor driver) (87/1454)
[2025-06-26T19:40:10.626+0700] {subprocess.py:93} INFO - 25/06/26 19:40:10 INFO Executor: Running task 108.0 in stage 0.0 (TID 108)
[2025-06-26T19:40:10.626+0700] {subprocess.py:93} INFO - 25/06/26 19:40:10 INFO Executor: Finished task 93.0 in stage 0.0 (TID 93). 3175 bytes result sent to driver
[2025-06-26T19:40:10.627+0700] {subprocess.py:93} INFO - 25/06/26 19:40:10 INFO Executor: Finished task 84.0 in stage 0.0 (TID 84). 3218 bytes result sent to driver
[2025-06-26T19:40:10.627+0700] {subprocess.py:93} INFO - 25/06/26 19:40:10 INFO TaskSetManager: Starting task 109.0 in stage 0.0 (TID 109) (localhost, executor driver, partition 109, PROCESS_LOCAL, 9215 bytes)
[2025-06-26T19:40:10.627+0700] {subprocess.py:93} INFO - 25/06/26 19:40:10 INFO TaskSetManager: Starting task 110.0 in stage 0.0 (TID 110) (localhost, executor driver, partition 110, PROCESS_LOCAL, 9215 bytes)
[2025-06-26T19:40:10.627+0700] {subprocess.py:93} INFO - 25/06/26 19:40:10 INFO Executor: Running task 109.0 in stage 0.0 (TID 109)
[2025-06-26T19:40:10.628+0700] {subprocess.py:93} INFO - 25/06/26 19:40:10 INFO Executor: Running task 110.0 in stage 0.0 (TID 110)
[2025-06-26T19:40:10.628+0700] {subprocess.py:93} INFO - 25/06/26 19:40:10 INFO TaskSetManager: Finished task 93.0 in stage 0.0 (TID 93) in 64 ms on localhost (executor driver) (88/1454)
[2025-06-26T19:40:10.628+0700] {subprocess.py:93} INFO - 25/06/26 19:40:10 INFO Executor: Finished task 86.0 in stage 0.0 (TID 86). 3175 bytes result sent to driver
[2025-06-26T19:40:10.628+0700] {subprocess.py:93} INFO - 25/06/26 19:40:10 INFO TaskSetManager: Finished task 84.0 in stage 0.0 (TID 84) in 94 ms on localhost (executor driver) (89/1454)
[2025-06-26T19:40:10.630+0700] {subprocess.py:93} INFO - 25/06/26 19:40:10 INFO TaskSetManager: Starting task 111.0 in stage 0.0 (TID 111) (localhost, executor driver, partition 111, PROCESS_LOCAL, 9215 bytes)
[2025-06-26T19:40:10.630+0700] {subprocess.py:93} INFO - 25/06/26 19:40:10 INFO Executor: Running task 111.0 in stage 0.0 (TID 111)
[2025-06-26T19:40:10.630+0700] {subprocess.py:93} INFO - 25/06/26 19:40:10 INFO TaskSetManager: Finished task 86.0 in stage 0.0 (TID 86) in 94 ms on localhost (executor driver) (90/1454)
[2025-06-26T19:40:10.632+0700] {subprocess.py:93} INFO - 25/06/26 19:40:10 INFO Executor: Finished task 89.0 in stage 0.0 (TID 89). 3175 bytes result sent to driver
[2025-06-26T19:40:10.633+0700] {subprocess.py:93} INFO - 25/06/26 19:40:10 INFO Executor: Finished task 97.0 in stage 0.0 (TID 97). 3175 bytes result sent to driver
[2025-06-26T19:40:10.634+0700] {subprocess.py:93} INFO - 25/06/26 19:40:10 INFO TaskSetManager: Starting task 112.0 in stage 0.0 (TID 112) (localhost, executor driver, partition 112, PROCESS_LOCAL, 9215 bytes)
[2025-06-26T19:40:10.635+0700] {subprocess.py:93} INFO - 25/06/26 19:40:10 INFO TaskSetManager: Finished task 89.0 in stage 0.0 (TID 89) in 83 ms on localhost (executor driver) (91/1454)
[2025-06-26T19:40:10.635+0700] {subprocess.py:93} INFO - 25/06/26 19:40:10 INFO Executor: Finished task 99.0 in stage 0.0 (TID 99). 3175 bytes result sent to driver
[2025-06-26T19:40:10.636+0700] {subprocess.py:93} INFO - 25/06/26 19:40:10 INFO Executor: Running task 112.0 in stage 0.0 (TID 112)
[2025-06-26T19:40:10.636+0700] {subprocess.py:93} INFO - 25/06/26 19:40:10 INFO TaskSetManager: Starting task 113.0 in stage 0.0 (TID 113) (localhost, executor driver, partition 113, PROCESS_LOCAL, 9215 bytes)
[2025-06-26T19:40:10.636+0700] {subprocess.py:93} INFO - 25/06/26 19:40:10 INFO Executor: Finished task 98.0 in stage 0.0 (TID 98). 3175 bytes result sent to driver
[2025-06-26T19:40:10.636+0700] {subprocess.py:93} INFO - 25/06/26 19:40:10 INFO TaskSetManager: Starting task 114.0 in stage 0.0 (TID 114) (localhost, executor driver, partition 114, PROCESS_LOCAL, 9215 bytes)
[2025-06-26T19:40:10.637+0700] {subprocess.py:93} INFO - 25/06/26 19:40:10 INFO Executor: Running task 113.0 in stage 0.0 (TID 113)
[2025-06-26T19:40:10.638+0700] {subprocess.py:93} INFO - 25/06/26 19:40:10 INFO TaskSetManager: Starting task 115.0 in stage 0.0 (TID 115) (localhost, executor driver, partition 115, PROCESS_LOCAL, 9215 bytes)
[2025-06-26T19:40:10.638+0700] {subprocess.py:93} INFO - 25/06/26 19:40:10 INFO Executor: Running task 114.0 in stage 0.0 (TID 114)
[2025-06-26T19:40:10.638+0700] {subprocess.py:93} INFO - 25/06/26 19:40:10 INFO Executor: Running task 115.0 in stage 0.0 (TID 115)
[2025-06-26T19:40:10.642+0700] {subprocess.py:93} INFO - 25/06/26 19:40:10 INFO Executor: Finished task 88.0 in stage 0.0 (TID 88). 3175 bytes result sent to driver
[2025-06-26T19:40:10.642+0700] {subprocess.py:93} INFO - 25/06/26 19:40:10 INFO TaskSetManager: Starting task 116.0 in stage 0.0 (TID 116) (localhost, executor driver, partition 116, PROCESS_LOCAL, 9215 bytes)
[2025-06-26T19:40:10.642+0700] {subprocess.py:93} INFO - 25/06/26 19:40:10 INFO Executor: Running task 116.0 in stage 0.0 (TID 116)
[2025-06-26T19:40:10.642+0700] {subprocess.py:93} INFO - 25/06/26 19:40:10 INFO TaskSetManager: Finished task 99.0 in stage 0.0 (TID 99) in 44 ms on localhost (executor driver) (92/1454)
[2025-06-26T19:40:10.642+0700] {subprocess.py:93} INFO - 25/06/26 19:40:10 INFO Executor: Finished task 94.0 in stage 0.0 (TID 94). 3175 bytes result sent to driver
[2025-06-26T19:40:10.644+0700] {subprocess.py:93} INFO - 25/06/26 19:40:10 INFO TaskSetManager: Starting task 117.0 in stage 0.0 (TID 117) (localhost, executor driver, partition 117, PROCESS_LOCAL, 9215 bytes)
[2025-06-26T19:40:10.646+0700] {subprocess.py:93} INFO - 25/06/26 19:40:10 INFO Executor: Running task 117.0 in stage 0.0 (TID 117)
[2025-06-26T19:40:10.646+0700] {subprocess.py:93} INFO - 25/06/26 19:40:10 INFO Executor: Finished task 95.0 in stage 0.0 (TID 95). 3175 bytes result sent to driver
[2025-06-26T19:40:10.647+0700] {subprocess.py:93} INFO - 25/06/26 19:40:10 INFO Executor: Finished task 92.0 in stage 0.0 (TID 92). 3175 bytes result sent to driver
[2025-06-26T19:40:10.647+0700] {subprocess.py:93} INFO - 25/06/26 19:40:10 INFO TaskSetManager: Finished task 94.0 in stage 0.0 (TID 94) in 80 ms on localhost (executor driver) (93/1454)
[2025-06-26T19:40:10.647+0700] {subprocess.py:93} INFO - 25/06/26 19:40:10 INFO TaskSetManager: Starting task 118.0 in stage 0.0 (TID 118) (localhost, executor driver, partition 118, PROCESS_LOCAL, 9215 bytes)
[2025-06-26T19:40:10.647+0700] {subprocess.py:93} INFO - 25/06/26 19:40:10 INFO Executor: Running task 118.0 in stage 0.0 (TID 118)
[2025-06-26T19:40:10.647+0700] {subprocess.py:93} INFO - 25/06/26 19:40:10 INFO Executor: Finished task 108.0 in stage 0.0 (TID 108). 3175 bytes result sent to driver
[2025-06-26T19:40:10.647+0700] {subprocess.py:93} INFO - 25/06/26 19:40:10 INFO Executor: Finished task 100.0 in stage 0.0 (TID 100). 3175 bytes result sent to driver
[2025-06-26T19:40:10.647+0700] {subprocess.py:93} INFO - 25/06/26 19:40:10 INFO Executor: Finished task 91.0 in stage 0.0 (TID 91). 3218 bytes result sent to driver
[2025-06-26T19:40:10.647+0700] {subprocess.py:93} INFO - 25/06/26 19:40:10 INFO TaskSetManager: Starting task 119.0 in stage 0.0 (TID 119) (localhost, executor driver, partition 119, PROCESS_LOCAL, 9215 bytes)
[2025-06-26T19:40:10.647+0700] {subprocess.py:93} INFO - 25/06/26 19:40:10 INFO Executor: Finished task 101.0 in stage 0.0 (TID 101). 3175 bytes result sent to driver
[2025-06-26T19:40:10.648+0700] {subprocess.py:93} INFO - 25/06/26 19:40:10 INFO TaskSetManager: Finished task 97.0 in stage 0.0 (TID 97) in 76 ms on localhost (executor driver) (94/1454)
[2025-06-26T19:40:10.648+0700] {subprocess.py:93} INFO - 25/06/26 19:40:10 INFO TaskSetManager: Finished task 88.0 in stage 0.0 (TID 88) in 97 ms on localhost (executor driver) (95/1454)
[2025-06-26T19:40:10.648+0700] {subprocess.py:93} INFO - 25/06/26 19:40:10 INFO TaskSetManager: Starting task 120.0 in stage 0.0 (TID 120) (localhost, executor driver, partition 120, PROCESS_LOCAL, 9215 bytes)
[2025-06-26T19:40:10.650+0700] {subprocess.py:93} INFO - 25/06/26 19:40:10 INFO Executor: Running task 119.0 in stage 0.0 (TID 119)
[2025-06-26T19:40:10.650+0700] {subprocess.py:93} INFO - 25/06/26 19:40:10 INFO TaskSetManager: Starting task 121.0 in stage 0.0 (TID 121) (localhost, executor driver, partition 121, PROCESS_LOCAL, 9215 bytes)
[2025-06-26T19:40:10.651+0700] {subprocess.py:93} INFO - 25/06/26 19:40:10 INFO Executor: Finished task 96.0 in stage 0.0 (TID 96). 3175 bytes result sent to driver
[2025-06-26T19:40:10.651+0700] {subprocess.py:93} INFO - 25/06/26 19:40:10 INFO Executor: Running task 120.0 in stage 0.0 (TID 120)
[2025-06-26T19:40:10.651+0700] {subprocess.py:93} INFO - 25/06/26 19:40:10 INFO Executor: Finished task 104.0 in stage 0.0 (TID 104). 3175 bytes result sent to driver
[2025-06-26T19:40:10.651+0700] {subprocess.py:93} INFO - 25/06/26 19:40:10 INFO TaskSetManager: Starting task 122.0 in stage 0.0 (TID 122) (localhost, executor driver, partition 122, PROCESS_LOCAL, 9215 bytes)
[2025-06-26T19:40:10.660+0700] {subprocess.py:93} INFO - 25/06/26 19:40:10 INFO Executor: Running task 121.0 in stage 0.0 (TID 121)
[2025-06-26T19:40:10.661+0700] {subprocess.py:93} INFO - 25/06/26 19:40:10 INFO Executor: Running task 122.0 in stage 0.0 (TID 122)
[2025-06-26T19:40:10.661+0700] {subprocess.py:93} INFO - 25/06/26 19:40:10 INFO Executor: Finished task 105.0 in stage 0.0 (TID 105). 3175 bytes result sent to driver
[2025-06-26T19:40:10.661+0700] {subprocess.py:93} INFO - 25/06/26 19:40:10 INFO Executor: Finished task 103.0 in stage 0.0 (TID 103). 3218 bytes result sent to driver
[2025-06-26T19:40:10.661+0700] {subprocess.py:93} INFO - 25/06/26 19:40:10 INFO TaskSetManager: Finished task 95.0 in stage 0.0 (TID 95) in 91 ms on localhost (executor driver) (96/1454)
[2025-06-26T19:40:10.661+0700] {subprocess.py:93} INFO - 25/06/26 19:40:10 INFO Executor: Finished task 102.0 in stage 0.0 (TID 102). 3261 bytes result sent to driver
[2025-06-26T19:40:10.661+0700] {subprocess.py:93} INFO - 25/06/26 19:40:10 INFO TaskSetManager: Finished task 92.0 in stage 0.0 (TID 92) in 99 ms on localhost (executor driver) (97/1454)
[2025-06-26T19:40:10.661+0700] {subprocess.py:93} INFO - 25/06/26 19:40:10 INFO TaskSetManager: Finished task 108.0 in stage 0.0 (TID 108) in 38 ms on localhost (executor driver) (98/1454)
[2025-06-26T19:40:10.662+0700] {subprocess.py:93} INFO - 25/06/26 19:40:10 INFO TaskSetManager: Finished task 98.0 in stage 0.0 (TID 98) in 89 ms on localhost (executor driver) (99/1454)
[2025-06-26T19:40:10.662+0700] {subprocess.py:93} INFO - 25/06/26 19:40:10 INFO TaskSetManager: Finished task 91.0 in stage 0.0 (TID 91) in 103 ms on localhost (executor driver) (100/1454)
[2025-06-26T19:40:10.664+0700] {subprocess.py:93} INFO - 25/06/26 19:40:10 INFO Executor: Finished task 110.0 in stage 0.0 (TID 110). 3218 bytes result sent to driver
[2025-06-26T19:40:10.664+0700] {subprocess.py:93} INFO - 25/06/26 19:40:10 INFO TaskSetManager: Starting task 123.0 in stage 0.0 (TID 123) (localhost, executor driver, partition 123, PROCESS_LOCAL, 9215 bytes)
[2025-06-26T19:40:10.664+0700] {subprocess.py:93} INFO - 25/06/26 19:40:10 INFO TaskSetManager: Finished task 101.0 in stage 0.0 (TID 101) in 59 ms on localhost (executor driver) (101/1454)
[2025-06-26T19:40:10.665+0700] {subprocess.py:93} INFO - 25/06/26 19:40:10 INFO Executor: Running task 123.0 in stage 0.0 (TID 123)
[2025-06-26T19:40:10.666+0700] {subprocess.py:93} INFO - 25/06/26 19:40:10 INFO TaskSetManager: Starting task 124.0 in stage 0.0 (TID 124) (localhost, executor driver, partition 124, PROCESS_LOCAL, 9215 bytes)
[2025-06-26T19:40:10.667+0700] {subprocess.py:93} INFO - 25/06/26 19:40:10 INFO TaskSetManager: Finished task 96.0 in stage 0.0 (TID 96) in 96 ms on localhost (executor driver) (102/1454)
[2025-06-26T19:40:10.667+0700] {subprocess.py:93} INFO - 25/06/26 19:40:10 INFO TaskSetManager: Finished task 100.0 in stage 0.0 (TID 100) in 68 ms on localhost (executor driver) (103/1454)
[2025-06-26T19:40:10.667+0700] {subprocess.py:93} INFO - 25/06/26 19:40:10 INFO Executor: Finished task 112.0 in stage 0.0 (TID 112). 3218 bytes result sent to driver
[2025-06-26T19:40:10.667+0700] {subprocess.py:93} INFO - 25/06/26 19:40:10 INFO Executor: Running task 124.0 in stage 0.0 (TID 124)
[2025-06-26T19:40:10.668+0700] {subprocess.py:93} INFO - 25/06/26 19:40:10 INFO TaskSetManager: Starting task 125.0 in stage 0.0 (TID 125) (localhost, executor driver, partition 125, PROCESS_LOCAL, 9215 bytes)
[2025-06-26T19:40:10.669+0700] {subprocess.py:93} INFO - 25/06/26 19:40:10 INFO Executor: Finished task 107.0 in stage 0.0 (TID 107). 3218 bytes result sent to driver
[2025-06-26T19:40:10.673+0700] {subprocess.py:93} INFO - 25/06/26 19:40:10 INFO Executor: Running task 125.0 in stage 0.0 (TID 125)
[2025-06-26T19:40:10.673+0700] {subprocess.py:93} INFO - 25/06/26 19:40:10 INFO TaskSetManager: Starting task 126.0 in stage 0.0 (TID 126) (localhost, executor driver, partition 126, PROCESS_LOCAL, 9215 bytes)
[2025-06-26T19:40:10.674+0700] {subprocess.py:93} INFO - 25/06/26 19:40:10 INFO Executor: Running task 126.0 in stage 0.0 (TID 126)
[2025-06-26T19:40:10.674+0700] {subprocess.py:93} INFO - 25/06/26 19:40:10 INFO Executor: Finished task 111.0 in stage 0.0 (TID 111). 3218 bytes result sent to driver
[2025-06-26T19:40:10.674+0700] {subprocess.py:93} INFO - 25/06/26 19:40:10 INFO Executor: Finished task 109.0 in stage 0.0 (TID 109). 3218 bytes result sent to driver
[2025-06-26T19:40:10.674+0700] {subprocess.py:93} INFO - 25/06/26 19:40:10 INFO TaskSetManager: Starting task 127.0 in stage 0.0 (TID 127) (localhost, executor driver, partition 127, PROCESS_LOCAL, 9215 bytes)
[2025-06-26T19:40:10.674+0700] {subprocess.py:93} INFO - 25/06/26 19:40:10 INFO Executor: Finished task 106.0 in stage 0.0 (TID 106). 3218 bytes result sent to driver
[2025-06-26T19:40:10.675+0700] {subprocess.py:93} INFO - 25/06/26 19:40:10 INFO Executor: Finished task 114.0 in stage 0.0 (TID 114). 3218 bytes result sent to driver
[2025-06-26T19:40:10.676+0700] {subprocess.py:93} INFO - 25/06/26 19:40:10 INFO TaskSetManager: Finished task 104.0 in stage 0.0 (TID 104) in 61 ms on localhost (executor driver) (104/1454)
[2025-06-26T19:40:10.676+0700] {subprocess.py:93} INFO - 25/06/26 19:40:10 INFO Executor: Running task 127.0 in stage 0.0 (TID 127)
[2025-06-26T19:40:10.676+0700] {subprocess.py:93} INFO - 25/06/26 19:40:10 INFO TaskSetManager: Finished task 103.0 in stage 0.0 (TID 103) in 64 ms on localhost (executor driver) (105/1454)
[2025-06-26T19:40:10.677+0700] {subprocess.py:93} INFO - 25/06/26 19:40:10 INFO TaskSetManager: Finished task 105.0 in stage 0.0 (TID 105) in 61 ms on localhost (executor driver) (106/1454)
[2025-06-26T19:40:10.678+0700] {subprocess.py:93} INFO - 25/06/26 19:40:10 INFO TaskSetManager: Starting task 128.0 in stage 0.0 (TID 128) (localhost, executor driver, partition 128, PROCESS_LOCAL, 9215 bytes)
[2025-06-26T19:40:10.679+0700] {subprocess.py:93} INFO - 25/06/26 19:40:10 INFO TaskSetManager: Starting task 129.0 in stage 0.0 (TID 129) (localhost, executor driver, partition 129, PROCESS_LOCAL, 9215 bytes)
[2025-06-26T19:40:10.679+0700] {subprocess.py:93} INFO - 25/06/26 19:40:10 INFO Executor: Running task 128.0 in stage 0.0 (TID 128)
[2025-06-26T19:40:10.687+0700] {subprocess.py:93} INFO - 25/06/26 19:40:10 INFO Executor: Finished task 116.0 in stage 0.0 (TID 116). 3218 bytes result sent to driver
[2025-06-26T19:40:10.687+0700] {subprocess.py:93} INFO - 25/06/26 19:40:10 INFO TaskSetManager: Starting task 130.0 in stage 0.0 (TID 130) (localhost, executor driver, partition 130, PROCESS_LOCAL, 9215 bytes)
[2025-06-26T19:40:10.689+0700] {subprocess.py:93} INFO - 25/06/26 19:40:10 INFO TaskSetManager: Starting task 131.0 in stage 0.0 (TID 131) (localhost, executor driver, partition 131, PROCESS_LOCAL, 9215 bytes)
[2025-06-26T19:40:10.690+0700] {subprocess.py:93} INFO - 25/06/26 19:40:10 INFO TaskSetManager: Finished task 112.0 in stage 0.0 (TID 112) in 55 ms on localhost (executor driver) (107/1454)
[2025-06-26T19:40:10.690+0700] {subprocess.py:93} INFO - 25/06/26 19:40:10 INFO Executor: Running task 129.0 in stage 0.0 (TID 129)
[2025-06-26T19:40:10.690+0700] {subprocess.py:93} INFO - 25/06/26 19:40:10 INFO Executor: Running task 130.0 in stage 0.0 (TID 130)
[2025-06-26T19:40:10.691+0700] {subprocess.py:93} INFO - 25/06/26 19:40:10 INFO Executor: Running task 131.0 in stage 0.0 (TID 131)
[2025-06-26T19:40:10.691+0700] {subprocess.py:93} INFO - 25/06/26 19:40:10 INFO TaskSetManager: Finished task 102.0 in stage 0.0 (TID 102) in 78 ms on localhost (executor driver) (108/1454)
[2025-06-26T19:40:10.691+0700] {subprocess.py:93} INFO - 25/06/26 19:40:10 INFO TaskSetManager: Finished task 110.0 in stage 0.0 (TID 110) in 62 ms on localhost (executor driver) (109/1454)
[2025-06-26T19:40:10.692+0700] {subprocess.py:93} INFO - 25/06/26 19:40:10 INFO TaskSetManager: Starting task 132.0 in stage 0.0 (TID 132) (localhost, executor driver, partition 132, PROCESS_LOCAL, 9215 bytes)
[2025-06-26T19:40:10.692+0700] {subprocess.py:93} INFO - 25/06/26 19:40:10 INFO Executor: Finished task 121.0 in stage 0.0 (TID 121). 3175 bytes result sent to driver
[2025-06-26T19:40:10.692+0700] {subprocess.py:93} INFO - 25/06/26 19:40:10 INFO Executor: Finished task 115.0 in stage 0.0 (TID 115). 3218 bytes result sent to driver
[2025-06-26T19:40:10.692+0700] {subprocess.py:93} INFO - 25/06/26 19:40:10 INFO TaskSetManager: Starting task 133.0 in stage 0.0 (TID 133) (localhost, executor driver, partition 133, PROCESS_LOCAL, 9215 bytes)
[2025-06-26T19:40:10.693+0700] {subprocess.py:93} INFO - 25/06/26 19:40:10 INFO Executor: Running task 132.0 in stage 0.0 (TID 132)
[2025-06-26T19:40:10.693+0700] {subprocess.py:93} INFO - 25/06/26 19:40:10 INFO Executor: Running task 133.0 in stage 0.0 (TID 133)
[2025-06-26T19:40:10.693+0700] {subprocess.py:93} INFO - 25/06/26 19:40:10 INFO TaskSetManager: Starting task 134.0 in stage 0.0 (TID 134) (localhost, executor driver, partition 134, PROCESS_LOCAL, 9215 bytes)
[2025-06-26T19:40:10.693+0700] {subprocess.py:93} INFO - 25/06/26 19:40:10 INFO TaskSetManager: Starting task 135.0 in stage 0.0 (TID 135) (localhost, executor driver, partition 135, PROCESS_LOCAL, 9215 bytes)
[2025-06-26T19:40:10.693+0700] {subprocess.py:93} INFO - 25/06/26 19:40:10 INFO Executor: Running task 135.0 in stage 0.0 (TID 135)
[2025-06-26T19:40:10.694+0700] {subprocess.py:93} INFO - 25/06/26 19:40:10 INFO Executor: Running task 134.0 in stage 0.0 (TID 134)
