[2025-06-26T19:00:03.168+0700] {local_task_job_runner.py:120} INFO - ::group::Pre task execution logs
[2025-06-26T19:00:03.189+0700] {taskinstance.py:2073} INFO - Dependencies all met for dep_context=non-requeueable deps ti=<TaskInstance: send_data_to_powerbi.compact_csv_to_one_file scheduled__2025-06-26T11:50:00+00:00 [queued]>
[2025-06-26T19:00:03.195+0700] {taskinstance.py:2073} INFO - Dependencies all met for dep_context=requeueable deps ti=<TaskInstance: send_data_to_powerbi.compact_csv_to_one_file scheduled__2025-06-26T11:50:00+00:00 [queued]>
[2025-06-26T19:00:03.196+0700] {taskinstance.py:2303} INFO - Starting attempt 1 of 3
[2025-06-26T19:00:03.209+0700] {taskinstance.py:2327} INFO - Executing <Task(BashOperator): compact_csv_to_one_file> on 2025-06-26 11:50:00+00:00
[2025-06-26T19:00:03.218+0700] {standard_task_runner.py:63} INFO - Started process 33861 to run task
[2025-06-26T19:00:03.223+0700] {standard_task_runner.py:90} INFO - Running: ['airflow', 'tasks', 'run', 'send_data_to_powerbi', 'compact_csv_to_one_file', 'scheduled__2025-06-26T11:50:00+00:00', '--job-id', '52', '--raw', '--subdir', 'DAGS_FOLDER/load_power_bi.py', '--cfg-path', '/tmp/tmp3nqbbzu5']
[2025-06-26T19:00:03.224+0700] {standard_task_runner.py:91} INFO - Job 52: Subtask compact_csv_to_one_file
[2025-06-26T19:00:03.271+0700] {task_command.py:426} INFO - Running <TaskInstance: send_data_to_powerbi.compact_csv_to_one_file scheduled__2025-06-26T11:50:00+00:00 [running]> on host Panda
[2025-06-26T19:00:03.351+0700] {taskinstance.py:2644} INFO - Exporting env vars: AIRFLOW_CTX_DAG_OWNER='group_03' AIRFLOW_CTX_DAG_ID='send_data_to_powerbi' AIRFLOW_CTX_TASK_ID='compact_csv_to_one_file' AIRFLOW_CTX_EXECUTION_DATE='2025-06-26T11:50:00+00:00' AIRFLOW_CTX_TRY_NUMBER='1' AIRFLOW_CTX_DAG_RUN_ID='scheduled__2025-06-26T11:50:00+00:00'
[2025-06-26T19:00:03.352+0700] {taskinstance.py:430} INFO - ::endgroup::
[2025-06-26T19:00:03.352+0700] {subprocess.py:63} INFO - Tmp dir root location: /tmp
[2025-06-26T19:00:03.353+0700] {subprocess.py:75} INFO - Running command: ['/usr/bin/bash', '-c', 'spark-submit /home/panda/Documents/ODAP/Project/hadoop/compact_csv.py && sleep 10']
[2025-06-26T19:00:03.370+0700] {subprocess.py:86} INFO - Output:
[2025-06-26T19:00:05.675+0700] {subprocess.py:93} INFO - 25/06/26 19:00:05 INFO SparkContext: Running Spark version 3.5.5
[2025-06-26T19:00:05.677+0700] {subprocess.py:93} INFO - 25/06/26 19:00:05 INFO SparkContext: OS info Linux, 6.11.0-26-generic, amd64
[2025-06-26T19:00:05.677+0700] {subprocess.py:93} INFO - 25/06/26 19:00:05 INFO SparkContext: Java version 11.0.27
[2025-06-26T19:00:05.828+0700] {subprocess.py:93} INFO - 25/06/26 19:00:05 INFO ResourceUtils: ==============================================================
[2025-06-26T19:00:05.828+0700] {subprocess.py:93} INFO - 25/06/26 19:00:05 INFO ResourceUtils: No custom resources configured for spark.driver.
[2025-06-26T19:00:05.828+0700] {subprocess.py:93} INFO - 25/06/26 19:00:05 INFO ResourceUtils: ==============================================================
[2025-06-26T19:00:05.829+0700] {subprocess.py:93} INFO - 25/06/26 19:00:05 INFO SparkContext: Submitted application: CompactSmallFiles
[2025-06-26T19:00:05.851+0700] {subprocess.py:93} INFO - 25/06/26 19:00:05 INFO ResourceProfile: Default ResourceProfile created, executor resources: Map(cores -> name: cores, amount: 1, script: , vendor: , memory -> name: memory, amount: 1024, script: , vendor: , offHeap -> name: offHeap, amount: 0, script: , vendor: ), task resources: Map(cpus -> name: cpus, amount: 1.0)
[2025-06-26T19:00:05.864+0700] {subprocess.py:93} INFO - 25/06/26 19:00:05 INFO ResourceProfile: Limiting resource is cpu
[2025-06-26T19:00:05.865+0700] {subprocess.py:93} INFO - 25/06/26 19:00:05 INFO ResourceProfileManager: Added ResourceProfile id: 0
[2025-06-26T19:00:05.923+0700] {subprocess.py:93} INFO - 25/06/26 19:00:05 INFO SecurityManager: Changing view acls to: panda
[2025-06-26T19:00:05.924+0700] {subprocess.py:93} INFO - 25/06/26 19:00:05 INFO SecurityManager: Changing modify acls to: panda
[2025-06-26T19:00:05.924+0700] {subprocess.py:93} INFO - 25/06/26 19:00:05 INFO SecurityManager: Changing view acls groups to:
[2025-06-26T19:00:05.924+0700] {subprocess.py:93} INFO - 25/06/26 19:00:05 INFO SecurityManager: Changing modify acls groups to:
[2025-06-26T19:00:05.925+0700] {subprocess.py:93} INFO - 25/06/26 19:00:05 INFO SecurityManager: SecurityManager: authentication disabled; ui acls disabled; users with view permissions: panda; groups with view permissions: EMPTY; users with modify permissions: panda; groups with modify permissions: EMPTY
[2025-06-26T19:00:06.195+0700] {subprocess.py:93} INFO - 25/06/26 19:00:06 INFO Utils: Successfully started service 'sparkDriver' on port 39395.
[2025-06-26T19:00:06.225+0700] {subprocess.py:93} INFO - 25/06/26 19:00:06 INFO SparkEnv: Registering MapOutputTracker
[2025-06-26T19:00:06.276+0700] {subprocess.py:93} INFO - 25/06/26 19:00:06 INFO SparkEnv: Registering BlockManagerMaster
[2025-06-26T19:00:06.297+0700] {subprocess.py:93} INFO - 25/06/26 19:00:06 INFO BlockManagerMasterEndpoint: Using org.apache.spark.storage.DefaultTopologyMapper for getting topology information
[2025-06-26T19:00:06.298+0700] {subprocess.py:93} INFO - 25/06/26 19:00:06 INFO BlockManagerMasterEndpoint: BlockManagerMasterEndpoint up
[2025-06-26T19:00:06.302+0700] {subprocess.py:93} INFO - 25/06/26 19:00:06 INFO SparkEnv: Registering BlockManagerMasterHeartbeat
[2025-06-26T19:00:06.331+0700] {subprocess.py:93} INFO - 25/06/26 19:00:06 INFO DiskBlockManager: Created local directory at /tmp/blockmgr-f505251e-008d-4c6e-94b3-4d2a2cbb804a
[2025-06-26T19:00:06.347+0700] {subprocess.py:93} INFO - 25/06/26 19:00:06 INFO MemoryStore: MemoryStore started with capacity 434.4 MiB
[2025-06-26T19:00:06.362+0700] {subprocess.py:93} INFO - 25/06/26 19:00:06 INFO SparkEnv: Registering OutputCommitCoordinator
[2025-06-26T19:00:06.516+0700] {subprocess.py:93} INFO - 25/06/26 19:00:06 INFO JettyUtils: Start Jetty 127.0.0.1:4040 for SparkUI
[2025-06-26T19:00:06.579+0700] {subprocess.py:93} INFO - 25/06/26 19:00:06 WARN Utils: Service 'SparkUI' could not bind on port 4040. Attempting port 4041.
[2025-06-26T19:00:06.599+0700] {subprocess.py:93} INFO - 25/06/26 19:00:06 INFO Utils: Successfully started service 'SparkUI' on port 4041.
[2025-06-26T19:00:06.720+0700] {subprocess.py:93} INFO - 25/06/26 19:00:06 INFO Executor: Starting executor ID driver on host localhost
[2025-06-26T19:00:06.721+0700] {subprocess.py:93} INFO - 25/06/26 19:00:06 INFO Executor: OS info Linux, 6.11.0-26-generic, amd64
[2025-06-26T19:00:06.721+0700] {subprocess.py:93} INFO - 25/06/26 19:00:06 INFO Executor: Java version 11.0.27
[2025-06-26T19:00:06.732+0700] {subprocess.py:93} INFO - 25/06/26 19:00:06 INFO Executor: Starting executor with user classpath (userClassPathFirst = false): ''
[2025-06-26T19:00:06.732+0700] {subprocess.py:93} INFO - 25/06/26 19:00:06 INFO Executor: Created or updated repl class loader org.apache.spark.util.MutableURLClassLoader@7bd107b1 for default.
[2025-06-26T19:00:06.763+0700] {subprocess.py:93} INFO - 25/06/26 19:00:06 INFO Utils: Successfully started service 'org.apache.spark.network.netty.NettyBlockTransferService' on port 44225.
[2025-06-26T19:00:06.763+0700] {subprocess.py:93} INFO - 25/06/26 19:00:06 INFO NettyBlockTransferService: Server created on localhost:44225
[2025-06-26T19:00:06.766+0700] {subprocess.py:93} INFO - 25/06/26 19:00:06 INFO BlockManager: Using org.apache.spark.storage.RandomBlockReplicationPolicy for block replication policy
[2025-06-26T19:00:06.775+0700] {subprocess.py:93} INFO - 25/06/26 19:00:06 INFO BlockManagerMaster: Registering BlockManager BlockManagerId(driver, localhost, 44225, None)
[2025-06-26T19:00:06.783+0700] {subprocess.py:93} INFO - 25/06/26 19:00:06 INFO BlockManagerMasterEndpoint: Registering block manager localhost:44225 with 434.4 MiB RAM, BlockManagerId(driver, localhost, 44225, None)
[2025-06-26T19:00:06.787+0700] {subprocess.py:93} INFO - 25/06/26 19:00:06 INFO BlockManagerMaster: Registered BlockManager BlockManagerId(driver, localhost, 44225, None)
[2025-06-26T19:00:06.788+0700] {subprocess.py:93} INFO - 25/06/26 19:00:06 INFO BlockManager: Initialized BlockManager: BlockManagerId(driver, localhost, 44225, None)
[2025-06-26T19:00:07.240+0700] {subprocess.py:93} INFO - 25/06/26 19:00:07 INFO SharedState: Setting hive.metastore.warehouse.dir ('null') to the value of spark.sql.warehouse.dir.
[2025-06-26T19:00:07.249+0700] {subprocess.py:93} INFO - 25/06/26 19:00:07 INFO SharedState: Warehouse path is 'file:/tmp/airflowtmp12grq_8_/spark-warehouse'.
[2025-06-26T19:00:08.476+0700] {subprocess.py:93} INFO - 25/06/26 19:00:08 INFO MetadataLogFileIndex: Reading streaming file log from hdfs://localhost:9000/transactions_by_hour/_spark_metadata
[2025-06-26T19:00:08.545+0700] {subprocess.py:93} INFO - 25/06/26 19:00:08 INFO FileStreamSinkLog: BatchIds found from listing: 0, 1, 2, 3, 4, 5, 6, 7, 8, 9, 10, 11, 12, 13, 14, 15, 16, 17, 18, 19, 20, 21, 22, 23, 24, 25, 26, 27, 28, 29, 30, 31, 32, 33, 34, 35, 36, 37, 38, 39, 40, 41, 42, 43, 44, 45, 46, 47, 48, 49, 50, 51, 52, 53, 54, 55, 56, 57, 58, 59, 60, 61, 62, 63, 64, 65, 66, 67, 68, 69, 70, 71, 72, 73, 74, 75, 76, 77, 78, 79, 80, 81, 82, 83, 84, 85, 86, 87, 88, 89, 90, 91, 92, 93, 94, 95, 96, 97, 98, 99, 100, 101, 102, 103, 104, 105, 106, 107, 108, 109, 110, 111, 112, 113, 114, 115, 116, 117, 118, 119, 120, 121, 122, 123, 124, 125, 126, 127, 128, 129, 130, 131, 132, 133, 134, 135, 136, 137, 138, 139, 140, 141, 142, 143, 144, 145, 146, 147, 148, 149, 150, 151, 152, 153, 154, 155, 156, 157, 158, 159, 160, 161, 162, 163, 164, 165, 166, 167, 168, 169, 170, 171, 172, 173, 174, 175, 176, 177, 178, 179, 180, 181, 182, 183, 184, 185, 186, 187, 188, 189, 190, 191, 192, 193, 194, 195, 196, 197, 198, 199, 200, 201, 202, 203, 204, 205, 206, 207, 208, 209, 210, 211, 212, 213, 214, 215, 216, 217, 218, 219, 220, 221, 222, 223, 224, 225, 226, 227, 228, 229, 230, 231, 232, 233, 234, 235, 236, 237, 238, 239, 240, 241, 242, 243, 244, 245, 246, 247, 248, 249, 250, 251, 252, 253, 254, 255, 256, 257, 258, 259, 260, 261, 262, 263, 264, 265, 266, 267, 268, 269, 270, 271, 272, 273, 274, 275, 276, 277, 278, 279, 280, 281, 282
[2025-06-26T19:00:08.576+0700] {subprocess.py:93} INFO - 25/06/26 19:00:08 INFO FileStreamSinkLog: Set the compact interval to 10 [defaultCompactInterval: 10]
[2025-06-26T19:00:08.999+0700] {subprocess.py:93} INFO - 25/06/26 19:00:08 INFO HadoopFSUtils: Listing leaf files and directories in parallel under 283 paths. The first several paths are: hdfs://localhost:9000/transactions_by_hour/part-00000-35848e14-b857-426e-8939-db9c96261483-c000.csv, hdfs://localhost:9000/transactions_by_hour/part-00000-d7ab39d9-b4ef-4e2e-b472-4c1883c38273-c000.csv, hdfs://localhost:9000/transactions_by_hour/part-00000-cce2d287-6512-49d1-aa31-f452c0dcdaf9-c000.csv, hdfs://localhost:9000/transactions_by_hour/part-00000-ac8933a1-5bf2-4814-a228-6604c7045e4c-c000.csv, hdfs://localhost:9000/transactions_by_hour/part-00000-9c60d322-8794-4968-a7a5-364181d16d94-c000.csv, hdfs://localhost:9000/transactions_by_hour/part-00000-76895572-6aa7-4225-8325-6962e0c98ee2-c000.csv, hdfs://localhost:9000/transactions_by_hour/part-00000-a92a3ce5-6132-4e9e-8e69-11e47f72f0a2-c000.csv, hdfs://localhost:9000/transactions_by_hour/part-00000-b48a08d4-d847-4307-b612-e35a8f471916-c000.csv, hdfs://localhost:9000/transactions_by_hour/part-00000-e8f1544c-6d23-403f-a02b-06e9bef1638a-c000.csv, hdfs://localhost:9000/transactions_by_hour/part-00000-08040c60-6fee-4dcc-b2e9-af62320fb049-c000.csv.
[2025-06-26T19:00:09.348+0700] {subprocess.py:93} INFO - 25/06/26 19:00:09 INFO SparkContext: Starting job: csv at NativeMethodAccessorImpl.java:0
[2025-06-26T19:00:09.373+0700] {subprocess.py:93} INFO - 25/06/26 19:00:09 INFO DAGScheduler: Got job 0 (csv at NativeMethodAccessorImpl.java:0) with 283 output partitions
[2025-06-26T19:00:09.373+0700] {subprocess.py:93} INFO - 25/06/26 19:00:09 INFO DAGScheduler: Final stage: ResultStage 0 (csv at NativeMethodAccessorImpl.java:0)
[2025-06-26T19:00:09.374+0700] {subprocess.py:93} INFO - 25/06/26 19:00:09 INFO DAGScheduler: Parents of final stage: List()
[2025-06-26T19:00:09.377+0700] {subprocess.py:93} INFO - 25/06/26 19:00:09 INFO DAGScheduler: Missing parents: List()
[2025-06-26T19:00:09.383+0700] {subprocess.py:93} INFO - 25/06/26 19:00:09 INFO DAGScheduler: Submitting ResultStage 0 (MapPartitionsRDD[1] at csv at NativeMethodAccessorImpl.java:0), which has no missing parents
[2025-06-26T19:00:09.509+0700] {subprocess.py:93} INFO - 25/06/26 19:00:09 INFO MemoryStore: Block broadcast_0 stored as values in memory (estimated size 103.2 KiB, free 434.3 MiB)
[2025-06-26T19:00:09.552+0700] {subprocess.py:93} INFO - 25/06/26 19:00:09 INFO MemoryStore: Block broadcast_0_piece0 stored as bytes in memory (estimated size 37.3 KiB, free 434.3 MiB)
[2025-06-26T19:00:09.555+0700] {subprocess.py:93} INFO - 25/06/26 19:00:09 INFO BlockManagerInfo: Added broadcast_0_piece0 in memory on localhost:44225 (size: 37.3 KiB, free: 434.4 MiB)
[2025-06-26T19:00:09.560+0700] {subprocess.py:93} INFO - 25/06/26 19:00:09 INFO SparkContext: Created broadcast 0 from broadcast at DAGScheduler.scala:1585
[2025-06-26T19:00:09.588+0700] {subprocess.py:93} INFO - 25/06/26 19:00:09 INFO DAGScheduler: Submitting 283 missing tasks from ResultStage 0 (MapPartitionsRDD[1] at csv at NativeMethodAccessorImpl.java:0) (first 15 tasks are for partitions Vector(0, 1, 2, 3, 4, 5, 6, 7, 8, 9, 10, 11, 12, 13, 14))
[2025-06-26T19:00:09.590+0700] {subprocess.py:93} INFO - 25/06/26 19:00:09 INFO TaskSchedulerImpl: Adding task set 0.0 with 283 tasks resource profile 0
[2025-06-26T19:00:09.668+0700] {subprocess.py:93} INFO - 25/06/26 19:00:09 INFO TaskSetManager: Starting task 0.0 in stage 0.0 (TID 0) (localhost, executor driver, partition 0, PROCESS_LOCAL, 9215 bytes)
[2025-06-26T19:00:09.672+0700] {subprocess.py:93} INFO - 25/06/26 19:00:09 INFO TaskSetManager: Starting task 1.0 in stage 0.0 (TID 1) (localhost, executor driver, partition 1, PROCESS_LOCAL, 9215 bytes)
[2025-06-26T19:00:09.673+0700] {subprocess.py:93} INFO - 25/06/26 19:00:09 INFO TaskSetManager: Starting task 2.0 in stage 0.0 (TID 2) (localhost, executor driver, partition 2, PROCESS_LOCAL, 9215 bytes)
[2025-06-26T19:00:09.673+0700] {subprocess.py:93} INFO - 25/06/26 19:00:09 INFO TaskSetManager: Starting task 3.0 in stage 0.0 (TID 3) (localhost, executor driver, partition 3, PROCESS_LOCAL, 9215 bytes)
[2025-06-26T19:00:09.674+0700] {subprocess.py:93} INFO - 25/06/26 19:00:09 INFO TaskSetManager: Starting task 4.0 in stage 0.0 (TID 4) (localhost, executor driver, partition 4, PROCESS_LOCAL, 9215 bytes)
[2025-06-26T19:00:09.675+0700] {subprocess.py:93} INFO - 25/06/26 19:00:09 INFO TaskSetManager: Starting task 5.0 in stage 0.0 (TID 5) (localhost, executor driver, partition 5, PROCESS_LOCAL, 9215 bytes)
[2025-06-26T19:00:09.676+0700] {subprocess.py:93} INFO - 25/06/26 19:00:09 INFO TaskSetManager: Starting task 6.0 in stage 0.0 (TID 6) (localhost, executor driver, partition 6, PROCESS_LOCAL, 9215 bytes)
[2025-06-26T19:00:09.676+0700] {subprocess.py:93} INFO - 25/06/26 19:00:09 INFO TaskSetManager: Starting task 7.0 in stage 0.0 (TID 7) (localhost, executor driver, partition 7, PROCESS_LOCAL, 9215 bytes)
[2025-06-26T19:00:09.677+0700] {subprocess.py:93} INFO - 25/06/26 19:00:09 INFO TaskSetManager: Starting task 8.0 in stage 0.0 (TID 8) (localhost, executor driver, partition 8, PROCESS_LOCAL, 9215 bytes)
[2025-06-26T19:00:09.677+0700] {subprocess.py:93} INFO - 25/06/26 19:00:09 INFO TaskSetManager: Starting task 9.0 in stage 0.0 (TID 9) (localhost, executor driver, partition 9, PROCESS_LOCAL, 9215 bytes)
[2025-06-26T19:00:09.677+0700] {subprocess.py:93} INFO - 25/06/26 19:00:09 INFO TaskSetManager: Starting task 10.0 in stage 0.0 (TID 10) (localhost, executor driver, partition 10, PROCESS_LOCAL, 9215 bytes)
[2025-06-26T19:00:09.678+0700] {subprocess.py:93} INFO - 25/06/26 19:00:09 INFO TaskSetManager: Starting task 11.0 in stage 0.0 (TID 11) (localhost, executor driver, partition 11, PROCESS_LOCAL, 9215 bytes)
[2025-06-26T19:00:09.678+0700] {subprocess.py:93} INFO - 25/06/26 19:00:09 INFO TaskSetManager: Starting task 12.0 in stage 0.0 (TID 12) (localhost, executor driver, partition 12, PROCESS_LOCAL, 9215 bytes)
[2025-06-26T19:00:09.679+0700] {subprocess.py:93} INFO - 25/06/26 19:00:09 INFO TaskSetManager: Starting task 13.0 in stage 0.0 (TID 13) (localhost, executor driver, partition 13, PROCESS_LOCAL, 9215 bytes)
[2025-06-26T19:00:09.679+0700] {subprocess.py:93} INFO - 25/06/26 19:00:09 INFO TaskSetManager: Starting task 14.0 in stage 0.0 (TID 14) (localhost, executor driver, partition 14, PROCESS_LOCAL, 9215 bytes)
[2025-06-26T19:00:09.680+0700] {subprocess.py:93} INFO - 25/06/26 19:00:09 INFO TaskSetManager: Starting task 15.0 in stage 0.0 (TID 15) (localhost, executor driver, partition 15, PROCESS_LOCAL, 9215 bytes)
[2025-06-26T19:00:09.680+0700] {subprocess.py:93} INFO - 25/06/26 19:00:09 INFO TaskSetManager: Starting task 16.0 in stage 0.0 (TID 16) (localhost, executor driver, partition 16, PROCESS_LOCAL, 9215 bytes)
[2025-06-26T19:00:09.681+0700] {subprocess.py:93} INFO - 25/06/26 19:00:09 INFO TaskSetManager: Starting task 17.0 in stage 0.0 (TID 17) (localhost, executor driver, partition 17, PROCESS_LOCAL, 9215 bytes)
[2025-06-26T19:00:09.681+0700] {subprocess.py:93} INFO - 25/06/26 19:00:09 INFO TaskSetManager: Starting task 18.0 in stage 0.0 (TID 18) (localhost, executor driver, partition 18, PROCESS_LOCAL, 9215 bytes)
[2025-06-26T19:00:09.681+0700] {subprocess.py:93} INFO - 25/06/26 19:00:09 INFO TaskSetManager: Starting task 19.0 in stage 0.0 (TID 19) (localhost, executor driver, partition 19, PROCESS_LOCAL, 9215 bytes)
[2025-06-26T19:00:09.682+0700] {subprocess.py:93} INFO - 25/06/26 19:00:09 INFO TaskSetManager: Starting task 20.0 in stage 0.0 (TID 20) (localhost, executor driver, partition 20, PROCESS_LOCAL, 9215 bytes)
[2025-06-26T19:00:09.682+0700] {subprocess.py:93} INFO - 25/06/26 19:00:09 INFO TaskSetManager: Starting task 21.0 in stage 0.0 (TID 21) (localhost, executor driver, partition 21, PROCESS_LOCAL, 9215 bytes)
[2025-06-26T19:00:09.699+0700] {subprocess.py:93} INFO - 25/06/26 19:00:09 INFO Executor: Running task 8.0 in stage 0.0 (TID 8)
[2025-06-26T19:00:09.700+0700] {subprocess.py:93} INFO - 25/06/26 19:00:09 INFO Executor: Running task 2.0 in stage 0.0 (TID 2)
[2025-06-26T19:00:09.700+0700] {subprocess.py:93} INFO - 25/06/26 19:00:09 INFO Executor: Running task 5.0 in stage 0.0 (TID 5)
[2025-06-26T19:00:09.700+0700] {subprocess.py:93} INFO - 25/06/26 19:00:09 INFO Executor: Running task 15.0 in stage 0.0 (TID 15)
[2025-06-26T19:00:09.700+0700] {subprocess.py:93} INFO - 25/06/26 19:00:09 INFO Executor: Running task 0.0 in stage 0.0 (TID 0)
[2025-06-26T19:00:09.700+0700] {subprocess.py:93} INFO - 25/06/26 19:00:09 INFO Executor: Running task 7.0 in stage 0.0 (TID 7)
[2025-06-26T19:00:09.700+0700] {subprocess.py:93} INFO - 25/06/26 19:00:09 INFO Executor: Running task 21.0 in stage 0.0 (TID 21)
[2025-06-26T19:00:09.700+0700] {subprocess.py:93} INFO - 25/06/26 19:00:09 INFO Executor: Running task 18.0 in stage 0.0 (TID 18)
[2025-06-26T19:00:09.700+0700] {subprocess.py:93} INFO - 25/06/26 19:00:09 INFO Executor: Running task 4.0 in stage 0.0 (TID 4)
[2025-06-26T19:00:09.700+0700] {subprocess.py:93} INFO - 25/06/26 19:00:09 INFO Executor: Running task 1.0 in stage 0.0 (TID 1)
[2025-06-26T19:00:09.700+0700] {subprocess.py:93} INFO - 25/06/26 19:00:09 INFO Executor: Running task 10.0 in stage 0.0 (TID 10)
[2025-06-26T19:00:09.701+0700] {subprocess.py:93} INFO - 25/06/26 19:00:09 INFO Executor: Running task 12.0 in stage 0.0 (TID 12)
[2025-06-26T19:00:09.701+0700] {subprocess.py:93} INFO - 25/06/26 19:00:09 INFO Executor: Running task 14.0 in stage 0.0 (TID 14)
[2025-06-26T19:00:09.701+0700] {subprocess.py:93} INFO - 25/06/26 19:00:09 INFO Executor: Running task 16.0 in stage 0.0 (TID 16)
[2025-06-26T19:00:09.701+0700] {subprocess.py:93} INFO - 25/06/26 19:00:09 INFO Executor: Running task 3.0 in stage 0.0 (TID 3)
[2025-06-26T19:00:09.701+0700] {subprocess.py:93} INFO - 25/06/26 19:00:09 INFO Executor: Running task 6.0 in stage 0.0 (TID 6)
[2025-06-26T19:00:09.701+0700] {subprocess.py:93} INFO - 25/06/26 19:00:09 INFO Executor: Running task 11.0 in stage 0.0 (TID 11)
[2025-06-26T19:00:09.701+0700] {subprocess.py:93} INFO - 25/06/26 19:00:09 INFO Executor: Running task 19.0 in stage 0.0 (TID 19)
[2025-06-26T19:00:09.701+0700] {subprocess.py:93} INFO - 25/06/26 19:00:09 INFO Executor: Running task 13.0 in stage 0.0 (TID 13)
[2025-06-26T19:00:09.701+0700] {subprocess.py:93} INFO - 25/06/26 19:00:09 INFO Executor: Running task 17.0 in stage 0.0 (TID 17)
[2025-06-26T19:00:09.701+0700] {subprocess.py:93} INFO - 25/06/26 19:00:09 INFO Executor: Running task 20.0 in stage 0.0 (TID 20)
[2025-06-26T19:00:09.701+0700] {subprocess.py:93} INFO - 25/06/26 19:00:09 INFO Executor: Running task 9.0 in stage 0.0 (TID 9)
[2025-06-26T19:00:10.095+0700] {subprocess.py:93} INFO - 25/06/26 19:00:10 INFO Executor: Finished task 3.0 in stage 0.0 (TID 3). 3261 bytes result sent to driver
[2025-06-26T19:00:10.095+0700] {subprocess.py:93} INFO - 25/06/26 19:00:10 INFO Executor: Finished task 20.0 in stage 0.0 (TID 20). 3261 bytes result sent to driver
[2025-06-26T19:00:10.096+0700] {subprocess.py:93} INFO - 25/06/26 19:00:10 INFO Executor: Finished task 4.0 in stage 0.0 (TID 4). 3261 bytes result sent to driver
[2025-06-26T19:00:10.096+0700] {subprocess.py:93} INFO - 25/06/26 19:00:10 INFO Executor: Finished task 11.0 in stage 0.0 (TID 11). 3261 bytes result sent to driver
[2025-06-26T19:00:10.096+0700] {subprocess.py:93} INFO - 25/06/26 19:00:10 INFO Executor: Finished task 10.0 in stage 0.0 (TID 10). 3261 bytes result sent to driver
[2025-06-26T19:00:10.096+0700] {subprocess.py:93} INFO - 25/06/26 19:00:10 INFO Executor: Finished task 14.0 in stage 0.0 (TID 14). 3261 bytes result sent to driver
[2025-06-26T19:00:10.097+0700] {subprocess.py:93} INFO - 25/06/26 19:00:10 INFO Executor: Finished task 7.0 in stage 0.0 (TID 7). 3261 bytes result sent to driver
[2025-06-26T19:00:10.097+0700] {subprocess.py:93} INFO - 25/06/26 19:00:10 INFO Executor: Finished task 16.0 in stage 0.0 (TID 16). 3261 bytes result sent to driver
[2025-06-26T19:00:10.097+0700] {subprocess.py:93} INFO - 25/06/26 19:00:10 INFO Executor: Finished task 17.0 in stage 0.0 (TID 17). 3261 bytes result sent to driver
[2025-06-26T19:00:10.097+0700] {subprocess.py:93} INFO - 25/06/26 19:00:10 INFO Executor: Finished task 9.0 in stage 0.0 (TID 9). 3261 bytes result sent to driver
[2025-06-26T19:00:10.097+0700] {subprocess.py:93} INFO - 25/06/26 19:00:10 INFO Executor: Finished task 21.0 in stage 0.0 (TID 21). 3261 bytes result sent to driver
[2025-06-26T19:00:10.097+0700] {subprocess.py:93} INFO - 25/06/26 19:00:10 INFO Executor: Finished task 15.0 in stage 0.0 (TID 15). 3261 bytes result sent to driver
[2025-06-26T19:00:10.097+0700] {subprocess.py:93} INFO - 25/06/26 19:00:10 INFO Executor: Finished task 0.0 in stage 0.0 (TID 0). 3261 bytes result sent to driver
[2025-06-26T19:00:10.097+0700] {subprocess.py:93} INFO - 25/06/26 19:00:10 INFO Executor: Finished task 1.0 in stage 0.0 (TID 1). 3261 bytes result sent to driver
[2025-06-26T19:00:10.098+0700] {subprocess.py:93} INFO - 25/06/26 19:00:10 INFO Executor: Finished task 6.0 in stage 0.0 (TID 6). 3261 bytes result sent to driver
[2025-06-26T19:00:10.098+0700] {subprocess.py:93} INFO - 25/06/26 19:00:10 INFO Executor: Finished task 19.0 in stage 0.0 (TID 19). 3261 bytes result sent to driver
[2025-06-26T19:00:10.098+0700] {subprocess.py:93} INFO - 25/06/26 19:00:10 INFO Executor: Finished task 8.0 in stage 0.0 (TID 8). 3261 bytes result sent to driver
[2025-06-26T19:00:10.098+0700] {subprocess.py:93} INFO - 25/06/26 19:00:10 INFO Executor: Finished task 2.0 in stage 0.0 (TID 2). 3261 bytes result sent to driver
[2025-06-26T19:00:10.098+0700] {subprocess.py:93} INFO - 25/06/26 19:00:10 INFO Executor: Finished task 13.0 in stage 0.0 (TID 13). 3261 bytes result sent to driver
[2025-06-26T19:00:10.098+0700] {subprocess.py:93} INFO - 25/06/26 19:00:10 INFO Executor: Finished task 5.0 in stage 0.0 (TID 5). 3261 bytes result sent to driver
[2025-06-26T19:00:10.098+0700] {subprocess.py:93} INFO - 25/06/26 19:00:10 INFO Executor: Finished task 12.0 in stage 0.0 (TID 12). 3261 bytes result sent to driver
[2025-06-26T19:00:10.098+0700] {subprocess.py:93} INFO - 25/06/26 19:00:10 INFO Executor: Finished task 18.0 in stage 0.0 (TID 18). 3261 bytes result sent to driver
[2025-06-26T19:00:10.105+0700] {subprocess.py:93} INFO - 25/06/26 19:00:10 INFO TaskSetManager: Starting task 22.0 in stage 0.0 (TID 22) (localhost, executor driver, partition 22, PROCESS_LOCAL, 9215 bytes)
[2025-06-26T19:00:10.106+0700] {subprocess.py:93} INFO - 25/06/26 19:00:10 INFO Executor: Running task 22.0 in stage 0.0 (TID 22)
[2025-06-26T19:00:10.107+0700] {subprocess.py:93} INFO - 25/06/26 19:00:10 INFO TaskSetManager: Starting task 23.0 in stage 0.0 (TID 23) (localhost, executor driver, partition 23, PROCESS_LOCAL, 9215 bytes)
[2025-06-26T19:00:10.108+0700] {subprocess.py:93} INFO - 25/06/26 19:00:10 INFO Executor: Running task 23.0 in stage 0.0 (TID 23)
[2025-06-26T19:00:10.108+0700] {subprocess.py:93} INFO - 25/06/26 19:00:10 INFO TaskSetManager: Starting task 24.0 in stage 0.0 (TID 24) (localhost, executor driver, partition 24, PROCESS_LOCAL, 9215 bytes)
[2025-06-26T19:00:10.109+0700] {subprocess.py:93} INFO - 25/06/26 19:00:10 INFO Executor: Running task 24.0 in stage 0.0 (TID 24)
[2025-06-26T19:00:10.111+0700] {subprocess.py:93} INFO - 25/06/26 19:00:10 INFO TaskSetManager: Starting task 25.0 in stage 0.0 (TID 25) (localhost, executor driver, partition 25, PROCESS_LOCAL, 9215 bytes)
[2025-06-26T19:00:10.113+0700] {subprocess.py:93} INFO - 25/06/26 19:00:10 INFO Executor: Running task 25.0 in stage 0.0 (TID 25)
[2025-06-26T19:00:10.114+0700] {subprocess.py:93} INFO - 25/06/26 19:00:10 INFO TaskSetManager: Starting task 26.0 in stage 0.0 (TID 26) (localhost, executor driver, partition 26, PROCESS_LOCAL, 9215 bytes)
[2025-06-26T19:00:10.115+0700] {subprocess.py:93} INFO - 25/06/26 19:00:10 INFO Executor: Running task 26.0 in stage 0.0 (TID 26)
[2025-06-26T19:00:10.116+0700] {subprocess.py:93} INFO - 25/06/26 19:00:10 INFO TaskSetManager: Finished task 8.0 in stage 0.0 (TID 8) in 438 ms on localhost (executor driver) (1/283)
[2025-06-26T19:00:10.120+0700] {subprocess.py:93} INFO - 25/06/26 19:00:10 INFO TaskSetManager: Finished task 6.0 in stage 0.0 (TID 6) in 443 ms on localhost (executor driver) (2/283)
[2025-06-26T19:00:10.120+0700] {subprocess.py:93} INFO - 25/06/26 19:00:10 INFO TaskSetManager: Finished task 3.0 in stage 0.0 (TID 3) in 447 ms on localhost (executor driver) (3/283)
[2025-06-26T19:00:10.120+0700] {subprocess.py:93} INFO - 25/06/26 19:00:10 INFO TaskSetManager: Finished task 7.0 in stage 0.0 (TID 7) in 444 ms on localhost (executor driver) (4/283)
[2025-06-26T19:00:10.122+0700] {subprocess.py:93} INFO - 25/06/26 19:00:10 INFO TaskSetManager: Starting task 27.0 in stage 0.0 (TID 27) (localhost, executor driver, partition 27, PROCESS_LOCAL, 9215 bytes)
[2025-06-26T19:00:10.123+0700] {subprocess.py:93} INFO - 25/06/26 19:00:10 INFO TaskSetManager: Finished task 13.0 in stage 0.0 (TID 13) in 445 ms on localhost (executor driver) (5/283)
[2025-06-26T19:00:10.123+0700] {subprocess.py:93} INFO - 25/06/26 19:00:10 INFO Executor: Running task 27.0 in stage 0.0 (TID 27)
[2025-06-26T19:00:10.125+0700] {subprocess.py:93} INFO - 25/06/26 19:00:10 INFO TaskSetManager: Starting task 28.0 in stage 0.0 (TID 28) (localhost, executor driver, partition 28, PROCESS_LOCAL, 9215 bytes)
[2025-06-26T19:00:10.125+0700] {subprocess.py:93} INFO - 25/06/26 19:00:10 INFO TaskSetManager: Finished task 4.0 in stage 0.0 (TID 4) in 452 ms on localhost (executor driver) (6/283)
[2025-06-26T19:00:10.126+0700] {subprocess.py:93} INFO - 25/06/26 19:00:10 INFO Executor: Running task 28.0 in stage 0.0 (TID 28)
[2025-06-26T19:00:10.128+0700] {subprocess.py:93} INFO - 25/06/26 19:00:10 INFO TaskSetManager: Starting task 29.0 in stage 0.0 (TID 29) (localhost, executor driver, partition 29, PROCESS_LOCAL, 9215 bytes)
[2025-06-26T19:00:10.129+0700] {subprocess.py:93} INFO - 25/06/26 19:00:10 INFO Executor: Running task 29.0 in stage 0.0 (TID 29)
[2025-06-26T19:00:10.129+0700] {subprocess.py:93} INFO - 25/06/26 19:00:10 INFO TaskSetManager: Starting task 30.0 in stage 0.0 (TID 30) (localhost, executor driver, partition 30, PROCESS_LOCAL, 9215 bytes)
[2025-06-26T19:00:10.129+0700] {subprocess.py:93} INFO - 25/06/26 19:00:10 INFO TaskSetManager: Finished task 9.0 in stage 0.0 (TID 9) in 451 ms on localhost (executor driver) (7/283)
[2025-06-26T19:00:10.130+0700] {subprocess.py:93} INFO - 25/06/26 19:00:10 INFO Executor: Running task 30.0 in stage 0.0 (TID 30)
[2025-06-26T19:00:10.130+0700] {subprocess.py:93} INFO - 25/06/26 19:00:10 INFO TaskSetManager: Starting task 31.0 in stage 0.0 (TID 31) (localhost, executor driver, partition 31, PROCESS_LOCAL, 9215 bytes)
[2025-06-26T19:00:10.131+0700] {subprocess.py:93} INFO - 25/06/26 19:00:10 INFO TaskSetManager: Finished task 17.0 in stage 0.0 (TID 17) in 450 ms on localhost (executor driver) (8/283)
[2025-06-26T19:00:10.132+0700] {subprocess.py:93} INFO - 25/06/26 19:00:10 INFO TaskSetManager: Finished task 11.0 in stage 0.0 (TID 11) in 454 ms on localhost (executor driver) (9/283)
[2025-06-26T19:00:10.132+0700] {subprocess.py:93} INFO - 25/06/26 19:00:10 INFO Executor: Running task 31.0 in stage 0.0 (TID 31)
[2025-06-26T19:00:10.134+0700] {subprocess.py:93} INFO - 25/06/26 19:00:10 INFO TaskSetManager: Starting task 32.0 in stage 0.0 (TID 32) (localhost, executor driver, partition 32, PROCESS_LOCAL, 9215 bytes)
[2025-06-26T19:00:10.134+0700] {subprocess.py:93} INFO - 25/06/26 19:00:10 INFO TaskSetManager: Finished task 19.0 in stage 0.0 (TID 19) in 453 ms on localhost (executor driver) (10/283)
[2025-06-26T19:00:10.134+0700] {subprocess.py:93} INFO - 25/06/26 19:00:10 INFO TaskSetManager: Finished task 12.0 in stage 0.0 (TID 12) in 456 ms on localhost (executor driver) (11/283)
[2025-06-26T19:00:10.136+0700] {subprocess.py:93} INFO - 25/06/26 19:00:10 INFO Executor: Running task 32.0 in stage 0.0 (TID 32)
[2025-06-26T19:00:10.140+0700] {subprocess.py:93} INFO - 25/06/26 19:00:10 INFO TaskSetManager: Starting task 33.0 in stage 0.0 (TID 33) (localhost, executor driver, partition 33, PROCESS_LOCAL, 9215 bytes)
[2025-06-26T19:00:10.140+0700] {subprocess.py:93} INFO - 25/06/26 19:00:10 INFO TaskSetManager: Starting task 34.0 in stage 0.0 (TID 34) (localhost, executor driver, partition 34, PROCESS_LOCAL, 9215 bytes)
[2025-06-26T19:00:10.140+0700] {subprocess.py:93} INFO - 25/06/26 19:00:10 INFO Executor: Running task 33.0 in stage 0.0 (TID 33)
[2025-06-26T19:00:10.140+0700] {subprocess.py:93} INFO - 25/06/26 19:00:10 INFO TaskSetManager: Starting task 35.0 in stage 0.0 (TID 35) (localhost, executor driver, partition 35, PROCESS_LOCAL, 9215 bytes)
[2025-06-26T19:00:10.141+0700] {subprocess.py:93} INFO - 25/06/26 19:00:10 INFO Executor: Finished task 22.0 in stage 0.0 (TID 22). 3218 bytes result sent to driver
[2025-06-26T19:00:10.141+0700] {subprocess.py:93} INFO - 25/06/26 19:00:10 INFO Executor: Running task 35.0 in stage 0.0 (TID 35)
[2025-06-26T19:00:10.141+0700] {subprocess.py:93} INFO - 25/06/26 19:00:10 INFO Executor: Running task 34.0 in stage 0.0 (TID 34)
[2025-06-26T19:00:10.143+0700] {subprocess.py:93} INFO - 25/06/26 19:00:10 INFO TaskSetManager: Finished task 21.0 in stage 0.0 (TID 21) in 459 ms on localhost (executor driver) (12/283)
[2025-06-26T19:00:10.143+0700] {subprocess.py:93} INFO - 25/06/26 19:00:10 INFO TaskSetManager: Finished task 10.0 in stage 0.0 (TID 10) in 464 ms on localhost (executor driver) (13/283)
[2025-06-26T19:00:10.144+0700] {subprocess.py:93} INFO - 25/06/26 19:00:10 INFO TaskSetManager: Starting task 36.0 in stage 0.0 (TID 36) (localhost, executor driver, partition 36, PROCESS_LOCAL, 9215 bytes)
[2025-06-26T19:00:10.149+0700] {subprocess.py:93} INFO - 25/06/26 19:00:10 INFO TaskSetManager: Starting task 37.0 in stage 0.0 (TID 37) (localhost, executor driver, partition 37, PROCESS_LOCAL, 9215 bytes)
[2025-06-26T19:00:10.152+0700] {subprocess.py:93} INFO - 25/06/26 19:00:10 INFO Executor: Running task 37.0 in stage 0.0 (TID 37)
[2025-06-26T19:00:10.153+0700] {subprocess.py:93} INFO - 25/06/26 19:00:10 INFO Executor: Running task 36.0 in stage 0.0 (TID 36)
[2025-06-26T19:00:10.156+0700] {subprocess.py:93} INFO - 25/06/26 19:00:10 INFO TaskSetManager: Finished task 20.0 in stage 0.0 (TID 20) in 468 ms on localhost (executor driver) (14/283)
[2025-06-26T19:00:10.157+0700] {subprocess.py:93} INFO - 25/06/26 19:00:10 INFO TaskSetManager: Finished task 14.0 in stage 0.0 (TID 14) in 478 ms on localhost (executor driver) (15/283)
[2025-06-26T19:00:10.158+0700] {subprocess.py:93} INFO - 25/06/26 19:00:10 INFO TaskSetManager: Starting task 38.0 in stage 0.0 (TID 38) (localhost, executor driver, partition 38, PROCESS_LOCAL, 9215 bytes)
[2025-06-26T19:00:10.161+0700] {subprocess.py:93} INFO - 25/06/26 19:00:10 INFO TaskSetManager: Starting task 39.0 in stage 0.0 (TID 39) (localhost, executor driver, partition 39, PROCESS_LOCAL, 9215 bytes)
[2025-06-26T19:00:10.161+0700] {subprocess.py:93} INFO - 25/06/26 19:00:10 INFO Executor: Running task 38.0 in stage 0.0 (TID 38)
[2025-06-26T19:00:10.167+0700] {subprocess.py:93} INFO - 25/06/26 19:00:10 INFO TaskSetManager: Starting task 40.0 in stage 0.0 (TID 40) (localhost, executor driver, partition 40, PROCESS_LOCAL, 9215 bytes)
[2025-06-26T19:00:10.168+0700] {subprocess.py:93} INFO - 25/06/26 19:00:10 INFO Executor: Running task 39.0 in stage 0.0 (TID 39)
[2025-06-26T19:00:10.168+0700] {subprocess.py:93} INFO - 25/06/26 19:00:10 INFO TaskSetManager: Finished task 18.0 in stage 0.0 (TID 18) in 486 ms on localhost (executor driver) (16/283)
[2025-06-26T19:00:10.168+0700] {subprocess.py:93} INFO - 25/06/26 19:00:10 INFO Executor: Running task 40.0 in stage 0.0 (TID 40)
[2025-06-26T19:00:10.172+0700] {subprocess.py:93} INFO - 25/06/26 19:00:10 INFO TaskSetManager: Starting task 41.0 in stage 0.0 (TID 41) (localhost, executor driver, partition 41, PROCESS_LOCAL, 9215 bytes)
[2025-06-26T19:00:10.172+0700] {subprocess.py:93} INFO - 25/06/26 19:00:10 INFO Executor: Finished task 23.0 in stage 0.0 (TID 23). 3218 bytes result sent to driver
[2025-06-26T19:00:10.172+0700] {subprocess.py:93} INFO - 25/06/26 19:00:10 INFO Executor: Running task 41.0 in stage 0.0 (TID 41)
[2025-06-26T19:00:10.172+0700] {subprocess.py:93} INFO - 25/06/26 19:00:10 INFO TaskSetManager: Starting task 42.0 in stage 0.0 (TID 42) (localhost, executor driver, partition 42, PROCESS_LOCAL, 9215 bytes)
[2025-06-26T19:00:10.174+0700] {subprocess.py:93} INFO - 25/06/26 19:00:10 INFO Executor: Running task 42.0 in stage 0.0 (TID 42)
[2025-06-26T19:00:10.174+0700] {subprocess.py:93} INFO - 25/06/26 19:00:10 INFO TaskSetManager: Starting task 43.0 in stage 0.0 (TID 43) (localhost, executor driver, partition 43, PROCESS_LOCAL, 9215 bytes)
[2025-06-26T19:00:10.175+0700] {subprocess.py:93} INFO - 25/06/26 19:00:10 INFO Executor: Running task 43.0 in stage 0.0 (TID 43)
[2025-06-26T19:00:10.186+0700] {subprocess.py:93} INFO - 25/06/26 19:00:10 INFO TaskSetManager: Starting task 44.0 in stage 0.0 (TID 44) (localhost, executor driver, partition 44, PROCESS_LOCAL, 9215 bytes)
[2025-06-26T19:00:10.198+0700] {subprocess.py:93} INFO - 25/06/26 19:00:10 INFO Executor: Finished task 24.0 in stage 0.0 (TID 24). 3218 bytes result sent to driver
[2025-06-26T19:00:10.199+0700] {subprocess.py:93} INFO - 25/06/26 19:00:10 INFO TaskSetManager: Finished task 5.0 in stage 0.0 (TID 5) in 524 ms on localhost (executor driver) (17/283)
[2025-06-26T19:00:10.200+0700] {subprocess.py:93} INFO - 25/06/26 19:00:10 INFO Executor: Running task 44.0 in stage 0.0 (TID 44)
[2025-06-26T19:00:10.200+0700] {subprocess.py:93} INFO - 25/06/26 19:00:10 INFO Executor: Finished task 25.0 in stage 0.0 (TID 25). 3218 bytes result sent to driver
[2025-06-26T19:00:10.205+0700] {subprocess.py:93} INFO - 25/06/26 19:00:10 INFO TaskSetManager: Finished task 2.0 in stage 0.0 (TID 2) in 532 ms on localhost (executor driver) (18/283)
[2025-06-26T19:00:10.205+0700] {subprocess.py:93} INFO - 25/06/26 19:00:10 INFO TaskSetManager: Finished task 16.0 in stage 0.0 (TID 16) in 524 ms on localhost (executor driver) (19/283)
[2025-06-26T19:00:10.205+0700] {subprocess.py:93} INFO - 25/06/26 19:00:10 INFO TaskSetManager: Finished task 0.0 in stage 0.0 (TID 0) in 562 ms on localhost (executor driver) (20/283)
[2025-06-26T19:00:10.205+0700] {subprocess.py:93} INFO - 25/06/26 19:00:10 INFO Executor: Finished task 30.0 in stage 0.0 (TID 30). 3218 bytes result sent to driver
[2025-06-26T19:00:10.206+0700] {subprocess.py:93} INFO - 25/06/26 19:00:10 INFO TaskSetManager: Finished task 22.0 in stage 0.0 (TID 22) in 101 ms on localhost (executor driver) (21/283)
[2025-06-26T19:00:10.212+0700] {subprocess.py:93} INFO - 25/06/26 19:00:10 INFO TaskSetManager: Finished task 15.0 in stage 0.0 (TID 15) in 533 ms on localhost (executor driver) (22/283)
[2025-06-26T19:00:10.213+0700] {subprocess.py:93} INFO - 25/06/26 19:00:10 INFO TaskSetManager: Finished task 1.0 in stage 0.0 (TID 1) in 541 ms on localhost (executor driver) (23/283)
[2025-06-26T19:00:10.214+0700] {subprocess.py:93} INFO - 25/06/26 19:00:10 INFO Executor: Finished task 34.0 in stage 0.0 (TID 34). 3218 bytes result sent to driver
[2025-06-26T19:00:10.215+0700] {subprocess.py:93} INFO - 25/06/26 19:00:10 INFO Executor: Finished task 28.0 in stage 0.0 (TID 28). 3218 bytes result sent to driver
[2025-06-26T19:00:10.224+0700] {subprocess.py:93} INFO - 25/06/26 19:00:10 INFO Executor: Finished task 31.0 in stage 0.0 (TID 31). 3175 bytes result sent to driver
[2025-06-26T19:00:10.225+0700] {subprocess.py:93} INFO - 25/06/26 19:00:10 INFO TaskSetManager: Starting task 45.0 in stage 0.0 (TID 45) (localhost, executor driver, partition 45, PROCESS_LOCAL, 9215 bytes)
[2025-06-26T19:00:10.226+0700] {subprocess.py:93} INFO - 25/06/26 19:00:10 INFO Executor: Finished task 29.0 in stage 0.0 (TID 29). 3175 bytes result sent to driver
[2025-06-26T19:00:10.226+0700] {subprocess.py:93} INFO - 25/06/26 19:00:10 INFO Executor: Running task 45.0 in stage 0.0 (TID 45)
[2025-06-26T19:00:10.227+0700] {subprocess.py:93} INFO - 25/06/26 19:00:10 INFO TaskSetManager: Starting task 46.0 in stage 0.0 (TID 46) (localhost, executor driver, partition 46, PROCESS_LOCAL, 9215 bytes)
[2025-06-26T19:00:10.227+0700] {subprocess.py:93} INFO - 25/06/26 19:00:10 INFO Executor: Finished task 26.0 in stage 0.0 (TID 26). 3218 bytes result sent to driver
[2025-06-26T19:00:10.233+0700] {subprocess.py:93} INFO - 25/06/26 19:00:10 INFO TaskSetManager: Starting task 47.0 in stage 0.0 (TID 47) (localhost, executor driver, partition 47, PROCESS_LOCAL, 9215 bytes)
[2025-06-26T19:00:10.234+0700] {subprocess.py:93} INFO - 25/06/26 19:00:10 INFO Executor: Finished task 35.0 in stage 0.0 (TID 35). 3175 bytes result sent to driver
[2025-06-26T19:00:10.234+0700] {subprocess.py:93} INFO - 25/06/26 19:00:10 INFO Executor: Running task 46.0 in stage 0.0 (TID 46)
[2025-06-26T19:00:10.235+0700] {subprocess.py:93} INFO - 25/06/26 19:00:10 INFO Executor: Finished task 37.0 in stage 0.0 (TID 37). 3218 bytes result sent to driver
[2025-06-26T19:00:10.236+0700] {subprocess.py:93} INFO - 25/06/26 19:00:10 INFO TaskSetManager: Starting task 48.0 in stage 0.0 (TID 48) (localhost, executor driver, partition 48, PROCESS_LOCAL, 9215 bytes)
[2025-06-26T19:00:10.236+0700] {subprocess.py:93} INFO - 25/06/26 19:00:10 INFO Executor: Running task 48.0 in stage 0.0 (TID 48)
[2025-06-26T19:00:10.237+0700] {subprocess.py:93} INFO - 25/06/26 19:00:10 INFO TaskSetManager: Starting task 49.0 in stage 0.0 (TID 49) (localhost, executor driver, partition 49, PROCESS_LOCAL, 9215 bytes)
[2025-06-26T19:00:10.238+0700] {subprocess.py:93} INFO - 25/06/26 19:00:10 INFO Executor: Running task 47.0 in stage 0.0 (TID 47)
[2025-06-26T19:00:10.247+0700] {subprocess.py:93} INFO - 25/06/26 19:00:10 INFO Executor: Running task 49.0 in stage 0.0 (TID 49)
[2025-06-26T19:00:10.247+0700] {subprocess.py:93} INFO - 25/06/26 19:00:10 INFO TaskSetManager: Finished task 25.0 in stage 0.0 (TID 25) in 130 ms on localhost (executor driver) (24/283)
[2025-06-26T19:00:10.248+0700] {subprocess.py:93} INFO - 25/06/26 19:00:10 INFO TaskSetManager: Finished task 30.0 in stage 0.0 (TID 30) in 120 ms on localhost (executor driver) (25/283)
[2025-06-26T19:00:10.252+0700] {subprocess.py:93} INFO - 25/06/26 19:00:10 INFO TaskSetManager: Finished task 23.0 in stage 0.0 (TID 23) in 145 ms on localhost (executor driver) (26/283)
[2025-06-26T19:00:10.270+0700] {subprocess.py:93} INFO - 25/06/26 19:00:10 INFO Executor: Finished task 27.0 in stage 0.0 (TID 27). 3218 bytes result sent to driver
[2025-06-26T19:00:10.272+0700] {subprocess.py:93} INFO - 25/06/26 19:00:10 INFO TaskSetManager: Finished task 34.0 in stage 0.0 (TID 34) in 114 ms on localhost (executor driver) (27/283)
[2025-06-26T19:00:10.273+0700] {subprocess.py:93} INFO - 25/06/26 19:00:10 INFO TaskSetManager: Finished task 24.0 in stage 0.0 (TID 24) in 165 ms on localhost (executor driver) (28/283)
[2025-06-26T19:00:10.274+0700] {subprocess.py:93} INFO - 25/06/26 19:00:10 INFO Executor: Finished task 32.0 in stage 0.0 (TID 32). 3261 bytes result sent to driver
[2025-06-26T19:00:10.274+0700] {subprocess.py:93} INFO - 25/06/26 19:00:10 INFO Executor: Finished task 39.0 in stage 0.0 (TID 39). 3261 bytes result sent to driver
[2025-06-26T19:00:10.275+0700] {subprocess.py:93} INFO - 25/06/26 19:00:10 INFO TaskSetManager: Starting task 50.0 in stage 0.0 (TID 50) (localhost, executor driver, partition 50, PROCESS_LOCAL, 9215 bytes)
[2025-06-26T19:00:10.275+0700] {subprocess.py:93} INFO - 25/06/26 19:00:10 INFO Executor: Finished task 36.0 in stage 0.0 (TID 36). 3218 bytes result sent to driver
[2025-06-26T19:00:10.284+0700] {subprocess.py:93} INFO - 25/06/26 19:00:10 INFO Executor: Running task 50.0 in stage 0.0 (TID 50)
[2025-06-26T19:00:10.285+0700] {subprocess.py:93} INFO - 25/06/26 19:00:10 INFO TaskSetManager: Starting task 51.0 in stage 0.0 (TID 51) (localhost, executor driver, partition 51, PROCESS_LOCAL, 9215 bytes)
[2025-06-26T19:00:10.287+0700] {subprocess.py:93} INFO - 25/06/26 19:00:10 INFO TaskSetManager: Finished task 28.0 in stage 0.0 (TID 28) in 163 ms on localhost (executor driver) (29/283)
[2025-06-26T19:00:10.287+0700] {subprocess.py:93} INFO - 25/06/26 19:00:10 INFO Executor: Finished task 41.0 in stage 0.0 (TID 41). 3218 bytes result sent to driver
[2025-06-26T19:00:10.287+0700] {subprocess.py:93} INFO - 25/06/26 19:00:10 INFO Executor: Running task 51.0 in stage 0.0 (TID 51)
[2025-06-26T19:00:10.287+0700] {subprocess.py:93} INFO - 25/06/26 19:00:10 INFO Executor: Finished task 33.0 in stage 0.0 (TID 33). 3261 bytes result sent to driver
[2025-06-26T19:00:10.288+0700] {subprocess.py:93} INFO - 25/06/26 19:00:10 INFO Executor: Finished task 38.0 in stage 0.0 (TID 38). 3218 bytes result sent to driver
[2025-06-26T19:00:10.294+0700] {subprocess.py:93} INFO - 25/06/26 19:00:10 INFO Executor: Finished task 42.0 in stage 0.0 (TID 42). 3218 bytes result sent to driver
[2025-06-26T19:00:10.297+0700] {subprocess.py:93} INFO - 25/06/26 19:00:10 INFO TaskSetManager: Starting task 52.0 in stage 0.0 (TID 52) (localhost, executor driver, partition 52, PROCESS_LOCAL, 9215 bytes)
[2025-06-26T19:00:10.297+0700] {subprocess.py:93} INFO - 25/06/26 19:00:10 INFO TaskSetManager: Finished task 31.0 in stage 0.0 (TID 31) in 168 ms on localhost (executor driver) (30/283)
[2025-06-26T19:00:10.297+0700] {subprocess.py:93} INFO - 25/06/26 19:00:10 INFO Executor: Running task 52.0 in stage 0.0 (TID 52)
[2025-06-26T19:00:10.297+0700] {subprocess.py:93} INFO - 25/06/26 19:00:10 INFO TaskSetManager: Finished task 29.0 in stage 0.0 (TID 29) in 171 ms on localhost (executor driver) (31/283)
[2025-06-26T19:00:10.298+0700] {subprocess.py:93} INFO - 25/06/26 19:00:10 INFO Executor: Finished task 43.0 in stage 0.0 (TID 43). 3218 bytes result sent to driver
[2025-06-26T19:00:10.298+0700] {subprocess.py:93} INFO - 25/06/26 19:00:10 INFO Executor: Finished task 40.0 in stage 0.0 (TID 40). 3218 bytes result sent to driver
[2025-06-26T19:00:10.298+0700] {subprocess.py:93} INFO - 25/06/26 19:00:10 INFO Executor: Finished task 44.0 in stage 0.0 (TID 44). 3218 bytes result sent to driver
[2025-06-26T19:00:10.299+0700] {subprocess.py:93} INFO - 25/06/26 19:00:10 INFO TaskSetManager: Starting task 53.0 in stage 0.0 (TID 53) (localhost, executor driver, partition 53, PROCESS_LOCAL, 9215 bytes)
[2025-06-26T19:00:10.301+0700] {subprocess.py:93} INFO - 25/06/26 19:00:10 INFO TaskSetManager: Starting task 54.0 in stage 0.0 (TID 54) (localhost, executor driver, partition 54, PROCESS_LOCAL, 9215 bytes)
[2025-06-26T19:00:10.301+0700] {subprocess.py:93} INFO - 25/06/26 19:00:10 INFO Executor: Running task 54.0 in stage 0.0 (TID 54)
[2025-06-26T19:00:10.302+0700] {subprocess.py:93} INFO - 25/06/26 19:00:10 INFO TaskSetManager: Starting task 55.0 in stage 0.0 (TID 55) (localhost, executor driver, partition 55, PROCESS_LOCAL, 9215 bytes)
[2025-06-26T19:00:10.302+0700] {subprocess.py:93} INFO - 25/06/26 19:00:10 INFO Executor: Running task 53.0 in stage 0.0 (TID 53)
[2025-06-26T19:00:10.302+0700] {subprocess.py:93} INFO - 25/06/26 19:00:10 INFO Executor: Running task 55.0 in stage 0.0 (TID 55)
[2025-06-26T19:00:10.306+0700] {subprocess.py:93} INFO - 25/06/26 19:00:10 INFO TaskSetManager: Starting task 56.0 in stage 0.0 (TID 56) (localhost, executor driver, partition 56, PROCESS_LOCAL, 9215 bytes)
[2025-06-26T19:00:10.306+0700] {subprocess.py:93} INFO - 25/06/26 19:00:10 INFO TaskSetManager: Finished task 26.0 in stage 0.0 (TID 26) in 194 ms on localhost (executor driver) (32/283)
[2025-06-26T19:00:10.307+0700] {subprocess.py:93} INFO - 25/06/26 19:00:10 INFO TaskSetManager: Finished task 35.0 in stage 0.0 (TID 35) in 168 ms on localhost (executor driver) (33/283)
[2025-06-26T19:00:10.326+0700] {subprocess.py:93} INFO - 25/06/26 19:00:10 INFO Executor: Running task 56.0 in stage 0.0 (TID 56)
[2025-06-26T19:00:10.327+0700] {subprocess.py:93} INFO - 25/06/26 19:00:10 INFO TaskSetManager: Finished task 37.0 in stage 0.0 (TID 37) in 180 ms on localhost (executor driver) (34/283)
[2025-06-26T19:00:10.328+0700] {subprocess.py:93} INFO - 25/06/26 19:00:10 INFO Executor: Finished task 47.0 in stage 0.0 (TID 47). 3218 bytes result sent to driver
[2025-06-26T19:00:10.328+0700] {subprocess.py:93} INFO - 25/06/26 19:00:10 INFO Executor: Finished task 48.0 in stage 0.0 (TID 48). 3218 bytes result sent to driver
[2025-06-26T19:00:10.328+0700] {subprocess.py:93} INFO - 25/06/26 19:00:10 INFO Executor: Finished task 46.0 in stage 0.0 (TID 46). 3261 bytes result sent to driver
[2025-06-26T19:00:10.328+0700] {subprocess.py:93} INFO - 25/06/26 19:00:10 INFO TaskSetManager: Starting task 57.0 in stage 0.0 (TID 57) (localhost, executor driver, partition 57, PROCESS_LOCAL, 9215 bytes)
[2025-06-26T19:00:10.329+0700] {subprocess.py:93} INFO - 25/06/26 19:00:10 INFO Executor: Finished task 49.0 in stage 0.0 (TID 49). 3261 bytes result sent to driver
[2025-06-26T19:00:10.331+0700] {subprocess.py:93} INFO - 25/06/26 19:00:10 INFO TaskSetManager: Finished task 27.0 in stage 0.0 (TID 27) in 207 ms on localhost (executor driver) (35/283)
[2025-06-26T19:00:10.332+0700] {subprocess.py:93} INFO - 25/06/26 19:00:10 INFO Executor: Finished task 45.0 in stage 0.0 (TID 45). 3218 bytes result sent to driver
[2025-06-26T19:00:10.333+0700] {subprocess.py:93} INFO - 25/06/26 19:00:10 INFO TaskSetManager: Starting task 58.0 in stage 0.0 (TID 58) (localhost, executor driver, partition 58, PROCESS_LOCAL, 9215 bytes)
[2025-06-26T19:00:10.333+0700] {subprocess.py:93} INFO - 25/06/26 19:00:10 INFO TaskSetManager: Finished task 32.0 in stage 0.0 (TID 32) in 200 ms on localhost (executor driver) (36/283)
[2025-06-26T19:00:10.333+0700] {subprocess.py:93} INFO - 25/06/26 19:00:10 INFO Executor: Running task 58.0 in stage 0.0 (TID 58)
[2025-06-26T19:00:10.333+0700] {subprocess.py:93} INFO - 25/06/26 19:00:10 INFO Executor: Running task 57.0 in stage 0.0 (TID 57)
[2025-06-26T19:00:10.337+0700] {subprocess.py:93} INFO - 25/06/26 19:00:10 INFO TaskSetManager: Starting task 59.0 in stage 0.0 (TID 59) (localhost, executor driver, partition 59, PROCESS_LOCAL, 9215 bytes)
[2025-06-26T19:00:10.338+0700] {subprocess.py:93} INFO - 25/06/26 19:00:10 INFO Executor: Finished task 51.0 in stage 0.0 (TID 51). 3175 bytes result sent to driver
[2025-06-26T19:00:10.338+0700] {subprocess.py:93} INFO - 25/06/26 19:00:10 INFO Executor: Finished task 52.0 in stage 0.0 (TID 52). 3175 bytes result sent to driver
[2025-06-26T19:00:10.338+0700] {subprocess.py:93} INFO - 25/06/26 19:00:10 INFO Executor: Finished task 50.0 in stage 0.0 (TID 50). 3175 bytes result sent to driver
[2025-06-26T19:00:10.338+0700] {subprocess.py:93} INFO - 25/06/26 19:00:10 INFO TaskSetManager: Starting task 60.0 in stage 0.0 (TID 60) (localhost, executor driver, partition 60, PROCESS_LOCAL, 9215 bytes)
[2025-06-26T19:00:10.338+0700] {subprocess.py:93} INFO - 25/06/26 19:00:10 INFO TaskSetManager: Finished task 39.0 in stage 0.0 (TID 39) in 178 ms on localhost (executor driver) (37/283)
[2025-06-26T19:00:10.342+0700] {subprocess.py:93} INFO - 25/06/26 19:00:10 INFO Executor: Running task 59.0 in stage 0.0 (TID 59)
[2025-06-26T19:00:10.342+0700] {subprocess.py:93} INFO - 25/06/26 19:00:10 INFO TaskSetManager: Finished task 36.0 in stage 0.0 (TID 36) in 198 ms on localhost (executor driver) (38/283)
[2025-06-26T19:00:10.342+0700] {subprocess.py:93} INFO - 25/06/26 19:00:10 INFO Executor: Running task 60.0 in stage 0.0 (TID 60)
[2025-06-26T19:00:10.343+0700] {subprocess.py:93} INFO - 25/06/26 19:00:10 INFO TaskSetManager: Starting task 61.0 in stage 0.0 (TID 61) (localhost, executor driver, partition 61, PROCESS_LOCAL, 9215 bytes)
[2025-06-26T19:00:10.343+0700] {subprocess.py:93} INFO - 25/06/26 19:00:10 INFO TaskSetManager: Finished task 41.0 in stage 0.0 (TID 41) in 174 ms on localhost (executor driver) (39/283)
[2025-06-26T19:00:10.344+0700] {subprocess.py:93} INFO - 25/06/26 19:00:10 INFO TaskSetManager: Finished task 38.0 in stage 0.0 (TID 38) in 186 ms on localhost (executor driver) (40/283)
[2025-06-26T19:00:10.344+0700] {subprocess.py:93} INFO - 25/06/26 19:00:10 INFO Executor: Finished task 54.0 in stage 0.0 (TID 54). 3218 bytes result sent to driver
[2025-06-26T19:00:10.344+0700] {subprocess.py:93} INFO - 25/06/26 19:00:10 INFO Executor: Running task 61.0 in stage 0.0 (TID 61)
[2025-06-26T19:00:10.345+0700] {subprocess.py:93} INFO - 25/06/26 19:00:10 INFO TaskSetManager: Starting task 62.0 in stage 0.0 (TID 62) (localhost, executor driver, partition 62, PROCESS_LOCAL, 9215 bytes)
[2025-06-26T19:00:10.346+0700] {subprocess.py:93} INFO - 25/06/26 19:00:10 INFO Executor: Running task 62.0 in stage 0.0 (TID 62)
[2025-06-26T19:00:10.346+0700] {subprocess.py:93} INFO - 25/06/26 19:00:10 INFO TaskSetManager: Starting task 63.0 in stage 0.0 (TID 63) (localhost, executor driver, partition 63, PROCESS_LOCAL, 9215 bytes)
[2025-06-26T19:00:10.346+0700] {subprocess.py:93} INFO - 25/06/26 19:00:10 INFO Executor: Finished task 55.0 in stage 0.0 (TID 55). 3175 bytes result sent to driver
[2025-06-26T19:00:10.347+0700] {subprocess.py:93} INFO - 25/06/26 19:00:10 INFO Executor: Running task 63.0 in stage 0.0 (TID 63)
[2025-06-26T19:00:10.347+0700] {subprocess.py:93} INFO - 25/06/26 19:00:10 INFO TaskSetManager: Starting task 64.0 in stage 0.0 (TID 64) (localhost, executor driver, partition 64, PROCESS_LOCAL, 9215 bytes)
[2025-06-26T19:00:10.348+0700] {subprocess.py:93} INFO - 25/06/26 19:00:10 INFO TaskSetManager: Finished task 33.0 in stage 0.0 (TID 33) in 211 ms on localhost (executor driver) (41/283)
[2025-06-26T19:00:10.349+0700] {subprocess.py:93} INFO - 25/06/26 19:00:10 INFO Executor: Running task 64.0 in stage 0.0 (TID 64)
[2025-06-26T19:00:10.349+0700] {subprocess.py:93} INFO - 25/06/26 19:00:10 INFO TaskSetManager: Finished task 42.0 in stage 0.0 (TID 42) in 178 ms on localhost (executor driver) (42/283)
[2025-06-26T19:00:10.352+0700] {subprocess.py:93} INFO - 25/06/26 19:00:10 INFO Executor: Finished task 53.0 in stage 0.0 (TID 53). 3175 bytes result sent to driver
[2025-06-26T19:00:10.353+0700] {subprocess.py:93} INFO - 25/06/26 19:00:10 INFO Executor: Finished task 56.0 in stage 0.0 (TID 56). 3175 bytes result sent to driver
[2025-06-26T19:00:10.353+0700] {subprocess.py:93} INFO - 25/06/26 19:00:10 INFO TaskSetManager: Starting task 65.0 in stage 0.0 (TID 65) (localhost, executor driver, partition 65, PROCESS_LOCAL, 9215 bytes)
[2025-06-26T19:00:10.354+0700] {subprocess.py:93} INFO - 25/06/26 19:00:10 INFO TaskSetManager: Finished task 40.0 in stage 0.0 (TID 40) in 193 ms on localhost (executor driver) (43/283)
[2025-06-26T19:00:10.354+0700] {subprocess.py:93} INFO - 25/06/26 19:00:10 INFO TaskSetManager: Finished task 43.0 in stage 0.0 (TID 43) in 181 ms on localhost (executor driver) (44/283)
[2025-06-26T19:00:10.354+0700] {subprocess.py:93} INFO - 25/06/26 19:00:10 INFO Executor: Finished task 60.0 in stage 0.0 (TID 60). 3175 bytes result sent to driver
[2025-06-26T19:00:10.354+0700] {subprocess.py:93} INFO - 25/06/26 19:00:10 INFO Executor: Finished task 57.0 in stage 0.0 (TID 57). 3175 bytes result sent to driver
[2025-06-26T19:00:10.355+0700] {subprocess.py:93} INFO - 25/06/26 19:00:10 INFO Executor: Running task 65.0 in stage 0.0 (TID 65)
[2025-06-26T19:00:10.355+0700] {subprocess.py:93} INFO - 25/06/26 19:00:10 INFO TaskSetManager: Starting task 66.0 in stage 0.0 (TID 66) (localhost, executor driver, partition 66, PROCESS_LOCAL, 9215 bytes)
[2025-06-26T19:00:10.356+0700] {subprocess.py:93} INFO - 25/06/26 19:00:10 INFO Executor: Running task 66.0 in stage 0.0 (TID 66)
[2025-06-26T19:00:10.357+0700] {subprocess.py:93} INFO - 25/06/26 19:00:10 INFO TaskSetManager: Starting task 67.0 in stage 0.0 (TID 67) (localhost, executor driver, partition 67, PROCESS_LOCAL, 9215 bytes)
[2025-06-26T19:00:10.357+0700] {subprocess.py:93} INFO - 25/06/26 19:00:10 INFO TaskSetManager: Finished task 44.0 in stage 0.0 (TID 44) in 182 ms on localhost (executor driver) (45/283)
[2025-06-26T19:00:10.357+0700] {subprocess.py:93} INFO - 25/06/26 19:00:10 INFO Executor: Running task 67.0 in stage 0.0 (TID 67)
[2025-06-26T19:00:10.358+0700] {subprocess.py:93} INFO - 25/06/26 19:00:10 INFO Executor: Finished task 59.0 in stage 0.0 (TID 59). 3175 bytes result sent to driver
[2025-06-26T19:00:10.358+0700] {subprocess.py:93} INFO - 25/06/26 19:00:10 INFO TaskSetManager: Starting task 68.0 in stage 0.0 (TID 68) (localhost, executor driver, partition 68, PROCESS_LOCAL, 9215 bytes)
[2025-06-26T19:00:10.358+0700] {subprocess.py:93} INFO - 25/06/26 19:00:10 INFO Executor: Finished task 64.0 in stage 0.0 (TID 64). 3175 bytes result sent to driver
[2025-06-26T19:00:10.358+0700] {subprocess.py:93} INFO - 25/06/26 19:00:10 INFO Executor: Finished task 63.0 in stage 0.0 (TID 63). 3175 bytes result sent to driver
[2025-06-26T19:00:10.358+0700] {subprocess.py:93} INFO - 25/06/26 19:00:10 INFO Executor: Finished task 61.0 in stage 0.0 (TID 61). 3175 bytes result sent to driver
[2025-06-26T19:00:10.359+0700] {subprocess.py:93} INFO - 25/06/26 19:00:10 INFO Executor: Running task 68.0 in stage 0.0 (TID 68)
[2025-06-26T19:00:10.359+0700] {subprocess.py:93} INFO - 25/06/26 19:00:10 INFO TaskSetManager: Starting task 69.0 in stage 0.0 (TID 69) (localhost, executor driver, partition 69, PROCESS_LOCAL, 9215 bytes)
[2025-06-26T19:00:10.359+0700] {subprocess.py:93} INFO - 25/06/26 19:00:10 INFO Executor: Finished task 58.0 in stage 0.0 (TID 58). 3175 bytes result sent to driver
[2025-06-26T19:00:10.360+0700] {subprocess.py:93} INFO - 25/06/26 19:00:10 INFO TaskSetManager: Finished task 48.0 in stage 0.0 (TID 48) in 125 ms on localhost (executor driver) (46/283)
[2025-06-26T19:00:10.360+0700] {subprocess.py:93} INFO - 25/06/26 19:00:10 INFO Executor: Running task 69.0 in stage 0.0 (TID 69)
[2025-06-26T19:00:10.360+0700] {subprocess.py:93} INFO - 25/06/26 19:00:10 INFO TaskSetManager: Finished task 47.0 in stage 0.0 (TID 47) in 133 ms on localhost (executor driver) (47/283)
[2025-06-26T19:00:10.361+0700] {subprocess.py:93} INFO - 25/06/26 19:00:10 INFO TaskSetManager: Starting task 70.0 in stage 0.0 (TID 70) (localhost, executor driver, partition 70, PROCESS_LOCAL, 9215 bytes)
[2025-06-26T19:00:10.361+0700] {subprocess.py:93} INFO - 25/06/26 19:00:10 INFO Executor: Finished task 62.0 in stage 0.0 (TID 62). 3175 bytes result sent to driver
[2025-06-26T19:00:10.361+0700] {subprocess.py:93} INFO - 25/06/26 19:00:10 INFO Executor: Running task 70.0 in stage 0.0 (TID 70)
[2025-06-26T19:00:10.362+0700] {subprocess.py:93} INFO - 25/06/26 19:00:10 INFO TaskSetManager: Finished task 46.0 in stage 0.0 (TID 46) in 135 ms on localhost (executor driver) (48/283)
[2025-06-26T19:00:10.364+0700] {subprocess.py:93} INFO - 25/06/26 19:00:10 INFO TaskSetManager: Starting task 71.0 in stage 0.0 (TID 71) (localhost, executor driver, partition 71, PROCESS_LOCAL, 9215 bytes)
[2025-06-26T19:00:10.365+0700] {subprocess.py:93} INFO - 25/06/26 19:00:10 INFO TaskSetManager: Finished task 49.0 in stage 0.0 (TID 49) in 128 ms on localhost (executor driver) (49/283)
[2025-06-26T19:00:10.365+0700] {subprocess.py:93} INFO - 25/06/26 19:00:10 INFO TaskSetManager: Finished task 45.0 in stage 0.0 (TID 45) in 143 ms on localhost (executor driver) (50/283)
[2025-06-26T19:00:10.365+0700] {subprocess.py:93} INFO - 25/06/26 19:00:10 INFO Executor: Running task 71.0 in stage 0.0 (TID 71)
[2025-06-26T19:00:10.367+0700] {subprocess.py:93} INFO - 25/06/26 19:00:10 INFO TaskSetManager: Starting task 72.0 in stage 0.0 (TID 72) (localhost, executor driver, partition 72, PROCESS_LOCAL, 9215 bytes)
[2025-06-26T19:00:10.368+0700] {subprocess.py:93} INFO - 25/06/26 19:00:10 INFO Executor: Running task 72.0 in stage 0.0 (TID 72)
[2025-06-26T19:00:10.368+0700] {subprocess.py:93} INFO - 25/06/26 19:00:10 INFO Executor: Finished task 67.0 in stage 0.0 (TID 67). 3175 bytes result sent to driver
[2025-06-26T19:00:10.369+0700] {subprocess.py:93} INFO - 25/06/26 19:00:10 INFO TaskSetManager: Starting task 73.0 in stage 0.0 (TID 73) (localhost, executor driver, partition 73, PROCESS_LOCAL, 9215 bytes)
[2025-06-26T19:00:10.369+0700] {subprocess.py:93} INFO - 25/06/26 19:00:10 INFO TaskSetManager: Finished task 51.0 in stage 0.0 (TID 51) in 85 ms on localhost (executor driver) (51/283)
[2025-06-26T19:00:10.369+0700] {subprocess.py:93} INFO - 25/06/26 19:00:10 INFO Executor: Running task 73.0 in stage 0.0 (TID 73)
[2025-06-26T19:00:10.370+0700] {subprocess.py:93} INFO - 25/06/26 19:00:10 INFO TaskSetManager: Starting task 74.0 in stage 0.0 (TID 74) (localhost, executor driver, partition 74, PROCESS_LOCAL, 9215 bytes)
[2025-06-26T19:00:10.370+0700] {subprocess.py:93} INFO - 25/06/26 19:00:10 INFO Executor: Finished task 68.0 in stage 0.0 (TID 68). 3175 bytes result sent to driver
[2025-06-26T19:00:10.372+0700] {subprocess.py:93} INFO - 25/06/26 19:00:10 INFO Executor: Finished task 65.0 in stage 0.0 (TID 65). 3175 bytes result sent to driver
[2025-06-26T19:00:10.380+0700] {subprocess.py:93} INFO - 25/06/26 19:00:10 INFO TaskSetManager: Starting task 75.0 in stage 0.0 (TID 75) (localhost, executor driver, partition 75, PROCESS_LOCAL, 9215 bytes)
[2025-06-26T19:00:10.381+0700] {subprocess.py:93} INFO - 25/06/26 19:00:10 INFO Executor: Finished task 66.0 in stage 0.0 (TID 66). 3218 bytes result sent to driver
[2025-06-26T19:00:10.381+0700] {subprocess.py:93} INFO - 25/06/26 19:00:10 INFO Executor: Running task 74.0 in stage 0.0 (TID 74)
[2025-06-26T19:00:10.382+0700] {subprocess.py:93} INFO - 25/06/26 19:00:10 INFO TaskSetManager: Finished task 52.0 in stage 0.0 (TID 52) in 86 ms on localhost (executor driver) (52/283)
[2025-06-26T19:00:10.382+0700] {subprocess.py:93} INFO - 25/06/26 19:00:10 INFO Executor: Running task 75.0 in stage 0.0 (TID 75)
[2025-06-26T19:00:10.382+0700] {subprocess.py:93} INFO - 25/06/26 19:00:10 INFO Executor: Finished task 70.0 in stage 0.0 (TID 70). 3218 bytes result sent to driver
[2025-06-26T19:00:10.382+0700] {subprocess.py:93} INFO - 25/06/26 19:00:10 INFO Executor: Finished task 69.0 in stage 0.0 (TID 69). 3261 bytes result sent to driver
[2025-06-26T19:00:10.382+0700] {subprocess.py:93} INFO - 25/06/26 19:00:10 INFO TaskSetManager: Starting task 76.0 in stage 0.0 (TID 76) (localhost, executor driver, partition 76, PROCESS_LOCAL, 9215 bytes)
[2025-06-26T19:00:10.383+0700] {subprocess.py:93} INFO - 25/06/26 19:00:10 INFO Executor: Running task 76.0 in stage 0.0 (TID 76)
[2025-06-26T19:00:10.384+0700] {subprocess.py:93} INFO - 25/06/26 19:00:10 INFO TaskSetManager: Finished task 50.0 in stage 0.0 (TID 50) in 110 ms on localhost (executor driver) (53/283)
[2025-06-26T19:00:10.385+0700] {subprocess.py:93} INFO - 25/06/26 19:00:10 INFO TaskSetManager: Starting task 77.0 in stage 0.0 (TID 77) (localhost, executor driver, partition 77, PROCESS_LOCAL, 9215 bytes)
[2025-06-26T19:00:10.387+0700] {subprocess.py:93} INFO - 25/06/26 19:00:10 INFO Executor: Running task 77.0 in stage 0.0 (TID 77)
[2025-06-26T19:00:10.387+0700] {subprocess.py:93} INFO - 25/06/26 19:00:10 INFO TaskSetManager: Starting task 78.0 in stage 0.0 (TID 78) (localhost, executor driver, partition 78, PROCESS_LOCAL, 9215 bytes)
[2025-06-26T19:00:10.388+0700] {subprocess.py:93} INFO - 25/06/26 19:00:10 INFO Executor: Running task 78.0 in stage 0.0 (TID 78)
[2025-06-26T19:00:10.388+0700] {subprocess.py:93} INFO - 25/06/26 19:00:10 INFO TaskSetManager: Starting task 79.0 in stage 0.0 (TID 79) (localhost, executor driver, partition 79, PROCESS_LOCAL, 9215 bytes)
[2025-06-26T19:00:10.389+0700] {subprocess.py:93} INFO - 25/06/26 19:00:10 INFO TaskSetManager: Starting task 80.0 in stage 0.0 (TID 80) (localhost, executor driver, partition 80, PROCESS_LOCAL, 9215 bytes)
[2025-06-26T19:00:10.390+0700] {subprocess.py:93} INFO - 25/06/26 19:00:10 INFO Executor: Running task 79.0 in stage 0.0 (TID 79)
[2025-06-26T19:00:10.390+0700] {subprocess.py:93} INFO - 25/06/26 19:00:10 INFO Executor: Running task 80.0 in stage 0.0 (TID 80)
[2025-06-26T19:00:10.390+0700] {subprocess.py:93} INFO - 25/06/26 19:00:10 INFO TaskSetManager: Finished task 55.0 in stage 0.0 (TID 55) in 90 ms on localhost (executor driver) (54/283)
[2025-06-26T19:00:10.390+0700] {subprocess.py:93} INFO - 25/06/26 19:00:10 INFO Executor: Finished task 72.0 in stage 0.0 (TID 72). 3218 bytes result sent to driver
[2025-06-26T19:00:10.390+0700] {subprocess.py:93} INFO - 25/06/26 19:00:10 INFO Executor: Finished task 71.0 in stage 0.0 (TID 71). 3218 bytes result sent to driver
[2025-06-26T19:00:10.391+0700] {subprocess.py:93} INFO - 25/06/26 19:00:10 INFO TaskSetManager: Finished task 60.0 in stage 0.0 (TID 60) in 54 ms on localhost (executor driver) (55/283)
[2025-06-26T19:00:10.392+0700] {subprocess.py:93} INFO - 25/06/26 19:00:10 INFO TaskSetManager: Finished task 57.0 in stage 0.0 (TID 57) in 64 ms on localhost (executor driver) (56/283)
[2025-06-26T19:00:10.392+0700] {subprocess.py:93} INFO - 25/06/26 19:00:10 INFO TaskSetManager: Finished task 53.0 in stage 0.0 (TID 53) in 94 ms on localhost (executor driver) (57/283)
[2025-06-26T19:00:10.393+0700] {subprocess.py:93} INFO - 25/06/26 19:00:10 INFO TaskSetManager: Finished task 56.0 in stage 0.0 (TID 56) in 91 ms on localhost (executor driver) (58/283)
[2025-06-26T19:00:10.393+0700] {subprocess.py:93} INFO - 25/06/26 19:00:10 INFO TaskSetManager: Finished task 54.0 in stage 0.0 (TID 54) in 93 ms on localhost (executor driver) (59/283)
[2025-06-26T19:00:10.393+0700] {subprocess.py:93} INFO - 25/06/26 19:00:10 INFO TaskSetManager: Starting task 81.0 in stage 0.0 (TID 81) (localhost, executor driver, partition 81, PROCESS_LOCAL, 9215 bytes)
[2025-06-26T19:00:10.395+0700] {subprocess.py:93} INFO - 25/06/26 19:00:10 INFO TaskSetManager: Starting task 82.0 in stage 0.0 (TID 82) (localhost, executor driver, partition 82, PROCESS_LOCAL, 9215 bytes)
[2025-06-26T19:00:10.396+0700] {subprocess.py:93} INFO - 25/06/26 19:00:10 INFO TaskSetManager: Starting task 83.0 in stage 0.0 (TID 83) (localhost, executor driver, partition 83, PROCESS_LOCAL, 9215 bytes)
[2025-06-26T19:00:10.397+0700] {subprocess.py:93} INFO - 25/06/26 19:00:10 INFO Executor: Running task 82.0 in stage 0.0 (TID 82)
[2025-06-26T19:00:10.397+0700] {subprocess.py:93} INFO - 25/06/26 19:00:10 INFO Executor: Running task 81.0 in stage 0.0 (TID 81)
[2025-06-26T19:00:10.397+0700] {subprocess.py:93} INFO - 25/06/26 19:00:10 INFO Executor: Finished task 75.0 in stage 0.0 (TID 75). 3175 bytes result sent to driver
[2025-06-26T19:00:10.397+0700] {subprocess.py:93} INFO - 25/06/26 19:00:10 INFO Executor: Finished task 74.0 in stage 0.0 (TID 74). 3175 bytes result sent to driver
[2025-06-26T19:00:10.398+0700] {subprocess.py:93} INFO - 25/06/26 19:00:10 INFO Executor: Finished task 77.0 in stage 0.0 (TID 77). 3175 bytes result sent to driver
[2025-06-26T19:00:10.399+0700] {subprocess.py:93} INFO - 25/06/26 19:00:10 INFO TaskSetManager: Starting task 84.0 in stage 0.0 (TID 84) (localhost, executor driver, partition 84, PROCESS_LOCAL, 9215 bytes)
[2025-06-26T19:00:10.400+0700] {subprocess.py:93} INFO - 25/06/26 19:00:10 INFO Executor: Running task 83.0 in stage 0.0 (TID 83)
[2025-06-26T19:00:10.400+0700] {subprocess.py:93} INFO - 25/06/26 19:00:10 INFO Executor: Finished task 76.0 in stage 0.0 (TID 76). 3218 bytes result sent to driver
[2025-06-26T19:00:10.403+0700] {subprocess.py:93} INFO - 25/06/26 19:00:10 INFO Executor: Finished task 80.0 in stage 0.0 (TID 80). 3175 bytes result sent to driver
[2025-06-26T19:00:10.404+0700] {subprocess.py:93} INFO - 25/06/26 19:00:10 INFO Executor: Finished task 78.0 in stage 0.0 (TID 78). 3175 bytes result sent to driver
[2025-06-26T19:00:10.405+0700] {subprocess.py:93} INFO - 25/06/26 19:00:10 INFO Executor: Finished task 79.0 in stage 0.0 (TID 79). 3175 bytes result sent to driver
[2025-06-26T19:00:10.405+0700] {subprocess.py:93} INFO - 25/06/26 19:00:10 INFO Executor: Finished task 73.0 in stage 0.0 (TID 73). 3261 bytes result sent to driver
[2025-06-26T19:00:10.406+0700] {subprocess.py:93} INFO - 25/06/26 19:00:10 INFO Executor: Running task 84.0 in stage 0.0 (TID 84)
[2025-06-26T19:00:10.406+0700] {subprocess.py:93} INFO - 25/06/26 19:00:10 INFO TaskSetManager: Finished task 64.0 in stage 0.0 (TID 64) in 59 ms on localhost (executor driver) (60/283)
[2025-06-26T19:00:10.424+0700] {subprocess.py:93} INFO - 25/06/26 19:00:10 INFO TaskSetManager: Finished task 63.0 in stage 0.0 (TID 63) in 77 ms on localhost (executor driver) (61/283)
[2025-06-26T19:00:10.426+0700] {subprocess.py:93} INFO - 25/06/26 19:00:10 INFO Executor: Finished task 82.0 in stage 0.0 (TID 82). 3218 bytes result sent to driver
[2025-06-26T19:00:10.426+0700] {subprocess.py:93} INFO - 25/06/26 19:00:10 INFO TaskSetManager: Starting task 85.0 in stage 0.0 (TID 85) (localhost, executor driver, partition 85, PROCESS_LOCAL, 9215 bytes)
[2025-06-26T19:00:10.426+0700] {subprocess.py:93} INFO - 25/06/26 19:00:10 INFO Executor: Finished task 81.0 in stage 0.0 (TID 81). 3175 bytes result sent to driver
[2025-06-26T19:00:10.426+0700] {subprocess.py:93} INFO - 25/06/26 19:00:10 INFO Executor: Running task 85.0 in stage 0.0 (TID 85)
[2025-06-26T19:00:10.427+0700] {subprocess.py:93} INFO - 25/06/26 19:00:10 INFO TaskSetManager: Finished task 61.0 in stage 0.0 (TID 61) in 84 ms on localhost (executor driver) (62/283)
[2025-06-26T19:00:10.428+0700] {subprocess.py:93} INFO - 25/06/26 19:00:10 INFO TaskSetManager: Finished task 59.0 in stage 0.0 (TID 59) in 93 ms on localhost (executor driver) (63/283)
[2025-06-26T19:00:10.430+0700] {subprocess.py:93} INFO - 25/06/26 19:00:10 INFO TaskSetManager: Starting task 86.0 in stage 0.0 (TID 86) (localhost, executor driver, partition 86, PROCESS_LOCAL, 9215 bytes)
[2025-06-26T19:00:10.431+0700] {subprocess.py:93} INFO - 25/06/26 19:00:10 INFO TaskSetManager: Finished task 58.0 in stage 0.0 (TID 58) in 98 ms on localhost (executor driver) (64/283)
[2025-06-26T19:00:10.431+0700] {subprocess.py:93} INFO - 25/06/26 19:00:10 INFO Executor: Running task 86.0 in stage 0.0 (TID 86)
[2025-06-26T19:00:10.432+0700] {subprocess.py:93} INFO - 25/06/26 19:00:10 INFO TaskSetManager: Finished task 62.0 in stage 0.0 (TID 62) in 87 ms on localhost (executor driver) (65/283)
[2025-06-26T19:00:10.433+0700] {subprocess.py:93} INFO - 25/06/26 19:00:10 INFO TaskSetManager: Starting task 87.0 in stage 0.0 (TID 87) (localhost, executor driver, partition 87, PROCESS_LOCAL, 9215 bytes)
[2025-06-26T19:00:10.435+0700] {subprocess.py:93} INFO - 25/06/26 19:00:10 INFO Executor: Running task 87.0 in stage 0.0 (TID 87)
[2025-06-26T19:00:10.437+0700] {subprocess.py:93} INFO - 25/06/26 19:00:10 INFO Executor: Finished task 83.0 in stage 0.0 (TID 83). 3175 bytes result sent to driver
[2025-06-26T19:00:10.437+0700] {subprocess.py:93} INFO - 25/06/26 19:00:10 INFO TaskSetManager: Starting task 88.0 in stage 0.0 (TID 88) (localhost, executor driver, partition 88, PROCESS_LOCAL, 9215 bytes)
[2025-06-26T19:00:10.438+0700] {subprocess.py:93} INFO - 25/06/26 19:00:10 INFO Executor: Running task 88.0 in stage 0.0 (TID 88)
[2025-06-26T19:00:10.438+0700] {subprocess.py:93} INFO - 25/06/26 19:00:10 INFO Executor: Finished task 84.0 in stage 0.0 (TID 84). 3175 bytes result sent to driver
[2025-06-26T19:00:10.439+0700] {subprocess.py:93} INFO - 25/06/26 19:00:10 INFO Executor: Finished task 85.0 in stage 0.0 (TID 85). 3175 bytes result sent to driver
[2025-06-26T19:00:10.439+0700] {subprocess.py:93} INFO - 25/06/26 19:00:10 INFO TaskSetManager: Starting task 89.0 in stage 0.0 (TID 89) (localhost, executor driver, partition 89, PROCESS_LOCAL, 9215 bytes)
[2025-06-26T19:00:10.439+0700] {subprocess.py:93} INFO - 25/06/26 19:00:10 INFO Executor: Running task 89.0 in stage 0.0 (TID 89)
[2025-06-26T19:00:10.440+0700] {subprocess.py:93} INFO - 25/06/26 19:00:10 INFO TaskSetManager: Finished task 67.0 in stage 0.0 (TID 67) in 83 ms on localhost (executor driver) (66/283)
[2025-06-26T19:00:10.440+0700] {subprocess.py:93} INFO - 25/06/26 19:00:10 INFO TaskSetManager: Finished task 68.0 in stage 0.0 (TID 68) in 82 ms on localhost (executor driver) (67/283)
[2025-06-26T19:00:10.440+0700] {subprocess.py:93} INFO - 25/06/26 19:00:10 INFO TaskSetManager: Starting task 90.0 in stage 0.0 (TID 90) (localhost, executor driver, partition 90, PROCESS_LOCAL, 9215 bytes)
[2025-06-26T19:00:10.441+0700] {subprocess.py:93} INFO - 25/06/26 19:00:10 INFO TaskSetManager: Finished task 65.0 in stage 0.0 (TID 65) in 89 ms on localhost (executor driver) (68/283)
[2025-06-26T19:00:10.441+0700] {subprocess.py:93} INFO - 25/06/26 19:00:10 INFO TaskSetManager: Finished task 66.0 in stage 0.0 (TID 66) in 86 ms on localhost (executor driver) (69/283)
[2025-06-26T19:00:10.441+0700] {subprocess.py:93} INFO - 25/06/26 19:00:10 INFO Executor: Running task 90.0 in stage 0.0 (TID 90)
[2025-06-26T19:00:10.444+0700] {subprocess.py:93} INFO - 25/06/26 19:00:10 INFO TaskSetManager: Starting task 91.0 in stage 0.0 (TID 91) (localhost, executor driver, partition 91, PROCESS_LOCAL, 9215 bytes)
[2025-06-26T19:00:10.445+0700] {subprocess.py:93} INFO - 25/06/26 19:00:10 INFO Executor: Running task 91.0 in stage 0.0 (TID 91)
[2025-06-26T19:00:10.446+0700] {subprocess.py:93} INFO - 25/06/26 19:00:10 INFO TaskSetManager: Starting task 92.0 in stage 0.0 (TID 92) (localhost, executor driver, partition 92, PROCESS_LOCAL, 9215 bytes)
[2025-06-26T19:00:10.447+0700] {subprocess.py:93} INFO - 25/06/26 19:00:10 INFO Executor: Running task 92.0 in stage 0.0 (TID 92)
[2025-06-26T19:00:10.447+0700] {subprocess.py:93} INFO - 25/06/26 19:00:10 INFO TaskSetManager: Finished task 70.0 in stage 0.0 (TID 70) in 86 ms on localhost (executor driver) (70/283)
[2025-06-26T19:00:10.447+0700] {subprocess.py:93} INFO - 25/06/26 19:00:10 INFO Executor: Finished task 86.0 in stage 0.0 (TID 86). 3175 bytes result sent to driver
[2025-06-26T19:00:10.448+0700] {subprocess.py:93} INFO - 25/06/26 19:00:10 INFO Executor: Finished task 87.0 in stage 0.0 (TID 87). 3175 bytes result sent to driver
[2025-06-26T19:00:10.448+0700] {subprocess.py:93} INFO - 25/06/26 19:00:10 INFO TaskSetManager: Finished task 69.0 in stage 0.0 (TID 69) in 88 ms on localhost (executor driver) (71/283)
[2025-06-26T19:00:10.451+0700] {subprocess.py:93} INFO - 25/06/26 19:00:10 INFO TaskSetManager: Starting task 93.0 in stage 0.0 (TID 93) (localhost, executor driver, partition 93, PROCESS_LOCAL, 9215 bytes)
[2025-06-26T19:00:10.453+0700] {subprocess.py:93} INFO - 25/06/26 19:00:10 INFO Executor: Running task 93.0 in stage 0.0 (TID 93)
[2025-06-26T19:00:10.453+0700] {subprocess.py:93} INFO - 25/06/26 19:00:10 INFO Executor: Finished task 89.0 in stage 0.0 (TID 89). 3175 bytes result sent to driver
[2025-06-26T19:00:10.454+0700] {subprocess.py:93} INFO - 25/06/26 19:00:10 INFO TaskSetManager: Starting task 94.0 in stage 0.0 (TID 94) (localhost, executor driver, partition 94, PROCESS_LOCAL, 9215 bytes)
[2025-06-26T19:00:10.455+0700] {subprocess.py:93} INFO - 25/06/26 19:00:10 INFO Executor: Running task 94.0 in stage 0.0 (TID 94)
[2025-06-26T19:00:10.456+0700] {subprocess.py:93} INFO - 25/06/26 19:00:10 INFO Executor: Finished task 88.0 in stage 0.0 (TID 88). 3175 bytes result sent to driver
[2025-06-26T19:00:10.456+0700] {subprocess.py:93} INFO - 25/06/26 19:00:10 INFO TaskSetManager: Starting task 95.0 in stage 0.0 (TID 95) (localhost, executor driver, partition 95, PROCESS_LOCAL, 9215 bytes)
[2025-06-26T19:00:10.456+0700] {subprocess.py:93} INFO - 25/06/26 19:00:10 INFO TaskSetManager: Finished task 72.0 in stage 0.0 (TID 72) in 90 ms on localhost (executor driver) (72/283)
[2025-06-26T19:00:10.457+0700] {subprocess.py:93} INFO - 25/06/26 19:00:10 INFO Executor: Running task 95.0 in stage 0.0 (TID 95)
[2025-06-26T19:00:10.458+0700] {subprocess.py:93} INFO - 25/06/26 19:00:10 INFO TaskSetManager: Starting task 96.0 in stage 0.0 (TID 96) (localhost, executor driver, partition 96, PROCESS_LOCAL, 9215 bytes)
[2025-06-26T19:00:10.458+0700] {subprocess.py:93} INFO - 25/06/26 19:00:10 INFO Executor: Finished task 90.0 in stage 0.0 (TID 90). 3175 bytes result sent to driver
[2025-06-26T19:00:10.458+0700] {subprocess.py:93} INFO - 25/06/26 19:00:10 INFO TaskSetManager: Finished task 71.0 in stage 0.0 (TID 71) in 96 ms on localhost (executor driver) (73/283)
[2025-06-26T19:00:10.458+0700] {subprocess.py:93} INFO - 25/06/26 19:00:10 INFO Executor: Running task 96.0 in stage 0.0 (TID 96)
[2025-06-26T19:00:10.459+0700] {subprocess.py:93} INFO - 25/06/26 19:00:10 INFO TaskSetManager: Starting task 97.0 in stage 0.0 (TID 97) (localhost, executor driver, partition 97, PROCESS_LOCAL, 9215 bytes)
[2025-06-26T19:00:10.460+0700] {subprocess.py:93} INFO - 25/06/26 19:00:10 INFO TaskSetManager: Finished task 75.0 in stage 0.0 (TID 75) in 88 ms on localhost (executor driver) (74/283)
[2025-06-26T19:00:10.460+0700] {subprocess.py:93} INFO - 25/06/26 19:00:10 INFO Executor: Running task 97.0 in stage 0.0 (TID 97)
[2025-06-26T19:00:10.461+0700] {subprocess.py:93} INFO - 25/06/26 19:00:10 INFO TaskSetManager: Starting task 98.0 in stage 0.0 (TID 98) (localhost, executor driver, partition 98, PROCESS_LOCAL, 9215 bytes)
[2025-06-26T19:00:10.461+0700] {subprocess.py:93} INFO - 25/06/26 19:00:10 INFO Executor: Finished task 91.0 in stage 0.0 (TID 91). 3175 bytes result sent to driver
[2025-06-26T19:00:10.462+0700] {subprocess.py:93} INFO - 25/06/26 19:00:10 INFO Executor: Finished task 92.0 in stage 0.0 (TID 92). 3175 bytes result sent to driver
[2025-06-26T19:00:10.462+0700] {subprocess.py:93} INFO - 25/06/26 19:00:10 INFO Executor: Running task 98.0 in stage 0.0 (TID 98)
[2025-06-26T19:00:10.463+0700] {subprocess.py:93} INFO - 25/06/26 19:00:10 INFO TaskSetManager: Finished task 74.0 in stage 0.0 (TID 74) in 91 ms on localhost (executor driver) (75/283)
[2025-06-26T19:00:10.464+0700] {subprocess.py:93} INFO - 25/06/26 19:00:10 INFO TaskSetManager: Finished task 77.0 in stage 0.0 (TID 77) in 78 ms on localhost (executor driver) (76/283)
[2025-06-26T19:00:10.464+0700] {subprocess.py:93} INFO - 25/06/26 19:00:10 INFO TaskSetManager: Starting task 99.0 in stage 0.0 (TID 99) (localhost, executor driver, partition 99, PROCESS_LOCAL, 9215 bytes)
[2025-06-26T19:00:10.464+0700] {subprocess.py:93} INFO - 25/06/26 19:00:10 INFO TaskSetManager: Finished task 76.0 in stage 0.0 (TID 76) in 82 ms on localhost (executor driver) (77/283)
[2025-06-26T19:00:10.464+0700] {subprocess.py:93} INFO - 25/06/26 19:00:10 INFO Executor: Running task 99.0 in stage 0.0 (TID 99)
[2025-06-26T19:00:10.465+0700] {subprocess.py:93} INFO - 25/06/26 19:00:10 INFO TaskSetManager: Finished task 80.0 in stage 0.0 (TID 80) in 77 ms on localhost (executor driver) (78/283)
[2025-06-26T19:00:10.466+0700] {subprocess.py:93} INFO - 25/06/26 19:00:10 INFO Executor: Finished task 93.0 in stage 0.0 (TID 93). 3175 bytes result sent to driver
[2025-06-26T19:00:10.468+0700] {subprocess.py:93} INFO - 25/06/26 19:00:10 INFO TaskSetManager: Starting task 100.0 in stage 0.0 (TID 100) (localhost, executor driver, partition 100, PROCESS_LOCAL, 9215 bytes)
[2025-06-26T19:00:10.469+0700] {subprocess.py:93} INFO - 25/06/26 19:00:10 INFO Executor: Finished task 94.0 in stage 0.0 (TID 94). 3175 bytes result sent to driver
[2025-06-26T19:00:10.469+0700] {subprocess.py:93} INFO - 25/06/26 19:00:10 INFO Executor: Finished task 96.0 in stage 0.0 (TID 96). 3175 bytes result sent to driver
[2025-06-26T19:00:10.469+0700] {subprocess.py:93} INFO - 25/06/26 19:00:10 INFO TaskSetManager: Finished task 79.0 in stage 0.0 (TID 79) in 82 ms on localhost (executor driver) (79/283)
[2025-06-26T19:00:10.469+0700] {subprocess.py:93} INFO - 25/06/26 19:00:10 INFO Executor: Running task 100.0 in stage 0.0 (TID 100)
[2025-06-26T19:00:10.470+0700] {subprocess.py:93} INFO - 25/06/26 19:00:10 INFO TaskSetManager: Starting task 101.0 in stage 0.0 (TID 101) (localhost, executor driver, partition 101, PROCESS_LOCAL, 9215 bytes)
[2025-06-26T19:00:10.471+0700] {subprocess.py:93} INFO - 25/06/26 19:00:10 INFO Executor: Finished task 95.0 in stage 0.0 (TID 95). 3175 bytes result sent to driver
[2025-06-26T19:00:10.472+0700] {subprocess.py:93} INFO - 25/06/26 19:00:10 INFO Executor: Running task 101.0 in stage 0.0 (TID 101)
[2025-06-26T19:00:10.473+0700] {subprocess.py:93} INFO - 25/06/26 19:00:10 INFO TaskSetManager: Starting task 102.0 in stage 0.0 (TID 102) (localhost, executor driver, partition 102, PROCESS_LOCAL, 9215 bytes)
[2025-06-26T19:00:10.473+0700] {subprocess.py:93} INFO - 25/06/26 19:00:10 INFO TaskSetManager: Finished task 78.0 in stage 0.0 (TID 78) in 86 ms on localhost (executor driver) (80/283)
[2025-06-26T19:00:10.473+0700] {subprocess.py:93} INFO - 25/06/26 19:00:10 INFO Executor: Running task 102.0 in stage 0.0 (TID 102)
[2025-06-26T19:00:10.473+0700] {subprocess.py:93} INFO - 25/06/26 19:00:10 INFO TaskSetManager: Finished task 73.0 in stage 0.0 (TID 73) in 105 ms on localhost (executor driver) (81/283)
[2025-06-26T19:00:10.474+0700] {subprocess.py:93} INFO - 25/06/26 19:00:10 INFO Executor: Finished task 97.0 in stage 0.0 (TID 97). 3175 bytes result sent to driver
[2025-06-26T19:00:10.474+0700] {subprocess.py:93} INFO - 25/06/26 19:00:10 INFO Executor: Finished task 98.0 in stage 0.0 (TID 98). 3175 bytes result sent to driver
[2025-06-26T19:00:10.474+0700] {subprocess.py:93} INFO - 25/06/26 19:00:10 INFO TaskSetManager: Starting task 103.0 in stage 0.0 (TID 103) (localhost, executor driver, partition 103, PROCESS_LOCAL, 9215 bytes)
[2025-06-26T19:00:10.475+0700] {subprocess.py:93} INFO - 25/06/26 19:00:10 INFO Executor: Running task 103.0 in stage 0.0 (TID 103)
[2025-06-26T19:00:10.476+0700] {subprocess.py:93} INFO - 25/06/26 19:00:10 INFO TaskSetManager: Starting task 104.0 in stage 0.0 (TID 104) (localhost, executor driver, partition 104, PROCESS_LOCAL, 9215 bytes)
[2025-06-26T19:00:10.476+0700] {subprocess.py:93} INFO - 25/06/26 19:00:10 INFO Executor: Finished task 99.0 in stage 0.0 (TID 99). 3175 bytes result sent to driver
[2025-06-26T19:00:10.476+0700] {subprocess.py:93} INFO - 25/06/26 19:00:10 INFO TaskSetManager: Finished task 82.0 in stage 0.0 (TID 82) in 82 ms on localhost (executor driver) (82/283)
[2025-06-26T19:00:10.477+0700] {subprocess.py:93} INFO - 25/06/26 19:00:10 INFO Executor: Running task 104.0 in stage 0.0 (TID 104)
[2025-06-26T19:00:10.477+0700] {subprocess.py:93} INFO - 25/06/26 19:00:10 INFO TaskSetManager: Finished task 81.0 in stage 0.0 (TID 81) in 84 ms on localhost (executor driver) (83/283)
[2025-06-26T19:00:10.478+0700] {subprocess.py:93} INFO - 25/06/26 19:00:10 INFO TaskSetManager: Starting task 105.0 in stage 0.0 (TID 105) (localhost, executor driver, partition 105, PROCESS_LOCAL, 9215 bytes)
[2025-06-26T19:00:10.479+0700] {subprocess.py:93} INFO - 25/06/26 19:00:10 INFO Executor: Running task 105.0 in stage 0.0 (TID 105)
[2025-06-26T19:00:10.480+0700] {subprocess.py:93} INFO - 25/06/26 19:00:10 INFO TaskSetManager: Starting task 106.0 in stage 0.0 (TID 106) (localhost, executor driver, partition 106, PROCESS_LOCAL, 9215 bytes)
[2025-06-26T19:00:10.481+0700] {subprocess.py:93} INFO - 25/06/26 19:00:10 INFO Executor: Running task 106.0 in stage 0.0 (TID 106)
[2025-06-26T19:00:10.482+0700] {subprocess.py:93} INFO - 25/06/26 19:00:10 INFO TaskSetManager: Finished task 83.0 in stage 0.0 (TID 83) in 85 ms on localhost (executor driver) (84/283)
[2025-06-26T19:00:10.483+0700] {subprocess.py:93} INFO - 25/06/26 19:00:10 INFO TaskSetManager: Finished task 84.0 in stage 0.0 (TID 84) in 84 ms on localhost (executor driver) (85/283)
[2025-06-26T19:00:10.484+0700] {subprocess.py:93} INFO - 25/06/26 19:00:10 INFO TaskSetManager: Starting task 107.0 in stage 0.0 (TID 107) (localhost, executor driver, partition 107, PROCESS_LOCAL, 9215 bytes)
[2025-06-26T19:00:10.485+0700] {subprocess.py:93} INFO - 25/06/26 19:00:10 INFO Executor: Running task 107.0 in stage 0.0 (TID 107)
[2025-06-26T19:00:10.487+0700] {subprocess.py:93} INFO - 25/06/26 19:00:10 INFO TaskSetManager: Starting task 108.0 in stage 0.0 (TID 108) (localhost, executor driver, partition 108, PROCESS_LOCAL, 9215 bytes)
[2025-06-26T19:00:10.497+0700] {subprocess.py:93} INFO - 25/06/26 19:00:10 INFO Executor: Finished task 100.0 in stage 0.0 (TID 100). 3175 bytes result sent to driver
[2025-06-26T19:00:10.498+0700] {subprocess.py:93} INFO - 25/06/26 19:00:10 INFO Executor: Running task 108.0 in stage 0.0 (TID 108)
[2025-06-26T19:00:10.498+0700] {subprocess.py:93} INFO - 25/06/26 19:00:10 INFO TaskSetManager: Finished task 85.0 in stage 0.0 (TID 85) in 71 ms on localhost (executor driver) (86/283)
[2025-06-26T19:00:10.498+0700] {subprocess.py:93} INFO - 25/06/26 19:00:10 INFO Executor: Finished task 103.0 in stage 0.0 (TID 103). 3261 bytes result sent to driver
[2025-06-26T19:00:10.498+0700] {subprocess.py:93} INFO - 25/06/26 19:00:10 INFO TaskSetManager: Starting task 109.0 in stage 0.0 (TID 109) (localhost, executor driver, partition 109, PROCESS_LOCAL, 9215 bytes)
[2025-06-26T19:00:10.499+0700] {subprocess.py:93} INFO - 25/06/26 19:00:10 INFO Executor: Finished task 104.0 in stage 0.0 (TID 104). 3218 bytes result sent to driver
[2025-06-26T19:00:10.499+0700] {subprocess.py:93} INFO - 25/06/26 19:00:10 INFO TaskSetManager: Starting task 110.0 in stage 0.0 (TID 110) (localhost, executor driver, partition 110, PROCESS_LOCAL, 9215 bytes)
[2025-06-26T19:00:10.500+0700] {subprocess.py:93} INFO - 25/06/26 19:00:10 INFO Executor: Running task 109.0 in stage 0.0 (TID 109)
[2025-06-26T19:00:10.500+0700] {subprocess.py:93} INFO - 25/06/26 19:00:10 INFO Executor: Finished task 101.0 in stage 0.0 (TID 101). 3261 bytes result sent to driver
[2025-06-26T19:00:10.500+0700] {subprocess.py:93} INFO - 25/06/26 19:00:10 INFO Executor: Finished task 102.0 in stage 0.0 (TID 102). 3261 bytes result sent to driver
[2025-06-26T19:00:10.501+0700] {subprocess.py:93} INFO - 25/06/26 19:00:10 INFO TaskSetManager: Starting task 111.0 in stage 0.0 (TID 111) (localhost, executor driver, partition 111, PROCESS_LOCAL, 9215 bytes)
[2025-06-26T19:00:10.502+0700] {subprocess.py:93} INFO - 25/06/26 19:00:10 INFO Executor: Running task 111.0 in stage 0.0 (TID 111)
[2025-06-26T19:00:10.503+0700] {subprocess.py:93} INFO - 25/06/26 19:00:10 INFO Executor: Running task 110.0 in stage 0.0 (TID 110)
[2025-06-26T19:00:10.504+0700] {subprocess.py:93} INFO - 25/06/26 19:00:10 INFO TaskSetManager: Starting task 112.0 in stage 0.0 (TID 112) (localhost, executor driver, partition 112, PROCESS_LOCAL, 9215 bytes)
[2025-06-26T19:00:10.504+0700] {subprocess.py:93} INFO - 25/06/26 19:00:10 INFO TaskSetManager: Finished task 86.0 in stage 0.0 (TID 86) in 74 ms on localhost (executor driver) (87/283)
[2025-06-26T19:00:10.504+0700] {subprocess.py:93} INFO - 25/06/26 19:00:10 INFO Executor: Finished task 106.0 in stage 0.0 (TID 106). 3218 bytes result sent to driver
[2025-06-26T19:00:10.505+0700] {subprocess.py:93} INFO - 25/06/26 19:00:10 INFO TaskSetManager: Finished task 87.0 in stage 0.0 (TID 87) in 73 ms on localhost (executor driver) (88/283)
[2025-06-26T19:00:10.505+0700] {subprocess.py:93} INFO - 25/06/26 19:00:10 INFO Executor: Running task 112.0 in stage 0.0 (TID 112)
[2025-06-26T19:00:10.507+0700] {subprocess.py:93} INFO - 25/06/26 19:00:10 INFO Executor: Finished task 105.0 in stage 0.0 (TID 105). 3218 bytes result sent to driver
[2025-06-26T19:00:10.510+0700] {subprocess.py:93} INFO - 25/06/26 19:00:10 INFO TaskSetManager: Starting task 113.0 in stage 0.0 (TID 113) (localhost, executor driver, partition 113, PROCESS_LOCAL, 9215 bytes)
[2025-06-26T19:00:10.510+0700] {subprocess.py:93} INFO - 25/06/26 19:00:10 INFO TaskSetManager: Finished task 89.0 in stage 0.0 (TID 89) in 72 ms on localhost (executor driver) (89/283)
[2025-06-26T19:00:10.512+0700] {subprocess.py:93} INFO - 25/06/26 19:00:10 INFO Executor: Running task 113.0 in stage 0.0 (TID 113)
[2025-06-26T19:00:10.513+0700] {subprocess.py:93} INFO - 25/06/26 19:00:10 INFO TaskSetManager: Finished task 88.0 in stage 0.0 (TID 88) in 74 ms on localhost (executor driver) (90/283)
[2025-06-26T19:00:10.514+0700] {subprocess.py:93} INFO - 25/06/26 19:00:10 INFO TaskSetManager: Finished task 90.0 in stage 0.0 (TID 90) in 73 ms on localhost (executor driver) (91/283)
[2025-06-26T19:00:10.523+0700] {subprocess.py:93} INFO - 25/06/26 19:00:10 INFO TaskSetManager: Starting task 114.0 in stage 0.0 (TID 114) (localhost, executor driver, partition 114, PROCESS_LOCAL, 9215 bytes)
[2025-06-26T19:00:10.524+0700] {subprocess.py:93} INFO - 25/06/26 19:00:10 INFO Executor: Running task 114.0 in stage 0.0 (TID 114)
[2025-06-26T19:00:10.524+0700] {subprocess.py:93} INFO - 25/06/26 19:00:10 INFO Executor: Finished task 107.0 in stage 0.0 (TID 107). 3218 bytes result sent to driver
[2025-06-26T19:00:10.524+0700] {subprocess.py:93} INFO - 25/06/26 19:00:10 INFO Executor: Finished task 109.0 in stage 0.0 (TID 109). 3175 bytes result sent to driver
[2025-06-26T19:00:10.525+0700] {subprocess.py:93} INFO - 25/06/26 19:00:10 INFO TaskSetManager: Starting task 115.0 in stage 0.0 (TID 115) (localhost, executor driver, partition 115, PROCESS_LOCAL, 9215 bytes)
[2025-06-26T19:00:10.526+0700] {subprocess.py:93} INFO - 25/06/26 19:00:10 INFO Executor: Running task 115.0 in stage 0.0 (TID 115)
[2025-06-26T19:00:10.526+0700] {subprocess.py:93} INFO - 25/06/26 19:00:10 INFO Executor: Finished task 108.0 in stage 0.0 (TID 108). 3175 bytes result sent to driver
[2025-06-26T19:00:10.527+0700] {subprocess.py:93} INFO - 25/06/26 19:00:10 INFO TaskSetManager: Starting task 116.0 in stage 0.0 (TID 116) (localhost, executor driver, partition 116, PROCESS_LOCAL, 9215 bytes)
[2025-06-26T19:00:10.527+0700] {subprocess.py:93} INFO - 25/06/26 19:00:10 INFO TaskSetManager: Finished task 91.0 in stage 0.0 (TID 91) in 84 ms on localhost (executor driver) (92/283)
[2025-06-26T19:00:10.528+0700] {subprocess.py:93} INFO - 25/06/26 19:00:10 INFO Executor: Running task 116.0 in stage 0.0 (TID 116)
[2025-06-26T19:00:10.529+0700] {subprocess.py:93} INFO - 25/06/26 19:00:10 INFO Executor: Finished task 110.0 in stage 0.0 (TID 110). 3175 bytes result sent to driver
[2025-06-26T19:00:10.529+0700] {subprocess.py:93} INFO - 25/06/26 19:00:10 INFO Executor: Finished task 112.0 in stage 0.0 (TID 112). 3175 bytes result sent to driver
[2025-06-26T19:00:10.529+0700] {subprocess.py:93} INFO - 25/06/26 19:00:10 INFO TaskSetManager: Finished task 96.0 in stage 0.0 (TID 96) in 71 ms on localhost (executor driver) (93/283)
[2025-06-26T19:00:10.529+0700] {subprocess.py:93} INFO - 25/06/26 19:00:10 INFO Executor: Finished task 113.0 in stage 0.0 (TID 113). 3175 bytes result sent to driver
[2025-06-26T19:00:10.529+0700] {subprocess.py:93} INFO - 25/06/26 19:00:10 INFO TaskSetManager: Starting task 117.0 in stage 0.0 (TID 117) (localhost, executor driver, partition 117, PROCESS_LOCAL, 9215 bytes)
[2025-06-26T19:00:10.530+0700] {subprocess.py:93} INFO - 25/06/26 19:00:10 INFO TaskSetManager: Finished task 92.0 in stage 0.0 (TID 92) in 85 ms on localhost (executor driver) (94/283)
[2025-06-26T19:00:10.530+0700] {subprocess.py:93} INFO - 25/06/26 19:00:10 INFO Executor: Running task 117.0 in stage 0.0 (TID 117)
[2025-06-26T19:00:10.530+0700] {subprocess.py:93} INFO - 25/06/26 19:00:10 INFO TaskSetManager: Finished task 93.0 in stage 0.0 (TID 93) in 80 ms on localhost (executor driver) (95/283)
[2025-06-26T19:00:10.531+0700] {subprocess.py:93} INFO - 25/06/26 19:00:10 INFO Executor: Finished task 111.0 in stage 0.0 (TID 111). 3218 bytes result sent to driver
[2025-06-26T19:00:10.531+0700] {subprocess.py:93} INFO - 25/06/26 19:00:10 INFO TaskSetManager: Finished task 94.0 in stage 0.0 (TID 94) in 77 ms on localhost (executor driver) (96/283)
[2025-06-26T19:00:10.535+0700] {subprocess.py:93} INFO - 25/06/26 19:00:10 INFO TaskSetManager: Starting task 118.0 in stage 0.0 (TID 118) (localhost, executor driver, partition 118, PROCESS_LOCAL, 9215 bytes)
[2025-06-26T19:00:10.537+0700] {subprocess.py:93} INFO - 25/06/26 19:00:10 INFO Executor: Running task 118.0 in stage 0.0 (TID 118)
[2025-06-26T19:00:10.537+0700] {subprocess.py:93} INFO - 25/06/26 19:00:10 INFO TaskSetManager: Starting task 119.0 in stage 0.0 (TID 119) (localhost, executor driver, partition 119, PROCESS_LOCAL, 9215 bytes)
[2025-06-26T19:00:10.538+0700] {subprocess.py:93} INFO - 25/06/26 19:00:10 INFO TaskSetManager: Finished task 95.0 in stage 0.0 (TID 95) in 83 ms on localhost (executor driver) (97/283)
[2025-06-26T19:00:10.539+0700] {subprocess.py:93} INFO - 25/06/26 19:00:10 INFO Executor: Running task 119.0 in stage 0.0 (TID 119)
[2025-06-26T19:00:10.539+0700] {subprocess.py:93} INFO - 25/06/26 19:00:10 INFO TaskSetManager: Finished task 98.0 in stage 0.0 (TID 98) in 78 ms on localhost (executor driver) (98/283)
[2025-06-26T19:00:10.540+0700] {subprocess.py:93} INFO - 25/06/26 19:00:10 INFO TaskSetManager: Starting task 120.0 in stage 0.0 (TID 120) (localhost, executor driver, partition 120, PROCESS_LOCAL, 9215 bytes)
[2025-06-26T19:00:10.541+0700] {subprocess.py:93} INFO - 25/06/26 19:00:10 INFO Executor: Finished task 114.0 in stage 0.0 (TID 114). 3218 bytes result sent to driver
[2025-06-26T19:00:10.541+0700] {subprocess.py:93} INFO - 25/06/26 19:00:10 INFO Executor: Finished task 115.0 in stage 0.0 (TID 115). 3175 bytes result sent to driver
[2025-06-26T19:00:10.541+0700] {subprocess.py:93} INFO - 25/06/26 19:00:10 INFO Executor: Running task 120.0 in stage 0.0 (TID 120)
[2025-06-26T19:00:10.542+0700] {subprocess.py:93} INFO - 25/06/26 19:00:10 INFO TaskSetManager: Starting task 121.0 in stage 0.0 (TID 121) (localhost, executor driver, partition 121, PROCESS_LOCAL, 9215 bytes)
[2025-06-26T19:00:10.543+0700] {subprocess.py:93} INFO - 25/06/26 19:00:10 INFO Executor: Finished task 116.0 in stage 0.0 (TID 116). 3175 bytes result sent to driver
[2025-06-26T19:00:10.543+0700] {subprocess.py:93} INFO - 25/06/26 19:00:10 INFO Executor: Running task 121.0 in stage 0.0 (TID 121)
[2025-06-26T19:00:10.543+0700] {subprocess.py:93} INFO - 25/06/26 19:00:10 INFO TaskSetManager: Finished task 97.0 in stage 0.0 (TID 97) in 83 ms on localhost (executor driver) (99/283)
[2025-06-26T19:00:10.546+0700] {subprocess.py:93} INFO - 25/06/26 19:00:10 INFO TaskSetManager: Starting task 122.0 in stage 0.0 (TID 122) (localhost, executor driver, partition 122, PROCESS_LOCAL, 9215 bytes)
[2025-06-26T19:00:10.547+0700] {subprocess.py:93} INFO - 25/06/26 19:00:10 INFO TaskSetManager: Finished task 99.0 in stage 0.0 (TID 99) in 83 ms on localhost (executor driver) (100/283)
[2025-06-26T19:00:10.547+0700] {subprocess.py:93} INFO - 25/06/26 19:00:10 INFO Executor: Running task 122.0 in stage 0.0 (TID 122)
[2025-06-26T19:00:10.549+0700] {subprocess.py:93} INFO - 25/06/26 19:00:10 INFO Executor: Finished task 117.0 in stage 0.0 (TID 117). 3175 bytes result sent to driver
[2025-06-26T19:00:10.549+0700] {subprocess.py:93} INFO - 25/06/26 19:00:10 INFO TaskSetManager: Starting task 123.0 in stage 0.0 (TID 123) (localhost, executor driver, partition 123, PROCESS_LOCAL, 9215 bytes)
[2025-06-26T19:00:10.550+0700] {subprocess.py:93} INFO - 25/06/26 19:00:10 INFO TaskSetManager: Finished task 100.0 in stage 0.0 (TID 100) in 82 ms on localhost (executor driver) (101/283)
[2025-06-26T19:00:10.550+0700] {subprocess.py:93} INFO - 25/06/26 19:00:10 INFO TaskSetManager: Finished task 103.0 in stage 0.0 (TID 103) in 76 ms on localhost (executor driver) (102/283)
[2025-06-26T19:00:10.550+0700] {subprocess.py:93} INFO - 25/06/26 19:00:10 INFO Executor: Running task 123.0 in stage 0.0 (TID 123)
[2025-06-26T19:00:10.552+0700] {subprocess.py:93} INFO - 25/06/26 19:00:10 INFO TaskSetManager: Starting task 124.0 in stage 0.0 (TID 124) (localhost, executor driver, partition 124, PROCESS_LOCAL, 9215 bytes)
[2025-06-26T19:00:10.553+0700] {subprocess.py:93} INFO - 25/06/26 19:00:10 INFO Executor: Finished task 118.0 in stage 0.0 (TID 118). 3175 bytes result sent to driver
[2025-06-26T19:00:10.553+0700] {subprocess.py:93} INFO - 25/06/26 19:00:10 INFO Executor: Running task 124.0 in stage 0.0 (TID 124)
[2025-06-26T19:00:10.554+0700] {subprocess.py:93} INFO - 25/06/26 19:00:10 INFO TaskSetManager: Starting task 125.0 in stage 0.0 (TID 125) (localhost, executor driver, partition 125, PROCESS_LOCAL, 9215 bytes)
[2025-06-26T19:00:10.554+0700] {subprocess.py:93} INFO - 25/06/26 19:00:10 INFO Executor: Finished task 120.0 in stage 0.0 (TID 120). 3175 bytes result sent to driver
[2025-06-26T19:00:10.554+0700] {subprocess.py:93} INFO - 25/06/26 19:00:10 INFO Executor: Finished task 119.0 in stage 0.0 (TID 119). 3175 bytes result sent to driver
[2025-06-26T19:00:10.554+0700] {subprocess.py:93} INFO - 25/06/26 19:00:10 INFO Executor: Finished task 121.0 in stage 0.0 (TID 121). 3175 bytes result sent to driver
[2025-06-26T19:00:10.555+0700] {subprocess.py:93} INFO - 25/06/26 19:00:10 INFO TaskSetManager: Finished task 104.0 in stage 0.0 (TID 104) in 79 ms on localhost (executor driver) (103/283)
[2025-06-26T19:00:10.555+0700] {subprocess.py:93} INFO - 25/06/26 19:00:10 INFO Executor: Running task 125.0 in stage 0.0 (TID 125)
[2025-06-26T19:00:10.555+0700] {subprocess.py:93} INFO - 25/06/26 19:00:10 INFO TaskSetManager: Starting task 126.0 in stage 0.0 (TID 126) (localhost, executor driver, partition 126, PROCESS_LOCAL, 9215 bytes)
[2025-06-26T19:00:10.556+0700] {subprocess.py:93} INFO - 25/06/26 19:00:10 INFO TaskSetManager: Finished task 101.0 in stage 0.0 (TID 101) in 85 ms on localhost (executor driver) (104/283)
[2025-06-26T19:00:10.556+0700] {subprocess.py:93} INFO - 25/06/26 19:00:10 INFO TaskSetManager: Finished task 102.0 in stage 0.0 (TID 102) in 85 ms on localhost (executor driver) (105/283)
[2025-06-26T19:00:10.556+0700] {subprocess.py:93} INFO - 25/06/26 19:00:10 INFO Executor: Running task 126.0 in stage 0.0 (TID 126)
[2025-06-26T19:00:10.557+0700] {subprocess.py:93} INFO - 25/06/26 19:00:10 INFO TaskSetManager: Starting task 127.0 in stage 0.0 (TID 127) (localhost, executor driver, partition 127, PROCESS_LOCAL, 9215 bytes)
[2025-06-26T19:00:10.558+0700] {subprocess.py:93} INFO - 25/06/26 19:00:10 INFO Executor: Running task 127.0 in stage 0.0 (TID 127)
[2025-06-26T19:00:10.558+0700] {subprocess.py:93} INFO - 25/06/26 19:00:10 INFO TaskSetManager: Starting task 128.0 in stage 0.0 (TID 128) (localhost, executor driver, partition 128, PROCESS_LOCAL, 9215 bytes)
[2025-06-26T19:00:10.559+0700] {subprocess.py:93} INFO - 25/06/26 19:00:10 INFO Executor: Running task 128.0 in stage 0.0 (TID 128)
[2025-06-26T19:00:10.559+0700] {subprocess.py:93} INFO - 25/06/26 19:00:10 INFO TaskSetManager: Finished task 105.0 in stage 0.0 (TID 105) in 81 ms on localhost (executor driver) (106/283)
[2025-06-26T19:00:10.560+0700] {subprocess.py:93} INFO - 25/06/26 19:00:10 INFO TaskSetManager: Starting task 129.0 in stage 0.0 (TID 129) (localhost, executor driver, partition 129, PROCESS_LOCAL, 9215 bytes)
[2025-06-26T19:00:10.560+0700] {subprocess.py:93} INFO - 25/06/26 19:00:10 INFO TaskSetManager: Finished task 106.0 in stage 0.0 (TID 106) in 81 ms on localhost (executor driver) (107/283)
[2025-06-26T19:00:10.561+0700] {subprocess.py:93} INFO - 25/06/26 19:00:10 INFO Executor: Running task 129.0 in stage 0.0 (TID 129)
[2025-06-26T19:00:10.562+0700] {subprocess.py:93} INFO - 25/06/26 19:00:10 INFO TaskSetManager: Starting task 130.0 in stage 0.0 (TID 130) (localhost, executor driver, partition 130, PROCESS_LOCAL, 9215 bytes)
[2025-06-26T19:00:10.562+0700] {subprocess.py:93} INFO - 25/06/26 19:00:10 INFO TaskSetManager: Starting task 131.0 in stage 0.0 (TID 131) (localhost, executor driver, partition 131, PROCESS_LOCAL, 9215 bytes)
[2025-06-26T19:00:10.563+0700] {subprocess.py:93} INFO - 25/06/26 19:00:10 INFO Executor: Running task 130.0 in stage 0.0 (TID 130)
[2025-06-26T19:00:10.563+0700] {subprocess.py:93} INFO - 25/06/26 19:00:10 INFO TaskSetManager: Finished task 109.0 in stage 0.0 (TID 109) in 64 ms on localhost (executor driver) (108/283)
[2025-06-26T19:00:10.563+0700] {subprocess.py:93} INFO - 25/06/26 19:00:10 INFO TaskSetManager: Finished task 107.0 in stage 0.0 (TID 107) in 79 ms on localhost (executor driver) (109/283)
[2025-06-26T19:00:10.563+0700] {subprocess.py:93} INFO - 25/06/26 19:00:10 INFO Executor: Finished task 123.0 in stage 0.0 (TID 123). 3175 bytes result sent to driver
[2025-06-26T19:00:10.563+0700] {subprocess.py:93} INFO - 25/06/26 19:00:10 INFO Executor: Finished task 122.0 in stage 0.0 (TID 122). 3175 bytes result sent to driver
[2025-06-26T19:00:10.564+0700] {subprocess.py:93} INFO - 25/06/26 19:00:10 INFO Executor: Running task 131.0 in stage 0.0 (TID 131)
[2025-06-26T19:00:10.564+0700] {subprocess.py:93} INFO - 25/06/26 19:00:10 INFO TaskSetManager: Finished task 108.0 in stage 0.0 (TID 108) in 78 ms on localhost (executor driver) (110/283)
[2025-06-26T19:00:10.565+0700] {subprocess.py:93} INFO - 25/06/26 19:00:10 INFO Executor: Finished task 125.0 in stage 0.0 (TID 125). 3175 bytes result sent to driver
[2025-06-26T19:00:10.565+0700] {subprocess.py:93} INFO - 25/06/26 19:00:10 INFO Executor: Finished task 124.0 in stage 0.0 (TID 124). 3175 bytes result sent to driver
[2025-06-26T19:00:10.566+0700] {subprocess.py:93} INFO - 25/06/26 19:00:10 INFO TaskSetManager: Starting task 132.0 in stage 0.0 (TID 132) (localhost, executor driver, partition 132, PROCESS_LOCAL, 9215 bytes)
