[2025-06-26T19:30:04.585+0700] {local_task_job_runner.py:120} INFO - ::group::Pre task execution logs
[2025-06-26T19:30:04.607+0700] {taskinstance.py:2073} INFO - Dependencies all met for dep_context=non-requeueable deps ti=<TaskInstance: send_data_to_powerbi.compact_csv_to_one_file scheduled__2025-06-26T12:20:00+00:00 [queued]>
[2025-06-26T19:30:04.615+0700] {taskinstance.py:2073} INFO - Dependencies all met for dep_context=requeueable deps ti=<TaskInstance: send_data_to_powerbi.compact_csv_to_one_file scheduled__2025-06-26T12:20:00+00:00 [queued]>
[2025-06-26T19:30:04.615+0700] {taskinstance.py:2303} INFO - Starting attempt 1 of 3
[2025-06-26T19:30:04.630+0700] {taskinstance.py:2327} INFO - Executing <Task(BashOperator): compact_csv_to_one_file> on 2025-06-26 12:20:00+00:00
[2025-06-26T19:30:04.637+0700] {standard_task_runner.py:63} INFO - Started process 71137 to run task
[2025-06-26T19:30:04.642+0700] {standard_task_runner.py:90} INFO - Running: ['airflow', 'tasks', 'run', 'send_data_to_powerbi', 'compact_csv_to_one_file', 'scheduled__2025-06-26T12:20:00+00:00', '--job-id', '58', '--raw', '--subdir', 'DAGS_FOLDER/load_power_bi.py', '--cfg-path', '/tmp/tmpxwc7y87g']
[2025-06-26T19:30:04.643+0700] {standard_task_runner.py:91} INFO - Job 58: Subtask compact_csv_to_one_file
[2025-06-26T19:30:04.694+0700] {task_command.py:426} INFO - Running <TaskInstance: send_data_to_powerbi.compact_csv_to_one_file scheduled__2025-06-26T12:20:00+00:00 [running]> on host Panda
[2025-06-26T19:30:04.771+0700] {taskinstance.py:2644} INFO - Exporting env vars: AIRFLOW_CTX_DAG_OWNER='group_03' AIRFLOW_CTX_DAG_ID='send_data_to_powerbi' AIRFLOW_CTX_TASK_ID='compact_csv_to_one_file' AIRFLOW_CTX_EXECUTION_DATE='2025-06-26T12:20:00+00:00' AIRFLOW_CTX_TRY_NUMBER='1' AIRFLOW_CTX_DAG_RUN_ID='scheduled__2025-06-26T12:20:00+00:00'
[2025-06-26T19:30:04.772+0700] {taskinstance.py:430} INFO - ::endgroup::
[2025-06-26T19:30:04.772+0700] {subprocess.py:63} INFO - Tmp dir root location: /tmp
[2025-06-26T19:30:04.773+0700] {subprocess.py:75} INFO - Running command: ['/usr/bin/bash', '-c', 'spark-submit /home/panda/Documents/ODAP/Project/hadoop/compact_csv.py && sleep 10']
[2025-06-26T19:30:04.786+0700] {subprocess.py:86} INFO - Output:
[2025-06-26T19:30:07.271+0700] {subprocess.py:93} INFO - 25/06/26 19:30:07 INFO SparkContext: Running Spark version 3.5.5
[2025-06-26T19:30:07.273+0700] {subprocess.py:93} INFO - 25/06/26 19:30:07 INFO SparkContext: OS info Linux, 6.11.0-26-generic, amd64
[2025-06-26T19:30:07.273+0700] {subprocess.py:93} INFO - 25/06/26 19:30:07 INFO SparkContext: Java version 11.0.27
[2025-06-26T19:30:07.423+0700] {subprocess.py:93} INFO - 25/06/26 19:30:07 INFO ResourceUtils: ==============================================================
[2025-06-26T19:30:07.424+0700] {subprocess.py:93} INFO - 25/06/26 19:30:07 INFO ResourceUtils: No custom resources configured for spark.driver.
[2025-06-26T19:30:07.424+0700] {subprocess.py:93} INFO - 25/06/26 19:30:07 INFO ResourceUtils: ==============================================================
[2025-06-26T19:30:07.425+0700] {subprocess.py:93} INFO - 25/06/26 19:30:07 INFO SparkContext: Submitted application: CompactSmallFiles
[2025-06-26T19:30:07.450+0700] {subprocess.py:93} INFO - 25/06/26 19:30:07 INFO ResourceProfile: Default ResourceProfile created, executor resources: Map(cores -> name: cores, amount: 1, script: , vendor: , memory -> name: memory, amount: 1024, script: , vendor: , offHeap -> name: offHeap, amount: 0, script: , vendor: ), task resources: Map(cpus -> name: cpus, amount: 1.0)
[2025-06-26T19:30:07.465+0700] {subprocess.py:93} INFO - 25/06/26 19:30:07 INFO ResourceProfile: Limiting resource is cpu
[2025-06-26T19:30:07.466+0700] {subprocess.py:93} INFO - 25/06/26 19:30:07 INFO ResourceProfileManager: Added ResourceProfile id: 0
[2025-06-26T19:30:07.529+0700] {subprocess.py:93} INFO - 25/06/26 19:30:07 INFO SecurityManager: Changing view acls to: panda
[2025-06-26T19:30:07.530+0700] {subprocess.py:93} INFO - 25/06/26 19:30:07 INFO SecurityManager: Changing modify acls to: panda
[2025-06-26T19:30:07.530+0700] {subprocess.py:93} INFO - 25/06/26 19:30:07 INFO SecurityManager: Changing view acls groups to:
[2025-06-26T19:30:07.530+0700] {subprocess.py:93} INFO - 25/06/26 19:30:07 INFO SecurityManager: Changing modify acls groups to:
[2025-06-26T19:30:07.531+0700] {subprocess.py:93} INFO - 25/06/26 19:30:07 INFO SecurityManager: SecurityManager: authentication disabled; ui acls disabled; users with view permissions: panda; groups with view permissions: EMPTY; users with modify permissions: panda; groups with modify permissions: EMPTY
[2025-06-26T19:30:07.776+0700] {subprocess.py:93} INFO - 25/06/26 19:30:07 INFO Utils: Successfully started service 'sparkDriver' on port 42161.
[2025-06-26T19:30:07.809+0700] {subprocess.py:93} INFO - 25/06/26 19:30:07 INFO SparkEnv: Registering MapOutputTracker
[2025-06-26T19:30:07.864+0700] {subprocess.py:93} INFO - 25/06/26 19:30:07 INFO SparkEnv: Registering BlockManagerMaster
[2025-06-26T19:30:07.886+0700] {subprocess.py:93} INFO - 25/06/26 19:30:07 INFO BlockManagerMasterEndpoint: Using org.apache.spark.storage.DefaultTopologyMapper for getting topology information
[2025-06-26T19:30:07.887+0700] {subprocess.py:93} INFO - 25/06/26 19:30:07 INFO BlockManagerMasterEndpoint: BlockManagerMasterEndpoint up
[2025-06-26T19:30:07.893+0700] {subprocess.py:93} INFO - 25/06/26 19:30:07 INFO SparkEnv: Registering BlockManagerMasterHeartbeat
[2025-06-26T19:30:07.926+0700] {subprocess.py:93} INFO - 25/06/26 19:30:07 INFO DiskBlockManager: Created local directory at /tmp/blockmgr-d50802bc-2e51-44b0-93a6-8511cfea6d12
[2025-06-26T19:30:07.951+0700] {subprocess.py:93} INFO - 25/06/26 19:30:07 INFO MemoryStore: MemoryStore started with capacity 434.4 MiB
[2025-06-26T19:30:07.975+0700] {subprocess.py:93} INFO - 25/06/26 19:30:07 INFO SparkEnv: Registering OutputCommitCoordinator
[2025-06-26T19:30:08.166+0700] {subprocess.py:93} INFO - 25/06/26 19:30:08 INFO JettyUtils: Start Jetty 127.0.0.1:4040 for SparkUI
[2025-06-26T19:30:08.249+0700] {subprocess.py:93} INFO - 25/06/26 19:30:08 WARN Utils: Service 'SparkUI' could not bind on port 4040. Attempting port 4041.
[2025-06-26T19:30:08.267+0700] {subprocess.py:93} INFO - 25/06/26 19:30:08 INFO Utils: Successfully started service 'SparkUI' on port 4041.
[2025-06-26T19:30:08.401+0700] {subprocess.py:93} INFO - 25/06/26 19:30:08 INFO Executor: Starting executor ID driver on host localhost
[2025-06-26T19:30:08.402+0700] {subprocess.py:93} INFO - 25/06/26 19:30:08 INFO Executor: OS info Linux, 6.11.0-26-generic, amd64
[2025-06-26T19:30:08.402+0700] {subprocess.py:93} INFO - 25/06/26 19:30:08 INFO Executor: Java version 11.0.27
[2025-06-26T19:30:08.415+0700] {subprocess.py:93} INFO - 25/06/26 19:30:08 INFO Executor: Starting executor with user classpath (userClassPathFirst = false): ''
[2025-06-26T19:30:08.416+0700] {subprocess.py:93} INFO - 25/06/26 19:30:08 INFO Executor: Created or updated repl class loader org.apache.spark.util.MutableURLClassLoader@bef90e5 for default.
[2025-06-26T19:30:08.451+0700] {subprocess.py:93} INFO - 25/06/26 19:30:08 INFO Utils: Successfully started service 'org.apache.spark.network.netty.NettyBlockTransferService' on port 41445.
[2025-06-26T19:30:08.452+0700] {subprocess.py:93} INFO - 25/06/26 19:30:08 INFO NettyBlockTransferService: Server created on localhost:41445
[2025-06-26T19:30:08.454+0700] {subprocess.py:93} INFO - 25/06/26 19:30:08 INFO BlockManager: Using org.apache.spark.storage.RandomBlockReplicationPolicy for block replication policy
[2025-06-26T19:30:08.464+0700] {subprocess.py:93} INFO - 25/06/26 19:30:08 INFO BlockManagerMaster: Registering BlockManager BlockManagerId(driver, localhost, 41445, None)
[2025-06-26T19:30:08.471+0700] {subprocess.py:93} INFO - 25/06/26 19:30:08 INFO BlockManagerMasterEndpoint: Registering block manager localhost:41445 with 434.4 MiB RAM, BlockManagerId(driver, localhost, 41445, None)
[2025-06-26T19:30:08.475+0700] {subprocess.py:93} INFO - 25/06/26 19:30:08 INFO BlockManagerMaster: Registered BlockManager BlockManagerId(driver, localhost, 41445, None)
[2025-06-26T19:30:08.476+0700] {subprocess.py:93} INFO - 25/06/26 19:30:08 INFO BlockManager: Initialized BlockManager: BlockManagerId(driver, localhost, 41445, None)
[2025-06-26T19:30:08.944+0700] {subprocess.py:93} INFO - 25/06/26 19:30:08 INFO SharedState: Setting hive.metastore.warehouse.dir ('null') to the value of spark.sql.warehouse.dir.
[2025-06-26T19:30:08.952+0700] {subprocess.py:93} INFO - 25/06/26 19:30:08 INFO SharedState: Warehouse path is 'file:/tmp/airflowtmpvap9gsk4/spark-warehouse'.
[2025-06-26T19:30:10.397+0700] {subprocess.py:93} INFO - 25/06/26 19:30:10 INFO MetadataLogFileIndex: Reading streaming file log from hdfs://localhost:9000/transactions_by_hour/_spark_metadata
[2025-06-26T19:30:10.492+0700] {subprocess.py:93} INFO - 25/06/26 19:30:10 INFO FileStreamSinkLog: BatchIds found from listing: 856, 857, 858, 859, 860, 861, 862, 863, 864, 865, 866, 867, 868, 869, 870, 871, 872, 873, 874, 875, 876, 877, 878, 879, 880, 881, 882, 883, 884, 885, 886, 887, 888, 889, 890, 891, 892, 893, 894, 895, 896, 897, 898, 899, 900, 901, 902, 903, 904, 905, 906, 907, 908, 909, 910, 911, 912, 913, 914, 915, 916, 917, 918, 919, 920, 921, 922, 923, 924, 925, 926, 927, 928, 929, 930, 931, 932, 933, 934, 935, 936, 937, 938, 939, 940, 941, 942, 943, 944, 945, 946, 947, 948, 949, 950, 951, 952, 953, 954, 955, 956, 957, 958, 959, 960, 961, 962, 963, 964, 965, 966, 967, 968, 969, 970, 971, 972, 973, 974, 975, 976, 977, 978, 979, 980, 981, 982, 983, 984, 985, 986, 987, 988, 989, 990, 991, 992, 993, 994, 995, 996, 997, 998, 999, 1000, 1001, 1002, 1003, 1004, 1005, 1006, 1007, 1008, 1009, 1010, 1011, 1012, 1013, 1014, 1015, 1016, 1017, 1018, 1019, 1020, 1021, 1022, 1023, 1024, 1025, 1026, 1027, 1028, 1029, 1030, 1031, 1032, 1033, 1034, 1035, 1036, 1037, 1038, 1039, 1040, 1041, 1042, 1043, 1044, 1045, 1046, 1047, 1048, 1049, 1050, 1051, 1052, 1053, 1054, 1055, 1056, 1057, 1058, 1059, 1060, 1061, 1062, 1063, 1064, 1065, 1066, 1067, 1068, 1069, 1070, 1071, 1072, 1073, 1074, 1075, 1076, 1077, 1078, 1079, 1080, 1081, 1082, 1083, 1084, 1085, 1086, 1087, 1088, 1089, 1090, 1091, 1092, 1093, 1094, 1095, 1096, 1097, 1098, 1099, 1100, 1101, 1102, 1103, 1104, 1105, 1106, 1107, 1108, 1109, 1110, 1111, 1112, 1113, 1114, 1115, 1116, 1117, 1118, 1119, 1120, 1121, 1122, 1123, 1124, 1125, 1126, 1127, 1128, 1129, 1130, 1131, 1132, 1133, 1134, 1135, 1136, 1137, 1138, 1139, 1140, 1141, 1142, 1143, 1144, 1145, 1146, 1147, 1148, 1149, 1150
[2025-06-26T19:30:10.532+0700] {subprocess.py:93} INFO - 25/06/26 19:30:10 INFO FileStreamSinkLog: Set the compact interval to 10 [defaultCompactInterval: 10]
[2025-06-26T19:30:11.109+0700] {subprocess.py:93} INFO - 25/06/26 19:30:11 INFO HadoopFSUtils: Listing leaf files and directories in parallel under 1151 paths. The first several paths are: hdfs://localhost:9000/transactions_by_hour/part-00000-35848e14-b857-426e-8939-db9c96261483-c000.csv, hdfs://localhost:9000/transactions_by_hour/part-00000-d7ab39d9-b4ef-4e2e-b472-4c1883c38273-c000.csv, hdfs://localhost:9000/transactions_by_hour/part-00000-cce2d287-6512-49d1-aa31-f452c0dcdaf9-c000.csv, hdfs://localhost:9000/transactions_by_hour/part-00000-ac8933a1-5bf2-4814-a228-6604c7045e4c-c000.csv, hdfs://localhost:9000/transactions_by_hour/part-00000-9c60d322-8794-4968-a7a5-364181d16d94-c000.csv, hdfs://localhost:9000/transactions_by_hour/part-00000-76895572-6aa7-4225-8325-6962e0c98ee2-c000.csv, hdfs://localhost:9000/transactions_by_hour/part-00000-a92a3ce5-6132-4e9e-8e69-11e47f72f0a2-c000.csv, hdfs://localhost:9000/transactions_by_hour/part-00000-b48a08d4-d847-4307-b612-e35a8f471916-c000.csv, hdfs://localhost:9000/transactions_by_hour/part-00000-e8f1544c-6d23-403f-a02b-06e9bef1638a-c000.csv, hdfs://localhost:9000/transactions_by_hour/part-00000-08040c60-6fee-4dcc-b2e9-af62320fb049-c000.csv.
[2025-06-26T19:30:11.517+0700] {subprocess.py:93} INFO - 25/06/26 19:30:11 INFO SparkContext: Starting job: csv at NativeMethodAccessorImpl.java:0
[2025-06-26T19:30:11.538+0700] {subprocess.py:93} INFO - 25/06/26 19:30:11 INFO DAGScheduler: Got job 0 (csv at NativeMethodAccessorImpl.java:0) with 1151 output partitions
[2025-06-26T19:30:11.538+0700] {subprocess.py:93} INFO - 25/06/26 19:30:11 INFO DAGScheduler: Final stage: ResultStage 0 (csv at NativeMethodAccessorImpl.java:0)
[2025-06-26T19:30:11.538+0700] {subprocess.py:93} INFO - 25/06/26 19:30:11 INFO DAGScheduler: Parents of final stage: List()
[2025-06-26T19:30:11.540+0700] {subprocess.py:93} INFO - 25/06/26 19:30:11 INFO DAGScheduler: Missing parents: List()
[2025-06-26T19:30:11.544+0700] {subprocess.py:93} INFO - 25/06/26 19:30:11 INFO DAGScheduler: Submitting ResultStage 0 (MapPartitionsRDD[1] at csv at NativeMethodAccessorImpl.java:0), which has no missing parents
[2025-06-26T19:30:11.659+0700] {subprocess.py:93} INFO - 25/06/26 19:30:11 INFO MemoryStore: Block broadcast_0 stored as values in memory (estimated size 103.2 KiB, free 434.3 MiB)
[2025-06-26T19:30:11.694+0700] {subprocess.py:93} INFO - 25/06/26 19:30:11 INFO MemoryStore: Block broadcast_0_piece0 stored as bytes in memory (estimated size 37.3 KiB, free 434.3 MiB)
[2025-06-26T19:30:11.697+0700] {subprocess.py:93} INFO - 25/06/26 19:30:11 INFO BlockManagerInfo: Added broadcast_0_piece0 in memory on localhost:41445 (size: 37.3 KiB, free: 434.4 MiB)
[2025-06-26T19:30:11.701+0700] {subprocess.py:93} INFO - 25/06/26 19:30:11 INFO SparkContext: Created broadcast 0 from broadcast at DAGScheduler.scala:1585
[2025-06-26T19:30:11.735+0700] {subprocess.py:93} INFO - 25/06/26 19:30:11 INFO DAGScheduler: Submitting 1151 missing tasks from ResultStage 0 (MapPartitionsRDD[1] at csv at NativeMethodAccessorImpl.java:0) (first 15 tasks are for partitions Vector(0, 1, 2, 3, 4, 5, 6, 7, 8, 9, 10, 11, 12, 13, 14))
[2025-06-26T19:30:11.737+0700] {subprocess.py:93} INFO - 25/06/26 19:30:11 INFO TaskSchedulerImpl: Adding task set 0.0 with 1151 tasks resource profile 0
[2025-06-26T19:30:11.823+0700] {subprocess.py:93} INFO - 25/06/26 19:30:11 INFO TaskSetManager: Starting task 0.0 in stage 0.0 (TID 0) (localhost, executor driver, partition 0, PROCESS_LOCAL, 9215 bytes)
[2025-06-26T19:30:11.827+0700] {subprocess.py:93} INFO - 25/06/26 19:30:11 INFO TaskSetManager: Starting task 1.0 in stage 0.0 (TID 1) (localhost, executor driver, partition 1, PROCESS_LOCAL, 9215 bytes)
[2025-06-26T19:30:11.828+0700] {subprocess.py:93} INFO - 25/06/26 19:30:11 INFO TaskSetManager: Starting task 2.0 in stage 0.0 (TID 2) (localhost, executor driver, partition 2, PROCESS_LOCAL, 9215 bytes)
[2025-06-26T19:30:11.828+0700] {subprocess.py:93} INFO - 25/06/26 19:30:11 INFO TaskSetManager: Starting task 3.0 in stage 0.0 (TID 3) (localhost, executor driver, partition 3, PROCESS_LOCAL, 9215 bytes)
[2025-06-26T19:30:11.829+0700] {subprocess.py:93} INFO - 25/06/26 19:30:11 INFO TaskSetManager: Starting task 4.0 in stage 0.0 (TID 4) (localhost, executor driver, partition 4, PROCESS_LOCAL, 9215 bytes)
[2025-06-26T19:30:11.830+0700] {subprocess.py:93} INFO - 25/06/26 19:30:11 INFO TaskSetManager: Starting task 5.0 in stage 0.0 (TID 5) (localhost, executor driver, partition 5, PROCESS_LOCAL, 9215 bytes)
[2025-06-26T19:30:11.830+0700] {subprocess.py:93} INFO - 25/06/26 19:30:11 INFO TaskSetManager: Starting task 6.0 in stage 0.0 (TID 6) (localhost, executor driver, partition 6, PROCESS_LOCAL, 9215 bytes)
[2025-06-26T19:30:11.831+0700] {subprocess.py:93} INFO - 25/06/26 19:30:11 INFO TaskSetManager: Starting task 7.0 in stage 0.0 (TID 7) (localhost, executor driver, partition 7, PROCESS_LOCAL, 9215 bytes)
[2025-06-26T19:30:11.831+0700] {subprocess.py:93} INFO - 25/06/26 19:30:11 INFO TaskSetManager: Starting task 8.0 in stage 0.0 (TID 8) (localhost, executor driver, partition 8, PROCESS_LOCAL, 9215 bytes)
[2025-06-26T19:30:11.831+0700] {subprocess.py:93} INFO - 25/06/26 19:30:11 INFO TaskSetManager: Starting task 9.0 in stage 0.0 (TID 9) (localhost, executor driver, partition 9, PROCESS_LOCAL, 9215 bytes)
[2025-06-26T19:30:11.832+0700] {subprocess.py:93} INFO - 25/06/26 19:30:11 INFO TaskSetManager: Starting task 10.0 in stage 0.0 (TID 10) (localhost, executor driver, partition 10, PROCESS_LOCAL, 9215 bytes)
[2025-06-26T19:30:11.832+0700] {subprocess.py:93} INFO - 25/06/26 19:30:11 INFO TaskSetManager: Starting task 11.0 in stage 0.0 (TID 11) (localhost, executor driver, partition 11, PROCESS_LOCAL, 9215 bytes)
[2025-06-26T19:30:11.832+0700] {subprocess.py:93} INFO - 25/06/26 19:30:11 INFO TaskSetManager: Starting task 12.0 in stage 0.0 (TID 12) (localhost, executor driver, partition 12, PROCESS_LOCAL, 9215 bytes)
[2025-06-26T19:30:11.833+0700] {subprocess.py:93} INFO - 25/06/26 19:30:11 INFO TaskSetManager: Starting task 13.0 in stage 0.0 (TID 13) (localhost, executor driver, partition 13, PROCESS_LOCAL, 9215 bytes)
[2025-06-26T19:30:11.833+0700] {subprocess.py:93} INFO - 25/06/26 19:30:11 INFO TaskSetManager: Starting task 14.0 in stage 0.0 (TID 14) (localhost, executor driver, partition 14, PROCESS_LOCAL, 9215 bytes)
[2025-06-26T19:30:11.835+0700] {subprocess.py:93} INFO - 25/06/26 19:30:11 INFO TaskSetManager: Starting task 15.0 in stage 0.0 (TID 15) (localhost, executor driver, partition 15, PROCESS_LOCAL, 9215 bytes)
[2025-06-26T19:30:11.835+0700] {subprocess.py:93} INFO - 25/06/26 19:30:11 INFO TaskSetManager: Starting task 16.0 in stage 0.0 (TID 16) (localhost, executor driver, partition 16, PROCESS_LOCAL, 9215 bytes)
[2025-06-26T19:30:11.835+0700] {subprocess.py:93} INFO - 25/06/26 19:30:11 INFO TaskSetManager: Starting task 17.0 in stage 0.0 (TID 17) (localhost, executor driver, partition 17, PROCESS_LOCAL, 9215 bytes)
[2025-06-26T19:30:11.835+0700] {subprocess.py:93} INFO - 25/06/26 19:30:11 INFO TaskSetManager: Starting task 18.0 in stage 0.0 (TID 18) (localhost, executor driver, partition 18, PROCESS_LOCAL, 9215 bytes)
[2025-06-26T19:30:11.836+0700] {subprocess.py:93} INFO - 25/06/26 19:30:11 INFO TaskSetManager: Starting task 19.0 in stage 0.0 (TID 19) (localhost, executor driver, partition 19, PROCESS_LOCAL, 9215 bytes)
[2025-06-26T19:30:11.836+0700] {subprocess.py:93} INFO - 25/06/26 19:30:11 INFO TaskSetManager: Starting task 20.0 in stage 0.0 (TID 20) (localhost, executor driver, partition 20, PROCESS_LOCAL, 9215 bytes)
[2025-06-26T19:30:11.837+0700] {subprocess.py:93} INFO - 25/06/26 19:30:11 INFO TaskSetManager: Starting task 21.0 in stage 0.0 (TID 21) (localhost, executor driver, partition 21, PROCESS_LOCAL, 9215 bytes)
[2025-06-26T19:30:11.856+0700] {subprocess.py:93} INFO - 25/06/26 19:30:11 INFO Executor: Running task 14.0 in stage 0.0 (TID 14)
[2025-06-26T19:30:11.857+0700] {subprocess.py:93} INFO - 25/06/26 19:30:11 INFO Executor: Running task 0.0 in stage 0.0 (TID 0)
[2025-06-26T19:30:11.857+0700] {subprocess.py:93} INFO - 25/06/26 19:30:11 INFO Executor: Running task 1.0 in stage 0.0 (TID 1)
[2025-06-26T19:30:11.857+0700] {subprocess.py:93} INFO - 25/06/26 19:30:11 INFO Executor: Running task 7.0 in stage 0.0 (TID 7)
[2025-06-26T19:30:11.857+0700] {subprocess.py:93} INFO - 25/06/26 19:30:11 INFO Executor: Running task 20.0 in stage 0.0 (TID 20)
[2025-06-26T19:30:11.857+0700] {subprocess.py:93} INFO - 25/06/26 19:30:11 INFO Executor: Running task 8.0 in stage 0.0 (TID 8)
[2025-06-26T19:30:11.857+0700] {subprocess.py:93} INFO - 25/06/26 19:30:11 INFO Executor: Running task 17.0 in stage 0.0 (TID 17)
[2025-06-26T19:30:11.857+0700] {subprocess.py:93} INFO - 25/06/26 19:30:11 INFO Executor: Running task 3.0 in stage 0.0 (TID 3)
[2025-06-26T19:30:11.858+0700] {subprocess.py:93} INFO - 25/06/26 19:30:11 INFO Executor: Running task 5.0 in stage 0.0 (TID 5)
[2025-06-26T19:30:11.858+0700] {subprocess.py:93} INFO - 25/06/26 19:30:11 INFO Executor: Running task 4.0 in stage 0.0 (TID 4)
[2025-06-26T19:30:11.858+0700] {subprocess.py:93} INFO - 25/06/26 19:30:11 INFO Executor: Running task 21.0 in stage 0.0 (TID 21)
[2025-06-26T19:30:11.858+0700] {subprocess.py:93} INFO - 25/06/26 19:30:11 INFO Executor: Running task 12.0 in stage 0.0 (TID 12)
[2025-06-26T19:30:11.858+0700] {subprocess.py:93} INFO - 25/06/26 19:30:11 INFO Executor: Running task 15.0 in stage 0.0 (TID 15)
[2025-06-26T19:30:11.858+0700] {subprocess.py:93} INFO - 25/06/26 19:30:11 INFO Executor: Running task 10.0 in stage 0.0 (TID 10)
[2025-06-26T19:30:11.858+0700] {subprocess.py:93} INFO - 25/06/26 19:30:11 INFO Executor: Running task 9.0 in stage 0.0 (TID 9)
[2025-06-26T19:30:11.858+0700] {subprocess.py:93} INFO - 25/06/26 19:30:11 INFO Executor: Running task 2.0 in stage 0.0 (TID 2)
[2025-06-26T19:30:11.859+0700] {subprocess.py:93} INFO - 25/06/26 19:30:11 INFO Executor: Running task 19.0 in stage 0.0 (TID 19)
[2025-06-26T19:30:11.859+0700] {subprocess.py:93} INFO - 25/06/26 19:30:11 INFO Executor: Running task 18.0 in stage 0.0 (TID 18)
[2025-06-26T19:30:11.859+0700] {subprocess.py:93} INFO - 25/06/26 19:30:11 INFO Executor: Running task 11.0 in stage 0.0 (TID 11)
[2025-06-26T19:30:11.859+0700] {subprocess.py:93} INFO - 25/06/26 19:30:11 INFO Executor: Running task 6.0 in stage 0.0 (TID 6)
[2025-06-26T19:30:11.859+0700] {subprocess.py:93} INFO - 25/06/26 19:30:11 INFO Executor: Running task 16.0 in stage 0.0 (TID 16)
[2025-06-26T19:30:11.859+0700] {subprocess.py:93} INFO - 25/06/26 19:30:11 INFO Executor: Running task 13.0 in stage 0.0 (TID 13)
[2025-06-26T19:30:12.249+0700] {subprocess.py:93} INFO - 25/06/26 19:30:12 INFO Executor: Finished task 18.0 in stage 0.0 (TID 18). 3261 bytes result sent to driver
[2025-06-26T19:30:12.250+0700] {subprocess.py:93} INFO - 25/06/26 19:30:12 INFO Executor: Finished task 15.0 in stage 0.0 (TID 15). 3261 bytes result sent to driver
[2025-06-26T19:30:12.250+0700] {subprocess.py:93} INFO - 25/06/26 19:30:12 INFO Executor: Finished task 20.0 in stage 0.0 (TID 20). 3261 bytes result sent to driver
[2025-06-26T19:30:12.250+0700] {subprocess.py:93} INFO - 25/06/26 19:30:12 INFO Executor: Finished task 3.0 in stage 0.0 (TID 3). 3261 bytes result sent to driver
[2025-06-26T19:30:12.251+0700] {subprocess.py:93} INFO - 25/06/26 19:30:12 INFO Executor: Finished task 1.0 in stage 0.0 (TID 1). 3261 bytes result sent to driver
[2025-06-26T19:30:12.251+0700] {subprocess.py:93} INFO - 25/06/26 19:30:12 INFO Executor: Finished task 5.0 in stage 0.0 (TID 5). 3261 bytes result sent to driver
[2025-06-26T19:30:12.251+0700] {subprocess.py:93} INFO - 25/06/26 19:30:12 INFO Executor: Finished task 17.0 in stage 0.0 (TID 17). 3261 bytes result sent to driver
[2025-06-26T19:30:12.251+0700] {subprocess.py:93} INFO - 25/06/26 19:30:12 INFO Executor: Finished task 2.0 in stage 0.0 (TID 2). 3261 bytes result sent to driver
[2025-06-26T19:30:12.251+0700] {subprocess.py:93} INFO - 25/06/26 19:30:12 INFO Executor: Finished task 14.0 in stage 0.0 (TID 14). 3261 bytes result sent to driver
[2025-06-26T19:30:12.251+0700] {subprocess.py:93} INFO - 25/06/26 19:30:12 INFO Executor: Finished task 7.0 in stage 0.0 (TID 7). 3261 bytes result sent to driver
[2025-06-26T19:30:12.251+0700] {subprocess.py:93} INFO - 25/06/26 19:30:12 INFO Executor: Finished task 11.0 in stage 0.0 (TID 11). 3261 bytes result sent to driver
[2025-06-26T19:30:12.251+0700] {subprocess.py:93} INFO - 25/06/26 19:30:12 INFO Executor: Finished task 8.0 in stage 0.0 (TID 8). 3261 bytes result sent to driver
[2025-06-26T19:30:12.251+0700] {subprocess.py:93} INFO - 25/06/26 19:30:12 INFO Executor: Finished task 0.0 in stage 0.0 (TID 0). 3261 bytes result sent to driver
[2025-06-26T19:30:12.252+0700] {subprocess.py:93} INFO - 25/06/26 19:30:12 INFO Executor: Finished task 16.0 in stage 0.0 (TID 16). 3261 bytes result sent to driver
[2025-06-26T19:30:12.252+0700] {subprocess.py:93} INFO - 25/06/26 19:30:12 INFO Executor: Finished task 21.0 in stage 0.0 (TID 21). 3261 bytes result sent to driver
[2025-06-26T19:30:12.252+0700] {subprocess.py:93} INFO - 25/06/26 19:30:12 INFO Executor: Finished task 9.0 in stage 0.0 (TID 9). 3261 bytes result sent to driver
[2025-06-26T19:30:12.252+0700] {subprocess.py:93} INFO - 25/06/26 19:30:12 INFO Executor: Finished task 12.0 in stage 0.0 (TID 12). 3261 bytes result sent to driver
[2025-06-26T19:30:12.252+0700] {subprocess.py:93} INFO - 25/06/26 19:30:12 INFO Executor: Finished task 4.0 in stage 0.0 (TID 4). 3261 bytes result sent to driver
[2025-06-26T19:30:12.252+0700] {subprocess.py:93} INFO - 25/06/26 19:30:12 INFO Executor: Finished task 19.0 in stage 0.0 (TID 19). 3261 bytes result sent to driver
[2025-06-26T19:30:12.252+0700] {subprocess.py:93} INFO - 25/06/26 19:30:12 INFO Executor: Finished task 13.0 in stage 0.0 (TID 13). 3261 bytes result sent to driver
[2025-06-26T19:30:12.252+0700] {subprocess.py:93} INFO - 25/06/26 19:30:12 INFO Executor: Finished task 6.0 in stage 0.0 (TID 6). 3261 bytes result sent to driver
[2025-06-26T19:30:12.252+0700] {subprocess.py:93} INFO - 25/06/26 19:30:12 INFO Executor: Finished task 10.0 in stage 0.0 (TID 10). 3261 bytes result sent to driver
[2025-06-26T19:30:12.260+0700] {subprocess.py:93} INFO - 25/06/26 19:30:12 INFO TaskSetManager: Starting task 22.0 in stage 0.0 (TID 22) (localhost, executor driver, partition 22, PROCESS_LOCAL, 9215 bytes)
[2025-06-26T19:30:12.261+0700] {subprocess.py:93} INFO - 25/06/26 19:30:12 INFO Executor: Running task 22.0 in stage 0.0 (TID 22)
[2025-06-26T19:30:12.263+0700] {subprocess.py:93} INFO - 25/06/26 19:30:12 INFO TaskSetManager: Starting task 23.0 in stage 0.0 (TID 23) (localhost, executor driver, partition 23, PROCESS_LOCAL, 9215 bytes)
[2025-06-26T19:30:12.264+0700] {subprocess.py:93} INFO - 25/06/26 19:30:12 INFO Executor: Running task 23.0 in stage 0.0 (TID 23)
[2025-06-26T19:30:12.266+0700] {subprocess.py:93} INFO - 25/06/26 19:30:12 INFO TaskSetManager: Starting task 24.0 in stage 0.0 (TID 24) (localhost, executor driver, partition 24, PROCESS_LOCAL, 9215 bytes)
[2025-06-26T19:30:12.267+0700] {subprocess.py:93} INFO - 25/06/26 19:30:12 INFO Executor: Running task 24.0 in stage 0.0 (TID 24)
[2025-06-26T19:30:12.268+0700] {subprocess.py:93} INFO - 25/06/26 19:30:12 INFO TaskSetManager: Starting task 25.0 in stage 0.0 (TID 25) (localhost, executor driver, partition 25, PROCESS_LOCAL, 9215 bytes)
[2025-06-26T19:30:12.269+0700] {subprocess.py:93} INFO - 25/06/26 19:30:12 INFO Executor: Running task 25.0 in stage 0.0 (TID 25)
[2025-06-26T19:30:12.269+0700] {subprocess.py:93} INFO - 25/06/26 19:30:12 INFO TaskSetManager: Starting task 26.0 in stage 0.0 (TID 26) (localhost, executor driver, partition 26, PROCESS_LOCAL, 9215 bytes)
[2025-06-26T19:30:12.271+0700] {subprocess.py:93} INFO - 25/06/26 19:30:12 INFO Executor: Running task 26.0 in stage 0.0 (TID 26)
[2025-06-26T19:30:12.271+0700] {subprocess.py:93} INFO - 25/06/26 19:30:12 INFO TaskSetManager: Finished task 19.0 in stage 0.0 (TID 19) in 434 ms on localhost (executor driver) (1/1151)
[2025-06-26T19:30:12.273+0700] {subprocess.py:93} INFO - 25/06/26 19:30:12 INFO TaskSetManager: Finished task 8.0 in stage 0.0 (TID 8) in 442 ms on localhost (executor driver) (2/1151)
[2025-06-26T19:30:12.274+0700] {subprocess.py:93} INFO - 25/06/26 19:30:12 INFO TaskSetManager: Finished task 9.0 in stage 0.0 (TID 9) in 442 ms on localhost (executor driver) (3/1151)
[2025-06-26T19:30:12.274+0700] {subprocess.py:93} INFO - 25/06/26 19:30:12 INFO TaskSetManager: Finished task 5.0 in stage 0.0 (TID 5) in 445 ms on localhost (executor driver) (4/1151)
[2025-06-26T19:30:12.274+0700] {subprocess.py:93} INFO - 25/06/26 19:30:12 INFO TaskSetManager: Finished task 11.0 in stage 0.0 (TID 11) in 442 ms on localhost (executor driver) (5/1151)
[2025-06-26T19:30:12.275+0700] {subprocess.py:93} INFO - 25/06/26 19:30:12 INFO TaskSetManager: Starting task 27.0 in stage 0.0 (TID 27) (localhost, executor driver, partition 27, PROCESS_LOCAL, 9215 bytes)
[2025-06-26T19:30:12.277+0700] {subprocess.py:93} INFO - 25/06/26 19:30:12 INFO Executor: Running task 27.0 in stage 0.0 (TID 27)
[2025-06-26T19:30:12.278+0700] {subprocess.py:93} INFO - 25/06/26 19:30:12 INFO TaskSetManager: Starting task 28.0 in stage 0.0 (TID 28) (localhost, executor driver, partition 28, PROCESS_LOCAL, 9215 bytes)
[2025-06-26T19:30:12.278+0700] {subprocess.py:93} INFO - 25/06/26 19:30:12 INFO TaskSetManager: Finished task 21.0 in stage 0.0 (TID 21) in 442 ms on localhost (executor driver) (6/1151)
[2025-06-26T19:30:12.278+0700] {subprocess.py:93} INFO - 25/06/26 19:30:12 INFO Executor: Running task 28.0 in stage 0.0 (TID 28)
[2025-06-26T19:30:12.279+0700] {subprocess.py:93} INFO - 25/06/26 19:30:12 INFO TaskSetManager: Starting task 29.0 in stage 0.0 (TID 29) (localhost, executor driver, partition 29, PROCESS_LOCAL, 9215 bytes)
[2025-06-26T19:30:12.280+0700] {subprocess.py:93} INFO - 25/06/26 19:30:12 INFO TaskSetManager: Finished task 12.0 in stage 0.0 (TID 12) in 447 ms on localhost (executor driver) (7/1151)
[2025-06-26T19:30:12.281+0700] {subprocess.py:93} INFO - 25/06/26 19:30:12 INFO Executor: Running task 29.0 in stage 0.0 (TID 29)
[2025-06-26T19:30:12.281+0700] {subprocess.py:93} INFO - 25/06/26 19:30:12 INFO TaskSetManager: Starting task 30.0 in stage 0.0 (TID 30) (localhost, executor driver, partition 30, PROCESS_LOCAL, 9215 bytes)
[2025-06-26T19:30:12.281+0700] {subprocess.py:93} INFO - 25/06/26 19:30:12 INFO TaskSetManager: Finished task 7.0 in stage 0.0 (TID 7) in 451 ms on localhost (executor driver) (8/1151)
[2025-06-26T19:30:12.282+0700] {subprocess.py:93} INFO - 25/06/26 19:30:12 INFO Executor: Running task 30.0 in stage 0.0 (TID 30)
[2025-06-26T19:30:12.283+0700] {subprocess.py:93} INFO - 25/06/26 19:30:12 INFO TaskSetManager: Starting task 31.0 in stage 0.0 (TID 31) (localhost, executor driver, partition 31, PROCESS_LOCAL, 9215 bytes)
[2025-06-26T19:30:12.284+0700] {subprocess.py:93} INFO - 25/06/26 19:30:12 INFO TaskSetManager: Finished task 1.0 in stage 0.0 (TID 1) in 457 ms on localhost (executor driver) (9/1151)
[2025-06-26T19:30:12.284+0700] {subprocess.py:93} INFO - 25/06/26 19:30:12 INFO Executor: Running task 31.0 in stage 0.0 (TID 31)
[2025-06-26T19:30:12.284+0700] {subprocess.py:93} INFO - 25/06/26 19:30:12 INFO Executor: Finished task 22.0 in stage 0.0 (TID 22). 3218 bytes result sent to driver
[2025-06-26T19:30:12.284+0700] {subprocess.py:93} INFO - 25/06/26 19:30:12 INFO TaskSetManager: Starting task 32.0 in stage 0.0 (TID 32) (localhost, executor driver, partition 32, PROCESS_LOCAL, 9215 bytes)
[2025-06-26T19:30:12.285+0700] {subprocess.py:93} INFO - 25/06/26 19:30:12 INFO Executor: Finished task 23.0 in stage 0.0 (TID 23). 3218 bytes result sent to driver
[2025-06-26T19:30:12.286+0700] {subprocess.py:93} INFO - 25/06/26 19:30:12 INFO TaskSetManager: Finished task 2.0 in stage 0.0 (TID 2) in 458 ms on localhost (executor driver) (10/1151)
[2025-06-26T19:30:12.287+0700] {subprocess.py:93} INFO - 25/06/26 19:30:12 INFO Executor: Running task 32.0 in stage 0.0 (TID 32)
[2025-06-26T19:30:12.287+0700] {subprocess.py:93} INFO - 25/06/26 19:30:12 INFO TaskSetManager: Starting task 33.0 in stage 0.0 (TID 33) (localhost, executor driver, partition 33, PROCESS_LOCAL, 9215 bytes)
[2025-06-26T19:30:12.287+0700] {subprocess.py:93} INFO - 25/06/26 19:30:12 INFO TaskSetManager: Finished task 18.0 in stage 0.0 (TID 18) in 451 ms on localhost (executor driver) (11/1151)
[2025-06-26T19:30:12.287+0700] {subprocess.py:93} INFO - 25/06/26 19:30:12 INFO Executor: Running task 33.0 in stage 0.0 (TID 33)
[2025-06-26T19:30:12.288+0700] {subprocess.py:93} INFO - 25/06/26 19:30:12 INFO TaskSetManager: Starting task 34.0 in stage 0.0 (TID 34) (localhost, executor driver, partition 34, PROCESS_LOCAL, 9215 bytes)
[2025-06-26T19:30:12.288+0700] {subprocess.py:93} INFO - 25/06/26 19:30:12 INFO Executor: Running task 34.0 in stage 0.0 (TID 34)
[2025-06-26T19:30:12.289+0700] {subprocess.py:93} INFO - 25/06/26 19:30:12 INFO TaskSetManager: Starting task 35.0 in stage 0.0 (TID 35) (localhost, executor driver, partition 35, PROCESS_LOCAL, 9215 bytes)
[2025-06-26T19:30:12.289+0700] {subprocess.py:93} INFO - 25/06/26 19:30:12 INFO TaskSetManager: Finished task 15.0 in stage 0.0 (TID 15) in 456 ms on localhost (executor driver) (12/1151)
[2025-06-26T19:30:12.289+0700] {subprocess.py:93} INFO - 25/06/26 19:30:12 INFO Executor: Running task 35.0 in stage 0.0 (TID 35)
[2025-06-26T19:30:12.293+0700] {subprocess.py:93} INFO - 25/06/26 19:30:12 INFO TaskSetManager: Starting task 36.0 in stage 0.0 (TID 36) (localhost, executor driver, partition 36, PROCESS_LOCAL, 9215 bytes)
[2025-06-26T19:30:12.294+0700] {subprocess.py:93} INFO - 25/06/26 19:30:12 INFO TaskSetManager: Finished task 20.0 in stage 0.0 (TID 20) in 458 ms on localhost (executor driver) (13/1151)
[2025-06-26T19:30:12.294+0700] {subprocess.py:93} INFO - 25/06/26 19:30:12 INFO Executor: Running task 36.0 in stage 0.0 (TID 36)
[2025-06-26T19:30:12.295+0700] {subprocess.py:93} INFO - 25/06/26 19:30:12 INFO TaskSetManager: Starting task 37.0 in stage 0.0 (TID 37) (localhost, executor driver, partition 37, PROCESS_LOCAL, 9215 bytes)
[2025-06-26T19:30:12.296+0700] {subprocess.py:93} INFO - 25/06/26 19:30:12 INFO TaskSetManager: Finished task 0.0 in stage 0.0 (TID 0) in 499 ms on localhost (executor driver) (14/1151)
[2025-06-26T19:30:12.296+0700] {subprocess.py:93} INFO - 25/06/26 19:30:12 INFO Executor: Running task 37.0 in stage 0.0 (TID 37)
[2025-06-26T19:30:12.300+0700] {subprocess.py:93} INFO - 25/06/26 19:30:12 INFO TaskSetManager: Finished task 14.0 in stage 0.0 (TID 14) in 466 ms on localhost (executor driver) (15/1151)
[2025-06-26T19:30:12.301+0700] {subprocess.py:93} INFO - 25/06/26 19:30:12 INFO TaskSetManager: Finished task 16.0 in stage 0.0 (TID 16) in 466 ms on localhost (executor driver) (16/1151)
[2025-06-26T19:30:12.302+0700] {subprocess.py:93} INFO - 25/06/26 19:30:12 INFO TaskSetManager: Finished task 6.0 in stage 0.0 (TID 6) in 471 ms on localhost (executor driver) (17/1151)
[2025-06-26T19:30:12.304+0700] {subprocess.py:93} INFO - 25/06/26 19:30:12 INFO TaskSetManager: Starting task 38.0 in stage 0.0 (TID 38) (localhost, executor driver, partition 38, PROCESS_LOCAL, 9215 bytes)
[2025-06-26T19:30:12.306+0700] {subprocess.py:93} INFO - 25/06/26 19:30:12 INFO Executor: Finished task 24.0 in stage 0.0 (TID 24). 3218 bytes result sent to driver
[2025-06-26T19:30:12.308+0700] {subprocess.py:93} INFO - 25/06/26 19:30:12 INFO Executor: Running task 38.0 in stage 0.0 (TID 38)
[2025-06-26T19:30:12.308+0700] {subprocess.py:93} INFO - 25/06/26 19:30:12 INFO TaskSetManager: Starting task 39.0 in stage 0.0 (TID 39) (localhost, executor driver, partition 39, PROCESS_LOCAL, 9215 bytes)
[2025-06-26T19:30:12.309+0700] {subprocess.py:93} INFO - 25/06/26 19:30:12 INFO Executor: Running task 39.0 in stage 0.0 (TID 39)
[2025-06-26T19:30:12.315+0700] {subprocess.py:93} INFO - 25/06/26 19:30:12 INFO TaskSetManager: Starting task 40.0 in stage 0.0 (TID 40) (localhost, executor driver, partition 40, PROCESS_LOCAL, 9215 bytes)
[2025-06-26T19:30:12.317+0700] {subprocess.py:93} INFO - 25/06/26 19:30:12 INFO TaskSetManager: Starting task 41.0 in stage 0.0 (TID 41) (localhost, executor driver, partition 41, PROCESS_LOCAL, 9215 bytes)
[2025-06-26T19:30:12.317+0700] {subprocess.py:93} INFO - 25/06/26 19:30:12 INFO Executor: Running task 40.0 in stage 0.0 (TID 40)
[2025-06-26T19:30:12.317+0700] {subprocess.py:93} INFO - 25/06/26 19:30:12 INFO Executor: Finished task 25.0 in stage 0.0 (TID 25). 3175 bytes result sent to driver
[2025-06-26T19:30:12.318+0700] {subprocess.py:93} INFO - 25/06/26 19:30:12 INFO TaskSetManager: Finished task 3.0 in stage 0.0 (TID 3) in 489 ms on localhost (executor driver) (18/1151)
[2025-06-26T19:30:12.320+0700] {subprocess.py:93} INFO - 25/06/26 19:30:12 INFO Executor: Running task 41.0 in stage 0.0 (TID 41)
[2025-06-26T19:30:12.320+0700] {subprocess.py:93} INFO - 25/06/26 19:30:12 INFO Executor: Finished task 26.0 in stage 0.0 (TID 26). 3218 bytes result sent to driver
[2025-06-26T19:30:12.320+0700] {subprocess.py:93} INFO - 25/06/26 19:30:12 INFO TaskSetManager: Starting task 42.0 in stage 0.0 (TID 42) (localhost, executor driver, partition 42, PROCESS_LOCAL, 9215 bytes)
[2025-06-26T19:30:12.321+0700] {subprocess.py:93} INFO - 25/06/26 19:30:12 INFO TaskSetManager: Finished task 4.0 in stage 0.0 (TID 4) in 492 ms on localhost (executor driver) (19/1151)
[2025-06-26T19:30:12.321+0700] {subprocess.py:93} INFO - 25/06/26 19:30:12 INFO TaskSetManager: Starting task 43.0 in stage 0.0 (TID 43) (localhost, executor driver, partition 43, PROCESS_LOCAL, 9215 bytes)
[2025-06-26T19:30:12.322+0700] {subprocess.py:93} INFO - 25/06/26 19:30:12 INFO Executor: Running task 42.0 in stage 0.0 (TID 42)
[2025-06-26T19:30:12.325+0700] {subprocess.py:93} INFO - 25/06/26 19:30:12 INFO Executor: Running task 43.0 in stage 0.0 (TID 43)
[2025-06-26T19:30:12.325+0700] {subprocess.py:93} INFO - 25/06/26 19:30:12 INFO TaskSetManager: Starting task 44.0 in stage 0.0 (TID 44) (localhost, executor driver, partition 44, PROCESS_LOCAL, 9215 bytes)
[2025-06-26T19:30:12.325+0700] {subprocess.py:93} INFO - 25/06/26 19:30:12 INFO TaskSetManager: Starting task 45.0 in stage 0.0 (TID 45) (localhost, executor driver, partition 45, PROCESS_LOCAL, 9215 bytes)
[2025-06-26T19:30:12.325+0700] {subprocess.py:93} INFO - 25/06/26 19:30:12 INFO Executor: Running task 45.0 in stage 0.0 (TID 45)
[2025-06-26T19:30:12.325+0700] {subprocess.py:93} INFO - 25/06/26 19:30:12 INFO Executor: Running task 44.0 in stage 0.0 (TID 44)
[2025-06-26T19:30:12.325+0700] {subprocess.py:93} INFO - 25/06/26 19:30:12 INFO TaskSetManager: Starting task 46.0 in stage 0.0 (TID 46) (localhost, executor driver, partition 46, PROCESS_LOCAL, 9215 bytes)
[2025-06-26T19:30:12.328+0700] {subprocess.py:93} INFO - 25/06/26 19:30:12 INFO TaskSetManager: Finished task 13.0 in stage 0.0 (TID 13) in 493 ms on localhost (executor driver) (20/1151)
[2025-06-26T19:30:12.328+0700] {subprocess.py:93} INFO - 25/06/26 19:30:12 INFO TaskSetManager: Finished task 10.0 in stage 0.0 (TID 10) in 497 ms on localhost (executor driver) (21/1151)
[2025-06-26T19:30:12.334+0700] {subprocess.py:93} INFO - 25/06/26 19:30:12 INFO TaskSetManager: Starting task 47.0 in stage 0.0 (TID 47) (localhost, executor driver, partition 47, PROCESS_LOCAL, 9215 bytes)
[2025-06-26T19:30:12.340+0700] {subprocess.py:93} INFO - 25/06/26 19:30:12 INFO TaskSetManager: Finished task 17.0 in stage 0.0 (TID 17) in 504 ms on localhost (executor driver) (22/1151)
[2025-06-26T19:30:12.341+0700] {subprocess.py:93} INFO - 25/06/26 19:30:12 INFO Executor: Running task 47.0 in stage 0.0 (TID 47)
[2025-06-26T19:30:12.343+0700] {subprocess.py:93} INFO - 25/06/26 19:30:12 INFO Executor: Running task 46.0 in stage 0.0 (TID 46)
[2025-06-26T19:30:12.344+0700] {subprocess.py:93} INFO - 25/06/26 19:30:12 INFO TaskSetManager: Finished task 22.0 in stage 0.0 (TID 22) in 85 ms on localhost (executor driver) (23/1151)
[2025-06-26T19:30:12.346+0700] {subprocess.py:93} INFO - 25/06/26 19:30:12 INFO TaskSetManager: Finished task 23.0 in stage 0.0 (TID 23) in 84 ms on localhost (executor driver) (24/1151)
[2025-06-26T19:30:12.347+0700] {subprocess.py:93} INFO - 25/06/26 19:30:12 INFO TaskSetManager: Finished task 24.0 in stage 0.0 (TID 24) in 81 ms on localhost (executor driver) (25/1151)
[2025-06-26T19:30:12.348+0700] {subprocess.py:93} INFO - 25/06/26 19:30:12 INFO Executor: Finished task 31.0 in stage 0.0 (TID 31). 3218 bytes result sent to driver
[2025-06-26T19:30:12.348+0700] {subprocess.py:93} INFO - 25/06/26 19:30:12 INFO Executor: Finished task 33.0 in stage 0.0 (TID 33). 3218 bytes result sent to driver
[2025-06-26T19:30:12.348+0700] {subprocess.py:93} INFO - 25/06/26 19:30:12 INFO TaskSetManager: Starting task 48.0 in stage 0.0 (TID 48) (localhost, executor driver, partition 48, PROCESS_LOCAL, 9215 bytes)
[2025-06-26T19:30:12.350+0700] {subprocess.py:93} INFO - 25/06/26 19:30:12 INFO TaskSetManager: Starting task 49.0 in stage 0.0 (TID 49) (localhost, executor driver, partition 49, PROCESS_LOCAL, 9215 bytes)
[2025-06-26T19:30:12.351+0700] {subprocess.py:93} INFO - 25/06/26 19:30:12 INFO Executor: Finished task 32.0 in stage 0.0 (TID 32). 3218 bytes result sent to driver
[2025-06-26T19:30:12.351+0700] {subprocess.py:93} INFO - 25/06/26 19:30:12 INFO Executor: Running task 49.0 in stage 0.0 (TID 49)
[2025-06-26T19:30:12.351+0700] {subprocess.py:93} INFO - 25/06/26 19:30:12 INFO TaskSetManager: Starting task 50.0 in stage 0.0 (TID 50) (localhost, executor driver, partition 50, PROCESS_LOCAL, 9215 bytes)
[2025-06-26T19:30:12.352+0700] {subprocess.py:93} INFO - 25/06/26 19:30:12 INFO Executor: Running task 48.0 in stage 0.0 (TID 48)
[2025-06-26T19:30:12.352+0700] {subprocess.py:93} INFO - 25/06/26 19:30:12 INFO Executor: Running task 50.0 in stage 0.0 (TID 50)
[2025-06-26T19:30:12.358+0700] {subprocess.py:93} INFO - 25/06/26 19:30:12 INFO TaskSetManager: Finished task 26.0 in stage 0.0 (TID 26) in 83 ms on localhost (executor driver) (26/1151)
[2025-06-26T19:30:12.363+0700] {subprocess.py:93} INFO - 25/06/26 19:30:12 INFO Executor: Finished task 27.0 in stage 0.0 (TID 27). 3218 bytes result sent to driver
[2025-06-26T19:30:12.364+0700] {subprocess.py:93} INFO - 25/06/26 19:30:12 INFO TaskSetManager: Finished task 25.0 in stage 0.0 (TID 25) in 91 ms on localhost (executor driver) (27/1151)
[2025-06-26T19:30:12.365+0700] {subprocess.py:93} INFO - 25/06/26 19:30:12 INFO Executor: Finished task 30.0 in stage 0.0 (TID 30). 3218 bytes result sent to driver
[2025-06-26T19:30:12.365+0700] {subprocess.py:93} INFO - 25/06/26 19:30:12 INFO TaskSetManager: Finished task 31.0 in stage 0.0 (TID 31) in 80 ms on localhost (executor driver) (28/1151)
[2025-06-26T19:30:12.365+0700] {subprocess.py:93} INFO - 25/06/26 19:30:12 INFO Executor: Finished task 35.0 in stage 0.0 (TID 35). 3175 bytes result sent to driver
[2025-06-26T19:30:12.368+0700] {subprocess.py:93} INFO - 25/06/26 19:30:12 INFO TaskSetManager: Starting task 51.0 in stage 0.0 (TID 51) (localhost, executor driver, partition 51, PROCESS_LOCAL, 9215 bytes)
[2025-06-26T19:30:12.384+0700] {subprocess.py:93} INFO - 25/06/26 19:30:12 INFO Executor: Running task 51.0 in stage 0.0 (TID 51)
[2025-06-26T19:30:12.385+0700] {subprocess.py:93} INFO - 25/06/26 19:30:12 INFO TaskSetManager: Finished task 33.0 in stage 0.0 (TID 33) in 82 ms on localhost (executor driver) (29/1151)
[2025-06-26T19:30:12.385+0700] {subprocess.py:93} INFO - 25/06/26 19:30:12 INFO Executor: Finished task 34.0 in stage 0.0 (TID 34). 3218 bytes result sent to driver
[2025-06-26T19:30:12.386+0700] {subprocess.py:93} INFO - 25/06/26 19:30:12 INFO Executor: Finished task 29.0 in stage 0.0 (TID 29). 3218 bytes result sent to driver
[2025-06-26T19:30:12.386+0700] {subprocess.py:93} INFO - 25/06/26 19:30:12 INFO TaskSetManager: Starting task 52.0 in stage 0.0 (TID 52) (localhost, executor driver, partition 52, PROCESS_LOCAL, 9215 bytes)
[2025-06-26T19:30:12.387+0700] {subprocess.py:93} INFO - 25/06/26 19:30:12 INFO TaskSetManager: Finished task 32.0 in stage 0.0 (TID 32) in 102 ms on localhost (executor driver) (30/1151)
[2025-06-26T19:30:12.387+0700] {subprocess.py:93} INFO - 25/06/26 19:30:12 INFO Executor: Running task 52.0 in stage 0.0 (TID 52)
[2025-06-26T19:30:12.388+0700] {subprocess.py:93} INFO - 25/06/26 19:30:12 INFO Executor: Finished task 28.0 in stage 0.0 (TID 28). 3218 bytes result sent to driver
[2025-06-26T19:30:12.388+0700] {subprocess.py:93} INFO - 25/06/26 19:30:12 INFO TaskSetManager: Starting task 53.0 in stage 0.0 (TID 53) (localhost, executor driver, partition 53, PROCESS_LOCAL, 9215 bytes)
[2025-06-26T19:30:12.389+0700] {subprocess.py:93} INFO - 25/06/26 19:30:12 INFO Executor: Running task 53.0 in stage 0.0 (TID 53)
[2025-06-26T19:30:12.389+0700] {subprocess.py:93} INFO - 25/06/26 19:30:12 INFO TaskSetManager: Starting task 54.0 in stage 0.0 (TID 54) (localhost, executor driver, partition 54, PROCESS_LOCAL, 9215 bytes)
[2025-06-26T19:30:12.391+0700] {subprocess.py:93} INFO - 25/06/26 19:30:12 INFO TaskSetManager: Starting task 55.0 in stage 0.0 (TID 55) (localhost, executor driver, partition 55, PROCESS_LOCAL, 9215 bytes)
[2025-06-26T19:30:12.392+0700] {subprocess.py:93} INFO - 25/06/26 19:30:12 INFO Executor: Running task 54.0 in stage 0.0 (TID 54)
[2025-06-26T19:30:12.393+0700] {subprocess.py:93} INFO - 25/06/26 19:30:12 INFO Executor: Running task 55.0 in stage 0.0 (TID 55)
[2025-06-26T19:30:12.393+0700] {subprocess.py:93} INFO - 25/06/26 19:30:12 INFO TaskSetManager: Starting task 56.0 in stage 0.0 (TID 56) (localhost, executor driver, partition 56, PROCESS_LOCAL, 9215 bytes)
[2025-06-26T19:30:12.393+0700] {subprocess.py:93} INFO - 25/06/26 19:30:12 INFO Executor: Running task 56.0 in stage 0.0 (TID 56)
[2025-06-26T19:30:12.394+0700] {subprocess.py:93} INFO - 25/06/26 19:30:12 INFO TaskSetManager: Starting task 57.0 in stage 0.0 (TID 57) (localhost, executor driver, partition 57, PROCESS_LOCAL, 9215 bytes)
[2025-06-26T19:30:12.394+0700] {subprocess.py:93} INFO - 25/06/26 19:30:12 INFO TaskSetManager: Finished task 27.0 in stage 0.0 (TID 27) in 118 ms on localhost (executor driver) (31/1151)
[2025-06-26T19:30:12.395+0700] {subprocess.py:93} INFO - 25/06/26 19:30:12 INFO Executor: Running task 57.0 in stage 0.0 (TID 57)
[2025-06-26T19:30:12.395+0700] {subprocess.py:93} INFO - 25/06/26 19:30:12 INFO TaskSetManager: Finished task 29.0 in stage 0.0 (TID 29) in 115 ms on localhost (executor driver) (32/1151)
[2025-06-26T19:30:12.396+0700] {subprocess.py:93} INFO - 25/06/26 19:30:12 INFO TaskSetManager: Finished task 28.0 in stage 0.0 (TID 28) in 118 ms on localhost (executor driver) (33/1151)
[2025-06-26T19:30:12.405+0700] {subprocess.py:93} INFO - 25/06/26 19:30:12 INFO TaskSetManager: Finished task 30.0 in stage 0.0 (TID 30) in 120 ms on localhost (executor driver) (34/1151)
[2025-06-26T19:30:12.410+0700] {subprocess.py:93} INFO - 25/06/26 19:30:12 INFO TaskSetManager: Finished task 35.0 in stage 0.0 (TID 35) in 116 ms on localhost (executor driver) (35/1151)
[2025-06-26T19:30:12.410+0700] {subprocess.py:93} INFO - 25/06/26 19:30:12 INFO TaskSetManager: Finished task 34.0 in stage 0.0 (TID 34) in 123 ms on localhost (executor driver) (36/1151)
[2025-06-26T19:30:12.410+0700] {subprocess.py:93} INFO - 25/06/26 19:30:12 INFO Executor: Finished task 38.0 in stage 0.0 (TID 38). 3218 bytes result sent to driver
[2025-06-26T19:30:12.411+0700] {subprocess.py:93} INFO - 25/06/26 19:30:12 INFO Executor: Finished task 37.0 in stage 0.0 (TID 37). 3261 bytes result sent to driver
[2025-06-26T19:30:12.411+0700] {subprocess.py:93} INFO - 25/06/26 19:30:12 INFO Executor: Finished task 39.0 in stage 0.0 (TID 39). 3218 bytes result sent to driver
[2025-06-26T19:30:12.412+0700] {subprocess.py:93} INFO - 25/06/26 19:30:12 INFO Executor: Finished task 41.0 in stage 0.0 (TID 41). 3261 bytes result sent to driver
[2025-06-26T19:30:12.416+0700] {subprocess.py:93} INFO - 25/06/26 19:30:12 INFO TaskSetManager: Starting task 58.0 in stage 0.0 (TID 58) (localhost, executor driver, partition 58, PROCESS_LOCAL, 9215 bytes)
[2025-06-26T19:30:12.417+0700] {subprocess.py:93} INFO - 25/06/26 19:30:12 INFO Executor: Running task 58.0 in stage 0.0 (TID 58)
[2025-06-26T19:30:12.418+0700] {subprocess.py:93} INFO - 25/06/26 19:30:12 INFO TaskSetManager: Starting task 59.0 in stage 0.0 (TID 59) (localhost, executor driver, partition 59, PROCESS_LOCAL, 9215 bytes)
[2025-06-26T19:30:12.418+0700] {subprocess.py:93} INFO - 25/06/26 19:30:12 INFO Executor: Finished task 36.0 in stage 0.0 (TID 36). 3218 bytes result sent to driver
[2025-06-26T19:30:12.418+0700] {subprocess.py:93} INFO - 25/06/26 19:30:12 INFO Executor: Running task 59.0 in stage 0.0 (TID 59)
[2025-06-26T19:30:12.419+0700] {subprocess.py:93} INFO - 25/06/26 19:30:12 INFO TaskSetManager: Starting task 60.0 in stage 0.0 (TID 60) (localhost, executor driver, partition 60, PROCESS_LOCAL, 9215 bytes)
[2025-06-26T19:30:12.420+0700] {subprocess.py:93} INFO - 25/06/26 19:30:12 INFO Executor: Running task 60.0 in stage 0.0 (TID 60)
[2025-06-26T19:30:12.420+0700] {subprocess.py:93} INFO - 25/06/26 19:30:12 INFO Executor: Finished task 40.0 in stage 0.0 (TID 40). 3218 bytes result sent to driver
[2025-06-26T19:30:12.421+0700] {subprocess.py:93} INFO - 25/06/26 19:30:12 INFO TaskSetManager: Starting task 61.0 in stage 0.0 (TID 61) (localhost, executor driver, partition 61, PROCESS_LOCAL, 9215 bytes)
[2025-06-26T19:30:12.421+0700] {subprocess.py:93} INFO - 25/06/26 19:30:12 INFO Executor: Running task 61.0 in stage 0.0 (TID 61)
[2025-06-26T19:30:12.422+0700] {subprocess.py:93} INFO - 25/06/26 19:30:12 INFO Executor: Finished task 43.0 in stage 0.0 (TID 43). 3218 bytes result sent to driver
[2025-06-26T19:30:12.422+0700] {subprocess.py:93} INFO - 25/06/26 19:30:12 INFO TaskSetManager: Starting task 62.0 in stage 0.0 (TID 62) (localhost, executor driver, partition 62, PROCESS_LOCAL, 9215 bytes)
[2025-06-26T19:30:12.422+0700] {subprocess.py:93} INFO - 25/06/26 19:30:12 INFO TaskSetManager: Finished task 38.0 in stage 0.0 (TID 38) in 119 ms on localhost (executor driver) (37/1151)
[2025-06-26T19:30:12.422+0700] {subprocess.py:93} INFO - 25/06/26 19:30:12 INFO Executor: Running task 62.0 in stage 0.0 (TID 62)
[2025-06-26T19:30:12.422+0700] {subprocess.py:93} INFO - 25/06/26 19:30:12 INFO Executor: Finished task 44.0 in stage 0.0 (TID 44). 3218 bytes result sent to driver
[2025-06-26T19:30:12.423+0700] {subprocess.py:93} INFO - 25/06/26 19:30:12 INFO TaskSetManager: Starting task 63.0 in stage 0.0 (TID 63) (localhost, executor driver, partition 63, PROCESS_LOCAL, 9215 bytes)
[2025-06-26T19:30:12.424+0700] {subprocess.py:93} INFO - 25/06/26 19:30:12 INFO Executor: Running task 63.0 in stage 0.0 (TID 63)
[2025-06-26T19:30:12.424+0700] {subprocess.py:93} INFO - 25/06/26 19:30:12 INFO TaskSetManager: Starting task 64.0 in stage 0.0 (TID 64) (localhost, executor driver, partition 64, PROCESS_LOCAL, 9215 bytes)
[2025-06-26T19:30:12.425+0700] {subprocess.py:93} INFO - 25/06/26 19:30:12 INFO Executor: Running task 64.0 in stage 0.0 (TID 64)
[2025-06-26T19:30:12.425+0700] {subprocess.py:93} INFO - 25/06/26 19:30:12 INFO TaskSetManager: Starting task 65.0 in stage 0.0 (TID 65) (localhost, executor driver, partition 65, PROCESS_LOCAL, 9215 bytes)
[2025-06-26T19:30:12.426+0700] {subprocess.py:93} INFO - 25/06/26 19:30:12 INFO TaskSetManager: Finished task 41.0 in stage 0.0 (TID 41) in 109 ms on localhost (executor driver) (38/1151)
[2025-06-26T19:30:12.427+0700] {subprocess.py:93} INFO - 25/06/26 19:30:12 INFO Executor: Running task 65.0 in stage 0.0 (TID 65)
[2025-06-26T19:30:12.428+0700] {subprocess.py:93} INFO - 25/06/26 19:30:12 INFO TaskSetManager: Finished task 40.0 in stage 0.0 (TID 40) in 115 ms on localhost (executor driver) (39/1151)
[2025-06-26T19:30:12.429+0700] {subprocess.py:93} INFO - 25/06/26 19:30:12 INFO TaskSetManager: Finished task 36.0 in stage 0.0 (TID 36) in 137 ms on localhost (executor driver) (40/1151)
[2025-06-26T19:30:12.429+0700] {subprocess.py:93} INFO - 25/06/26 19:30:12 INFO TaskSetManager: Finished task 37.0 in stage 0.0 (TID 37) in 134 ms on localhost (executor driver) (41/1151)
[2025-06-26T19:30:12.429+0700] {subprocess.py:93} INFO - 25/06/26 19:30:12 INFO TaskSetManager: Finished task 39.0 in stage 0.0 (TID 39) in 124 ms on localhost (executor driver) (42/1151)
[2025-06-26T19:30:12.429+0700] {subprocess.py:93} INFO - 25/06/26 19:30:12 INFO Executor: Finished task 42.0 in stage 0.0 (TID 42). 3218 bytes result sent to driver
[2025-06-26T19:30:12.430+0700] {subprocess.py:93} INFO - 25/06/26 19:30:12 INFO TaskSetManager: Finished task 43.0 in stage 0.0 (TID 43) in 108 ms on localhost (executor driver) (43/1151)
[2025-06-26T19:30:12.431+0700] {subprocess.py:93} INFO - 25/06/26 19:30:12 INFO TaskSetManager: Finished task 44.0 in stage 0.0 (TID 44) in 108 ms on localhost (executor driver) (44/1151)
[2025-06-26T19:30:12.431+0700] {subprocess.py:93} INFO - 25/06/26 19:30:12 INFO Executor: Finished task 45.0 in stage 0.0 (TID 45). 3218 bytes result sent to driver
[2025-06-26T19:30:12.432+0700] {subprocess.py:93} INFO - 25/06/26 19:30:12 INFO Executor: Finished task 49.0 in stage 0.0 (TID 49). 3218 bytes result sent to driver
[2025-06-26T19:30:12.433+0700] {subprocess.py:93} INFO - 25/06/26 19:30:12 INFO TaskSetManager: Starting task 66.0 in stage 0.0 (TID 66) (localhost, executor driver, partition 66, PROCESS_LOCAL, 9215 bytes)
[2025-06-26T19:30:12.433+0700] {subprocess.py:93} INFO - 25/06/26 19:30:12 INFO Executor: Finished task 53.0 in stage 0.0 (TID 53). 3175 bytes result sent to driver
[2025-06-26T19:30:12.434+0700] {subprocess.py:93} INFO - 25/06/26 19:30:12 INFO TaskSetManager: Starting task 67.0 in stage 0.0 (TID 67) (localhost, executor driver, partition 67, PROCESS_LOCAL, 9215 bytes)
[2025-06-26T19:30:12.435+0700] {subprocess.py:93} INFO - 25/06/26 19:30:12 INFO Executor: Running task 66.0 in stage 0.0 (TID 66)
[2025-06-26T19:30:12.435+0700] {subprocess.py:93} INFO - 25/06/26 19:30:12 INFO Executor: Finished task 47.0 in stage 0.0 (TID 47). 3218 bytes result sent to driver
[2025-06-26T19:30:12.436+0700] {subprocess.py:93} INFO - 25/06/26 19:30:12 INFO Executor: Running task 67.0 in stage 0.0 (TID 67)
[2025-06-26T19:30:12.437+0700] {subprocess.py:93} INFO - 25/06/26 19:30:12 INFO TaskSetManager: Starting task 68.0 in stage 0.0 (TID 68) (localhost, executor driver, partition 68, PROCESS_LOCAL, 9215 bytes)
[2025-06-26T19:30:12.437+0700] {subprocess.py:93} INFO - 25/06/26 19:30:12 INFO Executor: Finished task 46.0 in stage 0.0 (TID 46). 3218 bytes result sent to driver
[2025-06-26T19:30:12.438+0700] {subprocess.py:93} INFO - 25/06/26 19:30:12 INFO Executor: Running task 68.0 in stage 0.0 (TID 68)
[2025-06-26T19:30:12.438+0700] {subprocess.py:93} INFO - 25/06/26 19:30:12 INFO Executor: Finished task 50.0 in stage 0.0 (TID 50). 3218 bytes result sent to driver
[2025-06-26T19:30:12.438+0700] {subprocess.py:93} INFO - 25/06/26 19:30:12 INFO TaskSetManager: Starting task 69.0 in stage 0.0 (TID 69) (localhost, executor driver, partition 69, PROCESS_LOCAL, 9215 bytes)
[2025-06-26T19:30:12.439+0700] {subprocess.py:93} INFO - 25/06/26 19:30:12 INFO Executor: Running task 69.0 in stage 0.0 (TID 69)
[2025-06-26T19:30:12.440+0700] {subprocess.py:93} INFO - 25/06/26 19:30:12 INFO TaskSetManager: Starting task 70.0 in stage 0.0 (TID 70) (localhost, executor driver, partition 70, PROCESS_LOCAL, 9215 bytes)
[2025-06-26T19:30:12.440+0700] {subprocess.py:93} INFO - 25/06/26 19:30:12 INFO Executor: Running task 70.0 in stage 0.0 (TID 70)
[2025-06-26T19:30:12.440+0700] {subprocess.py:93} INFO - 25/06/26 19:30:12 INFO TaskSetManager: Starting task 71.0 in stage 0.0 (TID 71) (localhost, executor driver, partition 71, PROCESS_LOCAL, 9215 bytes)
[2025-06-26T19:30:12.442+0700] {subprocess.py:93} INFO - 25/06/26 19:30:12 INFO TaskSetManager: Starting task 72.0 in stage 0.0 (TID 72) (localhost, executor driver, partition 72, PROCESS_LOCAL, 9215 bytes)
[2025-06-26T19:30:12.442+0700] {subprocess.py:93} INFO - 25/06/26 19:30:12 INFO Executor: Running task 71.0 in stage 0.0 (TID 71)
[2025-06-26T19:30:12.442+0700] {subprocess.py:93} INFO - 25/06/26 19:30:12 INFO TaskSetManager: Finished task 42.0 in stage 0.0 (TID 42) in 123 ms on localhost (executor driver) (45/1151)
[2025-06-26T19:30:12.444+0700] {subprocess.py:93} INFO - 25/06/26 19:30:12 INFO TaskSetManager: Finished task 47.0 in stage 0.0 (TID 47) in 110 ms on localhost (executor driver) (46/1151)
[2025-06-26T19:30:12.445+0700] {subprocess.py:93} INFO - 25/06/26 19:30:12 INFO TaskSetManager: Finished task 45.0 in stage 0.0 (TID 45) in 122 ms on localhost (executor driver) (47/1151)
[2025-06-26T19:30:12.447+0700] {subprocess.py:93} INFO - 25/06/26 19:30:12 INFO Executor: Running task 72.0 in stage 0.0 (TID 72)
[2025-06-26T19:30:12.449+0700] {subprocess.py:93} INFO - 25/06/26 19:30:12 INFO TaskSetManager: Finished task 50.0 in stage 0.0 (TID 50) in 98 ms on localhost (executor driver) (48/1151)
[2025-06-26T19:30:12.449+0700] {subprocess.py:93} INFO - 25/06/26 19:30:12 INFO TaskSetManager: Finished task 49.0 in stage 0.0 (TID 49) in 100 ms on localhost (executor driver) (49/1151)
[2025-06-26T19:30:12.450+0700] {subprocess.py:93} INFO - 25/06/26 19:30:12 INFO Executor: Finished task 57.0 in stage 0.0 (TID 57). 3175 bytes result sent to driver
[2025-06-26T19:30:12.450+0700] {subprocess.py:93} INFO - 25/06/26 19:30:12 INFO Executor: Finished task 52.0 in stage 0.0 (TID 52). 3218 bytes result sent to driver
[2025-06-26T19:30:12.451+0700] {subprocess.py:93} INFO - 25/06/26 19:30:12 INFO Executor: Finished task 48.0 in stage 0.0 (TID 48). 3218 bytes result sent to driver
[2025-06-26T19:30:12.451+0700] {subprocess.py:93} INFO - 25/06/26 19:30:12 INFO TaskSetManager: Starting task 73.0 in stage 0.0 (TID 73) (localhost, executor driver, partition 73, PROCESS_LOCAL, 9215 bytes)
[2025-06-26T19:30:12.452+0700] {subprocess.py:93} INFO - 25/06/26 19:30:12 INFO Executor: Finished task 56.0 in stage 0.0 (TID 56). 3175 bytes result sent to driver
[2025-06-26T19:30:12.452+0700] {subprocess.py:93} INFO - 25/06/26 19:30:12 INFO Executor: Running task 73.0 in stage 0.0 (TID 73)
[2025-06-26T19:30:12.453+0700] {subprocess.py:93} INFO - 25/06/26 19:30:12 INFO TaskSetManager: Starting task 74.0 in stage 0.0 (TID 74) (localhost, executor driver, partition 74, PROCESS_LOCAL, 9215 bytes)
[2025-06-26T19:30:12.454+0700] {subprocess.py:93} INFO - 25/06/26 19:30:12 INFO TaskSetManager: Finished task 53.0 in stage 0.0 (TID 53) in 66 ms on localhost (executor driver) (50/1151)
[2025-06-26T19:30:12.459+0700] {subprocess.py:93} INFO - 25/06/26 19:30:12 INFO Executor: Running task 74.0 in stage 0.0 (TID 74)
[2025-06-26T19:30:12.459+0700] {subprocess.py:93} INFO - 25/06/26 19:30:12 INFO TaskSetManager: Finished task 46.0 in stage 0.0 (TID 46) in 132 ms on localhost (executor driver) (51/1151)
[2025-06-26T19:30:12.459+0700] {subprocess.py:93} INFO - 25/06/26 19:30:12 INFO Executor: Finished task 55.0 in stage 0.0 (TID 55). 3175 bytes result sent to driver
[2025-06-26T19:30:12.459+0700] {subprocess.py:93} INFO - 25/06/26 19:30:12 INFO TaskSetManager: Finished task 52.0 in stage 0.0 (TID 52) in 72 ms on localhost (executor driver) (52/1151)
[2025-06-26T19:30:12.460+0700] {subprocess.py:93} INFO - 25/06/26 19:30:12 INFO Executor: Finished task 54.0 in stage 0.0 (TID 54). 3175 bytes result sent to driver
[2025-06-26T19:30:12.460+0700] {subprocess.py:93} INFO - 25/06/26 19:30:12 INFO Executor: Finished task 51.0 in stage 0.0 (TID 51). 3175 bytes result sent to driver
[2025-06-26T19:30:12.460+0700] {subprocess.py:93} INFO - 25/06/26 19:30:12 INFO Executor: Finished task 62.0 in stage 0.0 (TID 62). 3175 bytes result sent to driver
[2025-06-26T19:30:12.461+0700] {subprocess.py:93} INFO - 25/06/26 19:30:12 INFO TaskSetManager: Starting task 75.0 in stage 0.0 (TID 75) (localhost, executor driver, partition 75, PROCESS_LOCAL, 9215 bytes)
[2025-06-26T19:30:12.461+0700] {subprocess.py:93} INFO - 25/06/26 19:30:12 INFO Executor: Finished task 61.0 in stage 0.0 (TID 61). 3175 bytes result sent to driver
[2025-06-26T19:30:12.462+0700] {subprocess.py:93} INFO - 25/06/26 19:30:12 INFO TaskSetManager: Finished task 57.0 in stage 0.0 (TID 57) in 69 ms on localhost (executor driver) (53/1151)
[2025-06-26T19:30:12.462+0700] {subprocess.py:93} INFO - 25/06/26 19:30:12 INFO Executor: Finished task 59.0 in stage 0.0 (TID 59). 3175 bytes result sent to driver
[2025-06-26T19:30:12.462+0700] {subprocess.py:93} INFO - 25/06/26 19:30:12 INFO Executor: Running task 75.0 in stage 0.0 (TID 75)
[2025-06-26T19:30:12.463+0700] {subprocess.py:93} INFO - 25/06/26 19:30:12 INFO Executor: Finished task 58.0 in stage 0.0 (TID 58). 3175 bytes result sent to driver
[2025-06-26T19:30:12.464+0700] {subprocess.py:93} INFO - 25/06/26 19:30:12 INFO Executor: Finished task 64.0 in stage 0.0 (TID 64). 3175 bytes result sent to driver
[2025-06-26T19:30:12.464+0700] {subprocess.py:93} INFO - 25/06/26 19:30:12 INFO TaskSetManager: Starting task 76.0 in stage 0.0 (TID 76) (localhost, executor driver, partition 76, PROCESS_LOCAL, 9215 bytes)
[2025-06-26T19:30:12.465+0700] {subprocess.py:93} INFO - 25/06/26 19:30:12 INFO Executor: Finished task 60.0 in stage 0.0 (TID 60). 3175 bytes result sent to driver
[2025-06-26T19:30:12.465+0700] {subprocess.py:93} INFO - 25/06/26 19:30:12 INFO TaskSetManager: Finished task 56.0 in stage 0.0 (TID 56) in 74 ms on localhost (executor driver) (54/1151)
[2025-06-26T19:30:12.466+0700] {subprocess.py:93} INFO - 25/06/26 19:30:12 INFO Executor: Running task 76.0 in stage 0.0 (TID 76)
[2025-06-26T19:30:12.467+0700] {subprocess.py:93} INFO - 25/06/26 19:30:12 INFO TaskSetManager: Starting task 77.0 in stage 0.0 (TID 77) (localhost, executor driver, partition 77, PROCESS_LOCAL, 9215 bytes)
[2025-06-26T19:30:12.467+0700] {subprocess.py:93} INFO - 25/06/26 19:30:12 INFO TaskSetManager: Finished task 48.0 in stage 0.0 (TID 48) in 120 ms on localhost (executor driver) (55/1151)
[2025-06-26T19:30:12.468+0700] {subprocess.py:93} INFO - 25/06/26 19:30:12 INFO Executor: Running task 77.0 in stage 0.0 (TID 77)
[2025-06-26T19:30:12.468+0700] {subprocess.py:93} INFO - 25/06/26 19:30:12 INFO TaskSetManager: Starting task 78.0 in stage 0.0 (TID 78) (localhost, executor driver, partition 78, PROCESS_LOCAL, 9215 bytes)
[2025-06-26T19:30:12.469+0700] {subprocess.py:93} INFO - 25/06/26 19:30:12 INFO Executor: Finished task 63.0 in stage 0.0 (TID 63). 3175 bytes result sent to driver
[2025-06-26T19:30:12.469+0700] {subprocess.py:93} INFO - 25/06/26 19:30:12 INFO Executor: Running task 78.0 in stage 0.0 (TID 78)
[2025-06-26T19:30:12.469+0700] {subprocess.py:93} INFO - 25/06/26 19:30:12 INFO TaskSetManager: Finished task 55.0 in stage 0.0 (TID 55) in 79 ms on localhost (executor driver) (56/1151)
[2025-06-26T19:30:12.470+0700] {subprocess.py:93} INFO - 25/06/26 19:30:12 INFO Executor: Finished task 67.0 in stage 0.0 (TID 67). 3175 bytes result sent to driver
[2025-06-26T19:30:12.470+0700] {subprocess.py:93} INFO - 25/06/26 19:30:12 INFO Executor: Finished task 65.0 in stage 0.0 (TID 65). 3175 bytes result sent to driver
[2025-06-26T19:30:12.470+0700] {subprocess.py:93} INFO - 25/06/26 19:30:12 INFO Executor: Finished task 68.0 in stage 0.0 (TID 68). 3175 bytes result sent to driver
[2025-06-26T19:30:12.471+0700] {subprocess.py:93} INFO - 25/06/26 19:30:12 INFO Executor: Finished task 69.0 in stage 0.0 (TID 69). 3175 bytes result sent to driver
[2025-06-26T19:30:12.471+0700] {subprocess.py:93} INFO - 25/06/26 19:30:12 INFO Executor: Finished task 66.0 in stage 0.0 (TID 66). 3175 bytes result sent to driver
[2025-06-26T19:30:12.471+0700] {subprocess.py:93} INFO - 25/06/26 19:30:12 INFO TaskSetManager: Starting task 79.0 in stage 0.0 (TID 79) (localhost, executor driver, partition 79, PROCESS_LOCAL, 9215 bytes)
[2025-06-26T19:30:12.482+0700] {subprocess.py:93} INFO - 25/06/26 19:30:12 INFO TaskSetManager: Finished task 54.0 in stage 0.0 (TID 54) in 82 ms on localhost (executor driver) (57/1151)
[2025-06-26T19:30:12.483+0700] {subprocess.py:93} INFO - 25/06/26 19:30:12 INFO Executor: Running task 79.0 in stage 0.0 (TID 79)
[2025-06-26T19:30:12.485+0700] {subprocess.py:93} INFO - 25/06/26 19:30:12 INFO Executor: Finished task 72.0 in stage 0.0 (TID 72). 3261 bytes result sent to driver
[2025-06-26T19:30:12.485+0700] {subprocess.py:93} INFO - 25/06/26 19:30:12 INFO TaskSetManager: Starting task 80.0 in stage 0.0 (TID 80) (localhost, executor driver, partition 80, PROCESS_LOCAL, 9215 bytes)
[2025-06-26T19:30:12.485+0700] {subprocess.py:93} INFO - 25/06/26 19:30:12 INFO Executor: Running task 80.0 in stage 0.0 (TID 80)
[2025-06-26T19:30:12.486+0700] {subprocess.py:93} INFO - 25/06/26 19:30:12 INFO TaskSetManager: Starting task 81.0 in stage 0.0 (TID 81) (localhost, executor driver, partition 81, PROCESS_LOCAL, 9215 bytes)
[2025-06-26T19:30:12.486+0700] {subprocess.py:93} INFO - 25/06/26 19:30:12 INFO Executor: Running task 81.0 in stage 0.0 (TID 81)
[2025-06-26T19:30:12.486+0700] {subprocess.py:93} INFO - 25/06/26 19:30:12 INFO TaskSetManager: Finished task 51.0 in stage 0.0 (TID 51) in 119 ms on localhost (executor driver) (58/1151)
[2025-06-26T19:30:12.488+0700] {subprocess.py:93} INFO - 25/06/26 19:30:12 INFO TaskSetManager: Finished task 62.0 in stage 0.0 (TID 62) in 67 ms on localhost (executor driver) (59/1151)
[2025-06-26T19:30:12.490+0700] {subprocess.py:93} INFO - 25/06/26 19:30:12 INFO Executor: Finished task 70.0 in stage 0.0 (TID 70). 3218 bytes result sent to driver
[2025-06-26T19:30:12.491+0700] {subprocess.py:93} INFO - 25/06/26 19:30:12 INFO TaskSetManager: Starting task 82.0 in stage 0.0 (TID 82) (localhost, executor driver, partition 82, PROCESS_LOCAL, 9215 bytes)
[2025-06-26T19:30:12.491+0700] {subprocess.py:93} INFO - 25/06/26 19:30:12 INFO Executor: Finished task 73.0 in stage 0.0 (TID 73). 3218 bytes result sent to driver
[2025-06-26T19:30:12.491+0700] {subprocess.py:93} INFO - 25/06/26 19:30:12 INFO Executor: Finished task 71.0 in stage 0.0 (TID 71). 3218 bytes result sent to driver
[2025-06-26T19:30:12.492+0700] {subprocess.py:93} INFO - 25/06/26 19:30:12 INFO Executor: Finished task 74.0 in stage 0.0 (TID 74). 3218 bytes result sent to driver
[2025-06-26T19:30:12.492+0700] {subprocess.py:93} INFO - 25/06/26 19:30:12 INFO Executor: Running task 82.0 in stage 0.0 (TID 82)
[2025-06-26T19:30:12.493+0700] {subprocess.py:93} INFO - 25/06/26 19:30:12 INFO TaskSetManager: Starting task 83.0 in stage 0.0 (TID 83) (localhost, executor driver, partition 83, PROCESS_LOCAL, 9215 bytes)
[2025-06-26T19:30:12.493+0700] {subprocess.py:93} INFO - 25/06/26 19:30:12 INFO TaskSetManager: Finished task 59.0 in stage 0.0 (TID 59) in 76 ms on localhost (executor driver) (60/1151)
[2025-06-26T19:30:12.494+0700] {subprocess.py:93} INFO - 25/06/26 19:30:12 INFO Executor: Running task 83.0 in stage 0.0 (TID 83)
[2025-06-26T19:30:12.494+0700] {subprocess.py:93} INFO - 25/06/26 19:30:12 INFO TaskSetManager: Finished task 61.0 in stage 0.0 (TID 61) in 73 ms on localhost (executor driver) (61/1151)
[2025-06-26T19:30:12.494+0700] {subprocess.py:93} INFO - 25/06/26 19:30:12 INFO TaskSetManager: Starting task 84.0 in stage 0.0 (TID 84) (localhost, executor driver, partition 84, PROCESS_LOCAL, 9215 bytes)
[2025-06-26T19:30:12.495+0700] {subprocess.py:93} INFO - 25/06/26 19:30:12 INFO TaskSetManager: Finished task 58.0 in stage 0.0 (TID 58) in 84 ms on localhost (executor driver) (62/1151)
[2025-06-26T19:30:12.495+0700] {subprocess.py:93} INFO - 25/06/26 19:30:12 INFO Executor: Running task 84.0 in stage 0.0 (TID 84)
[2025-06-26T19:30:12.496+0700] {subprocess.py:93} INFO - 25/06/26 19:30:12 INFO TaskSetManager: Starting task 85.0 in stage 0.0 (TID 85) (localhost, executor driver, partition 85, PROCESS_LOCAL, 9215 bytes)
[2025-06-26T19:30:12.496+0700] {subprocess.py:93} INFO - 25/06/26 19:30:12 INFO Executor: Running task 85.0 in stage 0.0 (TID 85)
[2025-06-26T19:30:12.497+0700] {subprocess.py:93} INFO - 25/06/26 19:30:12 INFO TaskSetManager: Finished task 64.0 in stage 0.0 (TID 64) in 72 ms on localhost (executor driver) (63/1151)
[2025-06-26T19:30:12.498+0700] {subprocess.py:93} INFO - 25/06/26 19:30:12 INFO TaskSetManager: Finished task 60.0 in stage 0.0 (TID 60) in 78 ms on localhost (executor driver) (64/1151)
[2025-06-26T19:30:12.500+0700] {subprocess.py:93} INFO - 25/06/26 19:30:12 INFO TaskSetManager: Starting task 86.0 in stage 0.0 (TID 86) (localhost, executor driver, partition 86, PROCESS_LOCAL, 9215 bytes)
[2025-06-26T19:30:12.500+0700] {subprocess.py:93} INFO - 25/06/26 19:30:12 INFO Executor: Running task 86.0 in stage 0.0 (TID 86)
[2025-06-26T19:30:12.500+0700] {subprocess.py:93} INFO - 25/06/26 19:30:12 INFO TaskSetManager: Starting task 87.0 in stage 0.0 (TID 87) (localhost, executor driver, partition 87, PROCESS_LOCAL, 9215 bytes)
[2025-06-26T19:30:12.500+0700] {subprocess.py:93} INFO - 25/06/26 19:30:12 INFO TaskSetManager: Starting task 88.0 in stage 0.0 (TID 88) (localhost, executor driver, partition 88, PROCESS_LOCAL, 9215 bytes)
[2025-06-26T19:30:12.501+0700] {subprocess.py:93} INFO - 25/06/26 19:30:12 INFO Executor: Running task 87.0 in stage 0.0 (TID 87)
[2025-06-26T19:30:12.503+0700] {subprocess.py:93} INFO - 25/06/26 19:30:12 INFO TaskSetManager: Finished task 63.0 in stage 0.0 (TID 63) in 78 ms on localhost (executor driver) (65/1151)
[2025-06-26T19:30:12.503+0700] {subprocess.py:93} INFO - 25/06/26 19:30:12 INFO TaskSetManager: Finished task 67.0 in stage 0.0 (TID 67) in 67 ms on localhost (executor driver) (66/1151)
[2025-06-26T19:30:12.503+0700] {subprocess.py:93} INFO - 25/06/26 19:30:12 INFO Executor: Running task 88.0 in stage 0.0 (TID 88)
[2025-06-26T19:30:12.503+0700] {subprocess.py:93} INFO - 25/06/26 19:30:12 INFO TaskSetManager: Starting task 89.0 in stage 0.0 (TID 89) (localhost, executor driver, partition 89, PROCESS_LOCAL, 9215 bytes)
[2025-06-26T19:30:12.525+0700] {subprocess.py:93} INFO - 25/06/26 19:30:12 INFO Executor: Running task 89.0 in stage 0.0 (TID 89)
[2025-06-26T19:30:12.526+0700] {subprocess.py:93} INFO - 25/06/26 19:30:12 INFO TaskSetManager: Starting task 90.0 in stage 0.0 (TID 90) (localhost, executor driver, partition 90, PROCESS_LOCAL, 9215 bytes)
[2025-06-26T19:30:12.526+0700] {subprocess.py:93} INFO - 25/06/26 19:30:12 INFO TaskSetManager: Finished task 68.0 in stage 0.0 (TID 68) in 90 ms on localhost (executor driver) (67/1151)
[2025-06-26T19:30:12.526+0700] {subprocess.py:93} INFO - 25/06/26 19:30:12 INFO Executor: Running task 90.0 in stage 0.0 (TID 90)
[2025-06-26T19:30:12.527+0700] {subprocess.py:93} INFO - 25/06/26 19:30:12 INFO TaskSetManager: Finished task 65.0 in stage 0.0 (TID 65) in 101 ms on localhost (executor driver) (68/1151)
[2025-06-26T19:30:12.528+0700] {subprocess.py:93} INFO - 25/06/26 19:30:12 INFO TaskSetManager: Finished task 69.0 in stage 0.0 (TID 69) in 90 ms on localhost (executor driver) (69/1151)
[2025-06-26T19:30:12.530+0700] {subprocess.py:93} INFO - 25/06/26 19:30:12 INFO TaskSetManager: Starting task 91.0 in stage 0.0 (TID 91) (localhost, executor driver, partition 91, PROCESS_LOCAL, 9215 bytes)
[2025-06-26T19:30:12.534+0700] {subprocess.py:93} INFO - 25/06/26 19:30:12 INFO Executor: Running task 91.0 in stage 0.0 (TID 91)
[2025-06-26T19:30:12.535+0700] {subprocess.py:93} INFO - 25/06/26 19:30:12 INFO TaskSetManager: Starting task 92.0 in stage 0.0 (TID 92) (localhost, executor driver, partition 92, PROCESS_LOCAL, 9215 bytes)
[2025-06-26T19:30:12.536+0700] {subprocess.py:93} INFO - 25/06/26 19:30:12 INFO TaskSetManager: Starting task 93.0 in stage 0.0 (TID 93) (localhost, executor driver, partition 93, PROCESS_LOCAL, 9215 bytes)
[2025-06-26T19:30:12.536+0700] {subprocess.py:93} INFO - 25/06/26 19:30:12 INFO Executor: Running task 92.0 in stage 0.0 (TID 92)
[2025-06-26T19:30:12.537+0700] {subprocess.py:93} INFO - 25/06/26 19:30:12 INFO Executor: Finished task 75.0 in stage 0.0 (TID 75). 3218 bytes result sent to driver
[2025-06-26T19:30:12.537+0700] {subprocess.py:93} INFO - 25/06/26 19:30:12 INFO TaskSetManager: Finished task 66.0 in stage 0.0 (TID 66) in 104 ms on localhost (executor driver) (70/1151)
[2025-06-26T19:30:12.537+0700] {subprocess.py:93} INFO - 25/06/26 19:30:12 INFO Executor: Running task 93.0 in stage 0.0 (TID 93)
[2025-06-26T19:30:12.537+0700] {subprocess.py:93} INFO - 25/06/26 19:30:12 INFO TaskSetManager: Finished task 72.0 in stage 0.0 (TID 72) in 96 ms on localhost (executor driver) (71/1151)
[2025-06-26T19:30:12.540+0700] {subprocess.py:93} INFO - 25/06/26 19:30:12 INFO TaskSetManager: Starting task 94.0 in stage 0.0 (TID 94) (localhost, executor driver, partition 94, PROCESS_LOCAL, 9215 bytes)
[2025-06-26T19:30:12.540+0700] {subprocess.py:93} INFO - 25/06/26 19:30:12 INFO Executor: Running task 94.0 in stage 0.0 (TID 94)
[2025-06-26T19:30:12.540+0700] {subprocess.py:93} INFO - 25/06/26 19:30:12 INFO TaskSetManager: Starting task 95.0 in stage 0.0 (TID 95) (localhost, executor driver, partition 95, PROCESS_LOCAL, 9215 bytes)
[2025-06-26T19:30:12.540+0700] {subprocess.py:93} INFO - 25/06/26 19:30:12 INFO TaskSetManager: Finished task 70.0 in stage 0.0 (TID 70) in 100 ms on localhost (executor driver) (72/1151)
[2025-06-26T19:30:12.540+0700] {subprocess.py:93} INFO - 25/06/26 19:30:12 INFO Executor: Running task 95.0 in stage 0.0 (TID 95)
[2025-06-26T19:30:12.541+0700] {subprocess.py:93} INFO - 25/06/26 19:30:12 INFO TaskSetManager: Starting task 96.0 in stage 0.0 (TID 96) (localhost, executor driver, partition 96, PROCESS_LOCAL, 9215 bytes)
[2025-06-26T19:30:12.544+0700] {subprocess.py:93} INFO - 25/06/26 19:30:12 INFO TaskSetManager: Starting task 97.0 in stage 0.0 (TID 97) (localhost, executor driver, partition 97, PROCESS_LOCAL, 9215 bytes)
[2025-06-26T19:30:12.544+0700] {subprocess.py:93} INFO - 25/06/26 19:30:12 INFO Executor: Running task 96.0 in stage 0.0 (TID 96)
[2025-06-26T19:30:12.544+0700] {subprocess.py:93} INFO - 25/06/26 19:30:12 INFO Executor: Running task 97.0 in stage 0.0 (TID 97)
[2025-06-26T19:30:12.544+0700] {subprocess.py:93} INFO - 25/06/26 19:30:12 INFO TaskSetManager: Finished task 73.0 in stage 0.0 (TID 73) in 92 ms on localhost (executor driver) (73/1151)
[2025-06-26T19:30:12.544+0700] {subprocess.py:93} INFO - 25/06/26 19:30:12 INFO TaskSetManager: Finished task 74.0 in stage 0.0 (TID 74) in 92 ms on localhost (executor driver) (74/1151)
[2025-06-26T19:30:12.544+0700] {subprocess.py:93} INFO - 25/06/26 19:30:12 INFO Executor: Finished task 76.0 in stage 0.0 (TID 76). 3218 bytes result sent to driver
[2025-06-26T19:30:12.548+0700] {subprocess.py:93} INFO - 25/06/26 19:30:12 INFO Executor: Finished task 79.0 in stage 0.0 (TID 79). 3175 bytes result sent to driver
[2025-06-26T19:30:12.548+0700] {subprocess.py:93} INFO - 25/06/26 19:30:12 INFO TaskSetManager: Starting task 98.0 in stage 0.0 (TID 98) (localhost, executor driver, partition 98, PROCESS_LOCAL, 9215 bytes)
[2025-06-26T19:30:12.548+0700] {subprocess.py:93} INFO - 25/06/26 19:30:12 INFO Executor: Running task 98.0 in stage 0.0 (TID 98)
[2025-06-26T19:30:12.548+0700] {subprocess.py:93} INFO - 25/06/26 19:30:12 INFO TaskSetManager: Starting task 99.0 in stage 0.0 (TID 99) (localhost, executor driver, partition 99, PROCESS_LOCAL, 9215 bytes)
[2025-06-26T19:30:12.549+0700] {subprocess.py:93} INFO - 25/06/26 19:30:12 INFO TaskSetManager: Finished task 71.0 in stage 0.0 (TID 71) in 107 ms on localhost (executor driver) (75/1151)
[2025-06-26T19:30:12.549+0700] {subprocess.py:93} INFO - 25/06/26 19:30:12 INFO Executor: Running task 99.0 in stage 0.0 (TID 99)
[2025-06-26T19:30:12.549+0700] {subprocess.py:93} INFO - 25/06/26 19:30:12 INFO TaskSetManager: Finished task 75.0 in stage 0.0 (TID 75) in 89 ms on localhost (executor driver) (76/1151)
[2025-06-26T19:30:12.549+0700] {subprocess.py:93} INFO - 25/06/26 19:30:12 INFO Executor: Finished task 77.0 in stage 0.0 (TID 77). 3218 bytes result sent to driver
[2025-06-26T19:30:12.549+0700] {subprocess.py:93} INFO - 25/06/26 19:30:12 INFO TaskSetManager: Starting task 100.0 in stage 0.0 (TID 100) (localhost, executor driver, partition 100, PROCESS_LOCAL, 9215 bytes)
[2025-06-26T19:30:12.550+0700] {subprocess.py:93} INFO - 25/06/26 19:30:12 INFO Executor: Finished task 78.0 in stage 0.0 (TID 78). 3218 bytes result sent to driver
[2025-06-26T19:30:12.550+0700] {subprocess.py:93} INFO - 25/06/26 19:30:12 INFO TaskSetManager: Finished task 76.0 in stage 0.0 (TID 76) in 86 ms on localhost (executor driver) (77/1151)
[2025-06-26T19:30:12.550+0700] {subprocess.py:93} INFO - 25/06/26 19:30:12 INFO Executor: Running task 100.0 in stage 0.0 (TID 100)
[2025-06-26T19:30:12.550+0700] {subprocess.py:93} INFO - 25/06/26 19:30:12 INFO Executor: Finished task 85.0 in stage 0.0 (TID 85). 3175 bytes result sent to driver
[2025-06-26T19:30:12.550+0700] {subprocess.py:93} INFO - 25/06/26 19:30:12 INFO TaskSetManager: Finished task 79.0 in stage 0.0 (TID 79) in 80 ms on localhost (executor driver) (78/1151)
[2025-06-26T19:30:12.551+0700] {subprocess.py:93} INFO - 25/06/26 19:30:12 INFO TaskSetManager: Starting task 101.0 in stage 0.0 (TID 101) (localhost, executor driver, partition 101, PROCESS_LOCAL, 9215 bytes)
[2025-06-26T19:30:12.553+0700] {subprocess.py:93} INFO - 25/06/26 19:30:12 INFO TaskSetManager: Starting task 102.0 in stage 0.0 (TID 102) (localhost, executor driver, partition 102, PROCESS_LOCAL, 9215 bytes)
[2025-06-26T19:30:12.553+0700] {subprocess.py:93} INFO - 25/06/26 19:30:12 INFO Executor: Finished task 80.0 in stage 0.0 (TID 80). 3175 bytes result sent to driver
[2025-06-26T19:30:12.553+0700] {subprocess.py:93} INFO - 25/06/26 19:30:12 INFO Executor: Running task 102.0 in stage 0.0 (TID 102)
[2025-06-26T19:30:12.553+0700] {subprocess.py:93} INFO - 25/06/26 19:30:12 INFO Executor: Running task 101.0 in stage 0.0 (TID 101)
[2025-06-26T19:30:12.554+0700] {subprocess.py:93} INFO - 25/06/26 19:30:12 INFO TaskSetManager: Starting task 103.0 in stage 0.0 (TID 103) (localhost, executor driver, partition 103, PROCESS_LOCAL, 9215 bytes)
[2025-06-26T19:30:12.555+0700] {subprocess.py:93} INFO - 25/06/26 19:30:12 INFO TaskSetManager: Finished task 78.0 in stage 0.0 (TID 78) in 86 ms on localhost (executor driver) (79/1151)
[2025-06-26T19:30:12.556+0700] {subprocess.py:93} INFO - 25/06/26 19:30:12 INFO Executor: Running task 103.0 in stage 0.0 (TID 103)
[2025-06-26T19:30:12.556+0700] {subprocess.py:93} INFO - 25/06/26 19:30:12 INFO TaskSetManager: Finished task 85.0 in stage 0.0 (TID 85) in 61 ms on localhost (executor driver) (80/1151)
[2025-06-26T19:30:12.556+0700] {subprocess.py:93} INFO - 25/06/26 19:30:12 INFO TaskSetManager: Finished task 77.0 in stage 0.0 (TID 77) in 90 ms on localhost (executor driver) (81/1151)
[2025-06-26T19:30:12.556+0700] {subprocess.py:93} INFO - 25/06/26 19:30:12 INFO TaskSetManager: Finished task 80.0 in stage 0.0 (TID 80) in 72 ms on localhost (executor driver) (82/1151)
[2025-06-26T19:30:12.557+0700] {subprocess.py:93} INFO - 25/06/26 19:30:12 INFO Executor: Finished task 82.0 in stage 0.0 (TID 82). 3175 bytes result sent to driver
[2025-06-26T19:30:12.557+0700] {subprocess.py:93} INFO - 25/06/26 19:30:12 INFO Executor: Finished task 83.0 in stage 0.0 (TID 83). 3175 bytes result sent to driver
[2025-06-26T19:30:12.560+0700] {subprocess.py:93} INFO - 25/06/26 19:30:12 INFO TaskSetManager: Starting task 104.0 in stage 0.0 (TID 104) (localhost, executor driver, partition 104, PROCESS_LOCAL, 9215 bytes)
[2025-06-26T19:30:12.560+0700] {subprocess.py:93} INFO - 25/06/26 19:30:12 INFO Executor: Finished task 84.0 in stage 0.0 (TID 84). 3175 bytes result sent to driver
[2025-06-26T19:30:12.560+0700] {subprocess.py:93} INFO - 25/06/26 19:30:12 INFO Executor: Running task 104.0 in stage 0.0 (TID 104)
[2025-06-26T19:30:12.561+0700] {subprocess.py:93} INFO - 25/06/26 19:30:12 INFO TaskSetManager: Starting task 105.0 in stage 0.0 (TID 105) (localhost, executor driver, partition 105, PROCESS_LOCAL, 9215 bytes)
[2025-06-26T19:30:12.565+0700] {subprocess.py:93} INFO - 25/06/26 19:30:12 INFO Executor: Running task 105.0 in stage 0.0 (TID 105)
[2025-06-26T19:30:12.565+0700] {subprocess.py:93} INFO - 25/06/26 19:30:12 INFO TaskSetManager: Starting task 106.0 in stage 0.0 (TID 106) (localhost, executor driver, partition 106, PROCESS_LOCAL, 9215 bytes)
[2025-06-26T19:30:12.565+0700] {subprocess.py:93} INFO - 25/06/26 19:30:12 INFO Executor: Running task 106.0 in stage 0.0 (TID 106)
[2025-06-26T19:30:12.565+0700] {subprocess.py:93} INFO - 25/06/26 19:30:12 INFO TaskSetManager: Finished task 82.0 in stage 0.0 (TID 82) in 76 ms on localhost (executor driver) (83/1151)
[2025-06-26T19:30:12.568+0700] {subprocess.py:93} INFO - 25/06/26 19:30:12 INFO TaskSetManager: Finished task 83.0 in stage 0.0 (TID 83) in 75 ms on localhost (executor driver) (84/1151)
[2025-06-26T19:30:12.571+0700] {subprocess.py:93} INFO - 25/06/26 19:30:12 INFO TaskSetManager: Finished task 84.0 in stage 0.0 (TID 84) in 77 ms on localhost (executor driver) (85/1151)
[2025-06-26T19:30:12.571+0700] {subprocess.py:93} INFO - 25/06/26 19:30:12 INFO Executor: Finished task 81.0 in stage 0.0 (TID 81). 3175 bytes result sent to driver
[2025-06-26T19:30:12.571+0700] {subprocess.py:93} INFO - 25/06/26 19:30:12 INFO Executor: Finished task 86.0 in stage 0.0 (TID 86). 3175 bytes result sent to driver
[2025-06-26T19:30:12.573+0700] {subprocess.py:93} INFO - 25/06/26 19:30:12 INFO Executor: Finished task 87.0 in stage 0.0 (TID 87). 3175 bytes result sent to driver
[2025-06-26T19:30:12.574+0700] {subprocess.py:93} INFO - 25/06/26 19:30:12 INFO TaskSetManager: Starting task 107.0 in stage 0.0 (TID 107) (localhost, executor driver, partition 107, PROCESS_LOCAL, 9215 bytes)
[2025-06-26T19:30:12.576+0700] {subprocess.py:93} INFO - 25/06/26 19:30:12 INFO Executor: Running task 107.0 in stage 0.0 (TID 107)
[2025-06-26T19:30:12.577+0700] {subprocess.py:93} INFO - 25/06/26 19:30:12 INFO TaskSetManager: Finished task 81.0 in stage 0.0 (TID 81) in 92 ms on localhost (executor driver) (86/1151)
[2025-06-26T19:30:12.577+0700] {subprocess.py:93} INFO - 25/06/26 19:30:12 INFO Executor: Finished task 97.0 in stage 0.0 (TID 97). 3218 bytes result sent to driver
[2025-06-26T19:30:12.578+0700] {subprocess.py:93} INFO - 25/06/26 19:30:12 INFO Executor: Finished task 88.0 in stage 0.0 (TID 88). 3175 bytes result sent to driver
[2025-06-26T19:30:12.578+0700] {subprocess.py:93} INFO - 25/06/26 19:30:12 INFO Executor: Finished task 89.0 in stage 0.0 (TID 89). 3218 bytes result sent to driver
[2025-06-26T19:30:12.579+0700] {subprocess.py:93} INFO - 25/06/26 19:30:12 INFO TaskSetManager: Starting task 108.0 in stage 0.0 (TID 108) (localhost, executor driver, partition 108, PROCESS_LOCAL, 9215 bytes)
[2025-06-26T19:30:12.579+0700] {subprocess.py:93} INFO - 25/06/26 19:30:12 INFO TaskSetManager: Finished task 86.0 in stage 0.0 (TID 86) in 81 ms on localhost (executor driver) (87/1151)
[2025-06-26T19:30:12.580+0700] {subprocess.py:93} INFO - 25/06/26 19:30:12 INFO Executor: Finished task 94.0 in stage 0.0 (TID 94). 3175 bytes result sent to driver
[2025-06-26T19:30:12.580+0700] {subprocess.py:93} INFO - 25/06/26 19:30:12 INFO Executor: Running task 108.0 in stage 0.0 (TID 108)
[2025-06-26T19:30:12.581+0700] {subprocess.py:93} INFO - 25/06/26 19:30:12 INFO Executor: Finished task 98.0 in stage 0.0 (TID 98). 3175 bytes result sent to driver
[2025-06-26T19:30:12.582+0700] {subprocess.py:93} INFO - 25/06/26 19:30:12 INFO Executor: Finished task 91.0 in stage 0.0 (TID 91). 3175 bytes result sent to driver
[2025-06-26T19:30:12.582+0700] {subprocess.py:93} INFO - 25/06/26 19:30:12 INFO TaskSetManager: Starting task 109.0 in stage 0.0 (TID 109) (localhost, executor driver, partition 109, PROCESS_LOCAL, 9215 bytes)
[2025-06-26T19:30:12.582+0700] {subprocess.py:93} INFO - 25/06/26 19:30:12 INFO Executor: Running task 109.0 in stage 0.0 (TID 109)
[2025-06-26T19:30:12.583+0700] {subprocess.py:93} INFO - 25/06/26 19:30:12 INFO TaskSetManager: Starting task 110.0 in stage 0.0 (TID 110) (localhost, executor driver, partition 110, PROCESS_LOCAL, 9215 bytes)
[2025-06-26T19:30:12.583+0700] {subprocess.py:93} INFO - 25/06/26 19:30:12 INFO Executor: Finished task 96.0 in stage 0.0 (TID 96). 3175 bytes result sent to driver
[2025-06-26T19:30:12.583+0700] {subprocess.py:93} INFO - 25/06/26 19:30:12 INFO TaskSetManager: Finished task 87.0 in stage 0.0 (TID 87) in 84 ms on localhost (executor driver) (88/1151)
[2025-06-26T19:30:12.583+0700] {subprocess.py:93} INFO - 25/06/26 19:30:12 INFO Executor: Running task 110.0 in stage 0.0 (TID 110)
[2025-06-26T19:30:12.584+0700] {subprocess.py:93} INFO - 25/06/26 19:30:12 INFO Executor: Finished task 93.0 in stage 0.0 (TID 93). 3175 bytes result sent to driver
[2025-06-26T19:30:12.584+0700] {subprocess.py:93} INFO - 25/06/26 19:30:12 INFO TaskSetManager: Starting task 111.0 in stage 0.0 (TID 111) (localhost, executor driver, partition 111, PROCESS_LOCAL, 9215 bytes)
[2025-06-26T19:30:12.585+0700] {subprocess.py:93} INFO - 25/06/26 19:30:12 INFO TaskSetManager: Finished task 97.0 in stage 0.0 (TID 97) in 43 ms on localhost (executor driver) (89/1151)
[2025-06-26T19:30:12.585+0700] {subprocess.py:93} INFO - 25/06/26 19:30:12 INFO Executor: Finished task 101.0 in stage 0.0 (TID 101). 3175 bytes result sent to driver
[2025-06-26T19:30:12.586+0700] {subprocess.py:93} INFO - 25/06/26 19:30:12 INFO TaskSetManager: Starting task 112.0 in stage 0.0 (TID 112) (localhost, executor driver, partition 112, PROCESS_LOCAL, 9215 bytes)
[2025-06-26T19:30:12.586+0700] {subprocess.py:93} INFO - 25/06/26 19:30:12 INFO Executor: Finished task 90.0 in stage 0.0 (TID 90). 3175 bytes result sent to driver
[2025-06-26T19:30:12.587+0700] {subprocess.py:93} INFO - 25/06/26 19:30:12 INFO Executor: Finished task 92.0 in stage 0.0 (TID 92). 3175 bytes result sent to driver
[2025-06-26T19:30:12.587+0700] {subprocess.py:93} INFO - 25/06/26 19:30:12 INFO TaskSetManager: Starting task 113.0 in stage 0.0 (TID 113) (localhost, executor driver, partition 113, PROCESS_LOCAL, 9215 bytes)
[2025-06-26T19:30:12.587+0700] {subprocess.py:93} INFO - 25/06/26 19:30:12 INFO Executor: Running task 111.0 in stage 0.0 (TID 111)
[2025-06-26T19:30:12.587+0700] {subprocess.py:93} INFO - 25/06/26 19:30:12 INFO Executor: Finished task 100.0 in stage 0.0 (TID 100). 3175 bytes result sent to driver
[2025-06-26T19:30:12.588+0700] {subprocess.py:93} INFO - 25/06/26 19:30:12 INFO Executor: Running task 113.0 in stage 0.0 (TID 113)
[2025-06-26T19:30:12.588+0700] {subprocess.py:93} INFO - 25/06/26 19:30:12 INFO TaskSetManager: Starting task 114.0 in stage 0.0 (TID 114) (localhost, executor driver, partition 114, PROCESS_LOCAL, 9215 bytes)
[2025-06-26T19:30:12.589+0700] {subprocess.py:93} INFO - 25/06/26 19:30:12 INFO Executor: Running task 114.0 in stage 0.0 (TID 114)
[2025-06-26T19:30:12.590+0700] {subprocess.py:93} INFO - 25/06/26 19:30:12 INFO Executor: Finished task 95.0 in stage 0.0 (TID 95). 3175 bytes result sent to driver
[2025-06-26T19:30:12.590+0700] {subprocess.py:93} INFO - 25/06/26 19:30:12 INFO TaskSetManager: Starting task 115.0 in stage 0.0 (TID 115) (localhost, executor driver, partition 115, PROCESS_LOCAL, 9215 bytes)
[2025-06-26T19:30:12.590+0700] {subprocess.py:93} INFO - 25/06/26 19:30:12 INFO Executor: Finished task 102.0 in stage 0.0 (TID 102). 3175 bytes result sent to driver
[2025-06-26T19:30:12.590+0700] {subprocess.py:93} INFO - 25/06/26 19:30:12 INFO TaskSetManager: Starting task 116.0 in stage 0.0 (TID 116) (localhost, executor driver, partition 116, PROCESS_LOCAL, 9215 bytes)
[2025-06-26T19:30:12.591+0700] {subprocess.py:93} INFO - 25/06/26 19:30:12 INFO Executor: Running task 115.0 in stage 0.0 (TID 115)
[2025-06-26T19:30:12.591+0700] {subprocess.py:93} INFO - 25/06/26 19:30:12 INFO Executor: Running task 116.0 in stage 0.0 (TID 116)
[2025-06-26T19:30:12.591+0700] {subprocess.py:93} INFO - 25/06/26 19:30:12 INFO TaskSetManager: Starting task 117.0 in stage 0.0 (TID 117) (localhost, executor driver, partition 117, PROCESS_LOCAL, 9215 bytes)
[2025-06-26T19:30:12.600+0700] {subprocess.py:93} INFO - 25/06/26 19:30:12 INFO Executor: Running task 112.0 in stage 0.0 (TID 112)
[2025-06-26T19:30:12.601+0700] {subprocess.py:93} INFO - 25/06/26 19:30:12 INFO TaskSetManager: Finished task 88.0 in stage 0.0 (TID 88) in 100 ms on localhost (executor driver) (90/1151)
[2025-06-26T19:30:12.602+0700] {subprocess.py:93} INFO - 25/06/26 19:30:12 INFO Executor: Running task 117.0 in stage 0.0 (TID 117)
[2025-06-26T19:30:12.602+0700] {subprocess.py:93} INFO - 25/06/26 19:30:12 INFO Executor: Finished task 99.0 in stage 0.0 (TID 99). 3261 bytes result sent to driver
[2025-06-26T19:30:12.602+0700] {subprocess.py:93} INFO - 25/06/26 19:30:12 INFO TaskSetManager: Starting task 118.0 in stage 0.0 (TID 118) (localhost, executor driver, partition 118, PROCESS_LOCAL, 9215 bytes)
[2025-06-26T19:30:12.606+0700] {subprocess.py:93} INFO - 25/06/26 19:30:12 INFO Executor: Running task 118.0 in stage 0.0 (TID 118)
[2025-06-26T19:30:12.606+0700] {subprocess.py:93} INFO - 25/06/26 19:30:12 INFO TaskSetManager: Starting task 119.0 in stage 0.0 (TID 119) (localhost, executor driver, partition 119, PROCESS_LOCAL, 9215 bytes)
[2025-06-26T19:30:12.607+0700] {subprocess.py:93} INFO - 25/06/26 19:30:12 INFO TaskSetManager: Starting task 120.0 in stage 0.0 (TID 120) (localhost, executor driver, partition 120, PROCESS_LOCAL, 9215 bytes)
[2025-06-26T19:30:12.607+0700] {subprocess.py:93} INFO - 25/06/26 19:30:12 INFO Executor: Finished task 106.0 in stage 0.0 (TID 106). 3218 bytes result sent to driver
[2025-06-26T19:30:12.607+0700] {subprocess.py:93} INFO - 25/06/26 19:30:12 INFO TaskSetManager: Finished task 89.0 in stage 0.0 (TID 89) in 102 ms on localhost (executor driver) (91/1151)
[2025-06-26T19:30:12.607+0700] {subprocess.py:93} INFO - 25/06/26 19:30:12 INFO Executor: Running task 120.0 in stage 0.0 (TID 120)
[2025-06-26T19:30:12.608+0700] {subprocess.py:93} INFO - 25/06/26 19:30:12 INFO Executor: Running task 119.0 in stage 0.0 (TID 119)
[2025-06-26T19:30:12.608+0700] {subprocess.py:93} INFO - 25/06/26 19:30:12 INFO TaskSetManager: Starting task 121.0 in stage 0.0 (TID 121) (localhost, executor driver, partition 121, PROCESS_LOCAL, 9215 bytes)
[2025-06-26T19:30:12.608+0700] {subprocess.py:93} INFO - 25/06/26 19:30:12 INFO Executor: Running task 121.0 in stage 0.0 (TID 121)
[2025-06-26T19:30:12.608+0700] {subprocess.py:93} INFO - 25/06/26 19:30:12 INFO TaskSetManager: Finished task 96.0 in stage 0.0 (TID 96) in 65 ms on localhost (executor driver) (92/1151)
[2025-06-26T19:30:12.608+0700] {subprocess.py:93} INFO - 25/06/26 19:30:12 INFO TaskSetManager: Finished task 91.0 in stage 0.0 (TID 91) in 78 ms on localhost (executor driver) (93/1151)
[2025-06-26T19:30:12.610+0700] {subprocess.py:93} INFO - 25/06/26 19:30:12 INFO TaskSetManager: Starting task 122.0 in stage 0.0 (TID 122) (localhost, executor driver, partition 122, PROCESS_LOCAL, 9215 bytes)
[2025-06-26T19:30:12.611+0700] {subprocess.py:93} INFO - 25/06/26 19:30:12 INFO Executor: Running task 122.0 in stage 0.0 (TID 122)
[2025-06-26T19:30:12.612+0700] {subprocess.py:93} INFO - 25/06/26 19:30:12 INFO Executor: Finished task 104.0 in stage 0.0 (TID 104). 3218 bytes result sent to driver
[2025-06-26T19:30:12.613+0700] {subprocess.py:93} INFO - 25/06/26 19:30:12 INFO TaskSetManager: Starting task 123.0 in stage 0.0 (TID 123) (localhost, executor driver, partition 123, PROCESS_LOCAL, 9215 bytes)
[2025-06-26T19:30:12.613+0700] {subprocess.py:93} INFO - 25/06/26 19:30:12 INFO Executor: Finished task 105.0 in stage 0.0 (TID 105). 3218 bytes result sent to driver
[2025-06-26T19:30:12.613+0700] {subprocess.py:93} INFO - 25/06/26 19:30:12 INFO Executor: Finished task 107.0 in stage 0.0 (TID 107). 3218 bytes result sent to driver
[2025-06-26T19:30:12.614+0700] {subprocess.py:93} INFO - 25/06/26 19:30:12 INFO TaskSetManager: Starting task 124.0 in stage 0.0 (TID 124) (localhost, executor driver, partition 124, PROCESS_LOCAL, 9215 bytes)
[2025-06-26T19:30:12.615+0700] {subprocess.py:93} INFO - 25/06/26 19:30:12 INFO Executor: Running task 123.0 in stage 0.0 (TID 123)
[2025-06-26T19:30:12.616+0700] {subprocess.py:93} INFO - 25/06/26 19:30:12 INFO Executor: Finished task 103.0 in stage 0.0 (TID 103). 3261 bytes result sent to driver
[2025-06-26T19:30:12.616+0700] {subprocess.py:93} INFO - 25/06/26 19:30:12 INFO Executor: Finished task 108.0 in stage 0.0 (TID 108). 3218 bytes result sent to driver
[2025-06-26T19:30:12.617+0700] {subprocess.py:93} INFO - 25/06/26 19:30:12 INFO TaskSetManager: Finished task 94.0 in stage 0.0 (TID 94) in 78 ms on localhost (executor driver) (94/1151)
[2025-06-26T19:30:12.617+0700] {subprocess.py:93} INFO - 25/06/26 19:30:12 INFO Executor: Running task 124.0 in stage 0.0 (TID 124)
[2025-06-26T19:30:12.617+0700] {subprocess.py:93} INFO - 25/06/26 19:30:12 INFO TaskSetManager: Finished task 93.0 in stage 0.0 (TID 93) in 81 ms on localhost (executor driver) (95/1151)
[2025-06-26T19:30:12.617+0700] {subprocess.py:93} INFO - 25/06/26 19:30:12 INFO TaskSetManager: Finished task 98.0 in stage 0.0 (TID 98) in 72 ms on localhost (executor driver) (96/1151)
[2025-06-26T19:30:12.618+0700] {subprocess.py:93} INFO - 25/06/26 19:30:12 INFO TaskSetManager: Finished task 101.0 in stage 0.0 (TID 101) in 67 ms on localhost (executor driver) (97/1151)
[2025-06-26T19:30:12.621+0700] {subprocess.py:93} INFO - 25/06/26 19:30:12 INFO TaskSetManager: Starting task 125.0 in stage 0.0 (TID 125) (localhost, executor driver, partition 125, PROCESS_LOCAL, 9215 bytes)
[2025-06-26T19:30:12.622+0700] {subprocess.py:93} INFO - 25/06/26 19:30:12 INFO Executor: Finished task 110.0 in stage 0.0 (TID 110). 3218 bytes result sent to driver
[2025-06-26T19:30:12.622+0700] {subprocess.py:93} INFO - 25/06/26 19:30:12 INFO TaskSetManager: Starting task 126.0 in stage 0.0 (TID 126) (localhost, executor driver, partition 126, PROCESS_LOCAL, 9215 bytes)
[2025-06-26T19:30:12.623+0700] {subprocess.py:93} INFO - 25/06/26 19:30:12 INFO Executor: Running task 126.0 in stage 0.0 (TID 126)
[2025-06-26T19:30:12.624+0700] {subprocess.py:93} INFO - 25/06/26 19:30:12 INFO Executor: Running task 125.0 in stage 0.0 (TID 125)
[2025-06-26T19:30:12.624+0700] {subprocess.py:93} INFO - 25/06/26 19:30:12 INFO TaskSetManager: Starting task 127.0 in stage 0.0 (TID 127) (localhost, executor driver, partition 127, PROCESS_LOCAL, 9215 bytes)
[2025-06-26T19:30:12.626+0700] {subprocess.py:93} INFO - 25/06/26 19:30:12 INFO TaskSetManager: Starting task 128.0 in stage 0.0 (TID 128) (localhost, executor driver, partition 128, PROCESS_LOCAL, 9215 bytes)
[2025-06-26T19:30:12.626+0700] {subprocess.py:93} INFO - 25/06/26 19:30:12 INFO Executor: Running task 127.0 in stage 0.0 (TID 127)
[2025-06-26T19:30:12.648+0700] {subprocess.py:93} INFO - 25/06/26 19:30:12 INFO Executor: Running task 128.0 in stage 0.0 (TID 128)
[2025-06-26T19:30:12.650+0700] {subprocess.py:93} INFO - 25/06/26 19:30:12 INFO Executor: Finished task 114.0 in stage 0.0 (TID 114). 3218 bytes result sent to driver
[2025-06-26T19:30:12.651+0700] {subprocess.py:93} INFO - 25/06/26 19:30:12 INFO TaskSetManager: Starting task 129.0 in stage 0.0 (TID 129) (localhost, executor driver, partition 129, PROCESS_LOCAL, 9215 bytes)
[2025-06-26T19:30:12.652+0700] {subprocess.py:93} INFO - 25/06/26 19:30:12 INFO Executor: Running task 129.0 in stage 0.0 (TID 129)
[2025-06-26T19:30:12.653+0700] {subprocess.py:93} INFO - 25/06/26 19:30:12 INFO Executor: Finished task 113.0 in stage 0.0 (TID 113). 3261 bytes result sent to driver
[2025-06-26T19:30:12.653+0700] {subprocess.py:93} INFO - 25/06/26 19:30:12 INFO TaskSetManager: Starting task 130.0 in stage 0.0 (TID 130) (localhost, executor driver, partition 130, PROCESS_LOCAL, 9215 bytes)
[2025-06-26T19:30:12.653+0700] {subprocess.py:93} INFO - 25/06/26 19:30:12 INFO TaskSetManager: Finished task 90.0 in stage 0.0 (TID 90) in 150 ms on localhost (executor driver) (98/1151)
[2025-06-26T19:30:12.655+0700] {subprocess.py:93} INFO - 25/06/26 19:30:12 INFO TaskSetManager: Finished task 95.0 in stage 0.0 (TID 95) in 115 ms on localhost (executor driver) (99/1151)
[2025-06-26T19:30:12.656+0700] {subprocess.py:93} INFO - 25/06/26 19:30:12 INFO Executor: Running task 130.0 in stage 0.0 (TID 130)
[2025-06-26T19:30:12.656+0700] {subprocess.py:93} INFO - 25/06/26 19:30:12 INFO TaskSetManager: Finished task 102.0 in stage 0.0 (TID 102) in 103 ms on localhost (executor driver) (100/1151)
[2025-06-26T19:30:12.656+0700] {subprocess.py:93} INFO - 25/06/26 19:30:12 INFO TaskSetManager: Finished task 92.0 in stage 0.0 (TID 92) in 125 ms on localhost (executor driver) (101/1151)
[2025-06-26T19:30:12.656+0700] {subprocess.py:93} INFO - 25/06/26 19:30:12 INFO Executor: Finished task 111.0 in stage 0.0 (TID 111). 3218 bytes result sent to driver
[2025-06-26T19:30:12.656+0700] {subprocess.py:93} INFO - 25/06/26 19:30:12 INFO TaskSetManager: Finished task 99.0 in stage 0.0 (TID 99) in 109 ms on localhost (executor driver) (102/1151)
[2025-06-26T19:30:12.656+0700] {subprocess.py:93} INFO - 25/06/26 19:30:12 INFO TaskSetManager: Finished task 106.0 in stage 0.0 (TID 106) in 93 ms on localhost (executor driver) (103/1151)
[2025-06-26T19:30:12.656+0700] {subprocess.py:93} INFO - 25/06/26 19:30:12 INFO TaskSetManager: Finished task 100.0 in stage 0.0 (TID 100) in 107 ms on localhost (executor driver) (104/1151)
[2025-06-26T19:30:12.658+0700] {subprocess.py:93} INFO - 25/06/26 19:30:12 INFO TaskSetManager: Finished task 107.0 in stage 0.0 (TID 107) in 84 ms on localhost (executor driver) (105/1151)
[2025-06-26T19:30:12.664+0700] {subprocess.py:93} INFO - 25/06/26 19:30:12 INFO Executor: Finished task 112.0 in stage 0.0 (TID 112). 3218 bytes result sent to driver
[2025-06-26T19:30:12.664+0700] {subprocess.py:93} INFO - 25/06/26 19:30:12 INFO TaskSetManager: Finished task 103.0 in stage 0.0 (TID 103) in 106 ms on localhost (executor driver) (106/1151)
[2025-06-26T19:30:12.665+0700] {subprocess.py:93} INFO - 25/06/26 19:30:12 INFO TaskSetManager: Finished task 105.0 in stage 0.0 (TID 105) in 105 ms on localhost (executor driver) (107/1151)
[2025-06-26T19:30:12.665+0700] {subprocess.py:93} INFO - 25/06/26 19:30:12 INFO Executor: Finished task 121.0 in stage 0.0 (TID 121). 3175 bytes result sent to driver
[2025-06-26T19:30:12.667+0700] {subprocess.py:93} INFO - 25/06/26 19:30:12 INFO TaskSetManager: Starting task 131.0 in stage 0.0 (TID 131) (localhost, executor driver, partition 131, PROCESS_LOCAL, 9215 bytes)
[2025-06-26T19:30:12.667+0700] {subprocess.py:93} INFO - 25/06/26 19:30:12 INFO TaskSetManager: Finished task 104.0 in stage 0.0 (TID 104) in 109 ms on localhost (executor driver) (108/1151)
[2025-06-26T19:30:12.667+0700] {subprocess.py:93} INFO - 25/06/26 19:30:12 INFO Executor: Running task 131.0 in stage 0.0 (TID 131)
[2025-06-26T19:30:12.668+0700] {subprocess.py:93} INFO - 25/06/26 19:30:12 INFO TaskSetManager: Starting task 132.0 in stage 0.0 (TID 132) (localhost, executor driver, partition 132, PROCESS_LOCAL, 9215 bytes)
[2025-06-26T19:30:12.668+0700] {subprocess.py:93} INFO - 25/06/26 19:30:12 INFO Executor: Finished task 115.0 in stage 0.0 (TID 115). 3218 bytes result sent to driver
[2025-06-26T19:30:12.669+0700] {subprocess.py:93} INFO - 25/06/26 19:30:12 INFO TaskSetManager: Finished task 110.0 in stage 0.0 (TID 110) in 86 ms on localhost (executor driver) (109/1151)
[2025-06-26T19:30:12.669+0700] {subprocess.py:93} INFO - 25/06/26 19:30:12 INFO TaskSetManager: Finished task 108.0 in stage 0.0 (TID 108) in 90 ms on localhost (executor driver) (110/1151)
[2025-06-26T19:30:12.669+0700] {subprocess.py:93} INFO - 25/06/26 19:30:12 INFO Executor: Running task 132.0 in stage 0.0 (TID 132)
[2025-06-26T19:30:12.669+0700] {subprocess.py:93} INFO - 25/06/26 19:30:12 INFO Executor: Finished task 119.0 in stage 0.0 (TID 119). 3175 bytes result sent to driver
[2025-06-26T19:30:12.669+0700] {subprocess.py:93} INFO - 25/06/26 19:30:12 INFO TaskSetManager: Starting task 133.0 in stage 0.0 (TID 133) (localhost, executor driver, partition 133, PROCESS_LOCAL, 9215 bytes)
[2025-06-26T19:30:12.670+0700] {subprocess.py:93} INFO - 25/06/26 19:30:12 INFO TaskSetManager: Starting task 134.0 in stage 0.0 (TID 134) (localhost, executor driver, partition 134, PROCESS_LOCAL, 9215 bytes)
[2025-06-26T19:30:12.670+0700] {subprocess.py:93} INFO - 25/06/26 19:30:12 INFO TaskSetManager: Finished task 114.0 in stage 0.0 (TID 114) in 83 ms on localhost (executor driver) (111/1151)
[2025-06-26T19:30:12.670+0700] {subprocess.py:93} INFO - 25/06/26 19:30:12 INFO Executor: Running task 133.0 in stage 0.0 (TID 133)
[2025-06-26T19:30:12.670+0700] {subprocess.py:93} INFO - 25/06/26 19:30:12 INFO Executor: Running task 134.0 in stage 0.0 (TID 134)
