[2025-06-26T20:10:03.624+0700] {local_task_job_runner.py:120} INFO - ::group::Pre task execution logs
[2025-06-26T20:10:03.646+0700] {taskinstance.py:2073} INFO - Dependencies all met for dep_context=non-requeueable deps ti=<TaskInstance: send_data_to_powerbi.compact_csv_to_one_file scheduled__2025-06-26T13:00:00+00:00 [queued]>
[2025-06-26T20:10:03.654+0700] {taskinstance.py:2073} INFO - Dependencies all met for dep_context=requeueable deps ti=<TaskInstance: send_data_to_powerbi.compact_csv_to_one_file scheduled__2025-06-26T13:00:00+00:00 [queued]>
[2025-06-26T20:10:03.654+0700] {taskinstance.py:2303} INFO - Starting attempt 1 of 3
[2025-06-26T20:10:03.675+0700] {taskinstance.py:2327} INFO - Executing <Task(BashOperator): compact_csv_to_one_file> on 2025-06-26 13:00:00+00:00
[2025-06-26T20:10:03.681+0700] {standard_task_runner.py:63} INFO - Started process 121878 to run task
[2025-06-26T20:10:03.685+0700] {standard_task_runner.py:90} INFO - Running: ['airflow', 'tasks', 'run', 'send_data_to_powerbi', 'compact_csv_to_one_file', 'scheduled__2025-06-26T13:00:00+00:00', '--job-id', '66', '--raw', '--subdir', 'DAGS_FOLDER/load_power_bi.py', '--cfg-path', '/tmp/tmp9blsf2um']
[2025-06-26T20:10:03.686+0700] {standard_task_runner.py:91} INFO - Job 66: Subtask compact_csv_to_one_file
[2025-06-26T20:10:03.726+0700] {task_command.py:426} INFO - Running <TaskInstance: send_data_to_powerbi.compact_csv_to_one_file scheduled__2025-06-26T13:00:00+00:00 [running]> on host Panda
[2025-06-26T20:10:03.799+0700] {taskinstance.py:2644} INFO - Exporting env vars: AIRFLOW_CTX_DAG_OWNER='group_03' AIRFLOW_CTX_DAG_ID='send_data_to_powerbi' AIRFLOW_CTX_TASK_ID='compact_csv_to_one_file' AIRFLOW_CTX_EXECUTION_DATE='2025-06-26T13:00:00+00:00' AIRFLOW_CTX_TRY_NUMBER='1' AIRFLOW_CTX_DAG_RUN_ID='scheduled__2025-06-26T13:00:00+00:00'
[2025-06-26T20:10:03.800+0700] {taskinstance.py:430} INFO - ::endgroup::
[2025-06-26T20:10:03.801+0700] {subprocess.py:63} INFO - Tmp dir root location: /tmp
[2025-06-26T20:10:03.802+0700] {subprocess.py:75} INFO - Running command: ['/usr/bin/bash', '-c', 'spark-submit /home/panda/Documents/ODAP/Project/hadoop/compact_csv.py && sleep 10']
[2025-06-26T20:10:03.817+0700] {subprocess.py:86} INFO - Output:
[2025-06-26T20:10:06.112+0700] {subprocess.py:93} INFO - 25/06/26 20:10:06 INFO SparkContext: Running Spark version 3.5.5
[2025-06-26T20:10:06.115+0700] {subprocess.py:93} INFO - 25/06/26 20:10:06 INFO SparkContext: OS info Linux, 6.11.0-26-generic, amd64
[2025-06-26T20:10:06.116+0700] {subprocess.py:93} INFO - 25/06/26 20:10:06 INFO SparkContext: Java version 11.0.27
[2025-06-26T20:10:06.291+0700] {subprocess.py:93} INFO - 25/06/26 20:10:06 INFO ResourceUtils: ==============================================================
[2025-06-26T20:10:06.291+0700] {subprocess.py:93} INFO - 25/06/26 20:10:06 INFO ResourceUtils: No custom resources configured for spark.driver.
[2025-06-26T20:10:06.291+0700] {subprocess.py:93} INFO - 25/06/26 20:10:06 INFO ResourceUtils: ==============================================================
[2025-06-26T20:10:06.291+0700] {subprocess.py:93} INFO - 25/06/26 20:10:06 INFO SparkContext: Submitted application: CompactSmallFiles
[2025-06-26T20:10:06.314+0700] {subprocess.py:93} INFO - 25/06/26 20:10:06 INFO ResourceProfile: Default ResourceProfile created, executor resources: Map(cores -> name: cores, amount: 1, script: , vendor: , memory -> name: memory, amount: 1024, script: , vendor: , offHeap -> name: offHeap, amount: 0, script: , vendor: ), task resources: Map(cpus -> name: cpus, amount: 1.0)
[2025-06-26T20:10:06.326+0700] {subprocess.py:93} INFO - 25/06/26 20:10:06 INFO ResourceProfile: Limiting resource is cpu
[2025-06-26T20:10:06.326+0700] {subprocess.py:93} INFO - 25/06/26 20:10:06 INFO ResourceProfileManager: Added ResourceProfile id: 0
[2025-06-26T20:10:06.391+0700] {subprocess.py:93} INFO - 25/06/26 20:10:06 INFO SecurityManager: Changing view acls to: panda
[2025-06-26T20:10:06.392+0700] {subprocess.py:93} INFO - 25/06/26 20:10:06 INFO SecurityManager: Changing modify acls to: panda
[2025-06-26T20:10:06.392+0700] {subprocess.py:93} INFO - 25/06/26 20:10:06 INFO SecurityManager: Changing view acls groups to:
[2025-06-26T20:10:06.393+0700] {subprocess.py:93} INFO - 25/06/26 20:10:06 INFO SecurityManager: Changing modify acls groups to:
[2025-06-26T20:10:06.393+0700] {subprocess.py:93} INFO - 25/06/26 20:10:06 INFO SecurityManager: SecurityManager: authentication disabled; ui acls disabled; users with view permissions: panda; groups with view permissions: EMPTY; users with modify permissions: panda; groups with modify permissions: EMPTY
[2025-06-26T20:10:06.650+0700] {subprocess.py:93} INFO - 25/06/26 20:10:06 INFO Utils: Successfully started service 'sparkDriver' on port 35641.
[2025-06-26T20:10:06.690+0700] {subprocess.py:93} INFO - 25/06/26 20:10:06 INFO SparkEnv: Registering MapOutputTracker
[2025-06-26T20:10:06.734+0700] {subprocess.py:93} INFO - 25/06/26 20:10:06 INFO SparkEnv: Registering BlockManagerMaster
[2025-06-26T20:10:06.761+0700] {subprocess.py:93} INFO - 25/06/26 20:10:06 INFO BlockManagerMasterEndpoint: Using org.apache.spark.storage.DefaultTopologyMapper for getting topology information
[2025-06-26T20:10:06.762+0700] {subprocess.py:93} INFO - 25/06/26 20:10:06 INFO BlockManagerMasterEndpoint: BlockManagerMasterEndpoint up
[2025-06-26T20:10:06.767+0700] {subprocess.py:93} INFO - 25/06/26 20:10:06 INFO SparkEnv: Registering BlockManagerMasterHeartbeat
[2025-06-26T20:10:06.798+0700] {subprocess.py:93} INFO - 25/06/26 20:10:06 INFO DiskBlockManager: Created local directory at /tmp/blockmgr-77ecb39f-82f5-4913-a624-309bb2329e13
[2025-06-26T20:10:06.819+0700] {subprocess.py:93} INFO - 25/06/26 20:10:06 INFO MemoryStore: MemoryStore started with capacity 434.4 MiB
[2025-06-26T20:10:06.838+0700] {subprocess.py:93} INFO - 25/06/26 20:10:06 INFO SparkEnv: Registering OutputCommitCoordinator
[2025-06-26T20:10:07.028+0700] {subprocess.py:93} INFO - 25/06/26 20:10:07 INFO JettyUtils: Start Jetty 127.0.0.1:4040 for SparkUI
[2025-06-26T20:10:07.093+0700] {subprocess.py:93} INFO - 25/06/26 20:10:07 WARN Utils: Service 'SparkUI' could not bind on port 4040. Attempting port 4041.
[2025-06-26T20:10:07.111+0700] {subprocess.py:93} INFO - 25/06/26 20:10:07 INFO Utils: Successfully started service 'SparkUI' on port 4041.
[2025-06-26T20:10:07.221+0700] {subprocess.py:93} INFO - 25/06/26 20:10:07 INFO Executor: Starting executor ID driver on host localhost
[2025-06-26T20:10:07.221+0700] {subprocess.py:93} INFO - 25/06/26 20:10:07 INFO Executor: OS info Linux, 6.11.0-26-generic, amd64
[2025-06-26T20:10:07.222+0700] {subprocess.py:93} INFO - 25/06/26 20:10:07 INFO Executor: Java version 11.0.27
[2025-06-26T20:10:07.230+0700] {subprocess.py:93} INFO - 25/06/26 20:10:07 INFO Executor: Starting executor with user classpath (userClassPathFirst = false): ''
[2025-06-26T20:10:07.231+0700] {subprocess.py:93} INFO - 25/06/26 20:10:07 INFO Executor: Created or updated repl class loader org.apache.spark.util.MutableURLClassLoader@5aa5b801 for default.
[2025-06-26T20:10:07.258+0700] {subprocess.py:93} INFO - 25/06/26 20:10:07 INFO Utils: Successfully started service 'org.apache.spark.network.netty.NettyBlockTransferService' on port 46795.
[2025-06-26T20:10:07.259+0700] {subprocess.py:93} INFO - 25/06/26 20:10:07 INFO NettyBlockTransferService: Server created on localhost:46795
[2025-06-26T20:10:07.262+0700] {subprocess.py:93} INFO - 25/06/26 20:10:07 INFO BlockManager: Using org.apache.spark.storage.RandomBlockReplicationPolicy for block replication policy
[2025-06-26T20:10:07.270+0700] {subprocess.py:93} INFO - 25/06/26 20:10:07 INFO BlockManagerMaster: Registering BlockManager BlockManagerId(driver, localhost, 46795, None)
[2025-06-26T20:10:07.274+0700] {subprocess.py:93} INFO - 25/06/26 20:10:07 INFO BlockManagerMasterEndpoint: Registering block manager localhost:46795 with 434.4 MiB RAM, BlockManagerId(driver, localhost, 46795, None)
[2025-06-26T20:10:07.277+0700] {subprocess.py:93} INFO - 25/06/26 20:10:07 INFO BlockManagerMaster: Registered BlockManager BlockManagerId(driver, localhost, 46795, None)
[2025-06-26T20:10:07.279+0700] {subprocess.py:93} INFO - 25/06/26 20:10:07 INFO BlockManager: Initialized BlockManager: BlockManagerId(driver, localhost, 46795, None)
[2025-06-26T20:10:07.806+0700] {subprocess.py:93} INFO - 25/06/26 20:10:07 INFO SharedState: Setting hive.metastore.warehouse.dir ('null') to the value of spark.sql.warehouse.dir.
[2025-06-26T20:10:07.814+0700] {subprocess.py:93} INFO - 25/06/26 20:10:07 INFO SharedState: Warehouse path is 'file:/tmp/airflowtmp1390ay68/spark-warehouse'.
[2025-06-26T20:10:09.114+0700] {subprocess.py:93} INFO - 25/06/26 20:10:09 INFO MetadataLogFileIndex: Reading streaming file log from hdfs://localhost:9000/transactions_by_hour/_spark_metadata
[2025-06-26T20:10:09.195+0700] {subprocess.py:93} INFO - 25/06/26 20:10:09 INFO FileStreamSinkLog: BatchIds found from listing: 2038, 2039, 2040, 2041, 2042, 2043, 2044, 2045, 2046, 2047, 2048, 2049, 2050, 2051, 2052, 2053, 2054, 2055, 2056, 2057, 2058, 2059, 2060, 2061, 2062, 2063, 2064, 2065, 2066, 2067, 2068, 2069, 2070, 2071, 2072, 2073, 2074, 2075, 2076, 2077, 2078, 2079, 2080, 2081, 2082, 2083, 2084, 2085, 2086, 2087, 2088, 2089, 2090, 2091, 2092, 2093, 2094, 2095, 2096, 2097, 2098, 2099, 2100, 2101, 2102, 2103, 2104, 2105, 2106, 2107, 2108, 2109, 2110, 2111, 2112, 2113, 2114, 2115, 2116, 2117, 2118, 2119, 2120, 2121, 2122, 2123, 2124, 2125, 2126, 2127, 2128, 2129, 2130, 2131, 2132, 2133, 2134, 2135, 2136, 2137, 2138, 2139, 2140, 2141, 2142, 2143, 2144, 2145, 2146, 2147, 2148, 2149, 2150, 2151, 2152, 2153, 2154, 2155, 2156, 2157, 2158, 2159, 2160, 2161, 2162, 2163, 2164, 2165, 2166, 2167, 2168, 2169, 2170, 2171, 2172, 2173, 2174, 2175, 2176, 2177, 2178, 2179, 2180, 2181, 2182, 2183, 2184, 2185, 2186, 2187, 2188, 2189, 2190, 2191, 2192, 2193, 2194, 2195, 2196, 2197, 2198, 2199, 2200, 2201, 2202, 2203, 2204, 2205, 2206, 2207, 2208, 2209, 2210, 2211, 2212, 2213, 2214, 2215, 2216, 2217, 2218, 2219, 2220, 2221, 2222, 2223, 2224, 2225, 2226, 2227, 2228, 2229, 2230, 2231, 2232, 2233, 2234, 2235, 2236, 2237, 2238, 2239, 2240, 2241, 2242, 2243, 2244, 2245, 2246, 2247, 2248, 2249, 2250, 2251, 2252, 2253, 2254, 2255, 2256, 2257, 2258, 2259, 2260, 2261, 2262, 2263, 2264, 2265, 2266, 2267, 2268, 2269, 2270, 2271, 2272, 2273, 2274, 2275, 2276, 2277, 2278, 2279, 2280, 2281, 2282, 2283, 2284, 2285, 2286, 2287, 2288, 2289, 2290, 2291, 2292, 2293, 2294, 2295, 2296, 2297, 2298, 2299, 2300, 2301, 2302, 2303, 2304, 2305, 2306, 2307, 2308, 2309, 2310, 2311, 2312, 2313, 2314, 2315, 2316, 2317, 2318, 2319, 2320, 2321, 2322, 2323, 2324, 2325, 2326, 2327, 2328, 2329, 2330, 2331, 2332, 2333
[2025-06-26T20:10:09.227+0700] {subprocess.py:93} INFO - 25/06/26 20:10:09 INFO FileStreamSinkLog: Set the compact interval to 10 [defaultCompactInterval: 10]
[2025-06-26T20:10:09.904+0700] {subprocess.py:93} INFO - 25/06/26 20:10:09 INFO HadoopFSUtils: Listing leaf files and directories in parallel under 2334 paths. The first several paths are: hdfs://localhost:9000/transactions_by_hour/part-00000-35848e14-b857-426e-8939-db9c96261483-c000.csv, hdfs://localhost:9000/transactions_by_hour/part-00000-d7ab39d9-b4ef-4e2e-b472-4c1883c38273-c000.csv, hdfs://localhost:9000/transactions_by_hour/part-00000-cce2d287-6512-49d1-aa31-f452c0dcdaf9-c000.csv, hdfs://localhost:9000/transactions_by_hour/part-00000-ac8933a1-5bf2-4814-a228-6604c7045e4c-c000.csv, hdfs://localhost:9000/transactions_by_hour/part-00000-9c60d322-8794-4968-a7a5-364181d16d94-c000.csv, hdfs://localhost:9000/transactions_by_hour/part-00000-76895572-6aa7-4225-8325-6962e0c98ee2-c000.csv, hdfs://localhost:9000/transactions_by_hour/part-00000-a92a3ce5-6132-4e9e-8e69-11e47f72f0a2-c000.csv, hdfs://localhost:9000/transactions_by_hour/part-00000-b48a08d4-d847-4307-b612-e35a8f471916-c000.csv, hdfs://localhost:9000/transactions_by_hour/part-00000-e8f1544c-6d23-403f-a02b-06e9bef1638a-c000.csv, hdfs://localhost:9000/transactions_by_hour/part-00000-08040c60-6fee-4dcc-b2e9-af62320fb049-c000.csv.
[2025-06-26T20:10:10.339+0700] {subprocess.py:93} INFO - 25/06/26 20:10:10 INFO SparkContext: Starting job: csv at NativeMethodAccessorImpl.java:0
[2025-06-26T20:10:10.372+0700] {subprocess.py:93} INFO - 25/06/26 20:10:10 INFO DAGScheduler: Got job 0 (csv at NativeMethodAccessorImpl.java:0) with 2334 output partitions
[2025-06-26T20:10:10.372+0700] {subprocess.py:93} INFO - 25/06/26 20:10:10 INFO DAGScheduler: Final stage: ResultStage 0 (csv at NativeMethodAccessorImpl.java:0)
[2025-06-26T20:10:10.372+0700] {subprocess.py:93} INFO - 25/06/26 20:10:10 INFO DAGScheduler: Parents of final stage: List()
[2025-06-26T20:10:10.375+0700] {subprocess.py:93} INFO - 25/06/26 20:10:10 INFO DAGScheduler: Missing parents: List()
[2025-06-26T20:10:10.381+0700] {subprocess.py:93} INFO - 25/06/26 20:10:10 INFO DAGScheduler: Submitting ResultStage 0 (MapPartitionsRDD[1] at csv at NativeMethodAccessorImpl.java:0), which has no missing parents
[2025-06-26T20:10:10.516+0700] {subprocess.py:93} INFO - 25/06/26 20:10:10 INFO MemoryStore: Block broadcast_0 stored as values in memory (estimated size 103.2 KiB, free 434.3 MiB)
[2025-06-26T20:10:10.552+0700] {subprocess.py:93} INFO - 25/06/26 20:10:10 INFO MemoryStore: Block broadcast_0_piece0 stored as bytes in memory (estimated size 37.3 KiB, free 434.3 MiB)
[2025-06-26T20:10:10.555+0700] {subprocess.py:93} INFO - 25/06/26 20:10:10 INFO BlockManagerInfo: Added broadcast_0_piece0 in memory on localhost:46795 (size: 37.3 KiB, free: 434.4 MiB)
[2025-06-26T20:10:10.559+0700] {subprocess.py:93} INFO - 25/06/26 20:10:10 INFO SparkContext: Created broadcast 0 from broadcast at DAGScheduler.scala:1585
[2025-06-26T20:10:10.588+0700] {subprocess.py:93} INFO - 25/06/26 20:10:10 INFO DAGScheduler: Submitting 2334 missing tasks from ResultStage 0 (MapPartitionsRDD[1] at csv at NativeMethodAccessorImpl.java:0) (first 15 tasks are for partitions Vector(0, 1, 2, 3, 4, 5, 6, 7, 8, 9, 10, 11, 12, 13, 14))
[2025-06-26T20:10:10.590+0700] {subprocess.py:93} INFO - 25/06/26 20:10:10 INFO TaskSchedulerImpl: Adding task set 0.0 with 2334 tasks resource profile 0
[2025-06-26T20:10:10.673+0700] {subprocess.py:93} INFO - 25/06/26 20:10:10 INFO TaskSetManager: Starting task 0.0 in stage 0.0 (TID 0) (localhost, executor driver, partition 0, PROCESS_LOCAL, 9215 bytes)
[2025-06-26T20:10:10.676+0700] {subprocess.py:93} INFO - 25/06/26 20:10:10 INFO TaskSetManager: Starting task 1.0 in stage 0.0 (TID 1) (localhost, executor driver, partition 1, PROCESS_LOCAL, 9215 bytes)
[2025-06-26T20:10:10.677+0700] {subprocess.py:93} INFO - 25/06/26 20:10:10 INFO TaskSetManager: Starting task 2.0 in stage 0.0 (TID 2) (localhost, executor driver, partition 2, PROCESS_LOCAL, 9215 bytes)
[2025-06-26T20:10:10.677+0700] {subprocess.py:93} INFO - 25/06/26 20:10:10 INFO TaskSetManager: Starting task 3.0 in stage 0.0 (TID 3) (localhost, executor driver, partition 3, PROCESS_LOCAL, 9215 bytes)
[2025-06-26T20:10:10.677+0700] {subprocess.py:93} INFO - 25/06/26 20:10:10 INFO TaskSetManager: Starting task 4.0 in stage 0.0 (TID 4) (localhost, executor driver, partition 4, PROCESS_LOCAL, 9215 bytes)
[2025-06-26T20:10:10.678+0700] {subprocess.py:93} INFO - 25/06/26 20:10:10 INFO TaskSetManager: Starting task 5.0 in stage 0.0 (TID 5) (localhost, executor driver, partition 5, PROCESS_LOCAL, 9215 bytes)
[2025-06-26T20:10:10.678+0700] {subprocess.py:93} INFO - 25/06/26 20:10:10 INFO TaskSetManager: Starting task 6.0 in stage 0.0 (TID 6) (localhost, executor driver, partition 6, PROCESS_LOCAL, 9215 bytes)
[2025-06-26T20:10:10.680+0700] {subprocess.py:93} INFO - 25/06/26 20:10:10 INFO TaskSetManager: Starting task 7.0 in stage 0.0 (TID 7) (localhost, executor driver, partition 7, PROCESS_LOCAL, 9215 bytes)
[2025-06-26T20:10:10.681+0700] {subprocess.py:93} INFO - 25/06/26 20:10:10 INFO TaskSetManager: Starting task 8.0 in stage 0.0 (TID 8) (localhost, executor driver, partition 8, PROCESS_LOCAL, 9215 bytes)
[2025-06-26T20:10:10.681+0700] {subprocess.py:93} INFO - 25/06/26 20:10:10 INFO TaskSetManager: Starting task 9.0 in stage 0.0 (TID 9) (localhost, executor driver, partition 9, PROCESS_LOCAL, 9215 bytes)
[2025-06-26T20:10:10.681+0700] {subprocess.py:93} INFO - 25/06/26 20:10:10 INFO TaskSetManager: Starting task 10.0 in stage 0.0 (TID 10) (localhost, executor driver, partition 10, PROCESS_LOCAL, 9215 bytes)
[2025-06-26T20:10:10.682+0700] {subprocess.py:93} INFO - 25/06/26 20:10:10 INFO TaskSetManager: Starting task 11.0 in stage 0.0 (TID 11) (localhost, executor driver, partition 11, PROCESS_LOCAL, 9215 bytes)
[2025-06-26T20:10:10.682+0700] {subprocess.py:93} INFO - 25/06/26 20:10:10 INFO TaskSetManager: Starting task 12.0 in stage 0.0 (TID 12) (localhost, executor driver, partition 12, PROCESS_LOCAL, 9215 bytes)
[2025-06-26T20:10:10.682+0700] {subprocess.py:93} INFO - 25/06/26 20:10:10 INFO TaskSetManager: Starting task 13.0 in stage 0.0 (TID 13) (localhost, executor driver, partition 13, PROCESS_LOCAL, 9215 bytes)
[2025-06-26T20:10:10.684+0700] {subprocess.py:93} INFO - 25/06/26 20:10:10 INFO TaskSetManager: Starting task 14.0 in stage 0.0 (TID 14) (localhost, executor driver, partition 14, PROCESS_LOCAL, 9215 bytes)
[2025-06-26T20:10:10.685+0700] {subprocess.py:93} INFO - 25/06/26 20:10:10 INFO TaskSetManager: Starting task 15.0 in stage 0.0 (TID 15) (localhost, executor driver, partition 15, PROCESS_LOCAL, 9215 bytes)
[2025-06-26T20:10:10.686+0700] {subprocess.py:93} INFO - 25/06/26 20:10:10 INFO TaskSetManager: Starting task 16.0 in stage 0.0 (TID 16) (localhost, executor driver, partition 16, PROCESS_LOCAL, 9215 bytes)
[2025-06-26T20:10:10.686+0700] {subprocess.py:93} INFO - 25/06/26 20:10:10 INFO TaskSetManager: Starting task 17.0 in stage 0.0 (TID 17) (localhost, executor driver, partition 17, PROCESS_LOCAL, 9215 bytes)
[2025-06-26T20:10:10.686+0700] {subprocess.py:93} INFO - 25/06/26 20:10:10 INFO TaskSetManager: Starting task 18.0 in stage 0.0 (TID 18) (localhost, executor driver, partition 18, PROCESS_LOCAL, 9215 bytes)
[2025-06-26T20:10:10.686+0700] {subprocess.py:93} INFO - 25/06/26 20:10:10 INFO TaskSetManager: Starting task 19.0 in stage 0.0 (TID 19) (localhost, executor driver, partition 19, PROCESS_LOCAL, 9215 bytes)
[2025-06-26T20:10:10.687+0700] {subprocess.py:93} INFO - 25/06/26 20:10:10 INFO TaskSetManager: Starting task 20.0 in stage 0.0 (TID 20) (localhost, executor driver, partition 20, PROCESS_LOCAL, 9215 bytes)
[2025-06-26T20:10:10.687+0700] {subprocess.py:93} INFO - 25/06/26 20:10:10 INFO TaskSetManager: Starting task 21.0 in stage 0.0 (TID 21) (localhost, executor driver, partition 21, PROCESS_LOCAL, 9215 bytes)
[2025-06-26T20:10:10.705+0700] {subprocess.py:93} INFO - 25/06/26 20:10:10 INFO Executor: Running task 16.0 in stage 0.0 (TID 16)
[2025-06-26T20:10:10.706+0700] {subprocess.py:93} INFO - 25/06/26 20:10:10 INFO Executor: Running task 1.0 in stage 0.0 (TID 1)
[2025-06-26T20:10:10.706+0700] {subprocess.py:93} INFO - 25/06/26 20:10:10 INFO Executor: Running task 17.0 in stage 0.0 (TID 17)
[2025-06-26T20:10:10.706+0700] {subprocess.py:93} INFO - 25/06/26 20:10:10 INFO Executor: Running task 7.0 in stage 0.0 (TID 7)
[2025-06-26T20:10:10.706+0700] {subprocess.py:93} INFO - 25/06/26 20:10:10 INFO Executor: Running task 5.0 in stage 0.0 (TID 5)
[2025-06-26T20:10:10.706+0700] {subprocess.py:93} INFO - 25/06/26 20:10:10 INFO Executor: Running task 4.0 in stage 0.0 (TID 4)
[2025-06-26T20:10:10.706+0700] {subprocess.py:93} INFO - 25/06/26 20:10:10 INFO Executor: Running task 3.0 in stage 0.0 (TID 3)
[2025-06-26T20:10:10.706+0700] {subprocess.py:93} INFO - 25/06/26 20:10:10 INFO Executor: Running task 0.0 in stage 0.0 (TID 0)
[2025-06-26T20:10:10.707+0700] {subprocess.py:93} INFO - 25/06/26 20:10:10 INFO Executor: Running task 18.0 in stage 0.0 (TID 18)
[2025-06-26T20:10:10.707+0700] {subprocess.py:93} INFO - 25/06/26 20:10:10 INFO Executor: Running task 13.0 in stage 0.0 (TID 13)
[2025-06-26T20:10:10.707+0700] {subprocess.py:93} INFO - 25/06/26 20:10:10 INFO Executor: Running task 9.0 in stage 0.0 (TID 9)
[2025-06-26T20:10:10.707+0700] {subprocess.py:93} INFO - 25/06/26 20:10:10 INFO Executor: Running task 19.0 in stage 0.0 (TID 19)
[2025-06-26T20:10:10.707+0700] {subprocess.py:93} INFO - 25/06/26 20:10:10 INFO Executor: Running task 10.0 in stage 0.0 (TID 10)
[2025-06-26T20:10:10.707+0700] {subprocess.py:93} INFO - 25/06/26 20:10:10 INFO Executor: Running task 14.0 in stage 0.0 (TID 14)
[2025-06-26T20:10:10.707+0700] {subprocess.py:93} INFO - 25/06/26 20:10:10 INFO Executor: Running task 6.0 in stage 0.0 (TID 6)
[2025-06-26T20:10:10.707+0700] {subprocess.py:93} INFO - 25/06/26 20:10:10 INFO Executor: Running task 2.0 in stage 0.0 (TID 2)
[2025-06-26T20:10:10.707+0700] {subprocess.py:93} INFO - 25/06/26 20:10:10 INFO Executor: Running task 11.0 in stage 0.0 (TID 11)
[2025-06-26T20:10:10.707+0700] {subprocess.py:93} INFO - 25/06/26 20:10:10 INFO Executor: Running task 8.0 in stage 0.0 (TID 8)
[2025-06-26T20:10:10.707+0700] {subprocess.py:93} INFO - 25/06/26 20:10:10 INFO Executor: Running task 15.0 in stage 0.0 (TID 15)
[2025-06-26T20:10:10.708+0700] {subprocess.py:93} INFO - 25/06/26 20:10:10 INFO Executor: Running task 12.0 in stage 0.0 (TID 12)
[2025-06-26T20:10:10.708+0700] {subprocess.py:93} INFO - 25/06/26 20:10:10 INFO Executor: Running task 21.0 in stage 0.0 (TID 21)
[2025-06-26T20:10:10.708+0700] {subprocess.py:93} INFO - 25/06/26 20:10:10 INFO Executor: Running task 20.0 in stage 0.0 (TID 20)
[2025-06-26T20:10:11.077+0700] {subprocess.py:93} INFO - 25/06/26 20:10:11 INFO Executor: Finished task 14.0 in stage 0.0 (TID 14). 3261 bytes result sent to driver
[2025-06-26T20:10:11.078+0700] {subprocess.py:93} INFO - 25/06/26 20:10:11 INFO Executor: Finished task 20.0 in stage 0.0 (TID 20). 3261 bytes result sent to driver
[2025-06-26T20:10:11.078+0700] {subprocess.py:93} INFO - 25/06/26 20:10:11 INFO Executor: Finished task 9.0 in stage 0.0 (TID 9). 3261 bytes result sent to driver
[2025-06-26T20:10:11.078+0700] {subprocess.py:93} INFO - 25/06/26 20:10:11 INFO Executor: Finished task 17.0 in stage 0.0 (TID 17). 3261 bytes result sent to driver
[2025-06-26T20:10:11.078+0700] {subprocess.py:93} INFO - 25/06/26 20:10:11 INFO Executor: Finished task 11.0 in stage 0.0 (TID 11). 3261 bytes result sent to driver
[2025-06-26T20:10:11.078+0700] {subprocess.py:93} INFO - 25/06/26 20:10:11 INFO Executor: Finished task 10.0 in stage 0.0 (TID 10). 3261 bytes result sent to driver
[2025-06-26T20:10:11.078+0700] {subprocess.py:93} INFO - 25/06/26 20:10:11 INFO Executor: Finished task 18.0 in stage 0.0 (TID 18). 3261 bytes result sent to driver
[2025-06-26T20:10:11.078+0700] {subprocess.py:93} INFO - 25/06/26 20:10:11 INFO Executor: Finished task 13.0 in stage 0.0 (TID 13). 3261 bytes result sent to driver
[2025-06-26T20:10:11.079+0700] {subprocess.py:93} INFO - 25/06/26 20:10:11 INFO Executor: Finished task 0.0 in stage 0.0 (TID 0). 3261 bytes result sent to driver
[2025-06-26T20:10:11.079+0700] {subprocess.py:93} INFO - 25/06/26 20:10:11 INFO Executor: Finished task 15.0 in stage 0.0 (TID 15). 3261 bytes result sent to driver
[2025-06-26T20:10:11.079+0700] {subprocess.py:93} INFO - 25/06/26 20:10:11 INFO Executor: Finished task 6.0 in stage 0.0 (TID 6). 3261 bytes result sent to driver
[2025-06-26T20:10:11.079+0700] {subprocess.py:93} INFO - 25/06/26 20:10:11 INFO Executor: Finished task 7.0 in stage 0.0 (TID 7). 3261 bytes result sent to driver
[2025-06-26T20:10:11.079+0700] {subprocess.py:93} INFO - 25/06/26 20:10:11 INFO Executor: Finished task 16.0 in stage 0.0 (TID 16). 3261 bytes result sent to driver
[2025-06-26T20:10:11.079+0700] {subprocess.py:93} INFO - 25/06/26 20:10:11 INFO Executor: Finished task 5.0 in stage 0.0 (TID 5). 3261 bytes result sent to driver
[2025-06-26T20:10:11.079+0700] {subprocess.py:93} INFO - 25/06/26 20:10:11 INFO Executor: Finished task 19.0 in stage 0.0 (TID 19). 3261 bytes result sent to driver
[2025-06-26T20:10:11.079+0700] {subprocess.py:93} INFO - 25/06/26 20:10:11 INFO Executor: Finished task 2.0 in stage 0.0 (TID 2). 3261 bytes result sent to driver
[2025-06-26T20:10:11.079+0700] {subprocess.py:93} INFO - 25/06/26 20:10:11 INFO Executor: Finished task 21.0 in stage 0.0 (TID 21). 3261 bytes result sent to driver
[2025-06-26T20:10:11.079+0700] {subprocess.py:93} INFO - 25/06/26 20:10:11 INFO Executor: Finished task 12.0 in stage 0.0 (TID 12). 3261 bytes result sent to driver
[2025-06-26T20:10:11.079+0700] {subprocess.py:93} INFO - 25/06/26 20:10:11 INFO Executor: Finished task 8.0 in stage 0.0 (TID 8). 3261 bytes result sent to driver
[2025-06-26T20:10:11.080+0700] {subprocess.py:93} INFO - 25/06/26 20:10:11 INFO Executor: Finished task 1.0 in stage 0.0 (TID 1). 3261 bytes result sent to driver
[2025-06-26T20:10:11.080+0700] {subprocess.py:93} INFO - 25/06/26 20:10:11 INFO Executor: Finished task 3.0 in stage 0.0 (TID 3). 3261 bytes result sent to driver
[2025-06-26T20:10:11.080+0700] {subprocess.py:93} INFO - 25/06/26 20:10:11 INFO Executor: Finished task 4.0 in stage 0.0 (TID 4). 3261 bytes result sent to driver
[2025-06-26T20:10:11.088+0700] {subprocess.py:93} INFO - 25/06/26 20:10:11 INFO TaskSetManager: Starting task 22.0 in stage 0.0 (TID 22) (localhost, executor driver, partition 22, PROCESS_LOCAL, 9215 bytes)
[2025-06-26T20:10:11.088+0700] {subprocess.py:93} INFO - 25/06/26 20:10:11 INFO Executor: Running task 22.0 in stage 0.0 (TID 22)
[2025-06-26T20:10:11.089+0700] {subprocess.py:93} INFO - 25/06/26 20:10:11 INFO TaskSetManager: Starting task 23.0 in stage 0.0 (TID 23) (localhost, executor driver, partition 23, PROCESS_LOCAL, 9215 bytes)
[2025-06-26T20:10:11.089+0700] {subprocess.py:93} INFO - 25/06/26 20:10:11 INFO Executor: Running task 23.0 in stage 0.0 (TID 23)
[2025-06-26T20:10:11.090+0700] {subprocess.py:93} INFO - 25/06/26 20:10:11 INFO TaskSetManager: Starting task 24.0 in stage 0.0 (TID 24) (localhost, executor driver, partition 24, PROCESS_LOCAL, 9215 bytes)
[2025-06-26T20:10:11.091+0700] {subprocess.py:93} INFO - 25/06/26 20:10:11 INFO Executor: Running task 24.0 in stage 0.0 (TID 24)
[2025-06-26T20:10:11.091+0700] {subprocess.py:93} INFO - 25/06/26 20:10:11 INFO TaskSetManager: Starting task 25.0 in stage 0.0 (TID 25) (localhost, executor driver, partition 25, PROCESS_LOCAL, 9215 bytes)
[2025-06-26T20:10:11.092+0700] {subprocess.py:93} INFO - 25/06/26 20:10:11 INFO Executor: Running task 25.0 in stage 0.0 (TID 25)
[2025-06-26T20:10:11.094+0700] {subprocess.py:93} INFO - 25/06/26 20:10:11 INFO TaskSetManager: Starting task 26.0 in stage 0.0 (TID 26) (localhost, executor driver, partition 26, PROCESS_LOCAL, 9215 bytes)
[2025-06-26T20:10:11.095+0700] {subprocess.py:93} INFO - 25/06/26 20:10:11 INFO Executor: Running task 26.0 in stage 0.0 (TID 26)
[2025-06-26T20:10:11.095+0700] {subprocess.py:93} INFO - 25/06/26 20:10:11 INFO TaskSetManager: Starting task 27.0 in stage 0.0 (TID 27) (localhost, executor driver, partition 27, PROCESS_LOCAL, 9215 bytes)
[2025-06-26T20:10:11.097+0700] {subprocess.py:93} INFO - 25/06/26 20:10:11 INFO Executor: Running task 27.0 in stage 0.0 (TID 27)
[2025-06-26T20:10:11.100+0700] {subprocess.py:93} INFO - 25/06/26 20:10:11 INFO TaskSetManager: Finished task 0.0 in stage 0.0 (TID 0) in 455 ms on localhost (executor driver) (1/2334)
[2025-06-26T20:10:11.102+0700] {subprocess.py:93} INFO - 25/06/26 20:10:11 INFO TaskSetManager: Finished task 6.0 in stage 0.0 (TID 6) in 424 ms on localhost (executor driver) (2/2334)
[2025-06-26T20:10:11.103+0700] {subprocess.py:93} INFO - 25/06/26 20:10:11 INFO TaskSetManager: Finished task 8.0 in stage 0.0 (TID 8) in 422 ms on localhost (executor driver) (3/2334)
[2025-06-26T20:10:11.103+0700] {subprocess.py:93} INFO - 25/06/26 20:10:11 INFO TaskSetManager: Finished task 1.0 in stage 0.0 (TID 1) in 428 ms on localhost (executor driver) (4/2334)
[2025-06-26T20:10:11.108+0700] {subprocess.py:93} INFO - 25/06/26 20:10:11 INFO TaskSetManager: Starting task 28.0 in stage 0.0 (TID 28) (localhost, executor driver, partition 28, PROCESS_LOCAL, 9215 bytes)
[2025-06-26T20:10:11.109+0700] {subprocess.py:93} INFO - 25/06/26 20:10:11 INFO TaskSetManager: Finished task 18.0 in stage 0.0 (TID 18) in 422 ms on localhost (executor driver) (5/2334)
[2025-06-26T20:10:11.111+0700] {subprocess.py:93} INFO - 25/06/26 20:10:11 INFO TaskSetManager: Finished task 7.0 in stage 0.0 (TID 7) in 432 ms on localhost (executor driver) (6/2334)
[2025-06-26T20:10:11.111+0700] {subprocess.py:93} INFO - 25/06/26 20:10:11 INFO Executor: Running task 28.0 in stage 0.0 (TID 28)
[2025-06-26T20:10:11.112+0700] {subprocess.py:93} INFO - 25/06/26 20:10:11 INFO TaskSetManager: Finished task 14.0 in stage 0.0 (TID 14) in 429 ms on localhost (executor driver) (7/2334)
[2025-06-26T20:10:11.114+0700] {subprocess.py:93} INFO - 25/06/26 20:10:11 INFO Executor: Finished task 23.0 in stage 0.0 (TID 23). 3218 bytes result sent to driver
[2025-06-26T20:10:11.114+0700] {subprocess.py:93} INFO - 25/06/26 20:10:11 INFO Executor: Finished task 22.0 in stage 0.0 (TID 22). 3218 bytes result sent to driver
[2025-06-26T20:10:11.119+0700] {subprocess.py:93} INFO - 25/06/26 20:10:11 INFO TaskSetManager: Starting task 29.0 in stage 0.0 (TID 29) (localhost, executor driver, partition 29, PROCESS_LOCAL, 9215 bytes)
[2025-06-26T20:10:11.120+0700] {subprocess.py:93} INFO - 25/06/26 20:10:11 INFO Executor: Finished task 26.0 in stage 0.0 (TID 26). 3175 bytes result sent to driver
[2025-06-26T20:10:11.120+0700] {subprocess.py:93} INFO - 25/06/26 20:10:11 INFO Executor: Finished task 25.0 in stage 0.0 (TID 25). 3218 bytes result sent to driver
[2025-06-26T20:10:11.120+0700] {subprocess.py:93} INFO - 25/06/26 20:10:11 INFO Executor: Finished task 24.0 in stage 0.0 (TID 24). 3175 bytes result sent to driver
[2025-06-26T20:10:11.120+0700] {subprocess.py:93} INFO - 25/06/26 20:10:11 INFO Executor: Running task 29.0 in stage 0.0 (TID 29)
[2025-06-26T20:10:11.120+0700] {subprocess.py:93} INFO - 25/06/26 20:10:11 INFO Executor: Finished task 27.0 in stage 0.0 (TID 27). 3175 bytes result sent to driver
[2025-06-26T20:10:11.120+0700] {subprocess.py:93} INFO - 25/06/26 20:10:11 INFO TaskSetManager: Starting task 30.0 in stage 0.0 (TID 30) (localhost, executor driver, partition 30, PROCESS_LOCAL, 9215 bytes)
[2025-06-26T20:10:11.121+0700] {subprocess.py:93} INFO - 25/06/26 20:10:11 INFO TaskSetManager: Finished task 10.0 in stage 0.0 (TID 10) in 440 ms on localhost (executor driver) (8/2334)
[2025-06-26T20:10:11.121+0700] {subprocess.py:93} INFO - 25/06/26 20:10:11 INFO Executor: Running task 30.0 in stage 0.0 (TID 30)
[2025-06-26T20:10:11.122+0700] {subprocess.py:93} INFO - 25/06/26 20:10:11 INFO TaskSetManager: Starting task 31.0 in stage 0.0 (TID 31) (localhost, executor driver, partition 31, PROCESS_LOCAL, 9215 bytes)
[2025-06-26T20:10:11.122+0700] {subprocess.py:93} INFO - 25/06/26 20:10:11 INFO TaskSetManager: Finished task 3.0 in stage 0.0 (TID 3) in 445 ms on localhost (executor driver) (9/2334)
[2025-06-26T20:10:11.123+0700] {subprocess.py:93} INFO - 25/06/26 20:10:11 INFO Executor: Running task 31.0 in stage 0.0 (TID 31)
[2025-06-26T20:10:11.124+0700] {subprocess.py:93} INFO - 25/06/26 20:10:11 INFO TaskSetManager: Starting task 32.0 in stage 0.0 (TID 32) (localhost, executor driver, partition 32, PROCESS_LOCAL, 9215 bytes)
[2025-06-26T20:10:11.124+0700] {subprocess.py:93} INFO - 25/06/26 20:10:11 INFO TaskSetManager: Finished task 5.0 in stage 0.0 (TID 5) in 447 ms on localhost (executor driver) (10/2334)
[2025-06-26T20:10:11.125+0700] {subprocess.py:93} INFO - 25/06/26 20:10:11 INFO Executor: Running task 32.0 in stage 0.0 (TID 32)
[2025-06-26T20:10:11.126+0700] {subprocess.py:93} INFO - 25/06/26 20:10:11 INFO TaskSetManager: Starting task 33.0 in stage 0.0 (TID 33) (localhost, executor driver, partition 33, PROCESS_LOCAL, 9215 bytes)
[2025-06-26T20:10:11.127+0700] {subprocess.py:93} INFO - 25/06/26 20:10:11 INFO Executor: Running task 33.0 in stage 0.0 (TID 33)
[2025-06-26T20:10:11.128+0700] {subprocess.py:93} INFO - 25/06/26 20:10:11 INFO TaskSetManager: Starting task 34.0 in stage 0.0 (TID 34) (localhost, executor driver, partition 34, PROCESS_LOCAL, 9215 bytes)
[2025-06-26T20:10:11.130+0700] {subprocess.py:93} INFO - 25/06/26 20:10:11 INFO TaskSetManager: Finished task 11.0 in stage 0.0 (TID 11) in 448 ms on localhost (executor driver) (11/2334)
[2025-06-26T20:10:11.130+0700] {subprocess.py:93} INFO - 25/06/26 20:10:11 INFO Executor: Running task 34.0 in stage 0.0 (TID 34)
[2025-06-26T20:10:11.130+0700] {subprocess.py:93} INFO - 25/06/26 20:10:11 INFO TaskSetManager: Finished task 17.0 in stage 0.0 (TID 17) in 444 ms on localhost (executor driver) (12/2334)
[2025-06-26T20:10:11.135+0700] {subprocess.py:93} INFO - 25/06/26 20:10:11 INFO TaskSetManager: Starting task 35.0 in stage 0.0 (TID 35) (localhost, executor driver, partition 35, PROCESS_LOCAL, 9215 bytes)
[2025-06-26T20:10:11.135+0700] {subprocess.py:93} INFO - 25/06/26 20:10:11 INFO Executor: Finished task 30.0 in stage 0.0 (TID 30). 3175 bytes result sent to driver
[2025-06-26T20:10:11.136+0700] {subprocess.py:93} INFO - 25/06/26 20:10:11 INFO Executor: Running task 35.0 in stage 0.0 (TID 35)
[2025-06-26T20:10:11.136+0700] {subprocess.py:93} INFO - 25/06/26 20:10:11 INFO Executor: Finished task 28.0 in stage 0.0 (TID 28). 3218 bytes result sent to driver
[2025-06-26T20:10:11.136+0700] {subprocess.py:93} INFO - 25/06/26 20:10:11 INFO TaskSetManager: Starting task 36.0 in stage 0.0 (TID 36) (localhost, executor driver, partition 36, PROCESS_LOCAL, 9215 bytes)
[2025-06-26T20:10:11.137+0700] {subprocess.py:93} INFO - 25/06/26 20:10:11 INFO TaskSetManager: Finished task 16.0 in stage 0.0 (TID 16) in 451 ms on localhost (executor driver) (13/2334)
[2025-06-26T20:10:11.137+0700] {subprocess.py:93} INFO - 25/06/26 20:10:11 INFO Executor: Running task 36.0 in stage 0.0 (TID 36)
[2025-06-26T20:10:11.138+0700] {subprocess.py:93} INFO - 25/06/26 20:10:11 INFO TaskSetManager: Starting task 37.0 in stage 0.0 (TID 37) (localhost, executor driver, partition 37, PROCESS_LOCAL, 9215 bytes)
[2025-06-26T20:10:11.138+0700] {subprocess.py:93} INFO - 25/06/26 20:10:11 INFO Executor: Finished task 29.0 in stage 0.0 (TID 29). 3175 bytes result sent to driver
[2025-06-26T20:10:11.139+0700] {subprocess.py:93} INFO - 25/06/26 20:10:11 INFO Executor: Running task 37.0 in stage 0.0 (TID 37)
[2025-06-26T20:10:11.139+0700] {subprocess.py:93} INFO - 25/06/26 20:10:11 INFO TaskSetManager: Finished task 21.0 in stage 0.0 (TID 21) in 451 ms on localhost (executor driver) (14/2334)
[2025-06-26T20:10:11.139+0700] {subprocess.py:93} INFO - 25/06/26 20:10:11 INFO Executor: Finished task 32.0 in stage 0.0 (TID 32). 3175 bytes result sent to driver
[2025-06-26T20:10:11.140+0700] {subprocess.py:93} INFO - 25/06/26 20:10:11 INFO TaskSetManager: Starting task 38.0 in stage 0.0 (TID 38) (localhost, executor driver, partition 38, PROCESS_LOCAL, 9215 bytes)
[2025-06-26T20:10:11.141+0700] {subprocess.py:93} INFO - 25/06/26 20:10:11 INFO TaskSetManager: Finished task 2.0 in stage 0.0 (TID 2) in 464 ms on localhost (executor driver) (15/2334)
[2025-06-26T20:10:11.141+0700] {subprocess.py:93} INFO - 25/06/26 20:10:11 INFO Executor: Running task 38.0 in stage 0.0 (TID 38)
[2025-06-26T20:10:11.142+0700] {subprocess.py:93} INFO - 25/06/26 20:10:11 INFO TaskSetManager: Starting task 39.0 in stage 0.0 (TID 39) (localhost, executor driver, partition 39, PROCESS_LOCAL, 9215 bytes)
[2025-06-26T20:10:11.143+0700] {subprocess.py:93} INFO - 25/06/26 20:10:11 INFO TaskSetManager: Finished task 9.0 in stage 0.0 (TID 9) in 462 ms on localhost (executor driver) (16/2334)
[2025-06-26T20:10:11.143+0700] {subprocess.py:93} INFO - 25/06/26 20:10:11 INFO Executor: Running task 39.0 in stage 0.0 (TID 39)
[2025-06-26T20:10:11.145+0700] {subprocess.py:93} INFO - 25/06/26 20:10:11 INFO TaskSetManager: Starting task 40.0 in stage 0.0 (TID 40) (localhost, executor driver, partition 40, PROCESS_LOCAL, 9215 bytes)
[2025-06-26T20:10:11.160+0700] {subprocess.py:93} INFO - 25/06/26 20:10:11 INFO TaskSetManager: Finished task 15.0 in stage 0.0 (TID 15) in 476 ms on localhost (executor driver) (17/2334)
[2025-06-26T20:10:11.161+0700] {subprocess.py:93} INFO - 25/06/26 20:10:11 INFO Executor: Finished task 33.0 in stage 0.0 (TID 33). 3175 bytes result sent to driver
[2025-06-26T20:10:11.162+0700] {subprocess.py:93} INFO - 25/06/26 20:10:11 INFO Executor: Finished task 31.0 in stage 0.0 (TID 31). 3218 bytes result sent to driver
[2025-06-26T20:10:11.162+0700] {subprocess.py:93} INFO - 25/06/26 20:10:11 INFO Executor: Running task 40.0 in stage 0.0 (TID 40)
[2025-06-26T20:10:11.162+0700] {subprocess.py:93} INFO - 25/06/26 20:10:11 INFO TaskSetManager: Finished task 12.0 in stage 0.0 (TID 12) in 478 ms on localhost (executor driver) (18/2334)
[2025-06-26T20:10:11.162+0700] {subprocess.py:93} INFO - 25/06/26 20:10:11 INFO TaskSetManager: Starting task 41.0 in stage 0.0 (TID 41) (localhost, executor driver, partition 41, PROCESS_LOCAL, 9215 bytes)
[2025-06-26T20:10:11.163+0700] {subprocess.py:93} INFO - 25/06/26 20:10:11 INFO Executor: Running task 41.0 in stage 0.0 (TID 41)
[2025-06-26T20:10:11.164+0700] {subprocess.py:93} INFO - 25/06/26 20:10:11 INFO TaskSetManager: Finished task 20.0 in stage 0.0 (TID 20) in 477 ms on localhost (executor driver) (19/2334)
[2025-06-26T20:10:11.164+0700] {subprocess.py:93} INFO - 25/06/26 20:10:11 INFO Executor: Finished task 34.0 in stage 0.0 (TID 34). 3218 bytes result sent to driver
[2025-06-26T20:10:11.164+0700] {subprocess.py:93} INFO - 25/06/26 20:10:11 INFO Executor: Finished task 35.0 in stage 0.0 (TID 35). 3218 bytes result sent to driver
[2025-06-26T20:10:11.165+0700] {subprocess.py:93} INFO - 25/06/26 20:10:11 INFO TaskSetManager: Starting task 42.0 in stage 0.0 (TID 42) (localhost, executor driver, partition 42, PROCESS_LOCAL, 9215 bytes)
[2025-06-26T20:10:11.166+0700] {subprocess.py:93} INFO - 25/06/26 20:10:11 INFO Executor: Finished task 36.0 in stage 0.0 (TID 36). 3218 bytes result sent to driver
[2025-06-26T20:10:11.166+0700] {subprocess.py:93} INFO - 25/06/26 20:10:11 INFO TaskSetManager: Finished task 13.0 in stage 0.0 (TID 13) in 483 ms on localhost (executor driver) (20/2334)
[2025-06-26T20:10:11.166+0700] {subprocess.py:93} INFO - 25/06/26 20:10:11 INFO Executor: Running task 42.0 in stage 0.0 (TID 42)
[2025-06-26T20:10:11.167+0700] {subprocess.py:93} INFO - 25/06/26 20:10:11 INFO TaskSetManager: Starting task 43.0 in stage 0.0 (TID 43) (localhost, executor driver, partition 43, PROCESS_LOCAL, 9215 bytes)
[2025-06-26T20:10:11.167+0700] {subprocess.py:93} INFO - 25/06/26 20:10:11 INFO Executor: Finished task 38.0 in stage 0.0 (TID 38). 3218 bytes result sent to driver
[2025-06-26T20:10:11.167+0700] {subprocess.py:93} INFO - 25/06/26 20:10:11 INFO Executor: Running task 43.0 in stage 0.0 (TID 43)
[2025-06-26T20:10:11.168+0700] {subprocess.py:93} INFO - 25/06/26 20:10:11 INFO TaskSetManager: Starting task 44.0 in stage 0.0 (TID 44) (localhost, executor driver, partition 44, PROCESS_LOCAL, 9215 bytes)
[2025-06-26T20:10:11.169+0700] {subprocess.py:93} INFO - 25/06/26 20:10:11 INFO Executor: Finished task 37.0 in stage 0.0 (TID 37). 3218 bytes result sent to driver
[2025-06-26T20:10:11.169+0700] {subprocess.py:93} INFO - 25/06/26 20:10:11 INFO TaskSetManager: Finished task 4.0 in stage 0.0 (TID 4) in 492 ms on localhost (executor driver) (21/2334)
[2025-06-26T20:10:11.169+0700] {subprocess.py:93} INFO - 25/06/26 20:10:11 INFO Executor: Running task 44.0 in stage 0.0 (TID 44)
[2025-06-26T20:10:11.169+0700] {subprocess.py:93} INFO - 25/06/26 20:10:11 INFO Executor: Finished task 39.0 in stage 0.0 (TID 39). 3218 bytes result sent to driver
[2025-06-26T20:10:11.170+0700] {subprocess.py:93} INFO - 25/06/26 20:10:11 INFO TaskSetManager: Finished task 19.0 in stage 0.0 (TID 19) in 483 ms on localhost (executor driver) (22/2334)
[2025-06-26T20:10:11.172+0700] {subprocess.py:93} INFO - 25/06/26 20:10:11 INFO TaskSetManager: Finished task 23.0 in stage 0.0 (TID 23) in 83 ms on localhost (executor driver) (23/2334)
[2025-06-26T20:10:11.173+0700] {subprocess.py:93} INFO - 25/06/26 20:10:11 INFO TaskSetManager: Starting task 45.0 in stage 0.0 (TID 45) (localhost, executor driver, partition 45, PROCESS_LOCAL, 9215 bytes)
[2025-06-26T20:10:11.174+0700] {subprocess.py:93} INFO - 25/06/26 20:10:11 INFO Executor: Running task 45.0 in stage 0.0 (TID 45)
[2025-06-26T20:10:11.174+0700] {subprocess.py:93} INFO - 25/06/26 20:10:11 INFO TaskSetManager: Starting task 46.0 in stage 0.0 (TID 46) (localhost, executor driver, partition 46, PROCESS_LOCAL, 9215 bytes)
[2025-06-26T20:10:11.175+0700] {subprocess.py:93} INFO - 25/06/26 20:10:11 INFO TaskSetManager: Finished task 22.0 in stage 0.0 (TID 22) in 87 ms on localhost (executor driver) (24/2334)
[2025-06-26T20:10:11.176+0700] {subprocess.py:93} INFO - 25/06/26 20:10:11 INFO Executor: Running task 46.0 in stage 0.0 (TID 46)
[2025-06-26T20:10:11.177+0700] {subprocess.py:93} INFO - 25/06/26 20:10:11 INFO TaskSetManager: Starting task 47.0 in stage 0.0 (TID 47) (localhost, executor driver, partition 47, PROCESS_LOCAL, 9215 bytes)
[2025-06-26T20:10:11.178+0700] {subprocess.py:93} INFO - 25/06/26 20:10:11 INFO Executor: Running task 47.0 in stage 0.0 (TID 47)
[2025-06-26T20:10:11.178+0700] {subprocess.py:93} INFO - 25/06/26 20:10:11 INFO TaskSetManager: Starting task 48.0 in stage 0.0 (TID 48) (localhost, executor driver, partition 48, PROCESS_LOCAL, 9215 bytes)
[2025-06-26T20:10:11.178+0700] {subprocess.py:93} INFO - 25/06/26 20:10:11 INFO TaskSetManager: Finished task 26.0 in stage 0.0 (TID 26) in 84 ms on localhost (executor driver) (25/2334)
[2025-06-26T20:10:11.178+0700] {subprocess.py:93} INFO - 25/06/26 20:10:11 INFO Executor: Running task 48.0 in stage 0.0 (TID 48)
[2025-06-26T20:10:11.179+0700] {subprocess.py:93} INFO - 25/06/26 20:10:11 INFO TaskSetManager: Finished task 24.0 in stage 0.0 (TID 24) in 88 ms on localhost (executor driver) (26/2334)
[2025-06-26T20:10:11.179+0700] {subprocess.py:93} INFO - 25/06/26 20:10:11 INFO TaskSetManager: Starting task 49.0 in stage 0.0 (TID 49) (localhost, executor driver, partition 49, PROCESS_LOCAL, 9215 bytes)
[2025-06-26T20:10:11.179+0700] {subprocess.py:93} INFO - 25/06/26 20:10:11 INFO Executor: Running task 49.0 in stage 0.0 (TID 49)
[2025-06-26T20:10:11.179+0700] {subprocess.py:93} INFO - 25/06/26 20:10:11 INFO TaskSetManager: Starting task 50.0 in stage 0.0 (TID 50) (localhost, executor driver, partition 50, PROCESS_LOCAL, 9215 bytes)
[2025-06-26T20:10:11.179+0700] {subprocess.py:93} INFO - 25/06/26 20:10:11 INFO TaskSetManager: Finished task 27.0 in stage 0.0 (TID 27) in 83 ms on localhost (executor driver) (27/2334)
[2025-06-26T20:10:11.179+0700] {subprocess.py:93} INFO - 25/06/26 20:10:11 INFO TaskSetManager: Starting task 51.0 in stage 0.0 (TID 51) (localhost, executor driver, partition 51, PROCESS_LOCAL, 9215 bytes)
[2025-06-26T20:10:11.180+0700] {subprocess.py:93} INFO - 25/06/26 20:10:11 INFO TaskSetManager: Finished task 30.0 in stage 0.0 (TID 30) in 60 ms on localhost (executor driver) (28/2334)
[2025-06-26T20:10:11.180+0700] {subprocess.py:93} INFO - 25/06/26 20:10:11 INFO Executor: Running task 50.0 in stage 0.0 (TID 50)
[2025-06-26T20:10:11.180+0700] {subprocess.py:93} INFO - 25/06/26 20:10:11 INFO Executor: Running task 51.0 in stage 0.0 (TID 51)
[2025-06-26T20:10:11.180+0700] {subprocess.py:93} INFO - 25/06/26 20:10:11 INFO TaskSetManager: Finished task 25.0 in stage 0.0 (TID 25) in 89 ms on localhost (executor driver) (29/2334)
[2025-06-26T20:10:11.180+0700] {subprocess.py:93} INFO - 25/06/26 20:10:11 INFO TaskSetManager: Finished task 28.0 in stage 0.0 (TID 28) in 76 ms on localhost (executor driver) (30/2334)
[2025-06-26T20:10:11.182+0700] {subprocess.py:93} INFO - 25/06/26 20:10:11 INFO TaskSetManager: Starting task 52.0 in stage 0.0 (TID 52) (localhost, executor driver, partition 52, PROCESS_LOCAL, 9215 bytes)
[2025-06-26T20:10:11.182+0700] {subprocess.py:93} INFO - 25/06/26 20:10:11 INFO TaskSetManager: Starting task 53.0 in stage 0.0 (TID 53) (localhost, executor driver, partition 53, PROCESS_LOCAL, 9215 bytes)
[2025-06-26T20:10:11.183+0700] {subprocess.py:93} INFO - 25/06/26 20:10:11 INFO Executor: Running task 52.0 in stage 0.0 (TID 52)
[2025-06-26T20:10:11.183+0700] {subprocess.py:93} INFO - 25/06/26 20:10:11 INFO TaskSetManager: Finished task 29.0 in stage 0.0 (TID 29) in 64 ms on localhost (executor driver) (31/2334)
[2025-06-26T20:10:11.183+0700] {subprocess.py:93} INFO - 25/06/26 20:10:11 INFO Executor: Running task 53.0 in stage 0.0 (TID 53)
[2025-06-26T20:10:11.183+0700] {subprocess.py:93} INFO - 25/06/26 20:10:11 INFO TaskSetManager: Finished task 32.0 in stage 0.0 (TID 32) in 59 ms on localhost (executor driver) (32/2334)
[2025-06-26T20:10:11.185+0700] {subprocess.py:93} INFO - 25/06/26 20:10:11 INFO TaskSetManager: Starting task 54.0 in stage 0.0 (TID 54) (localhost, executor driver, partition 54, PROCESS_LOCAL, 9215 bytes)
[2025-06-26T20:10:11.186+0700] {subprocess.py:93} INFO - 25/06/26 20:10:11 INFO Executor: Finished task 42.0 in stage 0.0 (TID 42). 3175 bytes result sent to driver
[2025-06-26T20:10:11.186+0700] {subprocess.py:93} INFO - 25/06/26 20:10:11 INFO Executor: Finished task 41.0 in stage 0.0 (TID 41). 3175 bytes result sent to driver
[2025-06-26T20:10:11.186+0700] {subprocess.py:93} INFO - 25/06/26 20:10:11 INFO TaskSetManager: Starting task 55.0 in stage 0.0 (TID 55) (localhost, executor driver, partition 55, PROCESS_LOCAL, 9215 bytes)
[2025-06-26T20:10:11.186+0700] {subprocess.py:93} INFO - 25/06/26 20:10:11 INFO Executor: Running task 54.0 in stage 0.0 (TID 54)
[2025-06-26T20:10:11.188+0700] {subprocess.py:93} INFO - 25/06/26 20:10:11 INFO Executor: Finished task 40.0 in stage 0.0 (TID 40). 3175 bytes result sent to driver
[2025-06-26T20:10:11.189+0700] {subprocess.py:93} INFO - 25/06/26 20:10:11 INFO Executor: Finished task 44.0 in stage 0.0 (TID 44). 3175 bytes result sent to driver
[2025-06-26T20:10:11.189+0700] {subprocess.py:93} INFO - 25/06/26 20:10:11 INFO TaskSetManager: Starting task 56.0 in stage 0.0 (TID 56) (localhost, executor driver, partition 56, PROCESS_LOCAL, 9215 bytes)
[2025-06-26T20:10:11.189+0700] {subprocess.py:93} INFO - 25/06/26 20:10:11 INFO TaskSetManager: Finished task 33.0 in stage 0.0 (TID 33) in 62 ms on localhost (executor driver) (33/2334)
[2025-06-26T20:10:11.189+0700] {subprocess.py:93} INFO - 25/06/26 20:10:11 INFO Executor: Finished task 43.0 in stage 0.0 (TID 43). 3175 bytes result sent to driver
[2025-06-26T20:10:11.189+0700] {subprocess.py:93} INFO - 25/06/26 20:10:11 INFO Executor: Running task 55.0 in stage 0.0 (TID 55)
[2025-06-26T20:10:11.189+0700] {subprocess.py:93} INFO - 25/06/26 20:10:11 INFO TaskSetManager: Finished task 34.0 in stage 0.0 (TID 34) in 63 ms on localhost (executor driver) (34/2334)
[2025-06-26T20:10:11.190+0700] {subprocess.py:93} INFO - 25/06/26 20:10:11 INFO Executor: Running task 56.0 in stage 0.0 (TID 56)
[2025-06-26T20:10:11.191+0700] {subprocess.py:93} INFO - 25/06/26 20:10:11 INFO TaskSetManager: Starting task 57.0 in stage 0.0 (TID 57) (localhost, executor driver, partition 57, PROCESS_LOCAL, 9215 bytes)
[2025-06-26T20:10:11.193+0700] {subprocess.py:93} INFO - 25/06/26 20:10:11 INFO Executor: Running task 57.0 in stage 0.0 (TID 57)
[2025-06-26T20:10:11.193+0700] {subprocess.py:93} INFO - 25/06/26 20:10:11 INFO TaskSetManager: Starting task 58.0 in stage 0.0 (TID 58) (localhost, executor driver, partition 58, PROCESS_LOCAL, 9215 bytes)
[2025-06-26T20:10:11.193+0700] {subprocess.py:93} INFO - 25/06/26 20:10:11 INFO Executor: Finished task 46.0 in stage 0.0 (TID 46). 3175 bytes result sent to driver
[2025-06-26T20:10:11.193+0700] {subprocess.py:93} INFO - 25/06/26 20:10:11 INFO Executor: Running task 58.0 in stage 0.0 (TID 58)
[2025-06-26T20:10:11.193+0700] {subprocess.py:93} INFO - 25/06/26 20:10:11 INFO TaskSetManager: Starting task 59.0 in stage 0.0 (TID 59) (localhost, executor driver, partition 59, PROCESS_LOCAL, 9215 bytes)
[2025-06-26T20:10:11.194+0700] {subprocess.py:93} INFO - 25/06/26 20:10:11 INFO Executor: Running task 59.0 in stage 0.0 (TID 59)
[2025-06-26T20:10:11.194+0700] {subprocess.py:93} INFO - 25/06/26 20:10:11 INFO TaskSetManager: Starting task 60.0 in stage 0.0 (TID 60) (localhost, executor driver, partition 60, PROCESS_LOCAL, 9215 bytes)
[2025-06-26T20:10:11.198+0700] {subprocess.py:93} INFO - 25/06/26 20:10:11 INFO TaskSetManager: Finished task 31.0 in stage 0.0 (TID 31) in 75 ms on localhost (executor driver) (35/2334)
[2025-06-26T20:10:11.198+0700] {subprocess.py:93} INFO - 25/06/26 20:10:11 INFO Executor: Running task 60.0 in stage 0.0 (TID 60)
[2025-06-26T20:10:11.198+0700] {subprocess.py:93} INFO - 25/06/26 20:10:11 INFO Executor: Finished task 45.0 in stage 0.0 (TID 45). 3175 bytes result sent to driver
[2025-06-26T20:10:11.199+0700] {subprocess.py:93} INFO - 25/06/26 20:10:11 INFO TaskSetManager: Starting task 61.0 in stage 0.0 (TID 61) (localhost, executor driver, partition 61, PROCESS_LOCAL, 9215 bytes)
[2025-06-26T20:10:11.199+0700] {subprocess.py:93} INFO - 25/06/26 20:10:11 INFO TaskSetManager: Finished task 35.0 in stage 0.0 (TID 35) in 64 ms on localhost (executor driver) (36/2334)
[2025-06-26T20:10:11.199+0700] {subprocess.py:93} INFO - 25/06/26 20:10:11 INFO Executor: Running task 61.0 in stage 0.0 (TID 61)
[2025-06-26T20:10:11.201+0700] {subprocess.py:93} INFO - 25/06/26 20:10:11 INFO TaskSetManager: Starting task 62.0 in stage 0.0 (TID 62) (localhost, executor driver, partition 62, PROCESS_LOCAL, 9215 bytes)
[2025-06-26T20:10:11.201+0700] {subprocess.py:93} INFO - 25/06/26 20:10:11 INFO TaskSetManager: Starting task 63.0 in stage 0.0 (TID 63) (localhost, executor driver, partition 63, PROCESS_LOCAL, 9215 bytes)
[2025-06-26T20:10:11.201+0700] {subprocess.py:93} INFO - 25/06/26 20:10:11 INFO Executor: Running task 62.0 in stage 0.0 (TID 62)
[2025-06-26T20:10:11.202+0700] {subprocess.py:93} INFO - 25/06/26 20:10:11 INFO TaskSetManager: Finished task 38.0 in stage 0.0 (TID 38) in 62 ms on localhost (executor driver) (37/2334)
[2025-06-26T20:10:11.202+0700] {subprocess.py:93} INFO - 25/06/26 20:10:11 INFO TaskSetManager: Finished task 39.0 in stage 0.0 (TID 39) in 60 ms on localhost (executor driver) (38/2334)
[2025-06-26T20:10:11.202+0700] {subprocess.py:93} INFO - 25/06/26 20:10:11 INFO TaskSetManager: Finished task 37.0 in stage 0.0 (TID 37) in 65 ms on localhost (executor driver) (39/2334)
[2025-06-26T20:10:11.202+0700] {subprocess.py:93} INFO - 25/06/26 20:10:11 INFO Executor: Running task 63.0 in stage 0.0 (TID 63)
[2025-06-26T20:10:11.203+0700] {subprocess.py:93} INFO - 25/06/26 20:10:11 INFO TaskSetManager: Finished task 42.0 in stage 0.0 (TID 42) in 38 ms on localhost (executor driver) (40/2334)
[2025-06-26T20:10:11.203+0700] {subprocess.py:93} INFO - 25/06/26 20:10:11 INFO TaskSetManager: Finished task 40.0 in stage 0.0 (TID 40) in 59 ms on localhost (executor driver) (41/2334)
[2025-06-26T20:10:11.203+0700] {subprocess.py:93} INFO - 25/06/26 20:10:11 INFO TaskSetManager: Finished task 36.0 in stage 0.0 (TID 36) in 68 ms on localhost (executor driver) (42/2334)
[2025-06-26T20:10:11.204+0700] {subprocess.py:93} INFO - 25/06/26 20:10:11 INFO TaskSetManager: Starting task 64.0 in stage 0.0 (TID 64) (localhost, executor driver, partition 64, PROCESS_LOCAL, 9215 bytes)
[2025-06-26T20:10:11.209+0700] {subprocess.py:93} INFO - 25/06/26 20:10:11 INFO Executor: Running task 64.0 in stage 0.0 (TID 64)
[2025-06-26T20:10:11.210+0700] {subprocess.py:93} INFO - 25/06/26 20:10:11 INFO TaskSetManager: Starting task 65.0 in stage 0.0 (TID 65) (localhost, executor driver, partition 65, PROCESS_LOCAL, 9215 bytes)
[2025-06-26T20:10:11.211+0700] {subprocess.py:93} INFO - 25/06/26 20:10:11 INFO Executor: Running task 65.0 in stage 0.0 (TID 65)
[2025-06-26T20:10:11.211+0700] {subprocess.py:93} INFO - 25/06/26 20:10:11 INFO Executor: Finished task 48.0 in stage 0.0 (TID 48). 3175 bytes result sent to driver
[2025-06-26T20:10:11.215+0700] {subprocess.py:93} INFO - 25/06/26 20:10:11 INFO Executor: Finished task 49.0 in stage 0.0 (TID 49). 3175 bytes result sent to driver
[2025-06-26T20:10:11.217+0700] {subprocess.py:93} INFO - 25/06/26 20:10:11 INFO TaskSetManager: Starting task 66.0 in stage 0.0 (TID 66) (localhost, executor driver, partition 66, PROCESS_LOCAL, 9215 bytes)
[2025-06-26T20:10:11.218+0700] {subprocess.py:93} INFO - 25/06/26 20:10:11 INFO TaskSetManager: Starting task 67.0 in stage 0.0 (TID 67) (localhost, executor driver, partition 67, PROCESS_LOCAL, 9215 bytes)
[2025-06-26T20:10:11.220+0700] {subprocess.py:93} INFO - 25/06/26 20:10:11 INFO TaskSetManager: Starting task 68.0 in stage 0.0 (TID 68) (localhost, executor driver, partition 68, PROCESS_LOCAL, 9215 bytes)
[2025-06-26T20:10:11.221+0700] {subprocess.py:93} INFO - 25/06/26 20:10:11 INFO Executor: Running task 68.0 in stage 0.0 (TID 68)
[2025-06-26T20:10:11.222+0700] {subprocess.py:93} INFO - 25/06/26 20:10:11 INFO Executor: Finished task 50.0 in stage 0.0 (TID 50). 3175 bytes result sent to driver
[2025-06-26T20:10:11.222+0700] {subprocess.py:93} INFO - 25/06/26 20:10:11 INFO Executor: Finished task 53.0 in stage 0.0 (TID 53). 3175 bytes result sent to driver
[2025-06-26T20:10:11.223+0700] {subprocess.py:93} INFO - 25/06/26 20:10:11 INFO Executor: Finished task 52.0 in stage 0.0 (TID 52). 3175 bytes result sent to driver
[2025-06-26T20:10:11.223+0700] {subprocess.py:93} INFO - 25/06/26 20:10:11 INFO Executor: Running task 66.0 in stage 0.0 (TID 66)
[2025-06-26T20:10:11.225+0700] {subprocess.py:93} INFO - 25/06/26 20:10:11 INFO Executor: Finished task 51.0 in stage 0.0 (TID 51). 3175 bytes result sent to driver
[2025-06-26T20:10:11.225+0700] {subprocess.py:93} INFO - 25/06/26 20:10:11 INFO Executor: Running task 67.0 in stage 0.0 (TID 67)
[2025-06-26T20:10:11.225+0700] {subprocess.py:93} INFO - 25/06/26 20:10:11 INFO TaskSetManager: Finished task 41.0 in stage 0.0 (TID 41) in 59 ms on localhost (executor driver) (43/2334)
[2025-06-26T20:10:11.226+0700] {subprocess.py:93} INFO - 25/06/26 20:10:11 INFO Executor: Finished task 47.0 in stage 0.0 (TID 47). 3175 bytes result sent to driver
[2025-06-26T20:10:11.227+0700] {subprocess.py:93} INFO - 25/06/26 20:10:11 INFO TaskSetManager: Starting task 69.0 in stage 0.0 (TID 69) (localhost, executor driver, partition 69, PROCESS_LOCAL, 9215 bytes)
[2025-06-26T20:10:11.231+0700] {subprocess.py:93} INFO - 25/06/26 20:10:11 INFO Executor: Running task 69.0 in stage 0.0 (TID 69)
[2025-06-26T20:10:11.232+0700] {subprocess.py:93} INFO - 25/06/26 20:10:11 INFO TaskSetManager: Starting task 70.0 in stage 0.0 (TID 70) (localhost, executor driver, partition 70, PROCESS_LOCAL, 9215 bytes)
[2025-06-26T20:10:11.233+0700] {subprocess.py:93} INFO - 25/06/26 20:10:11 INFO TaskSetManager: Starting task 71.0 in stage 0.0 (TID 71) (localhost, executor driver, partition 71, PROCESS_LOCAL, 9215 bytes)
[2025-06-26T20:10:11.233+0700] {subprocess.py:93} INFO - 25/06/26 20:10:11 INFO Executor: Running task 70.0 in stage 0.0 (TID 70)
[2025-06-26T20:10:11.236+0700] {subprocess.py:93} INFO - 25/06/26 20:10:11 INFO TaskSetManager: Starting task 72.0 in stage 0.0 (TID 72) (localhost, executor driver, partition 72, PROCESS_LOCAL, 9215 bytes)
[2025-06-26T20:10:11.236+0700] {subprocess.py:93} INFO - 25/06/26 20:10:11 INFO Executor: Running task 71.0 in stage 0.0 (TID 71)
[2025-06-26T20:10:11.236+0700] {subprocess.py:93} INFO - 25/06/26 20:10:11 INFO TaskSetManager: Finished task 46.0 in stage 0.0 (TID 46) in 62 ms on localhost (executor driver) (44/2334)
[2025-06-26T20:10:11.236+0700] {subprocess.py:93} INFO - 25/06/26 20:10:11 INFO Executor: Finished task 60.0 in stage 0.0 (TID 60). 3175 bytes result sent to driver
[2025-06-26T20:10:11.242+0700] {subprocess.py:93} INFO - 25/06/26 20:10:11 INFO TaskSetManager: Finished task 44.0 in stage 0.0 (TID 44) in 72 ms on localhost (executor driver) (45/2334)
[2025-06-26T20:10:11.242+0700] {subprocess.py:93} INFO - 25/06/26 20:10:11 INFO Executor: Finished task 56.0 in stage 0.0 (TID 56). 3175 bytes result sent to driver
[2025-06-26T20:10:11.243+0700] {subprocess.py:93} INFO - 25/06/26 20:10:11 INFO Executor: Finished task 54.0 in stage 0.0 (TID 54). 3175 bytes result sent to driver
[2025-06-26T20:10:11.243+0700] {subprocess.py:93} INFO - 25/06/26 20:10:11 INFO Executor: Running task 72.0 in stage 0.0 (TID 72)
[2025-06-26T20:10:11.243+0700] {subprocess.py:93} INFO - 25/06/26 20:10:11 INFO TaskSetManager: Starting task 73.0 in stage 0.0 (TID 73) (localhost, executor driver, partition 73, PROCESS_LOCAL, 9215 bytes)
[2025-06-26T20:10:11.249+0700] {subprocess.py:93} INFO - 25/06/26 20:10:11 INFO Executor: Finished task 61.0 in stage 0.0 (TID 61). 3175 bytes result sent to driver
[2025-06-26T20:10:11.249+0700] {subprocess.py:93} INFO - 25/06/26 20:10:11 INFO Executor: Finished task 59.0 in stage 0.0 (TID 59). 3175 bytes result sent to driver
[2025-06-26T20:10:11.249+0700] {subprocess.py:93} INFO - 25/06/26 20:10:11 INFO Executor: Running task 73.0 in stage 0.0 (TID 73)
[2025-06-26T20:10:11.255+0700] {subprocess.py:93} INFO - 25/06/26 20:10:11 INFO TaskSetManager: Starting task 74.0 in stage 0.0 (TID 74) (localhost, executor driver, partition 74, PROCESS_LOCAL, 9215 bytes)
[2025-06-26T20:10:11.258+0700] {subprocess.py:93} INFO - 25/06/26 20:10:11 INFO Executor: Finished task 62.0 in stage 0.0 (TID 62). 3175 bytes result sent to driver
[2025-06-26T20:10:11.258+0700] {subprocess.py:93} INFO - 25/06/26 20:10:11 INFO Executor: Finished task 58.0 in stage 0.0 (TID 58). 3175 bytes result sent to driver
[2025-06-26T20:10:11.258+0700] {subprocess.py:93} INFO - 25/06/26 20:10:11 INFO Executor: Finished task 55.0 in stage 0.0 (TID 55). 3175 bytes result sent to driver
[2025-06-26T20:10:11.259+0700] {subprocess.py:93} INFO - 25/06/26 20:10:11 INFO Executor: Finished task 63.0 in stage 0.0 (TID 63). 3175 bytes result sent to driver
[2025-06-26T20:10:11.261+0700] {subprocess.py:93} INFO - 25/06/26 20:10:11 INFO Executor: Running task 74.0 in stage 0.0 (TID 74)
[2025-06-26T20:10:11.263+0700] {subprocess.py:93} INFO - 25/06/26 20:10:11 INFO TaskSetManager: Starting task 75.0 in stage 0.0 (TID 75) (localhost, executor driver, partition 75, PROCESS_LOCAL, 9215 bytes)
[2025-06-26T20:10:11.264+0700] {subprocess.py:93} INFO - 25/06/26 20:10:11 INFO Executor: Running task 75.0 in stage 0.0 (TID 75)
[2025-06-26T20:10:11.267+0700] {subprocess.py:93} INFO - 25/06/26 20:10:11 INFO TaskSetManager: Finished task 45.0 in stage 0.0 (TID 45) in 91 ms on localhost (executor driver) (46/2334)
[2025-06-26T20:10:11.267+0700] {subprocess.py:93} INFO - 25/06/26 20:10:11 INFO TaskSetManager: Finished task 48.0 in stage 0.0 (TID 48) in 91 ms on localhost (executor driver) (47/2334)
[2025-06-26T20:10:11.268+0700] {subprocess.py:93} INFO - 25/06/26 20:10:11 INFO TaskSetManager: Finished task 49.0 in stage 0.0 (TID 49) in 90 ms on localhost (executor driver) (48/2334)
[2025-06-26T20:10:11.269+0700] {subprocess.py:93} INFO - 25/06/26 20:10:11 INFO Executor: Finished task 64.0 in stage 0.0 (TID 64). 3175 bytes result sent to driver
[2025-06-26T20:10:11.269+0700] {subprocess.py:93} INFO - 25/06/26 20:10:11 INFO TaskSetManager: Finished task 43.0 in stage 0.0 (TID 43) in 102 ms on localhost (executor driver) (49/2334)
[2025-06-26T20:10:11.286+0700] {subprocess.py:93} INFO - 25/06/26 20:10:11 INFO Executor: Finished task 71.0 in stage 0.0 (TID 71). 3175 bytes result sent to driver
[2025-06-26T20:10:11.286+0700] {subprocess.py:93} INFO - 25/06/26 20:10:11 INFO TaskSetManager: Finished task 52.0 in stage 0.0 (TID 52) in 89 ms on localhost (executor driver) (50/2334)
[2025-06-26T20:10:11.286+0700] {subprocess.py:93} INFO - 25/06/26 20:10:11 INFO Executor: Finished task 67.0 in stage 0.0 (TID 67). 3175 bytes result sent to driver
[2025-06-26T20:10:11.286+0700] {subprocess.py:93} INFO - 25/06/26 20:10:11 INFO Executor: Finished task 57.0 in stage 0.0 (TID 57). 3218 bytes result sent to driver
[2025-06-26T20:10:11.287+0700] {subprocess.py:93} INFO - 25/06/26 20:10:11 INFO TaskSetManager: Finished task 51.0 in stage 0.0 (TID 51) in 108 ms on localhost (executor driver) (51/2334)
[2025-06-26T20:10:11.288+0700] {subprocess.py:93} INFO - 25/06/26 20:10:11 INFO TaskSetManager: Finished task 53.0 in stage 0.0 (TID 53) in 105 ms on localhost (executor driver) (52/2334)
[2025-06-26T20:10:11.288+0700] {subprocess.py:93} INFO - 25/06/26 20:10:11 INFO Executor: Finished task 66.0 in stage 0.0 (TID 66). 3261 bytes result sent to driver
[2025-06-26T20:10:11.288+0700] {subprocess.py:93} INFO - 25/06/26 20:10:11 INFO Executor: Finished task 68.0 in stage 0.0 (TID 68). 3261 bytes result sent to driver
[2025-06-26T20:10:11.288+0700] {subprocess.py:93} INFO - 25/06/26 20:10:11 INFO Executor: Finished task 65.0 in stage 0.0 (TID 65). 3218 bytes result sent to driver
[2025-06-26T20:10:11.288+0700] {subprocess.py:93} INFO - 25/06/26 20:10:11 INFO TaskSetManager: Finished task 50.0 in stage 0.0 (TID 50) in 110 ms on localhost (executor driver) (53/2334)
[2025-06-26T20:10:11.291+0700] {subprocess.py:93} INFO - 25/06/26 20:10:11 INFO TaskSetManager: Starting task 76.0 in stage 0.0 (TID 76) (localhost, executor driver, partition 76, PROCESS_LOCAL, 9215 bytes)
[2025-06-26T20:10:11.291+0700] {subprocess.py:93} INFO - 25/06/26 20:10:11 INFO Executor: Finished task 69.0 in stage 0.0 (TID 69). 3218 bytes result sent to driver
[2025-06-26T20:10:11.292+0700] {subprocess.py:93} INFO - 25/06/26 20:10:11 INFO Executor: Running task 76.0 in stage 0.0 (TID 76)
[2025-06-26T20:10:11.292+0700] {subprocess.py:93} INFO - 25/06/26 20:10:11 INFO TaskSetManager: Finished task 60.0 in stage 0.0 (TID 60) in 97 ms on localhost (executor driver) (54/2334)
[2025-06-26T20:10:11.292+0700] {subprocess.py:93} INFO - 25/06/26 20:10:11 INFO Executor: Finished task 70.0 in stage 0.0 (TID 70). 3261 bytes result sent to driver
[2025-06-26T20:10:11.295+0700] {subprocess.py:93} INFO - 25/06/26 20:10:11 INFO TaskSetManager: Starting task 77.0 in stage 0.0 (TID 77) (localhost, executor driver, partition 77, PROCESS_LOCAL, 9215 bytes)
[2025-06-26T20:10:11.295+0700] {subprocess.py:93} INFO - 25/06/26 20:10:11 INFO Executor: Finished task 72.0 in stage 0.0 (TID 72). 3218 bytes result sent to driver
[2025-06-26T20:10:11.295+0700] {subprocess.py:93} INFO - 25/06/26 20:10:11 INFO Executor: Running task 77.0 in stage 0.0 (TID 77)
[2025-06-26T20:10:11.296+0700] {subprocess.py:93} INFO - 25/06/26 20:10:11 INFO TaskSetManager: Finished task 47.0 in stage 0.0 (TID 47) in 120 ms on localhost (executor driver) (55/2334)
[2025-06-26T20:10:11.296+0700] {subprocess.py:93} INFO - 25/06/26 20:10:11 INFO Executor: Finished task 75.0 in stage 0.0 (TID 75). 3218 bytes result sent to driver
[2025-06-26T20:10:11.298+0700] {subprocess.py:93} INFO - 25/06/26 20:10:11 INFO TaskSetManager: Starting task 78.0 in stage 0.0 (TID 78) (localhost, executor driver, partition 78, PROCESS_LOCAL, 9215 bytes)
[2025-06-26T20:10:11.299+0700] {subprocess.py:93} INFO - 25/06/26 20:10:11 INFO TaskSetManager: Finished task 54.0 in stage 0.0 (TID 54) in 113 ms on localhost (executor driver) (56/2334)
[2025-06-26T20:10:11.299+0700] {subprocess.py:93} INFO - 25/06/26 20:10:11 INFO Executor: Running task 78.0 in stage 0.0 (TID 78)
[2025-06-26T20:10:11.299+0700] {subprocess.py:93} INFO - 25/06/26 20:10:11 INFO Executor: Finished task 73.0 in stage 0.0 (TID 73). 3218 bytes result sent to driver
[2025-06-26T20:10:11.299+0700] {subprocess.py:93} INFO - 25/06/26 20:10:11 INFO Executor: Finished task 74.0 in stage 0.0 (TID 74). 3218 bytes result sent to driver
[2025-06-26T20:10:11.300+0700] {subprocess.py:93} INFO - 25/06/26 20:10:11 INFO TaskSetManager: Starting task 79.0 in stage 0.0 (TID 79) (localhost, executor driver, partition 79, PROCESS_LOCAL, 9215 bytes)
[2025-06-26T20:10:11.300+0700] {subprocess.py:93} INFO - 25/06/26 20:10:11 INFO Executor: Running task 79.0 in stage 0.0 (TID 79)
[2025-06-26T20:10:11.301+0700] {subprocess.py:93} INFO - 25/06/26 20:10:11 INFO TaskSetManager: Starting task 80.0 in stage 0.0 (TID 80) (localhost, executor driver, partition 80, PROCESS_LOCAL, 9215 bytes)
[2025-06-26T20:10:11.301+0700] {subprocess.py:93} INFO - 25/06/26 20:10:11 INFO TaskSetManager: Finished task 56.0 in stage 0.0 (TID 56) in 114 ms on localhost (executor driver) (57/2334)
[2025-06-26T20:10:11.302+0700] {subprocess.py:93} INFO - 25/06/26 20:10:11 INFO Executor: Running task 80.0 in stage 0.0 (TID 80)
[2025-06-26T20:10:11.302+0700] {subprocess.py:93} INFO - 25/06/26 20:10:11 INFO TaskSetManager: Finished task 61.0 in stage 0.0 (TID 61) in 104 ms on localhost (executor driver) (58/2334)
[2025-06-26T20:10:11.302+0700] {subprocess.py:93} INFO - 25/06/26 20:10:11 INFO TaskSetManager: Finished task 59.0 in stage 0.0 (TID 59) in 109 ms on localhost (executor driver) (59/2334)
[2025-06-26T20:10:11.304+0700] {subprocess.py:93} INFO - 25/06/26 20:10:11 INFO Executor: Finished task 76.0 in stage 0.0 (TID 76). 3175 bytes result sent to driver
[2025-06-26T20:10:11.304+0700] {subprocess.py:93} INFO - 25/06/26 20:10:11 INFO TaskSetManager: Starting task 81.0 in stage 0.0 (TID 81) (localhost, executor driver, partition 81, PROCESS_LOCAL, 9215 bytes)
[2025-06-26T20:10:11.304+0700] {subprocess.py:93} INFO - 25/06/26 20:10:11 INFO Executor: Running task 81.0 in stage 0.0 (TID 81)
[2025-06-26T20:10:11.305+0700] {subprocess.py:93} INFO - 25/06/26 20:10:11 INFO TaskSetManager: Starting task 82.0 in stage 0.0 (TID 82) (localhost, executor driver, partition 82, PROCESS_LOCAL, 9215 bytes)
[2025-06-26T20:10:11.306+0700] {subprocess.py:93} INFO - 25/06/26 20:10:11 INFO TaskSetManager: Finished task 62.0 in stage 0.0 (TID 62) in 106 ms on localhost (executor driver) (60/2334)
[2025-06-26T20:10:11.306+0700] {subprocess.py:93} INFO - 25/06/26 20:10:11 INFO Executor: Running task 82.0 in stage 0.0 (TID 82)
[2025-06-26T20:10:11.308+0700] {subprocess.py:93} INFO - 25/06/26 20:10:11 INFO TaskSetManager: Starting task 83.0 in stage 0.0 (TID 83) (localhost, executor driver, partition 83, PROCESS_LOCAL, 9215 bytes)
[2025-06-26T20:10:11.312+0700] {subprocess.py:93} INFO - 25/06/26 20:10:11 INFO Executor: Running task 83.0 in stage 0.0 (TID 83)
[2025-06-26T20:10:11.312+0700] {subprocess.py:93} INFO - 25/06/26 20:10:11 INFO TaskSetManager: Finished task 58.0 in stage 0.0 (TID 58) in 116 ms on localhost (executor driver) (61/2334)
[2025-06-26T20:10:11.312+0700] {subprocess.py:93} INFO - 25/06/26 20:10:11 INFO Executor: Finished task 77.0 in stage 0.0 (TID 77). 3175 bytes result sent to driver
[2025-06-26T20:10:11.313+0700] {subprocess.py:93} INFO - 25/06/26 20:10:11 INFO TaskSetManager: Starting task 84.0 in stage 0.0 (TID 84) (localhost, executor driver, partition 84, PROCESS_LOCAL, 9215 bytes)
[2025-06-26T20:10:11.313+0700] {subprocess.py:93} INFO - 25/06/26 20:10:11 INFO Executor: Running task 84.0 in stage 0.0 (TID 84)
[2025-06-26T20:10:11.313+0700] {subprocess.py:93} INFO - 25/06/26 20:10:11 INFO TaskSetManager: Starting task 85.0 in stage 0.0 (TID 85) (localhost, executor driver, partition 85, PROCESS_LOCAL, 9215 bytes)
[2025-06-26T20:10:11.313+0700] {subprocess.py:93} INFO - 25/06/26 20:10:11 INFO Executor: Running task 85.0 in stage 0.0 (TID 85)
[2025-06-26T20:10:11.313+0700] {subprocess.py:93} INFO - 25/06/26 20:10:11 INFO TaskSetManager: Finished task 63.0 in stage 0.0 (TID 63) in 110 ms on localhost (executor driver) (62/2334)
[2025-06-26T20:10:11.335+0700] {subprocess.py:93} INFO - 25/06/26 20:10:11 INFO TaskSetManager: Starting task 86.0 in stage 0.0 (TID 86) (localhost, executor driver, partition 86, PROCESS_LOCAL, 9215 bytes)
[2025-06-26T20:10:11.336+0700] {subprocess.py:93} INFO - 25/06/26 20:10:11 INFO Executor: Finished task 78.0 in stage 0.0 (TID 78). 3218 bytes result sent to driver
[2025-06-26T20:10:11.337+0700] {subprocess.py:93} INFO - 25/06/26 20:10:11 INFO Executor: Running task 86.0 in stage 0.0 (TID 86)
[2025-06-26T20:10:11.338+0700] {subprocess.py:93} INFO - 25/06/26 20:10:11 INFO TaskSetManager: Starting task 87.0 in stage 0.0 (TID 87) (localhost, executor driver, partition 87, PROCESS_LOCAL, 9215 bytes)
[2025-06-26T20:10:11.338+0700] {subprocess.py:93} INFO - 25/06/26 20:10:11 INFO TaskSetManager: Finished task 55.0 in stage 0.0 (TID 55) in 152 ms on localhost (executor driver) (63/2334)
[2025-06-26T20:10:11.339+0700] {subprocess.py:93} INFO - 25/06/26 20:10:11 INFO TaskSetManager: Finished task 64.0 in stage 0.0 (TID 64) in 136 ms on localhost (executor driver) (64/2334)
[2025-06-26T20:10:11.339+0700] {subprocess.py:93} INFO - 25/06/26 20:10:11 INFO TaskSetManager: Finished task 71.0 in stage 0.0 (TID 71) in 108 ms on localhost (executor driver) (65/2334)
[2025-06-26T20:10:11.341+0700] {subprocess.py:93} INFO - 25/06/26 20:10:11 INFO TaskSetManager: Starting task 88.0 in stage 0.0 (TID 88) (localhost, executor driver, partition 88, PROCESS_LOCAL, 9215 bytes)
[2025-06-26T20:10:11.342+0700] {subprocess.py:93} INFO - 25/06/26 20:10:11 INFO Executor: Finished task 80.0 in stage 0.0 (TID 80). 3175 bytes result sent to driver
[2025-06-26T20:10:11.342+0700] {subprocess.py:93} INFO - 25/06/26 20:10:11 INFO TaskSetManager: Starting task 89.0 in stage 0.0 (TID 89) (localhost, executor driver, partition 89, PROCESS_LOCAL, 9215 bytes)
[2025-06-26T20:10:11.343+0700] {subprocess.py:93} INFO - 25/06/26 20:10:11 INFO Executor: Finished task 81.0 in stage 0.0 (TID 81). 3175 bytes result sent to driver
[2025-06-26T20:10:11.344+0700] {subprocess.py:93} INFO - 25/06/26 20:10:11 INFO Executor: Running task 87.0 in stage 0.0 (TID 87)
[2025-06-26T20:10:11.345+0700] {subprocess.py:93} INFO - 25/06/26 20:10:11 INFO Executor: Running task 89.0 in stage 0.0 (TID 89)
[2025-06-26T20:10:11.345+0700] {subprocess.py:93} INFO - 25/06/26 20:10:11 INFO Executor: Finished task 79.0 in stage 0.0 (TID 79). 3175 bytes result sent to driver
[2025-06-26T20:10:11.345+0700] {subprocess.py:93} INFO - 25/06/26 20:10:11 INFO TaskSetManager: Starting task 90.0 in stage 0.0 (TID 90) (localhost, executor driver, partition 90, PROCESS_LOCAL, 9215 bytes)
[2025-06-26T20:10:11.345+0700] {subprocess.py:93} INFO - 25/06/26 20:10:11 INFO Executor: Running task 88.0 in stage 0.0 (TID 88)
[2025-06-26T20:10:11.345+0700] {subprocess.py:93} INFO - 25/06/26 20:10:11 INFO Executor: Finished task 82.0 in stage 0.0 (TID 82). 3175 bytes result sent to driver
[2025-06-26T20:10:11.345+0700] {subprocess.py:93} INFO - 25/06/26 20:10:11 INFO TaskSetManager: Starting task 91.0 in stage 0.0 (TID 91) (localhost, executor driver, partition 91, PROCESS_LOCAL, 9215 bytes)
[2025-06-26T20:10:11.345+0700] {subprocess.py:93} INFO - 25/06/26 20:10:11 INFO Executor: Running task 90.0 in stage 0.0 (TID 90)
[2025-06-26T20:10:11.345+0700] {subprocess.py:93} INFO - 25/06/26 20:10:11 INFO Executor: Running task 91.0 in stage 0.0 (TID 91)
[2025-06-26T20:10:11.347+0700] {subprocess.py:93} INFO - 25/06/26 20:10:11 INFO Executor: Finished task 85.0 in stage 0.0 (TID 85). 3175 bytes result sent to driver
[2025-06-26T20:10:11.348+0700] {subprocess.py:93} INFO - 25/06/26 20:10:11 INFO TaskSetManager: Starting task 92.0 in stage 0.0 (TID 92) (localhost, executor driver, partition 92, PROCESS_LOCAL, 9215 bytes)
[2025-06-26T20:10:11.348+0700] {subprocess.py:93} INFO - 25/06/26 20:10:11 INFO Executor: Finished task 83.0 in stage 0.0 (TID 83). 3218 bytes result sent to driver
[2025-06-26T20:10:11.348+0700] {subprocess.py:93} INFO - 25/06/26 20:10:11 INFO TaskSetManager: Finished task 67.0 in stage 0.0 (TID 67) in 131 ms on localhost (executor driver) (66/2334)
[2025-06-26T20:10:11.348+0700] {subprocess.py:93} INFO - 25/06/26 20:10:11 INFO Executor: Running task 92.0 in stage 0.0 (TID 92)
[2025-06-26T20:10:11.349+0700] {subprocess.py:93} INFO - 25/06/26 20:10:11 INFO Executor: Finished task 84.0 in stage 0.0 (TID 84). 3175 bytes result sent to driver
[2025-06-26T20:10:11.350+0700] {subprocess.py:93} INFO - 25/06/26 20:10:11 INFO TaskSetManager: Starting task 93.0 in stage 0.0 (TID 93) (localhost, executor driver, partition 93, PROCESS_LOCAL, 9215 bytes)
[2025-06-26T20:10:11.350+0700] {subprocess.py:93} INFO - 25/06/26 20:10:11 INFO TaskSetManager: Finished task 57.0 in stage 0.0 (TID 57) in 161 ms on localhost (executor driver) (67/2334)
[2025-06-26T20:10:11.351+0700] {subprocess.py:93} INFO - 25/06/26 20:10:11 INFO TaskSetManager: Finished task 66.0 in stage 0.0 (TID 66) in 139 ms on localhost (executor driver) (68/2334)
[2025-06-26T20:10:11.352+0700] {subprocess.py:93} INFO - 25/06/26 20:10:11 INFO TaskSetManager: Starting task 94.0 in stage 0.0 (TID 94) (localhost, executor driver, partition 94, PROCESS_LOCAL, 9215 bytes)
[2025-06-26T20:10:11.352+0700] {subprocess.py:93} INFO - 25/06/26 20:10:11 INFO Executor: Running task 93.0 in stage 0.0 (TID 93)
[2025-06-26T20:10:11.352+0700] {subprocess.py:93} INFO - 25/06/26 20:10:11 INFO TaskSetManager: Finished task 68.0 in stage 0.0 (TID 68) in 135 ms on localhost (executor driver) (69/2334)
[2025-06-26T20:10:11.352+0700] {subprocess.py:93} INFO - 25/06/26 20:10:11 INFO Executor: Running task 94.0 in stage 0.0 (TID 94)
[2025-06-26T20:10:11.353+0700] {subprocess.py:93} INFO - 25/06/26 20:10:11 INFO TaskSetManager: Starting task 95.0 in stage 0.0 (TID 95) (localhost, executor driver, partition 95, PROCESS_LOCAL, 9215 bytes)
[2025-06-26T20:10:11.354+0700] {subprocess.py:93} INFO - 25/06/26 20:10:11 INFO Executor: Running task 95.0 in stage 0.0 (TID 95)
[2025-06-26T20:10:11.356+0700] {subprocess.py:93} INFO - 25/06/26 20:10:11 INFO TaskSetManager: Starting task 96.0 in stage 0.0 (TID 96) (localhost, executor driver, partition 96, PROCESS_LOCAL, 9215 bytes)
[2025-06-26T20:10:11.357+0700] {subprocess.py:93} INFO - 25/06/26 20:10:11 INFO TaskSetManager: Starting task 97.0 in stage 0.0 (TID 97) (localhost, executor driver, partition 97, PROCESS_LOCAL, 9215 bytes)
[2025-06-26T20:10:11.358+0700] {subprocess.py:93} INFO - 25/06/26 20:10:11 INFO Executor: Running task 96.0 in stage 0.0 (TID 96)
[2025-06-26T20:10:11.358+0700] {subprocess.py:93} INFO - 25/06/26 20:10:11 INFO TaskSetManager: Starting task 98.0 in stage 0.0 (TID 98) (localhost, executor driver, partition 98, PROCESS_LOCAL, 9215 bytes)
[2025-06-26T20:10:11.358+0700] {subprocess.py:93} INFO - 25/06/26 20:10:11 INFO Executor: Running task 97.0 in stage 0.0 (TID 97)
[2025-06-26T20:10:11.358+0700] {subprocess.py:93} INFO - 25/06/26 20:10:11 INFO TaskSetManager: Finished task 65.0 in stage 0.0 (TID 65) in 153 ms on localhost (executor driver) (70/2334)
[2025-06-26T20:10:11.359+0700] {subprocess.py:93} INFO - 25/06/26 20:10:11 INFO Executor: Running task 98.0 in stage 0.0 (TID 98)
[2025-06-26T20:10:11.359+0700] {subprocess.py:93} INFO - 25/06/26 20:10:11 INFO TaskSetManager: Starting task 99.0 in stage 0.0 (TID 99) (localhost, executor driver, partition 99, PROCESS_LOCAL, 9215 bytes)
[2025-06-26T20:10:11.359+0700] {subprocess.py:93} INFO - 25/06/26 20:10:11 INFO TaskSetManager: Finished task 69.0 in stage 0.0 (TID 69) in 133 ms on localhost (executor driver) (71/2334)
[2025-06-26T20:10:11.361+0700] {subprocess.py:93} INFO - 25/06/26 20:10:11 INFO Executor: Finished task 86.0 in stage 0.0 (TID 86). 3175 bytes result sent to driver
[2025-06-26T20:10:11.361+0700] {subprocess.py:93} INFO - 25/06/26 20:10:11 INFO Executor: Running task 99.0 in stage 0.0 (TID 99)
[2025-06-26T20:10:11.362+0700] {subprocess.py:93} INFO - 25/06/26 20:10:11 INFO TaskSetManager: Finished task 70.0 in stage 0.0 (TID 70) in 130 ms on localhost (executor driver) (72/2334)
[2025-06-26T20:10:11.362+0700] {subprocess.py:93} INFO - 25/06/26 20:10:11 INFO TaskSetManager: Finished task 73.0 in stage 0.0 (TID 73) in 118 ms on localhost (executor driver) (73/2334)
[2025-06-26T20:10:11.362+0700] {subprocess.py:93} INFO - 25/06/26 20:10:11 INFO TaskSetManager: Finished task 76.0 in stage 0.0 (TID 76) in 71 ms on localhost (executor driver) (74/2334)
[2025-06-26T20:10:11.362+0700] {subprocess.py:93} INFO - 25/06/26 20:10:11 INFO Executor: Finished task 90.0 in stage 0.0 (TID 90). 3175 bytes result sent to driver
[2025-06-26T20:10:11.362+0700] {subprocess.py:93} INFO - 25/06/26 20:10:11 INFO TaskSetManager: Finished task 77.0 in stage 0.0 (TID 77) in 69 ms on localhost (executor driver) (75/2334)
[2025-06-26T20:10:11.362+0700] {subprocess.py:93} INFO - 25/06/26 20:10:11 INFO TaskSetManager: Finished task 74.0 in stage 0.0 (TID 74) in 113 ms on localhost (executor driver) (76/2334)
[2025-06-26T20:10:11.363+0700] {subprocess.py:93} INFO - 25/06/26 20:10:11 INFO Executor: Finished task 89.0 in stage 0.0 (TID 89). 3175 bytes result sent to driver
[2025-06-26T20:10:11.363+0700] {subprocess.py:93} INFO - 25/06/26 20:10:11 INFO TaskSetManager: Starting task 100.0 in stage 0.0 (TID 100) (localhost, executor driver, partition 100, PROCESS_LOCAL, 9215 bytes)
[2025-06-26T20:10:11.364+0700] {subprocess.py:93} INFO - 25/06/26 20:10:11 INFO Executor: Finished task 87.0 in stage 0.0 (TID 87). 3175 bytes result sent to driver
[2025-06-26T20:10:11.364+0700] {subprocess.py:93} INFO - 25/06/26 20:10:11 INFO Executor: Finished task 88.0 in stage 0.0 (TID 88). 3175 bytes result sent to driver
[2025-06-26T20:10:11.364+0700] {subprocess.py:93} INFO - 25/06/26 20:10:11 INFO Executor: Finished task 92.0 in stage 0.0 (TID 92). 3175 bytes result sent to driver
[2025-06-26T20:10:11.364+0700] {subprocess.py:93} INFO - 25/06/26 20:10:11 INFO TaskSetManager: Finished task 72.0 in stage 0.0 (TID 72) in 129 ms on localhost (executor driver) (77/2334)
[2025-06-26T20:10:11.365+0700] {subprocess.py:93} INFO - 25/06/26 20:10:11 INFO Executor: Finished task 91.0 in stage 0.0 (TID 91). 3175 bytes result sent to driver
[2025-06-26T20:10:11.365+0700] {subprocess.py:93} INFO - 25/06/26 20:10:11 INFO Executor: Running task 100.0 in stage 0.0 (TID 100)
[2025-06-26T20:10:11.365+0700] {subprocess.py:93} INFO - 25/06/26 20:10:11 INFO TaskSetManager: Finished task 78.0 in stage 0.0 (TID 78) in 67 ms on localhost (executor driver) (78/2334)
[2025-06-26T20:10:11.366+0700] {subprocess.py:93} INFO - 25/06/26 20:10:11 INFO TaskSetManager: Finished task 75.0 in stage 0.0 (TID 75) in 104 ms on localhost (executor driver) (79/2334)
[2025-06-26T20:10:11.367+0700] {subprocess.py:93} INFO - 25/06/26 20:10:11 INFO TaskSetManager: Starting task 101.0 in stage 0.0 (TID 101) (localhost, executor driver, partition 101, PROCESS_LOCAL, 9215 bytes)
[2025-06-26T20:10:11.368+0700] {subprocess.py:93} INFO - 25/06/26 20:10:11 INFO Executor: Running task 101.0 in stage 0.0 (TID 101)
[2025-06-26T20:10:11.369+0700] {subprocess.py:93} INFO - 25/06/26 20:10:11 INFO TaskSetManager: Starting task 102.0 in stage 0.0 (TID 102) (localhost, executor driver, partition 102, PROCESS_LOCAL, 9215 bytes)
[2025-06-26T20:10:11.369+0700] {subprocess.py:93} INFO - 25/06/26 20:10:11 INFO Executor: Finished task 94.0 in stage 0.0 (TID 94). 3175 bytes result sent to driver
[2025-06-26T20:10:11.369+0700] {subprocess.py:93} INFO - 25/06/26 20:10:11 INFO Executor: Finished task 93.0 in stage 0.0 (TID 93). 3175 bytes result sent to driver
[2025-06-26T20:10:11.369+0700] {subprocess.py:93} INFO - 25/06/26 20:10:11 INFO Executor: Finished task 95.0 in stage 0.0 (TID 95). 3175 bytes result sent to driver
[2025-06-26T20:10:11.369+0700] {subprocess.py:93} INFO - 25/06/26 20:10:11 INFO TaskSetManager: Finished task 80.0 in stage 0.0 (TID 80) in 69 ms on localhost (executor driver) (80/2334)
[2025-06-26T20:10:11.370+0700] {subprocess.py:93} INFO - 25/06/26 20:10:11 INFO Executor: Running task 102.0 in stage 0.0 (TID 102)
[2025-06-26T20:10:11.370+0700] {subprocess.py:93} INFO - 25/06/26 20:10:11 INFO TaskSetManager: Finished task 81.0 in stage 0.0 (TID 81) in 66 ms on localhost (executor driver) (81/2334)
[2025-06-26T20:10:11.370+0700] {subprocess.py:93} INFO - 25/06/26 20:10:11 INFO Executor: Finished task 97.0 in stage 0.0 (TID 97). 3175 bytes result sent to driver
[2025-06-26T20:10:11.370+0700] {subprocess.py:93} INFO - 25/06/26 20:10:11 INFO TaskSetManager: Starting task 103.0 in stage 0.0 (TID 103) (localhost, executor driver, partition 103, PROCESS_LOCAL, 9215 bytes)
[2025-06-26T20:10:11.370+0700] {subprocess.py:93} INFO - 25/06/26 20:10:11 INFO Executor: Running task 103.0 in stage 0.0 (TID 103)
[2025-06-26T20:10:11.371+0700] {subprocess.py:93} INFO - 25/06/26 20:10:11 INFO TaskSetManager: Starting task 104.0 in stage 0.0 (TID 104) (localhost, executor driver, partition 104, PROCESS_LOCAL, 9215 bytes)
[2025-06-26T20:10:11.371+0700] {subprocess.py:93} INFO - 25/06/26 20:10:11 INFO Executor: Running task 104.0 in stage 0.0 (TID 104)
[2025-06-26T20:10:11.372+0700] {subprocess.py:93} INFO - 25/06/26 20:10:11 INFO Executor: Finished task 98.0 in stage 0.0 (TID 98). 3175 bytes result sent to driver
[2025-06-26T20:10:11.372+0700] {subprocess.py:93} INFO - 25/06/26 20:10:11 INFO TaskSetManager: Starting task 105.0 in stage 0.0 (TID 105) (localhost, executor driver, partition 105, PROCESS_LOCAL, 9215 bytes)
[2025-06-26T20:10:11.372+0700] {subprocess.py:93} INFO - 25/06/26 20:10:11 INFO TaskSetManager: Finished task 82.0 in stage 0.0 (TID 82) in 67 ms on localhost (executor driver) (82/2334)
[2025-06-26T20:10:11.372+0700] {subprocess.py:93} INFO - 25/06/26 20:10:11 INFO Executor: Running task 105.0 in stage 0.0 (TID 105)
[2025-06-26T20:10:11.373+0700] {subprocess.py:93} INFO - 25/06/26 20:10:11 INFO Executor: Finished task 99.0 in stage 0.0 (TID 99). 3175 bytes result sent to driver
[2025-06-26T20:10:11.374+0700] {subprocess.py:93} INFO - 25/06/26 20:10:11 INFO Executor: Finished task 96.0 in stage 0.0 (TID 96). 3175 bytes result sent to driver
[2025-06-26T20:10:11.374+0700] {subprocess.py:93} INFO - 25/06/26 20:10:11 INFO TaskSetManager: Starting task 106.0 in stage 0.0 (TID 106) (localhost, executor driver, partition 106, PROCESS_LOCAL, 9215 bytes)
[2025-06-26T20:10:11.375+0700] {subprocess.py:93} INFO - 25/06/26 20:10:11 INFO Executor: Running task 106.0 in stage 0.0 (TID 106)
[2025-06-26T20:10:11.375+0700] {subprocess.py:93} INFO - 25/06/26 20:10:11 INFO TaskSetManager: Finished task 79.0 in stage 0.0 (TID 79) in 74 ms on localhost (executor driver) (83/2334)
[2025-06-26T20:10:11.375+0700] {subprocess.py:93} INFO - 25/06/26 20:10:11 INFO TaskSetManager: Finished task 85.0 in stage 0.0 (TID 85) in 64 ms on localhost (executor driver) (84/2334)
[2025-06-26T20:10:11.376+0700] {subprocess.py:93} INFO - 25/06/26 20:10:11 INFO TaskSetManager: Starting task 107.0 in stage 0.0 (TID 107) (localhost, executor driver, partition 107, PROCESS_LOCAL, 9215 bytes)
[2025-06-26T20:10:11.376+0700] {subprocess.py:93} INFO - 25/06/26 20:10:11 INFO Executor: Finished task 100.0 in stage 0.0 (TID 100). 3175 bytes result sent to driver
[2025-06-26T20:10:11.377+0700] {subprocess.py:93} INFO - 25/06/26 20:10:11 INFO Executor: Running task 107.0 in stage 0.0 (TID 107)
[2025-06-26T20:10:11.377+0700] {subprocess.py:93} INFO - 25/06/26 20:10:11 INFO TaskSetManager: Starting task 108.0 in stage 0.0 (TID 108) (localhost, executor driver, partition 108, PROCESS_LOCAL, 9215 bytes)
[2025-06-26T20:10:11.378+0700] {subprocess.py:93} INFO - 25/06/26 20:10:11 INFO TaskSetManager: Finished task 83.0 in stage 0.0 (TID 83) in 72 ms on localhost (executor driver) (85/2334)
[2025-06-26T20:10:11.378+0700] {subprocess.py:93} INFO - 25/06/26 20:10:11 INFO Executor: Running task 108.0 in stage 0.0 (TID 108)
[2025-06-26T20:10:11.387+0700] {subprocess.py:93} INFO - 25/06/26 20:10:11 INFO TaskSetManager: Starting task 109.0 in stage 0.0 (TID 109) (localhost, executor driver, partition 109, PROCESS_LOCAL, 9215 bytes)
[2025-06-26T20:10:11.388+0700] {subprocess.py:93} INFO - 25/06/26 20:10:11 INFO Executor: Finished task 102.0 in stage 0.0 (TID 102). 3261 bytes result sent to driver
[2025-06-26T20:10:11.389+0700] {subprocess.py:93} INFO - 25/06/26 20:10:11 INFO Executor: Running task 109.0 in stage 0.0 (TID 109)
[2025-06-26T20:10:11.389+0700] {subprocess.py:93} INFO - 25/06/26 20:10:11 INFO Executor: Finished task 101.0 in stage 0.0 (TID 101). 3175 bytes result sent to driver
[2025-06-26T20:10:11.389+0700] {subprocess.py:93} INFO - 25/06/26 20:10:11 INFO TaskSetManager: Starting task 110.0 in stage 0.0 (TID 110) (localhost, executor driver, partition 110, PROCESS_LOCAL, 9215 bytes)
[2025-06-26T20:10:11.390+0700] {subprocess.py:93} INFO - 25/06/26 20:10:11 INFO TaskSetManager: Finished task 90.0 in stage 0.0 (TID 90) in 47 ms on localhost (executor driver) (86/2334)
[2025-06-26T20:10:11.390+0700] {subprocess.py:93} INFO - 25/06/26 20:10:11 INFO Executor: Running task 110.0 in stage 0.0 (TID 110)
[2025-06-26T20:10:11.390+0700] {subprocess.py:93} INFO - 25/06/26 20:10:11 INFO TaskSetManager: Finished task 84.0 in stage 0.0 (TID 84) in 81 ms on localhost (executor driver) (87/2334)
[2025-06-26T20:10:11.390+0700] {subprocess.py:93} INFO - 25/06/26 20:10:11 INFO TaskSetManager: Finished task 86.0 in stage 0.0 (TID 86) in 77 ms on localhost (executor driver) (88/2334)
[2025-06-26T20:10:11.391+0700] {subprocess.py:93} INFO - 25/06/26 20:10:11 INFO Executor: Finished task 103.0 in stage 0.0 (TID 103). 3261 bytes result sent to driver
[2025-06-26T20:10:11.391+0700] {subprocess.py:93} INFO - 25/06/26 20:10:11 INFO TaskSetManager: Finished task 89.0 in stage 0.0 (TID 89) in 49 ms on localhost (executor driver) (89/2334)
[2025-06-26T20:10:11.391+0700] {subprocess.py:93} INFO - 25/06/26 20:10:11 INFO Executor: Finished task 104.0 in stage 0.0 (TID 104). 3218 bytes result sent to driver
[2025-06-26T20:10:11.393+0700] {subprocess.py:93} INFO - 25/06/26 20:10:11 INFO TaskSetManager: Starting task 111.0 in stage 0.0 (TID 111) (localhost, executor driver, partition 111, PROCESS_LOCAL, 9215 bytes)
[2025-06-26T20:10:11.393+0700] {subprocess.py:93} INFO - 25/06/26 20:10:11 INFO Executor: Finished task 106.0 in stage 0.0 (TID 106). 3218 bytes result sent to driver
[2025-06-26T20:10:11.393+0700] {subprocess.py:93} INFO - 25/06/26 20:10:11 INFO Executor: Finished task 107.0 in stage 0.0 (TID 107). 3218 bytes result sent to driver
[2025-06-26T20:10:11.394+0700] {subprocess.py:93} INFO - 25/06/26 20:10:11 INFO Executor: Running task 111.0 in stage 0.0 (TID 111)
[2025-06-26T20:10:11.395+0700] {subprocess.py:93} INFO - 25/06/26 20:10:11 INFO TaskSetManager: Starting task 112.0 in stage 0.0 (TID 112) (localhost, executor driver, partition 112, PROCESS_LOCAL, 9215 bytes)
[2025-06-26T20:10:11.395+0700] {subprocess.py:93} INFO - 25/06/26 20:10:11 INFO TaskSetManager: Finished task 87.0 in stage 0.0 (TID 87) in 59 ms on localhost (executor driver) (90/2334)
[2025-06-26T20:10:11.395+0700] {subprocess.py:93} INFO - 25/06/26 20:10:11 INFO Executor: Running task 112.0 in stage 0.0 (TID 112)
[2025-06-26T20:10:11.396+0700] {subprocess.py:93} INFO - 25/06/26 20:10:11 INFO TaskSetManager: Finished task 92.0 in stage 0.0 (TID 92) in 49 ms on localhost (executor driver) (91/2334)
[2025-06-26T20:10:11.396+0700] {subprocess.py:93} INFO - 25/06/26 20:10:11 INFO Executor: Finished task 105.0 in stage 0.0 (TID 105). 3218 bytes result sent to driver
[2025-06-26T20:10:11.397+0700] {subprocess.py:93} INFO - 25/06/26 20:10:11 INFO TaskSetManager: Starting task 113.0 in stage 0.0 (TID 113) (localhost, executor driver, partition 113, PROCESS_LOCAL, 9215 bytes)
[2025-06-26T20:10:11.398+0700] {subprocess.py:93} INFO - 25/06/26 20:10:11 INFO Executor: Running task 113.0 in stage 0.0 (TID 113)
[2025-06-26T20:10:11.398+0700] {subprocess.py:93} INFO - 25/06/26 20:10:11 INFO TaskSetManager: Starting task 114.0 in stage 0.0 (TID 114) (localhost, executor driver, partition 114, PROCESS_LOCAL, 9215 bytes)
[2025-06-26T20:10:11.399+0700] {subprocess.py:93} INFO - 25/06/26 20:10:11 INFO TaskSetManager: Finished task 88.0 in stage 0.0 (TID 88) in 58 ms on localhost (executor driver) (92/2334)
[2025-06-26T20:10:11.399+0700] {subprocess.py:93} INFO - 25/06/26 20:10:11 INFO TaskSetManager: Finished task 91.0 in stage 0.0 (TID 91) in 56 ms on localhost (executor driver) (93/2334)
[2025-06-26T20:10:11.399+0700] {subprocess.py:93} INFO - 25/06/26 20:10:11 INFO Executor: Running task 114.0 in stage 0.0 (TID 114)
[2025-06-26T20:10:11.400+0700] {subprocess.py:93} INFO - 25/06/26 20:10:11 INFO TaskSetManager: Starting task 115.0 in stage 0.0 (TID 115) (localhost, executor driver, partition 115, PROCESS_LOCAL, 9215 bytes)
[2025-06-26T20:10:11.401+0700] {subprocess.py:93} INFO - 25/06/26 20:10:11 INFO Executor: Running task 115.0 in stage 0.0 (TID 115)
[2025-06-26T20:10:11.401+0700] {subprocess.py:93} INFO - 25/06/26 20:10:11 INFO Executor: Finished task 108.0 in stage 0.0 (TID 108). 3218 bytes result sent to driver
[2025-06-26T20:10:11.401+0700] {subprocess.py:93} INFO - 25/06/26 20:10:11 INFO TaskSetManager: Starting task 116.0 in stage 0.0 (TID 116) (localhost, executor driver, partition 116, PROCESS_LOCAL, 9215 bytes)
[2025-06-26T20:10:11.402+0700] {subprocess.py:93} INFO - 25/06/26 20:10:11 INFO TaskSetManager: Finished task 94.0 in stage 0.0 (TID 94) in 50 ms on localhost (executor driver) (94/2334)
[2025-06-26T20:10:11.402+0700] {subprocess.py:93} INFO - 25/06/26 20:10:11 INFO Executor: Running task 116.0 in stage 0.0 (TID 116)
[2025-06-26T20:10:11.402+0700] {subprocess.py:93} INFO - 25/06/26 20:10:11 INFO TaskSetManager: Finished task 95.0 in stage 0.0 (TID 95) in 49 ms on localhost (executor driver) (95/2334)
[2025-06-26T20:10:11.403+0700] {subprocess.py:93} INFO - 25/06/26 20:10:11 INFO TaskSetManager: Starting task 117.0 in stage 0.0 (TID 117) (localhost, executor driver, partition 117, PROCESS_LOCAL, 9215 bytes)
[2025-06-26T20:10:11.404+0700] {subprocess.py:93} INFO - 25/06/26 20:10:11 INFO Executor: Finished task 110.0 in stage 0.0 (TID 110). 3175 bytes result sent to driver
[2025-06-26T20:10:11.404+0700] {subprocess.py:93} INFO - 25/06/26 20:10:11 INFO Executor: Finished task 109.0 in stage 0.0 (TID 109). 3175 bytes result sent to driver
[2025-06-26T20:10:11.404+0700] {subprocess.py:93} INFO - 25/06/26 20:10:11 INFO Executor: Running task 117.0 in stage 0.0 (TID 117)
[2025-06-26T20:10:11.404+0700] {subprocess.py:93} INFO - 25/06/26 20:10:11 INFO TaskSetManager: Starting task 118.0 in stage 0.0 (TID 118) (localhost, executor driver, partition 118, PROCESS_LOCAL, 9215 bytes)
[2025-06-26T20:10:11.405+0700] {subprocess.py:93} INFO - 25/06/26 20:10:11 INFO TaskSetManager: Finished task 93.0 in stage 0.0 (TID 93) in 56 ms on localhost (executor driver) (96/2334)
[2025-06-26T20:10:11.405+0700] {subprocess.py:93} INFO - 25/06/26 20:10:11 INFO Executor: Running task 118.0 in stage 0.0 (TID 118)
[2025-06-26T20:10:11.405+0700] {subprocess.py:93} INFO - 25/06/26 20:10:11 INFO Executor: Finished task 111.0 in stage 0.0 (TID 111). 3175 bytes result sent to driver
[2025-06-26T20:10:11.405+0700] {subprocess.py:93} INFO - 25/06/26 20:10:11 INFO TaskSetManager: Starting task 119.0 in stage 0.0 (TID 119) (localhost, executor driver, partition 119, PROCESS_LOCAL, 9215 bytes)
[2025-06-26T20:10:11.406+0700] {subprocess.py:93} INFO - 25/06/26 20:10:11 INFO Executor: Running task 119.0 in stage 0.0 (TID 119)
[2025-06-26T20:10:11.407+0700] {subprocess.py:93} INFO - 25/06/26 20:10:11 INFO Executor: Finished task 112.0 in stage 0.0 (TID 112). 3175 bytes result sent to driver
[2025-06-26T20:10:11.407+0700] {subprocess.py:93} INFO - 25/06/26 20:10:11 INFO TaskSetManager: Starting task 120.0 in stage 0.0 (TID 120) (localhost, executor driver, partition 120, PROCESS_LOCAL, 9215 bytes)
[2025-06-26T20:10:11.407+0700] {subprocess.py:93} INFO - 25/06/26 20:10:11 INFO TaskSetManager: Finished task 97.0 in stage 0.0 (TID 97) in 51 ms on localhost (executor driver) (97/2334)
[2025-06-26T20:10:11.408+0700] {subprocess.py:93} INFO - 25/06/26 20:10:11 INFO Executor: Running task 120.0 in stage 0.0 (TID 120)
[2025-06-26T20:10:11.409+0700] {subprocess.py:93} INFO - 25/06/26 20:10:11 INFO TaskSetManager: Finished task 98.0 in stage 0.0 (TID 98) in 50 ms on localhost (executor driver) (98/2334)
[2025-06-26T20:10:11.417+0700] {subprocess.py:93} INFO - 25/06/26 20:10:11 INFO Executor: Finished task 114.0 in stage 0.0 (TID 114). 3175 bytes result sent to driver
[2025-06-26T20:10:11.418+0700] {subprocess.py:93} INFO - 25/06/26 20:10:11 INFO TaskSetManager: Starting task 121.0 in stage 0.0 (TID 121) (localhost, executor driver, partition 121, PROCESS_LOCAL, 9215 bytes)
[2025-06-26T20:10:11.418+0700] {subprocess.py:93} INFO - 25/06/26 20:10:11 INFO TaskSetManager: Finished task 99.0 in stage 0.0 (TID 99) in 59 ms on localhost (executor driver) (99/2334)
[2025-06-26T20:10:11.418+0700] {subprocess.py:93} INFO - 25/06/26 20:10:11 INFO Executor: Running task 121.0 in stage 0.0 (TID 121)
[2025-06-26T20:10:11.419+0700] {subprocess.py:93} INFO - 25/06/26 20:10:11 INFO TaskSetManager: Starting task 122.0 in stage 0.0 (TID 122) (localhost, executor driver, partition 122, PROCESS_LOCAL, 9215 bytes)
[2025-06-26T20:10:11.420+0700] {subprocess.py:93} INFO - 25/06/26 20:10:11 INFO TaskSetManager: Finished task 96.0 in stage 0.0 (TID 96) in 67 ms on localhost (executor driver) (100/2334)
[2025-06-26T20:10:11.420+0700] {subprocess.py:93} INFO - 25/06/26 20:10:11 INFO Executor: Running task 122.0 in stage 0.0 (TID 122)
[2025-06-26T20:10:11.421+0700] {subprocess.py:93} INFO - 25/06/26 20:10:11 INFO Executor: Finished task 113.0 in stage 0.0 (TID 113). 3175 bytes result sent to driver
[2025-06-26T20:10:11.421+0700] {subprocess.py:93} INFO - 25/06/26 20:10:11 INFO TaskSetManager: Starting task 123.0 in stage 0.0 (TID 123) (localhost, executor driver, partition 123, PROCESS_LOCAL, 9215 bytes)
[2025-06-26T20:10:11.422+0700] {subprocess.py:93} INFO - 25/06/26 20:10:11 INFO Executor: Running task 123.0 in stage 0.0 (TID 123)
[2025-06-26T20:10:11.422+0700] {subprocess.py:93} INFO - 25/06/26 20:10:11 INFO TaskSetManager: Starting task 124.0 in stage 0.0 (TID 124) (localhost, executor driver, partition 124, PROCESS_LOCAL, 9215 bytes)
[2025-06-26T20:10:11.423+0700] {subprocess.py:93} INFO - 25/06/26 20:10:11 INFO Executor: Running task 124.0 in stage 0.0 (TID 124)
[2025-06-26T20:10:11.423+0700] {subprocess.py:93} INFO - 25/06/26 20:10:11 INFO Executor: Finished task 119.0 in stage 0.0 (TID 119). 3175 bytes result sent to driver
[2025-06-26T20:10:11.423+0700] {subprocess.py:93} INFO - 25/06/26 20:10:11 INFO Executor: Finished task 115.0 in stage 0.0 (TID 115). 3175 bytes result sent to driver
[2025-06-26T20:10:11.423+0700] {subprocess.py:93} INFO - 25/06/26 20:10:11 INFO TaskSetManager: Starting task 125.0 in stage 0.0 (TID 125) (localhost, executor driver, partition 125, PROCESS_LOCAL, 9215 bytes)
[2025-06-26T20:10:11.424+0700] {subprocess.py:93} INFO - 25/06/26 20:10:11 INFO Executor: Finished task 116.0 in stage 0.0 (TID 116). 3175 bytes result sent to driver
[2025-06-26T20:10:11.425+0700] {subprocess.py:93} INFO - 25/06/26 20:10:11 INFO TaskSetManager: Starting task 126.0 in stage 0.0 (TID 126) (localhost, executor driver, partition 126, PROCESS_LOCAL, 9215 bytes)
[2025-06-26T20:10:11.426+0700] {subprocess.py:93} INFO - 25/06/26 20:10:11 INFO Executor: Finished task 117.0 in stage 0.0 (TID 117). 3175 bytes result sent to driver
[2025-06-26T20:10:11.426+0700] {subprocess.py:93} INFO - 25/06/26 20:10:11 INFO TaskSetManager: Finished task 103.0 in stage 0.0 (TID 103) in 54 ms on localhost (executor driver) (101/2334)
[2025-06-26T20:10:11.426+0700] {subprocess.py:93} INFO - 25/06/26 20:10:11 INFO Executor: Running task 125.0 in stage 0.0 (TID 125)
[2025-06-26T20:10:11.426+0700] {subprocess.py:93} INFO - 25/06/26 20:10:11 INFO Executor: Running task 126.0 in stage 0.0 (TID 126)
[2025-06-26T20:10:11.427+0700] {subprocess.py:93} INFO - 25/06/26 20:10:11 INFO Executor: Finished task 120.0 in stage 0.0 (TID 120). 3175 bytes result sent to driver
[2025-06-26T20:10:11.427+0700] {subprocess.py:93} INFO - 25/06/26 20:10:11 INFO TaskSetManager: Finished task 104.0 in stage 0.0 (TID 104) in 55 ms on localhost (executor driver) (102/2334)
[2025-06-26T20:10:11.429+0700] {subprocess.py:93} INFO - 25/06/26 20:10:11 INFO TaskSetManager: Finished task 100.0 in stage 0.0 (TID 100) in 65 ms on localhost (executor driver) (103/2334)
[2025-06-26T20:10:11.430+0700] {subprocess.py:93} INFO - 25/06/26 20:10:11 INFO Executor: Finished task 118.0 in stage 0.0 (TID 118). 3175 bytes result sent to driver
[2025-06-26T20:10:11.431+0700] {subprocess.py:93} INFO - 25/06/26 20:10:11 INFO TaskSetManager: Starting task 127.0 in stage 0.0 (TID 127) (localhost, executor driver, partition 127, PROCESS_LOCAL, 9215 bytes)
[2025-06-26T20:10:11.432+0700] {subprocess.py:93} INFO - 25/06/26 20:10:11 INFO TaskSetManager: Finished task 102.0 in stage 0.0 (TID 102) in 64 ms on localhost (executor driver) (104/2334)
[2025-06-26T20:10:11.432+0700] {subprocess.py:93} INFO - 25/06/26 20:10:11 INFO Executor: Finished task 121.0 in stage 0.0 (TID 121). 3175 bytes result sent to driver
[2025-06-26T20:10:11.433+0700] {subprocess.py:93} INFO - 25/06/26 20:10:11 INFO Executor: Running task 127.0 in stage 0.0 (TID 127)
[2025-06-26T20:10:11.433+0700] {subprocess.py:93} INFO - 25/06/26 20:10:11 INFO TaskSetManager: Finished task 101.0 in stage 0.0 (TID 101) in 65 ms on localhost (executor driver) (105/2334)
[2025-06-26T20:10:11.433+0700] {subprocess.py:93} INFO - 25/06/26 20:10:11 INFO TaskSetManager: Finished task 107.0 in stage 0.0 (TID 107) in 58 ms on localhost (executor driver) (106/2334)
[2025-06-26T20:10:11.434+0700] {subprocess.py:93} INFO - 25/06/26 20:10:11 INFO TaskSetManager: Starting task 128.0 in stage 0.0 (TID 128) (localhost, executor driver, partition 128, PROCESS_LOCAL, 9215 bytes)
[2025-06-26T20:10:11.435+0700] {subprocess.py:93} INFO - 25/06/26 20:10:11 INFO Executor: Running task 128.0 in stage 0.0 (TID 128)
[2025-06-26T20:10:11.435+0700] {subprocess.py:93} INFO - 25/06/26 20:10:11 INFO Executor: Finished task 122.0 in stage 0.0 (TID 122). 3175 bytes result sent to driver
[2025-06-26T20:10:11.436+0700] {subprocess.py:93} INFO - 25/06/26 20:10:11 INFO Executor: Finished task 124.0 in stage 0.0 (TID 124). 3175 bytes result sent to driver
[2025-06-26T20:10:11.436+0700] {subprocess.py:93} INFO - 25/06/26 20:10:11 INFO Executor: Finished task 126.0 in stage 0.0 (TID 126). 3175 bytes result sent to driver
[2025-06-26T20:10:11.436+0700] {subprocess.py:93} INFO - 25/06/26 20:10:11 INFO TaskSetManager: Starting task 129.0 in stage 0.0 (TID 129) (localhost, executor driver, partition 129, PROCESS_LOCAL, 9215 bytes)
[2025-06-26T20:10:11.437+0700] {subprocess.py:93} INFO - 25/06/26 20:10:11 INFO TaskSetManager: Finished task 106.0 in stage 0.0 (TID 106) in 64 ms on localhost (executor driver) (107/2334)
[2025-06-26T20:10:11.437+0700] {subprocess.py:93} INFO - 25/06/26 20:10:11 INFO Executor: Running task 129.0 in stage 0.0 (TID 129)
[2025-06-26T20:10:11.437+0700] {subprocess.py:93} INFO - 25/06/26 20:10:11 INFO Executor: Finished task 123.0 in stage 0.0 (TID 123). 3175 bytes result sent to driver
[2025-06-26T20:10:11.437+0700] {subprocess.py:93} INFO - 25/06/26 20:10:11 INFO TaskSetManager: Finished task 105.0 in stage 0.0 (TID 105) in 66 ms on localhost (executor driver) (108/2334)
[2025-06-26T20:10:11.437+0700] {subprocess.py:93} INFO - 25/06/26 20:10:11 INFO Executor: Finished task 125.0 in stage 0.0 (TID 125). 3175 bytes result sent to driver
[2025-06-26T20:10:11.439+0700] {subprocess.py:93} INFO - 25/06/26 20:10:11 INFO TaskSetManager: Starting task 130.0 in stage 0.0 (TID 130) (localhost, executor driver, partition 130, PROCESS_LOCAL, 9215 bytes)
[2025-06-26T20:10:11.439+0700] {subprocess.py:93} INFO - 25/06/26 20:10:11 INFO Executor: Running task 130.0 in stage 0.0 (TID 130)
[2025-06-26T20:10:11.440+0700] {subprocess.py:93} INFO - 25/06/26 20:10:11 INFO TaskSetManager: Starting task 131.0 in stage 0.0 (TID 131) (localhost, executor driver, partition 131, PROCESS_LOCAL, 9215 bytes)
