[2025-06-26T20:30:03.961+0700] {local_task_job_runner.py:120} INFO - ::group::Pre task execution logs
[2025-06-26T20:30:03.986+0700] {taskinstance.py:2073} INFO - Dependencies all met for dep_context=non-requeueable deps ti=<TaskInstance: send_data_to_powerbi.compact_csv_to_one_file scheduled__2025-06-26T13:20:00+00:00 [queued]>
[2025-06-26T20:30:03.994+0700] {taskinstance.py:2073} INFO - Dependencies all met for dep_context=requeueable deps ti=<TaskInstance: send_data_to_powerbi.compact_csv_to_one_file scheduled__2025-06-26T13:20:00+00:00 [queued]>
[2025-06-26T20:30:03.995+0700] {taskinstance.py:2303} INFO - Starting attempt 1 of 3
[2025-06-26T20:30:04.014+0700] {taskinstance.py:2327} INFO - Executing <Task(BashOperator): compact_csv_to_one_file> on 2025-06-26 13:20:00+00:00
[2025-06-26T20:30:04.022+0700] {standard_task_runner.py:63} INFO - Started process 147252 to run task
[2025-06-26T20:30:04.027+0700] {standard_task_runner.py:90} INFO - Running: ['airflow', 'tasks', 'run', 'send_data_to_powerbi', 'compact_csv_to_one_file', 'scheduled__2025-06-26T13:20:00+00:00', '--job-id', '70', '--raw', '--subdir', 'DAGS_FOLDER/load_power_bi.py', '--cfg-path', '/tmp/tmpzk7uy6tq']
[2025-06-26T20:30:04.028+0700] {standard_task_runner.py:91} INFO - Job 70: Subtask compact_csv_to_one_file
[2025-06-26T20:30:04.080+0700] {task_command.py:426} INFO - Running <TaskInstance: send_data_to_powerbi.compact_csv_to_one_file scheduled__2025-06-26T13:20:00+00:00 [running]> on host Panda
[2025-06-26T20:30:04.167+0700] {taskinstance.py:2644} INFO - Exporting env vars: AIRFLOW_CTX_DAG_OWNER='group_03' AIRFLOW_CTX_DAG_ID='send_data_to_powerbi' AIRFLOW_CTX_TASK_ID='compact_csv_to_one_file' AIRFLOW_CTX_EXECUTION_DATE='2025-06-26T13:20:00+00:00' AIRFLOW_CTX_TRY_NUMBER='1' AIRFLOW_CTX_DAG_RUN_ID='scheduled__2025-06-26T13:20:00+00:00'
[2025-06-26T20:30:04.168+0700] {taskinstance.py:430} INFO - ::endgroup::
[2025-06-26T20:30:04.169+0700] {subprocess.py:63} INFO - Tmp dir root location: /tmp
[2025-06-26T20:30:04.169+0700] {subprocess.py:75} INFO - Running command: ['/usr/bin/bash', '-c', 'spark-submit /home/panda/Documents/ODAP/Project/hadoop/compact_csv.py && sleep 10']
[2025-06-26T20:30:04.187+0700] {subprocess.py:86} INFO - Output:
[2025-06-26T20:30:06.598+0700] {subprocess.py:93} INFO - 25/06/26 20:30:06 INFO SparkContext: Running Spark version 3.5.5
[2025-06-26T20:30:06.600+0700] {subprocess.py:93} INFO - 25/06/26 20:30:06 INFO SparkContext: OS info Linux, 6.11.0-26-generic, amd64
[2025-06-26T20:30:06.601+0700] {subprocess.py:93} INFO - 25/06/26 20:30:06 INFO SparkContext: Java version 11.0.27
[2025-06-26T20:30:06.777+0700] {subprocess.py:93} INFO - 25/06/26 20:30:06 INFO ResourceUtils: ==============================================================
[2025-06-26T20:30:06.777+0700] {subprocess.py:93} INFO - 25/06/26 20:30:06 INFO ResourceUtils: No custom resources configured for spark.driver.
[2025-06-26T20:30:06.777+0700] {subprocess.py:93} INFO - 25/06/26 20:30:06 INFO ResourceUtils: ==============================================================
[2025-06-26T20:30:06.778+0700] {subprocess.py:93} INFO - 25/06/26 20:30:06 INFO SparkContext: Submitted application: CompactSmallFiles
[2025-06-26T20:30:06.804+0700] {subprocess.py:93} INFO - 25/06/26 20:30:06 INFO ResourceProfile: Default ResourceProfile created, executor resources: Map(cores -> name: cores, amount: 1, script: , vendor: , memory -> name: memory, amount: 1024, script: , vendor: , offHeap -> name: offHeap, amount: 0, script: , vendor: ), task resources: Map(cpus -> name: cpus, amount: 1.0)
[2025-06-26T20:30:06.816+0700] {subprocess.py:93} INFO - 25/06/26 20:30:06 INFO ResourceProfile: Limiting resource is cpu
[2025-06-26T20:30:06.817+0700] {subprocess.py:93} INFO - 25/06/26 20:30:06 INFO ResourceProfileManager: Added ResourceProfile id: 0
[2025-06-26T20:30:06.879+0700] {subprocess.py:93} INFO - 25/06/26 20:30:06 INFO SecurityManager: Changing view acls to: panda
[2025-06-26T20:30:06.880+0700] {subprocess.py:93} INFO - 25/06/26 20:30:06 INFO SecurityManager: Changing modify acls to: panda
[2025-06-26T20:30:06.880+0700] {subprocess.py:93} INFO - 25/06/26 20:30:06 INFO SecurityManager: Changing view acls groups to:
[2025-06-26T20:30:06.880+0700] {subprocess.py:93} INFO - 25/06/26 20:30:06 INFO SecurityManager: Changing modify acls groups to:
[2025-06-26T20:30:06.881+0700] {subprocess.py:93} INFO - 25/06/26 20:30:06 INFO SecurityManager: SecurityManager: authentication disabled; ui acls disabled; users with view permissions: panda; groups with view permissions: EMPTY; users with modify permissions: panda; groups with modify permissions: EMPTY
[2025-06-26T20:30:07.181+0700] {subprocess.py:93} INFO - 25/06/26 20:30:07 INFO Utils: Successfully started service 'sparkDriver' on port 39263.
[2025-06-26T20:30:07.211+0700] {subprocess.py:93} INFO - 25/06/26 20:30:07 INFO SparkEnv: Registering MapOutputTracker
[2025-06-26T20:30:07.261+0700] {subprocess.py:93} INFO - 25/06/26 20:30:07 INFO SparkEnv: Registering BlockManagerMaster
[2025-06-26T20:30:07.283+0700] {subprocess.py:93} INFO - 25/06/26 20:30:07 INFO BlockManagerMasterEndpoint: Using org.apache.spark.storage.DefaultTopologyMapper for getting topology information
[2025-06-26T20:30:07.285+0700] {subprocess.py:93} INFO - 25/06/26 20:30:07 INFO BlockManagerMasterEndpoint: BlockManagerMasterEndpoint up
[2025-06-26T20:30:07.294+0700] {subprocess.py:93} INFO - 25/06/26 20:30:07 INFO SparkEnv: Registering BlockManagerMasterHeartbeat
[2025-06-26T20:30:07.328+0700] {subprocess.py:93} INFO - 25/06/26 20:30:07 INFO DiskBlockManager: Created local directory at /tmp/blockmgr-22fd7e4a-36ad-40ec-9cc3-e3e7bd500f73
[2025-06-26T20:30:07.350+0700] {subprocess.py:93} INFO - 25/06/26 20:30:07 INFO MemoryStore: MemoryStore started with capacity 434.4 MiB
[2025-06-26T20:30:07.365+0700] {subprocess.py:93} INFO - 25/06/26 20:30:07 INFO SparkEnv: Registering OutputCommitCoordinator
[2025-06-26T20:30:07.544+0700] {subprocess.py:93} INFO - 25/06/26 20:30:07 INFO JettyUtils: Start Jetty 127.0.0.1:4040 for SparkUI
[2025-06-26T20:30:07.624+0700] {subprocess.py:93} INFO - 25/06/26 20:30:07 WARN Utils: Service 'SparkUI' could not bind on port 4040. Attempting port 4041.
[2025-06-26T20:30:07.641+0700] {subprocess.py:93} INFO - 25/06/26 20:30:07 INFO Utils: Successfully started service 'SparkUI' on port 4041.
[2025-06-26T20:30:07.752+0700] {subprocess.py:93} INFO - 25/06/26 20:30:07 INFO Executor: Starting executor ID driver on host localhost
[2025-06-26T20:30:07.752+0700] {subprocess.py:93} INFO - 25/06/26 20:30:07 INFO Executor: OS info Linux, 6.11.0-26-generic, amd64
[2025-06-26T20:30:07.753+0700] {subprocess.py:93} INFO - 25/06/26 20:30:07 INFO Executor: Java version 11.0.27
[2025-06-26T20:30:07.760+0700] {subprocess.py:93} INFO - 25/06/26 20:30:07 INFO Executor: Starting executor with user classpath (userClassPathFirst = false): ''
[2025-06-26T20:30:07.760+0700] {subprocess.py:93} INFO - 25/06/26 20:30:07 INFO Executor: Created or updated repl class loader org.apache.spark.util.MutableURLClassLoader@15c1eac9 for default.
[2025-06-26T20:30:07.793+0700] {subprocess.py:93} INFO - 25/06/26 20:30:07 INFO Utils: Successfully started service 'org.apache.spark.network.netty.NettyBlockTransferService' on port 37893.
[2025-06-26T20:30:07.794+0700] {subprocess.py:93} INFO - 25/06/26 20:30:07 INFO NettyBlockTransferService: Server created on localhost:37893
[2025-06-26T20:30:07.797+0700] {subprocess.py:93} INFO - 25/06/26 20:30:07 INFO BlockManager: Using org.apache.spark.storage.RandomBlockReplicationPolicy for block replication policy
[2025-06-26T20:30:07.810+0700] {subprocess.py:93} INFO - 25/06/26 20:30:07 INFO BlockManagerMaster: Registering BlockManager BlockManagerId(driver, localhost, 37893, None)
[2025-06-26T20:30:07.818+0700] {subprocess.py:93} INFO - 25/06/26 20:30:07 INFO BlockManagerMasterEndpoint: Registering block manager localhost:37893 with 434.4 MiB RAM, BlockManagerId(driver, localhost, 37893, None)
[2025-06-26T20:30:07.823+0700] {subprocess.py:93} INFO - 25/06/26 20:30:07 INFO BlockManagerMaster: Registered BlockManager BlockManagerId(driver, localhost, 37893, None)
[2025-06-26T20:30:07.824+0700] {subprocess.py:93} INFO - 25/06/26 20:30:07 INFO BlockManager: Initialized BlockManager: BlockManagerId(driver, localhost, 37893, None)
[2025-06-26T20:30:08.377+0700] {subprocess.py:93} INFO - 25/06/26 20:30:08 INFO SharedState: Setting hive.metastore.warehouse.dir ('null') to the value of spark.sql.warehouse.dir.
[2025-06-26T20:30:08.386+0700] {subprocess.py:93} INFO - 25/06/26 20:30:08 INFO SharedState: Warehouse path is 'file:/tmp/airflowtmpuyyccrdv/spark-warehouse'.
[2025-06-26T20:30:09.649+0700] {subprocess.py:93} INFO - 25/06/26 20:30:09 INFO MetadataLogFileIndex: Reading streaming file log from hdfs://localhost:9000/transactions_by_hour/_spark_metadata
[2025-06-26T20:30:09.730+0700] {subprocess.py:93} INFO - 25/06/26 20:30:09 INFO FileStreamSinkLog: BatchIds found from listing: 2635, 2636, 2637, 2638, 2639, 2640, 2641, 2642, 2643, 2644, 2645, 2646, 2647, 2648, 2649, 2650, 2651, 2652, 2653, 2654, 2655, 2656, 2657, 2658, 2659, 2660, 2661, 2662, 2663, 2664, 2665, 2666, 2667, 2668, 2669, 2670, 2671, 2672, 2673, 2674, 2675, 2676, 2677, 2678, 2679, 2680, 2681, 2682, 2683, 2684, 2685, 2686, 2687, 2688, 2689, 2690, 2691, 2692, 2693, 2694, 2695, 2696, 2697, 2698, 2699, 2700, 2701, 2702, 2703, 2704, 2705, 2706, 2707, 2708, 2709, 2710, 2711, 2712, 2713, 2714, 2715, 2716, 2717, 2718, 2719, 2720, 2721, 2722, 2723, 2724, 2725, 2726, 2727, 2728, 2729, 2730, 2731, 2732, 2733, 2734, 2735, 2736, 2737, 2738, 2739, 2740, 2741, 2742, 2743, 2744, 2745, 2746, 2747, 2748, 2749, 2750, 2751, 2752, 2753, 2754, 2755, 2756, 2757, 2758, 2759, 2760, 2761, 2762, 2763, 2764, 2765, 2766, 2767, 2768, 2769, 2770, 2771, 2772, 2773, 2774, 2775, 2776, 2777, 2778, 2779, 2780, 2781, 2782, 2783, 2784, 2785, 2786, 2787, 2788, 2789, 2790, 2791, 2792, 2793, 2794, 2795, 2796, 2797, 2798, 2799, 2800, 2801, 2802, 2803, 2804, 2805, 2806, 2807, 2808, 2809, 2810, 2811, 2812, 2813, 2814, 2815, 2816, 2817, 2818, 2819, 2820, 2821, 2822, 2823, 2824, 2825, 2826, 2827, 2828, 2829, 2830, 2831, 2832, 2833, 2834, 2835, 2836, 2837, 2838, 2839, 2840, 2841, 2842, 2843, 2844, 2845, 2846, 2847, 2848, 2849, 2850, 2851, 2852, 2853, 2854, 2855, 2856, 2857, 2858, 2859, 2860, 2861, 2862, 2863, 2864, 2865, 2866, 2867, 2868, 2869, 2870, 2871, 2872, 2873, 2874, 2875, 2876, 2877, 2878, 2879, 2880, 2881, 2882, 2883, 2884, 2885, 2886, 2887, 2888, 2889, 2890, 2891, 2892, 2893, 2894, 2895, 2896, 2897, 2898, 2899, 2900, 2901, 2902, 2903, 2904, 2905, 2906, 2907, 2908, 2909, 2910, 2911, 2912, 2913, 2914, 2915, 2916, 2917, 2918, 2919, 2920, 2921, 2922, 2923, 2924, 2925, 2926, 2927, 2928, 2929
[2025-06-26T20:30:09.762+0700] {subprocess.py:93} INFO - 25/06/26 20:30:09 INFO FileStreamSinkLog: Set the compact interval to 10 [defaultCompactInterval: 10]
[2025-06-26T20:30:10.465+0700] {subprocess.py:93} INFO - 25/06/26 20:30:10 INFO HadoopFSUtils: Listing leaf files and directories in parallel under 2930 paths. The first several paths are: hdfs://localhost:9000/transactions_by_hour/part-00000-35848e14-b857-426e-8939-db9c96261483-c000.csv, hdfs://localhost:9000/transactions_by_hour/part-00000-d7ab39d9-b4ef-4e2e-b472-4c1883c38273-c000.csv, hdfs://localhost:9000/transactions_by_hour/part-00000-cce2d287-6512-49d1-aa31-f452c0dcdaf9-c000.csv, hdfs://localhost:9000/transactions_by_hour/part-00000-ac8933a1-5bf2-4814-a228-6604c7045e4c-c000.csv, hdfs://localhost:9000/transactions_by_hour/part-00000-9c60d322-8794-4968-a7a5-364181d16d94-c000.csv, hdfs://localhost:9000/transactions_by_hour/part-00000-76895572-6aa7-4225-8325-6962e0c98ee2-c000.csv, hdfs://localhost:9000/transactions_by_hour/part-00000-a92a3ce5-6132-4e9e-8e69-11e47f72f0a2-c000.csv, hdfs://localhost:9000/transactions_by_hour/part-00000-b48a08d4-d847-4307-b612-e35a8f471916-c000.csv, hdfs://localhost:9000/transactions_by_hour/part-00000-e8f1544c-6d23-403f-a02b-06e9bef1638a-c000.csv, hdfs://localhost:9000/transactions_by_hour/part-00000-08040c60-6fee-4dcc-b2e9-af62320fb049-c000.csv.
[2025-06-26T20:30:10.886+0700] {subprocess.py:93} INFO - 25/06/26 20:30:10 INFO SparkContext: Starting job: csv at NativeMethodAccessorImpl.java:0
[2025-06-26T20:30:10.915+0700] {subprocess.py:93} INFO - 25/06/26 20:30:10 INFO DAGScheduler: Got job 0 (csv at NativeMethodAccessorImpl.java:0) with 2930 output partitions
[2025-06-26T20:30:10.916+0700] {subprocess.py:93} INFO - 25/06/26 20:30:10 INFO DAGScheduler: Final stage: ResultStage 0 (csv at NativeMethodAccessorImpl.java:0)
[2025-06-26T20:30:10.916+0700] {subprocess.py:93} INFO - 25/06/26 20:30:10 INFO DAGScheduler: Parents of final stage: List()
[2025-06-26T20:30:10.919+0700] {subprocess.py:93} INFO - 25/06/26 20:30:10 INFO DAGScheduler: Missing parents: List()
[2025-06-26T20:30:10.924+0700] {subprocess.py:93} INFO - 25/06/26 20:30:10 INFO DAGScheduler: Submitting ResultStage 0 (MapPartitionsRDD[1] at csv at NativeMethodAccessorImpl.java:0), which has no missing parents
[2025-06-26T20:30:11.062+0700] {subprocess.py:93} INFO - 25/06/26 20:30:11 INFO MemoryStore: Block broadcast_0 stored as values in memory (estimated size 103.2 KiB, free 434.3 MiB)
[2025-06-26T20:30:11.104+0700] {subprocess.py:93} INFO - 25/06/26 20:30:11 INFO MemoryStore: Block broadcast_0_piece0 stored as bytes in memory (estimated size 37.3 KiB, free 434.3 MiB)
[2025-06-26T20:30:11.107+0700] {subprocess.py:93} INFO - 25/06/26 20:30:11 INFO BlockManagerInfo: Added broadcast_0_piece0 in memory on localhost:37893 (size: 37.3 KiB, free: 434.4 MiB)
[2025-06-26T20:30:11.113+0700] {subprocess.py:93} INFO - 25/06/26 20:30:11 INFO SparkContext: Created broadcast 0 from broadcast at DAGScheduler.scala:1585
[2025-06-26T20:30:11.154+0700] {subprocess.py:93} INFO - 25/06/26 20:30:11 INFO DAGScheduler: Submitting 2930 missing tasks from ResultStage 0 (MapPartitionsRDD[1] at csv at NativeMethodAccessorImpl.java:0) (first 15 tasks are for partitions Vector(0, 1, 2, 3, 4, 5, 6, 7, 8, 9, 10, 11, 12, 13, 14))
[2025-06-26T20:30:11.157+0700] {subprocess.py:93} INFO - 25/06/26 20:30:11 INFO TaskSchedulerImpl: Adding task set 0.0 with 2930 tasks resource profile 0
[2025-06-26T20:30:11.264+0700] {subprocess.py:93} INFO - 25/06/26 20:30:11 INFO TaskSetManager: Starting task 0.0 in stage 0.0 (TID 0) (localhost, executor driver, partition 0, PROCESS_LOCAL, 9215 bytes)
[2025-06-26T20:30:11.269+0700] {subprocess.py:93} INFO - 25/06/26 20:30:11 INFO TaskSetManager: Starting task 1.0 in stage 0.0 (TID 1) (localhost, executor driver, partition 1, PROCESS_LOCAL, 9215 bytes)
[2025-06-26T20:30:11.270+0700] {subprocess.py:93} INFO - 25/06/26 20:30:11 INFO TaskSetManager: Starting task 2.0 in stage 0.0 (TID 2) (localhost, executor driver, partition 2, PROCESS_LOCAL, 9215 bytes)
[2025-06-26T20:30:11.272+0700] {subprocess.py:93} INFO - 25/06/26 20:30:11 INFO TaskSetManager: Starting task 3.0 in stage 0.0 (TID 3) (localhost, executor driver, partition 3, PROCESS_LOCAL, 9215 bytes)
[2025-06-26T20:30:11.273+0700] {subprocess.py:93} INFO - 25/06/26 20:30:11 INFO TaskSetManager: Starting task 4.0 in stage 0.0 (TID 4) (localhost, executor driver, partition 4, PROCESS_LOCAL, 9215 bytes)
[2025-06-26T20:30:11.274+0700] {subprocess.py:93} INFO - 25/06/26 20:30:11 INFO TaskSetManager: Starting task 5.0 in stage 0.0 (TID 5) (localhost, executor driver, partition 5, PROCESS_LOCAL, 9215 bytes)
[2025-06-26T20:30:11.275+0700] {subprocess.py:93} INFO - 25/06/26 20:30:11 INFO TaskSetManager: Starting task 6.0 in stage 0.0 (TID 6) (localhost, executor driver, partition 6, PROCESS_LOCAL, 9215 bytes)
[2025-06-26T20:30:11.276+0700] {subprocess.py:93} INFO - 25/06/26 20:30:11 INFO TaskSetManager: Starting task 7.0 in stage 0.0 (TID 7) (localhost, executor driver, partition 7, PROCESS_LOCAL, 9215 bytes)
[2025-06-26T20:30:11.277+0700] {subprocess.py:93} INFO - 25/06/26 20:30:11 INFO TaskSetManager: Starting task 8.0 in stage 0.0 (TID 8) (localhost, executor driver, partition 8, PROCESS_LOCAL, 9215 bytes)
[2025-06-26T20:30:11.278+0700] {subprocess.py:93} INFO - 25/06/26 20:30:11 INFO TaskSetManager: Starting task 9.0 in stage 0.0 (TID 9) (localhost, executor driver, partition 9, PROCESS_LOCAL, 9215 bytes)
[2025-06-26T20:30:11.278+0700] {subprocess.py:93} INFO - 25/06/26 20:30:11 INFO TaskSetManager: Starting task 10.0 in stage 0.0 (TID 10) (localhost, executor driver, partition 10, PROCESS_LOCAL, 9215 bytes)
[2025-06-26T20:30:11.279+0700] {subprocess.py:93} INFO - 25/06/26 20:30:11 INFO TaskSetManager: Starting task 11.0 in stage 0.0 (TID 11) (localhost, executor driver, partition 11, PROCESS_LOCAL, 9215 bytes)
[2025-06-26T20:30:11.280+0700] {subprocess.py:93} INFO - 25/06/26 20:30:11 INFO TaskSetManager: Starting task 12.0 in stage 0.0 (TID 12) (localhost, executor driver, partition 12, PROCESS_LOCAL, 9215 bytes)
[2025-06-26T20:30:11.280+0700] {subprocess.py:93} INFO - 25/06/26 20:30:11 INFO TaskSetManager: Starting task 13.0 in stage 0.0 (TID 13) (localhost, executor driver, partition 13, PROCESS_LOCAL, 9215 bytes)
[2025-06-26T20:30:11.281+0700] {subprocess.py:93} INFO - 25/06/26 20:30:11 INFO TaskSetManager: Starting task 14.0 in stage 0.0 (TID 14) (localhost, executor driver, partition 14, PROCESS_LOCAL, 9215 bytes)
[2025-06-26T20:30:11.283+0700] {subprocess.py:93} INFO - 25/06/26 20:30:11 INFO TaskSetManager: Starting task 15.0 in stage 0.0 (TID 15) (localhost, executor driver, partition 15, PROCESS_LOCAL, 9215 bytes)
[2025-06-26T20:30:11.283+0700] {subprocess.py:93} INFO - 25/06/26 20:30:11 INFO TaskSetManager: Starting task 16.0 in stage 0.0 (TID 16) (localhost, executor driver, partition 16, PROCESS_LOCAL, 9215 bytes)
[2025-06-26T20:30:11.284+0700] {subprocess.py:93} INFO - 25/06/26 20:30:11 INFO TaskSetManager: Starting task 17.0 in stage 0.0 (TID 17) (localhost, executor driver, partition 17, PROCESS_LOCAL, 9215 bytes)
[2025-06-26T20:30:11.284+0700] {subprocess.py:93} INFO - 25/06/26 20:30:11 INFO TaskSetManager: Starting task 18.0 in stage 0.0 (TID 18) (localhost, executor driver, partition 18, PROCESS_LOCAL, 9215 bytes)
[2025-06-26T20:30:11.285+0700] {subprocess.py:93} INFO - 25/06/26 20:30:11 INFO TaskSetManager: Starting task 19.0 in stage 0.0 (TID 19) (localhost, executor driver, partition 19, PROCESS_LOCAL, 9215 bytes)
[2025-06-26T20:30:11.285+0700] {subprocess.py:93} INFO - 25/06/26 20:30:11 INFO TaskSetManager: Starting task 20.0 in stage 0.0 (TID 20) (localhost, executor driver, partition 20, PROCESS_LOCAL, 9215 bytes)
[2025-06-26T20:30:11.286+0700] {subprocess.py:93} INFO - 25/06/26 20:30:11 INFO TaskSetManager: Starting task 21.0 in stage 0.0 (TID 21) (localhost, executor driver, partition 21, PROCESS_LOCAL, 9215 bytes)
[2025-06-26T20:30:11.307+0700] {subprocess.py:93} INFO - 25/06/26 20:30:11 INFO Executor: Running task 11.0 in stage 0.0 (TID 11)
[2025-06-26T20:30:11.308+0700] {subprocess.py:93} INFO - 25/06/26 20:30:11 INFO Executor: Running task 1.0 in stage 0.0 (TID 1)
[2025-06-26T20:30:11.308+0700] {subprocess.py:93} INFO - 25/06/26 20:30:11 INFO Executor: Running task 4.0 in stage 0.0 (TID 4)
[2025-06-26T20:30:11.308+0700] {subprocess.py:93} INFO - 25/06/26 20:30:11 INFO Executor: Running task 19.0 in stage 0.0 (TID 19)
[2025-06-26T20:30:11.308+0700] {subprocess.py:93} INFO - 25/06/26 20:30:11 INFO Executor: Running task 8.0 in stage 0.0 (TID 8)
[2025-06-26T20:30:11.309+0700] {subprocess.py:93} INFO - 25/06/26 20:30:11 INFO Executor: Running task 2.0 in stage 0.0 (TID 2)
[2025-06-26T20:30:11.309+0700] {subprocess.py:93} INFO - 25/06/26 20:30:11 INFO Executor: Running task 13.0 in stage 0.0 (TID 13)
[2025-06-26T20:30:11.309+0700] {subprocess.py:93} INFO - 25/06/26 20:30:11 INFO Executor: Running task 14.0 in stage 0.0 (TID 14)
[2025-06-26T20:30:11.309+0700] {subprocess.py:93} INFO - 25/06/26 20:30:11 INFO Executor: Running task 16.0 in stage 0.0 (TID 16)
[2025-06-26T20:30:11.309+0700] {subprocess.py:93} INFO - 25/06/26 20:30:11 INFO Executor: Running task 12.0 in stage 0.0 (TID 12)
[2025-06-26T20:30:11.309+0700] {subprocess.py:93} INFO - 25/06/26 20:30:11 INFO Executor: Running task 21.0 in stage 0.0 (TID 21)
[2025-06-26T20:30:11.309+0700] {subprocess.py:93} INFO - 25/06/26 20:30:11 INFO Executor: Running task 10.0 in stage 0.0 (TID 10)
[2025-06-26T20:30:11.309+0700] {subprocess.py:93} INFO - 25/06/26 20:30:11 INFO Executor: Running task 3.0 in stage 0.0 (TID 3)
[2025-06-26T20:30:11.310+0700] {subprocess.py:93} INFO - 25/06/26 20:30:11 INFO Executor: Running task 6.0 in stage 0.0 (TID 6)
[2025-06-26T20:30:11.310+0700] {subprocess.py:93} INFO - 25/06/26 20:30:11 INFO Executor: Running task 15.0 in stage 0.0 (TID 15)
[2025-06-26T20:30:11.310+0700] {subprocess.py:93} INFO - 25/06/26 20:30:11 INFO Executor: Running task 9.0 in stage 0.0 (TID 9)
[2025-06-26T20:30:11.310+0700] {subprocess.py:93} INFO - 25/06/26 20:30:11 INFO Executor: Running task 20.0 in stage 0.0 (TID 20)
[2025-06-26T20:30:11.310+0700] {subprocess.py:93} INFO - 25/06/26 20:30:11 INFO Executor: Running task 17.0 in stage 0.0 (TID 17)
[2025-06-26T20:30:11.310+0700] {subprocess.py:93} INFO - 25/06/26 20:30:11 INFO Executor: Running task 0.0 in stage 0.0 (TID 0)
[2025-06-26T20:30:11.310+0700] {subprocess.py:93} INFO - 25/06/26 20:30:11 INFO Executor: Running task 7.0 in stage 0.0 (TID 7)
[2025-06-26T20:30:11.310+0700] {subprocess.py:93} INFO - 25/06/26 20:30:11 INFO Executor: Running task 5.0 in stage 0.0 (TID 5)
[2025-06-26T20:30:11.310+0700] {subprocess.py:93} INFO - 25/06/26 20:30:11 INFO Executor: Running task 18.0 in stage 0.0 (TID 18)
[2025-06-26T20:30:11.660+0700] {subprocess.py:93} INFO - 25/06/26 20:30:11 INFO Executor: Finished task 3.0 in stage 0.0 (TID 3). 3261 bytes result sent to driver
[2025-06-26T20:30:11.661+0700] {subprocess.py:93} INFO - 25/06/26 20:30:11 INFO Executor: Finished task 16.0 in stage 0.0 (TID 16). 3261 bytes result sent to driver
[2025-06-26T20:30:11.661+0700] {subprocess.py:93} INFO - 25/06/26 20:30:11 INFO Executor: Finished task 11.0 in stage 0.0 (TID 11). 3261 bytes result sent to driver
[2025-06-26T20:30:11.662+0700] {subprocess.py:93} INFO - 25/06/26 20:30:11 INFO Executor: Finished task 21.0 in stage 0.0 (TID 21). 3261 bytes result sent to driver
[2025-06-26T20:30:11.662+0700] {subprocess.py:93} INFO - 25/06/26 20:30:11 INFO Executor: Finished task 7.0 in stage 0.0 (TID 7). 3261 bytes result sent to driver
[2025-06-26T20:30:11.662+0700] {subprocess.py:93} INFO - 25/06/26 20:30:11 INFO Executor: Finished task 17.0 in stage 0.0 (TID 17). 3261 bytes result sent to driver
[2025-06-26T20:30:11.662+0700] {subprocess.py:93} INFO - 25/06/26 20:30:11 INFO Executor: Finished task 4.0 in stage 0.0 (TID 4). 3261 bytes result sent to driver
[2025-06-26T20:30:11.662+0700] {subprocess.py:93} INFO - 25/06/26 20:30:11 INFO Executor: Finished task 20.0 in stage 0.0 (TID 20). 3261 bytes result sent to driver
[2025-06-26T20:30:11.662+0700] {subprocess.py:93} INFO - 25/06/26 20:30:11 INFO Executor: Finished task 8.0 in stage 0.0 (TID 8). 3261 bytes result sent to driver
[2025-06-26T20:30:11.662+0700] {subprocess.py:93} INFO - 25/06/26 20:30:11 INFO Executor: Finished task 2.0 in stage 0.0 (TID 2). 3261 bytes result sent to driver
[2025-06-26T20:30:11.663+0700] {subprocess.py:93} INFO - 25/06/26 20:30:11 INFO Executor: Finished task 15.0 in stage 0.0 (TID 15). 3261 bytes result sent to driver
[2025-06-26T20:30:11.663+0700] {subprocess.py:93} INFO - 25/06/26 20:30:11 INFO Executor: Finished task 13.0 in stage 0.0 (TID 13). 3261 bytes result sent to driver
[2025-06-26T20:30:11.663+0700] {subprocess.py:93} INFO - 25/06/26 20:30:11 INFO Executor: Finished task 1.0 in stage 0.0 (TID 1). 3261 bytes result sent to driver
[2025-06-26T20:30:11.663+0700] {subprocess.py:93} INFO - 25/06/26 20:30:11 INFO Executor: Finished task 14.0 in stage 0.0 (TID 14). 3261 bytes result sent to driver
[2025-06-26T20:30:11.663+0700] {subprocess.py:93} INFO - 25/06/26 20:30:11 INFO Executor: Finished task 6.0 in stage 0.0 (TID 6). 3261 bytes result sent to driver
[2025-06-26T20:30:11.663+0700] {subprocess.py:93} INFO - 25/06/26 20:30:11 INFO Executor: Finished task 10.0 in stage 0.0 (TID 10). 3261 bytes result sent to driver
[2025-06-26T20:30:11.663+0700] {subprocess.py:93} INFO - 25/06/26 20:30:11 INFO Executor: Finished task 5.0 in stage 0.0 (TID 5). 3261 bytes result sent to driver
[2025-06-26T20:30:11.663+0700] {subprocess.py:93} INFO - 25/06/26 20:30:11 INFO Executor: Finished task 18.0 in stage 0.0 (TID 18). 3261 bytes result sent to driver
[2025-06-26T20:30:11.663+0700] {subprocess.py:93} INFO - 25/06/26 20:30:11 INFO Executor: Finished task 19.0 in stage 0.0 (TID 19). 3261 bytes result sent to driver
[2025-06-26T20:30:11.664+0700] {subprocess.py:93} INFO - 25/06/26 20:30:11 INFO Executor: Finished task 12.0 in stage 0.0 (TID 12). 3261 bytes result sent to driver
[2025-06-26T20:30:11.664+0700] {subprocess.py:93} INFO - 25/06/26 20:30:11 INFO Executor: Finished task 0.0 in stage 0.0 (TID 0). 3261 bytes result sent to driver
[2025-06-26T20:30:11.664+0700] {subprocess.py:93} INFO - 25/06/26 20:30:11 INFO Executor: Finished task 9.0 in stage 0.0 (TID 9). 3261 bytes result sent to driver
[2025-06-26T20:30:11.670+0700] {subprocess.py:93} INFO - 25/06/26 20:30:11 INFO TaskSetManager: Starting task 22.0 in stage 0.0 (TID 22) (localhost, executor driver, partition 22, PROCESS_LOCAL, 9215 bytes)
[2025-06-26T20:30:11.671+0700] {subprocess.py:93} INFO - 25/06/26 20:30:11 INFO Executor: Running task 22.0 in stage 0.0 (TID 22)
[2025-06-26T20:30:11.672+0700] {subprocess.py:93} INFO - 25/06/26 20:30:11 INFO TaskSetManager: Starting task 23.0 in stage 0.0 (TID 23) (localhost, executor driver, partition 23, PROCESS_LOCAL, 9215 bytes)
[2025-06-26T20:30:11.673+0700] {subprocess.py:93} INFO - 25/06/26 20:30:11 INFO Executor: Running task 23.0 in stage 0.0 (TID 23)
[2025-06-26T20:30:11.675+0700] {subprocess.py:93} INFO - 25/06/26 20:30:11 INFO TaskSetManager: Starting task 24.0 in stage 0.0 (TID 24) (localhost, executor driver, partition 24, PROCESS_LOCAL, 9215 bytes)
[2025-06-26T20:30:11.676+0700] {subprocess.py:93} INFO - 25/06/26 20:30:11 INFO Executor: Running task 24.0 in stage 0.0 (TID 24)
[2025-06-26T20:30:11.677+0700] {subprocess.py:93} INFO - 25/06/26 20:30:11 INFO TaskSetManager: Starting task 25.0 in stage 0.0 (TID 25) (localhost, executor driver, partition 25, PROCESS_LOCAL, 9215 bytes)
[2025-06-26T20:30:11.678+0700] {subprocess.py:93} INFO - 25/06/26 20:30:11 INFO Executor: Running task 25.0 in stage 0.0 (TID 25)
[2025-06-26T20:30:11.679+0700] {subprocess.py:93} INFO - 25/06/26 20:30:11 INFO TaskSetManager: Finished task 3.0 in stage 0.0 (TID 3) in 407 ms on localhost (executor driver) (1/2930)
[2025-06-26T20:30:11.682+0700] {subprocess.py:93} INFO - 25/06/26 20:30:11 INFO TaskSetManager: Finished task 18.0 in stage 0.0 (TID 18) in 397 ms on localhost (executor driver) (2/2930)
[2025-06-26T20:30:11.682+0700] {subprocess.py:93} INFO - 25/06/26 20:30:11 INFO TaskSetManager: Finished task 4.0 in stage 0.0 (TID 4) in 410 ms on localhost (executor driver) (3/2930)
[2025-06-26T20:30:11.683+0700] {subprocess.py:93} INFO - 25/06/26 20:30:11 INFO TaskSetManager: Finished task 11.0 in stage 0.0 (TID 11) in 404 ms on localhost (executor driver) (4/2930)
[2025-06-26T20:30:11.684+0700] {subprocess.py:93} INFO - 25/06/26 20:30:11 INFO TaskSetManager: Starting task 26.0 in stage 0.0 (TID 26) (localhost, executor driver, partition 26, PROCESS_LOCAL, 9215 bytes)
[2025-06-26T20:30:11.685+0700] {subprocess.py:93} INFO - 25/06/26 20:30:11 INFO Executor: Running task 26.0 in stage 0.0 (TID 26)
[2025-06-26T20:30:11.686+0700] {subprocess.py:93} INFO - 25/06/26 20:30:11 INFO TaskSetManager: Starting task 27.0 in stage 0.0 (TID 27) (localhost, executor driver, partition 27, PROCESS_LOCAL, 9215 bytes)
[2025-06-26T20:30:11.686+0700] {subprocess.py:93} INFO - 25/06/26 20:30:11 INFO TaskSetManager: Finished task 6.0 in stage 0.0 (TID 6) in 412 ms on localhost (executor driver) (5/2930)
[2025-06-26T20:30:11.686+0700] {subprocess.py:93} INFO - 25/06/26 20:30:11 INFO Executor: Running task 27.0 in stage 0.0 (TID 27)
[2025-06-26T20:30:11.687+0700] {subprocess.py:93} INFO - 25/06/26 20:30:11 INFO TaskSetManager: Finished task 9.0 in stage 0.0 (TID 9) in 409 ms on localhost (executor driver) (6/2930)
[2025-06-26T20:30:11.687+0700] {subprocess.py:93} INFO - 25/06/26 20:30:11 INFO TaskSetManager: Starting task 28.0 in stage 0.0 (TID 28) (localhost, executor driver, partition 28, PROCESS_LOCAL, 9215 bytes)
[2025-06-26T20:30:11.689+0700] {subprocess.py:93} INFO - 25/06/26 20:30:11 INFO Executor: Running task 28.0 in stage 0.0 (TID 28)
[2025-06-26T20:30:11.690+0700] {subprocess.py:93} INFO - 25/06/26 20:30:11 INFO TaskSetManager: Starting task 29.0 in stage 0.0 (TID 29) (localhost, executor driver, partition 29, PROCESS_LOCAL, 9215 bytes)
[2025-06-26T20:30:11.691+0700] {subprocess.py:93} INFO - 25/06/26 20:30:11 INFO TaskSetManager: Finished task 8.0 in stage 0.0 (TID 8) in 415 ms on localhost (executor driver) (7/2930)
[2025-06-26T20:30:11.691+0700] {subprocess.py:93} INFO - 25/06/26 20:30:11 INFO Executor: Running task 29.0 in stage 0.0 (TID 29)
[2025-06-26T20:30:11.692+0700] {subprocess.py:93} INFO - 25/06/26 20:30:11 INFO TaskSetManager: Starting task 30.0 in stage 0.0 (TID 30) (localhost, executor driver, partition 30, PROCESS_LOCAL, 9215 bytes)
[2025-06-26T20:30:11.692+0700] {subprocess.py:93} INFO - 25/06/26 20:30:11 INFO TaskSetManager: Finished task 16.0 in stage 0.0 (TID 16) in 409 ms on localhost (executor driver) (8/2930)
[2025-06-26T20:30:11.693+0700] {subprocess.py:93} INFO - 25/06/26 20:30:11 INFO Executor: Running task 30.0 in stage 0.0 (TID 30)
[2025-06-26T20:30:11.695+0700] {subprocess.py:93} INFO - 25/06/26 20:30:11 INFO TaskSetManager: Starting task 31.0 in stage 0.0 (TID 31) (localhost, executor driver, partition 31, PROCESS_LOCAL, 9215 bytes)
[2025-06-26T20:30:11.696+0700] {subprocess.py:93} INFO - 25/06/26 20:30:11 INFO Executor: Running task 31.0 in stage 0.0 (TID 31)
[2025-06-26T20:30:11.697+0700] {subprocess.py:93} INFO - 25/06/26 20:30:11 INFO Executor: Finished task 22.0 in stage 0.0 (TID 22). 3175 bytes result sent to driver
[2025-06-26T20:30:11.698+0700] {subprocess.py:93} INFO - 25/06/26 20:30:11 INFO TaskSetManager: Starting task 32.0 in stage 0.0 (TID 32) (localhost, executor driver, partition 32, PROCESS_LOCAL, 9215 bytes)
[2025-06-26T20:30:11.699+0700] {subprocess.py:93} INFO - 25/06/26 20:30:11 INFO TaskSetManager: Finished task 21.0 in stage 0.0 (TID 21) in 414 ms on localhost (executor driver) (9/2930)
[2025-06-26T20:30:11.699+0700] {subprocess.py:93} INFO - 25/06/26 20:30:11 INFO Executor: Running task 32.0 in stage 0.0 (TID 32)
[2025-06-26T20:30:11.699+0700] {subprocess.py:93} INFO - 25/06/26 20:30:11 INFO Executor: Finished task 23.0 in stage 0.0 (TID 23). 3175 bytes result sent to driver
[2025-06-26T20:30:11.700+0700] {subprocess.py:93} INFO - 25/06/26 20:30:11 INFO TaskSetManager: Starting task 33.0 in stage 0.0 (TID 33) (localhost, executor driver, partition 33, PROCESS_LOCAL, 9215 bytes)
[2025-06-26T20:30:11.700+0700] {subprocess.py:93} INFO - 25/06/26 20:30:11 INFO Executor: Finished task 24.0 in stage 0.0 (TID 24). 3175 bytes result sent to driver
[2025-06-26T20:30:11.700+0700] {subprocess.py:93} INFO - 25/06/26 20:30:11 INFO Executor: Running task 33.0 in stage 0.0 (TID 33)
[2025-06-26T20:30:11.701+0700] {subprocess.py:93} INFO - 25/06/26 20:30:11 INFO TaskSetManager: Starting task 34.0 in stage 0.0 (TID 34) (localhost, executor driver, partition 34, PROCESS_LOCAL, 9215 bytes)
[2025-06-26T20:30:11.702+0700] {subprocess.py:93} INFO - 25/06/26 20:30:11 INFO Executor: Running task 34.0 in stage 0.0 (TID 34)
[2025-06-26T20:30:11.702+0700] {subprocess.py:93} INFO - 25/06/26 20:30:11 INFO TaskSetManager: Finished task 14.0 in stage 0.0 (TID 14) in 421 ms on localhost (executor driver) (10/2930)
[2025-06-26T20:30:11.703+0700] {subprocess.py:93} INFO - 25/06/26 20:30:11 INFO TaskSetManager: Starting task 35.0 in stage 0.0 (TID 35) (localhost, executor driver, partition 35, PROCESS_LOCAL, 9215 bytes)
[2025-06-26T20:30:11.704+0700] {subprocess.py:93} INFO - 25/06/26 20:30:11 INFO TaskSetManager: Finished task 0.0 in stage 0.0 (TID 0) in 473 ms on localhost (executor driver) (11/2930)
[2025-06-26T20:30:11.704+0700] {subprocess.py:93} INFO - 25/06/26 20:30:11 INFO Executor: Running task 35.0 in stage 0.0 (TID 35)
[2025-06-26T20:30:11.704+0700] {subprocess.py:93} INFO - 25/06/26 20:30:11 INFO TaskSetManager: Finished task 5.0 in stage 0.0 (TID 5) in 431 ms on localhost (executor driver) (12/2930)
[2025-06-26T20:30:11.704+0700] {subprocess.py:93} INFO - 25/06/26 20:30:11 INFO TaskSetManager: Finished task 17.0 in stage 0.0 (TID 17) in 421 ms on localhost (executor driver) (13/2930)
[2025-06-26T20:30:11.705+0700] {subprocess.py:93} INFO - 25/06/26 20:30:11 INFO TaskSetManager: Finished task 13.0 in stage 0.0 (TID 13) in 424 ms on localhost (executor driver) (14/2930)
[2025-06-26T20:30:11.706+0700] {subprocess.py:93} INFO - 25/06/26 20:30:11 INFO TaskSetManager: Starting task 36.0 in stage 0.0 (TID 36) (localhost, executor driver, partition 36, PROCESS_LOCAL, 9215 bytes)
[2025-06-26T20:30:11.707+0700] {subprocess.py:93} INFO - 25/06/26 20:30:11 INFO Executor: Running task 36.0 in stage 0.0 (TID 36)
[2025-06-26T20:30:11.707+0700] {subprocess.py:93} INFO - 25/06/26 20:30:11 INFO TaskSetManager: Finished task 2.0 in stage 0.0 (TID 2) in 437 ms on localhost (executor driver) (15/2930)
[2025-06-26T20:30:11.708+0700] {subprocess.py:93} INFO - 25/06/26 20:30:11 INFO TaskSetManager: Starting task 37.0 in stage 0.0 (TID 37) (localhost, executor driver, partition 37, PROCESS_LOCAL, 9215 bytes)
[2025-06-26T20:30:11.710+0700] {subprocess.py:93} INFO - 25/06/26 20:30:11 INFO TaskSetManager: Starting task 38.0 in stage 0.0 (TID 38) (localhost, executor driver, partition 38, PROCESS_LOCAL, 9215 bytes)
[2025-06-26T20:30:11.710+0700] {subprocess.py:93} INFO - 25/06/26 20:30:11 INFO Executor: Running task 37.0 in stage 0.0 (TID 37)
[2025-06-26T20:30:11.710+0700] {subprocess.py:93} INFO - 25/06/26 20:30:11 INFO Executor: Running task 38.0 in stage 0.0 (TID 38)
[2025-06-26T20:30:11.711+0700] {subprocess.py:93} INFO - 25/06/26 20:30:11 INFO TaskSetManager: Starting task 39.0 in stage 0.0 (TID 39) (localhost, executor driver, partition 39, PROCESS_LOCAL, 9215 bytes)
[2025-06-26T20:30:11.712+0700] {subprocess.py:93} INFO - 25/06/26 20:30:11 INFO TaskSetManager: Starting task 40.0 in stage 0.0 (TID 40) (localhost, executor driver, partition 40, PROCESS_LOCAL, 9215 bytes)
[2025-06-26T20:30:11.713+0700] {subprocess.py:93} INFO - 25/06/26 20:30:11 INFO Executor: Running task 39.0 in stage 0.0 (TID 39)
[2025-06-26T20:30:11.713+0700] {subprocess.py:93} INFO - 25/06/26 20:30:11 INFO Executor: Running task 40.0 in stage 0.0 (TID 40)
[2025-06-26T20:30:11.720+0700] {subprocess.py:93} INFO - 25/06/26 20:30:11 INFO TaskSetManager: Starting task 41.0 in stage 0.0 (TID 41) (localhost, executor driver, partition 41, PROCESS_LOCAL, 9215 bytes)
[2025-06-26T20:30:11.723+0700] {subprocess.py:93} INFO - 25/06/26 20:30:11 INFO Executor: Running task 41.0 in stage 0.0 (TID 41)
[2025-06-26T20:30:11.723+0700] {subprocess.py:93} INFO - 25/06/26 20:30:11 INFO TaskSetManager: Finished task 19.0 in stage 0.0 (TID 19) in 439 ms on localhost (executor driver) (16/2930)
[2025-06-26T20:30:11.732+0700] {subprocess.py:93} INFO - 25/06/26 20:30:11 INFO TaskSetManager: Starting task 42.0 in stage 0.0 (TID 42) (localhost, executor driver, partition 42, PROCESS_LOCAL, 9215 bytes)
[2025-06-26T20:30:11.732+0700] {subprocess.py:93} INFO - 25/06/26 20:30:11 INFO Executor: Finished task 26.0 in stage 0.0 (TID 26). 3218 bytes result sent to driver
[2025-06-26T20:30:11.732+0700] {subprocess.py:93} INFO - 25/06/26 20:30:11 INFO Executor: Finished task 25.0 in stage 0.0 (TID 25). 3175 bytes result sent to driver
[2025-06-26T20:30:11.733+0700] {subprocess.py:93} INFO - 25/06/26 20:30:11 INFO Executor: Running task 42.0 in stage 0.0 (TID 42)
[2025-06-26T20:30:11.733+0700] {subprocess.py:93} INFO - 25/06/26 20:30:11 INFO TaskSetManager: Starting task 43.0 in stage 0.0 (TID 43) (localhost, executor driver, partition 43, PROCESS_LOCAL, 9215 bytes)
[2025-06-26T20:30:11.734+0700] {subprocess.py:93} INFO - 25/06/26 20:30:11 INFO TaskSetManager: Finished task 15.0 in stage 0.0 (TID 15) in 452 ms on localhost (executor driver) (17/2930)
[2025-06-26T20:30:11.740+0700] {subprocess.py:93} INFO - 25/06/26 20:30:11 INFO Executor: Running task 43.0 in stage 0.0 (TID 43)
[2025-06-26T20:30:11.740+0700] {subprocess.py:93} INFO - 25/06/26 20:30:11 INFO TaskSetManager: Finished task 20.0 in stage 0.0 (TID 20) in 454 ms on localhost (executor driver) (18/2930)
[2025-06-26T20:30:11.742+0700] {subprocess.py:93} INFO - 25/06/26 20:30:11 INFO TaskSetManager: Finished task 10.0 in stage 0.0 (TID 10) in 463 ms on localhost (executor driver) (19/2930)
[2025-06-26T20:30:11.743+0700] {subprocess.py:93} INFO - 25/06/26 20:30:11 INFO TaskSetManager: Finished task 12.0 in stage 0.0 (TID 12) in 463 ms on localhost (executor driver) (20/2930)
[2025-06-26T20:30:11.743+0700] {subprocess.py:93} INFO - 25/06/26 20:30:11 INFO Executor: Finished task 27.0 in stage 0.0 (TID 27). 3175 bytes result sent to driver
[2025-06-26T20:30:11.745+0700] {subprocess.py:93} INFO - 25/06/26 20:30:11 INFO TaskSetManager: Finished task 1.0 in stage 0.0 (TID 1) in 476 ms on localhost (executor driver) (21/2930)
[2025-06-26T20:30:11.747+0700] {subprocess.py:93} INFO - 25/06/26 20:30:11 INFO TaskSetManager: Starting task 44.0 in stage 0.0 (TID 44) (localhost, executor driver, partition 44, PROCESS_LOCAL, 9215 bytes)
[2025-06-26T20:30:11.747+0700] {subprocess.py:93} INFO - 25/06/26 20:30:11 INFO TaskSetManager: Finished task 7.0 in stage 0.0 (TID 7) in 472 ms on localhost (executor driver) (22/2930)
[2025-06-26T20:30:11.747+0700] {subprocess.py:93} INFO - 25/06/26 20:30:11 INFO Executor: Running task 44.0 in stage 0.0 (TID 44)
[2025-06-26T20:30:11.750+0700] {subprocess.py:93} INFO - 25/06/26 20:30:11 INFO TaskSetManager: Starting task 45.0 in stage 0.0 (TID 45) (localhost, executor driver, partition 45, PROCESS_LOCAL, 9215 bytes)
[2025-06-26T20:30:11.750+0700] {subprocess.py:93} INFO - 25/06/26 20:30:11 INFO Executor: Running task 45.0 in stage 0.0 (TID 45)
[2025-06-26T20:30:11.758+0700] {subprocess.py:93} INFO - 25/06/26 20:30:11 INFO TaskSetManager: Finished task 23.0 in stage 0.0 (TID 23) in 86 ms on localhost (executor driver) (23/2930)
[2025-06-26T20:30:11.761+0700] {subprocess.py:93} INFO - 25/06/26 20:30:11 INFO TaskSetManager: Starting task 46.0 in stage 0.0 (TID 46) (localhost, executor driver, partition 46, PROCESS_LOCAL, 9215 bytes)
[2025-06-26T20:30:11.763+0700] {subprocess.py:93} INFO - 25/06/26 20:30:11 INFO Executor: Finished task 29.0 in stage 0.0 (TID 29). 3175 bytes result sent to driver
[2025-06-26T20:30:11.763+0700] {subprocess.py:93} INFO - 25/06/26 20:30:11 INFO TaskSetManager: Starting task 47.0 in stage 0.0 (TID 47) (localhost, executor driver, partition 47, PROCESS_LOCAL, 9215 bytes)
[2025-06-26T20:30:11.768+0700] {subprocess.py:93} INFO - 25/06/26 20:30:11 INFO Executor: Running task 46.0 in stage 0.0 (TID 46)
[2025-06-26T20:30:11.768+0700] {subprocess.py:93} INFO - 25/06/26 20:30:11 INFO TaskSetManager: Finished task 22.0 in stage 0.0 (TID 22) in 96 ms on localhost (executor driver) (24/2930)
[2025-06-26T20:30:11.768+0700] {subprocess.py:93} INFO - 25/06/26 20:30:11 INFO Executor: Running task 47.0 in stage 0.0 (TID 47)
[2025-06-26T20:30:11.776+0700] {subprocess.py:93} INFO - 25/06/26 20:30:11 INFO Executor: Finished task 28.0 in stage 0.0 (TID 28). 3175 bytes result sent to driver
[2025-06-26T20:30:11.779+0700] {subprocess.py:93} INFO - 25/06/26 20:30:11 INFO TaskSetManager: Starting task 48.0 in stage 0.0 (TID 48) (localhost, executor driver, partition 48, PROCESS_LOCAL, 9215 bytes)
[2025-06-26T20:30:11.782+0700] {subprocess.py:93} INFO - 25/06/26 20:30:11 INFO Executor: Running task 48.0 in stage 0.0 (TID 48)
[2025-06-26T20:30:11.782+0700] {subprocess.py:93} INFO - 25/06/26 20:30:11 INFO TaskSetManager: Starting task 49.0 in stage 0.0 (TID 49) (localhost, executor driver, partition 49, PROCESS_LOCAL, 9215 bytes)
[2025-06-26T20:30:11.787+0700] {subprocess.py:93} INFO - 25/06/26 20:30:11 INFO Executor: Running task 49.0 in stage 0.0 (TID 49)
[2025-06-26T20:30:11.788+0700] {subprocess.py:93} INFO - 25/06/26 20:30:11 INFO TaskSetManager: Starting task 50.0 in stage 0.0 (TID 50) (localhost, executor driver, partition 50, PROCESS_LOCAL, 9215 bytes)
[2025-06-26T20:30:11.789+0700] {subprocess.py:93} INFO - 25/06/26 20:30:11 INFO TaskSetManager: Finished task 26.0 in stage 0.0 (TID 26) in 106 ms on localhost (executor driver) (25/2930)
[2025-06-26T20:30:11.789+0700] {subprocess.py:93} INFO - 25/06/26 20:30:11 INFO Executor: Running task 50.0 in stage 0.0 (TID 50)
[2025-06-26T20:30:11.809+0700] {subprocess.py:93} INFO - 25/06/26 20:30:11 INFO TaskSetManager: Finished task 29.0 in stage 0.0 (TID 29) in 119 ms on localhost (executor driver) (26/2930)
[2025-06-26T20:30:11.810+0700] {subprocess.py:93} INFO - 25/06/26 20:30:11 INFO TaskSetManager: Finished task 25.0 in stage 0.0 (TID 25) in 133 ms on localhost (executor driver) (27/2930)
[2025-06-26T20:30:11.811+0700] {subprocess.py:93} INFO - 25/06/26 20:30:11 INFO TaskSetManager: Finished task 24.0 in stage 0.0 (TID 24) in 136 ms on localhost (executor driver) (28/2930)
[2025-06-26T20:30:11.816+0700] {subprocess.py:93} INFO - 25/06/26 20:30:11 INFO Executor: Finished task 30.0 in stage 0.0 (TID 30). 3218 bytes result sent to driver
[2025-06-26T20:30:11.817+0700] {subprocess.py:93} INFO - 25/06/26 20:30:11 INFO TaskSetManager: Finished task 27.0 in stage 0.0 (TID 27) in 130 ms on localhost (executor driver) (29/2930)
[2025-06-26T20:30:11.823+0700] {subprocess.py:93} INFO - 25/06/26 20:30:11 INFO Executor: Finished task 32.0 in stage 0.0 (TID 32). 3261 bytes result sent to driver
[2025-06-26T20:30:11.823+0700] {subprocess.py:93} INFO - 25/06/26 20:30:11 INFO TaskSetManager: Starting task 51.0 in stage 0.0 (TID 51) (localhost, executor driver, partition 51, PROCESS_LOCAL, 9215 bytes)
[2025-06-26T20:30:11.824+0700] {subprocess.py:93} INFO - 25/06/26 20:30:11 INFO TaskSetManager: Finished task 28.0 in stage 0.0 (TID 28) in 137 ms on localhost (executor driver) (30/2930)
[2025-06-26T20:30:11.824+0700] {subprocess.py:93} INFO - 25/06/26 20:30:11 INFO Executor: Running task 51.0 in stage 0.0 (TID 51)
[2025-06-26T20:30:11.825+0700] {subprocess.py:93} INFO - 25/06/26 20:30:11 INFO TaskSetManager: Starting task 52.0 in stage 0.0 (TID 52) (localhost, executor driver, partition 52, PROCESS_LOCAL, 9215 bytes)
[2025-06-26T20:30:11.826+0700] {subprocess.py:93} INFO - 25/06/26 20:30:11 INFO TaskSetManager: Starting task 53.0 in stage 0.0 (TID 53) (localhost, executor driver, partition 53, PROCESS_LOCAL, 9215 bytes)
[2025-06-26T20:30:11.828+0700] {subprocess.py:93} INFO - 25/06/26 20:30:11 INFO Executor: Finished task 34.0 in stage 0.0 (TID 34). 3218 bytes result sent to driver
[2025-06-26T20:30:11.829+0700] {subprocess.py:93} INFO - 25/06/26 20:30:11 INFO Executor: Running task 53.0 in stage 0.0 (TID 53)
[2025-06-26T20:30:11.829+0700] {subprocess.py:93} INFO - 25/06/26 20:30:11 INFO Executor: Running task 52.0 in stage 0.0 (TID 52)
[2025-06-26T20:30:11.829+0700] {subprocess.py:93} INFO - 25/06/26 20:30:11 INFO Executor: Finished task 41.0 in stage 0.0 (TID 41). 3218 bytes result sent to driver
[2025-06-26T20:30:11.832+0700] {subprocess.py:93} INFO - 25/06/26 20:30:11 INFO TaskSetManager: Starting task 54.0 in stage 0.0 (TID 54) (localhost, executor driver, partition 54, PROCESS_LOCAL, 9215 bytes)
[2025-06-26T20:30:11.833+0700] {subprocess.py:93} INFO - 25/06/26 20:30:11 INFO Executor: Running task 54.0 in stage 0.0 (TID 54)
[2025-06-26T20:30:11.834+0700] {subprocess.py:93} INFO - 25/06/26 20:30:11 INFO Executor: Finished task 38.0 in stage 0.0 (TID 38). 3218 bytes result sent to driver
[2025-06-26T20:30:11.836+0700] {subprocess.py:93} INFO - 25/06/26 20:30:11 INFO Executor: Finished task 31.0 in stage 0.0 (TID 31). 3261 bytes result sent to driver
[2025-06-26T20:30:11.837+0700] {subprocess.py:93} INFO - 25/06/26 20:30:11 INFO TaskSetManager: Starting task 55.0 in stage 0.0 (TID 55) (localhost, executor driver, partition 55, PROCESS_LOCAL, 9215 bytes)
[2025-06-26T20:30:11.837+0700] {subprocess.py:93} INFO - 25/06/26 20:30:11 INFO Executor: Finished task 33.0 in stage 0.0 (TID 33). 3218 bytes result sent to driver
[2025-06-26T20:30:11.837+0700] {subprocess.py:93} INFO - 25/06/26 20:30:11 INFO Executor: Running task 55.0 in stage 0.0 (TID 55)
[2025-06-26T20:30:11.839+0700] {subprocess.py:93} INFO - 25/06/26 20:30:11 INFO Executor: Finished task 35.0 in stage 0.0 (TID 35). 3218 bytes result sent to driver
[2025-06-26T20:30:11.839+0700] {subprocess.py:93} INFO - 25/06/26 20:30:11 INFO Executor: Finished task 36.0 in stage 0.0 (TID 36). 3218 bytes result sent to driver
[2025-06-26T20:30:11.839+0700] {subprocess.py:93} INFO - 25/06/26 20:30:11 INFO TaskSetManager: Starting task 56.0 in stage 0.0 (TID 56) (localhost, executor driver, partition 56, PROCESS_LOCAL, 9215 bytes)
[2025-06-26T20:30:11.840+0700] {subprocess.py:93} INFO - 25/06/26 20:30:11 INFO Executor: Finished task 37.0 in stage 0.0 (TID 37). 3218 bytes result sent to driver
[2025-06-26T20:30:11.844+0700] {subprocess.py:93} INFO - 25/06/26 20:30:11 INFO Executor: Running task 56.0 in stage 0.0 (TID 56)
[2025-06-26T20:30:11.845+0700] {subprocess.py:93} INFO - 25/06/26 20:30:11 INFO TaskSetManager: Starting task 57.0 in stage 0.0 (TID 57) (localhost, executor driver, partition 57, PROCESS_LOCAL, 9215 bytes)
[2025-06-26T20:30:11.846+0700] {subprocess.py:93} INFO - 25/06/26 20:30:11 INFO Executor: Running task 57.0 in stage 0.0 (TID 57)
[2025-06-26T20:30:11.846+0700] {subprocess.py:93} INFO - 25/06/26 20:30:11 INFO TaskSetManager: Starting task 58.0 in stage 0.0 (TID 58) (localhost, executor driver, partition 58, PROCESS_LOCAL, 9215 bytes)
[2025-06-26T20:30:11.851+0700] {subprocess.py:93} INFO - 25/06/26 20:30:11 INFO Executor: Running task 58.0 in stage 0.0 (TID 58)
[2025-06-26T20:30:11.851+0700] {subprocess.py:93} INFO - 25/06/26 20:30:11 INFO TaskSetManager: Starting task 59.0 in stage 0.0 (TID 59) (localhost, executor driver, partition 59, PROCESS_LOCAL, 9215 bytes)
[2025-06-26T20:30:11.851+0700] {subprocess.py:93} INFO - 25/06/26 20:30:11 INFO Executor: Running task 59.0 in stage 0.0 (TID 59)
[2025-06-26T20:30:11.851+0700] {subprocess.py:93} INFO - 25/06/26 20:30:11 INFO TaskSetManager: Starting task 60.0 in stage 0.0 (TID 60) (localhost, executor driver, partition 60, PROCESS_LOCAL, 9215 bytes)
[2025-06-26T20:30:11.852+0700] {subprocess.py:93} INFO - 25/06/26 20:30:11 INFO TaskSetManager: Starting task 61.0 in stage 0.0 (TID 61) (localhost, executor driver, partition 61, PROCESS_LOCAL, 9215 bytes)
[2025-06-26T20:30:11.852+0700] {subprocess.py:93} INFO - 25/06/26 20:30:11 INFO Executor: Running task 60.0 in stage 0.0 (TID 60)
[2025-06-26T20:30:11.852+0700] {subprocess.py:93} INFO - 25/06/26 20:30:11 INFO TaskSetManager: Finished task 32.0 in stage 0.0 (TID 32) in 156 ms on localhost (executor driver) (31/2930)
[2025-06-26T20:30:11.860+0700] {subprocess.py:93} INFO - 25/06/26 20:30:11 INFO TaskSetManager: Finished task 34.0 in stage 0.0 (TID 34) in 160 ms on localhost (executor driver) (32/2930)
[2025-06-26T20:30:11.861+0700] {subprocess.py:93} INFO - 25/06/26 20:30:11 INFO TaskSetManager: Finished task 30.0 in stage 0.0 (TID 30) in 170 ms on localhost (executor driver) (33/2930)
[2025-06-26T20:30:11.863+0700] {subprocess.py:93} INFO - 25/06/26 20:30:11 INFO Executor: Running task 61.0 in stage 0.0 (TID 61)
[2025-06-26T20:30:11.864+0700] {subprocess.py:93} INFO - 25/06/26 20:30:11 INFO TaskSetManager: Finished task 41.0 in stage 0.0 (TID 41) in 144 ms on localhost (executor driver) (34/2930)
[2025-06-26T20:30:11.864+0700] {subprocess.py:93} INFO - 25/06/26 20:30:11 INFO Executor: Finished task 45.0 in stage 0.0 (TID 45). 3218 bytes result sent to driver
[2025-06-26T20:30:11.865+0700] {subprocess.py:93} INFO - 25/06/26 20:30:11 INFO TaskSetManager: Finished task 35.0 in stage 0.0 (TID 35) in 162 ms on localhost (executor driver) (35/2930)
[2025-06-26T20:30:11.869+0700] {subprocess.py:93} INFO - 25/06/26 20:30:11 INFO Executor: Finished task 39.0 in stage 0.0 (TID 39). 3218 bytes result sent to driver
[2025-06-26T20:30:11.869+0700] {subprocess.py:93} INFO - 25/06/26 20:30:11 INFO TaskSetManager: Finished task 38.0 in stage 0.0 (TID 38) in 156 ms on localhost (executor driver) (36/2930)
[2025-06-26T20:30:11.869+0700] {subprocess.py:93} INFO - 25/06/26 20:30:11 INFO TaskSetManager: Finished task 33.0 in stage 0.0 (TID 33) in 166 ms on localhost (executor driver) (37/2930)
[2025-06-26T20:30:11.869+0700] {subprocess.py:93} INFO - 25/06/26 20:30:11 INFO Executor: Finished task 40.0 in stage 0.0 (TID 40). 3218 bytes result sent to driver
[2025-06-26T20:30:11.869+0700] {subprocess.py:93} INFO - 25/06/26 20:30:11 INFO TaskSetManager: Finished task 31.0 in stage 0.0 (TID 31) in 173 ms on localhost (executor driver) (38/2930)
[2025-06-26T20:30:11.870+0700] {subprocess.py:93} INFO - 25/06/26 20:30:11 INFO TaskSetManager: Finished task 37.0 in stage 0.0 (TID 37) in 160 ms on localhost (executor driver) (39/2930)
[2025-06-26T20:30:11.870+0700] {subprocess.py:93} INFO - 25/06/26 20:30:11 INFO TaskSetManager: Finished task 36.0 in stage 0.0 (TID 36) in 163 ms on localhost (executor driver) (40/2930)
[2025-06-26T20:30:11.870+0700] {subprocess.py:93} INFO - 25/06/26 20:30:11 INFO TaskSetManager: Starting task 62.0 in stage 0.0 (TID 62) (localhost, executor driver, partition 62, PROCESS_LOCAL, 9215 bytes)
[2025-06-26T20:30:11.871+0700] {subprocess.py:93} INFO - 25/06/26 20:30:11 INFO Executor: Running task 62.0 in stage 0.0 (TID 62)
[2025-06-26T20:30:11.872+0700] {subprocess.py:93} INFO - 25/06/26 20:30:11 INFO TaskSetManager: Starting task 63.0 in stage 0.0 (TID 63) (localhost, executor driver, partition 63, PROCESS_LOCAL, 9215 bytes)
[2025-06-26T20:30:11.873+0700] {subprocess.py:93} INFO - 25/06/26 20:30:11 INFO Executor: Finished task 42.0 in stage 0.0 (TID 42). 3218 bytes result sent to driver
[2025-06-26T20:30:11.873+0700] {subprocess.py:93} INFO - 25/06/26 20:30:11 INFO Executor: Running task 63.0 in stage 0.0 (TID 63)
[2025-06-26T20:30:11.875+0700] {subprocess.py:93} INFO - 25/06/26 20:30:11 INFO TaskSetManager: Finished task 45.0 in stage 0.0 (TID 45) in 124 ms on localhost (executor driver) (41/2930)
[2025-06-26T20:30:11.875+0700] {subprocess.py:93} INFO - 25/06/26 20:30:11 INFO TaskSetManager: Starting task 64.0 in stage 0.0 (TID 64) (localhost, executor driver, partition 64, PROCESS_LOCAL, 9215 bytes)
[2025-06-26T20:30:11.877+0700] {subprocess.py:93} INFO - 25/06/26 20:30:11 INFO TaskSetManager: Starting task 65.0 in stage 0.0 (TID 65) (localhost, executor driver, partition 65, PROCESS_LOCAL, 9215 bytes)
[2025-06-26T20:30:11.877+0700] {subprocess.py:93} INFO - 25/06/26 20:30:11 INFO Executor: Running task 65.0 in stage 0.0 (TID 65)
[2025-06-26T20:30:11.882+0700] {subprocess.py:93} INFO - 25/06/26 20:30:11 INFO TaskSetManager: Finished task 40.0 in stage 0.0 (TID 40) in 167 ms on localhost (executor driver) (42/2930)
[2025-06-26T20:30:11.882+0700] {subprocess.py:93} INFO - 25/06/26 20:30:11 INFO Executor: Running task 64.0 in stage 0.0 (TID 64)
[2025-06-26T20:30:11.885+0700] {subprocess.py:93} INFO - 25/06/26 20:30:11 INFO Executor: Finished task 44.0 in stage 0.0 (TID 44). 3218 bytes result sent to driver
[2025-06-26T20:30:11.886+0700] {subprocess.py:93} INFO - 25/06/26 20:30:11 INFO TaskSetManager: Finished task 42.0 in stage 0.0 (TID 42) in 156 ms on localhost (executor driver) (43/2930)
[2025-06-26T20:30:11.886+0700] {subprocess.py:93} INFO - 25/06/26 20:30:11 INFO TaskSetManager: Finished task 39.0 in stage 0.0 (TID 39) in 176 ms on localhost (executor driver) (44/2930)
[2025-06-26T20:30:11.893+0700] {subprocess.py:93} INFO - 25/06/26 20:30:11 INFO TaskSetManager: Starting task 66.0 in stage 0.0 (TID 66) (localhost, executor driver, partition 66, PROCESS_LOCAL, 9215 bytes)
[2025-06-26T20:30:11.893+0700] {subprocess.py:93} INFO - 25/06/26 20:30:11 INFO TaskSetManager: Finished task 44.0 in stage 0.0 (TID 44) in 143 ms on localhost (executor driver) (45/2930)
[2025-06-26T20:30:11.893+0700] {subprocess.py:93} INFO - 25/06/26 20:30:11 INFO Executor: Finished task 43.0 in stage 0.0 (TID 43). 3218 bytes result sent to driver
[2025-06-26T20:30:11.893+0700] {subprocess.py:93} INFO - 25/06/26 20:30:11 INFO Executor: Running task 66.0 in stage 0.0 (TID 66)
[2025-06-26T20:30:11.893+0700] {subprocess.py:93} INFO - 25/06/26 20:30:11 INFO Executor: Finished task 46.0 in stage 0.0 (TID 46). 3218 bytes result sent to driver
[2025-06-26T20:30:11.894+0700] {subprocess.py:93} INFO - 25/06/26 20:30:11 INFO TaskSetManager: Starting task 67.0 in stage 0.0 (TID 67) (localhost, executor driver, partition 67, PROCESS_LOCAL, 9215 bytes)
[2025-06-26T20:30:11.894+0700] {subprocess.py:93} INFO - 25/06/26 20:30:11 INFO TaskSetManager: Starting task 68.0 in stage 0.0 (TID 68) (localhost, executor driver, partition 68, PROCESS_LOCAL, 9215 bytes)
[2025-06-26T20:30:11.894+0700] {subprocess.py:93} INFO - 25/06/26 20:30:11 INFO TaskSetManager: Finished task 43.0 in stage 0.0 (TID 43) in 162 ms on localhost (executor driver) (46/2930)
[2025-06-26T20:30:11.894+0700] {subprocess.py:93} INFO - 25/06/26 20:30:11 INFO TaskSetManager: Finished task 46.0 in stage 0.0 (TID 46) in 135 ms on localhost (executor driver) (47/2930)
[2025-06-26T20:30:11.895+0700] {subprocess.py:93} INFO - 25/06/26 20:30:11 INFO Executor: Running task 67.0 in stage 0.0 (TID 67)
[2025-06-26T20:30:11.898+0700] {subprocess.py:93} INFO - 25/06/26 20:30:11 INFO Executor: Finished task 47.0 in stage 0.0 (TID 47). 3218 bytes result sent to driver
[2025-06-26T20:30:11.903+0700] {subprocess.py:93} INFO - 25/06/26 20:30:11 INFO TaskSetManager: Starting task 69.0 in stage 0.0 (TID 69) (localhost, executor driver, partition 69, PROCESS_LOCAL, 9215 bytes)
[2025-06-26T20:30:11.906+0700] {subprocess.py:93} INFO - 25/06/26 20:30:11 INFO TaskSetManager: Finished task 47.0 in stage 0.0 (TID 47) in 141 ms on localhost (executor driver) (48/2930)
[2025-06-26T20:30:11.906+0700] {subprocess.py:93} INFO - 25/06/26 20:30:11 INFO Executor: Running task 69.0 in stage 0.0 (TID 69)
[2025-06-26T20:30:11.908+0700] {subprocess.py:93} INFO - 25/06/26 20:30:11 INFO Executor: Running task 68.0 in stage 0.0 (TID 68)
[2025-06-26T20:30:11.929+0700] {subprocess.py:93} INFO - 25/06/26 20:30:11 INFO Executor: Finished task 54.0 in stage 0.0 (TID 54). 3175 bytes result sent to driver
[2025-06-26T20:30:11.930+0700] {subprocess.py:93} INFO - 25/06/26 20:30:11 INFO Executor: Finished task 48.0 in stage 0.0 (TID 48). 3218 bytes result sent to driver
[2025-06-26T20:30:11.930+0700] {subprocess.py:93} INFO - 25/06/26 20:30:11 INFO TaskSetManager: Starting task 70.0 in stage 0.0 (TID 70) (localhost, executor driver, partition 70, PROCESS_LOCAL, 9215 bytes)
[2025-06-26T20:30:11.930+0700] {subprocess.py:93} INFO - 25/06/26 20:30:11 INFO Executor: Running task 70.0 in stage 0.0 (TID 70)
[2025-06-26T20:30:11.934+0700] {subprocess.py:93} INFO - 25/06/26 20:30:11 INFO Executor: Finished task 49.0 in stage 0.0 (TID 49). 3218 bytes result sent to driver
[2025-06-26T20:30:11.934+0700] {subprocess.py:93} INFO - 25/06/26 20:30:11 INFO TaskSetManager: Starting task 71.0 in stage 0.0 (TID 71) (localhost, executor driver, partition 71, PROCESS_LOCAL, 9215 bytes)
[2025-06-26T20:30:11.935+0700] {subprocess.py:93} INFO - 25/06/26 20:30:11 INFO Executor: Running task 71.0 in stage 0.0 (TID 71)
[2025-06-26T20:30:11.935+0700] {subprocess.py:93} INFO - 25/06/26 20:30:11 INFO Executor: Finished task 51.0 in stage 0.0 (TID 51). 3218 bytes result sent to driver
[2025-06-26T20:30:11.941+0700] {subprocess.py:93} INFO - 25/06/26 20:30:11 INFO TaskSetManager: Starting task 72.0 in stage 0.0 (TID 72) (localhost, executor driver, partition 72, PROCESS_LOCAL, 9215 bytes)
[2025-06-26T20:30:11.945+0700] {subprocess.py:93} INFO - 25/06/26 20:30:11 INFO Executor: Running task 72.0 in stage 0.0 (TID 72)
[2025-06-26T20:30:11.945+0700] {subprocess.py:93} INFO - 25/06/26 20:30:11 INFO TaskSetManager: Starting task 73.0 in stage 0.0 (TID 73) (localhost, executor driver, partition 73, PROCESS_LOCAL, 9215 bytes)
[2025-06-26T20:30:11.947+0700] {subprocess.py:93} INFO - 25/06/26 20:30:11 INFO TaskSetManager: Finished task 48.0 in stage 0.0 (TID 48) in 175 ms on localhost (executor driver) (49/2930)
[2025-06-26T20:30:11.948+0700] {subprocess.py:93} INFO - 25/06/26 20:30:11 INFO TaskSetManager: Finished task 54.0 in stage 0.0 (TID 54) in 118 ms on localhost (executor driver) (50/2930)
[2025-06-26T20:30:11.948+0700] {subprocess.py:93} INFO - 25/06/26 20:30:11 INFO TaskSetManager: Finished task 49.0 in stage 0.0 (TID 49) in 166 ms on localhost (executor driver) (51/2930)
[2025-06-26T20:30:11.950+0700] {subprocess.py:93} INFO - 25/06/26 20:30:11 INFO Executor: Finished task 52.0 in stage 0.0 (TID 52). 3175 bytes result sent to driver
[2025-06-26T20:30:11.951+0700] {subprocess.py:93} INFO - 25/06/26 20:30:11 INFO TaskSetManager: Starting task 74.0 in stage 0.0 (TID 74) (localhost, executor driver, partition 74, PROCESS_LOCAL, 9215 bytes)
[2025-06-26T20:30:11.952+0700] {subprocess.py:93} INFO - 25/06/26 20:30:11 INFO Executor: Running task 73.0 in stage 0.0 (TID 73)
[2025-06-26T20:30:11.953+0700] {subprocess.py:93} INFO - 25/06/26 20:30:11 INFO TaskSetManager: Finished task 52.0 in stage 0.0 (TID 52) in 128 ms on localhost (executor driver) (52/2930)
[2025-06-26T20:30:11.955+0700] {subprocess.py:93} INFO - 25/06/26 20:30:11 INFO TaskSetManager: Finished task 51.0 in stage 0.0 (TID 51) in 133 ms on localhost (executor driver) (53/2930)
[2025-06-26T20:30:11.959+0700] {subprocess.py:93} INFO - 25/06/26 20:30:11 INFO Executor: Running task 74.0 in stage 0.0 (TID 74)
[2025-06-26T20:30:11.966+0700] {subprocess.py:93} INFO - 25/06/26 20:30:11 INFO Executor: Finished task 50.0 in stage 0.0 (TID 50). 3218 bytes result sent to driver
[2025-06-26T20:30:11.966+0700] {subprocess.py:93} INFO - 25/06/26 20:30:11 INFO Executor: Finished task 56.0 in stage 0.0 (TID 56). 3175 bytes result sent to driver
[2025-06-26T20:30:11.967+0700] {subprocess.py:93} INFO - 25/06/26 20:30:11 INFO Executor: Finished task 57.0 in stage 0.0 (TID 57). 3175 bytes result sent to driver
[2025-06-26T20:30:11.967+0700] {subprocess.py:93} INFO - 25/06/26 20:30:11 INFO TaskSetManager: Starting task 75.0 in stage 0.0 (TID 75) (localhost, executor driver, partition 75, PROCESS_LOCAL, 9215 bytes)
[2025-06-26T20:30:11.967+0700] {subprocess.py:93} INFO - 25/06/26 20:30:11 INFO Executor: Running task 75.0 in stage 0.0 (TID 75)
[2025-06-26T20:30:11.967+0700] {subprocess.py:93} INFO - 25/06/26 20:30:11 INFO Executor: Finished task 58.0 in stage 0.0 (TID 58). 3175 bytes result sent to driver
[2025-06-26T20:30:11.967+0700] {subprocess.py:93} INFO - 25/06/26 20:30:11 INFO Executor: Finished task 59.0 in stage 0.0 (TID 59). 3175 bytes result sent to driver
[2025-06-26T20:30:11.970+0700] {subprocess.py:93} INFO - 25/06/26 20:30:11 INFO Executor: Finished task 61.0 in stage 0.0 (TID 61). 3175 bytes result sent to driver
[2025-06-26T20:30:11.970+0700] {subprocess.py:93} INFO - 25/06/26 20:30:11 INFO TaskSetManager: Starting task 76.0 in stage 0.0 (TID 76) (localhost, executor driver, partition 76, PROCESS_LOCAL, 9215 bytes)
[2025-06-26T20:30:11.971+0700] {subprocess.py:93} INFO - 25/06/26 20:30:11 INFO TaskSetManager: Starting task 77.0 in stage 0.0 (TID 77) (localhost, executor driver, partition 77, PROCESS_LOCAL, 9215 bytes)
[2025-06-26T20:30:11.971+0700] {subprocess.py:93} INFO - 25/06/26 20:30:11 INFO Executor: Running task 77.0 in stage 0.0 (TID 77)
[2025-06-26T20:30:11.972+0700] {subprocess.py:93} INFO - 25/06/26 20:30:11 INFO TaskSetManager: Starting task 78.0 in stage 0.0 (TID 78) (localhost, executor driver, partition 78, PROCESS_LOCAL, 9215 bytes)
[2025-06-26T20:30:11.979+0700] {subprocess.py:93} INFO - 25/06/26 20:30:11 INFO Executor: Running task 76.0 in stage 0.0 (TID 76)
[2025-06-26T20:30:11.980+0700] {subprocess.py:93} INFO - 25/06/26 20:30:11 INFO TaskSetManager: Finished task 59.0 in stage 0.0 (TID 59) in 126 ms on localhost (executor driver) (54/2930)
[2025-06-26T20:30:11.980+0700] {subprocess.py:93} INFO - 25/06/26 20:30:11 INFO TaskSetManager: Finished task 58.0 in stage 0.0 (TID 58) in 130 ms on localhost (executor driver) (55/2930)
[2025-06-26T20:30:11.981+0700] {subprocess.py:93} INFO - 25/06/26 20:30:11 INFO Executor: Running task 78.0 in stage 0.0 (TID 78)
[2025-06-26T20:30:11.981+0700] {subprocess.py:93} INFO - 25/06/26 20:30:11 INFO Executor: Finished task 53.0 in stage 0.0 (TID 53). 3175 bytes result sent to driver
[2025-06-26T20:30:11.981+0700] {subprocess.py:93} INFO - 25/06/26 20:30:11 INFO Executor: Finished task 55.0 in stage 0.0 (TID 55). 3175 bytes result sent to driver
[2025-06-26T20:30:11.981+0700] {subprocess.py:93} INFO - 25/06/26 20:30:11 INFO Executor: Finished task 62.0 in stage 0.0 (TID 62). 3175 bytes result sent to driver
[2025-06-26T20:30:11.981+0700] {subprocess.py:93} INFO - 25/06/26 20:30:11 INFO Executor: Finished task 63.0 in stage 0.0 (TID 63). 3175 bytes result sent to driver
[2025-06-26T20:30:11.981+0700] {subprocess.py:93} INFO - 25/06/26 20:30:11 INFO TaskSetManager: Starting task 79.0 in stage 0.0 (TID 79) (localhost, executor driver, partition 79, PROCESS_LOCAL, 9215 bytes)
[2025-06-26T20:30:11.981+0700] {subprocess.py:93} INFO - 25/06/26 20:30:11 INFO Executor: Finished task 66.0 in stage 0.0 (TID 66). 3175 bytes result sent to driver
[2025-06-26T20:30:11.982+0700] {subprocess.py:93} INFO - 25/06/26 20:30:11 INFO TaskSetManager: Finished task 56.0 in stage 0.0 (TID 56) in 141 ms on localhost (executor driver) (56/2930)
[2025-06-26T20:30:11.982+0700] {subprocess.py:93} INFO - 25/06/26 20:30:11 INFO TaskSetManager: Finished task 50.0 in stage 0.0 (TID 50) in 193 ms on localhost (executor driver) (57/2930)
[2025-06-26T20:30:11.982+0700] {subprocess.py:93} INFO - 25/06/26 20:30:11 INFO Executor: Finished task 64.0 in stage 0.0 (TID 64). 3175 bytes result sent to driver
[2025-06-26T20:30:11.996+0700] {subprocess.py:93} INFO - 25/06/26 20:30:11 INFO TaskSetManager: Starting task 80.0 in stage 0.0 (TID 80) (localhost, executor driver, partition 80, PROCESS_LOCAL, 9215 bytes)
[2025-06-26T20:30:11.997+0700] {subprocess.py:93} INFO - 25/06/26 20:30:11 INFO Executor: Running task 79.0 in stage 0.0 (TID 79)
[2025-06-26T20:30:11.997+0700] {subprocess.py:93} INFO - 25/06/26 20:30:11 INFO TaskSetManager: Finished task 61.0 in stage 0.0 (TID 61) in 146 ms on localhost (executor driver) (58/2930)
[2025-06-26T20:30:11.997+0700] {subprocess.py:93} INFO - 25/06/26 20:30:11 INFO Executor: Running task 80.0 in stage 0.0 (TID 80)
[2025-06-26T20:30:11.998+0700] {subprocess.py:93} INFO - 25/06/26 20:30:11 INFO Executor: Finished task 60.0 in stage 0.0 (TID 60). 3261 bytes result sent to driver
[2025-06-26T20:30:11.999+0700] {subprocess.py:93} INFO - 25/06/26 20:30:11 INFO Executor: Finished task 69.0 in stage 0.0 (TID 69). 3218 bytes result sent to driver
[2025-06-26T20:30:12.003+0700] {subprocess.py:93} INFO - 25/06/26 20:30:12 INFO TaskSetManager: Starting task 81.0 in stage 0.0 (TID 81) (localhost, executor driver, partition 81, PROCESS_LOCAL, 9215 bytes)
[2025-06-26T20:30:12.003+0700] {subprocess.py:93} INFO - 25/06/26 20:30:12 INFO Executor: Running task 81.0 in stage 0.0 (TID 81)
[2025-06-26T20:30:12.004+0700] {subprocess.py:93} INFO - 25/06/26 20:30:12 INFO TaskSetManager: Starting task 82.0 in stage 0.0 (TID 82) (localhost, executor driver, partition 82, PROCESS_LOCAL, 9215 bytes)
[2025-06-26T20:30:12.011+0700] {subprocess.py:93} INFO - 25/06/26 20:30:12 INFO Executor: Running task 82.0 in stage 0.0 (TID 82)
[2025-06-26T20:30:12.017+0700] {subprocess.py:93} INFO - 25/06/26 20:30:12 INFO TaskSetManager: Starting task 83.0 in stage 0.0 (TID 83) (localhost, executor driver, partition 83, PROCESS_LOCAL, 9215 bytes)
[2025-06-26T20:30:12.017+0700] {subprocess.py:93} INFO - 25/06/26 20:30:12 INFO TaskSetManager: Starting task 84.0 in stage 0.0 (TID 84) (localhost, executor driver, partition 84, PROCESS_LOCAL, 9215 bytes)
[2025-06-26T20:30:12.018+0700] {subprocess.py:93} INFO - 25/06/26 20:30:12 INFO TaskSetManager: Starting task 85.0 in stage 0.0 (TID 85) (localhost, executor driver, partition 85, PROCESS_LOCAL, 9215 bytes)
[2025-06-26T20:30:12.018+0700] {subprocess.py:93} INFO - 25/06/26 20:30:12 INFO Executor: Finished task 67.0 in stage 0.0 (TID 67). 3218 bytes result sent to driver
[2025-06-26T20:30:12.018+0700] {subprocess.py:93} INFO - 25/06/26 20:30:12 INFO Executor: Running task 83.0 in stage 0.0 (TID 83)
[2025-06-26T20:30:12.018+0700] {subprocess.py:93} INFO - 25/06/26 20:30:12 INFO TaskSetManager: Starting task 86.0 in stage 0.0 (TID 86) (localhost, executor driver, partition 86, PROCESS_LOCAL, 9215 bytes)
[2025-06-26T20:30:12.022+0700] {subprocess.py:93} INFO - 25/06/26 20:30:12 INFO TaskSetManager: Finished task 57.0 in stage 0.0 (TID 57) in 175 ms on localhost (executor driver) (59/2930)
[2025-06-26T20:30:12.022+0700] {subprocess.py:93} INFO - 25/06/26 20:30:12 INFO Executor: Running task 84.0 in stage 0.0 (TID 84)
[2025-06-26T20:30:12.022+0700] {subprocess.py:93} INFO - 25/06/26 20:30:12 INFO TaskSetManager: Finished task 66.0 in stage 0.0 (TID 66) in 132 ms on localhost (executor driver) (60/2930)
[2025-06-26T20:30:12.022+0700] {subprocess.py:93} INFO - 25/06/26 20:30:12 INFO TaskSetManager: Finished task 62.0 in stage 0.0 (TID 62) in 151 ms on localhost (executor driver) (61/2930)
[2025-06-26T20:30:12.022+0700] {subprocess.py:93} INFO - 25/06/26 20:30:12 INFO Executor: Running task 85.0 in stage 0.0 (TID 85)
[2025-06-26T20:30:12.022+0700] {subprocess.py:93} INFO - 25/06/26 20:30:12 INFO Executor: Finished task 75.0 in stage 0.0 (TID 75). 3218 bytes result sent to driver
[2025-06-26T20:30:12.023+0700] {subprocess.py:93} INFO - 25/06/26 20:30:12 INFO TaskSetManager: Finished task 63.0 in stage 0.0 (TID 63) in 151 ms on localhost (executor driver) (62/2930)
[2025-06-26T20:30:12.023+0700] {subprocess.py:93} INFO - 25/06/26 20:30:12 INFO Executor: Running task 86.0 in stage 0.0 (TID 86)
[2025-06-26T20:30:12.024+0700] {subprocess.py:93} INFO - 25/06/26 20:30:12 INFO Executor: Finished task 72.0 in stage 0.0 (TID 72). 3218 bytes result sent to driver
[2025-06-26T20:30:12.025+0700] {subprocess.py:93} INFO - 25/06/26 20:30:12 INFO Executor: Finished task 65.0 in stage 0.0 (TID 65). 3218 bytes result sent to driver
[2025-06-26T20:30:12.027+0700] {subprocess.py:93} INFO - 25/06/26 20:30:12 INFO Executor: Finished task 73.0 in stage 0.0 (TID 73). 3218 bytes result sent to driver
[2025-06-26T20:30:12.028+0700] {subprocess.py:93} INFO - 25/06/26 20:30:12 INFO Executor: Finished task 71.0 in stage 0.0 (TID 71). 3218 bytes result sent to driver
[2025-06-26T20:30:12.028+0700] {subprocess.py:93} INFO - 25/06/26 20:30:12 INFO TaskSetManager: Starting task 87.0 in stage 0.0 (TID 87) (localhost, executor driver, partition 87, PROCESS_LOCAL, 9215 bytes)
[2025-06-26T20:30:12.031+0700] {subprocess.py:93} INFO - 25/06/26 20:30:12 INFO TaskSetManager: Finished task 55.0 in stage 0.0 (TID 55) in 195 ms on localhost (executor driver) (63/2930)
[2025-06-26T20:30:12.031+0700] {subprocess.py:93} INFO - 25/06/26 20:30:12 INFO Executor: Running task 87.0 in stage 0.0 (TID 87)
[2025-06-26T20:30:12.031+0700] {subprocess.py:93} INFO - 25/06/26 20:30:12 INFO TaskSetManager: Finished task 53.0 in stage 0.0 (TID 53) in 206 ms on localhost (executor driver) (64/2930)
[2025-06-26T20:30:12.031+0700] {subprocess.py:93} INFO - 25/06/26 20:30:12 INFO TaskSetManager: Finished task 64.0 in stage 0.0 (TID 64) in 156 ms on localhost (executor driver) (65/2930)
[2025-06-26T20:30:12.032+0700] {subprocess.py:93} INFO - 25/06/26 20:30:12 INFO TaskSetManager: Finished task 60.0 in stage 0.0 (TID 60) in 183 ms on localhost (executor driver) (66/2930)
[2025-06-26T20:30:12.054+0700] {subprocess.py:93} INFO - 25/06/26 20:30:12 INFO TaskSetManager: Starting task 88.0 in stage 0.0 (TID 88) (localhost, executor driver, partition 88, PROCESS_LOCAL, 9215 bytes)
[2025-06-26T20:30:12.054+0700] {subprocess.py:93} INFO - 25/06/26 20:30:12 INFO Executor: Finished task 74.0 in stage 0.0 (TID 74). 3261 bytes result sent to driver
[2025-06-26T20:30:12.054+0700] {subprocess.py:93} INFO - 25/06/26 20:30:12 INFO Executor: Finished task 70.0 in stage 0.0 (TID 70). 3218 bytes result sent to driver
[2025-06-26T20:30:12.055+0700] {subprocess.py:93} INFO - 25/06/26 20:30:12 INFO Executor: Finished task 68.0 in stage 0.0 (TID 68). 3218 bytes result sent to driver
[2025-06-26T20:30:12.055+0700] {subprocess.py:93} INFO - 25/06/26 20:30:12 INFO Executor: Running task 88.0 in stage 0.0 (TID 88)
[2025-06-26T20:30:12.056+0700] {subprocess.py:93} INFO - 25/06/26 20:30:12 INFO TaskSetManager: Starting task 89.0 in stage 0.0 (TID 89) (localhost, executor driver, partition 89, PROCESS_LOCAL, 9215 bytes)
[2025-06-26T20:30:12.057+0700] {subprocess.py:93} INFO - 25/06/26 20:30:12 INFO TaskSetManager: Finished task 69.0 in stage 0.0 (TID 69) in 154 ms on localhost (executor driver) (67/2930)
[2025-06-26T20:30:12.057+0700] {subprocess.py:93} INFO - 25/06/26 20:30:12 INFO Executor: Running task 89.0 in stage 0.0 (TID 89)
[2025-06-26T20:30:12.057+0700] {subprocess.py:93} INFO - 25/06/26 20:30:12 INFO TaskSetManager: Finished task 67.0 in stage 0.0 (TID 67) in 167 ms on localhost (executor driver) (68/2930)
[2025-06-26T20:30:12.058+0700] {subprocess.py:93} INFO - 25/06/26 20:30:12 INFO TaskSetManager: Starting task 90.0 in stage 0.0 (TID 90) (localhost, executor driver, partition 90, PROCESS_LOCAL, 9215 bytes)
[2025-06-26T20:30:12.059+0700] {subprocess.py:93} INFO - 25/06/26 20:30:12 INFO Executor: Running task 90.0 in stage 0.0 (TID 90)
[2025-06-26T20:30:12.060+0700] {subprocess.py:93} INFO - 25/06/26 20:30:12 INFO TaskSetManager: Starting task 91.0 in stage 0.0 (TID 91) (localhost, executor driver, partition 91, PROCESS_LOCAL, 9215 bytes)
[2025-06-26T20:30:12.062+0700] {subprocess.py:93} INFO - 25/06/26 20:30:12 INFO TaskSetManager: Starting task 92.0 in stage 0.0 (TID 92) (localhost, executor driver, partition 92, PROCESS_LOCAL, 9215 bytes)
[2025-06-26T20:30:12.062+0700] {subprocess.py:93} INFO - 25/06/26 20:30:12 INFO TaskSetManager: Starting task 93.0 in stage 0.0 (TID 93) (localhost, executor driver, partition 93, PROCESS_LOCAL, 9215 bytes)
[2025-06-26T20:30:12.062+0700] {subprocess.py:93} INFO - 25/06/26 20:30:12 INFO Executor: Running task 92.0 in stage 0.0 (TID 92)
[2025-06-26T20:30:12.062+0700] {subprocess.py:93} INFO - 25/06/26 20:30:12 INFO Executor: Finished task 76.0 in stage 0.0 (TID 76). 3218 bytes result sent to driver
[2025-06-26T20:30:12.062+0700] {subprocess.py:93} INFO - 25/06/26 20:30:12 INFO Executor: Running task 93.0 in stage 0.0 (TID 93)
[2025-06-26T20:30:12.063+0700] {subprocess.py:93} INFO - 25/06/26 20:30:12 INFO TaskSetManager: Starting task 94.0 in stage 0.0 (TID 94) (localhost, executor driver, partition 94, PROCESS_LOCAL, 9215 bytes)
[2025-06-26T20:30:12.063+0700] {subprocess.py:93} INFO - 25/06/26 20:30:12 INFO Executor: Running task 91.0 in stage 0.0 (TID 91)
[2025-06-26T20:30:12.063+0700] {subprocess.py:93} INFO - 25/06/26 20:30:12 INFO Executor: Finished task 77.0 in stage 0.0 (TID 77). 3218 bytes result sent to driver
[2025-06-26T20:30:12.064+0700] {subprocess.py:93} INFO - 25/06/26 20:30:12 INFO TaskSetManager: Starting task 95.0 in stage 0.0 (TID 95) (localhost, executor driver, partition 95, PROCESS_LOCAL, 9215 bytes)
[2025-06-26T20:30:12.064+0700] {subprocess.py:93} INFO - 25/06/26 20:30:12 INFO Executor: Running task 95.0 in stage 0.0 (TID 95)
[2025-06-26T20:30:12.064+0700] {subprocess.py:93} INFO - 25/06/26 20:30:12 INFO Executor: Running task 94.0 in stage 0.0 (TID 94)
[2025-06-26T20:30:12.065+0700] {subprocess.py:93} INFO - 25/06/26 20:30:12 INFO TaskSetManager: Starting task 96.0 in stage 0.0 (TID 96) (localhost, executor driver, partition 96, PROCESS_LOCAL, 9215 bytes)
[2025-06-26T20:30:12.065+0700] {subprocess.py:93} INFO - 25/06/26 20:30:12 INFO TaskSetManager: Finished task 73.0 in stage 0.0 (TID 73) in 122 ms on localhost (executor driver) (69/2930)
[2025-06-26T20:30:12.066+0700] {subprocess.py:93} INFO - 25/06/26 20:30:12 INFO Executor: Running task 96.0 in stage 0.0 (TID 96)
[2025-06-26T20:30:12.069+0700] {subprocess.py:93} INFO - 25/06/26 20:30:12 INFO TaskSetManager: Finished task 65.0 in stage 0.0 (TID 65) in 192 ms on localhost (executor driver) (70/2930)
[2025-06-26T20:30:12.072+0700] {subprocess.py:93} INFO - 25/06/26 20:30:12 INFO Executor: Finished task 83.0 in stage 0.0 (TID 83). 3218 bytes result sent to driver
[2025-06-26T20:30:12.072+0700] {subprocess.py:93} INFO - 25/06/26 20:30:12 INFO Executor: Finished task 79.0 in stage 0.0 (TID 79). 3175 bytes result sent to driver
[2025-06-26T20:30:12.073+0700] {subprocess.py:93} INFO - 25/06/26 20:30:12 INFO TaskSetManager: Finished task 75.0 in stage 0.0 (TID 75) in 105 ms on localhost (executor driver) (71/2930)
[2025-06-26T20:30:12.073+0700] {subprocess.py:93} INFO - 25/06/26 20:30:12 INFO Executor: Finished task 85.0 in stage 0.0 (TID 85). 3218 bytes result sent to driver
[2025-06-26T20:30:12.073+0700] {subprocess.py:93} INFO - 25/06/26 20:30:12 INFO Executor: Finished task 84.0 in stage 0.0 (TID 84). 3175 bytes result sent to driver
[2025-06-26T20:30:12.074+0700] {subprocess.py:93} INFO - 25/06/26 20:30:12 INFO TaskSetManager: Starting task 97.0 in stage 0.0 (TID 97) (localhost, executor driver, partition 97, PROCESS_LOCAL, 9215 bytes)
[2025-06-26T20:30:12.074+0700] {subprocess.py:93} INFO - 25/06/26 20:30:12 INFO Executor: Finished task 80.0 in stage 0.0 (TID 80). 3175 bytes result sent to driver
[2025-06-26T20:30:12.075+0700] {subprocess.py:93} INFO - 25/06/26 20:30:12 INFO Executor: Running task 97.0 in stage 0.0 (TID 97)
[2025-06-26T20:30:12.075+0700] {subprocess.py:93} INFO - 25/06/26 20:30:12 INFO TaskSetManager: Finished task 72.0 in stage 0.0 (TID 72) in 142 ms on localhost (executor driver) (72/2930)
[2025-06-26T20:30:12.076+0700] {subprocess.py:93} INFO - 25/06/26 20:30:12 INFO Executor: Finished task 81.0 in stage 0.0 (TID 81). 3218 bytes result sent to driver
[2025-06-26T20:30:12.076+0700] {subprocess.py:93} INFO - 25/06/26 20:30:12 INFO TaskSetManager: Starting task 98.0 in stage 0.0 (TID 98) (localhost, executor driver, partition 98, PROCESS_LOCAL, 9215 bytes)
[2025-06-26T20:30:12.076+0700] {subprocess.py:93} INFO - 25/06/26 20:30:12 INFO Executor: Finished task 78.0 in stage 0.0 (TID 78). 3218 bytes result sent to driver
[2025-06-26T20:30:12.076+0700] {subprocess.py:93} INFO - 25/06/26 20:30:12 INFO TaskSetManager: Finished task 71.0 in stage 0.0 (TID 71) in 147 ms on localhost (executor driver) (73/2930)
[2025-06-26T20:30:12.077+0700] {subprocess.py:93} INFO - 25/06/26 20:30:12 INFO Executor: Running task 98.0 in stage 0.0 (TID 98)
[2025-06-26T20:30:12.077+0700] {subprocess.py:93} INFO - 25/06/26 20:30:12 INFO TaskSetManager: Finished task 70.0 in stage 0.0 (TID 70) in 151 ms on localhost (executor driver) (74/2930)
[2025-06-26T20:30:12.077+0700] {subprocess.py:93} INFO - 25/06/26 20:30:12 INFO TaskSetManager: Finished task 74.0 in stage 0.0 (TID 74) in 126 ms on localhost (executor driver) (75/2930)
[2025-06-26T20:30:12.084+0700] {subprocess.py:93} INFO - 25/06/26 20:30:12 INFO Executor: Finished task 87.0 in stage 0.0 (TID 87). 3175 bytes result sent to driver
[2025-06-26T20:30:12.085+0700] {subprocess.py:93} INFO - 25/06/26 20:30:12 INFO Executor: Finished task 86.0 in stage 0.0 (TID 86). 3218 bytes result sent to driver
[2025-06-26T20:30:12.086+0700] {subprocess.py:93} INFO - 25/06/26 20:30:12 INFO Executor: Finished task 88.0 in stage 0.0 (TID 88). 3175 bytes result sent to driver
[2025-06-26T20:30:12.086+0700] {subprocess.py:93} INFO - 25/06/26 20:30:12 INFO Executor: Finished task 82.0 in stage 0.0 (TID 82). 3175 bytes result sent to driver
[2025-06-26T20:30:12.086+0700] {subprocess.py:93} INFO - 25/06/26 20:30:12 INFO TaskSetManager: Starting task 99.0 in stage 0.0 (TID 99) (localhost, executor driver, partition 99, PROCESS_LOCAL, 9215 bytes)
[2025-06-26T20:30:12.087+0700] {subprocess.py:93} INFO - 25/06/26 20:30:12 INFO TaskSetManager: Finished task 68.0 in stage 0.0 (TID 68) in 196 ms on localhost (executor driver) (76/2930)
[2025-06-26T20:30:12.087+0700] {subprocess.py:93} INFO - 25/06/26 20:30:12 INFO Executor: Running task 99.0 in stage 0.0 (TID 99)
[2025-06-26T20:30:12.088+0700] {subprocess.py:93} INFO - 25/06/26 20:30:12 INFO TaskSetManager: Finished task 76.0 in stage 0.0 (TID 76) in 118 ms on localhost (executor driver) (77/2930)
[2025-06-26T20:30:12.088+0700] {subprocess.py:93} INFO - 25/06/26 20:30:12 INFO TaskSetManager: Finished task 77.0 in stage 0.0 (TID 77) in 117 ms on localhost (executor driver) (78/2930)
[2025-06-26T20:30:12.089+0700] {subprocess.py:93} INFO - 25/06/26 20:30:12 INFO TaskSetManager: Starting task 100.0 in stage 0.0 (TID 100) (localhost, executor driver, partition 100, PROCESS_LOCAL, 9215 bytes)
[2025-06-26T20:30:12.089+0700] {subprocess.py:93} INFO - 25/06/26 20:30:12 INFO Executor: Running task 100.0 in stage 0.0 (TID 100)
[2025-06-26T20:30:12.092+0700] {subprocess.py:93} INFO - 25/06/26 20:30:12 INFO TaskSetManager: Starting task 101.0 in stage 0.0 (TID 101) (localhost, executor driver, partition 101, PROCESS_LOCAL, 9215 bytes)
[2025-06-26T20:30:12.095+0700] {subprocess.py:93} INFO - 25/06/26 20:30:12 INFO TaskSetManager: Finished task 83.0 in stage 0.0 (TID 83) in 85 ms on localhost (executor driver) (79/2930)
[2025-06-26T20:30:12.095+0700] {subprocess.py:93} INFO - 25/06/26 20:30:12 INFO Executor: Running task 101.0 in stage 0.0 (TID 101)
[2025-06-26T20:30:12.095+0700] {subprocess.py:93} INFO - 25/06/26 20:30:12 INFO Executor: Finished task 90.0 in stage 0.0 (TID 90). 3175 bytes result sent to driver
[2025-06-26T20:30:12.095+0700] {subprocess.py:93} INFO - 25/06/26 20:30:12 INFO Executor: Finished task 89.0 in stage 0.0 (TID 89). 3218 bytes result sent to driver
[2025-06-26T20:30:12.096+0700] {subprocess.py:93} INFO - 25/06/26 20:30:12 INFO Executor: Finished task 93.0 in stage 0.0 (TID 93). 3218 bytes result sent to driver
[2025-06-26T20:30:12.098+0700] {subprocess.py:93} INFO - 25/06/26 20:30:12 INFO Executor: Finished task 91.0 in stage 0.0 (TID 91). 3218 bytes result sent to driver
[2025-06-26T20:30:12.098+0700] {subprocess.py:93} INFO - 25/06/26 20:30:12 INFO Executor: Finished task 92.0 in stage 0.0 (TID 92). 3175 bytes result sent to driver
[2025-06-26T20:30:12.106+0700] {subprocess.py:93} INFO - 25/06/26 20:30:12 INFO TaskSetManager: Starting task 102.0 in stage 0.0 (TID 102) (localhost, executor driver, partition 102, PROCESS_LOCAL, 9215 bytes)
[2025-06-26T20:30:12.107+0700] {subprocess.py:93} INFO - 25/06/26 20:30:12 INFO Executor: Finished task 96.0 in stage 0.0 (TID 96). 3218 bytes result sent to driver
[2025-06-26T20:30:12.109+0700] {subprocess.py:93} INFO - 25/06/26 20:30:12 INFO Executor: Running task 102.0 in stage 0.0 (TID 102)
[2025-06-26T20:30:12.109+0700] {subprocess.py:93} INFO - 25/06/26 20:30:12 INFO TaskSetManager: Finished task 79.0 in stage 0.0 (TID 79) in 130 ms on localhost (executor driver) (80/2930)
[2025-06-26T20:30:12.110+0700] {subprocess.py:93} INFO - 25/06/26 20:30:12 INFO Executor: Finished task 97.0 in stage 0.0 (TID 97). 3261 bytes result sent to driver
[2025-06-26T20:30:12.110+0700] {subprocess.py:93} INFO - 25/06/26 20:30:12 INFO TaskSetManager: Finished task 85.0 in stage 0.0 (TID 85) in 93 ms on localhost (executor driver) (81/2930)
[2025-06-26T20:30:12.110+0700] {subprocess.py:93} INFO - 25/06/26 20:30:12 INFO Executor: Finished task 95.0 in stage 0.0 (TID 95). 3218 bytes result sent to driver
[2025-06-26T20:30:12.111+0700] {subprocess.py:93} INFO - 25/06/26 20:30:12 INFO TaskSetManager: Starting task 103.0 in stage 0.0 (TID 103) (localhost, executor driver, partition 103, PROCESS_LOCAL, 9215 bytes)
[2025-06-26T20:30:12.111+0700] {subprocess.py:93} INFO - 25/06/26 20:30:12 INFO TaskSetManager: Finished task 84.0 in stage 0.0 (TID 84) in 96 ms on localhost (executor driver) (82/2930)
[2025-06-26T20:30:12.111+0700] {subprocess.py:93} INFO - 25/06/26 20:30:12 INFO Executor: Running task 103.0 in stage 0.0 (TID 103)
[2025-06-26T20:30:12.112+0700] {subprocess.py:93} INFO - 25/06/26 20:30:12 INFO TaskSetManager: Starting task 104.0 in stage 0.0 (TID 104) (localhost, executor driver, partition 104, PROCESS_LOCAL, 9215 bytes)
[2025-06-26T20:30:12.113+0700] {subprocess.py:93} INFO - 25/06/26 20:30:12 INFO Executor: Running task 104.0 in stage 0.0 (TID 104)
[2025-06-26T20:30:12.115+0700] {subprocess.py:93} INFO - 25/06/26 20:30:12 INFO TaskSetManager: Starting task 105.0 in stage 0.0 (TID 105) (localhost, executor driver, partition 105, PROCESS_LOCAL, 9215 bytes)
[2025-06-26T20:30:12.115+0700] {subprocess.py:93} INFO - 25/06/26 20:30:12 INFO Executor: Finished task 94.0 in stage 0.0 (TID 94). 3218 bytes result sent to driver
[2025-06-26T20:30:12.115+0700] {subprocess.py:93} INFO - 25/06/26 20:30:12 INFO Executor: Finished task 98.0 in stage 0.0 (TID 98). 3218 bytes result sent to driver
[2025-06-26T20:30:12.116+0700] {subprocess.py:93} INFO - 25/06/26 20:30:12 INFO Executor: Running task 105.0 in stage 0.0 (TID 105)
[2025-06-26T20:30:12.116+0700] {subprocess.py:93} INFO - 25/06/26 20:30:12 INFO TaskSetManager: Starting task 106.0 in stage 0.0 (TID 106) (localhost, executor driver, partition 106, PROCESS_LOCAL, 9215 bytes)
[2025-06-26T20:30:12.116+0700] {subprocess.py:93} INFO - 25/06/26 20:30:12 INFO TaskSetManager: Finished task 80.0 in stage 0.0 (TID 80) in 121 ms on localhost (executor driver) (83/2930)
[2025-06-26T20:30:12.116+0700] {subprocess.py:93} INFO - 25/06/26 20:30:12 INFO Executor: Running task 106.0 in stage 0.0 (TID 106)
[2025-06-26T20:30:12.117+0700] {subprocess.py:93} INFO - 25/06/26 20:30:12 INFO TaskSetManager: Starting task 107.0 in stage 0.0 (TID 107) (localhost, executor driver, partition 107, PROCESS_LOCAL, 9215 bytes)
[2025-06-26T20:30:12.118+0700] {subprocess.py:93} INFO - 25/06/26 20:30:12 INFO Executor: Running task 107.0 in stage 0.0 (TID 107)
[2025-06-26T20:30:12.118+0700] {subprocess.py:93} INFO - 25/06/26 20:30:12 INFO TaskSetManager: Starting task 108.0 in stage 0.0 (TID 108) (localhost, executor driver, partition 108, PROCESS_LOCAL, 9215 bytes)
[2025-06-26T20:30:12.118+0700] {subprocess.py:93} INFO - 25/06/26 20:30:12 INFO Executor: Finished task 100.0 in stage 0.0 (TID 100). 3218 bytes result sent to driver
[2025-06-26T20:30:12.118+0700] {subprocess.py:93} INFO - 25/06/26 20:30:12 INFO Executor: Finished task 99.0 in stage 0.0 (TID 99). 3218 bytes result sent to driver
[2025-06-26T20:30:12.119+0700] {subprocess.py:93} INFO - 25/06/26 20:30:12 INFO Executor: Running task 108.0 in stage 0.0 (TID 108)
[2025-06-26T20:30:12.119+0700] {subprocess.py:93} INFO - 25/06/26 20:30:12 INFO TaskSetManager: Starting task 109.0 in stage 0.0 (TID 109) (localhost, executor driver, partition 109, PROCESS_LOCAL, 9215 bytes)
[2025-06-26T20:30:12.120+0700] {subprocess.py:93} INFO - 25/06/26 20:30:12 INFO TaskSetManager: Finished task 81.0 in stage 0.0 (TID 81) in 120 ms on localhost (executor driver) (84/2930)
[2025-06-26T20:30:12.120+0700] {subprocess.py:93} INFO - 25/06/26 20:30:12 INFO Executor: Running task 109.0 in stage 0.0 (TID 109)
[2025-06-26T20:30:12.121+0700] {subprocess.py:93} INFO - 25/06/26 20:30:12 INFO Executor: Finished task 101.0 in stage 0.0 (TID 101). 3218 bytes result sent to driver
[2025-06-26T20:30:12.121+0700] {subprocess.py:93} INFO - 25/06/26 20:30:12 INFO TaskSetManager: Starting task 110.0 in stage 0.0 (TID 110) (localhost, executor driver, partition 110, PROCESS_LOCAL, 9215 bytes)
[2025-06-26T20:30:12.122+0700] {subprocess.py:93} INFO - 25/06/26 20:30:12 INFO TaskSetManager: Finished task 78.0 in stage 0.0 (TID 78) in 150 ms on localhost (executor driver) (85/2930)
[2025-06-26T20:30:12.122+0700] {subprocess.py:93} INFO - 25/06/26 20:30:12 INFO Executor: Running task 110.0 in stage 0.0 (TID 110)
[2025-06-26T20:30:12.124+0700] {subprocess.py:93} INFO - 25/06/26 20:30:12 INFO TaskSetManager: Finished task 82.0 in stage 0.0 (TID 82) in 119 ms on localhost (executor driver) (86/2930)
[2025-06-26T20:30:12.125+0700] {subprocess.py:93} INFO - 25/06/26 20:30:12 INFO TaskSetManager: Finished task 86.0 in stage 0.0 (TID 86) in 105 ms on localhost (executor driver) (87/2930)
[2025-06-26T20:30:12.125+0700] {subprocess.py:93} INFO - 25/06/26 20:30:12 INFO Executor: Finished task 103.0 in stage 0.0 (TID 103). 3175 bytes result sent to driver
[2025-06-26T20:30:12.125+0700] {subprocess.py:93} INFO - 25/06/26 20:30:12 INFO TaskSetManager: Starting task 111.0 in stage 0.0 (TID 111) (localhost, executor driver, partition 111, PROCESS_LOCAL, 9215 bytes)
[2025-06-26T20:30:12.125+0700] {subprocess.py:93} INFO - 25/06/26 20:30:12 INFO TaskSetManager: Finished task 88.0 in stage 0.0 (TID 88) in 71 ms on localhost (executor driver) (88/2930)
[2025-06-26T20:30:12.125+0700] {subprocess.py:93} INFO - 25/06/26 20:30:12 INFO Executor: Running task 111.0 in stage 0.0 (TID 111)
[2025-06-26T20:30:12.126+0700] {subprocess.py:93} INFO - 25/06/26 20:30:12 INFO TaskSetManager: Starting task 112.0 in stage 0.0 (TID 112) (localhost, executor driver, partition 112, PROCESS_LOCAL, 9215 bytes)
[2025-06-26T20:30:12.126+0700] {subprocess.py:93} INFO - 25/06/26 20:30:12 INFO TaskSetManager: Finished task 87.0 in stage 0.0 (TID 87) in 96 ms on localhost (executor driver) (89/2930)
[2025-06-26T20:30:12.126+0700] {subprocess.py:93} INFO - 25/06/26 20:30:12 INFO Executor: Running task 112.0 in stage 0.0 (TID 112)
[2025-06-26T20:30:12.126+0700] {subprocess.py:93} INFO - 25/06/26 20:30:12 INFO TaskSetManager: Starting task 113.0 in stage 0.0 (TID 113) (localhost, executor driver, partition 113, PROCESS_LOCAL, 9215 bytes)
[2025-06-26T20:30:12.126+0700] {subprocess.py:93} INFO - 25/06/26 20:30:12 INFO TaskSetManager: Finished task 90.0 in stage 0.0 (TID 90) in 67 ms on localhost (executor driver) (90/2930)
[2025-06-26T20:30:12.126+0700] {subprocess.py:93} INFO - 25/06/26 20:30:12 INFO Executor: Running task 113.0 in stage 0.0 (TID 113)
[2025-06-26T20:30:12.126+0700] {subprocess.py:93} INFO - 25/06/26 20:30:12 INFO TaskSetManager: Finished task 93.0 in stage 0.0 (TID 93) in 65 ms on localhost (executor driver) (91/2930)
[2025-06-26T20:30:12.128+0700] {subprocess.py:93} INFO - 25/06/26 20:30:12 INFO TaskSetManager: Starting task 114.0 in stage 0.0 (TID 114) (localhost, executor driver, partition 114, PROCESS_LOCAL, 9215 bytes)
[2025-06-26T20:30:12.129+0700] {subprocess.py:93} INFO - 25/06/26 20:30:12 INFO TaskSetManager: Starting task 115.0 in stage 0.0 (TID 115) (localhost, executor driver, partition 115, PROCESS_LOCAL, 9215 bytes)
[2025-06-26T20:30:12.129+0700] {subprocess.py:93} INFO - 25/06/26 20:30:12 INFO Executor: Running task 115.0 in stage 0.0 (TID 115)
[2025-06-26T20:30:12.129+0700] {subprocess.py:93} INFO - 25/06/26 20:30:12 INFO TaskSetManager: Starting task 116.0 in stage 0.0 (TID 116) (localhost, executor driver, partition 116, PROCESS_LOCAL, 9215 bytes)
[2025-06-26T20:30:12.129+0700] {subprocess.py:93} INFO - 25/06/26 20:30:12 INFO TaskSetManager: Finished task 91.0 in stage 0.0 (TID 91) in 69 ms on localhost (executor driver) (92/2930)
[2025-06-26T20:30:12.129+0700] {subprocess.py:93} INFO - 25/06/26 20:30:12 INFO Executor: Running task 114.0 in stage 0.0 (TID 114)
[2025-06-26T20:30:12.129+0700] {subprocess.py:93} INFO - 25/06/26 20:30:12 INFO TaskSetManager: Starting task 117.0 in stage 0.0 (TID 117) (localhost, executor driver, partition 117, PROCESS_LOCAL, 9215 bytes)
[2025-06-26T20:30:12.147+0700] {subprocess.py:93} INFO - 25/06/26 20:30:12 INFO Executor: Finished task 102.0 in stage 0.0 (TID 102). 3218 bytes result sent to driver
[2025-06-26T20:30:12.148+0700] {subprocess.py:93} INFO - 25/06/26 20:30:12 INFO TaskSetManager: Starting task 118.0 in stage 0.0 (TID 118) (localhost, executor driver, partition 118, PROCESS_LOCAL, 9215 bytes)
[2025-06-26T20:30:12.149+0700] {subprocess.py:93} INFO - 25/06/26 20:30:12 INFO Executor: Finished task 107.0 in stage 0.0 (TID 107). 3218 bytes result sent to driver
[2025-06-26T20:30:12.149+0700] {subprocess.py:93} INFO - 25/06/26 20:30:12 INFO Executor: Running task 116.0 in stage 0.0 (TID 116)
[2025-06-26T20:30:12.149+0700] {subprocess.py:93} INFO - 25/06/26 20:30:12 INFO Executor: Running task 117.0 in stage 0.0 (TID 117)
[2025-06-26T20:30:12.149+0700] {subprocess.py:93} INFO - 25/06/26 20:30:12 INFO TaskSetManager: Finished task 92.0 in stage 0.0 (TID 92) in 87 ms on localhost (executor driver) (93/2930)
[2025-06-26T20:30:12.149+0700] {subprocess.py:93} INFO - 25/06/26 20:30:12 INFO Executor: Finished task 105.0 in stage 0.0 (TID 105). 3218 bytes result sent to driver
[2025-06-26T20:30:12.150+0700] {subprocess.py:93} INFO - 25/06/26 20:30:12 INFO TaskSetManager: Finished task 89.0 in stage 0.0 (TID 89) in 93 ms on localhost (executor driver) (94/2930)
[2025-06-26T20:30:12.150+0700] {subprocess.py:93} INFO - 25/06/26 20:30:12 INFO TaskSetManager: Starting task 119.0 in stage 0.0 (TID 119) (localhost, executor driver, partition 119, PROCESS_LOCAL, 9215 bytes)
[2025-06-26T20:30:12.150+0700] {subprocess.py:93} INFO - 25/06/26 20:30:12 INFO Executor: Running task 118.0 in stage 0.0 (TID 118)
[2025-06-26T20:30:12.150+0700] {subprocess.py:93} INFO - 25/06/26 20:30:12 INFO Executor: Finished task 109.0 in stage 0.0 (TID 109). 3175 bytes result sent to driver
[2025-06-26T20:30:12.150+0700] {subprocess.py:93} INFO - 25/06/26 20:30:12 INFO Executor: Finished task 104.0 in stage 0.0 (TID 104). 3175 bytes result sent to driver
[2025-06-26T20:30:12.150+0700] {subprocess.py:93} INFO - 25/06/26 20:30:12 INFO Executor: Running task 119.0 in stage 0.0 (TID 119)
[2025-06-26T20:30:12.150+0700] {subprocess.py:93} INFO - 25/06/26 20:30:12 INFO TaskSetManager: Starting task 120.0 in stage 0.0 (TID 120) (localhost, executor driver, partition 120, PROCESS_LOCAL, 9215 bytes)
[2025-06-26T20:30:12.152+0700] {subprocess.py:93} INFO - 25/06/26 20:30:12 INFO TaskSetManager: Finished task 95.0 in stage 0.0 (TID 95) in 88 ms on localhost (executor driver) (95/2930)
[2025-06-26T20:30:12.152+0700] {subprocess.py:93} INFO - 25/06/26 20:30:12 INFO Executor: Running task 120.0 in stage 0.0 (TID 120)
[2025-06-26T20:30:12.152+0700] {subprocess.py:93} INFO - 25/06/26 20:30:12 INFO TaskSetManager: Finished task 97.0 in stage 0.0 (TID 97) in 78 ms on localhost (executor driver) (96/2930)
[2025-06-26T20:30:12.152+0700] {subprocess.py:93} INFO - 25/06/26 20:30:12 INFO TaskSetManager: Finished task 98.0 in stage 0.0 (TID 98) in 77 ms on localhost (executor driver) (97/2930)
[2025-06-26T20:30:12.152+0700] {subprocess.py:93} INFO - 25/06/26 20:30:12 INFO Executor: Finished task 106.0 in stage 0.0 (TID 106). 3218 bytes result sent to driver
[2025-06-26T20:30:12.153+0700] {subprocess.py:93} INFO - 25/06/26 20:30:12 INFO TaskSetManager: Starting task 121.0 in stage 0.0 (TID 121) (localhost, executor driver, partition 121, PROCESS_LOCAL, 9215 bytes)
[2025-06-26T20:30:12.154+0700] {subprocess.py:93} INFO - 25/06/26 20:30:12 INFO Executor: Running task 121.0 in stage 0.0 (TID 121)
[2025-06-26T20:30:12.154+0700] {subprocess.py:93} INFO - 25/06/26 20:30:12 INFO TaskSetManager: Starting task 122.0 in stage 0.0 (TID 122) (localhost, executor driver, partition 122, PROCESS_LOCAL, 9215 bytes)
[2025-06-26T20:30:12.157+0700] {subprocess.py:93} INFO - 25/06/26 20:30:12 INFO Executor: Running task 122.0 in stage 0.0 (TID 122)
[2025-06-26T20:30:12.157+0700] {subprocess.py:93} INFO - 25/06/26 20:30:12 INFO TaskSetManager: Starting task 123.0 in stage 0.0 (TID 123) (localhost, executor driver, partition 123, PROCESS_LOCAL, 9215 bytes)
[2025-06-26T20:30:12.158+0700] {subprocess.py:93} INFO - 25/06/26 20:30:12 INFO Executor: Finished task 108.0 in stage 0.0 (TID 108). 3175 bytes result sent to driver
[2025-06-26T20:30:12.158+0700] {subprocess.py:93} INFO - 25/06/26 20:30:12 INFO TaskSetManager: Finished task 96.0 in stage 0.0 (TID 96) in 93 ms on localhost (executor driver) (98/2930)
[2025-06-26T20:30:12.158+0700] {subprocess.py:93} INFO - 25/06/26 20:30:12 INFO Executor: Running task 123.0 in stage 0.0 (TID 123)
[2025-06-26T20:30:12.160+0700] {subprocess.py:93} INFO - 25/06/26 20:30:12 INFO TaskSetManager: Starting task 124.0 in stage 0.0 (TID 124) (localhost, executor driver, partition 124, PROCESS_LOCAL, 9215 bytes)
[2025-06-26T20:30:12.161+0700] {subprocess.py:93} INFO - 25/06/26 20:30:12 INFO Executor: Running task 124.0 in stage 0.0 (TID 124)
[2025-06-26T20:30:12.162+0700] {subprocess.py:93} INFO - 25/06/26 20:30:12 INFO TaskSetManager: Finished task 94.0 in stage 0.0 (TID 94) in 99 ms on localhost (executor driver) (99/2930)
[2025-06-26T20:30:12.163+0700] {subprocess.py:93} INFO - 25/06/26 20:30:12 INFO Executor: Finished task 113.0 in stage 0.0 (TID 113). 3175 bytes result sent to driver
[2025-06-26T20:30:12.164+0700] {subprocess.py:93} INFO - 25/06/26 20:30:12 INFO Executor: Finished task 110.0 in stage 0.0 (TID 110). 3175 bytes result sent to driver
[2025-06-26T20:30:12.164+0700] {subprocess.py:93} INFO - 25/06/26 20:30:12 INFO TaskSetManager: Starting task 125.0 in stage 0.0 (TID 125) (localhost, executor driver, partition 125, PROCESS_LOCAL, 9215 bytes)
[2025-06-26T20:30:12.164+0700] {subprocess.py:93} INFO - 25/06/26 20:30:12 INFO Executor: Running task 125.0 in stage 0.0 (TID 125)
[2025-06-26T20:30:12.164+0700] {subprocess.py:93} INFO - 25/06/26 20:30:12 INFO TaskSetManager: Finished task 99.0 in stage 0.0 (TID 99) in 82 ms on localhost (executor driver) (100/2930)
[2025-06-26T20:30:12.165+0700] {subprocess.py:93} INFO - 25/06/26 20:30:12 INFO Executor: Finished task 114.0 in stage 0.0 (TID 114). 3175 bytes result sent to driver
[2025-06-26T20:30:12.165+0700] {subprocess.py:93} INFO - 25/06/26 20:30:12 INFO Executor: Finished task 115.0 in stage 0.0 (TID 115). 3175 bytes result sent to driver
[2025-06-26T20:30:12.166+0700] {subprocess.py:93} INFO - 25/06/26 20:30:12 INFO TaskSetManager: Finished task 101.0 in stage 0.0 (TID 101) in 75 ms on localhost (executor driver) (101/2930)
[2025-06-26T20:30:12.166+0700] {subprocess.py:93} INFO - 25/06/26 20:30:12 INFO Executor: Finished task 117.0 in stage 0.0 (TID 117). 3175 bytes result sent to driver
[2025-06-26T20:30:12.166+0700] {subprocess.py:93} INFO - 25/06/26 20:30:12 INFO TaskSetManager: Finished task 100.0 in stage 0.0 (TID 100) in 77 ms on localhost (executor driver) (102/2930)
[2025-06-26T20:30:12.166+0700] {subprocess.py:93} INFO - 25/06/26 20:30:12 INFO Executor: Finished task 111.0 in stage 0.0 (TID 111). 3175 bytes result sent to driver
[2025-06-26T20:30:12.167+0700] {subprocess.py:93} INFO - 25/06/26 20:30:12 INFO Executor: Finished task 119.0 in stage 0.0 (TID 119). 3175 bytes result sent to driver
[2025-06-26T20:30:12.167+0700] {subprocess.py:93} INFO - 25/06/26 20:30:12 INFO Executor: Finished task 118.0 in stage 0.0 (TID 118). 3175 bytes result sent to driver
[2025-06-26T20:30:12.167+0700] {subprocess.py:93} INFO - 25/06/26 20:30:12 INFO Executor: Finished task 112.0 in stage 0.0 (TID 112). 3175 bytes result sent to driver
[2025-06-26T20:30:12.168+0700] {subprocess.py:93} INFO - 25/06/26 20:30:12 INFO Executor: Finished task 116.0 in stage 0.0 (TID 116). 3175 bytes result sent to driver
[2025-06-26T20:30:12.168+0700] {subprocess.py:93} INFO - 25/06/26 20:30:12 INFO TaskSetManager: Starting task 126.0 in stage 0.0 (TID 126) (localhost, executor driver, partition 126, PROCESS_LOCAL, 9215 bytes)
[2025-06-26T20:30:12.168+0700] {subprocess.py:93} INFO - 25/06/26 20:30:12 INFO TaskSetManager: Finished task 103.0 in stage 0.0 (TID 103) in 57 ms on localhost (executor driver) (103/2930)
[2025-06-26T20:30:12.168+0700] {subprocess.py:93} INFO - 25/06/26 20:30:12 INFO Executor: Running task 126.0 in stage 0.0 (TID 126)
[2025-06-26T20:30:12.168+0700] {subprocess.py:93} INFO - 25/06/26 20:30:12 INFO TaskSetManager: Finished task 102.0 in stage 0.0 (TID 102) in 72 ms on localhost (executor driver) (104/2930)
[2025-06-26T20:30:12.168+0700] {subprocess.py:93} INFO - 25/06/26 20:30:12 INFO Executor: Finished task 120.0 in stage 0.0 (TID 120). 3175 bytes result sent to driver
[2025-06-26T20:30:12.170+0700] {subprocess.py:93} INFO - 25/06/26 20:30:12 INFO TaskSetManager: Starting task 127.0 in stage 0.0 (TID 127) (localhost, executor driver, partition 127, PROCESS_LOCAL, 9215 bytes)
[2025-06-26T20:30:12.171+0700] {subprocess.py:93} INFO - 25/06/26 20:30:12 INFO TaskSetManager: Finished task 107.0 in stage 0.0 (TID 107) in 55 ms on localhost (executor driver) (105/2930)
[2025-06-26T20:30:12.171+0700] {subprocess.py:93} INFO - 25/06/26 20:30:12 INFO Executor: Running task 127.0 in stage 0.0 (TID 127)
[2025-06-26T20:30:12.172+0700] {subprocess.py:93} INFO - 25/06/26 20:30:12 INFO Executor: Finished task 122.0 in stage 0.0 (TID 122). 3175 bytes result sent to driver
[2025-06-26T20:30:12.172+0700] {subprocess.py:93} INFO - 25/06/26 20:30:12 INFO Executor: Finished task 121.0 in stage 0.0 (TID 121). 3175 bytes result sent to driver
[2025-06-26T20:30:12.172+0700] {subprocess.py:93} INFO - 25/06/26 20:30:12 INFO Executor: Finished task 124.0 in stage 0.0 (TID 124). 3175 bytes result sent to driver
[2025-06-26T20:30:12.173+0700] {subprocess.py:93} INFO - 25/06/26 20:30:12 INFO TaskSetManager: Starting task 128.0 in stage 0.0 (TID 128) (localhost, executor driver, partition 128, PROCESS_LOCAL, 9215 bytes)
[2025-06-26T20:30:12.173+0700] {subprocess.py:93} INFO - 25/06/26 20:30:12 INFO Executor: Running task 128.0 in stage 0.0 (TID 128)
[2025-06-26T20:30:12.174+0700] {subprocess.py:93} INFO - 25/06/26 20:30:12 INFO TaskSetManager: Finished task 105.0 in stage 0.0 (TID 105) in 60 ms on localhost (executor driver) (106/2930)
[2025-06-26T20:30:12.174+0700] {subprocess.py:93} INFO - 25/06/26 20:30:12 INFO Executor: Finished task 123.0 in stage 0.0 (TID 123). 3175 bytes result sent to driver
[2025-06-26T20:30:12.174+0700] {subprocess.py:93} INFO - 25/06/26 20:30:12 INFO TaskSetManager: Starting task 129.0 in stage 0.0 (TID 129) (localhost, executor driver, partition 129, PROCESS_LOCAL, 9215 bytes)
[2025-06-26T20:30:12.175+0700] {subprocess.py:93} INFO - 25/06/26 20:30:12 INFO Executor: Running task 129.0 in stage 0.0 (TID 129)
[2025-06-26T20:30:12.175+0700] {subprocess.py:93} INFO - 25/06/26 20:30:12 INFO TaskSetManager: Finished task 109.0 in stage 0.0 (TID 109) in 56 ms on localhost (executor driver) (107/2930)
[2025-06-26T20:30:12.175+0700] {subprocess.py:93} INFO - 25/06/26 20:30:12 INFO Executor: Finished task 125.0 in stage 0.0 (TID 125). 3175 bytes result sent to driver
[2025-06-26T20:30:12.176+0700] {subprocess.py:93} INFO - 25/06/26 20:30:12 INFO TaskSetManager: Starting task 130.0 in stage 0.0 (TID 130) (localhost, executor driver, partition 130, PROCESS_LOCAL, 9215 bytes)
[2025-06-26T20:30:12.183+0700] {subprocess.py:93} INFO - 25/06/26 20:30:12 INFO Executor: Running task 130.0 in stage 0.0 (TID 130)
[2025-06-26T20:30:12.183+0700] {subprocess.py:93} INFO - 25/06/26 20:30:12 INFO TaskSetManager: Finished task 104.0 in stage 0.0 (TID 104) in 64 ms on localhost (executor driver) (108/2930)
[2025-06-26T20:30:12.184+0700] {subprocess.py:93} INFO - 25/06/26 20:30:12 INFO Executor: Finished task 126.0 in stage 0.0 (TID 126). 3261 bytes result sent to driver
[2025-06-26T20:30:12.185+0700] {subprocess.py:93} INFO - 25/06/26 20:30:12 INFO TaskSetManager: Starting task 131.0 in stage 0.0 (TID 131) (localhost, executor driver, partition 131, PROCESS_LOCAL, 9215 bytes)
